<?xml version="1.0" ?>
<mujoco model="rollin-justin">
	<compiler meshdir="rollin-justin/meshes" texturedir="rollin-justin/textures" angle="radian" autolimits="true" balanceinertia="true" boundmass="0.000001" boundinertia="0.000001"/>
	<default>
		<default class="rollin-justin">
			<geom contype="0" conaffinity="0"/>
		</default>
		<default class="rollin-justin_collision">
			<geom rgba="0.9 0.9 0.9 1.0"/>
		</default>
	</default>
	<asset>
		<mesh name="mp_mobile_plattform_rj_BASE_collision_0_0010000000474974513_0_0010000000474974513_0_0010000000474974513" file="stl/mp_mobile_plattform_rj_BASE_collision.stl" scale="0.0010000000474974513 0.0010000000474974513 0.0010000000474974513"/>
		<mesh name="mp_mobile_plattform_rj_ROT1_collision_0_0010000000474974513_0_0010000000474974513_0_0010000000474974513" file="stl/mp_mobile_plattform_rj_ROT1_collision.stl" scale="0.0010000000474974513 0.0010000000474974513 0.0010000000474974513"/>
		<mesh name="mp_mobile_plattform_rj_ROT2_collision_0_0010000000474974513_0_0010000000474974513_0_0010000000474974513" file="stl/mp_mobile_plattform_rj_ROT2_collision.stl" scale="0.0010000000474974513 0.0010000000474974513 0.0010000000474974513"/>
		<mesh name="mp_mobile_plattform_rj_ROT3_collision_0_0010000000474974513_0_0010000000474974513_0_0010000000474974513" file="stl/mp_mobile_plattform_rj_ROT3_collision.stl" scale="0.0010000000474974513 0.0010000000474974513 0.0010000000474974513"/>
		<mesh name="mp_mobile_plattform_rj_ROT4_collision_0_0010000000474974513_0_0010000000474974513_0_0010000000474974513" file="stl/mp_mobile_plattform_rj_ROT4_collision.stl" scale="0.0010000000474974513 0.0010000000474974513 0.0010000000474974513"/>
		<mesh name="trs_plat_dummy_Trs_Base_A0_collision_0_0010000000474974513_0_0010000000474974513_0_0010000000474974513" file="stl/trs_plat_dummy_Trs_Base_A0_collision.stl" scale="0.0010000000474974513 0.0010000000474974513 0.0010000000474974513"/>
		<mesh name="trs_plat_dummy_A1_collision_0_0010000000474974513_0_0010000000474974513_0_0010000000474974513" file="stl/trs_plat_dummy_A1_collision.stl" scale="0.0010000000474974513 0.0010000000474974513 0.0010000000474974513"/>
		<mesh name="trs_plat_dummy_A2_collision_0_0010000000474974513_0_0010000000474974513_0_0010000000474974513" file="stl/trs_plat_dummy_A2_collision.stl" scale="0.0010000000474974513 0.0010000000474974513 0.0010000000474974513"/>
		<mesh name="trs_plat_dummy_A3_collision_0_0010000000474974513_0_0010000000474974513_0_0010000000474974513" file="stl/trs_plat_dummy_A3_collision.stl" scale="0.0010000000474974513 0.0010000000474974513 0.0010000000474974513"/>
		<mesh name="trs_plat_dummy_A4_collision_0_0010000000474974513_0_0010000000474974513_0_0010000000474974513" file="stl/trs_plat_dummy_A4_collision.stl" scale="0.0010000000474974513 0.0010000000474974513 0.0010000000474974513"/>
		<mesh name="lr33_J1_Base_frame_collision_0_0010000000474974513_0_0010000000474974513_0_0010000000474974513" file="stl/lr33_J1_Base_frame_collision.stl" scale="0.0010000000474974513 0.0010000000474974513 0.0010000000474974513"/>
		<mesh name="justin_rj_kopf_HALS_EINBAU_collision_0_0010000000474974513_0_0010000000474974513_0_0010000000474974513" file="stl/justin_rj_kopf_HALS_EINBAU_collision.stl" scale="0.0010000000474974513 0.0010000000474974513 0.0010000000474974513"/>
		<mesh name="lr33_J2_HUELLE_A1_collision_0_0010000000474974513_0_0010000000474974513_0_0010000000474974513" file="stl/lr33_J2_HUELLE_A1_collision.stl" scale="0.0010000000474974513 0.0010000000474974513 0.0010000000474974513"/>
		<mesh name="lr33_J3_HUELLE_A2_collision_0_0010000000474974513_0_0010000000474974513_0_0010000000474974513" file="stl/lr33_J3_HUELLE_A2_collision.stl" scale="0.0010000000474974513 0.0010000000474974513 0.0010000000474974513"/>
		<mesh name="lr33_J4_HUELLE_A3_collision_0_0010000000474974513_0_0010000000474974513_0_0010000000474974513" file="stl/lr33_J4_HUELLE_A3_collision.stl" scale="0.0010000000474974513 0.0010000000474974513 0.0010000000474974513"/>
		<mesh name="lr33_J5_HUELLE_A4_collision_0_0010000000474974513_0_0010000000474974513_0_0010000000474974513" file="stl/lr33_J5_HUELLE_A4_collision.stl" scale="0.0010000000474974513 0.0010000000474974513 0.0010000000474974513"/>
		<mesh name="lr33_J6_HUELLE_A5_collision_0_0010000000474974513_0_0010000000474974513_0_0010000000474974513" file="stl/lr33_J6_HUELLE_A5_collision.stl" scale="0.0010000000474974513 0.0010000000474974513 0.0010000000474974513"/>
		<mesh name="lr33_J7_HUELLE_A6_collision_0_0010000000474974513_0_0010000000474974513_0_0010000000474974513" file="stl/lr33_J7_HUELLE_A6_collision.stl" scale="0.0010000000474974513 0.0010000000474974513 0.0010000000474974513"/>
		<mesh name="lr33_J8_HUELLE_A7_collision_0_0010000000474974513_0_0010000000474974513_0_0010000000474974513" file="stl/lr33_J8_HUELLE_A7_collision.stl" scale="0.0010000000474974513 0.0010000000474974513 0.0010000000474974513"/>
		<mesh name="hii_links_export_Base_SWA_collision_0_0010000000474974513_0_0010000000474974513_0_0010000000474974513" file="stl/hii_links_export_Base_SWA_collision.stl" scale="0.0010000000474974513 0.0010000000474974513 0.0010000000474974513"/>
		<mesh name="hii_links_export_D_MP_AB1_collision_0_0010000000474974513_0_0010000000474974513_0_0010000000474974513" file="stl/hii_links_export_D_MP_AB1_collision.stl" scale="0.0010000000474974513 0.0010000000474974513 0.0010000000474974513"/>
		<mesh name="hii_links_export_D_MP_AB2_collision_0_0010000000474974513_0_0010000000474974513_0_0010000000474974513" file="stl/hii_links_export_D_MP_AB2_collision.stl" scale="0.0010000000474974513 0.0010000000474974513 0.0010000000474974513"/>
		<mesh name="hii_links_export_D_PIP_collision_0_0010000000474974513_0_0010000000474974513_0_0010000000474974513" file="stl/hii_links_export_D_PIP_collision.stl" scale="0.0010000000474974513 0.0010000000474974513 0.0010000000474974513"/>
		<mesh name="hii_links_export_D_DIP_collision_0_0010000000474974513_0_0010000000474974513_0_0010000000474974513" file="stl/hii_links_export_D_DIP_collision.stl" scale="0.0010000000474974513 0.0010000000474974513 0.0010000000474974513"/>
		<mesh name="hii_links_export_ZF_MP_AB1_collision_0_0010000000474974513_0_0010000000474974513_0_0010000000474974513" file="stl/hii_links_export_ZF_MP_AB1_collision.stl" scale="0.0010000000474974513 0.0010000000474974513 0.0010000000474974513"/>
		<mesh name="hii_links_export_ZF_MP_AB2_collision_0_0010000000474974513_0_0010000000474974513_0_0010000000474974513" file="stl/hii_links_export_ZF_MP_AB2_collision.stl" scale="0.0010000000474974513 0.0010000000474974513 0.0010000000474974513"/>
		<mesh name="hii_links_export_ZF_PIP_collision_0_0010000000474974513_0_0010000000474974513_0_0010000000474974513" file="stl/hii_links_export_ZF_PIP_collision.stl" scale="0.0010000000474974513 0.0010000000474974513 0.0010000000474974513"/>
		<mesh name="hii_links_export_ZF_DIP_collision_0_0010000000474974513_0_0010000000474974513_0_0010000000474974513" file="stl/hii_links_export_ZF_DIP_collision.stl" scale="0.0010000000474974513 0.0010000000474974513 0.0010000000474974513"/>
		<mesh name="hii_links_export_MF_MP_AB1_collision_0_0010000000474974513_0_0010000000474974513_0_0010000000474974513" file="stl/hii_links_export_MF_MP_AB1_collision.stl" scale="0.0010000000474974513 0.0010000000474974513 0.0010000000474974513"/>
		<mesh name="hii_links_export_MF_MP_AB2_collision_0_0010000000474974513_0_0010000000474974513_0_0010000000474974513" file="stl/hii_links_export_MF_MP_AB2_collision.stl" scale="0.0010000000474974513 0.0010000000474974513 0.0010000000474974513"/>
		<mesh name="hii_links_export_MF_PIP_collision_0_0010000000474974513_0_0010000000474974513_0_0010000000474974513" file="stl/hii_links_export_MF_PIP_collision.stl" scale="0.0010000000474974513 0.0010000000474974513 0.0010000000474974513"/>
		<mesh name="hii_links_export_MF_DIP_collision_0_0010000000474974513_0_0010000000474974513_0_0010000000474974513" file="stl/hii_links_export_MF_DIP_collision.stl" scale="0.0010000000474974513 0.0010000000474974513 0.0010000000474974513"/>
		<mesh name="hii_links_export_RF_MP_AB1_collision_0_0010000000474974513_0_0010000000474974513_0_0010000000474974513" file="stl/hii_links_export_RF_MP_AB1_collision.stl" scale="0.0010000000474974513 0.0010000000474974513 0.0010000000474974513"/>
		<mesh name="hii_links_export_RF_MP_AB2_collision_0_0010000000474974513_0_0010000000474974513_0_0010000000474974513" file="stl/hii_links_export_RF_MP_AB2_collision.stl" scale="0.0010000000474974513 0.0010000000474974513 0.0010000000474974513"/>
		<mesh name="hii_links_export_RF_PIP_collision_0_0010000000474974513_0_0010000000474974513_0_0010000000474974513" file="stl/hii_links_export_RF_PIP_collision.stl" scale="0.0010000000474974513 0.0010000000474974513 0.0010000000474974513"/>
		<mesh name="hii_links_export_RF_DIP_collision_0_0010000000474974513_0_0010000000474974513_0_0010000000474974513" file="stl/hii_links_export_RF_DIP_collision.stl" scale="0.0010000000474974513 0.0010000000474974513 0.0010000000474974513"/>
		<mesh name="hand2_export_Base_SWA_collision_0_0010000000474974513_0_0010000000474974513_0_0010000000474974513" file="stl/hand2_export_Base_SWA_collision.stl" scale="0.0010000000474974513 0.0010000000474974513 0.0010000000474974513"/>
		<mesh name="hand2_export_D_MP_AB1_collision_0_0010000000474974513_0_0010000000474974513_0_0010000000474974513" file="stl/hand2_export_D_MP_AB1_collision.stl" scale="0.0010000000474974513 0.0010000000474974513 0.0010000000474974513"/>
		<mesh name="hand2_export_D_MP_AB2_collision_0_0010000000474974513_0_0010000000474974513_0_0010000000474974513" file="stl/hand2_export_D_MP_AB2_collision.stl" scale="0.0010000000474974513 0.0010000000474974513 0.0010000000474974513"/>
		<mesh name="hand2_export_D_PIP_collision_0_0010000000474974513_0_0010000000474974513_0_0010000000474974513" file="stl/hand2_export_D_PIP_collision.stl" scale="0.0010000000474974513 0.0010000000474974513 0.0010000000474974513"/>
		<mesh name="hand2_export_D_DIP_collision_0_0010000000474974513_0_0010000000474974513_0_0010000000474974513" file="stl/hand2_export_D_DIP_collision.stl" scale="0.0010000000474974513 0.0010000000474974513 0.0010000000474974513"/>
		<mesh name="hand2_export_ZF_MP_AB1_collision_0_0010000000474974513_0_0010000000474974513_0_0010000000474974513" file="stl/hand2_export_ZF_MP_AB1_collision.stl" scale="0.0010000000474974513 0.0010000000474974513 0.0010000000474974513"/>
		<mesh name="hand2_export_ZF_MP_AB2_collision_0_0010000000474974513_0_0010000000474974513_0_0010000000474974513" file="stl/hand2_export_ZF_MP_AB2_collision.stl" scale="0.0010000000474974513 0.0010000000474974513 0.0010000000474974513"/>
		<mesh name="hand2_export_ZF_PIP_collision_0_0010000000474974513_0_0010000000474974513_0_0010000000474974513" file="stl/hand2_export_ZF_PIP_collision.stl" scale="0.0010000000474974513 0.0010000000474974513 0.0010000000474974513"/>
		<mesh name="hand2_export_ZF_DIP_collision_0_0010000000474974513_0_0010000000474974513_0_0010000000474974513" file="stl/hand2_export_ZF_DIP_collision.stl" scale="0.0010000000474974513 0.0010000000474974513 0.0010000000474974513"/>
		<mesh name="hand2_export_MF_MP_AB1_collision_0_0010000000474974513_0_0010000000474974513_0_0010000000474974513" file="stl/hand2_export_MF_MP_AB1_collision.stl" scale="0.0010000000474974513 0.0010000000474974513 0.0010000000474974513"/>
		<mesh name="hand2_export_MF_MP_AB2_collision_0_0010000000474974513_0_0010000000474974513_0_0010000000474974513" file="stl/hand2_export_MF_MP_AB2_collision.stl" scale="0.0010000000474974513 0.0010000000474974513 0.0010000000474974513"/>
		<mesh name="hand2_export_MF_PIP_collision_0_0010000000474974513_0_0010000000474974513_0_0010000000474974513" file="stl/hand2_export_MF_PIP_collision.stl" scale="0.0010000000474974513 0.0010000000474974513 0.0010000000474974513"/>
		<mesh name="hand2_export_MF_DIP_collision_0_0010000000474974513_0_0010000000474974513_0_0010000000474974513" file="stl/hand2_export_MF_DIP_collision.stl" scale="0.0010000000474974513 0.0010000000474974513 0.0010000000474974513"/>
		<mesh name="hand2_export_RF_MP_AB1_collision_0_0010000000474974513_0_0010000000474974513_0_0010000000474974513" file="stl/hand2_export_RF_MP_AB1_collision.stl" scale="0.0010000000474974513 0.0010000000474974513 0.0010000000474974513"/>
		<mesh name="hand2_export_RF_MP_AB2_collision_0_0010000000474974513_0_0010000000474974513_0_0010000000474974513" file="stl/hand2_export_RF_MP_AB2_collision.stl" scale="0.0010000000474974513 0.0010000000474974513 0.0010000000474974513"/>
		<mesh name="hand2_export_RF_PIP_collision_0_0010000000474974513_0_0010000000474974513_0_0010000000474974513" file="stl/hand2_export_RF_PIP_collision.stl" scale="0.0010000000474974513 0.0010000000474974513 0.0010000000474974513"/>
		<mesh name="hand2_export_RF_DIP_collision_0_0010000000474974513_0_0010000000474974513_0_0010000000474974513" file="stl/hand2_export_RF_DIP_collision.stl" scale="0.0010000000474974513 0.0010000000474974513 0.0010000000474974513"/>
		<mesh name="justin_rj_kopf_HALS_ROT_collision_0_0010000000474974513_0_0010000000474974513_0_0010000000474974513" file="stl/justin_rj_kopf_HALS_ROT_collision.stl" scale="0.0010000000474974513 0.0010000000474974513 0.0010000000474974513"/>
		<mesh name="justin_rj_kopf_HALS_KNICK_collision_0_0010000000474974513_0_0010000000474974513_0_0010000000474974513" file="stl/justin_rj_kopf_HALS_KNICK_collision.stl" scale="0.0010000000474974513 0.0010000000474974513 0.0010000000474974513"/>
	</asset>
	<worldbody>
		<body name="rollin-justin" pos="0.0 0.0 0.0" quat="1.0 0.0 0.0 0.0">
			<freejoint/>
			<body name="base_link" pos="0.0 0.0 0.0" quat="1.0 0.0 0.0 0.0">
				<body name="platform_link" pos="0.0 0.0 0.0" quat="1.0 0.0 0.0 0.0">
					<inertial mass="223.35980224609375" pos="-1.4043760643289716e-07 -1.881562639027834e-07 0.2798108756542206" quat="0.4998933672904968 0.5001075863838196 -0.4998925030231476 0.5001065135002136" diaginertia="0.015121474862098694 0.02837841585278511 0.032177478075027466"/>
					<geom name="platform_link_geom_collision_0_mp_mobile_plattform_rj_BASE_collision" type="mesh" pos="0.0 0.0 0.0" quat="1.0 0.0 0.0 0.0" mesh="mp_mobile_plattform_rj_BASE_collision_0_0010000000474974513_0_0010000000474974513_0_0010000000474974513" class="rollin-justin_collision"/>
					<body name="wheel_lf_link" pos="0.34198999404907227 0.25784000754356384 0.02889999933540821" quat="0.270600825548172 -0.270600825548172 -0.6532803177833557 0.6532803177833557">
						<inertial mass="4.602991104125977" pos="0.3495153784751892 0.2503224015235901 0.04731135070323944" quat="-0.48649007081985474 -0.49181240797042847 0.5139122009277344 0.5072891116142273" diaginertia="1.9325801986269653e-05 2.3513217456638813e-05 3.399273919058032e-05"/>
						<geom name="wheel_lf_link_geom_collision_0_mp_mobile_plattform_rj_ROT2_collision" type="mesh" pos="0.0 0.0 0.0" quat="1.0 0.0 0.0 0.0" mesh="mp_mobile_plattform_rj_ROT2_collision_0_0010000000474974513_0_0010000000474974513_0_0010000000474974513" class="rollin-justin_collision"/>
					</body>
					<body name="wheel_lb_link" pos="-0.34198999404907227 -0.25784000754356384 0.02889999933540821" quat="-0.6532803177833557 0.6532803177833557 -0.270600825548172 0.270600825548172">
						<inertial mass="4.602991104125977" pos="-0.3495153784751892 -0.2503224015235901 0.04731135070323944" quat="-0.48649007081985474 -0.49181240797042847 0.5139122009277344 0.5072891116142273" diaginertia="1.9325801986269653e-05 2.3513217456638813e-05 3.399273919058032e-05"/>
						<geom name="wheel_lb_link_geom_collision_0_mp_mobile_plattform_rj_ROT4_collision" type="mesh" pos="0.0 0.0 0.0" quat="1.0 0.0 0.0 0.0" mesh="mp_mobile_plattform_rj_ROT4_collision_0_0010000000474974513_0_0010000000474974513_0_0010000000474974513" class="rollin-justin_collision"/>
					</body>
					<body name="wheel_rf_link" pos="0.3427000045776367 -0.25714001059532166 0.02889999933540821" quat="0.653282642364502 -0.653282642364502 -0.2705952823162079 0.2705952823162079">
						<inertial mass="4.602991104125977" pos="0.33518221974372864 -0.2646655738353729 0.04731134697794914" quat="-0.4864896833896637 -0.49181199073791504 0.5139126181602478 0.507289469242096" diaginertia="1.9325827452121302e-05 2.3513242922490463e-05 3.399274282855913e-05"/>
						<geom name="wheel_rf_link_geom_collision_0_mp_mobile_plattform_rj_ROT1_collision" type="mesh" pos="0.0 0.0 0.0" quat="1.0 0.0 0.0 0.0" mesh="mp_mobile_plattform_rj_ROT1_collision_0_0010000000474974513_0_0010000000474974513_0_0010000000474974513" class="rollin-justin_collision"/>
					</body>
					<body name="torso_base_link" pos="0.0 0.0 0.5935999751091003" quat="0.7071067690849304 0.0 0.0 0.7071067690849304">
						<inertial mass="1.5521502494812012" pos="0.00020634671091102064 0.000574899953790009 0.558713972568512" quat="-0.6950117349624634 0.058600373566150665 0.714732825756073 0.051784858107566833" diaginertia="3.49068250216078e-06 5.32879266756936e-06 5.339084509614622e-06"/>
						<geom name="torso_base_link_geom_collision_0_trs_plat_dummy_Trs_Base_A0_collision" type="mesh" pos="0.0 0.0 0.0" quat="1.0 0.0 0.0 0.0" mesh="trs_plat_dummy_Trs_Base_A0_collision_0_0010000000474974513_0_0010000000474974513_0_0010000000474974513" class="rollin-justin_collision"/>
						<body name="torso1_link" pos="0.0 0.0 0.0" quat="0.7071067690849304 -7.850390690659011e-17 -7.85053362746886e-17 -0.7071067690849304">
							<inertial mass="6.073577880859375" pos="0.00010646606824593619 -1.0510984793654643e-05 0.6650705337524414" quat="0.00023532092745881528 -0.7069438695907593 -4.704707316705026e-05 0.7072696089744568" diaginertia="4.398792589199729e-05 6.0617599956458434e-05 6.622904038522393e-05"/>
							<geom name="torso1_link_geom_collision_0_trs_plat_dummy_A1_collision" type="mesh" pos="0.0 0.0 0.0" quat="1.0 0.0 0.0 0.0" mesh="trs_plat_dummy_A1_collision_0_0010000000474974513_0_0010000000474974513_0_0010000000474974513" class="rollin-justin_collision"/>
							<joint name="torso1" type="hinge" pos="0.0 0.0 0.0" range="-1.7453300952911377 3.3161301612854004" axis="0.0 0.0 1.0"/>
							<body name="torso2_link" pos="2.502442706504828e-17 2.2790941285239353e-22 0.11270000040531158" quat="0.5 -0.5 -0.5 -0.5">
								<inertial mass="11.692341804504395" pos="-0.008352112956345081 2.2683896531816572e-05 0.8464316725730896" quat="-0.7068337798118591 0.7070564031600952 -0.015143604949116707 0.015098030678927898" diaginertia="6.56901320326142e-05 0.0003861655422952026 0.0004174500936642289"/>
								<geom name="torso2_link_geom_collision_0_trs_plat_dummy_A2_collision" type="mesh" pos="0.0 0.0 0.0" quat="1.0 0.0 0.0 0.0" mesh="trs_plat_dummy_A2_collision_0_0010000000474974513_0_0010000000474974513_0_0010000000474974513" class="rollin-justin_collision"/>
								<joint name="torso2" type="hinge" pos="-1.5407439555097887e-32 -5.61291613287647e-38 -2.7755575615628914e-17" range="-1.2217299938201904 0.5235999822616577" axis="0.0 0.0 1.0"/>
								<body name="torso3_link" pos="0.30000001192092896 -2.4554090183517157e-16 -9.184547819103952e-18" quat="1.0 1.1102230246251565e-16 8.859277744181285e-33 2.701939016441264e-16">
									<inertial mass="11.692341804504395" pos="-0.008352110162377357 -0.0004773154214490205 1.1464316844940186" quat="-0.7066971063613892 0.7071917653083801 -0.01605169288814068 0.014189355075359344" diaginertia="6.569059769390151e-05 0.00038616772508248687 0.00041745277121663094"/>
									<geom name="torso3_link_geom_collision_0_trs_plat_dummy_A3_collision" type="mesh" pos="0.0 0.0 0.0" quat="1.0 0.0 0.0 0.0" mesh="trs_plat_dummy_A3_collision_0_0010000000474974513_0_0010000000474974513_0_0010000000474974513" class="rollin-justin_collision"/>
									<joint name="torso3" type="hinge" pos="8.271806125530277e-25 5.551115123125783e-17 -9.392203575540786e-25" range="0.17453299462795258 2.338740110397339" axis="0.0 0.0 1.0"/>
									<body name="torso4_link" pos="0.30000001192092896 -4.076572375276915e-16 -4.592273909551976e-18" quat="1.0 3.697785493223493e-32 -4.622231866529366e-33 -6.528573674202708e-16">
										<inertial mass="13.096269607543945" pos="0.0666206106543541 3.0387764127226546e-06 1.353256344795227" quat="0.6408016085624695 0.6407525539398193 0.29897257685661316 0.29903990030288696" diaginertia="0.00012765049177687615 0.00018537203141022474 0.00022400451416615397"/>
										<geom name="torso4_link_geom_collision_0_trs_plat_dummy_A4_collision" type="mesh" pos="0.0 0.0 0.0" quat="1.0 0.0 0.0 0.0" mesh="trs_plat_dummy_A4_collision_0_0010000000474974513_0_0010000000474974513_0_0010000000474974513" class="rollin-justin_collision"/>
										<joint name="torso4" type="hinge" pos="-8.271806125530277e-25 -5.551115123125783e-17 -3.32286317636865e-24" range="-1.5700000524520874 0.10000000149011612" axis="0.0 0.0 1.0"/>
										<body name="right_base_link" pos="0.03500000014901161 0.08799999952316284 0.012662800028920174" quat="5.914589533937914e-17 0.9659258127212524 -1.5848102248413717e-17 0.2588191330432892">
											<inertial mass="0.9763923287391663" pos="0.07900676131248474 0.08859748393297195 -0.06359962373971939" quat="0.706705629825592 -0.02453411929309368 -0.7065299153327942 -0.027941126376390457" diaginertia="1.359836574010842e-06 9.149946890829597e-06 9.160901754512452e-06"/>
											<geom name="right_base_link_geom_collision_0_lr33_J1_Base_frame_collision" type="mesh" pos="0.0 0.0 0.0" quat="1.0 0.0 0.0 0.0" mesh="lr33_J1_Base_frame_collision_0_0010000000474974513_0_0010000000474974513_0_0010000000474974513" class="rollin-justin_collision"/>
											<body name="right_arm1_link" pos="-2.220446049250313e-16 1.3877787807814457e-17 0.3100000023841858" quat="6.123234262925839e-17 2.7755575615628914e-17 4.591774807899561e-41 1.0">
												<inertial mass="3.0793471336364746" pos="0.11226725578308105 -0.1949746459722519 1.4611865282058716" quat="0.03663774952292442 -0.7061269879341125 -0.03648395836353302 0.7061948776245117" diaginertia="8.458228876406793e-06 3.231431037420407e-05 3.509830276016146e-05"/>
												<geom name="right_arm1_link_geom_collision_0_lr33_J2_HUELLE_A1_collision" type="mesh" pos="0.0 0.0 0.0" quat="1.0 0.0 0.0 0.0" mesh="lr33_J2_HUELLE_A1_collision_0_0010000000474974513_0_0010000000474974513_0_0010000000474974513" class="rollin-justin_collision"/>
												<joint name="right_arm1" type="hinge" pos="-1.511610762505288e-16 -2.220446049250313e-16 -7.124823591529958e-17" range="-2.96705961227417 2.96705961227417" axis="0.0 0.0 1.0"/>
												<body name="right_arm2_link" pos="2.220446049250313e-16 -1.3877787807814457e-17 0.0" quat="0.7071067690849304 0.7071067690849304 -1.962615539765984e-17 1.962615539765984e-17">
													<inertial mass="3.1030354499816895" pos="0.06202683970332146 -0.32687610387802124 1.5373198986053467" quat="-0.4756825566291809 -0.5231101512908936 0.47559916973114014 0.5233424305915833" diaginertia="8.657331818540115e-06 3.998390457127243e-05 4.301390072214417e-05"/>
													<geom name="right_arm2_link_geom_collision_0_lr33_J3_HUELLE_A2_collision" type="mesh" pos="0.0 0.0 0.0" quat="1.0 0.0 0.0 0.0" mesh="lr33_J3_HUELLE_A2_collision_0_0010000000474974513_0_0010000000474974513_0_0010000000474974513" class="rollin-justin_collision"/>
													<joint name="right_arm2" type="hinge" pos="-6.938893490316922e-18 -2.220446049250313e-16 -1.2018517401366765e-17" range="-2.094395160675049 2.094395160675049" axis="0.0 0.0 1.0"/>
													<body name="right_arm3_link" pos="0.0 0.4000000059604645 4.163336342344337e-17" quat="-0.5 0.5 0.5 0.5">
														<inertial mass="3.0793471336364746" pos="0.08800598978996277 -0.5535213947296143 1.6401653289794922" quat="0.03663774952292442 -0.7061269879341125 -0.03648395836353302 0.7061948776245117" diaginertia="8.458228876406793e-06 3.231431037420407e-05 3.509830276016146e-05"/>
														<geom name="right_arm3_link_geom_collision_0_lr33_J4_HUELLE_A3_collision" type="mesh" pos="0.0 0.0 0.0" quat="1.0 0.0 0.0 0.0" mesh="lr33_J4_HUELLE_A3_collision_0_0010000000474974513_0_0010000000474974513_0_0010000000474974513" class="rollin-justin_collision"/>
														<joint name="right_arm3" type="hinge" pos="1.2586638280957986e-16 1.8372602553132884e-16 -2.5541210838515554e-25" range="-2.96705961227417 2.96705961227417" axis="0.0 0.0 1.0"/>
														<body name="right_arm4_link" pos="0.0 0.0 0.0" quat="0.7071067690849304 0.7071067690849304 -5.84905010392065e-25 -0.0">
															<inertial mass="3.1030354499816895" pos="0.08798865973949432 -0.6602939367294312 1.759823203086853" quat="-0.4756825566291809 -0.5231101512908936 0.47559916973114014 0.5233424305915833" diaginertia="8.657331818540115e-06 3.998390457127243e-05 4.301390072214417e-05"/>
															<geom name="right_arm4_link_geom_collision_0_lr33_J5_HUELLE_A4_collision" type="mesh" pos="0.0 0.0 0.0" quat="1.0 0.0 0.0 0.0" mesh="lr33_J5_HUELLE_A4_collision_0_0010000000474974513_0_0010000000474974513_0_0010000000474974513" class="rollin-justin_collision"/>
															<joint name="right_arm4" type="hinge" pos="0.0 0.0 -0.0" range="-2.094395160675049 2.094395160675049" axis="0.0 0.0 1.0"/>
															<body name="right_arm5_link" pos="1.3877787807814457e-17 0.38999998569488525 2.220446049250313e-16" quat="-4.329780301713277e-17 -4.329780301713277e-17 0.7071067690849304 0.7071067690849304">
																<inertial mass="1.9394371509552002" pos="0.08799886703491211 -0.8520902991294861 1.8679139614105225" quat="0.7061198949813843 0.037408266216516495 -0.7061140537261963 -0.037393778562545776" diaginertia="4.423010523169069e-06 2.3651036826777272e-05 2.4864039005478844e-05"/>
																<geom name="right_arm5_link_geom_collision_0_lr33_J6_HUELLE_A5_collision" type="mesh" pos="0.0 0.0 0.0" quat="1.0 0.0 0.0 0.0" mesh="lr33_J6_HUELLE_A5_collision_0_0010000000474974513_0_0010000000474974513_0_0010000000474974513" class="rollin-justin_collision"/>
																<joint name="right_arm5" type="hinge" pos="1.3877785326272619e-17 -1.8328984326816227e-16 -9.542264887416591e-17" range="-2.96705961227417 2.96705961227417" axis="0.0 0.0 1.0"/>
																<body name="right_arm6_link" pos="0.0 0.0 2.220446049250313e-16" quat="0.5 0.5 -0.5 0.5">
																	<inertial mass="1.3900792598724365" pos="0.08627193421125412 -0.9440687298774719 1.8841923475265503" quat="0.7110596895217896 -0.7031316161155701 -1.2602770027569932e-07 -1.3971802559353819e-07" diaginertia="2.7204289381188573e-06 2.7872731607203605e-06 2.8588538043550216e-06"/>
																	<geom name="right_arm6_link_geom_collision_0_lr33_J7_HUELLE_A6_collision" type="mesh" pos="0.0 0.0 0.0" quat="1.0 0.0 0.0 0.0" mesh="lr33_J7_HUELLE_A6_collision_0_0010000000474974513_0_0010000000474974513_0_0010000000474974513" class="rollin-justin_collision"/>
																	<joint name="right_arm6" type="hinge" pos="3.3087222529968844e-24 -1.9229625195208864e-16 -1.1102234216718506e-16" range="-0.785398006439209 1.3962599039077759" axis="0.0 0.0 1.0"/>
																	<body name="right_arm7_link" pos="2.220446049250313e-16 1.3877787807814457e-17 0.0" quat="0.7071067690849304 0.7071067690849304 1.3746048541917424e-17 -3.93297125667781e-18">
																		<inertial mass="0.6071485877037048" pos="0.12233587354421616 -0.9822996854782104 1.9157418012619019" quat="0.6888859272003174 0.6888816952705383 -0.15949572622776031 0.15949717164039612" diaginertia="1.0716194083215669e-06 2.734082045208197e-06 3.341099045428564e-06"/>
																		<geom name="right_arm7_link_geom_collision_0_lr33_J8_HUELLE_A7_collision" type="mesh" pos="0.0 0.0 0.0" quat="1.0 0.0 0.0 0.0" mesh="lr33_J8_HUELLE_A7_collision_0_0010000000474974513_0_0010000000474974513_0_0010000000474974513" class="rollin-justin_collision"/>
																		<joint name="right_arm7" type="hinge" pos="1.2018514092644315e-17 2.220446049250313e-16 6.938898866990904e-18" range="-0.785398006439209 2.3561899662017822" axis="0.0 0.0 1.0"/>
																		<body name="rightarm7" pos="2.220446049250313e-16 0.0 0.0" quat="0.7071067690849304 -0.0 -5.84905010392065e-25 -0.7071067690849304">
																			<body name="right_arm" pos="0.0 0.11309999972581863 -1.3877787807814457e-17" quat="5.887846453861829e-17 -3.925231079531968e-17 -0.7071067690849304 0.7071067690849304"/>
																			<body name="right_arm_palm_link" pos="0.0 -2.220446049250313e-16 0.0" quat="0.7071067690849304 -5.84905010392065e-25 -0.0 0.7071067690849304">
																				<body name="right_hand_base_link" pos="0.10109999775886536 -2.220446049250313e-16 -2.7755575615628914e-17" quat="0.5 0.5 0.5 0.5">
																					<inertial mass="1.6466705799102783" pos="0.17472366988658905 -0.006593599915504456 0.00039287409163080156" quat="-0.6290421485900879 0.18150116503238678 0.7209003567695618 0.22730153799057007" diaginertia="3.6148605886410223e-06 1.2554863133118488e-05 1.3876930097467266e-05"/>
																					<geom name="right_hand_base_link_geom_collision_0_hand2_export_Base_SWA_collision" type="mesh" pos="0.0 0.0 0.0" quat="1.0 0.0 0.0 0.0" mesh="hand2_export_Base_SWA_collision_0_0010000000474974513_0_0010000000474974513_0_0010000000474974513" class="rollin-justin_collision"/>
																					<body name="right_2index_add" pos="-0.04822095111012459 0.02358194999396801 0.1388426423072815" quat="0.990906834602356 0.05092969164252281 -0.10476531833410263 0.06733562797307968">
																						<inertial mass="0.008686601184308529" pos="0.1095750629901886 -1.123643398284912 2.0526909828186035" quat="-0.4978440999984741 -0.5015620589256287 0.5021505355834961 0.4984291195869446" diaginertia="4.347223137024514e-10 7.927880574243318e-10 7.929277789919809e-10"/>
																						<geom name="right_2index_add_geom_collision_0_hand2_export_ZF_MP_AB1_collision" type="mesh" pos="0.0 0.0 0.0" quat="1.0 0.0 0.0 0.0" mesh="hand2_export_ZF_MP_AB1_collision_0_0010000000474974513_0_0010000000474974513_0_0010000000474974513" class="rollin-justin_collision"/>
																						<joint name="right_2index1" type="hinge" pos="1.2191988425475466e-16 -7.632783294297951e-17 -6.638433450414897e-17" range="-0.5235987901687622 0.5235987901687622" axis="1.0 0.0 0.0"/>
																						<body name="right_2index_prox" pos="1.1102230246251565e-16 -5.551115123125783e-17 4.440892098500626e-16" quat="1.0 1.3877787807814457e-17 2.7755575615628914e-17 1.0408340855860843e-17">
																							<inertial mass="0.05077756196260452" pos="0.10631357133388519 -1.153477430343628 2.0830869674682617" quat="0.5396631956100464 0.4863145053386688 0.5110192894935608 -0.4594791531562805" diaginertia="8.340645507587396e-09 1.0747631051799544e-07 1.0754273915836166e-07"/>
																							<geom name="right_2index_prox_geom_collision_0_hand2_export_ZF_MP_AB2_collision" type="mesh" pos="0.0 0.0 0.0" quat="1.0 0.0 0.0 0.0" mesh="hand2_export_ZF_MP_AB2_collision_0_0010000000474974513_0_0010000000474974513_0_0010000000474974513" class="rollin-justin_collision"/>
																							<joint name="right_2index2" type="hinge" pos="2.7420094981979047e-16 -1.8431906770841505e-16 -3.216566324342027e-16" range="-0.5235987901687622 1.5707963705062866" axis="0.0 1.0 0.0"/>
																							<body name="right_2index_middle" pos="-2.654909621924162e-06 -6.4521373133175075e-06 0.07549382746219635" quat="1.0 3.469446951953614e-18 2.7755575615628914e-17 3.469446951953614e-18">
																								<inertial mass="0.04571806639432907" pos="0.10114210844039917 -1.192001223564148 2.1145780086517334" quat="-0.7036200761795044 0.006517668254673481 0.7105464339256287 0.0002888062736019492" diaginertia="5.547038384179359e-09 2.9422251301980396e-08 2.990661940316386e-08"/>
																								<geom name="right_2index_middle_geom_collision_0_hand2_export_ZF_PIP_collision" type="mesh" pos="0.0 0.0 0.0" quat="1.0 0.0 0.0 0.0" mesh="hand2_export_ZF_PIP_collision_0_0010000000474974513_0_0010000000474974513_0_0010000000474974513" class="rollin-justin_collision"/>
																								<joint name="right_2index3" type="hinge" pos="1.1689316722927401e-16 -7.169135987816668e-17 -1.8844201381406516e-16" range="-0.5235987901687622 1.5707963705062866" axis="0.0 1.0 0.0"/>
																								<body name="right_2index_distal" pos="-1.1598298215176328e-06 2.644729875100893e-06 0.04000259190797806" quat="1.0 3.469446951953614e-18 2.7755575615628914e-17 3.469446951953614e-18">
																									<inertial mass="0.02205861546099186" pos="0.09609804302453995 -1.2226831912994385 2.139216184616089" quat="0.6639753580093384 -0.01907583698630333 0.7471897006034851 0.02191898040473461" diaginertia="1.7431386334365584e-09 1.0592434485090507e-08 1.0973617570186889e-08"/>
																									<geom name="right_2index_distal_geom_collision_0_hand2_export_ZF_DIP_collision" type="mesh" pos="0.0 0.0 0.0" quat="1.0 0.0 0.0 0.0" mesh="hand2_export_ZF_DIP_collision_0_0010000000474974513_0_0010000000474974513_0_0010000000474974513" class="rollin-justin_collision"/>
																									<joint name="right_2index4" type="hinge" pos="-4.4175764578362675e-16 -7.534414314108655e-17 3.807272013982803e-16" range="-0.5235987901687622 1.5707963705062866" axis="0.0 1.0 0.0"/>
																								</body>
																							</body>
																						</body>
																					</body>
																					<body name="right_3middle_add" pos="-0.04691247642040253 -0.01625622995197773 0.13329803943634033" quat="0.990906834602356 0.05092969164252281 -0.10476531833410263 0.06733562797307968">
																						<inertial mass="0.008686601184308529" pos="0.06973688304424286 -1.1194958686828613 2.048785448074341" quat="-0.4978441894054413 -0.5015619993209839 0.5021504759788513 0.49842920899391174" diaginertia="4.347223137024514e-10 7.927880574243318e-10 7.929277789919809e-10"/>
																						<geom name="right_3middle_add_geom_collision_0_hand2_export_MF_MP_AB1_collision" type="mesh" pos="0.0 0.0 0.0" quat="1.0 0.0 0.0 0.0" mesh="hand2_export_MF_MP_AB1_collision_0_0010000000474974513_0_0010000000474974513_0_0010000000474974513" class="rollin-justin_collision"/>
																						<joint name="right_3middle1" type="hinge" pos="7.731526160124121e-17 2.7755575615628914e-16 -3.261949026166932e-17" range="-0.5235987901687622 0.5235987901687622" axis="1.0 0.0 0.0"/>
																						<body name="right_3middle_prox" pos="0.0 5.551115123125783e-17 0.0" quat="1.0 6.938893903907228e-18 2.407412430484045e-35 1.734723475976807e-17">
																							<inertial mass="0.08720586448907852" pos="0.06784985214471817 -1.145501971244812 2.0741422176361084" quat="0.004220562521368265 0.6978588104248047 -0.0024516305420547724 0.7162187099456787" diaginertia="1.3704871903996718e-08 1.7591479206657823e-07 1.7702387822282617e-07"/>
																							<geom name="right_3middle_prox_geom_collision_0_hand2_export_MF_MP_AB2_collision" type="mesh" pos="0.0 0.0 0.0" quat="1.0 0.0 0.0 0.0" mesh="hand2_export_MF_MP_AB2_collision_0_0010000000474974513_0_0010000000474974513_0_0010000000474974513" class="rollin-justin_collision"/>
																							<joint name="right_3middle2" type="hinge" pos="3.720573691968793e-17 1.7391606795776947e-19 4.1196976019484895e-17" range="-0.5235987901687622 1.5707963705062866" axis="0.0 1.0 0.0"/>
																							<body name="right_3middle_middle" pos="-4.313829322200036e-06 3.3959411211981205e-06 0.07549331337213516" quat="1.0 -3.469446951953614e-18 0.0 3.469446951953614e-18">
																								<inertial mass="0.04571806639432907" pos="0.06131349503993988 -1.1878522634506226 2.110675096511841" quat="-0.7036200761795044 0.006517668254673481 0.7105464339256287 0.0002888062736019492" diaginertia="5.547038384179359e-09 2.9422251301980396e-08 2.990661940316386e-08"/>
																								<geom name="right_3middle_middle_geom_collision_0_hand2_export_MF_PIP_collision" type="mesh" pos="0.0 0.0 0.0" quat="1.0 0.0 0.0 0.0" mesh="hand2_export_MF_PIP_collision_0_0010000000474974513_0_0010000000474974513_0_0010000000474974513" class="rollin-justin_collision"/>
																								<joint name="right_3middle3" type="hinge" pos="-2.288317740522616e-16 1.2444369005863153e-17 1.6352570587252246e-16" range="-0.5235987901687622 1.5707963705062866" axis="0.0 1.0 0.0"/>
																								<body name="right_3middle_distal" pos="-1.1598298215176328e-06 2.644729875100893e-06 0.04000259190797806" quat="1.0 -6.938893903907228e-18 -0.0 3.469446951953614e-18">
																									<inertial mass="0.02205861546099186" pos="0.05626942589879036 -1.218534231185913 2.135313034057617" quat="0.6639753580093384 -0.01907583698630333 0.7471897006034851 0.02191898040473461" diaginertia="1.7431386334365584e-09 1.0592434485090507e-08 1.0973617570186889e-08"/>
																									<geom name="right_3middle_distal_geom_collision_0_hand2_export_MF_DIP_collision" type="mesh" pos="0.0 0.0 0.0" quat="1.0 0.0 0.0 0.0" mesh="hand2_export_MF_DIP_collision_0_0010000000474974513_0_0010000000474974513_0_0010000000474974513" class="rollin-justin_collision"/>
																									<joint name="right_3middle4" type="hinge" pos="-1.1964403907438036e-16 -1.420183084969843e-16 2.9664635677507397e-17" range="-0.5235987901687622 1.5707963705062866" axis="0.0 1.0 0.0"/>
																								</body>
																							</body>
																						</body>
																					</body>
																					<body name="right_4ring_add" pos="-0.037444453686475754 -0.06233131140470505 0.12780100107192993" quat="0.989348292350769 0.02939184568822384 -0.0807262659072876 0.11751319468021393">
																						<inertial mass="0.008686601184308529" pos="0.023692330345511436 -1.1196482181549072 2.037721872329712" quat="-0.4978434145450592 -0.501562774181366 0.5021511912345886 0.49842843413352966" diaginertia="4.347223137024514e-10 7.927880574243318e-10 7.929277789919809e-10"/>
																						<geom name="right_4ring_add_geom_collision_0_hand2_export_RF_MP_AB1_collision" type="mesh" pos="0.0 0.0 0.0" quat="1.0 0.0 0.0 0.0" mesh="hand2_export_RF_MP_AB1_collision_0_0010000000474974513_0_0010000000474974513_0_0010000000474974513" class="rollin-justin_collision"/>
																						<joint name="right_4ring1" type="hinge" pos="2.403702950877761e-16 -2.7755572306906463e-17 -1.3877793101770377e-16" range="-0.5235987901687622 0.5235987901687622" axis="1.0 0.0 0.0"/>
																						<body name="right_4ring_prox" pos="1.1102230246251565e-16 0.0 0.0" quat="1.0 0.0 1.0408340855860843e-17 1.0408340855860843e-17">
																							<inertial mass="0.08720586448907852" pos="0.02299962192773819 -1.1467567682266235 2.061959981918335" quat="0.004220562521368265 0.6978588104248047 -0.0024516305420547724 0.7162187099456787" diaginertia="1.3704871903996718e-08 1.7591479206657823e-07 1.7702387822282617e-07"/>
																							<geom name="right_4ring_prox_geom_collision_0_hand2_export_RF_MP_AB2_collision" type="mesh" pos="0.0 0.0 0.0" quat="1.0 0.0 0.0 0.0" mesh="hand2_export_RF_MP_AB2_collision_0_0010000000474974513_0_0010000000474974513_0_0010000000474974513" class="rollin-justin_collision"/>
																							<joint name="right_4ring2" type="hinge" pos="-2.52883903246813e-17 -1.0776419023090199e-16 8.563187940927594e-18" range="-0.5235987901687622 1.5707963705062866" axis="0.0 1.0 0.0"/>
																							<body name="right_4ring_middle" pos="4.239479949319502e-06 -4.270954832463758e-06 0.07550221681594849" quat="1.0 0.0 1.0408340855860843e-17 1.0408340855860843e-17">
																								<inertial mass="0.04571806639432907" pos="0.0186826903373003 -1.1910486221313477 2.0964787006378174" quat="-0.7036200761795044 0.006517668254673481 0.7105464339256287 0.0002888062736019492" diaginertia="5.547038384179359e-09 2.9422251301980396e-08 2.990661940316386e-08"/>
																								<geom name="right_4ring_middle_geom_collision_0_hand2_export_RF_PIP_collision" type="mesh" pos="0.0 0.0 0.0" quat="1.0 0.0 0.0 0.0" mesh="hand2_export_RF_PIP_collision_0_0010000000474974513_0_0010000000474974513_0_0010000000474974513" class="rollin-justin_collision"/>
																								<joint name="right_4ring3" type="hinge" pos="4.966209756289126e-16 1.2544397806669598e-16 -3.1720571252439776e-16" range="-0.5235987901687622 1.5707963705062866" axis="0.0 1.0 0.0"/>
																								<body name="right_4ring_distal" pos="-9.464939694225905e-07 3.012420165759977e-06 0.03999772667884827" quat="1.0 0.0 1.0408340855860843e-17 1.0408340855860843e-17">
																									<inertial mass="0.02205861546099186" pos="0.015353222377598286 -1.2230770587921143 2.119642496109009" quat="0.6639753580093384 -0.01907583698630333 0.7471897006034851 0.02191898040473461" diaginertia="1.7431386334365584e-09 1.0592434485090507e-08 1.0973617570186889e-08"/>
																									<geom name="right_4ring_distal_geom_collision_0_hand2_export_RF_DIP_collision" type="mesh" pos="0.0 0.0 0.0" quat="1.0 0.0 0.0 0.0" mesh="hand2_export_RF_DIP_collision_0_0010000000474974513_0_0010000000474974513_0_0010000000474974513" class="rollin-justin_collision"/>
																									<joint name="right_4ring4" type="hinge" pos="2.722674647687845e-16 -2.610606365414589e-16 -2.2429644201530687e-16" range="-0.5235987901687622 1.5707963705062866" axis="0.0 1.0 0.0"/>
																								</body>
																							</body>
																						</body>
																					</body>
																					<body name="right_1thumb_add" pos="0.050334978848695755 0.046195030212402344 0.1009046882390976" quat="-0.11157138645648956 0.28528428077697754 -0.018463127315044403 0.9517477750778198">
																						<inertial mass="0.008686601184308529" pos="0.1361790895462036 -1.1400424242019653 1.9491658210754395" quat="-0.49784401059150696 -0.5015621185302734 0.5021505951881409 0.4984290599822998" diaginertia="4.347223137024514e-10 7.927880574243318e-10 7.929277789919809e-10"/>
																						<geom name="right_1thumb_add_geom_collision_0_hand2_export_D_MP_AB1_collision" type="mesh" pos="0.0 0.0 0.0" quat="1.0 0.0 0.0 0.0" mesh="hand2_export_D_MP_AB1_collision_0_0010000000474974513_0_0010000000474974513_0_0010000000474974513" class="rollin-justin_collision"/>
																						<joint name="right_1thumb1" type="hinge" pos="7.55805447427093e-17 -1.0408340855860843e-16 -3.562412126637224e-17" range="-0.5235987901687622 0.5235987901687622" axis="1.0 0.0 0.0"/>
																						<body name="right_1thumb_prox" pos="2.220446049250313e-16 0.0 2.220446049250313e-16" quat="1.0 2.168404344971009e-18 1.734723475976807e-18 6.938893903907228e-18">
																							<inertial mass="0.05077756196260452" pos="0.1360437572002411 -1.1824158430099487 1.9437721967697144" quat="0.5396631956100464 0.4863145053386688 0.5110192894935608 -0.4594791531562805" diaginertia="8.340645507587396e-09 1.0747631051799544e-07 1.0754273915836166e-07"/>
																							<geom name="right_1thumb_prox_geom_collision_0_hand2_export_D_MP_AB2_collision" type="mesh" pos="0.0 0.0 0.0" quat="1.0 0.0 0.0 0.0" mesh="hand2_export_D_MP_AB2_collision_0_0010000000474974513_0_0010000000474974513_0_0010000000474974513" class="rollin-justin_collision"/>
																							<joint name="right_1thumb2" type="hinge" pos="-1.6654379014270794e-16 2.661478105435498e-16 6.009697933588648e-18" range="-0.5235987901687622 1.5707963705062866" axis="0.0 1.0 0.0"/>
																							<body name="right_1thumb_middle" pos="-2.7737087293644436e-06 8.763641972109326e-07 0.07549897581338882" quat="1.0 9.107298248878237e-18 1.734723475976807e-18 6.938893903907228e-18">
																								<inertial mass="0.04571806639432907" pos="0.1366734504699707 -1.2324362993240356 1.942999005317688" quat="-0.7036200761795044 0.006517668254673481 0.7105464339256287 0.0002888062736019492" diaginertia="5.547038384179359e-09 2.9422251301980396e-08 2.990661940316386e-08"/>
																								<geom name="right_1thumb_middle_geom_collision_0_hand2_export_D_PIP_collision" type="mesh" pos="0.0 0.0 0.0" quat="1.0 0.0 0.0 0.0" mesh="hand2_export_D_PIP_collision_0_0010000000474974513_0_0010000000474974513_0_0010000000474974513" class="rollin-justin_collision"/>
																								<joint name="right_1thumb3" type="hinge" pos="-1.9887475980671877e-16 -6.003975994419374e-17 6.759969360738027e-18" range="-0.5235987901687622 1.5707963705062866" axis="0.0 1.0 0.0"/>
																								<body name="right_1thumb_distal" pos="2.6136007136301487e-08 1.941551772688399e-06 0.03999917954206467" quat="1.0 1.3877787807814457e-17 1.734723475976807e-18 6.938893903907228e-18">
																									<inertial mass="0.02205861546099186" pos="0.13808998465538025 -1.2720791101455688 1.9428226947784424" quat="0.6639753580093384 -0.01907583698630333 0.7471897006034851 0.02191898040473461" diaginertia="1.7431386334365584e-09 1.0592434485090507e-08 1.0973617570186889e-08"/>
																									<geom name="right_1thumb_distal_geom_collision_0_hand2_export_D_DIP_collision" type="mesh" pos="0.0 0.0 0.0" quat="1.0 0.0 0.0 0.0" mesh="hand2_export_D_DIP_collision_0_0010000000474974513_0_0010000000474974513_0_0010000000474974513" class="rollin-justin_collision"/>
																									<joint name="right_1thumb4" type="hinge" pos="2.525044920434472e-16 -5.5243925571288896e-17 2.3796667697254197e-17" range="-0.5235987901687622 1.5707963705062866" axis="0.0 1.0 0.0"/>
																								</body>
																							</body>
																						</body>
																					</body>
																				</body>
																			</body>
																		</body>
																	</body>
																</body>
															</body>
														</body>
													</body>
												</body>
											</body>
										</body>
										<body name="head_base_link" pos="0.135685995221138 0.08799970149993896 -1.232595164407831e-32" quat="0.5 -0.5 0.5 0.5">
											<inertial mass="0.12163440883159637" pos="0.14376896619796753 0.08799944072961807 1.677055716520215e-10" quat="0.49999409914016724 0.4999966621398926 0.5000059008598328 -0.5000033378601074" diaginertia="5.6428994810175936e-08 5.643254752385474e-08 7.546869795760358e-08"/>
											<geom name="head_base_link_geom_collision_0_justin_rj_kopf_HALS_EINBAU_collision" type="mesh" pos="0.0 0.0 0.0" quat="1.0 0.0 0.0 0.0" mesh="justin_rj_kopf_HALS_EINBAU_collision_0_0010000000474974513_0_0010000000474974513_0_0010000000474974513" class="rollin-justin_collision"/>
											<body name="head1_link" pos="1.8368364410546407e-18 -0.029997816309332848 4.8436013457830995e-06" quat="1.0 0.0 -3.54876954373769e-32 0.0">
												<inertial mass="0.6304671764373779" pos="0.08798184245824814 -5.661715363203257e-07 1.5029081106185913" quat="0.7071075439453125 6.212377775227651e-05 0.00016525035607628524 0.7071059942245483" diaginertia="5.102347131469287e-07 1.603636974323308e-06 1.6319264659614419e-06"/>
												<geom name="head1_link_geom_collision_0_justin_rj_kopf_HALS_ROT_collision" type="mesh" pos="0.0 0.0 0.0" quat="1.0 0.0 0.0 0.0" mesh="justin_rj_kopf_HALS_ROT_collision_0_0010000000474974513_0_0010000000474974513_0_0010000000474974513" class="rollin-justin_collision"/>
												<joint name="head1" type="hinge" pos="8.673617379884035e-17 -1.6209669511605546e-17 -2.4154289829143205e-25" range="-0.785398006439209 0.785398006439209" axis="0.0 -1.0 0.0"/>
												<body name="head2_link" pos="4.246289074739421e-18 -0.06934716552495956 -7.17752209311584e-06" quat="0.7071067690849304 -2.229749878995289e-17 0.7071067690849304 2.229749878995289e-17">
													<inertial mass="8.385958671569824" pos="0.12665577232837677 -0.00015405705198645592 1.6853628158569336" quat="-0.6150720119476318 3.3358966902596876e-05 9.625759412301704e-05 0.7884709239006042" diaginertia="4.42802302131895e-05 0.00024724347167648375 0.0002590433869045228"/>
													<geom name="head2_link_geom_collision_0_justin_rj_kopf_HALS_KNICK_collision" type="mesh" pos="0.0 0.0 0.0" quat="1.0 0.0 0.0 0.0" mesh="justin_rj_kopf_HALS_KNICK_collision_0_0010000000474974513_0_0010000000474974513_0_0010000000474974513" class="rollin-justin_collision"/>
													<joint name="head2_joint" type="hinge" pos="-9.71445146547012e-17 -1.887189406482581e-18 -2.812125808253623e-26" range="-0.43633201718330383 0.785398006439209" axis="0.0 0.0 -1.0"/>
													<body name="head_realsense" pos="-0.128260999917984 -0.23263899981975555 -0.017500000074505806" quat="0.7010575532913208 -0.09229481965303421 -0.7010575532913208 -0.09229481965303421"/>
													<body name="head2" pos="0.0 0.0 2.0679515313825692e-25" quat="-4.084453421281075e-17 9.236319233846298e-17 -0.7071067690849304 0.7071067690849304"/>
												</body>
											</body>
										</body>
										<body name="left_base_link" pos="0.03500000014901161 0.08799999952316284 -0.012662800028920174" quat="0.9659258127212524 -2.6466832770764665e-18 0.2588191330432892 -9.877552291675366e-18">
											<inertial mass="0.9763923287391663" pos="0.07900676131248474 0.08740251511335373 0.06359962373971939" quat="0.706705629825592 -0.02453411929309368 -0.7065299153327942 -0.027941126376390457" diaginertia="1.359836574010842e-06 9.149946890829597e-06 9.160901754512452e-06"/>
											<geom name="left_base_link_geom_collision_0_lr33_J1_Base_frame_collision" type="mesh" pos="0.0 0.0 0.0" quat="1.0 0.0 0.0 0.0" mesh="lr33_J1_Base_frame_collision_0_0010000000474974513_0_0010000000474974513_0_0010000000474974513" class="rollin-justin_collision"/>
											<body name="left_arm1_link" pos="-2.220446049250313e-16 -2.7755575615628914e-17 0.3100000023841858" quat="1.0 -6.162975822039155e-33 -1.3877787807814457e-17 -4.1359030627651384e-25">
												<inertial mass="3.0793471336364746" pos="0.11226725578308105 0.19498062133789062 1.4611761569976807" quat="0.03663774952292442 -0.7061269879341125 -0.03648395836353302 0.7061948776245117" diaginertia="8.458228876406793e-06 3.231431037420407e-05 3.509830276016146e-05"/>
												<geom name="left_arm1_link_geom_collision_0_lr33_J2_HUELLE_A1_collision" type="mesh" pos="0.0 0.0 0.0" quat="1.0 0.0 0.0 0.0" mesh="lr33_J2_HUELLE_A1_collision_0_0010000000474974513_0_0010000000474974513_0_0010000000474974513" class="rollin-justin_collision"/>
												<joint name="left_arm1" type="hinge" pos="3.4196271871485254e-17 2.220446049250313e-16 5.1792617035807345e-17" range="-2.96705961227417 2.96705961227417" axis="0.0 0.0 -1.0"/>
												<body name="left_arm2_link" pos="-2.220446049250313e-16 -1.3877787807814457e-17 -1.1102230246251565e-16" quat="0.7071067690849304 0.7071067690849304 -2.4532688043220205e-18 6.869154637335128e-17">
													<inertial mass="3.1030354499816895" pos="0.06202683970332146 0.32686474919319153 1.5373395681381226" quat="-0.4756825566291809 -0.5231101512908936 0.47559916973114014 0.5233424305915833" diaginertia="8.657331818540115e-06 3.998390457127243e-05 4.301390072214417e-05"/>
													<geom name="left_arm2_link_geom_collision_0_lr33_J3_HUELLE_A2_collision" type="mesh" pos="0.0 0.0 0.0" quat="1.0 0.0 0.0 0.0" mesh="lr33_J3_HUELLE_A2_collision_0_0010000000474974513_0_0010000000474974513_0_0010000000474974513" class="rollin-justin_collision"/>
													<joint name="left_arm2" type="hinge" pos="8.92092320721371e-17 2.220446049250313e-16 6.752968848495929e-17" range="-2.094395160675049 2.094395160675049" axis="0.0 0.0 -1.0"/>
													<body name="left_arm3_link" pos="0.0 0.4000000059604645 2.7755575615628914e-17" quat="0.5 -0.5 0.5 0.5">
														<inertial mass="3.0793471336364746" pos="0.0879940390586853 0.5535213947296143 1.6401653289794922" quat="0.03663774952292442 -0.7061269879341125 -0.03648395836353302 0.7061948776245117" diaginertia="8.458228876406793e-06 3.231431037420407e-05 3.509830276016146e-05"/>
														<geom name="left_arm3_link_geom_collision_0_lr33_J4_HUELLE_A3_collision" type="mesh" pos="0.0 0.0 0.0" quat="1.0 0.0 0.0 0.0" mesh="lr33_J4_HUELLE_A3_collision_0_0010000000474974513_0_0010000000474974513_0_0010000000474974513" class="rollin-justin_collision"/>
														<joint name="left_arm3" type="hinge" pos="-1.1384857347481744e-16 1.9066452238854204e-16 -4.8629281198542696e-26" range="-2.96705961227417 2.96705961227417" axis="0.0 0.0 -1.0"/>
														<body name="left_arm4_link" pos="-1.3877787807814457e-17 -2.220446049250313e-16 -2.220446049250313e-16" quat="0.7071067690849304 0.7071067690849304 -5.84905010392065e-25 0.0">
															<inertial mass="3.1030354499816895" pos="0.08801136910915375 0.6602939367294312 1.759823203086853" quat="-0.4756825566291809 -0.5231101512908936 0.47559916973114014 0.5233424305915833" diaginertia="8.657331818540115e-06 3.998390457127243e-05 4.301390072214417e-05"/>
															<geom name="left_arm4_link_geom_collision_0_lr33_J5_HUELLE_A4_collision" type="mesh" pos="0.0 0.0 0.0" quat="1.0 0.0 0.0 0.0" mesh="lr33_J5_HUELLE_A4_collision_0_0010000000474974513_0_0010000000474974513_0_0010000000474974513" class="rollin-justin_collision"/>
															<joint name="left_arm4" type="hinge" pos="1.3877784499092007e-17 -8.127390316745869e-17 3.033185808843839e-16" range="-2.094395160675049 2.094395160675049" axis="0.0 0.0 -1.0"/>
															<body name="left_arm5_link" pos="1.3877787807814457e-17 0.38999998569488525 -2.220446049250313e-16" quat="-9.236319233846298e-17 -4.084453421281075e-17 0.7071067690849304 0.7071067690849304">
																<inertial mass="1.9394371509552002" pos="0.08800116926431656 0.8520902991294861 1.8679139614105225" quat="0.7061198949813843 0.037408266216516495 -0.7061140537261963 -0.037393778562545776" diaginertia="4.423010523169069e-06 2.3651036826777272e-05 2.4864039005478844e-05"/>
																<geom name="left_arm5_link_geom_collision_0_lr33_J6_HUELLE_A5_collision" type="mesh" pos="0.0 0.0 0.0" quat="1.0 0.0 0.0 0.0" mesh="lr33_J6_HUELLE_A5_collision_0_0010000000474974513_0_0010000000474974513_0_0010000000474974513" class="rollin-justin_collision"/>
																<joint name="left_arm5" type="hinge" pos="-1.3877791116536907e-17 2.0717046814322938e-16 1.3678507425105122e-16" range="-2.96705961227417 2.96705961227417" axis="0.0 0.0 -1.0"/>
																<body name="left_arm6_link" pos="1.3877787807814457e-17 2.220446049250313e-16 -2.220446049250313e-16" quat="0.5 0.5 0.5 -0.5">
																	<inertial mass="1.3900792598724365" pos="0.08627193421125412 0.9440687298774719 1.8841923475265503" quat="0.7110596895217896 -0.7031316161155701 -1.2602770027569932e-07 -1.3971802559353819e-07" diaginertia="2.7204289381188573e-06 2.7872731607203605e-06 2.8588538043550216e-06"/>
																	<geom name="left_arm6_link_geom_collision_0_lr33_J7_HUELLE_A6_collision" type="mesh" pos="0.0 0.0 0.0" quat="1.0 0.0 0.0 0.0" mesh="lr33_J7_HUELLE_A6_collision_0_0010000000474974513_0_0010000000474974513_0_0010000000474974513" class="rollin-justin_collision"/>
																	<joint name="left_arm6" type="hinge" pos="1.3877791116536907e-17 3.033185808843839e-16 -8.127390316745869e-17" range="-0.785398006439209 1.3962599039077759" axis="0.0 0.0 -1.0"/>
																	<body name="left_arm7_link" pos="0.0 1.3877787807814457e-17 -2.220446049250313e-16" quat="-1.2993184978882488e-16 9.404684899214322e-17 -0.7071067690849304 0.7071067690849304">
																		<inertial mass="0.6071485877037048" pos="0.12233587354421616 0.9822994470596313 1.91574227809906" quat="0.6888859272003174 0.6888816952705383 -0.15949572622776031 0.15949717164039612" diaginertia="1.0716194083215669e-06 2.734082045208197e-06 3.341099045428564e-06"/>
																		<geom name="left_arm7_link_geom_collision_0_lr33_J8_HUELLE_A7_collision" type="mesh" pos="0.0 0.0 0.0" quat="1.0 0.0 0.0 0.0" mesh="lr33_J8_HUELLE_A7_collision_0_0010000000474974513_0_0010000000474974513_0_0010000000474974513" class="rollin-justin_collision"/>
																		<joint name="left_arm7" type="hinge" pos="-9.900382476581829e-17 3.3087222529968844e-24 -1.9923514585599587e-16" range="-0.785398006439209 2.3561899662017822" axis="0.0 0.0 -1.0"/>
																		<body name="leftarm7" pos="0.0 2.220446049250313e-16 0.0" quat="2.3671647619472932e-17 0.7071067690849304 0.7071067690849304 6.292396006915384e-17">
																			<body name="left_arm" pos="0.0 0.11309999972581863 1.3877787807814457e-17" quat="3.925231079531968e-17 -3.925231079531968e-17 -0.7071067690849304 0.7071067690849304"/>
																			<body name="left_arm_palm_link" pos="0.0 0.0 1.3877787807814457e-17" quat="4.329780301713277e-17 0.7071067690849304 0.7071067690849304 4.329780301713277e-17">
																				<body name="left_hand_base_link" pos="0.10260000079870224 0.0 -1.3877787807814457e-17" quat="0.5 -0.5 0.5 -0.5">
																					<inertial mass="1.629738688468933" pos="0.17530398070812225 0.0069930884055793285 0.0011198993306607008" quat="-0.18155482411384583 0.6266546249389648 0.22534233331680298 0.7235763072967529" diaginertia="3.530853746269713e-06 1.2227224033267703e-05 1.3497080544766504e-05"/>
																					<geom name="left_hand_base_link_geom_collision_0_hii_links_export_Base_SWA_collision" type="mesh" pos="0.0 0.0 0.0" quat="1.0 0.0 0.0 0.0" mesh="hii_links_export_Base_SWA_collision_0_0010000000474974513_0_0010000000474974513_0_0010000000474974513" class="rollin-justin_collision"/>
																					<body name="left_2index_add" pos="-0.04822095111012459 -0.02358194999396801 0.1388426423072815" quat="0.990906834602356 -0.05092969164252281 -0.10476531833410263 -0.06733562797307968">
																						<inertial mass="0.008686601184308529" pos="0.11358842998743057 1.124955177307129 2.054126024246216" quat="-0.49784401059150696 -0.5015621185302734 0.5021505951881409 0.4984290599822998" diaginertia="4.347223137024514e-10 7.927880574243318e-10 7.929277789919809e-10"/>
																						<geom name="left_2index_add_geom_collision_0_hii_links_export_ZF_MP_AB1_collision" type="mesh" pos="0.0 0.0 0.0" quat="1.0 0.0 0.0 0.0" mesh="hii_links_export_ZF_MP_AB1_collision_0_0010000000474974513_0_0010000000474974513_0_0010000000474974513" class="rollin-justin_collision"/>
																						<joint name="left_2index1" type="hinge" pos="-4.113516577539248e-17 -2.7755575615628914e-17 3.977409963444058e-17" range="-0.5235987901687622 0.5235987901687622" axis="1.0 0.0 0.0"/>
																						<body name="left_2index_prox" pos="-1.1102230246251565e-16 0.0 0.0" quat="1.0 3.851859888774472e-34 2.7755575615628914e-17 3.469446951953614e-18">
																							<inertial mass="0.05077756196260452" pos="0.1064002737402916 1.1547768115997314 2.0838515758514404" quat="0.5396631956100464 0.4863145053386688 0.5110192894935608 -0.4594791531562805" diaginertia="8.340645507587396e-09 1.0747631051799544e-07 1.0754273915836166e-07"/>
																							<geom name="left_2index_prox_geom_collision_0_hii_links_export_ZF_MP_AB2_collision" type="mesh" pos="0.0 0.0 0.0" quat="1.0 0.0 0.0 0.0" mesh="hii_links_export_ZF_MP_AB2_collision_0_0010000000474974513_0_0010000000474974513_0_0010000000474974513" class="rollin-justin_collision"/>
																							<joint name="left_2index2" type="hinge" pos="1.3630799948712248e-17 -1.0943958831334649e-16 -1.2772230313454671e-17" range="-0.5235987901687622 1.5707963705062866" axis="0.0 1.0 0.0"/>
																							<body name="left_2index_middle" pos="-2.743769300650456e-06 2.1042985736130504e-06 0.07499294728040695" quat="1.0 3.851859888774472e-34 2.7755575615628914e-17 3.469446951953614e-18">
																								<inertial mass="0.04571806639432907" pos="0.10058864951133728 1.1932978630065918 2.1152331829071045" quat="-0.7035624384880066 0.006580233573913574 0.7106029391288757 0.0003683355753310025" diaginertia="5.546830994518359e-09 3.021420269533337e-08 3.069867560157036e-08"/>
																								<geom name="left_2index_middle_geom_collision_0_hii_links_export_ZF_PIP_collision" type="mesh" pos="0.0 0.0 0.0" quat="1.0 0.0 0.0 0.0" mesh="hii_links_export_ZF_PIP_collision_0_0010000000474974513_0_0010000000474974513_0_0010000000474974513" class="rollin-justin_collision"/>
																								<joint name="left_2index3" type="hinge" pos="1.7364882161828522e-16 -2.871394045588795e-17 -1.0907537738091694e-16" range="-0.5235987901687622 1.5707963705062866" axis="0.0 1.0 0.0"/>
																								<body name="left_2index_distal" pos="4.990901629753353e-07 7.203348559414735e-06 0.040003105998039246" quat="1.0 3.851859888774472e-34 2.7755575615628914e-17 3.469446951953614e-18">
																									<inertial mass="0.02205861546099186" pos="0.09698215126991272 1.2239857912063599 2.14011549949646" quat="0.6651047468185425 -0.018513325601816177 0.7462079524993896 0.021601757034659386" diaginertia="1.7446069033866252e-09 1.0966125785216718e-08 1.134570659644396e-08"/>
																									<geom name="left_2index_distal_geom_collision_0_hii_links_export_ZF_DIP_collision" type="mesh" pos="0.0 0.0 0.0" quat="1.0 0.0 0.0 0.0" mesh="hii_links_export_ZF_DIP_collision_0_0010000000474974513_0_0010000000474974513_0_0010000000474974513" class="rollin-justin_collision"/>
																									<joint name="left_2index4" type="hinge" pos="-1.6062765543538578e-17 1.730104499436311e-16 3.6780893648358245e-17" range="-0.5235987901687622 1.5707963705062866" axis="0.0 1.0 0.0"/>
																								</body>
																							</body>
																						</body>
																					</body>
																					<body name="left_3middle_add" pos="-0.04691247642040253 0.01625622995197773 0.13329803943634033" quat="0.990906834602356 -0.05092969164252281 -0.10476531833410263 -0.06733562797307968">
																						<inertial mass="0.008686601184308529" pos="0.07375025004148483 1.1208076477050781 2.050220489501953" quat="-0.49784421920776367 -0.5015619397163391 0.5021504163742065 0.49842923879623413" diaginertia="4.347223137024514e-10 7.927880574243318e-10 7.929277789919809e-10"/>
																						<geom name="left_3middle_add_geom_collision_0_hii_links_export_MF_MP_AB1_collision" type="mesh" pos="0.0 0.0 0.0" quat="1.0 0.0 0.0 0.0" mesh="hii_links_export_MF_MP_AB1_collision_0_0010000000474974513_0_0010000000474974513_0_0010000000474974513" class="rollin-justin_collision"/>
																						<joint name="left_3middle1" type="hinge" pos="1.2365460773073147e-16 1.457167719820518e-16 -6.337970349944605e-17" range="-0.5235987901687622 0.5235987901687622" axis="1.0 0.0 0.0"/>
																						<body name="left_3middle_prox" pos="2.220446049250313e-16 0.0 4.440892098500626e-16" quat="1.0 3.851859888774472e-34 2.7755575615628914e-17 3.469446951953614e-18">
																							<inertial mass="0.05077756196260452" pos="0.06656209379434586 1.1506292819976807 2.079946279525757" quat="0.5396631956100464 0.4863145053386688 0.5110192894935608 -0.4594791531562805" diaginertia="8.340645507587396e-09 1.0747631051799544e-07 1.0754273915836166e-07"/>
																							<geom name="left_3middle_prox_geom_collision_0_hii_links_export_MF_MP_AB2_collision" type="mesh" pos="0.0 0.0 0.0" quat="1.0 0.0 0.0 0.0" mesh="hii_links_export_MF_MP_AB2_collision_0_0010000000474974513_0_0010000000474974513_0_0010000000474974513" class="rollin-justin_collision"/>
																							<joint name="left_3middle2" type="hinge" pos="2.977758884451274e-16 2.935847429523335e-16 -2.676874252740825e-16" range="-0.5235987901687622 1.5707963705062866" axis="0.0 1.0 0.0"/>
																							<body name="left_3middle_middle" pos="-2.743769300650456e-06 2.1042985736130504e-06 0.07499294728040695" quat="1.0 3.851859888774472e-34 2.7755575615628914e-17 3.469446951953614e-18">
																								<inertial mass="0.04571806639432907" pos="0.06075046956539154 1.189150333404541 2.111327648162842" quat="-0.7035624384880066 0.006580233573913574 0.7106029391288757 0.0003683355753310025" diaginertia="5.546830994518359e-09 3.021420269533337e-08 3.069867560157036e-08"/>
																								<geom name="left_3middle_middle_geom_collision_0_hii_links_export_MF_PIP_collision" type="mesh" pos="0.0 0.0 0.0" quat="1.0 0.0 0.0 0.0" mesh="hii_links_export_MF_PIP_collision_0_0010000000474974513_0_0010000000474974513_0_0010000000474974513" class="rollin-justin_collision"/>
																								<joint name="left_3middle3" type="hinge" pos="1.110245920984512e-16 2.8808850497627795e-16 -1.187990443001554e-16" range="-0.5235987901687622 1.5707963705062866" axis="0.0 1.0 0.0"/>
																								<body name="left_3middle_distal" pos="-1.1598295941439574e-06 -2.6447296477272175e-06 0.04000259190797806" quat="1.0 3.851859888774472e-34 2.7755575615628914e-17 3.469446951953614e-18">
																									<inertial mass="0.02205861546099186" pos="0.05715353414416313 1.2198368310928345 2.1362125873565674" quat="0.6651047468185425 -0.018513325601816177 0.7462079524993896 0.021601757034659386" diaginertia="1.7446069033866252e-09 1.0966125785216718e-08 1.134570659644396e-08"/>
																									<geom name="left_3middle_distal_geom_collision_0_hii_links_export_MF_DIP_collision" type="mesh" pos="0.0 0.0 0.0" quat="1.0 0.0 0.0 0.0" mesh="hii_links_export_MF_DIP_collision_0_0010000000474974513_0_0010000000474974513_0_0010000000474974513" class="rollin-justin_collision"/>
																									<joint name="left_3middle4" type="hinge" pos="2.91112068490841e-16 -1.1814841711754568e-16 -1.5928687507177613e-16" range="-0.5235987901687622 1.5707963705062866" axis="0.0 1.0 0.0"/>
																								</body>
																							</body>
																						</body>
																					</body>
																					<body name="left_4ring_add" pos="-0.037444453686475754 0.06233131140470505 0.12780100107192993" quat="0.989348292350769 -0.029391737654805183 -0.08072628080844879 -0.11751299351453781">
																						<inertial mass="0.008686601184308529" pos="0.027644257992506027 1.1206023693084717 2.0393881797790527" quat="-0.49784407019615173 -0.5015620589256287 0.5021505355834961 0.4984291195869446" diaginertia="4.347223137024514e-10 7.927880574243318e-10 7.929277789919809e-10"/>
																						<geom name="left_4ring_add_geom_collision_0_hii_links_export_RF_MP_AB1_collision" type="mesh" pos="0.0 0.0 0.0" quat="1.0 0.0 0.0 0.0" mesh="hii_links_export_RF_MP_AB1_collision_0_0010000000474974513_0_0010000000474974513_0_0010000000474974513" class="rollin-justin_collision"/>
																						<joint name="left_4ring1" type="hinge" pos="-1.9229623871719884e-16 2.0816681711721685e-16 1.1102234216718506e-16" range="-0.5235987901687622 0.5235987901687622" axis="1.0 0.0 0.0"/>
																						<body name="left_4ring_prox" pos="-1.1102230246251565e-16 0.0 0.0" quat="1.0 -1.3877787807814457e-17 -1.3877787807814457e-17 6.938893903907228e-18">
																							<inertial mass="0.05077756196260452" pos="0.021822253242135048 1.1521989107131958 2.067537307739258" quat="0.5396631956100464 0.4863145053386688 0.5110192894935608 -0.4594791531562805" diaginertia="8.340645507587396e-09 1.0747631051799544e-07 1.0754273915836166e-07"/>
																							<geom name="left_4ring_prox_geom_collision_0_hii_links_export_RF_MP_AB2_collision" type="mesh" pos="0.0 0.0 0.0" quat="1.0 0.0 0.0 0.0" mesh="hii_links_export_RF_MP_AB2_collision_0_0010000000474974513_0_0010000000474974513_0_0010000000474974513" class="rollin-justin_collision"/>
																							<joint name="left_4ring2" type="hinge" pos="2.5288347311289448e-17 -1.0776420346579179e-16 -8.56316064396738e-18" range="-0.5235987901687622 1.5707963705062866" axis="0.0 1.0 0.0"/>
																							<body name="left_4ring_middle" pos="-2.127009565811022e-06 -6.785803066122753e-07 0.07499859482049942" quat="1.0 -1.3877787807814457e-17 -1.3877787807814457e-17 6.938893903907228e-18">
																								<inertial mass="0.04571806639432907" pos="0.018137047067284584 1.1923882961273193 2.097104787826538" quat="-0.7035624384880066 0.006580233573913574 0.7106029391288757 0.0003683355753310025" diaginertia="5.546830994518359e-09 3.021420269533337e-08 3.069867560157036e-08"/>
																								<geom name="left_4ring_middle_geom_collision_0_hii_links_export_RF_PIP_collision" type="mesh" pos="0.0 0.0 0.0" quat="1.0 0.0 0.0 0.0" mesh="hii_links_export_RF_PIP_collision_0_0010000000474974513_0_0010000000474974513_0_0010000000474974513" class="rollin-justin_collision"/>
																								<joint name="left_4ring3" type="hinge" pos="-5.53361785434651e-18 -1.0536581147766776e-17 -1.041308969975751e-17" range="-0.5235987901687622 1.5707963705062866" axis="0.0 1.0 0.0"/>
																								<body name="left_4ring_distal" pos="7.282319984369678e-06 6.307909188763006e-06 0.04000448063015938" quat="1.0 -1.3877787807814457e-17 -1.3877787807814457e-17 6.938893903907228e-18">
																									<inertial mass="0.02205861546099186" pos="0.016224874183535576 1.2243036031723022 2.1205949783325195" quat="0.6651047468185425 -0.018513325601816177 0.7462079524993896 0.021601757034659386" diaginertia="1.7446069033866252e-09 1.0966125785216718e-08 1.134570659644396e-08"/>
																									<geom name="left_4ring_distal_geom_collision_0_hii_links_export_RF_DIP_collision" type="mesh" pos="0.0 0.0 0.0" quat="1.0 0.0 0.0 0.0" mesh="hii_links_export_RF_DIP_collision_0_0010000000474974513_0_0010000000474974513_0_0010000000474974513" class="rollin-justin_collision"/>
																									<joint name="left_4ring4" type="hinge" pos="1.5835422562240014e-16 -1.3116405773395327e-16 -4.658293096755242e-17" range="-0.5235987901687622 1.5707963705062866" axis="0.0 1.0 0.0"/>
																								</body>
																							</body>
																						</body>
																					</body>
																					<body name="left_1thumb_add" pos="0.050334978848695755 -0.046195030212402344 0.1009046882390976" quat="0.11157157272100449 0.2852843105792999 0.01846318691968918 0.951747715473175">
																						<inertial mass="0.008686601184308529" pos="0.13221149146556854 1.1412975788116455 1.9490095376968384" quat="0.48452794551849365 0.5144374370574951 -0.48894718289375305 -0.5113877058029175" diaginertia="4.347223137024514e-10 7.927880574243318e-10 7.929277789919809e-10"/>
																						<geom name="left_1thumb_add_geom_collision_0_hii_links_export_D_MP_AB1_collision" type="mesh" pos="0.0 0.0 0.0" quat="1.0 0.0 0.0 0.0" mesh="hii_links_export_D_MP_AB1_collision_0_0010000000474974513_0_0010000000474974513_0_0010000000474974513" class="rollin-justin_collision"/>
																						<joint name="left_1thumb1" type="hinge" pos="-2.919138116451968e-16 -8.326672022944184e-17 1.6052425785881665e-16" range="-0.5235987901687622 0.5235987901687622" axis="1.0 0.0 0.0"/>
																						<body name="left_1thumb_prox" pos="0.0 0.0 0.0" quat="1.0 1.0842021724855044e-17 -7.703719777548943e-34 0.0">
																							<inertial mass="0.05077756568789482" pos="0.13378457725048065 1.183689832687378 1.9440062046051025" quat="0.5267485976219177 0.5002740025520325 0.5228724479675293 -0.4459441900253296" diaginertia="8.340645507587396e-09 1.074763176234228e-07 1.0754274626378901e-07"/>
																							<geom name="left_1thumb_prox_geom_collision_0_hii_links_export_D_MP_AB2_collision" type="mesh" pos="0.0 0.0 0.0" quat="1.0 0.0 0.0 0.0" mesh="hii_links_export_D_MP_AB2_collision_0_0010000000474974513_0_0010000000474974513_0_0010000000474974513" class="rollin-justin_collision"/>
																							<joint name="left_1thumb2" type="hinge" pos="0.0 0.0 0.0" range="-0.5235987901687622 1.5707963705062866" axis="0.0 1.0 0.0"/>
																							<body name="left_1thumb_middle" pos="-2.769701495708432e-06 -8.75379441822588e-07 0.07549897581338882" quat="1.0 3.0357660829594124e-18 1.734723475976807e-18 0.0">
																								<inertial mass="0.04571806639432907" pos="0.13250042498111725 1.2336891889572144 1.942795753479004" quat="-0.7028963565826416 -0.030240116640925407 0.7046186923980713 0.09238329529762268" diaginertia="5.808984848698628e-09 2.992796410694609e-08 3.06861167587158e-08"/>
																								<geom name="left_1thumb_middle_geom_collision_0_hii_links_export_D_PIP_collision" type="mesh" pos="0.0 0.0 0.0" quat="1.0 0.0 0.0 0.0" mesh="hii_links_export_D_PIP_collision_0_0010000000474974513_0_0010000000474974513_0_0010000000474974513" class="rollin-justin_collision"/>
																								<joint name="left_1thumb3" type="hinge" pos="-1.0137910367326636e-16 -3.820938361191159e-16 -7.003094369097674e-17" range="-0.5235987901687622 1.5707963705062866" axis="0.0 1.0 0.0"/>
																								<body name="left_1thumb_distal" pos="2.8259695028509668e-08 -1.941029495355906e-06 0.03999917954206467" quat="1.0 1.0408340855860843e-17 1.734723475976807e-18 0.0">
																									<inertial mass="0.02205861546099186" pos="0.13046444952487946 1.2732938528060913 1.9418308734893799" quat="0.6523569226264954 0.1368427723646164 0.7414860725402832 0.07683026790618896" diaginertia="2.078459626631002e-09 1.1298325830466638e-08 1.2019196304891011e-08"/>
																									<geom name="left_1thumb_distal_geom_collision_0_hii_links_export_D_DIP_collision" type="mesh" pos="0.0 0.0 0.0" quat="1.0 0.0 0.0 0.0" mesh="hii_links_export_D_DIP_collision_0_0010000000474974513_0_0010000000474974513_0_0010000000474974513" class="rollin-justin_collision"/>
																									<joint name="left_1thumb4" type="hinge" pos="-1.0976400193214489e-16 1.1254050314135058e-16 3.063870702323759e-17" range="-0.5235987901687622 1.5707963705062866" axis="0.0 1.0 0.0"/>
																								</body>
																							</body>
																						</body>
																					</body>
																				</body>
																			</body>
																		</body>
																	</body>
																</body>
															</body>
														</body>
													</body>
												</body>
											</body>
										</body>
									</body>
								</body>
							</body>
						</body>
					</body>
					<body name="wheel_rb_link" pos="-0.3427000045776367 0.25714001059532166 0.02889999933540821" quat="-0.2705952823162079 0.2705952823162079 -0.653282642364502 0.653282642364502">
						<inertial mass="4.602991104125977" pos="-0.33518221974372864 0.2646655738353729 0.04731134697794914" quat="-0.4864896833896637 -0.49181199073791504 0.5139126181602478 0.507289469242096" diaginertia="1.9325827452121302e-05 2.3513242922490463e-05 3.399274282855913e-05"/>
						<geom name="wheel_rb_link_geom_collision_0_mp_mobile_plattform_rj_ROT3_collision" type="mesh" pos="0.0 0.0 0.0" quat="1.0 0.0 0.0 0.0" mesh="mp_mobile_plattform_rj_ROT3_collision_0_0010000000474974513_0_0010000000474974513_0_0010000000474974513" class="rollin-justin_collision"/>
					</body>
				</body>
			</body>
		</body>
	</worldbody>
	<equality/>
</mujoco>
