<?xml version="1.0" ?>
<mujoco model="rollin-justin">
	<compiler meshdir="rollin-justin/meshes" texturedir="rollin-justin/textures" angle="radian" autolimits="true" balanceinertia="true" boundmass="0.000001" boundinertia="0.000001"/>
	<default>
		<default class="rollin-justin_visual">
			<geom contype="0" conaffinity="0"/>
		</default>
		<default class="rollin-justin_collision">
			<geom rgba="0.9 0.9 0.9 1.0"/>
		</default>
	</default>
	<asset>
		<mesh name="base" file="stl/base.stl" scale="1.0 1.0 1.0"/>
		<mesh name="torso1" file="stl/torso1.stl" scale="1.0 1.0 1.0"/>
		<mesh name="torso2" file="stl/torso2.stl" scale="1.0 1.0 1.0"/>
		<mesh name="torso3" file="stl/torso3.stl" scale="1.0 1.0 1.0"/>
		<mesh name="torso4" file="stl/torso4.stl" scale="1.0 1.0 1.0"/>
		<mesh name="head1" file="stl/head1.stl" scale="1.0 1.0 1.0"/>
		<mesh name="head2" file="stl/head2.stl" scale="1.0 1.0 1.0"/>
		<mesh name="left_arm1" file="stl/left_arm1.stl" scale="1.0 1.0 1.0"/>
		<mesh name="left_arm2" file="stl/left_arm2.stl" scale="1.0 1.0 1.0"/>
		<mesh name="left_arm3" file="stl/left_arm3.stl" scale="1.0 1.0 1.0"/>
		<mesh name="left_arm4" file="stl/left_arm4.stl" scale="1.0 1.0 1.0"/>
		<mesh name="left_arm5" file="stl/left_arm5.stl" scale="1.0 1.0 1.0"/>
		<mesh name="left_arm6" file="stl/left_arm6.stl" scale="1.0 1.0 1.0"/>
		<mesh name="left_arm7" file="stl/left_arm7.stl" scale="1.0 1.0 1.0"/>
		<mesh name="finger_base" file="stl/finger-base.stl" scale="1.0 1.0 1.0"/>
		<mesh name="finger_phaprox" file="stl/finger-phaprox.stl" scale="1.0 1.0 1.0"/>
		<mesh name="finger_phamed" file="stl/finger-phamed.stl" scale="1.0 1.0 1.0"/>
		<mesh name="hii2_geh_phadist_gesamt_asm" file="stl/hii2_geh_phadist_gesamt_asm.stl" scale="1.0 1.0 1.0"/>
		<mesh name="right_arm1" file="stl/right_arm1.stl" scale="1.0 1.0 1.0"/>
		<mesh name="right_arm2" file="stl/right_arm2.stl" scale="1.0 1.0 1.0"/>
		<mesh name="right_arm3" file="stl/right_arm3.stl" scale="1.0 1.0 1.0"/>
		<mesh name="right_arm4" file="stl/right_arm4.stl" scale="1.0 1.0 1.0"/>
		<mesh name="right_arm5" file="stl/right_arm5.stl" scale="1.0 1.0 1.0"/>
		<mesh name="right_arm6" file="stl/right_arm6.stl" scale="1.0 1.0 1.0"/>
		<mesh name="right_arm7" file="stl/right_arm7.stl" scale="1.0 1.0 1.0"/>
		<material name="material_1_003" rgba="0.09175040572881699 0.1469046026468277 0.32767999172210693 1.0" emission="0.0"/>
		<material name="material_1" rgba="0.11468800157308578 0.18363070487976074 0.40959998965263367 1.0" emission="0.0"/>
		<material name="material_3" rgba="0.5600000023841858 0.5499199628829956 0.459199994802475 1.0" emission="0.0"/>
		<material name="material_3_001" rgba="0.7027199864387512 0.7591999769210815 0.800000011920929 1.0" emission="0.0"/>
		<material name="Material_001" rgba="0.6399999856948853 0.6399999856948853 0.6399999856948853 1.0" emission="0.0"/>
		<material name="material_8" rgba="0.5120000243186951 0.5120000243186951 0.5120000243186951 1.0" emission="0.0"/>
		<material name="material_5_001" rgba="0.800000011920929 0.0 0.0 1.0"/>
		<material name="material_5_002" rgba="0.800000011920929 0.0 0.0 1.0"/>
		<material name="material_2_005" rgba="0.5760000348091125 0.5656319856643677 0.47231999039649963 1.0" emission="0.0"/>
		<material name="material_1_006" rgba="0.29600000381469727 0.4480000138282776 0.7360000610351562 1.0" emission="0.0"/>
		<material name="material_4_001_001" rgba="0.4672001004219055 0.4672001004219055 0.4672001004219055 1.0" emission="0.0"/>
		<material name="material_1_006_001_001" rgba="0.1515520066022873 0.22937600314617157 0.3768320083618164 1.0" emission="0.0"/>
		<material name="material_6" rgba="0.13750000298023224 0.19694800674915314 0.25 1.0" emission="0.0"/>
	</asset>
	<worldbody>
		<body name="rollin-justin" pos="0.0 0.0 0.0" quat="1.0 0.0 0.0 0.0">
			<body name="base_link" pos="0.0 0.0 0.0" quat="1.0 0.0 0.0 0.0">
				<inertial mass="224.7355194091797" pos="-0.00018272799206897616 1.6127123672049493e-05 0.23259808123111725" quat="0.5002467036247253 0.5003892779350281 0.4996047914028168 -0.499758780002594" diaginertia="14.472777366638184 23.62435531616211 27.990686416625977"/>
				<geom name="base_link_geom_collision_0_Mobile_Wheel_Flat_Ch_003" type="mesh" pos="0.0 0.0 0.0" quat="1.0 0.0 0.0 0.0" mesh="base" material="material_1_003" class="rollin-justin_collision"/>
				<body name="torso1" pos="0.0 0.0 0.6938999891281128" quat="1.0 0.0 0.0 0.0">
					<inertial mass="1.4712985754013062" pos="0.025275835767388344 0.0007431928534060717 0.6334223747253418" quat="0.8976299166679382 0.019020117819309235 0.4402303695678711 -0.009795311838388443" diaginertia="0.007986108772456646 0.011889693327248096 0.012127798981964588"/>
					<geom name="torso1_geom_collision_0_torso_link2_iv__Geometry_0" type="mesh" pos="0.0 0.0 0.0" quat="1.0 0.0 0.0 0.0" mesh="torso1" material="material_1" class="rollin-justin_collision"/>
					<joint name="torso1_joint" type="hinge" damping="1" pos="0.0 0.0 0.0" range="-1.7453300952911377 3.3161301612854004" axis="0.0 0.0 1.0"/>
					<body name="torso2" pos="0.0 0.0 0.0" quat="0.5000031590461731 -0.5 -0.5 -0.4999968409538269">
						<inertial mass="6.738800525665283" pos="-0.023618027567863464 3.0410037652472965e-06 0.8688623905181885" quat="0.7064671516418457 -0.706275999546051 0.03223329037427902 -0.032238781452178955" diaginertia="0.03799419850111008 0.29220476746559143 0.31166598200798035"/>
						<geom name="torso2_geom_collision_0_torso_link3_iv__Geometry_2" type="mesh" pos="0.0 0.0 0.0" quat="1.0 0.0 0.0 0.0" mesh="torso2" material="material_3" class="rollin-justin_collision"/>
						<joint name="torso2_joint" type="hinge" damping="1" pos="0.0 0.0 0.0" range="-1.2217299938201904 0.5235999822616577" axis="0.0 0.0 1.0"/>
						<body name="torso3" pos="0.30000001192092896 -8.470329472543003e-22 0.0" quat="1.0 2.0536479054491018e-23 -1.6155871338926322e-27 0.0">
							<inertial mass="6.738800525665283" pos="-0.023616129532456398 3.0410037652472965e-06 1.1688623428344727" quat="0.7064671516418457 -0.706275999546051 0.03223329037427902 -0.032238781452178955" diaginertia="0.03799419850111008 0.29220476746559143 0.31166598200798035"/>
							<geom name="torso3_geom_collision_0_torso_link3_iv__Geometry_2" type="mesh" pos="0.0 0.0 0.0" quat="1.0 0.0 0.0 0.0" mesh="torso3" material="material_3" class="rollin-justin_collision"/>
							<joint name="torso3_joint" type="hinge" damping="1" pos="-1.0536230218007488e-21 -1.6653345369377348e-16 1.9006558680808532e-21" range="0.17453299462795258 2.338740110397339" axis="0.0 0.0 1.0"/>
							<body name="torso4" pos="0.30000001192092896 -1.6940658945086007e-21 6.462348535570529e-27" quat="1.0 2.0536479054491018e-23 -1.6155871338926322e-27 0.0">
								<inertial mass="7.379939079284668" pos="0.07681548595428467 -3.699501758092083e-05 1.3429720401763916" quat="0.6380520462989807 0.638219952583313 0.304882287979126 0.30432167649269104" diaginertia="0.07201973348855972 0.11302699148654938 0.1323736608028412"/>
								<geom name="torso4_geom_collision_0_torso_link5_iv__Geometry_2" type="mesh" pos="0.0 0.0 0.0" quat="1.0 0.0 0.0 0.0" mesh="torso4" material="material_3_001" class="rollin-justin_collision"/>
								<joint name="torso4_joint" type="hinge" damping="1" pos="-3.5121412786760217e-22 -5.551115123125783e-17 2.0452735347841183e-21" range="-1.5700000524520874 0.0" axis="0.0 0.0 1.0"/>
								<body name="left_arm1" pos="0.1899999976158142 0.08799999952316284 0.25600001215934753" quat="-1.2815869467885932e-06 0.9659269452095032 -3.433941628827597e-07 -0.25881481170654297">
									<inertial mass="2.278517246246338" pos="0.12034201622009277 0.19148801267147064 1.4466506242752075" quat="0.7060986161231995 0.03782321885228157 -0.7060900926589966 -0.037828341126441956" diaginertia="0.006829763762652874 0.02660626918077469 0.029757529497146606"/>
									<geom name="left_arm1_geom_collision_0_right_lwr_3_link12_34_iv__Geometry_4" type="mesh" pos="0.0 0.0 0.0" quat="1.0 0.0 0.0 0.0" mesh="left_arm1" material="material_5_001" class="rollin-justin_collision"/>
									<joint name="left_arm1_joint" type="hinge" damping="1" pos="3.512076655190666e-22 5.551106189575167e-17 -1.387813853239418e-17" range="-2.967060089111328 2.967060089111328" axis="0.0 0.0 1.0"/>
									<body name="left_arm2" pos="0.0 0.0 0.0" quat="0.7071090340614319 0.7071045637130737 3.921008487941007e-17 3.9296260555625847e-17">
										<inertial mass="2.2794947624206543" pos="0.05568176135420799 0.3209896683692932 1.5214245319366455" quat="0.47288256883621216 0.5257428884506226 -0.4728938043117523 -0.525688111782074" diaginertia="0.006845938973128796 0.02685559168457985 0.03002076782286167"/>
										<geom name="left_arm2_geom_collision_0_left_lwr_3_link23_45_iv_MatrixTransform_Group__Geometry_4" type="mesh" pos="0.0 0.0 0.0" quat="1.0 0.0 0.0 0.0" mesh="left_arm2" material="material_5_002" class="rollin-justin_collision"/>
										<joint name="left_arm2_joint" type="hinge" damping="1" pos="0.0 0.0 -0.0" range="-2.094399929046631 2.094399929046631" axis="0.0 0.0 1.0"/>
										<body name="left_arm3" pos="-2.220446049250313e-16 -0.4000000059604645 0.0" quat="-0.49999797344207764 0.5000028610229492 0.5000001788139343 0.4999989867210388">
											<inertial mass="2.278517246246338" pos="0.08800058811903 0.5540670156478882 1.6186442375183105" quat="0.7060986161231995 0.03782321885228157 -0.7060900926589966 -0.037828341126441956" diaginertia="0.006829763762652874 0.02660626918077469 0.029757529497146606"/>
											<geom name="left_arm3_geom_collision_0_right_lwr_3_link12_34_iv__Geometry_4" type="mesh" pos="0.0 0.0 0.0" quat="1.0 0.0 0.0 0.0" mesh="left_arm3" material="material_5_001" class="rollin-justin_collision"/>
											<joint name="left_arm3_joint" type="hinge" damping="1" pos="5.55122232573317e-17 9.614831788194643e-17 2.2204426081789649e-16" range="-2.967060089111328 2.967060089111328" axis="0.0 0.0 1.0"/>
											<body name="left_arm4" pos="-1.3877787807814457e-17 0.0 0.0" quat="0.7071090340614319 0.7071045637130737 -5.4967650555418635e-17 -6.3249128903851494e-18">
												<inertial mass="2.2794947624206543" pos="0.08800823241472244 0.6512435078620911 1.7494093179702759" quat="0.47288256883621216 0.5257428884506226 -0.4728938043117523 -0.525688111782074" diaginertia="0.006845938973128796 0.02685559168457985 0.03002076782286167"/>
												<geom name="left_arm4_geom_collision_0_left_lwr_3_link23_45_iv_MatrixTransform_Group__Geometry_4" type="mesh" pos="0.0 0.0 0.0" quat="1.0 0.0 0.0 0.0" mesh="left_arm4" material="material_5_002" class="rollin-justin_collision"/>
												<joint name="left_arm4_joint" type="hinge" damping="1" pos="1.3877787807814457e-17 9.721435226537409e-23 -1.0364679981719312e-22" range="-2.094399929046631 2.094399929046631" axis="0.0 0.0 1.0"/>
												<body name="left_arm5" pos="1.3877787807814457e-17 -0.38999998569488525 -2.220446049250313e-16" quat="0.7071090340614319 -0.7071045637130737 1.4973237575545396e-22 5.98937076086506e-22">
													<inertial mass="1.2786157131195068" pos="0.08799681067466736 0.8377841711044312 1.8480994701385498" quat="0.028897732496261597 0.7065482139587402 -0.02890058048069477 -0.706483781337738" diaginertia="0.0032310120295733213 0.01969139277935028 0.02106323279440403"/>
													<geom name="left_arm5_geom_collision_0_left_lwr_3_link56_iv_MatrixTransform_Group__Geometry_1" type="mesh" pos="0.0 0.0 0.0" quat="1.0 0.0 0.0 0.0" mesh="left_arm5" material="material_2_005" class="rollin-justin_collision"/>
													<joint name="left_arm5_joint" type="hinge" damping="1" pos="-1.3879634074941675e-17 -1.4869411926143026e-17 -2.478076149415833e-16" range="-2.967060089111328 2.967060089111328" axis="0.0 0.0 1.0"/>
													<body name="left_arm6" pos="0.0 0.0 0.0" quat="0.5000038146972656 -0.4999982714653015 0.49999934434890747 0.4999985694885254">
														<inertial mass="1.3991453647613525" pos="0.08615120500326157 0.9439283013343811 1.8723913431167603" quat="0.7144667506217957 0.6996641755104065 0.00035026270779781044 -0.0026795067824423313" diaginertia="0.0027283544186502695 0.002825313014909625 0.0028757851105183363"/>
														<geom name="left_arm6_geom_collision_0_left_lwr_3_link67_iv_MatrixTransform__Geometry_0" type="mesh" pos="0.0 0.0 0.0" quat="1.0 0.0 0.0 0.0" mesh="left_arm6" material="material_1_006" class="rollin-justin_collision"/>
														<joint name="left_arm6_joint" type="hinge" damping="1" pos="-0.0 0.0 0.0" range="-0.785398006439209 1.3962599039077759" axis="0.0 0.0 1.0"/>
														<body name="left_arm7" pos="2.220446049250313e-16 -1.3877787807814457e-17 0.0" quat="0.5000036954879761 -0.49999913573265076 -0.499999463558197 -0.49999767541885376">
															<inertial mass="1.0555163621902466" pos="0.08725663274526596 1.0829014778137207 1.9724704027175903" quat="-0.5496354103088379 -0.4028584659099579 0.41921886801719666 0.599884569644928" diaginertia="0.0023810488637536764 0.03413848578929901 0.03500598669052124"/>
															<geom name="left_arm7_geom_collision_0_left_lwr_3_link7_bsa_iv_MatrixTransform_Group__Geometry_3_003" type="mesh" pos="0.0 0.0 0.0" quat="1.0 0.0 0.0 0.0" mesh="left_arm7" material="material_4_001_001" class="rollin-justin_collision"/>
															<joint name="left_arm7_joint" type="hinge" damping="1" pos="1.2015992018956641e-17 2.220446578645905e-16 -6.94176173909095e-18" range="-0.785398006439209 2.3561899662017822" axis="0.0 0.0 1.0"/>
															<body name="left_1thumb_base" pos="-0.05040000006556511 0.2029000073671341 -0.04619999974966049" quat="0.3802274763584137 0.28664183616638184 0.5528058409690857 0.6838634610176086">
																<body name="left_1thumb1" pos="0.0 0.0 0.0" quat="1.0 6.071532165918825e-18 3.0814879110195774e-33 8.673617379884035e-19">
																	<joint name="left_1thumb1_joint" type="hinge" damping="1" pos="0.0 0.0 0.0" range="-0.5235990285873413 0.5235990285873413" axis="0.0 0.0 1.0"/>
																	<body name="left_1thumb2" pos="0.0 0.0 0.0" quat="0.7071090340614319 0.7071045637130737 2.3919178109056975e-17 -8.58644660539136e-18">
																		<inertial mass="0.06310664862394333" pos="0.134935662150383 1.1825547218322754 1.9325861930847168" quat="0.7089327573776245 -0.7050617337226868 0.016155000776052475 -0.006425226107239723" diaginertia="1.0902839676418807e-05 0.0001451449206797406 0.00014662362809758633"/>
																		<geom name="left_1thumb2_geom_collision_0_finger_phaprox_ShapeIndexedFaceSet_001" type="mesh" pos="0.0 0.0 0.0" quat="1.0 0.0 0.0 0.0" mesh="finger_phaprox" class="rollin-justin_collision"/>
																		<joint name="left_1thumb2_joint" type="hinge" damping="1" pos="0.0 0.0 0.0" range="-0.34906598925590515 1.500980019569397" axis="0.0 0.0 1.0"/>
																		<body name="left_1thumb3" pos="0.07500000298023224 0.0 -1.1102230246251565e-16" quat="1.0 0.0 0.0 0.0">
																			<inertial mass="0.026522383093833923" pos="0.13785885274410248 1.2356280088424683 1.930206060409546" quat="0.7099601626396179 -0.7039278745651245 0.006069454830139875 -0.02013099379837513" diaginertia="4.763814104080666e-06 1.7667984138824977e-05 1.865063313744031e-05"/>
																			<geom name="left_1thumb3_geom_collision_0_finger_phamed_ShapeIndexedFaceSet_001" type="mesh" pos="0.0 0.0 0.0" quat="1.0 0.0 0.0 0.0" mesh="finger_phamed" class="rollin-justin_collision"/>
																			<joint name="left_1thumb3_joint" type="hinge" damping="1" pos="-1.119974838846279e-17 1.4848274483642091e-16 -1.5067052506006036e-16" range="-0.17453299462795258 1.7627800703048706" axis="0.0 0.0 1.0"/>
																			<body name="left_1thumb4" pos="0.03999000042676926 -2.220446049250313e-16 -1.1102230246251565e-16" quat="0.7071090340614319 0.0 0.0 -0.7071045637130737">
																				<inertial mass="0.027972880750894547" pos="0.1380554437637329 1.279028296470642 1.9312243461608887" quat="0.4448316991329193 0.49165210127830505 0.5386440753936768 0.5198706984519958" diaginertia="2.3384206997434376e-06 1.9123181118629873e-05 1.9700737539096735e-05"/>
																				<geom name="left_1thumb4_geom_collision_0_hii2_geh_phadist_gesamt_asm_ShapeIndexedFaceSet_001" type="mesh" pos="0.0 0.0 0.0" quat="1.0 0.0 0.0 0.0" mesh="hii2_geh_phadist_gesamt_asm" class="rollin-justin_collision"/>
																				<joint name="left_1thumb4_joint" type="hinge" damping="1" pos="2.1631920483207407e-16 1.1503569015039434e-16 4.871265634708045e-17" range="-0.17453299462795258 1.7627800703048706" axis="0.0 0.0 1.0"/>
																			</body>
																		</body>
																	</body>
																</body>
															</body>
															<body name="left_2tip_base" pos="0.04820000007748604 0.24089999496936798 -0.023600000888109207" quat="-0.5390362739562988 0.5562926530838013 0.5027128458023071 -0.3837422728538513">
																<body name="left_2tip1" pos="4.440892098500626e-16 5.551115123125783e-17 1.1102230246251565e-16" quat="1.0 3.469446951953614e-18 -1.3877787807814457e-17 -3.469446951953614e-18">
																	<joint name="left_2tip1_joint" type="hinge" damping="1" pos="-6.3397650010016e-17 -4.565960218931868e-16 -1.1111124257633858e-17" range="-0.5235990285873413 0.5235990285873413" axis="0.0 0.0 1.0"/>
																	<body name="left_2tip2" pos="4.440892098500626e-16 5.551115123125783e-17 1.1102230246251565e-16" quat="0.7071090340614319 0.7071045637130737 9.813047093147255e-18 4.415864988061671e-17">
																		<inertial mass="0.06310664862394333" pos="0.10744867473840714 1.1544967889785767 2.0699188709259033" quat="0.7089327573776245 -0.7050617337226868 0.016155000776052475 -0.006425226107239723" diaginertia="1.0902839676418807e-05 0.0001451449206797406 0.00014662362809758633"/>
																		<geom name="left_2tip2_geom_collision_0_finger_phaprox_ShapeIndexedFaceSet_001" type="mesh" pos="0.0 0.0 0.0" quat="1.0 0.0 0.0 0.0" mesh="finger_phaprox" class="rollin-justin_collision"/>
																		<joint name="left_2tip2_joint" type="hinge" damping="1" pos="-6.3397650010016e-17 -4.565960218931868e-16 -1.1111124257633858e-17" range="-0.34906598925590515 1.500980019569397" axis="0.0 0.0 1.0"/>
																		<body name="left_2tip3" pos="0.07500000298023224 -1.1102230246251565e-16 -1.6653345369377348e-16" quat="1.0 -6.938893903907228e-18 -6.938893903907228e-18 5.551115123125783e-17">
																			<inertial mass="0.026522383093833923" pos="0.09987806528806686 1.1941273212432861 2.104604482650757" quat="0.7099601626396179 -0.7039278745651245 0.006069454830139875 -0.02013099379837513" diaginertia="4.763814104080666e-06 1.7667984138824977e-05 1.865063313744031e-05"/>
																			<geom name="left_2tip3_geom_collision_0_finger_phamed_ShapeIndexedFaceSet_001" type="mesh" pos="0.0 0.0 0.0" quat="1.0 0.0 0.0 0.0" mesh="finger_phamed" class="rollin-justin_collision"/>
																			<joint name="left_2tip3_joint" type="hinge" damping="1" pos="2.641402895189979e-16 -1.252385990467664e-16 5.870309960177909e-16" range="-0.17453299462795258 1.7627800703048706" axis="0.0 0.0 1.0"/>
																			<body name="left_2tip4" pos="0.03999999910593033 1.1102230246251565e-16 -1.1102230246251565e-16" quat="0.7071090340614319 1.2416987454718263e-22 -5.3971632453676184e-17 -0.7071045637130737">
																				<inertial mass="0.027972880750894547" pos="0.09557826817035675 1.2286394834518433 2.130603551864624" quat="0.4448316991329193 0.49165210127830505 0.5386440753936768 0.5198706984519958" diaginertia="2.3384206997434376e-06 1.9123181118629873e-05 1.9700737539096735e-05"/>
																				<geom name="left_2tip4_geom_collision_0_hii2_geh_phadist_gesamt_asm_ShapeIndexedFaceSet_001" type="mesh" pos="0.0 0.0 0.0" quat="1.0 0.0 0.0 0.0" mesh="hii2_geh_phadist_gesamt_asm" class="rollin-justin_collision"/>
																				<joint name="left_2tip4_joint" type="hinge" damping="1" pos="-5.628677533059165e-17 -1.047256514385293e-16 -4.220430068758421e-16" range="-0.17453299462795258 1.7627800703048706" axis="0.0 0.0 1.0"/>
																			</body>
																		</body>
																	</body>
																</body>
															</body>
															<body name="left_3middle_base" pos="0.04690000042319298 0.2353000044822693 0.016289999708533287" quat="-0.5390362739562988 0.5562926530838013 0.5027128458023071 -0.3837422728538513">
																<inertial mass="0.10227017104625702" pos="0.037921417504549026 0.1940096616744995 0.011176788248121738" quat="-0.6848092675209045 0.7286957502365112 -0.004266366828233004 -0.004536712542176247" diaginertia="2.836716521414928e-05 0.000272170000243932 0.00028322578873485327"/>
																<geom name="left_3middle_base_geom_collision_0_finger_base_ShapeIndexedFaceSet_001" type="mesh" pos="0.0 0.0 0.0" quat="1.0 0.0 0.0 0.0" mesh="finger_base" class="rollin-justin_collision"/>
																<body name="left_3middle1" pos="4.440892098500626e-16 5.551115123125783e-17 0.0" quat="1.0 3.469446951953614e-18 -1.3877787807814457e-17 -3.469446951953614e-18">
																	<joint name="left_3middle1_joint" type="hinge" damping="1" pos="9.848323864730804e-18 -4.3779276396686817e-16 -9.239713321335726e-17" range="-0.5235990285873413 0.5235990285873413" axis="0.0 0.0 1.0"/>
																	<body name="left_3middle2" pos="4.440892098500626e-16 5.551115123125783e-17 0.0" quat="0.7071090340614319 0.7071045637130737 9.813047093147255e-18 4.415864988061671e-17">
																		<inertial mass="0.06310664862394333" pos="0.06755862385034561 1.1502968072891235 2.0659937858581543" quat="0.7089327573776245 -0.7050617337226868 0.016155000776052475 -0.006425226107239723" diaginertia="1.0902839676418807e-05 0.0001451449206797406 0.00014662362809758633"/>
																		<geom name="left_3middle2_geom_collision_0_finger_phaprox_ShapeIndexedFaceSet_001" type="mesh" pos="0.0 0.0 0.0" quat="1.0 0.0 0.0 0.0" mesh="finger_phaprox" class="rollin-justin_collision"/>
																		<joint name="left_3middle2_joint" type="hinge" damping="1" pos="9.848323864730804e-18 -4.3779276396686817e-16 -9.239713321335726e-17" range="-0.34906598925590515 1.500980019569397" axis="0.0 0.0 1.0"/>
																		<body name="left_3middle3" pos="0.07498999685049057 -2.220446049250313e-16 0.0" quat="1.0 -6.938893903907228e-18 -6.938893903907228e-18 5.551115123125783e-17">
																			<inertial mass="0.026522383093833923" pos="0.05998916178941727 1.1899199485778809 2.100672721862793" quat="0.7099601626396179 -0.7039278745651245 0.006069454830139875 -0.02013099379837513" diaginertia="4.763814104080666e-06 1.7667984138824977e-05 1.865063313744031e-05"/>
																			<geom name="left_3middle3_geom_collision_0_finger_phamed_ShapeIndexedFaceSet_001" type="mesh" pos="0.0 0.0 0.0" quat="1.0 0.0 0.0 0.0" mesh="finger_phamed" class="rollin-justin_collision"/>
																			<joint name="left_3middle3_joint" type="hinge" damping="1" pos="2.287408238895502e-16 7.966926542333442e-17 5.466105308352565e-16" range="-0.17453299462795258 1.7627800703048706" axis="0.0 0.0 1.0"/>
																			<body name="left_3middle4" pos="0.03999999910593033 -1.1102230246251565e-16 -5.551115123125783e-17" quat="0.7071090340614319 1.2416987454718263e-22 -5.3971632453676184e-17 -0.7071045637130737">
																				<inertial mass="0.027972880750894547" pos="0.05568936839699745 1.224432110786438 2.12667179107666" quat="0.4448316991329193 0.49165210127830505 0.5386440753936768 0.5198706984519958" diaginertia="2.3384206997434376e-06 1.9123181118629873e-05 1.9700737539096735e-05"/>
																				<geom name="left_3middle4_geom_collision_0_hii2_geh_phadist_gesamt_asm_ShapeIndexedFaceSet_001" type="mesh" pos="0.0 0.0 0.0" quat="1.0 0.0 0.0 0.0" mesh="hii2_geh_phadist_gesamt_asm" class="rollin-justin_collision"/>
																				<joint name="left_3middle4_joint" type="hinge" damping="1" pos="7.1989594884939e-17 8.461759219652464e-17 -4.1312086473527774e-16" range="-0.17453299462795258 1.7627800703048706" axis="0.0 0.0 1.0"/>
																			</body>
																		</body>
																	</body>
																</body>
															</body>
															<body name="left_4ring_base" pos="0.03739999979734421 0.22990000247955322 0.062300000339746475" quat="-0.5390362739562988 0.5562926530838013 0.5027128458023071 -0.3837422728538513">
																<body name="left_4ring1" pos="4.440892098500626e-16 5.551115123125783e-17 -1.1102230246251565e-16" quat="1.0 3.469446951953614e-18 -1.3877787807814457e-17 -3.469446951953614e-18">
																	<joint name="left_4ring1_joint" type="hinge" damping="1" pos="8.309429608511639e-17 -4.1898945310099036e-16 -1.7368313968753882e-16" range="-0.5235990285873413 0.5235990285873413" axis="0.0 0.0 1.0"/>
																	<body name="left_4ring2" pos="4.440892098500626e-16 5.551115123125783e-17 -1.1102230246251565e-16" quat="0.7071090340614319 0.7071045637130737 9.813047093147255e-18 4.415864988061671e-17">
																		<inertial mass="0.06310664862394333" pos="0.021548444405198097 1.1503700017929077 2.055067300796509" quat="0.7089327573776245 -0.7050617337226868 0.016155000776052475 -0.006425226107239723" diaginertia="1.0902839676418807e-05 0.0001451449206797406 0.00014662362809758633"/>
																		<geom name="left_4ring2_geom_collision_0_finger_phaprox_ShapeIndexedFaceSet_001" type="mesh" pos="0.0 0.0 0.0" quat="1.0 0.0 0.0 0.0" mesh="finger_phaprox" class="rollin-justin_collision"/>
																		<joint name="left_4ring2_joint" type="hinge" damping="1" pos="8.309429608511639e-17 -4.1898945310099036e-16 -1.7368313968753882e-16" range="-0.34906598925590515 1.500980019569397" axis="0.0 0.0 1.0"/>
																		<body name="left_4ring3" pos="0.07500000298023224 -2.220446049250313e-16 -5.551115123125783e-17" quat="1.0 -6.938893903907228e-18 -6.938893903907228e-18 5.551115123125783e-17">
																			<inertial mass="0.026522383093833923" pos="0.013977831229567528 1.1900005340576172 2.0897529125213623" quat="0.7099601626396179 -0.7039278745651245 0.006069454830139875 -0.02013099379837513" diaginertia="4.763814104080666e-06 1.7667984138824977e-05 1.865063313744031e-05"/>
																			<geom name="left_4ring3_geom_collision_0_finger_phamed_ShapeIndexedFaceSet_001" type="mesh" pos="0.0 0.0 0.0" quat="1.0 0.0 0.0 0.0" mesh="finger_phamed" class="rollin-justin_collision"/>
																			<joint name="left_4ring3_joint" type="hinge" damping="1" pos="2.222708156615074e-16 8.562226591619685e-17 1.6792266713660934e-16" range="-0.17453299462795258 1.7627800703048706" axis="0.0 0.0 1.0"/>
																			<body name="left_4ring4" pos="0.03999999910593033 -1.1102230246251565e-16 -5.551115123125783e-17" quat="0.7071090340614319 1.2416987454718263e-22 -5.3971632453676184e-17 -0.7071045637130737">
																				<inertial mass="0.027972880750894547" pos="0.009678036905825138 1.2245126962661743 2.1157519817352295" quat="0.4448316991329193 0.49165210127830505 0.5386440753936768 0.5198706984519958" diaginertia="2.3384206997434376e-06 1.9123181118629873e-05 1.9700737539096735e-05"/>
																				<geom name="left_4ring4_geom_collision_0_hii2_geh_phadist_gesamt_asm_ShapeIndexedFaceSet_001" type="mesh" pos="0.0 0.0 0.0" quat="1.0 0.0 0.0 0.0" mesh="hii2_geh_phadist_gesamt_asm" class="rollin-justin_collision"/>
																				<joint name="left_4ring4_joint" type="hinge" damping="1" pos="1.2306275669372733e-16 2.939276457121837e-17 2.4551354200923077e-17" range="-0.17453299462795258 1.7627800703048706" axis="0.0 0.0 1.0"/>
																			</body>
																		</body>
																	</body>
																</body>
															</body>
															<body name="left_palm" pos="0.0 0.10109999775886536 0.0" quat="9.381886343362567e-07 9.381827226206951e-07 0.7071045637130737 0.7071090340614319"/>
														</body>
													</body>
												</body>
											</body>
										</body>
									</body>
								</body>
								<body name="right_arm1" pos="0.1899999976158142 0.08799999952316284 -0.25600001215934753" quat="0.25881481170654297 9.381927839058335e-07 0.9659269452095032 9.381927839058335e-07">
									<inertial mass="2.278517246246338" pos="0.12034415453672409 -0.19148379564285278 1.446655035018921" quat="-0.7060900926589966 -0.037828389555215836 0.7060985565185547 0.03782327473163605" diaginertia="0.006829763762652874 0.02660626731812954 0.029757527634501457"/>
									<geom name="right_arm1_geom_collision_0_right_lwr_3_link12_34_iv__Geometry_4" type="mesh" pos="0.0 0.0 0.0" quat="1.0 0.0 0.0 0.0" mesh="right_arm1" material="material_5_001" class="rollin-justin_collision"/>
									<joint name="right_arm1_joint" type="hinge" damping="1" pos="1.75603840332598e-21 2.7755583556562794e-16 1.3876031703374007e-17" range="-2.967060089111328 2.967060089111328" axis="0.0 0.0 1.0"/>
									<body name="right_arm2" pos="-2.220446049250313e-16 0.0 -1.1102230246251565e-16" quat="0.7071090340614319 0.7071045637130737 -2.994620756947174e-22 5.989454064576651e-22">
										<inertial mass="2.2794950008392334" pos="0.05568613484501839 -0.3209926187992096 1.5214184522628784" quat="-0.4728938639163971 -0.5256880521774292 0.47288259863853455 0.5257428288459778" diaginertia="0.006845939438790083 0.026855593547225 0.03002077154815197"/>
										<geom name="right_arm2_geom_collision_0_left_lwr_3_link23_45_iv_MatrixTransform_Group__Geometry_4" type="mesh" pos="0.0 0.0 0.0" quat="1.0 0.0 0.0 0.0" mesh="right_arm2" material="material_5_002" class="rollin-justin_collision"/>
										<joint name="right_arm2_joint" type="hinge" damping="1" pos="-9.614862228441185e-17 2.2204404905965967e-16 5.551252104235221e-17" range="-2.094399929046631 2.094399929046631" axis="0.0 0.0 1.0"/>
										<body name="right_arm3" pos="2.220446049250313e-16 0.4000000059604645 -1.3877787807814457e-17" quat="-0.5 0.49999889731407166 0.49999815225601196 0.5000029802322388">
											<inertial mass="2.278517246246338" pos="0.08801484107971191 -0.5540659427642822 1.6186442375183105" quat="-0.7060900926589966 -0.037828389555215836 0.7060985565185547 0.03782327473163605" diaginertia="0.006829763762652874 0.02660626731812954 0.029757527634501457"/>
											<geom name="right_arm3_geom_collision_0_right_lwr_3_link12_34_iv__Geometry_4" type="mesh" pos="0.0 0.0 0.0" quat="1.0 0.0 0.0 0.0" mesh="right_arm3" material="material_5_001" class="rollin-justin_collision"/>
											<joint name="right_arm3_joint" type="hinge" damping="1" pos="-1.2018573649648419e-17 6.935169936789515e-18 2.220447108041497e-16" range="-2.967060089111328 2.967060089111328" axis="0.0 0.0 1.0"/>
											<body name="right_arm4" pos="0.0 0.0 0.0" quat="0.7071090340614319 0.7071045637130737 1.497364021015142e-22 -1.4973573314746658e-22">
												<inertial mass="2.2794950008392334" pos="0.08801046013832092 -0.6512423753738403 1.7494093179702759" quat="-0.4728938639163971 -0.5256880521774292 0.47288259863853455 0.5257428288459778" diaginertia="0.006845939438790083 0.026855593547225 0.03002077154815197"/>
												<geom name="right_arm4_geom_collision_0_left_lwr_3_link23_45_iv_MatrixTransform_Group__Geometry_4" type="mesh" pos="0.0 0.0 0.0" quat="1.0 0.0 0.0 0.0" mesh="right_arm4" material="material_5_002" class="rollin-justin_collision"/>
												<joint name="right_arm4_joint" type="hinge" damping="1" pos="-0.0 0.0 0.0" range="-2.094399929046631 2.094399929046631" axis="0.0 0.0 1.0"/>
												<body name="right_arm5" pos="0.0 0.38999998569488525 2.220446049250313e-16" quat="-9.381886343362567e-07 -9.381827226206951e-07 0.7071045637130737 0.7071090340614319">
													<inertial mass="1.27861487865448" pos="0.08802531659603119 -0.8377830982208252 1.8480994701385498" quat="-0.7064837217330933 -0.02890048362314701 0.7065482139587402 0.028897924348711967" diaginertia="0.0032310073729604483 0.01969137229025364 0.02106321230530739"/>
													<geom name="right_arm5_geom_collision_0_left_lwr_3_link56_iv_MatrixTransform_Group__Geometry_1" type="mesh" pos="0.0 0.0 0.0" quat="1.0 0.0 0.0 0.0" mesh="right_arm5" material="material_2_005" class="rollin-justin_collision"/>
													<joint name="right_arm5_joint" type="hinge" damping="1" pos="-2.4494946473744053e-21 -2.0716787410482841e-16 -1.3678900501332207e-16" range="-2.967060089111328 2.967060089111328" axis="0.0 0.0 1.0"/>
													<body name="right_arm6" pos="0.0 -2.220446049250313e-16 0.0" quat="0.5000036358833313 0.4999975860118866 -0.4999995231628418 0.4999992549419403">
														<inertial mass="1.3991397619247437" pos="0.08616156876087189 -0.9439118504524231 1.872382402420044" quat="0.7144690155982971 -0.6996618509292603 0.0003507633809931576 0.002678107703104615" diaginertia="0.002728336723521352 0.002825294155627489 0.0028757681138813496"/>
														<geom name="right_arm6_geom_collision_0_left_lwr_3_link67_iv_MatrixTransform__Geometry_0_003" type="mesh" pos="0.0 0.0 0.0" quat="1.0 0.0 0.0 0.0" mesh="right_arm6" material="material_1_006_001_001" class="rollin-justin_collision"/>
														<joint name="right_arm6_joint" type="hinge" damping="1" pos="2.2572541167769954e-21 1.110199069474617e-16 -1.9229765485040753e-16" range="-0.785398006439209 1.3962599039077759" axis="0.0 0.0 1.0"/>
														<body name="right_arm7" pos="0.0 0.0 0.0" quat="0.5000005960464478 0.5000025629997253 0.4999975562095642 -0.4999992847442627">
															<inertial mass="0.901043713092804" pos="0.09258520603179932 -1.0850979089736938 1.976768970489502" quat="-0.35568782687187195 -0.5755832195281982 0.6251466274261475 0.38907817006111145" diaginertia="0.0021221847273409367 0.03040979616343975 0.031320925801992416"/>
															<geom name="right_arm7_geom_collision_0_aVis_Hand_right_Group__Geometry_5" type="mesh" pos="0.0 0.0 0.0" quat="1.0 0.0 0.0 0.0" mesh="right_arm7" material="material_6" class="rollin-justin_collision"/>
															<joint name="right_arm7_joint" type="hinge" damping="1" pos="0.0 0.0 -0.0" range="-0.785398006439209 2.3561899662017822" axis="0.0 0.0 1.0"/>
															<body name="right_1thumb_base" pos="-0.05040000006556511 0.2029000073671341 0.04619999974966049" quat="0.287274032831192 0.3797719180583954 0.6829645037651062 0.5539010763168335">
																<body name="right_1thumb1" pos="0.0 0.0 2.220446049250313e-16" quat="1.0 1.3877787807814457e-17 1.734723475976807e-18 -1.3010426069826053e-18">
																	<joint name="right_1thumb1_joint" type="hinge" damping="1" pos="1.2167786278805022e-17 -4.9424385707178226e-17 -2.1613186496694306e-16" range="-0.5235990285873413 0.5235990285873413" axis="0.0 0.0 1.0"/>
																	<body name="right_1thumb2" pos="0.0 0.0 2.220446049250313e-16" quat="0.7071090340614319 0.7071045637130737 3.97693631982531e-18 -3.3828159128106293e-18">
																		<inertial mass="0.06310664862394333" pos="0.1365979164838791 -1.1825270652770996 1.932967185974121" quat="0.7089327573776245 -0.7050617337226868 0.016155000776052475 -0.006425226107239723" diaginertia="1.0902839676418807e-05 0.0001451449206797406 0.00014662362809758633"/>
																		<geom name="right_1thumb2_geom_collision_0_finger_phaprox_ShapeIndexedFaceSet_001" type="mesh" pos="0.0 0.0 0.0" quat="1.0 0.0 0.0 0.0" mesh="finger_phaprox" class="rollin-justin_collision"/>
																		<joint name="right_1thumb2_joint" type="hinge" damping="1" pos="1.2167786278805022e-17 -4.9424385707178226e-17 -2.1613186496694306e-16" range="-0.34906598925590515 1.500980019569397" axis="0.0 0.0 1.0"/>
																		<body name="right_1thumb3" pos="0.07500000298023224 4.440892098500626e-16 0.0" quat="1.0 1.3877787807814457e-17 8.673617379884035e-19 5.7777898331617076e-34">
																			<inertial mass="0.026522383093833923" pos="0.1365964561700821 -1.2356464862823486 1.929916501045227" quat="0.7099601626396179 -0.7039278745651245 0.006069454830139875 -0.02013099379837513" diaginertia="4.763814104080666e-06 1.7667984138824977e-05 1.865063313744031e-05"/>
																			<geom name="right_1thumb3_geom_collision_0_finger_phamed_ShapeIndexedFaceSet_001" type="mesh" pos="0.0 0.0 0.0" quat="1.0 0.0 0.0 0.0" mesh="finger_phamed" class="rollin-justin_collision"/>
																			<joint name="right_1thumb3_joint" type="hinge" damping="1" pos="4.444228349521624e-16 1.7308264626749473e-17 -3.3724550620480964e-17" range="-0.17453299462795258 1.7627800703048706" axis="0.0 0.0 1.0"/>
																			<body name="right_1thumb4" pos="0.03999999910593033 2.220446049250313e-16 0.0" quat="0.7071090340614319 3.679861433862097e-18 1.4719508601174942e-17 -0.7071045637130737">
																				<inertial mass="0.027972880750894547" pos="0.13727280497550964 -1.2790491580963135 1.9310462474822998" quat="0.4448316991329193 0.49165210127830505 0.5386440753936768 0.5198706984519958" diaginertia="2.3384206997434376e-06 1.9123181118629873e-05 1.9700737539096735e-05"/>
																				<geom name="right_1thumb4_geom_collision_0_hii2_geh_phadist_gesamt_asm_ShapeIndexedFaceSet_001" type="mesh" pos="0.0 0.0 0.0" quat="1.0 0.0 0.0 0.0" mesh="hii2_geh_phadist_gesamt_asm" class="rollin-justin_collision"/>
																				<joint name="right_1thumb4_joint" type="hinge" damping="1" pos="2.269289145362548e-16 -2.8201581475750155e-17 -1.7919770798596854e-16" range="-0.17453299462795258 1.7627800703048706" axis="0.0 0.0 1.0"/>
																			</body>
																		</body>
																	</body>
																</body>
															</body>
															<body name="right_3middle_base" pos="0.04690000042319298 0.2353000044822693 -0.016289999708533287" quat="0.5554459691047668 -0.5398693680763245 -0.38459038734436035 0.5021066069602966">
																<body name="right_3middle1" pos="0.0 0.0 -2.220446049250313e-16" quat="1.0 6.938893903907228e-18 2.7755575615628914e-17 7.703719777548943e-34">
																	<joint name="right_3middle1_joint" type="hinge" damping="1" pos="1.4647904869502146e-16 -3.707859595081608e-17 -1.6270486477218404e-16" range="-0.5235990285873413 0.5235990285873413" axis="0.0 0.0 1.0"/>
																	<body name="right_3middle2" pos="0.0 0.0 -2.220446049250313e-16" quat="0.7071090340614319 0.7071045637130737 -4.906461508027686e-18 -3.9251940218405255e-17">
																		<inertial mass="0.06310664862394333" pos="0.06590870767831802 -1.1502935886383057 2.065706968307495" quat="0.7089327573776245 -0.7050617337226868 0.016155000776052475 -0.006425226107239723" diaginertia="1.0902839676418807e-05 0.0001451449206797406 0.00014662362809758633"/>
																		<geom name="right_3middle2_geom_collision_0_finger_phaprox_ShapeIndexedFaceSet_001" type="mesh" pos="0.0 0.0 0.0" quat="1.0 0.0 0.0 0.0" mesh="finger_phaprox" class="rollin-justin_collision"/>
																		<joint name="right_3middle2_joint" type="hinge" damping="1" pos="1.4647904869502146e-16 -3.707859595081608e-17 -1.6270486477218404e-16" range="-0.34906598925590515 1.500980019569397" axis="0.0 0.0 1.0"/>
																		<body name="right_3middle3" pos="0.07500000298023224 0.0 1.1102230246251565e-16" quat="1.0 6.071532165918825e-18 5.204170427930421e-18 1.3877787807814457e-17">
																			<inertial mass="0.026522383093833923" pos="0.06130296736955643 -1.1899374723434448 2.100893974304199" quat="0.7099601626396179 -0.7039278745651245 0.006069454830139875 -0.02013099379837513" diaginertia="4.763814104080666e-06 1.7667984138824977e-05 1.865063313744031e-05"/>
																			<geom name="right_3middle3_geom_collision_0_finger_phamed_ShapeIndexedFaceSet_001" type="mesh" pos="0.0 0.0 0.0" quat="1.0 0.0 0.0 0.0" mesh="finger_phamed" class="rollin-justin_collision"/>
																			<joint name="right_3middle3_joint" type="hinge" damping="1" pos="-5.251291929577362e-17 5.947727051021278e-17 -1.964154128792557e-16" range="-0.17453299462795258 1.7627800703048706" axis="0.0 0.0 1.0"/>
																			<body name="right_3middle4" pos="0.03999999910593033 0.0 5.551115123125783e-17" quat="0.7071090340614319 4.051696407279485e-17 3.549565349979785e-17 -0.7071045637130737">
																				<inertial mass="0.027972880750894547" pos="0.05652354285120964 -1.224450707435608 2.126807689666748" quat="0.4448316991329193 0.49165210127830505 0.5386440753936768 0.5198706984519958" diaginertia="2.3384206997434376e-06 1.9123181118629873e-05 1.9700737539096735e-05"/>
																				<geom name="right_3middle4_geom_collision_0_hii2_geh_phadist_gesamt_asm_ShapeIndexedFaceSet_001" type="mesh" pos="0.0 0.0 0.0" quat="1.0 0.0 0.0 0.0" mesh="hii2_geh_phadist_gesamt_asm" class="rollin-justin_collision"/>
																				<joint name="right_3middle4_joint" type="hinge" damping="1" pos="1.8385460579446653e-17 -1.7377350751509902e-17 -4.813266310959338e-16" range="-0.17453299462795258 1.7627800703048706" axis="0.0 0.0 1.0"/>
																			</body>
																		</body>
																	</body>
																</body>
															</body>
															<body name="right_4ring_base" pos="0.03739999979734421 0.22990000247955322 -0.062300000339746475" quat="0.5554459691047668 -0.5398693680763245 -0.38459038734436035 0.5021066069602966">
																<body name="right_4ring1" pos="-4.440892098500626e-16 5.551115123125783e-17 -4.440892098500626e-16" quat="1.0 6.938893903907228e-18 2.7755575615628914e-17 7.703719777548943e-34">
																	<joint name="right_4ring1_joint" type="hinge" damping="1" pos="2.831675082505265e-16 -5.122396808411307e-16 -2.343898983730259e-16" range="-0.5235990285873413 0.5235990285873413" axis="0.0 0.0 1.0"/>
																	<body name="right_4ring2" pos="-4.440892098500626e-16 5.551115123125783e-17 -4.440892098500626e-16" quat="0.7071090340614319 0.7071045637130737 -4.906461508027686e-18 -3.9251940218405255e-17">
																		<inertial mass="0.06310664862394333" pos="0.019898520782589912 -1.1503674983978271 2.0547804832458496" quat="0.7089327573776245 -0.7050617337226868 0.016155000776052475 -0.006425226107239723" diaginertia="1.0902839676418807e-05 0.0001451449206797406 0.00014662362809758633"/>
																		<geom name="right_4ring2_geom_collision_0_finger_phaprox_ShapeIndexedFaceSet_001" type="mesh" pos="0.0 0.0 0.0" quat="1.0 0.0 0.0 0.0" mesh="finger_phaprox" class="rollin-justin_collision"/>
																		<joint name="right_4ring2_joint" type="hinge" damping="1" pos="2.831675082505265e-16 -5.122396808411307e-16 -2.343898983730259e-16" range="-0.34906598925590515 1.500980019569397" axis="0.0 0.0 1.0"/>
																		<body name="right_4ring3" pos="0.07500000298023224 1.1102230246251565e-16 5.551115123125783e-17" quat="1.0 6.071532165918825e-18 5.204170427930421e-18 1.3877787807814457e-17">
																			<inertial mass="0.026522383093833923" pos="0.015292785130441189 -1.1900113821029663 2.0899674892425537" quat="0.7099601626396179 -0.7039278745651245 0.006069454830139875 -0.02013099379837513" diaginertia="4.763814104080666e-06 1.7667984138824977e-05 1.865063313744031e-05"/>
																			<geom name="right_4ring3_geom_collision_0_finger_phamed_ShapeIndexedFaceSet_001" type="mesh" pos="0.0 0.0 0.0" quat="1.0 0.0 0.0 0.0" mesh="finger_phamed" class="rollin-justin_collision"/>
																			<joint name="right_4ring3_joint" type="hinge" damping="1" pos="6.656433562288541e-17 9.314140385875287e-17 -1.8668026469311502e-16" range="-0.17453299462795258 1.7627800703048706" axis="0.0 0.0 1.0"/>
																			<body name="right_4ring4" pos="0.03999999910593033 0.0 5.551115123125783e-17" quat="0.7071090340614319 4.051696407279485e-17 3.549565349979785e-17 -0.7071045637130737">
																				<inertial mass="0.027972880750894547" pos="0.010513360612094402 -1.2245246171951294 2.1158812046051025" quat="0.4448316991329193 0.49165210127830505 0.5386440753936768 0.5198706984519958" diaginertia="2.3384206997434376e-06 1.9123181118629873e-05 1.9700737539096735e-05"/>
																				<geom name="right_4ring4_geom_collision_0_hii2_geh_phadist_gesamt_asm_ShapeIndexedFaceSet_001" type="mesh" pos="0.0 0.0 0.0" quat="1.0 0.0 0.0 0.0" mesh="hii2_geh_phadist_gesamt_asm" class="rollin-justin_collision"/>
																				<joint name="right_4ring4_joint" type="hinge" damping="1" pos="-3.2633876586882844e-17 3.646948992623408e-17 -4.3476437633497273e-17" range="-0.17453299462795258 1.7627800703048706" axis="0.0 0.0 1.0"/>
																			</body>
																		</body>
																	</body>
																</body>
															</body>
															<body name="right_2tip_base" pos="0.04820000007748604 0.24089999496936798 0.023600000888109207" quat="0.5554459691047668 -0.5398693680763245 -0.38459038734436035 0.5021066069602966">
																<body name="right_2tip1" pos="0.0 5.551115123125783e-17 0.0" quat="1.0 6.938893903907228e-18 2.7755575615628914e-17 7.703719777548943e-34">
																	<joint name="right_2tip1_joint" type="hinge" damping="1" pos="4.122874637245183e-17 -2.326417038471834e-19 3.717020785801755e-17" range="-0.5235990285873413 0.5235990285873413" axis="0.0 0.0 1.0"/>
																	<body name="right_2tip2" pos="0.0 5.551115123125783e-17 0.0" quat="0.7071090340614319 0.7071045637130737 -4.906461508027686e-18 -3.9251940218405255e-17">
																		<inertial mass="0.06310664862394333" pos="0.10579882562160492 -1.154492974281311 2.069632053375244" quat="0.7089327573776245 -0.7050617337226868 0.016155000776052475 -0.006425226107239723" diaginertia="1.0902839676418807e-05 0.0001451449206797406 0.00014662362809758633"/>
																		<geom name="right_2tip2_geom_collision_0_finger_phaprox_ShapeIndexedFaceSet_001" type="mesh" pos="0.0 0.0 0.0" quat="1.0 0.0 0.0 0.0" mesh="finger_phaprox" class="rollin-justin_collision"/>
																		<joint name="right_2tip2_joint" type="hinge" damping="1" pos="4.122874637245183e-17 -2.326417038471834e-19 3.717020785801755e-17" range="-0.34906598925590515 1.500980019569397" axis="0.0 0.0 1.0"/>
																		<body name="right_2tip3" pos="0.07500000298023224 2.220446049250313e-16 5.551115123125783e-17" quat="1.0 6.071532165918825e-18 5.204170427930421e-18 1.3877787807814457e-17">
																			<inertial mass="0.026522383093833923" pos="0.10119308531284332 -1.1941367387771606 2.1048192977905273" quat="0.7099601626396179 -0.7039278745651245 0.006069454830139875 -0.02013099379837513" diaginertia="4.763814104080666e-06 1.7667984138824977e-05 1.865063313744031e-05"/>
																			<geom name="right_2tip3_geom_collision_0_finger_phamed_ShapeIndexedFaceSet_001" type="mesh" pos="0.0 0.0 0.0" quat="1.0 0.0 0.0 0.0" mesh="finger_phamed" class="rollin-justin_collision"/>
																			<joint name="right_2tip3_joint" type="hinge" damping="1" pos="2.0004116387975734e-16 1.1363497558832154e-16 -6.240647058398474e-16" range="-0.17453299462795258 1.7627800703048706" axis="0.0 0.0 1.0"/>
																			<body name="right_2tip4" pos="0.03999999910593033 0.0 0.0" quat="0.7071090340614319 4.051696407279485e-17 3.549565349979785e-17 -0.7071045637130737">
																				<inertial mass="0.027972880750894547" pos="0.09641366451978683 -1.2286499738693237 2.130732774734497" quat="0.4448316991329193 0.49165210127830505 0.5386440753936768 0.5198706984519958" diaginertia="2.3384206997434376e-06 1.9123181118629873e-05 1.9700737539096735e-05"/>
																				<geom name="right_2tip4_geom_collision_0_hii2_geh_phadist_gesamt_asm_ShapeIndexedFaceSet_001" type="mesh" pos="0.0 0.0 0.0" quat="1.0 0.0 0.0 0.0" mesh="hii2_geh_phadist_gesamt_asm" class="rollin-justin_collision"/>
																				<joint name="right_2tip4_joint" type="hinge" damping="1" pos="5.5005224407563244e-17 -5.805362650156002e-17 -4.720572319167747e-16" range="-0.17453299462795258 1.7627800703048706" axis="0.0 0.0 1.0"/>
																			</body>
																		</body>
																	</body>
																</body>
															</body>
															<body name="right_palm" pos="0.0 0.10109999775886536 -1.3877787807814457e-17" quat="9.381886343362567e-07 9.381827226206951e-07 0.7071045637130737 0.7071090340614319"/>
														</body>
													</body>
												</body>
											</body>
										</body>
									</body>
								</body>
								<body name="head1" pos="0.23499999940395355 0.08799999952316284 -2.3985006589770017e-23" quat="0.5000031590461731 0.5 0.4999968409538269 0.5">
									<inertial mass="0.34576472640037537" pos="0.08800528198480606 4.770113832819334e-07 1.5162755250930786" quat="0.7071066498756409 -0.0004667574248742312 -0.7071066498756409 -0.0004667580942623317" diaginertia="0.0003185742534697056 0.0029316951986402273 0.0029531472828239202"/>
									<geom name="head1_geom_collision_0_head_link1_ShapeIndexedFaceSet" type="mesh" pos="0.0 0.0 0.054999999701976776" quat="1.0 0.0 0.0 0.0" mesh="head1" material="Material_001" class="rollin-justin_collision"/>
									<joint name="head1_joint" type="hinge" damping="1" pos="7.264003376279032e-22 1.1102239510674426e-16 1.38770855314744e-17" range="-0.785398006439209 0.785398006439209" axis="0.0 0.0 1.0"/>
									<body name="head2" pos="2.7755575615628914e-17 0.0 0.0" quat="0.7071090340614319 -0.7071045637130737 -2.994756567240617e-22 8.765023672926565e-22">
										<inertial mass="8.571843147277832" pos="0.12576240301132202 1.1199107348147663e-06 1.68004310131073" quat="0.7857056856155396 0.0001402134366799146 -0.00010025411756942049 -0.6186004281044006" diaginertia="0.04123448207974434 0.2622269093990326 0.27076107263565063"/>
										<geom name="head2_geom_collision_0_Head_Ch" type="mesh" pos="0.0 0.0 0.0" quat="1.0 0.0 0.0 0.0" mesh="head2" material="material_8" class="rollin-justin_collision"/>
										<joint name="head2_joint" type="hinge" damping="1" pos="-2.7755575615628914e-17 1.756038327595333e-22 1.1110059107113177e-27" range="-0.43633201718330383 0.785398006439209" axis="0.0 0.0 1.0"/>
									</body>
								</body>
							</body>
						</body>
					</body>
				</body>
			</body>
		</body>
	</worldbody>
	<equality/>
</mujoco>
