<?xml version="1.0" ?>
<mujoco model="crane">
	<compiler meshdir="../meshes/" angle="radian" autolimits="true" balanceinertia="true" boundmass="0.000001" boundinertia="0.000001"/>
	<default>
		<default class="visual">
			<geom contype="0" conaffinity="0"/>
		</default>
		<default class="collision">
			<geom rgba="1.0 0.0 0.0 0.0" />
		</default>
	</default>
	<asset>
		<mesh name="lkw_fahrerkabine_rote_teile_visual" file="visual/lkw_fahrerkabine_rote_teile.stl"/>
		<mesh name="lkw_fahrerkabine_rote_teile_collision" file="collision/lkw_fahrerkabine_rote_teile.stl"/>
		<mesh name="lkw_vorderraeder_graue_teile_visual" file="visual/lkw_vorderraeder_graue_teile.stl"/>
		<mesh name="lkw_hinterraeder_schwarze_teile_collision" file="collision/lkw_hinterraeder_schwarze_teile.stl"/>
		<mesh name="lkw_hinterraeder_schwarze_teile_visual" file="visual/lkw_hinterraeder_schwarze_teile.stl"/>
		<mesh name="lkw_kotfluegel_vorne_rot_visual" file="visual/lkw_kotfluegel_vorne_rot.stl"/>
		<mesh name="lkw_tank_visual" file="visual/lkw_tank.stl"/>
		<mesh name="lkw_rungen_002_collision" file="collision/lkw_rungen_002.stl"/>
		<mesh name="lkw_rungen_010_collision" file="collision/lkw_rungen_010.stl"/>
		<mesh name="lkw_rungen_006_collision" file="collision/lkw_rungen_006.stl"/>
		<mesh name="lkw_rungen_005_collision" file="collision/lkw_rungen_005.stl"/>
		<mesh name="lkw_rungen_003_collision" file="collision/lkw_rungen_003.stl"/>
		<mesh name="lkw_rungen_004_collision" file="collision/lkw_rungen_004.stl"/>
		<mesh name="lkw_rungen_001_collision" file="collision/lkw_rungen_001.stl"/>
		<mesh name="lkw_rungen_visual" file="visual/lkw_rungen.stl"/>
		<mesh name="lkw_rungen_009_collision" file="collision/lkw_rungen_009.stl"/>
		<mesh name="lkw_rungen_007_collision" file="collision/lkw_rungen_007.stl"/>
		<mesh name="lkw_rungen_008_collision" file="collision/lkw_rungen_008.stl"/>
		<mesh name="support_front_visual" file="visual/support_front.stl"/>
		<mesh name="support_front_collision" file="collision/support_front.stl"/>
		<mesh name="lkw_vorderachse_und_fahrerkabine_schwarze_teile_visual" file="visual/lkw_vorderachse_und_fahrerkabine_schwarze_teile.stl"/>
		<mesh name="lkw_vorderachse_und_fahrerkabine_schwarze_teile_collision" file="collision/lkw_vorderachse_und_fahrerkabine_schwarze_teile.stl"/>
		<mesh name="lkw_hinterraeder_graue_teile_visual" file="visual/lkw_hinterraeder_graue_teile.stl"/>
		<mesh name="lkw_kotfluegel_hinten_schwarz_visual" file="visual/lkw_kotfluegel_hinten_schwarz.stl"/>
		<mesh name="mounting_base_visual" file="visual/mounting_base.stl"/>
		<mesh name="mounting_base_collision" file="collision/mounting_base.stl"/>
		<mesh name="lkw_fahrerkabine_weisse_teile_visual" file="visual/lkw_fahrerkabine_weisse_teile.stl"/>
		<mesh name="lkw_ladeflaeche_mit_rammschutz_seitlich_001_collision" file="collision/lkw_ladeflaeche_mit_rammschutz_seitlich_001.stl"/>
		<mesh name="lkw_ladeflaeche_mit_rammschutz_seitlich_002_collision" file="collision/lkw_ladeflaeche_mit_rammschutz_seitlich_002.stl"/>
		<mesh name="lkw_ladeflaeche_mit_rammschutz_seitlich_003_collision" file="collision/lkw_ladeflaeche_mit_rammschutz_seitlich_003.stl"/>
		<mesh name="lkw_ladeflaeche_mit_rammschutz_seitlich_004_collision" file="collision/lkw_ladeflaeche_mit_rammschutz_seitlich_004.stl"/>
		<mesh name="lkw_ladeflaeche_mit_rammschutz_seitlich_005_collision" file="collision/lkw_ladeflaeche_mit_rammschutz_seitlich_005.stl"/>
		<mesh name="lkw_ladeflaeche_mit_rammschutz_seitlich_visual" file="visual/lkw_ladeflaeche_mit_rammschutz_seitlich.stl"/>
		<mesh name="slewing_column_collision" file="collision/slewing_column.stl"/>
		<mesh name="slewing_column_visual" file="visual/slewing_column.stl"/>
		<mesh name="control_box_visual" file="visual/control_box.stl"/>
		<mesh name="boom_visual" file="visual/boom.stl"/>
		<mesh name="boom_collision" file="collision/boom.stl"/>
		<mesh name="arm_001_collision" file="collision/arm_001.stl"/>
		<mesh name="arm_visual" file="visual/arm.stl"/>
		<mesh name="arm_004_collision" file="collision/arm_004.stl"/>
		<mesh name="arm_003_collision" file="collision/arm_003.stl"/>
		<mesh name="arm_002_collision" file="collision/arm_002.stl"/>
		<mesh name="outer_telescope_002_collision" file="collision/outer_telescope_002.stl"/>
		<mesh name="outer_telescope_001_collision" file="collision/outer_telescope_001.stl"/>
		<mesh name="outer_telescope_003_collision" file="collision/outer_telescope_003.stl"/>
		<mesh name="outer_telescope_visual" file="visual/outer_telescope.stl"/>
		<mesh name="outer_telescope_004_collision" file="collision/outer_telescope_004.stl"/>
		<mesh name="inner_telescope_collision" file="collision/inner_telescope.stl"/>
		<mesh name="inner_telescope_visual" file="visual/inner_telescope.stl"/>
		<mesh name="double_joint_link_visual" file="visual/double_joint_link.stl"/>
		<mesh name="double_joint_link_collision" file="collision/double_joint_link.stl"/>
		<mesh name="rotator_upper_part_visual" file="visual/rotator_upper_part.stl"/>
		<mesh name="rotator_upper_part_collision" file="collision/rotator_upper_part.stl"/>
		<mesh name="pincer_frame_visual" file="visual/pincer_frame.stl"/>
		<mesh name="pincer_frame_collision" file="collision/pincer_frame.stl"/>
		<mesh name="inner_jaw_013_collision" file="collision/inner_jaw_013.stl"/>
		<mesh name="inner_jaw_003_collision" file="collision/inner_jaw_003.stl"/>
		<mesh name="inner_jaw_002_collision" file="collision/inner_jaw_002.stl"/>
		<mesh name="inner_jaw_015_collision" file="collision/inner_jaw_015.stl"/>
		<mesh name="inner_jaw_011_collision" file="collision/inner_jaw_011.stl"/>
		<mesh name="inner_jaw_005_collision" file="collision/inner_jaw_005.stl"/>
		<mesh name="inner_jaw_012_collision" file="collision/inner_jaw_012.stl"/>
		<mesh name="inner_jaw_007_collision" file="collision/inner_jaw_007.stl"/>
		<mesh name="inner_jaw_008_collision" file="collision/inner_jaw_008.stl"/>
		<mesh name="inner_jaw_visual" file="visual/inner_jaw.stl"/>
		<mesh name="inner_jaw_004_collision" file="collision/inner_jaw_004.stl"/>
		<mesh name="inner_jaw_009_collision" file="collision/inner_jaw_009.stl"/>
		<mesh name="inner_jaw_010_collision" file="collision/inner_jaw_010.stl"/>
		<mesh name="inner_jaw_014_collision" file="collision/inner_jaw_014.stl"/>
		<mesh name="inner_jaw_006_collision" file="collision/inner_jaw_006.stl"/>
		<mesh name="inner_jaw_001_collision" file="collision/inner_jaw_001.stl"/>
		<mesh name="outer_jaw_014_collision" file="collision/outer_jaw_014.stl"/>
		<mesh name="outer_jaw_visual" file="visual/outer_jaw.stl"/>
		<mesh name="outer_jaw_002_collision" file="collision/outer_jaw_002.stl"/>
		<mesh name="outer_jaw_005_collision" file="collision/outer_jaw_005.stl"/>
		<mesh name="outer_jaw_011_collision" file="collision/outer_jaw_011.stl"/>
		<mesh name="outer_jaw_007_collision" file="collision/outer_jaw_007.stl"/>
		<mesh name="outer_jaw_013_collision" file="collision/outer_jaw_013.stl"/>
		<mesh name="outer_jaw_001_collision" file="collision/outer_jaw_001.stl"/>
		<mesh name="outer_jaw_003_collision" file="collision/outer_jaw_003.stl"/>
		<mesh name="outer_jaw_008_collision" file="collision/outer_jaw_008.stl"/>
		<mesh name="outer_jaw_009_collision" file="collision/outer_jaw_009.stl"/>
		<mesh name="outer_jaw_010_collision" file="collision/outer_jaw_010.stl"/>
		<mesh name="outer_jaw_012_collision" file="collision/outer_jaw_012.stl"/>
		<mesh name="outer_jaw_015_collision" file="collision/outer_jaw_015.stl"/>
		<mesh name="outer_jaw_004_collision" file="collision/outer_jaw_004.stl"/>
		<mesh name="outer_jaw_006_collision" file="collision/outer_jaw_006.stl"/>
	</asset>
	<worldbody>
		<body name="crane" pos="0.0 0.0 0.0" quat="1.0 0.0 0.0 0.0">
			<freejoint/>
			<body name="truck_cab" pos="0.0 0.0 0.52" quat="1.0 0.0 0.0 0.0">
				<geom name="truck_cab_visual_0" pos="0.0 0.0 0.0" quat="1.0 0.0 0.0 0.0" class="visual" type="mesh" mesh="lkw_fahrerkabine_rote_teile_visual"/>
				<geom name="truck_cab_collision_0" pos="0.0 0.0 0.0" quat="1.0 0.0 0.0 0.0" class="collision" type="mesh" mesh="lkw_fahrerkabine_rote_teile_collision"/>
				<body name="tr_grey" pos="0.0 0.0 0.0" quat="1.0 0.0 0.0 0.0">
					<geom name="tr_grey_visual_0" pos="0.0 0.0 0.0" quat="1.0 0.0 0.0 0.0" class="visual" type="mesh" mesh="lkw_vorderraeder_graue_teile_visual"/>
				</body>
				<body name="tr_rr_wheels" pos="0.0 0.0 0.0" quat="1.0 0.0 0.0 0.0">
					<geom name="tr_rr_wheels_collision_0" pos="-3.7 0.0 0.0" quat="1.0 0.0 0.0 0.0" class="collision" type="mesh" mesh="lkw_hinterraeder_schwarze_teile_collision"/>
					<geom name="tr_rr_wheels_visual_0" pos="-3.7 0.0 0.0" quat="1.0 0.0 0.0 0.0" class="visual" type="mesh" mesh="lkw_hinterraeder_schwarze_teile_visual"/>
				</body>
				<body name="cab_fender" pos="0.0 0.0 0.0" quat="1.0 0.0 0.0 0.0">
					<geom name="cab_fender_visual_0" pos="0.0 0.0 0.0" quat="1.0 0.0 0.0 0.0" class="visual" type="mesh" mesh="lkw_kotfluegel_vorne_rot_visual"/>
				</body>
				<body name="tr_tank" pos="0.0 0.0 0.0" quat="1.0 0.0 0.0 0.0">
					<geom name="tr_tank_visual_0" pos="0.0 0.0 0.0" quat="1.0 0.0 0.0 0.0" class="visual" type="mesh" mesh="lkw_tank_visual"/>
				</body>
				<body name="tr_rungen" pos="0.0 0.0 0.0" quat="1.0 0.0 0.0 0.0">
					<geom name="tr_rungen_collision_1" pos="0.0 0.0 0.0" quat="1.0 0.0 0.0 0.0" class="collision" type="mesh" mesh="lkw_rungen_002_collision"/>
					<geom name="tr_rungen_collision_9" pos="0.0 0.0 0.0" quat="1.0 0.0 0.0 0.0" class="collision" type="mesh" mesh="lkw_rungen_010_collision"/>
					<geom name="tr_rungen_collision_5" pos="0.0 0.0 0.0" quat="1.0 0.0 0.0 0.0" class="collision" type="mesh" mesh="lkw_rungen_006_collision"/>
					<geom name="tr_rungen_collision_4" pos="0.0 0.0 0.0" quat="1.0 0.0 0.0 0.0" class="collision" type="mesh" mesh="lkw_rungen_005_collision"/>
					<geom name="tr_rungen_collision_2" pos="0.0 0.0 0.0" quat="1.0 0.0 0.0 0.0" class="collision" type="mesh" mesh="lkw_rungen_003_collision"/>
					<geom name="tr_rungen_collision_3" pos="0.0 0.0 0.0" quat="1.0 0.0 0.0 0.0" class="collision" type="mesh" mesh="lkw_rungen_004_collision"/>
					<geom name="tr_rungen_collision_0" pos="0.0 0.0 0.0" quat="1.0 0.0 0.0 0.0" class="collision" type="mesh" mesh="lkw_rungen_001_collision"/>
					<geom name="tr_rungen_visual_0" pos="0.0 0.0 0.0" quat="1.0 0.0 0.0 0.0" class="visual" type="mesh" mesh="lkw_rungen_visual"/>
					<geom name="tr_rungen_collision_8" pos="0.0 0.0 0.0" quat="1.0 0.0 0.0 0.0" class="collision" type="mesh" mesh="lkw_rungen_009_collision"/>
					<geom name="tr_rungen_collision_6" pos="0.0 0.0 0.0" quat="1.0 0.0 0.0 0.0" class="collision" type="mesh" mesh="lkw_rungen_007_collision"/>
					<geom name="tr_rungen_collision_7" pos="0.0 0.0 0.0" quat="1.0 0.0 0.0 0.0" class="collision" type="mesh" mesh="lkw_rungen_008_collision"/>
				</body>
				<body name="support_front" pos="-0.8 0.35 0.6207" quat="-2.0510342851533115e-10 0.0 0.0 1.0">
					<geom name="support_front_visual_0" pos="-0.315 0.35 0.1485" quat="1.0 0.0 0.0 0.0" class="visual" type="mesh" mesh="support_front_visual"/>
					<geom name="support_front_collision_0" pos="-0.315 0.35 0.1485" quat="1.0 0.0 0.0 0.0" class="collision" type="mesh" mesh="support_front_collision"/>
				</body>
				<body name="tr_black" pos="0.0 0.0 0.0" quat="1.0 0.0 0.0 0.0">
					<geom name="tr_black_visual_0" pos="0.0 0.0 0.0" quat="1.0 0.0 0.0 0.0" class="visual" type="mesh" mesh="lkw_vorderachse_und_fahrerkabine_schwarze_teile_visual"/>
					<geom name="tr_black_collision_0" pos="0.0 0.0 0.0" quat="1.0 0.0 0.0 0.0" class="collision" type="mesh" mesh="lkw_vorderachse_und_fahrerkabine_schwarze_teile_collision"/>
				</body>
				<body name="tr_rr_rims" pos="0.0 0.0 0.0" quat="1.0 0.0 0.0 0.0">
					<geom name="tr_rr_rims_visual_0" pos="-3.7 0.0 0.0" quat="1.0 0.0 0.0 0.0" class="visual" type="mesh" mesh="lkw_hinterraeder_graue_teile_visual"/>
				</body>
				<body name="tr_rr_fender" pos="0.0 0.0 0.0" quat="1.0 0.0 0.0 0.0">
					<geom name="tr_rr_fender_visual_0" pos="0.0 0.0 0.0" quat="1.0 0.0 0.0 0.0" class="visual" type="mesh" mesh="lkw_kotfluegel_hinten_schwarz_visual"/>
				</body>
				<body name="K0_mounting_base" pos="-6.93852 0.35 0.6207" quat="-2.0510342851533115e-10 0.0 0.0 1.0">
					<geom name="K0_mounting_base_visual_0" pos="-0.315 0.35 0.1485" quat="1.0 0.0 0.0 0.0" class="visual" type="mesh" mesh="mounting_base_visual"/>
					<geom name="K0_mounting_base_collision_0" pos="-0.315 0.35 0.1485" quat="1.0 0.0 0.0 0.0" class="collision" type="mesh" mesh="mounting_base_collision"/>
					<body name="moved_with_q1" pos="0.0 0.0 0.0" quat="1.0 0.0 0.0 0.0">
						<joint name="theta1_slewing_joint" pos="0.0 0.0 0.0" type="hinge" range="-3.7099999134770023 3.7099999134770023" axis="0.0 0.0 1.0"/>
						<body name="K1_slewing_column" pos="-0.17999999999999972 0.0 2.425" quat="0.7071067811140325 0.7071067812590626 0.0 0.0">
							<geom name="K1_slewing_column_collision_0" pos="0.18 -2.3652 0.0" quat="1.0 0.0 0.0 0.0" class="collision" type="mesh" mesh="slewing_column_collision"/>
							<geom name="K1_slewing_column_visual_0" pos="0.18 -2.3652 0.0" quat="1.0 0.0 0.0 0.0" class="visual" type="mesh" mesh="slewing_column_visual"/>
							<body name="control_box" pos="0.03000000000000025 -0.9100000000000001 -0.5000000000000001" quat="3.2759568508397764e-05 -3.275641303610518e-05 0.7071408362725098 0.7070727229427278">
								<geom name="control_box_visual_0" pos="0.0 0.0 0.0" quat="1.0 0.0 0.0 0.0" class="visual" type="mesh" mesh="control_box_visual"/>
								<geom name="control_box_collision_0" pos="0.0 -0.04 0.0" quat="1.0 0.0 0.0 0.0" class="collision" type="box" size="0.4 0.225 0.55"/>
							</body>
							<body name="moved_with_q2" pos="0.0 0.0 0.0" quat="1.0 0.0 0.0 0.0">
								<joint name="theta2_boom_joint" pos="0.0 0.0 -0.0" type="hinge" range="-1.2000000140073657 1.563000055861744" axis="0.0 0.0 1.0"/>
								<body name="K2_boom" pos="3.4928833300000006 0.0 -5.551115123125783e-17" quat="1.0 0.0 0.0 0.0">
									<geom name="K2_boom_visual_0" pos="-3.49288333 0.0 0.0" quat="0.9987192078450507 0.0 0.0 -0.050595887988594" class="visual" type="mesh" mesh="boom_visual"/>
									<geom name="K2_boom_collision_0" pos="-3.49288333 0.0 0.0" quat="0.9987192078450507 0.0 0.0 -0.050595887988594" class="collision" type="mesh" mesh="boom_collision"/>
									<body name="moved_with_q3" pos="0.0 0.0 0.0" quat="1.0 0.0 0.0 0.0">
										<joint name="theta3_arm_joint" pos="0.0 0.0 -0.0" type="hinge" range="-0.9100000139512037 4.5999998539578195" axis="0.0 0.0 1.0"/>
										<body name="K3_arm" pos="-0.39250000000000007 0.0 5.551115123125783e-17" quat="0.7071067811140325 0.7071067812590626 0.0 0.0">
											<geom name="K3_arm_collision_0" pos="0.3925 0.0 0.0" quat="1.0 0.0 0.0 0.0" class="collision" type="mesh" mesh="arm_001_collision"/>
											<geom name="K3_arm_visual_0" pos="0.3925 0.0 0.0" quat="1.0 0.0 0.0 0.0" class="visual" type="mesh" mesh="arm_visual"/>
											<geom name="K3_arm_collision_3" pos="0.3925 0.0 0.0" quat="1.0 0.0 0.0 0.0" class="collision" type="mesh" mesh="arm_004_collision"/>
											<geom name="K3_arm_collision_2" pos="0.3925 0.0 0.0" quat="1.0 0.0 0.0 0.0" class="collision" type="mesh" mesh="arm_003_collision"/>
											<geom name="K3_arm_collision_1" pos="0.3925 0.0 0.0" quat="1.0 0.0 0.0 0.0" class="collision" type="mesh" mesh="arm_002_collision"/>
											<body name="moved_with_q4" pos="0.0 0.0 0.0" quat="1.0 0.0 0.0 0.0">
												<joint name="q4_big_telescope" pos="0.0 0.0 0.0" type="slide" range="0.0 2.2360000610351562" axis="0.0 0.0 1.0"/>
												<body name="K4_outer_telescope" pos="0.0 0.0 3.157001602823" quat="1.0 0.0 0.0 0.0">
													<geom name="K4_outer_telescope_collision_1" pos="0.2905 0.0 -0.0712" quat="1.0 0.0 0.0 0.0" class="collision" type="mesh" mesh="outer_telescope_002_collision"/>
													<geom name="K4_outer_telescope_collision_0" pos="0.2905 0.0 -0.0712" quat="1.0 0.0 0.0 0.0" class="collision" type="mesh" mesh="outer_telescope_001_collision"/>
													<geom name="K4_outer_telescope_collision_2" pos="0.2905 0.0 -0.0712" quat="1.0 0.0 0.0 0.0" class="collision" type="mesh" mesh="outer_telescope_003_collision"/>
													<geom name="K4_outer_telescope_visual_0" pos="0.2905 0.0 -0.0712" quat="1.0 0.0 0.0 0.0" class="visual" type="mesh" mesh="outer_telescope_visual"/>
													<geom name="K4_outer_telescope_collision_3" pos="0.2905 0.0 -0.0712" quat="1.0 0.0 0.0 0.0" class="collision" type="mesh" mesh="outer_telescope_004_collision"/>
													<body name="moved_with_q5" pos="0.0 0.0 0.0" quat="1.0 0.0 0.0 0.0">
														<joint name="q5_small_telescope" pos="0.0 0.0 0.0" type="slide" range="0.0 2.2360000610351562" axis="0.0 0.0 1.0"/>
														<body name="K5_inner_telescope" pos="0.0 0.0 0.0" quat="-0.7071067811140325 0.7071067812590626 0.0 0.0">
															<geom name="K5_inner_telescope_collision_0" pos="0.281 0.0 0.0" quat="1.0 0.0 0.0 0.0" class="collision" type="mesh" mesh="inner_telescope_collision"/>
															<geom name="K5_inner_telescope_visual_0" pos="0.281 0.0 0.0" quat="1.0 0.0 0.0 0.0" class="visual" type="mesh" mesh="inner_telescope_visual"/>
															<body name="moved_with_q6" pos="0.0 0.0 0.0" quat="1.0 0.0 0.0 0.0">
																<joint name="theta6_tip_joint" pos="0.0 0.0 -0.0" type="hinge" range="-1.570000041628963 1.570000041628963" axis="0.0 0.0 1.0"/>
																<body name="K6_double_joint_link" pos="-0.2129999999999992 0.0 0.0" quat="-0.7071067811140325 0.7071067812590626 0.0 0.0">
																	<geom name="K6_double_joint_link_visual_0" pos="0.0 0.0 0.0" quat="1.0 0.0 0.0 0.0" class="visual" type="mesh" mesh="double_joint_link_visual"/>
																	<geom name="K6_double_joint_link_collision_0" pos="0.0 0.0 0.0" quat="1.0 0.0 0.0 0.0" class="collision" type="mesh" mesh="double_joint_link_collision"/>
																	<body name="moved_with_q7" pos="0.0 0.0 0.0" quat="1.0 0.0 0.0 0.0">
																		<joint name="theta7_tilt_joint" pos="0.0 0.0 0.0" type="hinge" range="0.7853980302393938 2.3561899628184917" axis="0.0 0.0 1.0"/>
																		<body name="K7_rotator_upper_part" pos="0.0 0.0 0.0" quat="-0.7071067811140325 0.7071067812590626 0.0 0.0">
																			<geom name="K7_rotator_upper_part_visual_0" pos="0.0 0.0 0.113385" quat="1.0 0.0 0.0 0.0" class="visual" type="mesh" mesh="rotator_upper_part_visual"/>
																			<geom name="K7_rotator_upper_part_collision_0" pos="0.0 0.0 0.113385" quat="1.0 0.0 0.0 0.0" class="collision" type="mesh" mesh="rotator_upper_part_collision"/>
																			<body name="moved_with_q8" pos="0.0 0.0 0.0" quat="1.0 0.0 0.0 0.0">
																				<joint name="theta8_rotator_joint" pos="0.0 0.0 0.0" axis="0.0 0.0 1.0"/>
																				<body name="K8_tool_center_point" pos="0.0 0.0 0.578" quat="1.0 0.0 0.0 0.0">
																					<geom name="K8_tool_center_point_visual_0" pos="0.0 0.0 -0.454717" quat="1.0 0.0 0.0 0.0" class="visual" type="mesh" mesh="pincer_frame_visual"/>
																					<geom name="K8_tool_center_point_collision_0" pos="0.0 0.0 -0.454717" quat="1.0 0.0 0.0 0.0" class="collision" type="mesh" mesh="pincer_frame_collision"/>
																					<body name="K11" pos="0.0 0.3248 2.7755575615628914e-17" quat="0.49999999989744826 0.5 0.5000000001025517 0.5">
																						<body name="moved_with_q12" pos="-1.3877787807814457e-17 0.0 0.0" quat="1.0 -2.1562786888997945e-30 0.0 0.0">
																							<joint name="theta12_inner_jaw_joint" pos="2.8463827093604277e-27 2.8463802397415088e-27 -1.3877787807814457e-17" type="hinge" range="-3.000000101597441 3.000000101597441" axis="0.0 0.0 1.0"/>
																							<body name="K12_inner_jaw" pos="0.8566 0.0 -1.7763568394002505e-15" quat="1.0 -2.1562786888997945e-30 0.0 0.0">
																								<geom name="K12_inner_jaw_collision_12" pos="-0.5663 0.4813 0.0" quat="-0.7064682714200307 -0.03004299210485709 0.7064682715649296 -0.030042992098695164" class="collision" type="mesh" mesh="inner_jaw_013_collision"/>
																								<geom name="K12_inner_jaw_collision_2" pos="-0.5663 0.4813 0.0" quat="-0.7064682714200307 -0.03004299210485709 0.7064682715649296 -0.030042992098695164" class="collision" type="mesh" mesh="inner_jaw_003_collision"/>
																								<geom name="K12_inner_jaw_collision_1" pos="-0.5663 0.4813 0.0" quat="-0.7064682714200307 -0.03004299210485709 0.7064682715649296 -0.030042992098695164" class="collision" type="mesh" mesh="inner_jaw_002_collision"/>
																								<geom name="K12_inner_jaw_collision_14" pos="-0.5663 0.4813 0.0" quat="-0.7064682714200307 -0.03004299210485709 0.7064682715649296 -0.030042992098695164" class="collision" type="mesh" mesh="inner_jaw_015_collision"/>
																								<geom name="K12_inner_jaw_collision_10" pos="-0.5663 0.4813 0.0" quat="-0.7064682714200307 -0.03004299210485709 0.7064682715649296 -0.030042992098695164" class="collision" type="mesh" mesh="inner_jaw_011_collision"/>
																								<geom name="K12_inner_jaw_collision_4" pos="-0.5663 0.4813 0.0" quat="-0.7064682714200307 -0.03004299210485709 0.7064682715649296 -0.030042992098695164" class="collision" type="mesh" mesh="inner_jaw_005_collision"/>
																								<geom name="K12_inner_jaw_collision_11" pos="-0.5663 0.4813 0.0" quat="-0.7064682714200307 -0.03004299210485709 0.7064682715649296 -0.030042992098695164" class="collision" type="mesh" mesh="inner_jaw_012_collision"/>
																								<geom name="K12_inner_jaw_collision_6" pos="-0.5663 0.4813 0.0" quat="-0.7064682714200307 -0.03004299210485709 0.7064682715649296 -0.030042992098695164" class="collision" type="mesh" mesh="inner_jaw_007_collision"/>
																								<geom name="K12_inner_jaw_collision_7" pos="-0.5663 0.4813 0.0" quat="-0.7064682714200307 -0.03004299210485709 0.7064682715649296 -0.030042992098695164" class="collision" type="mesh" mesh="inner_jaw_008_collision"/>
																								<geom name="K12_inner_jaw_visual_0" pos="-0.5663 0.4813 0.0" quat="-0.7064682714200307 -0.03004299210485709 0.7064682715649296 -0.030042992098695164" class="visual" type="mesh" mesh="inner_jaw_visual"/>
																								<geom name="K12_inner_jaw_collision_3" pos="-0.5663 0.4813 0.0" quat="-0.7064682714200307 -0.03004299210485709 0.7064682715649296 -0.030042992098695164" class="collision" type="mesh" mesh="inner_jaw_004_collision"/>
																								<geom name="K12_inner_jaw_collision_8" pos="-0.5663 0.4813 0.0" quat="-0.7064682714200307 -0.03004299210485709 0.7064682715649296 -0.030042992098695164" class="collision" type="mesh" mesh="inner_jaw_009_collision"/>
																								<geom name="K12_inner_jaw_collision_9" pos="-0.5663 0.4813 0.0" quat="-0.7064682714200307 -0.03004299210485709 0.7064682715649296 -0.030042992098695164" class="collision" type="mesh" mesh="inner_jaw_010_collision"/>
																								<geom name="K12_inner_jaw_collision_13" pos="-0.5663 0.4813 0.0" quat="-0.7064682714200307 -0.03004299210485709 0.7064682715649296 -0.030042992098695164" class="collision" type="mesh" mesh="inner_jaw_014_collision"/>
																								<geom name="K12_inner_jaw_collision_5" pos="-0.5663 0.4813 0.0" quat="-0.7064682714200307 -0.03004299210485709 0.7064682715649296 -0.030042992098695164" class="collision" type="mesh" mesh="inner_jaw_006_collision"/>
																								<geom name="K12_inner_jaw_collision_0" pos="-0.5663 0.4813 0.0" quat="-0.7064682714200307 -0.03004299210485709 0.7064682715649296 -0.030042992098695164" class="collision" type="mesh" mesh="inner_jaw_001_collision"/>
																							</body>
																						</body>
																					</body>
																					<body name="K9" pos="0.0 -0.3401799999999999 0.0" quat="-0.49999999989744826 -0.5 0.5000000001025517 0.5">
																						<body name="moved_with_q10" pos="0.0 -2.7755575615628914e-17 0.0" quat="1.0 -2.1562756796342564e-30 0.0 0.0">
																							<joint name="theta10_outer_jaw_joint" pos="-5.692763875057885e-27 -2.7755575615628914e-17 1.7078294398412643e-26" type="hinge" range="0.0 3.000000101597441" axis="0.0 0.0 1.0"/>
																							<body name="K10_outer_jaw" pos="0.8566000000000001 0.0 1.7763568394002505e-15" quat="1.0 -2.1562756796342564e-30 0.0 0.0">
																								<geom name="K10_outer_jaw_collision_13" pos="-0.5509339 0.47161 0.0" quat="0.706860923855094 -0.018644951711224565 0.7068609240000736 0.018644951707400423" class="collision" type="mesh" mesh="outer_jaw_014_collision"/>
																								<geom name="K10_outer_jaw_visual_0" pos="-0.5509339 0.47161 0.0" quat="0.706860923855094 -0.018644951711224572 0.7068609240000736 0.01864495170740042" class="visual" type="mesh" mesh="outer_jaw_visual"/>
																								<geom name="K10_outer_jaw_collision_1" pos="-0.5509339 0.47161 0.0" quat="0.706860923855094 -0.018644951711224565 0.7068609240000736 0.018644951707400423" class="collision" type="mesh" mesh="outer_jaw_002_collision"/>
																								<geom name="K10_outer_jaw_collision_4" pos="-0.5509339 0.47161 0.0" quat="0.706860923855094 -0.018644951711224565 0.7068609240000736 0.018644951707400423" class="collision" type="mesh" mesh="outer_jaw_005_collision"/>
																								<geom name="K10_outer_jaw_collision_10" pos="-0.5509339 0.47161 0.0" quat="0.706860923855094 -0.018644951711224565 0.7068609240000736 0.018644951707400423" class="collision" type="mesh" mesh="outer_jaw_011_collision"/>
																								<geom name="K10_outer_jaw_collision_6" pos="-0.5509339 0.47161 0.0" quat="0.706860923855094 -0.018644951711224565 0.7068609240000736 0.018644951707400423" class="collision" type="mesh" mesh="outer_jaw_007_collision"/>
																								<geom name="K10_outer_jaw_collision_12" pos="-0.5509339 0.47161 0.0" quat="0.706860923855094 -0.018644951711224565 0.7068609240000736 0.018644951707400423" class="collision" type="mesh" mesh="outer_jaw_013_collision"/>
																								<geom name="K10_outer_jaw_collision_0" pos="-0.5509339 0.47161 0.0" quat="0.706860923855094 -0.018644951711224565 0.7068609240000736 0.018644951707400423" class="collision" type="mesh" mesh="outer_jaw_001_collision"/>
																								<geom name="K10_outer_jaw_collision_2" pos="-0.5509339 0.47161 0.0" quat="0.706860923855094 -0.018644951711224565 0.7068609240000736 0.018644951707400423" class="collision" type="mesh" mesh="outer_jaw_003_collision"/>
																								<geom name="K10_outer_jaw_collision_7" pos="-0.5509339 0.47161 0.0" quat="0.706860923855094 -0.018644951711224565 0.7068609240000736 0.018644951707400423" class="collision" type="mesh" mesh="outer_jaw_008_collision"/>
																								<geom name="K10_outer_jaw_collision_8" pos="-0.5509339 0.47161 0.0" quat="0.706860923855094 -0.018644951711224565 0.7068609240000736 0.018644951707400423" class="collision" type="mesh" mesh="outer_jaw_009_collision"/>
																								<geom name="K10_outer_jaw_collision_9" pos="-0.5509339 0.47161 0.0" quat="0.706860923855094 -0.018644951711224565 0.7068609240000736 0.018644951707400423" class="collision" type="mesh" mesh="outer_jaw_010_collision"/>
																								<geom name="K10_outer_jaw_collision_11" pos="-0.5509339 0.47161 0.0" quat="0.706860923855094 -0.018644951711224565 0.7068609240000736 0.018644951707400423" class="collision" type="mesh" mesh="outer_jaw_012_collision"/>
																								<geom name="K10_outer_jaw_collision_14" pos="-0.5509339 0.47161 0.0" quat="0.706860923855094 -0.018644951711224565 0.7068609240000736 0.018644951707400423" class="collision" type="mesh" mesh="outer_jaw_015_collision"/>
																								<geom name="K10_outer_jaw_collision_3" pos="-0.5509339 0.47161 0.0" quat="0.706860923855094 -0.018644951711224565 0.7068609240000736 0.018644951707400423" class="collision" type="mesh" mesh="outer_jaw_004_collision"/>
																								<geom name="K10_outer_jaw_collision_5" pos="-0.5509339 0.47161 0.0" quat="0.706860923855094 -0.018644951711224565 0.7068609240000736 0.018644951707400423" class="collision" type="mesh" mesh="outer_jaw_006_collision"/>
																							</body>
																						</body>
																					</body>
																				</body>
																			</body>
																		</body>
																	</body>
																</body>
															</body>
														</body>
													</body>
												</body>
											</body>
										</body>
									</body>
								</body>
							</body>
							<body name="hydraulic_block" pos="-0.2999999999999998 -0.7400000000000002 -5.551115123125783e-17" quat="0.9987502603949663 -1.5597328848292796e-19 -2.0938167711289532e-18 0.04997916927067833">
								<geom name="hydraulic_block_collision_0" pos="0.0 0.0 0.0" quat="1.0 0.0 0.0 0.0" class="collision" type="box" size="0.2 0.34 0.31"/>
								<geom name="hydraulic_block_visual_0" pos="0.0 0.0 0.0" quat="1.0 0.0 0.0 0.0" class="visual" type="box" size="0.2 0.34 0.31"/>
							</body>
						</body>
					</body>
				</body>
				<body name="tr_white" pos="0.0 0.0 0.0" quat="1.0 0.0 0.0 0.0">
					<geom name="tr_white_visual_0" pos="0.0 0.0 0.0" quat="1.0 0.0 0.0 0.0" class="visual" type="mesh" mesh="lkw_fahrerkabine_weisse_teile_visual"/>
				</body>
				<body name="tr_crane_frameplate" pos="-6.85 0.0 0.55" quat="1.0 0.0 0.0 0.0">
					<geom name="tr_crane_frameplate_visual_0" pos="0.0 0.0 0.0" quat="1.0 0.0 0.0 0.0" class="visual" type="box" size="0.475 0.355 0.09"/>
				</body>
				<body name="tr_bed" pos="0.0 0.0 0.0" quat="1.0 0.0 0.0 0.0">
					<geom name="tr_bed_collision_0" pos="0.0 0.0 0.0" quat="1.0 0.0 0.0 0.0" class="collision" type="mesh" mesh="lkw_ladeflaeche_mit_rammschutz_seitlich_001_collision"/>
					<geom name="tr_bed_collision_1" pos="0.0 0.0 0.0" quat="1.0 0.0 0.0 0.0" class="collision" type="mesh" mesh="lkw_ladeflaeche_mit_rammschutz_seitlich_002_collision"/>
					<geom name="tr_bed_collision_2" pos="0.0 0.0 0.0" quat="1.0 0.0 0.0 0.0" class="collision" type="mesh" mesh="lkw_ladeflaeche_mit_rammschutz_seitlich_003_collision"/>
					<geom name="tr_bed_collision_3" pos="0.0 0.0 0.0" quat="1.0 0.0 0.0 0.0" class="collision" type="mesh" mesh="lkw_ladeflaeche_mit_rammschutz_seitlich_004_collision"/>
					<geom name="tr_bed_collision_4" pos="0.0 0.0 0.0" quat="1.0 0.0 0.0 0.0" class="collision" type="mesh" mesh="lkw_ladeflaeche_mit_rammschutz_seitlich_005_collision"/>
					<geom name="tr_bed_visual_0" pos="0.0 0.0 0.0" quat="1.0 0.0 0.0 0.0" class="visual" type="mesh" mesh="lkw_ladeflaeche_mit_rammschutz_seitlich_visual"/>
				</body>
			</body>
		</body>
	</worldbody>

	<equality>
		<joint joint1="q4_big_telescope" joint2="q5_small_telescope" polycoef="0 1 0 0 0" name="equality1"/>
		<joint joint1="theta10_outer_jaw_joint" joint2="theta12_inner_jaw_joint" polycoef="0 1 0 0 0" name="equality2"/>
	</equality>
</mujoco>
