<?xml version="1.0" ?>
<robot name="gripper-2F-85" version="1.0">
  <link name="gripper-2F-85"/>
  <joint name="base_mount_joint" type="fixed">
    <origin xyz="0.0 0.0 0.007" rpy="0.0 0.0 0.0"/>
    <parent link="gripper-2F-85"/>
    <child link="base_mount"/>
  </joint>
  <link name="base_mount">
    <inertial>
      <origin xyz="-0.0003605835954658687 8.536274981452152e-05 -5.91993702983018e-05" rpy="0.010714340023696423 -1.5679504871368408 3.132357358932495"/>
      <mass value="0.1500028520822525"/>
      <inertia ixx="0.00010234548972221091" ixy="0.0" ixz="0.0" iyy="5.359968781704083e-05" iyz="0.0" izz="5.21717629453633e-05"/>
    </inertial>
    <visual name="Geom_0">
      <origin xyz="-0.0003605835954658687 8.536274981452152e-05 -5.91993702983018e-05" rpy="0.010714522562921047 -1.5679504871368408 3.132357120513916"/>
      <geometry>
        <mesh filename="file://../meshes/obj/base_mount.obj" scale="1.0 1.0 1.0"/>
      </geometry>
    </visual>
    <collision name="Geom_1">
      <origin xyz="-0.0003605835954658687 8.536274981452152e-05 -5.91993702983018e-05" rpy="0.010714522562921047 -1.5679504871368408 3.132357120513916"/>
      <geometry>
        <mesh filename="file://../meshes/stl/base_mount.stl" scale="1.0 1.0 1.0"/>
      </geometry>
    </collision>
  </link>
  <joint name="base_joint" type="fixed">
    <origin xyz="0.0 0.0 0.0038" rpy="0.0 0.0 -1.5707963705062866"/>
    <parent link="base_mount"/>
    <child link="base"/>
  </joint>
  <link name="base">
    <inertial>
      <origin xyz="0.0 -2.7039399355999194e-05 0.03546750172972679" rpy="-0.003056977642700076 0.0 0.0"/>
      <mass value="0.7774410247802734"/>
      <inertia ixx="0.00026028501451946795" ixy="0.0" ixz="0.0" iyy="0.00022538099437952042" iyz="0.0" izz="0.00015270800213329494"/>
    </inertial>
    <visual name="Geom_2">
      <origin xyz="9.197026429319521e-08 -2.703939208004158e-05 0.0354674831032753" rpy="-0.003056990448385477 7.76175497207987e-08 2.5390105292899534e-05"/>
      <geometry>
        <mesh filename="file://../meshes/obj/base.obj" scale="1.0 1.0 1.0"/>
      </geometry>
    </visual>
    <collision name="Geom_3">
      <origin xyz="9.197026429319521e-08 -2.703939208004158e-05 0.0354674831032753" rpy="-0.003056990448385477 7.76175497207987e-08 2.5390105292899534e-05"/>
      <geometry>
        <mesh filename="file://../meshes/stl/base.stl" scale="1.0 1.0 1.0"/>
      </geometry>
    </collision>
  </link>
  <joint name="right_driver_joint" type="revolute">
    <origin xyz="0.0 0.030601099133491516 0.05490399897098541" rpy="0.0 0.0 0.0"/>
    <axis xyz="1.0 0.0 0.0"/>
    <parent link="base"/>
    <child link="right_driver"/>
    <limit effort="1000.0" lower="0.0" upper="0.800000011920929" velocity="1000.0"/>
  </joint>
  <link name="right_driver">
    <inertial>
      <origin xyz="2.9693099107969134e-12 0.017754700034856796 0.0010731399524956942" rpy="1.6425151824951172 0.0 0.0"/>
      <mass value="0.008995629847049713"/>
      <inertia ixx="1.7235199720744276e-06" ixy="0.0" ixz="0.0" iyy="1.609059950169467e-06" iyz="0.0" izz="3.220060023068072e-07"/>
    </inertial>
    <visual name="Geom_4">
      <origin xyz="2.9693094771160444e-12 0.0177546925842762 0.0010731416987255216" rpy="1.6425158977508545 0.0 0.0"/>
      <geometry>
        <mesh filename="file://../meshes/obj/driver.obj" scale="1.0 1.0 1.0"/>
      </geometry>
    </visual>
    <collision name="Geom_5">
      <origin xyz="2.9693094771160444e-12 0.0177546925842762 0.0010731416987255216" rpy="1.6425158977508545 0.0 0.0"/>
      <geometry>
        <mesh filename="file://../meshes/stl/driver.stl" scale="1.0 1.0 1.0"/>
      </geometry>
    </collision>
  </link>
  <joint name="right_coupler_joint" type="revolute">
    <origin xyz="0.0 0.03150000050663948 -0.004100000020116568" rpy="0.0 0.0 0.0"/>
    <axis xyz="1.0 0.0 0.0"/>
    <parent link="right_driver"/>
    <child link="right_coupler"/>
    <limit effort="1000.0" lower="-1.5700000524520874" upper="0.0" velocity="1000.0"/>
  </joint>
  <link name="right_coupler">
    <inertial>
      <origin xyz="0.0 0.003012089990079403 0.023217499256134033" rpy="0.0 0.12903854250907898 1.5707963705062866"/>
      <mass value="0.01409740000963211"/>
      <inertia ixx="4.162060122325784e-06" ixy="0.0" ixz="0.0" iyy="3.5221598864154657e-06" iyz="0.0" izz="8.881310122887953e-07"/>
    </inertial>
    <visual name="Geom_6">
      <origin xyz="8.458042209322225e-13 0.00301208533346653 0.023217538371682167" rpy="1.399413406969249e-17 0.1290387511253357 1.5707963705062866"/>
      <geometry>
        <mesh filename="file://../meshes/obj/coupler.obj" scale="1.0 1.0 1.0"/>
      </geometry>
    </visual>
    <collision name="Geom_7">
      <origin xyz="8.458042209322225e-13 0.00301208533346653 0.023217538371682167" rpy="1.399413406969249e-17 0.1290387511253357 1.5707963705062866"/>
      <geometry>
        <mesh filename="file://../meshes/stl/coupler.stl" scale="1.0 1.0 1.0"/>
      </geometry>
    </collision>
  </link>
  <joint name="right_spring_link_joint" type="revolute">
    <origin xyz="-3.851859888774472e-34 0.013199999928474426 0.0608999989926815" rpy="0.0 0.0 0.0"/>
    <axis xyz="1.0 0.0 0.0"/>
    <parent link="base"/>
    <child link="right_spring_link"/>
    <limit effort="1000.0" lower="-0.296705961227417" upper="0.800000011920929" velocity="1000.0"/>
  </joint>
  <link name="right_spring_link">
    <inertial>
      <origin xyz="-8.650049565517293e-09 0.018162399530410767 0.021265799179673195" rpy="0.0 0.7068443298339844 1.5707963705062866"/>
      <mass value="0.022164199501276016"/>
      <inertia ixx="8.96852998266695e-06" ixy="0.0" ixz="0.0" iyy="6.717330052197212e-06" iyz="0.0" izz="2.6393099687993526e-06"/>
    </inertial>
    <visual name="Geom_8">
      <origin xyz="-8.650050453695712e-09 0.018162399530410767 0.02126581035554409" rpy="0.0 0.7068434953689575 1.5707963705062866"/>
      <geometry>
        <mesh filename="file://../meshes/obj/spring_link.obj" scale="1.0 1.0 1.0"/>
      </geometry>
    </visual>
    <collision name="Geom_9">
      <origin xyz="-8.650050453695712e-09 0.018162399530410767 0.02126581035554409" rpy="0.0 0.7068434953689575 1.5707963705062866"/>
      <geometry>
        <mesh filename="file://../meshes/stl/spring_link.stl" scale="1.0 1.0 1.0"/>
      </geometry>
    </collision>
  </link>
  <joint name="right_follower_joint" type="revolute">
    <origin xyz="0.0 0.054999999701976776 0.03750000149011612" rpy="0.0 0.0 0.0"/>
    <axis xyz="1.0 0.0 0.0"/>
    <parent link="right_spring_link"/>
    <child link="right_follower"/>
    <limit effort="1000.0" lower="-0.8726640343666077" upper="0.8726640343666077" velocity="1000.0"/>
  </joint>
  <link name="right_follower">
    <inertial>
      <origin xyz="0.0 -0.011045999825000763 0.012478600256145" rpy="0.32977840304374695 0.0 0.0"/>
      <mass value="0.012522200122475624"/>
      <inertia ixx="2.674149982340168e-06" ixy="0.0" ixz="0.0" iyy="2.4558999029977713e-06" iyz="0.0" izz="6.02030979734991e-07"/>
    </inertial>
    <visual name="Geom_10">
      <origin xyz="-8.222505698540772e-08 -0.011045964434742928 0.012478641234338284" rpy="0.33435603976249695 1.1571604773052968e-05 4.019967491331045e-06"/>
      <geometry>
        <mesh filename="file://../meshes/obj/follower.obj" scale="1.0 1.0 1.0"/>
      </geometry>
    </visual>
    <collision name="Geom_11">
      <origin xyz="-8.222505698540772e-08 -0.011045964434742928 0.012478641234338284" rpy="0.33435603976249695 1.1571604773052968e-05 4.019967491331045e-06"/>
      <geometry>
        <mesh filename="file://../meshes/stl/follower.stl" scale="1.0 1.0 1.0"/>
      </geometry>
    </collision>
  </link>
  <joint name="right_pad_joint" type="fixed">
    <origin xyz="0.0 -0.0189 0.01352" rpy="0.0 0.0 0.0"/>
    <parent link="right_follower"/>
    <child link="right_pad"/>
  </joint>
  <link name="right_pad">
    <inertial>
      <origin xyz="0.0 -0.0024999999441206455 0.01850000023841858" rpy="0.0 0.0 1.5707963705062866"/>
      <mass value="0.0035000001080334187"/>
      <inertia ixx="4.7395801061611564e-07" ixy="0.0" ixz="0.0" iyy="3.645830020104768e-07" iyz="0.0" izz="1.2395800297326787e-07"/>
    </inertial>
    <collision name="right_pad1">
      <origin xyz="0.0 -0.0026000000070780516 0.02812499925494194" rpy="0.0 0.0 0.0"/>
      <geometry>
        <box size="0.02199999988079071 0.00800000037997961 0.01875000074505806"/>
      </geometry>
    </collision>
    <collision name="right_pad2">
      <origin xyz="0.0 -0.0026000000070780516 0.00937500037252903" rpy="0.0 0.0 0.0"/>
      <geometry>
        <box size="0.02199999988079071 0.00800000037997961 0.01875000074505806"/>
      </geometry>
    </collision>
    <visual name="Geom_14">
      <origin xyz="1.9278732459721525e-14 -0.0024999999441206455 0.018517374992370605" rpy="0.0 0.0 1.5707963705062866"/>
      <geometry>
        <mesh filename="file://../meshes/stl/pad.stl" scale="1.0 1.0 1.0"/>
      </geometry>
    </visual>
  </link>
  <joint name="right_silicone_pad_joint" type="fixed">
    <origin xyz="0.0 0.0 0.0" rpy="0.0 0.0 0.0"/>
    <parent link="right_pad"/>
    <child link="right_silicone_pad"/>
  </joint>
  <link name="right_silicone_pad">
    <inertial>
      <origin xyz="1.9279010286528224e-14 -0.005799999926239252 0.018517374992370605" rpy="0.0 0.0 1.5707963705062866"/>
      <mass value="0.0013028120156377554"/>
      <inertia ixx="2.0080436513580935e-07" ixy="0.0" ixz="0.0" iyy="1.4953603511003166e-07" iyz="0.0" izz="5.182418760796281e-08"/>
    </inertial>
    <visual name="Geom_15">
      <origin xyz="1.9279010286528224e-14 -0.005799999926239252 0.018517374992370605" rpy="0.0 0.0 1.5707963705062866"/>
      <geometry>
        <mesh filename="file://../meshes/obj/silicone_pad.obj" scale="1.0 1.0 1.0"/>
      </geometry>
    </visual>
  </link>
  <joint name="left_driver_joint" type="revolute">
    <origin xyz="0.0 -0.030601099133491516 0.05490399897098541" rpy="0.0 0.0 3.1415927410125732"/>
    <axis xyz="1.0 0.0 0.0"/>
    <parent link="base"/>
    <child link="left_driver"/>
    <limit effort="1000.0" lower="0.0" upper="0.800000011920929" velocity="1000.0"/>
  </joint>
  <link name="left_driver">
    <inertial>
      <origin xyz="0.0 0.017754700034856796 0.0010731399524956942" rpy="1.6425151824951172 0.0 0.0"/>
      <mass value="0.008995629847049713"/>
      <inertia ixx="1.7235199720744276e-06" ixy="0.0" ixz="0.0" iyy="1.609059950169467e-06" iyz="0.0" izz="3.220060023068072e-07"/>
    </inertial>
    <visual name="Geom_16">
      <origin xyz="2.9693094771160444e-12 0.0177546925842762 0.0010731416987255216" rpy="1.6425158977508545 0.0 0.0"/>
      <geometry>
        <mesh filename="file://../meshes/obj/driver.obj" scale="1.0 1.0 1.0"/>
      </geometry>
    </visual>
    <collision name="Geom_17">
      <origin xyz="2.9693094771160444e-12 0.0177546925842762 0.0010731416987255216" rpy="1.6425158977508545 0.0 0.0"/>
      <geometry>
        <mesh filename="file://../meshes/stl/driver.stl" scale="1.0 1.0 1.0"/>
      </geometry>
    </collision>
  </link>
  <joint name="left_coupler_joint" type="revolute">
    <origin xyz="0.0 0.03150000050663948 -0.004100000020116568" rpy="0.0 0.0 0.0"/>
    <axis xyz="1.0 0.0 0.0"/>
    <parent link="left_driver"/>
    <child link="left_coupler"/>
    <limit effort="1000.0" lower="-1.5700000524520874" upper="0.0" velocity="1000.0"/>
  </joint>
  <link name="left_coupler">
    <inertial>
      <origin xyz="0.0 0.003012089990079403 0.023217499256134033" rpy="0.0 0.12903854250907898 1.5707963705062866"/>
      <mass value="0.01409740000963211"/>
      <inertia ixx="4.162060122325784e-06" ixy="0.0" ixz="0.0" iyy="3.5221598864154657e-06" iyz="0.0" izz="8.881310122887953e-07"/>
    </inertial>
    <visual name="Geom_18">
      <origin xyz="8.458042209322225e-13 0.00301208533346653 0.023217538371682167" rpy="1.399413406969249e-17 0.1290387511253357 1.5707963705062866"/>
      <geometry>
        <mesh filename="file://../meshes/obj/coupler.obj" scale="1.0 1.0 1.0"/>
      </geometry>
    </visual>
    <collision name="Geom_19">
      <origin xyz="8.458042209322225e-13 0.00301208533346653 0.023217538371682167" rpy="1.399413406969249e-17 0.1290387511253357 1.5707963705062866"/>
      <geometry>
        <mesh filename="file://../meshes/stl/coupler.stl" scale="1.0 1.0 1.0"/>
      </geometry>
    </collision>
  </link>
  <joint name="left_spring_link_joint" type="revolute">
    <origin xyz="3.851859888774472e-34 -0.013199999928474426 0.0608999989926815" rpy="0.0 0.0 3.1415927410125732"/>
    <axis xyz="1.0 0.0 0.0"/>
    <parent link="base"/>
    <child link="left_spring_link"/>
    <limit effort="1000.0" lower="-0.296705961227417" upper="0.800000011920929" velocity="1000.0"/>
  </joint>
  <link name="left_spring_link">
    <inertial>
      <origin xyz="-8.650049565517293e-09 0.018162399530410767 0.021265799179673195" rpy="0.0 0.7068443298339844 1.5707963705062866"/>
      <mass value="0.022164199501276016"/>
      <inertia ixx="8.96852998266695e-06" ixy="0.0" ixz="0.0" iyy="6.717330052197212e-06" iyz="0.0" izz="2.6393099687993526e-06"/>
    </inertial>
    <visual name="Geom_20">
      <origin xyz="-8.650050453695712e-09 0.018162399530410767 0.02126581035554409" rpy="0.0 0.7068434953689575 1.5707963705062866"/>
      <geometry>
        <mesh filename="file://../meshes/obj/spring_link.obj" scale="1.0 1.0 1.0"/>
      </geometry>
    </visual>
    <collision name="Geom_21">
      <origin xyz="-8.650050453695712e-09 0.018162399530410767 0.02126581035554409" rpy="0.0 0.7068434953689575 1.5707963705062866"/>
      <geometry>
        <mesh filename="file://../meshes/stl/spring_link.stl" scale="1.0 1.0 1.0"/>
      </geometry>
    </collision>
  </link>
  <joint name="left_follower_joint" type="revolute">
    <origin xyz="0.0 0.054999999701976776 0.03750000149011612" rpy="0.0 0.0 0.0"/>
    <axis xyz="1.0 0.0 0.0"/>
    <parent link="left_spring_link"/>
    <child link="left_follower"/>
    <limit effort="1000.0" lower="-0.8726640343666077" upper="0.8726640343666077" velocity="1000.0"/>
  </joint>
  <link name="left_follower">
    <inertial>
      <origin xyz="0.0 -0.011045999825000763 0.012478600256145" rpy="0.32977840304374695 0.0 0.0"/>
      <mass value="0.012522200122475624"/>
      <inertia ixx="2.674149982340168e-06" ixy="0.0" ixz="0.0" iyy="2.4558999029977713e-06" iyz="0.0" izz="6.02030979734991e-07"/>
    </inertial>
    <visual name="Geom_22">
      <origin xyz="-8.222505698540772e-08 -0.011045964434742928 0.012478641234338284" rpy="0.33435603976249695 1.1571604773052968e-05 4.019967491331045e-06"/>
      <geometry>
        <mesh filename="file://../meshes/obj/follower.obj" scale="1.0 1.0 1.0"/>
      </geometry>
    </visual>
    <collision name="Geom_23">
      <origin xyz="-8.222505698540772e-08 -0.011045964434742928 0.012478641234338284" rpy="0.33435603976249695 1.1571604773052968e-05 4.019967491331045e-06"/>
      <geometry>
        <mesh filename="file://../meshes/stl/follower.stl" scale="1.0 1.0 1.0"/>
      </geometry>
    </collision>
  </link>
  <joint name="left_pad_joint" type="fixed">
    <origin xyz="0.0 -0.0189 0.01352" rpy="0.0 0.0 0.0"/>
    <parent link="left_follower"/>
    <child link="left_pad"/>
  </joint>
  <link name="left_pad">
    <inertial>
      <origin xyz="0.0 -0.0024999999441206455 0.01850000023841858" rpy="0.0 0.0 1.5707963705062866"/>
      <mass value="0.0035000001080334187"/>
      <inertia ixx="4.7395801061611564e-07" ixy="0.0" ixz="0.0" iyy="3.645830020104768e-07" iyz="0.0" izz="1.2395800297326787e-07"/>
    </inertial>
    <collision name="left_pad1">
      <origin xyz="0.0 -0.0026000000070780516 0.02812499925494194" rpy="0.0 0.0 0.0"/>
      <geometry>
        <box size="0.02199999988079071 0.00800000037997961 0.01875000074505806"/>
      </geometry>
    </collision>
    <collision name="left_pad2">
      <origin xyz="0.0 -0.0026000000070780516 0.00937500037252903" rpy="0.0 0.0 0.0"/>
      <geometry>
        <box size="0.02199999988079071 0.00800000037997961 0.01875000074505806"/>
      </geometry>
    </collision>
    <visual name="Geom_26">
      <origin xyz="1.9278732459721525e-14 -0.0024999999441206455 0.018517374992370605" rpy="0.0 0.0 1.5707963705062866"/>
      <geometry>
        <mesh filename="file://../meshes/stl/pad.stl" scale="1.0 1.0 1.0"/>
      </geometry>
    </visual>
  </link>
  <joint name="left_silicone_pad_joint" type="fixed">
    <origin xyz="0.0 0.0 0.0" rpy="0.0 0.0 0.0"/>
    <parent link="left_pad"/>
    <child link="left_silicone_pad"/>
  </joint>
  <link name="left_silicone_pad">
    <inertial>
      <origin xyz="1.9279010286528224e-14 -0.005799999926239252 0.018517374992370605" rpy="0.0 0.0 1.5707963705062866"/>
      <mass value="0.0013028120156377554"/>
      <inertia ixx="2.0080436513580935e-07" ixy="0.0" ixz="0.0" iyy="1.4953603511003166e-07" iyz="0.0" izz="5.182418760796281e-08"/>
    </inertial>
    <visual name="Geom_27">
      <origin xyz="1.9279010286528224e-14 -0.005799999926239252 0.018517374992370605" rpy="0.0 0.0 1.5707963705062866"/>
      <geometry>
        <mesh filename="file://../meshes/obj/silicone_pad.obj" scale="1.0 1.0 1.0"/>
      </geometry>
    </visual>
  </link>
</robot>