<?xml version="1.0" ?>
<mujoco model="LiCAS_A1">
	<compiler meshdir="../meshes" angle="radian" autolimits="true" balanceinertia="true" boundmass="0.000001" boundinertia="0.000001"/>
	<option>
		<flag contact="enable"/>
	</option>
	<default>
		<default class="visual">
			<geom contype="0" conaffinity="0"/>
		</default>
		<default class="collision">
			<geom rgba="0.9 0.9 0.9 0.0"/>
		</default>
	</default>
	<asset>
		<mesh name="ShoulderPitchStructure" file="obj/ShoulderPitchStructure.obj" scale="1.0 1.0 1.0"/>
		<mesh name="UCX_ShoulderPitchStructure_001" file="stl/mjcf/UCX_ShoulderPitchStructure_001.stl" scale="1.0 1.0 1.0"/>
		<mesh name="UCX_ShoulderPitchStructure_002" file="stl/mjcf/UCX_ShoulderPitchStructure_002.stl" scale="1.0 1.0 1.0"/>
		<mesh name="UCX_ShoulderPitchStructure_003" file="stl/mjcf/UCX_ShoulderPitchStructure_003.stl" scale="1.0 1.0 1.0"/>
		<mesh name="ShoulderRollStructureRight" file="obj/ShoulderRollStructureRight.obj" scale="1.0 1.0 1.0"/>
		<mesh name="UCX_ShoulderRollStructureRight_001" file="stl/mjcf/UCX_ShoulderRollStructureRight_001.stl" scale="1.0 1.0 1.0"/>
		<mesh name="UCX_ShoulderRollStructureRight_002" file="stl/mjcf/UCX_ShoulderRollStructureRight_002.stl" scale="1.0 1.0 1.0"/>
		<mesh name="UCX_ShoulderRollStructureRight_003" file="stl/mjcf/UCX_ShoulderRollStructureRight_003.stl" scale="1.0 1.0 1.0"/>
		<mesh name="ShoulderRollStructureLeft" file="obj/ShoulderRollStructureLeft.obj" scale="1.0 1.0 1.0"/>
		<mesh name="UCX_ShoulderRollStructureLeft_001" file="stl/mjcf/UCX_ShoulderRollStructureLeft_001.stl" scale="1.0 1.0 1.0"/>
		<mesh name="UCX_ShoulderRollStructureLeft_002" file="stl/mjcf/UCX_ShoulderRollStructureLeft_002.stl" scale="1.0 1.0 1.0"/>
		<mesh name="UCX_ShoulderRollStructureLeft_003" file="stl/mjcf/UCX_ShoulderRollStructureLeft_003.stl" scale="1.0 1.0 1.0"/>
		<mesh name="ShoulderYawStructure" file="obj/ShoulderYawStructure.obj" scale="1.0 1.0 1.0"/>
		<mesh name="UCX_ShoulderYawStructure_001" file="stl/mjcf/UCX_ShoulderYawStructure_001.stl" scale="1.0 1.0 1.0"/>
		<mesh name="UCX_ShoulderYawStructure_002" file="stl/mjcf/UCX_ShoulderYawStructure_002.stl" scale="1.0 1.0 1.0"/>
		<mesh name="UCX_ShoulderYawStructure_003" file="stl/mjcf/UCX_ShoulderYawStructure_003.stl" scale="1.0 1.0 1.0"/>
		<mesh name="UCX_ShoulderYawStructure_004" file="stl/mjcf/UCX_ShoulderYawStructure_004.stl" scale="1.0 1.0 1.0"/>
		<mesh name="UCX_ShoulderYawStructure_005" file="stl/mjcf/UCX_ShoulderYawStructure_005.stl" scale="1.0 1.0 1.0"/>
		<mesh name="UCX_ShoulderYawStructure_006" file="stl/mjcf/UCX_ShoulderYawStructure_006.stl" scale="1.0 1.0 1.0"/>
		<mesh name="ElbowPitchStructureRight" file="obj/ElbowPitchStructureRight.obj" scale="1.0 1.0 1.0"/>
		<mesh name="UCX_ElbowPitchStructureRight_001" file="stl/mjcf/UCX_ElbowPitchStructureRight_001.stl" scale="1.0 1.0 1.0"/>
		<mesh name="UCX_ElbowPitchStructureRight_002" file="stl/mjcf/UCX_ElbowPitchStructureRight_002.stl" scale="1.0 1.0 1.0"/>
		<mesh name="UCX_ElbowPitchStructureRight_003" file="stl/mjcf/UCX_ElbowPitchStructureRight_003.stl" scale="1.0 1.0 1.0"/>
		<mesh name="UCX_ElbowPitchStructureRight_004" file="stl/mjcf/UCX_ElbowPitchStructureRight_004.stl" scale="1.0 1.0 1.0"/>
		<mesh name="UCX_ElbowPitchStructureRight_005" file="stl/mjcf/UCX_ElbowPitchStructureRight_005.stl" scale="1.0 1.0 1.0"/>
		<mesh name="ForearmLink" file="obj/ForearmLink.obj" scale="1.0 1.0 1.0"/>
		<mesh name="UCX_ForearmLink_001" file="stl/mjcf/UCX_ForearmLink_001.stl" scale="1.0 1.0 1.0"/>
		<mesh name="UCX_ForearmLink_002" file="stl/mjcf/UCX_ForearmLink_002.stl" scale="1.0 1.0 1.0"/>
		<mesh name="UCX_ForearmLink_003" file="stl/mjcf/UCX_ForearmLink_003.stl" scale="1.0 1.0 1.0"/>
		<mesh name="UCX_ForearmLink_004" file="stl/mjcf/UCX_ForearmLink_004.stl" scale="1.0 1.0 1.0"/>
		<mesh name="UCX_ForearmLink_005" file="stl/mjcf/UCX_ForearmLink_005.stl" scale="1.0 1.0 1.0"/>
		<mesh name="UCX_ForearmLink_006" file="stl/mjcf/UCX_ForearmLink_006.stl" scale="1.0 1.0 1.0"/>
		<mesh name="UCX_ForearmLink_007" file="stl/mjcf/UCX_ForearmLink_007.stl" scale="1.0 1.0 1.0"/>
		<mesh name="MultirotorX4Main" file="obj/MultirotorX4Main.obj" scale="1.0 1.0 1.0"/>
		<mesh name="UCX_MultirotorX4Main_001" file="stl/mjcf/UCX_MultirotorX4Main_001.stl" scale="1.0 1.0 1.0"/>
		<mesh name="UCX_MultirotorX4Main_002" file="stl/mjcf/UCX_MultirotorX4Main_002.stl" scale="1.0 1.0 1.0"/>
		<mesh name="UCX_MultirotorX4Main_003" file="stl/mjcf/UCX_MultirotorX4Main_003.stl" scale="1.0 1.0 1.0"/>
		<mesh name="UCX_MultirotorX4Main_004" file="stl/mjcf/UCX_MultirotorX4Main_004.stl" scale="1.0 1.0 1.0"/>
		<mesh name="UCX_MultirotorX4Main_005" file="stl/mjcf/UCX_MultirotorX4Main_005.stl" scale="1.0 1.0 1.0"/>
		<mesh name="UCX_MultirotorX4Main_006" file="stl/mjcf/UCX_MultirotorX4Main_006.stl" scale="1.0 1.0 1.0"/>
		<mesh name="UCX_MultirotorX4Main_007" file="stl/mjcf/UCX_MultirotorX4Main_007.stl" scale="1.0 1.0 1.0"/>
		<mesh name="UCX_MultirotorX4Main_008" file="stl/mjcf/UCX_MultirotorX4Main_008.stl" scale="1.0 1.0 1.0"/>
		<mesh name="UCX_MultirotorX4Main_009" file="stl/mjcf/UCX_MultirotorX4Main_009.stl" scale="1.0 1.0 1.0"/>
		<mesh name="UCX_MultirotorX4Main_010" file="stl/mjcf/UCX_MultirotorX4Main_010.stl" scale="1.0 1.0 1.0"/>
		<mesh name="UCX_MultirotorX4Main_011" file="stl/mjcf/UCX_MultirotorX4Main_011.stl" scale="1.0 1.0 1.0"/>
		<mesh name="UCX_MultirotorX4Main_012" file="stl/mjcf/UCX_MultirotorX4Main_012.stl" scale="1.0 1.0 1.0"/>
		<mesh name="UCX_MultirotorX4Main_013" file="stl/mjcf/UCX_MultirotorX4Main_013.stl" scale="1.0 1.0 1.0"/>
		<mesh name="MultirotorX4Propeller" file="obj/MultirotorX4Propeller.obj" scale="1.0 1.0 1.0"/>
		<mesh name="UCX_MultirotorX4Propeller_001" file="stl/mjcf/UCX_MultirotorX4Propeller_001.stl" scale="1.0 1.0 1.0"/>
		<mesh name="MultirotorX4Leg" file="obj/MultirotorX4Leg.obj" scale="1.0 1.0 1.0"/>
		<mesh name="UCX_MultirotorX4Leg_001" file="stl/mjcf/UCX_MultirotorX4Leg_001.stl" scale="1.0 1.0 1.0"/>
		<mesh name="UCX_MultirotorX4Leg_002" file="stl/mjcf/UCX_MultirotorX4Leg_002.stl" scale="1.0 1.0 1.0"/>
	</asset>
	<worldbody>
		<body name="LiCAS_A1" pos="0.0 0.0 0.0" quat="1.0 0.0 0.0 0.0">
			<freejoint/>
			<body name="multirotor_x4_main" pos="0.05 0.0 0.125" quat="1.0 0.0 0.0 0.0">
				<geom name="multirotor_x4_main_visual" type="mesh" pos="0.0 0.0 0.0" quat="1.0 0.0 0.0 0.0" mesh="MultirotorX4Main" class="visual"/>
				<geom name="multirotor_x4_main_collision_001" type="mesh" pos="0.0 0.0 0.0" quat="1.0 0.0 0.0 0.0" mesh="UCX_MultirotorX4Main_001" class="collision"/>
				<geom name="multirotor_x4_main_collision_002" type="mesh" pos="0.0 0.0 0.0" quat="1.0 0.0 0.0 0.0" mesh="UCX_MultirotorX4Main_002" class="collision"/>
				<geom name="multirotor_x4_main_collision_003" type="mesh" pos="0.0 0.0 0.0" quat="1.0 0.0 0.0 0.0" mesh="UCX_MultirotorX4Main_003" class="collision"/>
				<geom name="multirotor_x4_main_collision_004" type="mesh" pos="0.0 0.0 0.0" quat="1.0 0.0 0.0 0.0" mesh="UCX_MultirotorX4Main_004" class="collision"/>
				<geom name="multirotor_x4_main_collision_005" type="mesh" pos="0.0 0.0 0.0" quat="1.0 0.0 0.0 0.0" mesh="UCX_MultirotorX4Main_005" class="collision"/>
				<geom name="multirotor_x4_main_collision_006" type="mesh" pos="0.0 0.0 0.0" quat="1.0 0.0 0.0 0.0" mesh="UCX_MultirotorX4Main_006" class="collision"/>
				<geom name="multirotor_x4_main_collision_007" type="mesh" pos="0.0 0.0 0.0" quat="1.0 0.0 0.0 0.0" mesh="UCX_MultirotorX4Main_007" class="collision"/>
				<geom name="multirotor_x4_main_collision_008" type="mesh" pos="0.0 0.0 0.0" quat="1.0 0.0 0.0 0.0" mesh="UCX_MultirotorX4Main_008" class="collision"/>
				<geom name="multirotor_x4_main_collision_009" type="mesh" pos="0.0 0.0 0.0" quat="1.0 0.0 0.0 0.0" mesh="UCX_MultirotorX4Main_009" class="collision"/>
				<geom name="multirotor_x4_main_collision_010" type="mesh" pos="0.0 0.0 0.0" quat="1.0 0.0 0.0 0.0" mesh="UCX_MultirotorX4Main_010" class="collision"/>
				<geom name="multirotor_x4_main_collision_011" type="mesh" pos="0.0 0.0 0.0" quat="1.0 0.0 0.0 0.0" mesh="UCX_MultirotorX4Main_011" class="collision"/>
				<geom name="multirotor_x4_main_collision_012" type="mesh" pos="0.0 0.0 0.0" quat="1.0 0.0 0.0 0.0" mesh="UCX_MultirotorX4Main_012" class="collision"/>
				<geom name="multirotor_x4_main_collision_013" type="mesh" pos="0.0 0.0 0.0" quat="1.0 0.0 0.0 0.0" mesh="UCX_MultirotorX4Main_013" class="collision"/>
				<site name="multirotor_x4_propeller_001" pos="0.339089 -0.338345 0.059"/>
				<site name="multirotor_x4_propeller_002" pos="0.339089 0.338345 0.059"/>
				<site name="multirotor_x4_propeller_003" pos="-0.339089 -0.338345 0.059"/>
				<site name="multirotor_x4_propeller_004" pos="-0.339089 0.338345 0.059"/>
				<body name="multirotor_x4_propeller_001" pos="0.339089 -0.338345 0.059" quat="1.0 0.0 0.0 0.0">
					<geom name="multirotor_x4_propeller_001_visual" type="mesh" pos="0.0 0.0 0.0" quat="1.0 0.0 0.0 0.0" mesh="MultirotorX4Propeller" class="visual"/>
					<geom name="multirotor_x4_propeller_001_collision_001" type="mesh" pos="0.0 0.0 0.0" quat="1.0 0.0 0.0 0.0" mesh="UCX_MultirotorX4Propeller_001" class="collision"/>
				</body>
				<body name="multirotor_x4_propeller_002" pos="0.339089 0.338345 0.059" quat="1.0 0.0 0.0 0.0">
					<geom name="multirotor_x4_propeller_002_visual" type="mesh" pos="0.0 0.0 0.0" quat="1.0 0.0 0.0 0.0" mesh="MultirotorX4Propeller" class="visual"/>
					<geom name="multirotor_x4_propeller_002_collision_001" type="mesh" pos="0.0 0.0 0.0" quat="1.0 0.0 0.0 0.0" mesh="UCX_MultirotorX4Propeller_001" class="collision"/>
				</body>
				<body name="multirotor_x4_propeller_003" pos="-0.339089 -0.338345 0.059" quat="1.0 0.0 0.0 0.0">
					<geom name="multirotor_x4_propeller_003_visual" type="mesh" pos="0.0 0.0 0.0" quat="1.0 0.0 0.0 0.0" mesh="MultirotorX4Propeller" class="visual"/>
					<geom name="multirotor_x4_propeller_003_collision_001" type="mesh" pos="0.0 0.0 0.0" quat="1.0 0.0 0.0 0.0" mesh="UCX_MultirotorX4Propeller_001" class="collision"/>
				</body>
				<body name="multirotor_x4_propeller_004" pos="-0.339089 0.338345 0.059" quat="1.0 0.0 0.0 0.0">
					<geom name="multirotor_x4_propeller_004_visual" type="mesh" pos="0.0 0.0 0.0" quat="1.0 0.0 0.0 0.0" mesh="MultirotorX4Propeller" class="visual"/>
					<geom name="multirotor_x4_propeller_004_collision_001" type="mesh" pos="0.0 0.0 0.0" quat="1.0 0.0 0.0 0.0" mesh="UCX_MultirotorX4Propeller_001" class="collision"/>
				</body>
				<body name="multirotor_x4_leg_001" pos="0.0 -0.13 -0.02" quat="1.0 0.0 0.0 0.0">
					<joint name="multirotor_x4_leg_001_joint" type="hinge" range="0.0 1.4" axis="-1 0 0"/>
					<geom name="multirotor_x4_leg_001_visual" type="mesh" pos="0.0 0.0 0.0" quat="1.0 0.0 0.0 0.0" mesh="MultirotorX4Leg" class="visual"/>
					<geom name="multirotor_x4_leg_001_collision_001" type="mesh" pos="0.0 0.0 0.0" quat="1.0 0.0 0.0 0.0" mesh="UCX_MultirotorX4Leg_001" class="collision"/>
					<geom name="multirotor_x4_leg_001_collision_002" type="mesh" pos="0.0 0.0 0.0" quat="1.0 0.0 0.0 0.0" mesh="UCX_MultirotorX4Leg_002" class="collision"/>
				</body>
				<body name="multirotor_x4_leg_002" pos="0.0 0.13 -0.02" quat="1.0 0.0 0.0 0.0">
					<joint name="multirotor_x4_leg_002_joint" type="hinge" range="0.0 1.4" axis="1 0 0"/>
					<geom name="multirotor_x4_leg_002_visual" type="mesh" pos="0.0 0.0 0.0" quat="1.0 0.0 0.0 0.0" mesh="MultirotorX4Leg" class="visual"/>
					<geom name="multirotor_x4_leg_002_collision_001" type="mesh" pos="0.0 0.0 0.0" quat="1.0 0.0 0.0 0.0" mesh="UCX_MultirotorX4Leg_001" class="collision"/>
					<geom name="multirotor_x4_leg_002_collision_002" type="mesh" pos="0.0 0.0 0.0" quat="1.0 0.0 0.0 0.0" mesh="UCX_MultirotorX4Leg_002" class="collision"/>
				</body>
			</body>

			<body name="shoulder_pitch_structure" pos="0.0 0.0 0.0" quat="1.0 0.0 0.0 0.0">
				<inertial mass="0.639" pos="0 0 -1.2e-2" diaginertia="3.02e-3 8.64e-4 3.39e-3"/>
				<geom name="shoulder_pitch_structure_visual" type="mesh" pos="0.0 0.0 0.0" quat="1.0 0.0 0.0 0.0" mesh="ShoulderPitchStructure" class="visual"/>
				<geom name="shoulder_pitch_structure_collision_001" type="mesh" pos="0.0 0.0 0.0" quat="1.0 0.0 0.0 0.0" mesh="UCX_ShoulderPitchStructure_001" class="collision"/>
				<geom name="shoulder_pitch_structure_collision_002" type="mesh" pos="0.0 0.0 0.0" quat="1.0 0.0 0.0 0.0" mesh="UCX_ShoulderPitchStructure_002" class="collision"/>
				<geom name="shoulder_pitch_structure_collision_003" type="mesh" pos="0.0 0.0 0.0" quat="1.0 0.0 0.0 0.0" mesh="UCX_ShoulderPitchStructure_003" class="collision"/>
				<body name="shoulder_roll_structure_right" pos="0.0 -0.18 0.0" quat="1.0 0.0 0.0 0.0">
					<joint name="shoulder_roll_structure_right_joint" type="hinge" range="-3.14 3.14" axis="0 1 0"/>
					<inertial mass="0.233" pos="0 2.36e-2 9.46e-3" diaginertia="3.68e-4 1.16e-4 3.76e-4"/>
					<geom name="shoulder_roll_structure_right_visual" type="mesh" pos="0.0 0.0 0.0" quat="1.0 0.0 0.0 0.0" mesh="ShoulderRollStructureRight" class="visual"/>
					<geom name="shoulder_roll_structure_right_collision_001" type="mesh" pos="0.0 0.0 0.0" quat="1.0 0.0 0.0 0.0" mesh="UCX_ShoulderRollStructureRight_001" class="collision"/>
					<geom name="shoulder_roll_structure_right_collision_002" type="mesh" pos="0.0 0.0 0.0" quat="1.0 0.0 0.0 0.0" mesh="UCX_ShoulderRollStructureRight_002" class="collision"/>
					<body name="shoulder_yaw_structure_right" pos="0.0 0.0 0.0" quat="1.0 0.0 0.0 0.0">
						<joint name="shoulder_yaw_structure_right_joint" type="hinge" range="-0.7 0.7" axis="1 0 0"/>
						<inertial mass="0.246" pos="-1.5e-2 0 -1e-1" diaginertia="3.49e-4 4.46e-4 1.49e-4"/>
						<geom name="shoulder_yaw_structure_right_visual" type="mesh" pos="0.0 0.0 0.0" quat="1.0 0.0 0.0 0.0" mesh="ShoulderYawStructure" class="visual"/>
						<geom name="shoulder_yaw_structure_right_collision_001" type="mesh" pos="0.0 0.0 0.0" quat="1.0 0.0 0.0 0.0" mesh="UCX_ShoulderYawStructure_001" class="collision"/>
						<geom name="shoulder_yaw_structure_right_collision_002" type="mesh" pos="0.0 0.0 0.0" quat="1.0 0.0 0.0 0.0" mesh="UCX_ShoulderYawStructure_002" class="collision"/>
						<geom name="shoulder_yaw_structure_right_collision_003" type="mesh" pos="0.0 0.0 0.0" quat="1.0 0.0 0.0 0.0" mesh="UCX_ShoulderYawStructure_003" class="collision"/>
						<geom name="shoulder_yaw_structure_right_collision_004" type="mesh" pos="0.0 0.0 0.0" quat="1.0 0.0 0.0 0.0" mesh="UCX_ShoulderYawStructure_004" class="collision"/>
						<geom name="shoulder_yaw_structure_right_collision_005" type="mesh" pos="0.0 0.0 0.0" quat="1.0 0.0 0.0 0.0" mesh="UCX_ShoulderYawStructure_005" class="collision"/>
						<geom name="shoulder_yaw_structure_right_collision_006" type="mesh" pos="0.0 0.0 0.0" quat="1.0 0.0 0.0 0.0" mesh="UCX_ShoulderYawStructure_006" class="collision"/>
						<body name="elbow_pitch_structure_right" pos="0.0 0.0 -0.275" quat="1.0 0.0 0.0 0.0">
							<joint name="elbow_pitch_structure_right_joint" type="hinge" range="-1.57 1.57" axis="0 0 1"/>
							<inertial mass="0.214" pos="0 0 3.9e-2" diaginertia="4.21e-4 4.26e-4 5.01e-5"/>
							<geom name="elbow_pitch_structure_right_visual" type="mesh" pos="0.0 0.0 0.0" quat="1.0 0.0 0.0 0.0" mesh="ElbowPitchStructureRight" class="visual"/>
							<geom name="elbow_pitch_structure_right_collision_001" type="mesh" pos="0.0 0.0 0.0" quat="1.0 0.0 0.0 0.0" mesh="UCX_ElbowPitchStructureRight_001" class="collision"/>
							<geom name="elbow_pitch_structure_right_collision_002" type="mesh" pos="0.0 0.0 0.0" quat="1.0 0.0 0.0 0.0" mesh="UCX_ElbowPitchStructureRight_002" class="collision"/>
							<geom name="elbow_pitch_structure_right_collision_003" type="mesh" pos="0.0 0.0 0.0" quat="1.0 0.0 0.0 0.0" mesh="UCX_ElbowPitchStructureRight_003" class="collision"/>
							<geom name="elbow_pitch_structure_right_collision_004" type="mesh" pos="0.0 0.0 0.0" quat="1.0 0.0 0.0 0.0" mesh="UCX_ElbowPitchStructureRight_004" class="collision"/>
							<geom name="elbow_pitch_structure_right_collision_005" type="mesh" pos="0.0 0.0 0.0" quat="1.0 0.0 0.0 0.0" mesh="UCX_ElbowPitchStructureRight_005" class="collision"/>
							<body name="forearm_link_right" pos="0.0 0.0 0.0" quat="1.0 0.0 0.0 0.0">
								<joint name="forearm_link_right_joint" type="hinge" range="-1.57 1.57" axis="0 1 0"/>
								<inertial mass="0.106" pos="0 0 -9.2e-2" diaginertia="3.94e-4 3.75e-4 3.05e-5"/>
								<geom name="forearm_link_right_visual" type="mesh" pos="0.0 0.0 0.0" quat="1.0 0.0 0.0 0.0" mesh="ForearmLink" class="visual"/>
								<geom name="forearm_link_right_collision_001" type="mesh" pos="0.0 0.0 0.0" quat="1.0 0.0 0.0 0.0" mesh="UCX_ForearmLink_001" class="collision"/>
								<geom name="forearm_link_right_collision_002" type="mesh" pos="0.0 0.0 0.0" quat="1.0 0.0 0.0 0.0" mesh="UCX_ForearmLink_002" class="collision"/>
								<geom name="forearm_link_right_collision_003" type="mesh" pos="0.0 0.0 0.0" quat="1.0 0.0 0.0 0.0" mesh="UCX_ForearmLink_003" class="collision"/>
								<geom name="forearm_link_right_collision_004" type="mesh" pos="0.0 0.0 0.0" quat="1.0 0.0 0.0 0.0" mesh="UCX_ForearmLink_004" class="collision"/>
								<geom name="forearm_link_right_collision_005" type="mesh" pos="0.0 0.0 0.0" quat="1.0 0.0 0.0 0.0" mesh="UCX_ForearmLink_005" class="collision"/>
								<geom name="forearm_link_right_collision_006" type="mesh" pos="0.0 0.0 0.0" quat="1.0 0.0 0.0 0.0" mesh="UCX_ForearmLink_006" class="collision"/>
								<geom name="forearm_link_right_collision_007" type="mesh" pos="0.0 0.0 0.0" quat="1.0 0.0 0.0 0.0" mesh="UCX_ForearmLink_007" class="collision"/>
							</body>
						</body>
					</body>
				</body>
				<body name="shoulder_roll_structure_left" pos="0.0 0.18 0.0" quat="1.0 0.0 0.0 0.0">
					<joint name="shoulder_roll_structure_left_joint" type="hinge" range="-3.14 3.14" axis="0 1 0"/>
					<inertial mass="0.233" pos="0 2.36e-2 9.46e-3" diaginertia="3.68e-4 1.16e-4 3.76e-4"/>
					<geom name="shoulder_roll_structure_left_visual" type="mesh" pos="0.0 0.0 0.0" quat="1.0 0.0 0.0 0.0" mesh="ShoulderRollStructureLeft" class="visual"/>
					<geom name="shoulder_roll_structure_left_collision_001" type="mesh" pos="0.0 0.0 0.0" quat="1.0 0.0 0.0 0.0" mesh="UCX_ShoulderRollStructureLeft_001" class="collision"/>
					<geom name="shoulder_roll_structure_left_collision_002" type="mesh" pos="0.0 0.0 0.0" quat="1.0 0.0 0.0 0.0" mesh="UCX_ShoulderRollStructureLeft_002" class="collision"/>
					<body name="shoulder_yaw_structure_left" pos="0.0 0.0 0.0" quat="1.0 0.0 0.0 0.0">
						<joint name="shoulder_yaw_structure_left_joint" type="hinge" range="-0.7 0.7" axis="1 0 0"/>
						<inertial mass="0.246" pos="-1.5e-2 0 -1e-1" diaginertia="3.49e-4 4.46e-4 1.49e-4"/>
						<geom name="shoulder_yaw_structure_left_visual" type="mesh" pos="0.0 0.0 0.0" quat="1.0 0.0 0.0 0.0" mesh="ShoulderYawStructure" class="visual"/>
						<geom name="shoulder_yaw_structure_left_collision_001" type="mesh" pos="0.0 0.0 0.0" quat="1.0 0.0 0.0 0.0" mesh="UCX_ShoulderYawStructure_001" class="collision"/>
						<geom name="shoulder_yaw_structure_left_collision_002" type="mesh" pos="0.0 0.0 0.0" quat="1.0 0.0 0.0 0.0" mesh="UCX_ShoulderYawStructure_002" class="collision"/>
						<geom name="shoulder_yaw_structure_left_collision_003" type="mesh" pos="0.0 0.0 0.0" quat="1.0 0.0 0.0 0.0" mesh="UCX_ShoulderYawStructure_003" class="collision"/>
						<geom name="shoulder_yaw_structure_left_collision_004" type="mesh" pos="0.0 0.0 0.0" quat="1.0 0.0 0.0 0.0" mesh="UCX_ShoulderYawStructure_004" class="collision"/>
						<geom name="shoulder_yaw_structure_left_collision_005" type="mesh" pos="0.0 0.0 0.0" quat="1.0 0.0 0.0 0.0" mesh="UCX_ShoulderYawStructure_005" class="collision"/>
						<geom name="shoulder_yaw_structure_left_collision_006" type="mesh" pos="0.0 0.0 0.0" quat="1.0 0.0 0.0 0.0" mesh="UCX_ShoulderYawStructure_006" class="collision"/>
						<body name="elbow_pitch_structure_left" pos="0.0 0.0 -0.275" quat="1.0 0.0 0.0 0.0">
							<joint name="elbow_pitch_structure_left_joint" type="hinge" range="-1.57 1.57" axis="0 0 1"/>
							<inertial mass="0.214" pos="0 0 3.9e-2" diaginertia="4.21e-4 4.26e-4 5.01e-5"/>
							<geom name="elbow_pitch_structure_left_visual" type="mesh" pos="0.0 0.0 0.0" quat="1.0 0.0 0.0 0.0" mesh="ElbowPitchStructureRight" class="visual"/>
							<geom name="elbow_pitch_structure_left_collision_001" type="mesh" pos="0.0 0.0 0.0" quat="1.0 0.0 0.0 0.0" mesh="UCX_ElbowPitchStructureRight_001" class="collision"/>
							<geom name="elbow_pitch_structure_left_collision_002" type="mesh" pos="0.0 0.0 0.0" quat="1.0 0.0 0.0 0.0" mesh="UCX_ElbowPitchStructureRight_002" class="collision"/>
							<geom name="elbow_pitch_structure_left_collision_003" type="mesh" pos="0.0 0.0 0.0" quat="1.0 0.0 0.0 0.0" mesh="UCX_ElbowPitchStructureRight_003" class="collision"/>
							<geom name="elbow_pitch_structure_left_collision_004" type="mesh" pos="0.0 0.0 0.0" quat="1.0 0.0 0.0 0.0" mesh="UCX_ElbowPitchStructureRight_004" class="collision"/>
							<geom name="elbow_pitch_structure_left_collision_005" type="mesh" pos="0.0 0.0 0.0" quat="1.0 0.0 0.0 0.0" mesh="UCX_ElbowPitchStructureRight_005" class="collision"/>
							<body name="forearm_link_left" pos="0.0 0.0 0.0" quat="1.0 0.0 0.0 0.0">
								<joint name="forearm_link_left_joint" type="hinge" range="-1.57 1.57" axis="0 1 0"/>
								<inertial mass="0.106" pos="0 0 -9.2e-2" diaginertia="3.94e-4 3.75e-4 3.05e-5"/>
								<geom name="forearm_link_left_visual" type="mesh" pos="0.0 0.0 0.0" quat="1.0 0.0 0.0 0.0" mesh="ForearmLink" class="visual"/>
								<geom name="forearm_link_left_collision_001" type="mesh" pos="0.0 0.0 0.0" quat="1.0 0.0 0.0 0.0" mesh="UCX_ForearmLink_001" class="collision"/>
								<geom name="forearm_link_left_collision_002" type="mesh" pos="0.0 0.0 0.0" quat="1.0 0.0 0.0 0.0" mesh="UCX_ForearmLink_002" class="collision"/>
								<geom name="forearm_link_left_collision_003" type="mesh" pos="0.0 0.0 0.0" quat="1.0 0.0 0.0 0.0" mesh="UCX_ForearmLink_003" class="collision"/>
								<geom name="forearm_link_left_collision_004" type="mesh" pos="0.0 0.0 0.0" quat="1.0 0.0 0.0 0.0" mesh="UCX_ForearmLink_004" class="collision"/>
								<geom name="forearm_link_left_collision_005" type="mesh" pos="0.0 0.0 0.0" quat="1.0 0.0 0.0 0.0" mesh="UCX_ForearmLink_005" class="collision"/>
								<geom name="forearm_link_left_collision_006" type="mesh" pos="0.0 0.0 0.0" quat="1.0 0.0 0.0 0.0" mesh="UCX_ForearmLink_006" class="collision"/>
								<geom name="forearm_link_left_collision_007" type="mesh" pos="0.0 0.0 0.0" quat="1.0 0.0 0.0 0.0" mesh="UCX_ForearmLink_007" class="collision"/>
							</body>
						</body>
					</body>
				</body>
			</body>
		</body>
	</worldbody> 

	<actuator>
		<motor name="thrust1" site="multirotor_x4_propeller_001" gear="0 0 1 0 0 -.02" ctrlrange="0 150"/>
		<motor name="thrust2" site="multirotor_x4_propeller_002" gear="0 0 1 0 0  .02" ctrlrange="0 150"/>
		<motor name="thrust3" site="multirotor_x4_propeller_003" gear="0 0 1 0 0  .02" ctrlrange="0 150"/>
		<motor name="thrust4" site="multirotor_x4_propeller_004" gear="0 0 1 0 0 -.02" ctrlrange="0 150"/>

		<position name="multirotor_x4_leg_001_actuator" joint="multirotor_x4_leg_001_joint" kp="500" kv="200" ctrlrange="0.0 1.4" forcerange="-100 100"/>
		<position name="multirotor_x4_leg_002_actuator" joint="multirotor_x4_leg_002_joint" kp="500" kv="200" ctrlrange="0.0 1.4" forcerange="-100 100"/>

		<position name="shoulder_roll_structure_right_actuator" joint="shoulder_roll_structure_right_joint" kp="10" kv="4" ctrlrange="-3.14 3.14" forcerange="-100 100"/>
		<position name="shoulder_yaw_structure_right_actuator" joint="shoulder_yaw_structure_right_joint" kp="20" kv="4" ctrlrange="-0.7 0.7" forcerange="-100 100"/>
		<position name="elbow_pitch_structure_right_actuator" joint="elbow_pitch_structure_right_joint" kp="0.5" kv="0.04" ctrlrange="-1.57 1.57" forcerange="-100 100"/>
		<position name="forearm_link_right_actuator" joint="forearm_link_right_joint" kp="0.5" kv="0.04" ctrlrange="-1.57 1.57" forcerange="-100 100"/>
		
		<position name="shoulder_roll_structure_left_actuator" joint="shoulder_roll_structure_left_joint" kp="10" kv="4" ctrlrange="-3.14 3.14" forcerange="-100 100"/>
		<position name="shoulder_yaw_structure_left_actuator" joint="shoulder_yaw_structure_left_joint" kp="20" kv="4" ctrlrange="-0.7 0.7" forcerange="-100 100"/>
		<position name="elbow_pitch_structure_left_actuator" joint="elbow_pitch_structure_left_joint" kp="0.5" kv="0.04" ctrlrange="-1.57 1.57" forcerange="-100 100"/>
		<position name="forearm_link_left_actuator" joint="forearm_link_left_joint" kp="0.5" kv="0.04" ctrlrange="-1.57 1.57" forcerange="-100 100"/>
	</actuator>
</mujoco>