<?xml version="1.0" ?>
<robot name="tiago_dual" version="1.0">
  <link name="tiago_dual"/>
  <joint name="base_footprint_joint" type="fixed">
    <origin xyz="0.0 0.0 0.0" rpy="0.0 -0.0 0.0"/>
    <parent link="tiago_dual"/>
    <child link="base_footprint"/>
  </joint>
  <link name="base_footprint"/>
  <joint name="base_link_joint" type="fixed">
    <origin xyz="0.0 0.0 0.0985" rpy="0.0 -0.0 0.0"/>
    <parent link="base_footprint"/>
    <child link="base_link"/>
  </joint>
  <link name="base_link">
    <collision name="base_collision">
      <origin xyz="0.0 0.0 0.0" rpy="0.0 -0.0 0.0"/>
      <geometry>
        <mesh filename="file://../meshes/stl/base_collision.stl" scale="1.0 1.0 1.0"/>
      </geometry>
    </collision>
    <visual name="base">
      <origin xyz="0.0 0.0 0.0" rpy="0.0 -0.0 0.0"/>
      <geometry>
        <mesh filename="file://../meshes/obj/base.obj" scale="1.0 1.0 1.0"/>
      </geometry>
    </visual>
  </link>
  <joint name="torso_fixed_link_joint" type="fixed">
    <origin xyz="-0.062 0.0 0.193" rpy="0.0 -0.0 0.0"/>
    <parent link="base_link"/>
    <child link="torso_fixed_link"/>
  </joint>
  <link name="torso_fixed_link">
    <visual name="torso_fix">
      <origin xyz="0.0 0.0 0.0" rpy="0.0 -0.0 0.0"/>
      <geometry>
        <mesh filename="file://../meshes/obj/torso_fix.obj" scale="1.0 1.0 1.0"/>
      </geometry>
    </visual>
    <collision name="torso_fixed_link_collision_0">
      <origin xyz="0.085 0.0 0.02" rpy="0.0 -0.0 0.0"/>
      <geometry>
        <box size="0.4 0.25 0.04"/>
      </geometry>
    </collision>
    <collision name="torso_fixed_link_collision_1">
      <origin xyz="0.0 0.0 0.05" rpy="0.0 -0.0 0.0"/>
      <geometry>
        <box size="0.25 0.25 0.1"/>
      </geometry>
    </collision>
  </link>
  <joint name="torso_lift_joint" type="prismatic">
    <origin xyz="0.0 0.0 0.597000002861023" rpy="0.0 -0.0 0.0"/>
    <axis xyz="0 0 1"/>
    <parent link="torso_fixed_link"/>
    <child link="torso_lift_link"/>
    <limit effort="1000" lower="0.0" upper="0.800000011920929" velocity="1000"/>
  </joint>
  <link name="torso_lift_link">
    <collision name="torso_lift_collision_shoulder">
      <origin xyz="-0.131 0.17 -0.02556" rpy="0.0 -0.0 0.0"/>
      <geometry>
        <mesh filename="file://../meshes/stl/torso_lift_collision_shoulder.stl" scale="1.0 1.0 1.0"/>
      </geometry>
    </collision>
    <collision name="torso_lift_collision_shoulder">
      <origin xyz="-0.131 -0.19 -0.02556" rpy="0.0 -0.0 0.0"/>
      <geometry>
        <mesh filename="file://../meshes/stl/torso_lift_collision_shoulder.stl" scale="1.0 1.0 1.0"/>
      </geometry>
    </collision>
    <collision name="torso_lift_collision_core">
      <origin xyz="0.0 0.0 0.0" rpy="0.0 -0.0 0.0"/>
      <geometry>
        <mesh filename="file://../meshes/stl/torso_lift_collision_core.stl" scale="1.0 1.0 1.0"/>
      </geometry>
    </collision>
    <visual name="torso_lift_dual_arm">
      <origin xyz="0.0 0.0 0.0" rpy="0.0 -0.0 0.0"/>
      <geometry>
        <mesh filename="file://../meshes/obj/torso_lift_dual_arm.obj" scale="1.0 1.0 1.0"/>
      </geometry>
    </visual>
    <collision name="torso_lift_collision_neck">
      <origin xyz="0.0 0.0 0.0" rpy="0.0 -0.0 0.0"/>
      <geometry>
        <mesh filename="file://../meshes/stl/torso_lift_collision_neck.stl" scale="1.0 1.0 1.0"/>
      </geometry>
    </collision>
  </link>
  <joint name="arm_left_1_joint" type="revolute">
    <origin xyz="0.02556000091135502 0.1899999976158142 -0.17100000381469727" rpy="3.141592653589793 -0.0 1.5707963267948966"/>
    <axis xyz="0 0 1"/>
    <parent link="torso_lift_link"/>
    <child link="arm_left_1_link"/>
    <limit effort="1000" lower="-1.1780972450961724" upper="1.5707963267948966" velocity="1000"/>
  </joint>
  <link name="arm_left_1_link">
    <visual name="arm_1">
      <origin xyz="0.0 0.0 0.0" rpy="3.141592653589793 -0.0 0.0"/>
      <geometry>
        <mesh filename="file://../meshes/obj/arm_1.obj" scale="1.0 1.0000000000000004 1.0000000000000004"/>
      </geometry>
    </visual>
    <collision name="arm_1_collision">
      <origin xyz="0.0 0.0 0.0" rpy="3.141592653589793 -0.0 0.0"/>
      <geometry>
        <mesh filename="file://../meshes/stl/arm_1_collision.stl" scale="1.0 1.0000000000000004 1.0000000000000004"/>
      </geometry>
    </collision>
  </link>
</robot>