<?xml version="1.0" ?>
<!-- 
    This is a property of DLR
-->
<robot name="justin">
	<link name="base_link">
		<inertial>
			<inertia ixx="0.0001" ixy="0" ixz="0" iyy="0" iyz="0.0001" izz="0"/>
			<origin rpy="0 0 0" xyz="0 0 0"/>
			<mass value="0.0001"/>
		</inertial>
	</link>
	<link name="platform_link">
		<collision>
			<geometry>
				<mesh filename="file://../meshes/mp_mobile_plattform_rj_BASE_collision.stl" scale="0.001 0.001 0.001"/>
			</geometry>
			<origin rpy="0 0 0" xyz="0 0 0"/>
		</collision>
		<visual>
			<geometry>
				<mesh filename="file://../meshes/mp_mobile_plattform_rj_BASE.stl" scale="0.001 0.001 0.001"/>
			</geometry>
			<origin rpy="0 0 0" xyz="0 0 0"/>
			<material name="mp_mobile_plattform_rj_BASE.stl">
				<color rgba="0.4891 0.5125 0.5281 1.0"/>
			</material>
		</visual>
		<inertial>
			<inertia ixx="3996.9249" ixy="-0.38014026" ixz="-172.63779" iyy="2088.9994" iyz="-0.077339483" izz="5381.3384"/>
			<origin rpy="0 0 0" xyz="0.76003989 -4.5083652e-05 0.35229543"/>
			<mass value="7066.028"/>
		</inertial>
	</link>
	<link name="wheel_rf_link">
		<collision>
			<geometry>
				<mesh filename="file://../meshes/mp_mobile_plattform_rj_ROT1_collision.stl" scale="0.001 0.001 0.001"/>
			</geometry>
			<origin rpy="0 0 0" xyz="0 0 0"/>
		</collision>
		<visual>
			<geometry>
				<mesh filename="file://../meshes/mp_mobile_plattform_rj_ROT1.stl" scale="0.001 0.001 0.001"/>
			</geometry>
			<origin rpy="0 0 0" xyz="0 0 0"/>
			<material name="mp_mobile_plattform_rj_ROT1.stl">
				<color rgba="0.4891 0.5125 0.5281 1.0"/>
			</material>
		</visual>
		<inertial>
			<inertia ixx="0.036091638" ixy="0.00020395783" ixz="-7.3579825e-05" iyy="0.019192014" iyz="-7.8685567e-05" izz="0.02395449"/>
			<origin rpy="0 0 0" xyz="-0.014599462 -0.011620927 -3.1071025e-05"/>
			<mass value="5.6581599"/>
		</inertial>
	</link>
	<link name="wheel_lf_link">
		<collision>
			<geometry>
				<mesh filename="file://../meshes/mp_mobile_plattform_rj_ROT2_collision.stl" scale="0.001 0.001 0.001"/>
			</geometry>
			<origin rpy="0 0 0" xyz="0 0 0"/>
		</collision>
		<visual>
			<geometry>
				<mesh filename="file://../meshes/mp_mobile_plattform_rj_ROT2.stl" scale="0.001 0.001 0.001"/>
			</geometry>
			<origin rpy="0 0 0" xyz="0 0 0"/>
			<material name="mp_mobile_plattform_rj_ROT2.stl">
				<color rgba="0.4891 0.5125 0.5281 1.0"/>
			</material>
		</visual>
		<inertial>
			<inertia ixx="0.036091638" ixy="0.00020395783" ixz="-7.3579825e-05" iyy="0.019192014" iyz="-7.8685567e-05" izz="0.02395449"/>
			<origin rpy="0 0 0" xyz="-0.014599199 -0.011620927 -3.1071023e-05"/>
			<mass value="5.6581599"/>
		</inertial>
	</link>
	<link name="wheel_rb_link">
		<collision>
			<geometry>
				<mesh filename="file://../meshes/mp_mobile_plattform_rj_ROT3_collision.stl" scale="0.001 0.001 0.001"/>
			</geometry>
			<origin rpy="0 0 0" xyz="0 0 0"/>
		</collision>
		<visual>
			<geometry>
				<mesh filename="file://../meshes/mp_mobile_plattform_rj_ROT3.stl" scale="0.001 0.001 0.001"/>
			</geometry>
			<origin rpy="0 0 0" xyz="0 0 0"/>
			<material name="mp_mobile_plattform_rj_ROT3.stl">
				<color rgba="0.4891 0.5125 0.5281 1.0"/>
			</material>
		</visual>
		<inertial>
			<inertia ixx="0.036091638" ixy="0.00020395783" ixz="-7.3579825e-05" iyy="0.019192014" iyz="-7.8685567e-05" izz="0.02395449"/>
			<origin rpy="0 0 0" xyz="-0.014599462 -0.011620927 -3.1071025e-05"/>
			<mass value="5.6581599"/>
		</inertial>
	</link>
	<link name="wheel_lb_link">
		<collision>
			<geometry>
				<mesh filename="file://../meshes/mp_mobile_plattform_rj_ROT4_collision.stl" scale="0.001 0.001 0.001"/>
			</geometry>
			<origin rpy="0 0 0" xyz="0 0 0"/>
		</collision>
		<visual>
			<geometry>
				<mesh filename="file://../meshes/mp_mobile_plattform_rj_ROT4.stl" scale="0.001 0.001 0.001"/>
			</geometry>
			<origin rpy="0 0 0" xyz="0 0 0"/>
			<material name="mp_mobile_plattform_rj_ROT4.stl">
				<color rgba="0.4891 0.5125 0.5281 1.0"/>
			</material>
		</visual>
		<inertial>
			<inertia ixx="0.036091638" ixy="0.00020395783" ixz="-7.3579825e-05" iyy="0.019192014" iyz="-7.8685567e-05" izz="0.02395449"/>
			<origin rpy="0 0 0" xyz="-0.014599199 -0.011620927 -3.1071023e-05"/>
			<mass value="5.6581599"/>
		</inertial>
	</link>
	<link name="torso_base_link">
		<collision>
			<geometry>
				<mesh filename="file://../meshes/trs-plat-dummy_Trs-Base_A0_collision.stl" scale="0.001 0.001 0.001"/>
			</geometry>
			<origin rpy="0 0 0" xyz="0 0 0"/>
		</collision>
		<visual>
			<geometry>
				<mesh filename="file://../meshes/trs-plat-dummy_Trs-Base_A0.stl" scale="0.001 0.001 0.001"/>
			</geometry>
			<origin rpy="0 0 0" xyz="0 0 0"/>
			<material name="trs-plat-dummy_Trs-Base_A0.stl">
				<color rgba="0.4891 0.5125 0.5281 1.0"/>
			</material>
		</visual>
		<inertial>
			<inertia ixx="0.0042258041" ixy="-4.8475726e-06" ixz="1.5118714e-05" iyy="0.0042147709" iyz="-5.2824223e-05" izz="0.004611298"/>
			<origin rpy="0 0 0" xyz="0.00012105821 -0.00053961391 -0.034391114"/>
			<mass value="1.9703622"/>
		</inertial>
	</link>
	<link name="torso1_link">
		<collision>
			<geometry>
				<mesh filename="file://../meshes/trs-plat-dummy_A1_collision.stl" scale="0.001 0.001 0.001"/>
			</geometry>
			<origin rpy="0 0 0" xyz="0 0 0"/>
		</collision>
		<visual>
			<geometry>
				<mesh filename="file://../meshes/trs-plat-dummy_A1.stl" scale="0.001 0.001 0.001"/>
			</geometry>
			<origin rpy="0 0 0" xyz="0 0 0"/>
			<material name="trs-plat-dummy_A1.stl">
				<color rgba="0.4891 0.5125 0.5281 1.0"/>
			</material>
		</visual>
		<inertial>
			<inertia ixx="0.029738675" ixy="0.00011607649" ixz="0.00045895858" iyy="0.02068692" iyz="-0.001561861" izz="0.024230199"/>
			<origin rpy="0 0 0" xyz="0.0035144892 0.0084362258 0.073206661"/>
			<mass value="4.5617348"/>
		</inertial>
	</link>
	<link name="torso2_link">
		<collision>
			<geometry>
				<mesh filename="file://../meshes/trs-plat-dummy_A2_collision.stl" scale="0.001 0.001 0.001"/>
			</geometry>
			<origin rpy="0 0 0" xyz="0 0 0"/>
		</collision>
		<visual>
			<geometry>
				<mesh filename="file://../meshes/trs-plat-dummy_A2.stl" scale="0.001 0.001 0.001"/>
			</geometry>
			<origin rpy="0 0 0" xyz="0 0 0"/>
			<material name="trs-plat-dummy_A2.stl">
				<color rgba="0.4891 0.5125 0.5281 1.0"/>
			</material>
		</visual>
		<inertial>
			<inertia ixx="0.033982984" ixy="-0.0036648885" ixz="0.0016239927" iyy="0.098533034" iyz="-0.0013359386" izz="0.077468325"/>
			<origin rpy="0 0 0" xyz="0.20680852 -0.013802093 0.0044908077"/>
			<mass value="5.4001973"/>
		</inertial>
	</link>
	<link name="torso3_link">
		<collision>
			<geometry>
				<mesh filename="file://../meshes/trs-plat-dummy_A3_collision.stl" scale="0.001 0.001 0.001"/>
			</geometry>
			<origin rpy="0 0 0" xyz="0 0 0"/>
		</collision>
		<visual>
			<geometry>
				<mesh filename="file://../meshes/trs-plat-dummy_A3.stl" scale="0.001 0.001 0.001"/>
			</geometry>
			<origin rpy="0 0 0" xyz="0 0 0"/>
			<material name="trs-plat-dummy_A3.stl">
				<color rgba="0.4891 0.5125 0.5281 1.0"/>
			</material>
		</visual>
		<inertial>
			<inertia ixx="0.024029356" ixy="0.00035611227" ixz="0.0022784592" iyy="0.059276259" iyz="-0.0011333897" izz="0.044021597"/>
			<origin rpy="0 0 0" xyz="0.14568642 -0.021572646 0.0039041655"/>
			<mass value="3.2497625"/>
		</inertial>
	</link>
	<link name="torso4_link">
		<collision>
			<geometry>
				<mesh filename="file://../meshes/trs-plat-dummy_A4_collision.stl" scale="0.001 0.001 0.001"/>
			</geometry>
			<origin rpy="0 0 0" xyz="0 0 0"/>
		</collision>
		<visual>
			<geometry>
				<mesh filename="file://../meshes/trs-plat-dummy_A4.stl" scale="0.001 0.001 0.001"/>
			</geometry>
			<origin rpy="0 0 0" xyz="0 0 0"/>
			<material name="trs-plat-dummy_A4.stl">
				<color rgba="0.4891 0.5125 0.5281 1.0"/>
			</material>
		</visual>
		<inertial>
			<inertia ixx="0.028746602" ixy="-0.0022869598" ixz="-0.0004338722" iyy="0.028860453" iyz="-0.00084553514" izz="0.020842822"/>
			<origin rpy="0 0 0" xyz="0.026601566 0.054789635 -0.0055993599"/>
			<mass value="2.8514467"/>
		</inertial>
	</link>
	<link name="left_base_link">
		<collision>
			<geometry>
				<mesh filename="file://../meshes/lr33_J1_Base_frame_collision.stl" scale="0.001 0.001 0.001"/>
			</geometry>
			<origin rpy="0 0 0" xyz="0 0 0"/>
		</collision>
		<visual>
			<geometry>
				<mesh filename="file://../meshes/lr33_J1_Base_frame.stl" scale="0.001 0.001 0.001"/>
			</geometry>
			<origin rpy="0 0 0" xyz="0 0 0"/>
			<material name="lr33_J1_Base_frame.stl">
				<color rgba="0.4891 0.5125 0.5281 1.0"/>
			</material>
		</visual>
		<inertial>
			<inertia ixx="0.001999327" ixy="4.9576601e-06" ixz="-2.9556616e-05" iyy="0.0020108452" iyz="-1.2899418e-05" izz="0.0021402397"/>
			<origin rpy="0 0 0" xyz="-0.00056177913 -0.00012307609 0.087904977"/>
			<mass value="1.6371831"/>
		</inertial>
	</link>
	<link name="left_arm1_link">
		<collision>
			<geometry>
				<mesh filename="file://../meshes/lr33_J2_HUELLE_A1_collision.stl" scale="0.001 0.001 0.001"/>
			</geometry>
			<origin rpy="0 0 0" xyz="0 0 0"/>
		</collision>
		<visual>
			<geometry>
				<mesh filename="file://../meshes/lr33_J2_HUELLE_A1.stl" scale="0.001 0.001 0.001"/>
			</geometry>
			<origin rpy="0 0 0" xyz="0 0 0"/>
			<material name="lr33_J2_HUELLE_A1.stl">
				<color rgba="0.4891 0.5125 0.5281 1.0"/>
			</material>
		</visual>
		<inertial>
			<inertia ixx="0.018297455" ixy="3.140387e-05" ixz="4.4845562e-05" iyy="0.017936786" iyz="-0.0018996179" izz="0.0046739064"/>
			<origin rpy="0 0 0" xyz="-0.00035588415 0.02011404 -0.046743755"/>
			<mass value="2.6517059"/>
		</inertial>
	</link>
	<link name="left_arm2_link">
		<collision>
			<geometry>
				<mesh filename="file://../meshes/lr33_J3_HUELLE_A2_collision.stl" scale="0.001 0.001 0.001"/>
			</geometry>
			<origin rpy="0 0 0" xyz="0 0 0"/>
		</collision>
		<visual>
			<geometry>
				<mesh filename="file://../meshes/lr33_J3_HUELLE_A2.stl" scale="0.001 0.001 0.001"/>
			</geometry>
			<origin rpy="0 0 0" xyz="0 0 0"/>
			<material name="lr33_J3_HUELLE_A2.stl">
				<color rgba="0.4891 0.5125 0.5281 1.0"/>
			</material>
		</visual>
		<inertial>
			<inertia ixx="0.020736057" ixy="-2.7846915e-05" ixz="2.587249e-05" iyy="0.0044726042" iyz="0.0037165157" izz="0.01999048"/>
			<origin rpy="0 0 0" xyz="-0.00050905976 0.11014487 0.017628708"/>
			<mass value="2.2434444"/>
		</inertial>
	</link>
	<link name="left_arm3_link">
		<collision>
			<geometry>
				<mesh filename="file://../meshes/lr33_J4_HUELLE_A3_collision.stl" scale="0.001 0.001 0.001"/>
			</geometry>
			<origin rpy="0 0 0" xyz="0 0 0"/>
		</collision>
		<visual>
			<geometry>
				<mesh filename="file://../meshes/lr33_J4_HUELLE_A3.stl" scale="0.001 0.001 0.001"/>
			</geometry>
			<origin rpy="0 0 0" xyz="0 0 0"/>
			<material name="lr33_J4_HUELLE_A3.stl">
				<color rgba="0.4891 0.5125 0.5281 1.0"/>
			</material>
		</visual>
		<inertial>
			<inertia ixx="0.016892566" ixy="1.8213812e-05" ixz="2.4283407e-05" iyy="0.016412578" iyz="-0.001663218" izz="0.0041598592"/>
			<origin rpy="0 0 0" xyz="-0.00021446701 0.017854825 -0.054431805"/>
			<mass value="2.2448128"/>
		</inertial>
	</link>
	<link name="left_arm4_link">
		<collision>
			<geometry>
				<mesh filename="file://../meshes/lr33_J5_HUELLE_A4_collision.stl" scale="0.001 0.001 0.001"/>
			</geometry>
			<origin rpy="0 0 0" xyz="0 0 0"/>
		</collision>
		<visual>
			<geometry>
				<mesh filename="file://../meshes/lr33_J5_HUELLE_A4.stl" scale="0.001 0.001 0.001"/>
			</geometry>
			<origin rpy="0 0 0" xyz="0 0 0"/>
			<material name="lr33_J5_HUELLE_A4.stl">
				<color rgba="0.4891 0.5125 0.5281 1.0"/>
			</material>
		</visual>
		<inertial>
			<inertia ixx="0.020873722" ixy="-2.8854092e-05" ixz="2.6449921e-05" iyy="0.004489527" iyz="0.0037480452" izz="0.020112826"/>
			<origin rpy="0 0 0" xyz="-0.00050540783 0.11100194 0.017489031"/>
			<mass value="2.26016"/>
		</inertial>
	</link>
	<link name="left_arm5_link">
		<collision>
			<geometry>
				<mesh filename="file://../meshes/lr33_J6_HUELLE_A5_collision.stl" scale="0.001 0.001 0.001"/>
			</geometry>
			<origin rpy="0 0 0" xyz="0 0 0"/>
		</collision>
		<visual>
			<geometry>
				<mesh filename="file://../meshes/lr33_J6_HUELLE_A5.stl" scale="0.001 0.001 0.001"/>
			</geometry>
			<origin rpy="0 0 0" xyz="0 0 0"/>
			<material name="lr33_J6_HUELLE_A5.stl">
				<color rgba="0.4891 0.5125 0.5281 1.0"/>
			</material>
		</visual>
		<inertial>
			<inertia ixx="0.0065069381" ixy="-4.3465385e-07" ixz="-9.7251312e-08" iyy="0.0059938767" iyz="-0.0017520055" izz="0.0022411912"/>
			<origin rpy="0 0 0" xyz="2.9554248e-05 0.0191264 -0.11188403"/>
			<mass value="0.9630036"/>
		</inertial>
	</link>
	<link name="left_arm6_link">
		<collision>
			<geometry>
				<mesh filename="file://../meshes/lr33_J7_HUELLE_A6_collision.stl" scale="0.001 0.001 0.001"/>
			</geometry>
			<origin rpy="0 0 0" xyz="0 0 0"/>
		</collision>
		<visual>
			<geometry>
				<mesh filename="file://../meshes/lr33_J7_HUELLE_A6.stl" scale="0.001 0.001 0.001"/>
			</geometry>
			<origin rpy="0 0 0" xyz="0 0 0"/>
			<material name="lr33_J7_HUELLE_A6.stl">
				<color rgba="0.4891 0.5125 0.5281 1.0"/>
			</material>
		</visual>
		<inertial>
			<inertia ixx="0.0033670847" ixy="-2.9504052e-05" ixz="3.2410535e-05" iyy="0.0032316552" iyz="-6.3747473e-06" izz="0.0031108301"/>
			<origin rpy="0 0 0" xyz="7.2398148e-05 -0.0071472053 -0.005423184"/>
			<mass value="1.7235874"/>
		</inertial>
	</link>
	<link name="left_arm7_link">
		<collision>
			<geometry>
				<mesh filename="file://../meshes/lr33_J8_HUELLE_A7_collision.stl" scale="0.001 0.001 0.001"/>
			</geometry>
			<origin rpy="0 0 0" xyz="0 0 0"/>
		</collision>
		<visual>
			<geometry>
				<mesh filename="file://../meshes/lr33_J8_HUELLE_A7.stl" scale="0.001 0.001 0.001"/>
			</geometry>
			<origin rpy="0 0 0" xyz="0 0 0"/>
			<material name="lr33_J8_HUELLE_A7.stl">
				<color rgba="0.4891 0.5125 0.5281 1.0"/>
			</material>
		</visual>
		<inertial>
			<inertia ixx="0.0004940393" ixy="2.3814086e-06" ixz="0.000366834" iyy="0.0010989451" iyz="-2.1175058e-06" izz="0.00087883997"/>
			<origin rpy="0 0 0" xyz="0.04210866 0.00026132641 0.041361769"/>
			<mass value="0.3805086"/>
		</inertial>
	</link>
	<link name="leftarm7">
		<inertial>
			<inertia ixx="0.0001" ixy="0" ixz="0" iyy="0" iyz="0.0001" izz="0"/>
			<origin rpy="0 0 0" xyz="0 0 0"/>
			<mass value="0.0001"/>
		</inertial>
	</link>
	<link name="left_arm_palm_link">
		<inertial>
			<inertia ixx="0.0001" ixy="0" ixz="0" iyy="0" iyz="0.0001" izz="0"/>
			<origin rpy="0 0 0" xyz="0 0 0"/>
			<mass value="0.0001"/>
		</inertial>
	</link>
	<link name="left_hand_base_link">
		<collision>
			<geometry>
				<mesh filename="file://../meshes/hii_links_export_Base_SWA_collision.stl" scale="0.001 0.001 0.001"/>
			</geometry>
			<origin rpy="0 0 0" xyz="0 0 0"/>
		</collision>
		<visual>
			<geometry>
				<mesh filename="file://../meshes/hii_links_export_Base_SWA.stl" scale="0.001 0.001 0.001"/>
			</geometry>
			<origin rpy="0 0 0" xyz="0 0 0"/>
			<material name="hii_links_export_Base_SWA.stl">
				<color rgba="0.4891 0.5125 0.5281 1.0"/>
			</material>
		</visual>
		<inertial>
			<inertia ixx="0.0017933357" ixy="0.00031399828" ixz="0.00034959916" iyy="0.0016447962" iyz="-5.9390687e-05" izz="0.0016132135"/>
			<origin rpy="0 0 0" xyz="-0.0087899569 -0.010129254 0.059896199"/>
			<mass value="1.3667323"/>
		</inertial>
	</link>
	<link name="left_1thumb_add">
		<collision>
			<geometry>
				<mesh filename="file://../meshes/hii_links_export_D_MP_AB1_collision.stl" scale="0.001 0.001 0.001"/>
			</geometry>
			<origin rpy="0 0 0" xyz="0 0 0"/>
		</collision>
		<visual>
			<geometry>
				<mesh filename="file://../meshes/hii_links_export_D_MP_AB1.stl" scale="0.001 0.001 0.001"/>
			</geometry>
			<origin rpy="0 0 0" xyz="0 0 0"/>
			<material name="hii_links_export_D_MP_AB1.stl">
				<color rgba="0.4891 0.5125 0.5281 1.0"/>
			</material>
		</visual>
		<inertial>
			<inertia ixx="1.949143e-06" ixy="2.4664698e-10" ixz="2.1929014e-11" iyy="8.1326153e-07" iyz="-8.8571547e-08" izz="1.9383156e-06"/>
			<origin rpy="0 0 0" xyz="1.3835101e-06 -0.0059482396 -4.2379221e-05"/>
			<mass value="0.018320891"/>
		</inertial>
	</link>
	<link name="left_1thumb_prox">
		<collision>
			<geometry>
				<mesh filename="file://../meshes/hii_links_export_D_MP_AB2_collision.stl" scale="0.001 0.001 0.001"/>
			</geometry>
			<origin rpy="0 0 0" xyz="0 0 0"/>
		</collision>
		<visual>
			<geometry>
				<mesh filename="file://../meshes/hii_links_export_D_MP_AB2.stl" scale="0.001 0.001 0.001"/>
			</geometry>
			<origin rpy="0 0 0" xyz="0 0 0"/>
			<material name="hii_links_export_D_MP_AB2.stl">
				<color rgba="0.4891 0.5125 0.5281 1.0"/>
			</material>
		</visual>
		<inertial>
			<inertia ixx="7.5834551e-05" ixy="-2.6281e-08" ixz="-9.6494677e-07" iyy="7.2189138e-05" iyz="7.2046567e-06" izz="1.302902e-05"/>
			<origin rpy="0 0 0" xyz="-0.00070620183 -0.00088929917 0.045435077"/>
			<mass value="0.1042168"/>
		</inertial>
	</link>
	<link name="left_1thumb_middle">
		<collision>
			<geometry>
				<mesh filename="file://../meshes/hii_links_export_D_PIP_collision.stl" scale="0.001 0.001 0.001"/>
			</geometry>
			<origin rpy="0 0 0" xyz="0 0 0"/>
		</collision>
		<visual>
			<geometry>
				<mesh filename="file://../meshes/hii_links_export_D_PIP.stl" scale="0.001 0.001 0.001"/>
			</geometry>
			<origin rpy="0 0 0" xyz="0 0 0"/>
			<material name="hii_links_export_D_PIP.stl">
				<color rgba="0.4891 0.5125 0.5281 1.0"/>
			</material>
		</visual>
		<inertial>
			<inertia ixx="5.7707856e-06" ixy="-3.775046e-08" ixz="1.7969102e-08" iyy="4.8638469e-06" iyz="1.7909968e-07" izz="3.3264698e-06"/>
			<origin rpy="0 0 0" xyz="-0.0021607212 -0.0039670011 0.018156604"/>
			<mass value="0.020456522"/>
		</inertial>
	</link>
	<link name="left_1thumb_distal">
		<collision>
			<geometry>
				<mesh filename="file://../meshes/hii_links_export_D_DIP_collision.stl" scale="0.001 0.001 0.001"/>
			</geometry>
			<origin rpy="0 0 0" xyz="0 0 0"/>
		</collision>
		<visual>
			<geometry>
				<mesh filename="file://../meshes/hii_links_export_D_DIP.stl" scale="0.001 0.001 0.001"/>
			</geometry>
			<origin rpy="0 0 0" xyz="0 0 0"/>
			<material name="hii_links_export_D_DIP.stl">
				<color rgba="0.4891 0.5125 0.5281 1.0"/>
			</material>
		</visual>
		<inertial>
			<inertia ixx="4.166899e-06" ixy="2.0543222e-08" ixz="-4.2301869e-07" iyy="3.8166969e-06" iyz="-2.3811409e-07" izz="1.6228215e-06"/>
			<origin rpy="0 0 0" xyz="0.0012768682 -0.0077855057 0.020496053"/>
			<mass value="0.022882065"/>
		</inertial>
	</link>
	<link name="left_2index_add">
		<collision>
			<geometry>
				<mesh filename="file://../meshes/hii_links_export_ZF_MP_AB1_collision.stl" scale="0.001 0.001 0.001"/>
			</geometry>
			<origin rpy="0 0 0" xyz="0 0 0"/>
		</collision>
		<visual>
			<geometry>
				<mesh filename="file://../meshes/hii_links_export_ZF_MP_AB1.stl" scale="0.001 0.001 0.001"/>
			</geometry>
			<origin rpy="0 0 0" xyz="0 0 0"/>
			<material name="hii_links_export_ZF_MP_AB1.stl">
				<color rgba="0.4891 0.5125 0.5281 1.0"/>
			</material>
		</visual>
		<inertial>
			<inertia ixx="1.949143e-06" ixy="2.4745663e-10" ixz="8.9904553e-12" iyy="8.0708486e-07" iyz="-2.9286257e-08" izz="1.9444923e-06"/>
			<origin rpy="0 0 0" xyz="1.3835101e-06 -0.0059423057 0.00026898567"/>
			<mass value="0.018320891"/>
		</inertial>
	</link>
	<link name="left_2index_prox">
		<collision>
			<geometry>
				<mesh filename="file://../meshes/hii_links_export_ZF_MP_AB2_collision.stl" scale="0.001 0.001 0.001"/>
			</geometry>
			<origin rpy="0 0 0" xyz="0 0 0"/>
		</collision>
		<visual>
			<geometry>
				<mesh filename="file://../meshes/hii_links_export_ZF_MP_AB2.stl" scale="0.001 0.001 0.001"/>
			</geometry>
			<origin rpy="0 0 0" xyz="0 0 0"/>
			<material name="hii_links_export_ZF_MP_AB2.stl">
				<color rgba="0.4891 0.5125 0.5281 1.0"/>
			</material>
		</visual>
		<inertial>
			<inertia ixx="7.5834551e-05" ixy="-7.6746395e-08" ixz="-9.622489e-07" iyy="7.2780187e-05" iyz="4.0732308e-06" izz="1.2437971e-05"/>
			<origin rpy="0 0 0" xyz="-0.00070620183 0.0014898078 0.045419352"/>
			<mass value="0.1042168"/>
		</inertial>
	</link>
	<link name="left_2index_middle">
		<collision>
			<geometry>
				<mesh filename="file://../meshes/hii_links_export_ZF_PIP_collision.stl" scale="0.001 0.001 0.001"/>
			</geometry>
			<origin rpy="0 0 0" xyz="0 0 0"/>
		</collision>
		<visual>
			<geometry>
				<mesh filename="file://../meshes/hii_links_export_ZF_PIP.stl" scale="0.001 0.001 0.001"/>
			</geometry>
			<origin rpy="0 0 0" xyz="0 0 0"/>
			<material name="hii_links_export_ZF_PIP.stl">
				<color rgba="0.4891 0.5125 0.5281 1.0"/>
			</material>
		</visual>
		<inertial>
			<inertia ixx="5.7707856e-06" ixy="-3.6758294e-08" ixz="1.9920182e-08" iyy="4.8783569e-06" iyz="9.7768728e-08" izz="3.3119598e-06"/>
			<origin rpy="0 0 0" xyz="-0.0021607212 0.0009400435 0.018735868"/>
			<mass value="0.020456522"/>
		</inertial>
	</link>
	<link name="left_2index_distal">
		<collision>
			<geometry>
				<mesh filename="file://../meshes/hii_links_export_ZF_DIP_collision.stl" scale="0.001 0.001 0.001"/>
			</geometry>
			<origin rpy="0 0 0" xyz="0 0 0"/>
		</collision>
		<visual>
			<geometry>
				<mesh filename="file://../meshes/hii_links_export_ZF_DIP.stl" scale="0.001 0.001 0.001"/>
			</geometry>
			<origin rpy="0 0 0" xyz="0 0 0"/>
			<material name="hii_links_export_ZF_DIP.stl">
				<color rgba="0.4891 0.5125 0.5281 1.0"/>
			</material>
		</visual>
		<inertial>
			<inertia ixx="4.166899e-06" ixy="-1.6240197e-09" ixz="-4.2351411e-07" iyy="3.7857981e-06" iyz="-3.5147089e-07" izz="1.6537203e-06"/>
			<origin rpy="0 0 0" xyz="0.0012768682 -0.00065735241 0.021217137"/>
			<mass value="0.022882065"/>
		</inertial>
	</link>
	<link name="left_3middle_add">
		<collision>
			<geometry>
				<mesh filename="file://../meshes/hii_links_export_MF_MP_AB1_collision.stl" scale="0.001 0.001 0.001"/>
			</geometry>
			<origin rpy="0 0 0" xyz="0 0 0"/>
		</collision>
		<visual>
			<geometry>
				<mesh filename="file://../meshes/hii_links_export_MF_MP_AB1.stl" scale="0.001 0.001 0.001"/>
			</geometry>
			<origin rpy="0 0 0" xyz="0 0 0"/>
			<material name="hii_links_export_MF_MP_AB1.stl">
				<color rgba="0.4891 0.5125 0.5281 1.0"/>
			</material>
		</visual>
		<inertial>
			<inertia ixx="1.949143e-06" ixy="2.4745663e-10" ixz="8.9904553e-12" iyy="8.0708486e-07" iyz="-2.9286257e-08" izz="1.9444923e-06"/>
			<origin rpy="0 0 0" xyz="1.3835101e-06 -0.0059423057 0.00026898567"/>
			<mass value="0.018320891"/>
		</inertial>
	</link>
	<link name="left_3middle_prox">
		<collision>
			<geometry>
				<mesh filename="file://../meshes/hii_links_export_MF_MP_AB2_collision.stl" scale="0.001 0.001 0.001"/>
			</geometry>
			<origin rpy="0 0 0" xyz="0 0 0"/>
		</collision>
		<visual>
			<geometry>
				<mesh filename="file://../meshes/hii_links_export_MF_MP_AB2.stl" scale="0.001 0.001 0.001"/>
			</geometry>
			<origin rpy="0 0 0" xyz="0 0 0"/>
			<material name="hii_links_export_MF_MP_AB2.stl">
				<color rgba="0.4891 0.5125 0.5281 1.0"/>
			</material>
		</visual>
		<inertial>
			<inertia ixx="7.5834551e-05" ixy="-7.6746395e-08" ixz="-9.622489e-07" iyy="7.2780187e-05" iyz="4.0732308e-06" izz="1.2437971e-05"/>
			<origin rpy="0 0 0" xyz="-0.00070620183 0.0014898078 0.045419352"/>
			<mass value="0.1042168"/>
		</inertial>
	</link>
	<link name="left_3middle_middle">
		<collision>
			<geometry>
				<mesh filename="file://../meshes/hii_links_export_MF_PIP_collision.stl" scale="0.001 0.001 0.001"/>
			</geometry>
			<origin rpy="0 0 0" xyz="0 0 0"/>
		</collision>
		<visual>
			<geometry>
				<mesh filename="file://../meshes/hii_links_export_MF_PIP.stl" scale="0.001 0.001 0.001"/>
			</geometry>
			<origin rpy="0 0 0" xyz="0 0 0"/>
			<material name="hii_links_export_MF_PIP.stl">
				<color rgba="0.4891 0.5125 0.5281 1.0"/>
			</material>
		</visual>
		<inertial>
			<inertia ixx="5.7707856e-06" ixy="-3.6758294e-08" ixz="1.9920182e-08" iyy="4.8783569e-06" iyz="9.7768728e-08" izz="3.3119598e-06"/>
			<origin rpy="0 0 0" xyz="-0.0021607212 0.0009400435 0.018735868"/>
			<mass value="0.020456522"/>
		</inertial>
	</link>
	<link name="left_3middle_distal">
		<collision>
			<geometry>
				<mesh filename="file://../meshes/hii_links_export_MF_DIP_collision.stl" scale="0.001 0.001 0.001"/>
			</geometry>
			<origin rpy="0 0 0" xyz="0 0 0"/>
		</collision>
		<visual>
			<geometry>
				<mesh filename="file://../meshes/hii_links_export_MF_DIP.stl" scale="0.001 0.001 0.001"/>
			</geometry>
			<origin rpy="0 0 0" xyz="0 0 0"/>
			<material name="hii_links_export_MF_DIP.stl">
				<color rgba="0.4891 0.5125 0.5281 1.0"/>
			</material>
		</visual>
		<inertial>
			<inertia ixx="4.166899e-06" ixy="-1.6240197e-09" ixz="-4.2351411e-07" iyy="3.7857981e-06" iyz="-3.5147089e-07" izz="1.6537203e-06"/>
			<origin rpy="0 0 0" xyz="0.0012768682 -0.00065735241 0.021217137"/>
			<mass value="0.022882065"/>
		</inertial>
	</link>
	<link name="left_4ring_add">
		<collision>
			<geometry>
				<mesh filename="file://../meshes/hii_links_export_RF_MP_AB1_collision.stl" scale="0.001 0.001 0.001"/>
			</geometry>
			<origin rpy="0 0 0" xyz="0 0 0"/>
		</collision>
		<visual>
			<geometry>
				<mesh filename="file://../meshes/hii_links_export_RF_MP_AB1.stl" scale="0.001 0.001 0.001"/>
			</geometry>
			<origin rpy="0 0 0" xyz="0 0 0"/>
			<material name="hii_links_export_RF_MP_AB1.stl">
				<color rgba="0.4891 0.5125 0.5281 1.0"/>
			</material>
		</visual>
		<inertial>
			<inertia ixx="1.949143e-06" ixy="2.4745663e-10" ixz="8.9904554e-12" iyy="8.0708486e-07" iyz="-2.9286257e-08" izz="1.9444923e-06"/>
			<origin rpy="0 0 0" xyz="1.3835101e-06 -0.0059423057 0.00026898567"/>
			<mass value="0.018320891"/>
		</inertial>
	</link>
	<link name="left_4ring_prox">
		<collision>
			<geometry>
				<mesh filename="file://../meshes/hii_links_export_RF_MP_AB2_collision.stl" scale="0.001 0.001 0.001"/>
			</geometry>
			<origin rpy="0 0 0" xyz="0 0 0"/>
		</collision>
		<visual>
			<geometry>
				<mesh filename="file://../meshes/hii_links_export_RF_MP_AB2.stl" scale="0.001 0.001 0.001"/>
			</geometry>
			<origin rpy="0 0 0" xyz="0 0 0"/>
			<material name="hii_links_export_RF_MP_AB2.stl">
				<color rgba="0.4891 0.5125 0.5281 1.0"/>
			</material>
		</visual>
		<inertial>
			<inertia ixx="7.5834551e-05" ixy="-7.6746395e-08" ixz="-9.622489e-07" iyy="7.2780187e-05" iyz="4.0732308e-06" izz="1.2437971e-05"/>
			<origin rpy="0 0 0" xyz="-0.00070620183 0.0014898078 0.045419352"/>
			<mass value="0.1042168"/>
		</inertial>
	</link>
	<link name="left_4ring_middle">
		<collision>
			<geometry>
				<mesh filename="file://../meshes/hii_links_export_RF_PIP_collision.stl" scale="0.001 0.001 0.001"/>
			</geometry>
			<origin rpy="0 0 0" xyz="0 0 0"/>
		</collision>
		<visual>
			<geometry>
				<mesh filename="file://../meshes/hii_links_export_RF_PIP.stl" scale="0.001 0.001 0.001"/>
			</geometry>
			<origin rpy="0 0 0" xyz="0 0 0"/>
			<material name="hii_links_export_RF_PIP.stl">
				<color rgba="0.4891 0.5125 0.5281 1.0"/>
			</material>
		</visual>
		<inertial>
			<inertia ixx="5.7707856e-06" ixy="-3.6758294e-08" ixz="1.9920182e-08" iyy="4.8783569e-06" iyz="9.7768728e-08" izz="3.3119598e-06"/>
			<origin rpy="0 0 0" xyz="-0.0021607212 0.0009400435 0.018735868"/>
			<mass value="0.020456522"/>
		</inertial>
	</link>
	<link name="left_4ring_distal">
		<collision>
			<geometry>
				<mesh filename="file://../meshes/hii_links_export_RF_DIP_collision.stl" scale="0.001 0.001 0.001"/>
			</geometry>
			<origin rpy="0 0 0" xyz="0 0 0"/>
		</collision>
		<visual>
			<geometry>
				<mesh filename="file://../meshes/hii_links_export_RF_DIP.stl" scale="0.001 0.001 0.001"/>
			</geometry>
			<origin rpy="0 0 0" xyz="0 0 0"/>
			<material name="hii_links_export_RF_DIP.stl">
				<color rgba="0.4891 0.5125 0.5281 1.0"/>
			</material>
		</visual>
		<inertial>
			<inertia ixx="4.166899e-06" ixy="-1.6240197e-09" ixz="-4.2351411e-07" iyy="3.7857981e-06" iyz="-3.5147089e-07" izz="1.6537203e-06"/>
			<origin rpy="0 0 0" xyz="0.0012768682 -0.00065735241 0.021217137"/>
			<mass value="0.022882065"/>
		</inertial>
	</link>
	<link name="left_arm">
		<inertial>
			<inertia ixx="0.0001" ixy="0" ixz="0" iyy="0" iyz="0.0001" izz="0"/>
			<origin rpy="0 0 0" xyz="0 0 0"/>
			<mass value="0.0001"/>
		</inertial>
	</link>
	<link name="right_base_link">
		<collision>
			<geometry>
				<mesh filename="file://../meshes/lr33_J1_Base_frame_collision.stl" scale="0.001 0.001 0.001"/>
			</geometry>
			<origin rpy="0 0 0" xyz="0 0 0"/>
		</collision>
		<visual>
			<geometry>
				<mesh filename="file://../meshes/lr33_J1_Base_frame.stl" scale="0.001 0.001 0.001"/>
			</geometry>
			<origin rpy="0 0 0" xyz="0 0 0"/>
			<material name="lr33_J1_Base_frame.stl">
				<color rgba="0.4891 0.5125 0.5281 1.0"/>
			</material>
		</visual>
		<inertial>
			<inertia ixx="0.001999327" ixy="4.9576601e-06" ixz="-2.9556616e-05" iyy="0.0020108452" iyz="-1.2899418e-05" izz="0.0021402397"/>
			<origin rpy="0 0 0" xyz="-0.00056177913 -0.00012307609 0.087904977"/>
			<mass value="1.6371831"/>
		</inertial>
	</link>
	<link name="right_arm1_link">
		<collision>
			<geometry>
				<mesh filename="file://../meshes/lr33_J2_HUELLE_A1_collision.stl" scale="0.001 0.001 0.001"/>
			</geometry>
			<origin rpy="0 0 0" xyz="0 0 0"/>
		</collision>
		<visual>
			<geometry>
				<mesh filename="file://../meshes/lr33_J2_HUELLE_A1.stl" scale="0.001 0.001 0.001"/>
			</geometry>
			<origin rpy="0 0 0" xyz="0 0 0"/>
			<material name="lr33_J2_HUELLE_A1.stl">
				<color rgba="0.4891 0.5125 0.5281 1.0"/>
			</material>
		</visual>
		<inertial>
			<inertia ixx="0.018296983" ixy="3.1396253e-05" ixz="4.4694254e-05" iyy="0.017936266" iyz="-0.0018995942" izz="0.0046738563"/>
			<origin rpy="0 0 0" xyz="-0.00035640179 0.020114122 -0.046742146"/>
			<mass value="2.6516672"/>
		</inertial>
	</link>
	<link name="right_arm2_link">
		<collision>
			<geometry>
				<mesh filename="file://../meshes/lr33_J3_HUELLE_A2_collision.stl" scale="0.001 0.001 0.001"/>
			</geometry>
			<origin rpy="0 0 0" xyz="0 0 0"/>
		</collision>
		<visual>
			<geometry>
				<mesh filename="file://../meshes/lr33_J3_HUELLE_A2.stl" scale="0.001 0.001 0.001"/>
			</geometry>
			<origin rpy="0 0 0" xyz="0 0 0"/>
			<material name="lr33_J3_HUELLE_A2.stl">
				<color rgba="0.4891 0.5125 0.5281 1.0"/>
			</material>
		</visual>
		<inertial>
			<inertia ixx="0.020735215" ixy="-2.7931565e-05" ixz="2.5887286e-05" iyy="0.0044725702" iyz="0.0037163729" izz="0.019989654"/>
			<origin rpy="0 0 0" xyz="-0.00050931943 0.11014738 0.01762827"/>
			<mass value="2.2434057"/>
		</inertial>
	</link>
	<link name="right_arm3_link">
		<collision>
			<geometry>
				<mesh filename="file://../meshes/lr33_J4_HUELLE_A3_collision.stl" scale="0.001 0.001 0.001"/>
			</geometry>
			<origin rpy="0 0 0" xyz="0 0 0"/>
		</collision>
		<visual>
			<geometry>
				<mesh filename="file://../meshes/lr33_J4_HUELLE_A3.stl" scale="0.001 0.001 0.001"/>
			</geometry>
			<origin rpy="0 0 0" xyz="0 0 0"/>
			<material name="lr33_J4_HUELLE_A3.stl">
				<color rgba="0.4891 0.5125 0.5281 1.0"/>
			</material>
		</visual>
		<inertial>
			<inertia ixx="0.016892158" ixy="1.8209314e-05" ixz="2.4143214e-05" iyy="0.016412123" iyz="-0.0016632049" izz="0.0041598103"/>
			<origin rpy="0 0 0" xyz="-0.00021507605 0.017854882 -0.054430037"/>
			<mass value="2.2447741"/>
		</inertial>
	</link>
	<link name="right_arm4_link">
		<collision>
			<geometry>
				<mesh filename="file://../meshes/lr33_J5_HUELLE_A4_collision.stl" scale="0.001 0.001 0.001"/>
			</geometry>
			<origin rpy="0 0 0" xyz="0 0 0"/>
		</collision>
		<visual>
			<geometry>
				<mesh filename="file://../meshes/lr33_J5_HUELLE_A4.stl" scale="0.001 0.001 0.001"/>
			</geometry>
			<origin rpy="0 0 0" xyz="0 0 0"/>
			<material name="lr33_J5_HUELLE_A4.stl">
				<color rgba="0.4891 0.5125 0.5281 1.0"/>
			</material>
		</visual>
		<inertial>
			<inertia ixx="0.02087287" ixy="-2.8939221e-05" ixz="2.6464794e-05" iyy="0.0044894926" iyz="0.0037479007" izz="0.020111991"/>
			<origin rpy="0 0 0" xyz="-0.00050566552 0.11100444 0.017488594"/>
			<mass value="2.2601213"/>
		</inertial>
	</link>
	<link name="right_arm5_link">
		<collision>
			<geometry>
				<mesh filename="file://../meshes/lr33_J6_HUELLE_A5_collision.stl" scale="0.001 0.001 0.001"/>
			</geometry>
			<origin rpy="0 0 0" xyz="0 0 0"/>
		</collision>
		<visual>
			<geometry>
				<mesh filename="file://../meshes/lr33_J6_HUELLE_A5.stl" scale="0.001 0.001 0.001"/>
			</geometry>
			<origin rpy="0 0 0" xyz="0 0 0"/>
			<material name="lr33_J6_HUELLE_A5.stl">
				<color rgba="0.4891 0.5125 0.5281 1.0"/>
			</material>
		</visual>
		<inertial>
			<inertia ixx="0.0065067762" ixy="-4.6514992e-07" ixz="-1.1696255e-07" iyy="0.0059938206" iyz="-0.0017519318" izz="0.002241069"/>
			<origin rpy="0 0 0" xyz="2.8970932e-05 0.01912858 -0.11188262"/>
			<mass value="0.96296489"/>
		</inertial>
	</link>
	<link name="right_arm6_link">
		<collision>
			<geometry>
				<mesh filename="file://../meshes/lr33_J7_HUELLE_A6_collision.stl" scale="0.001 0.001 0.001"/>
			</geometry>
			<origin rpy="0 0 0" xyz="0 0 0"/>
		</collision>
		<visual>
			<geometry>
				<mesh filename="file://../meshes/lr33_J7_HUELLE_A6.stl" scale="0.001 0.001 0.001"/>
			</geometry>
			<origin rpy="0 0 0" xyz="0 0 0"/>
			<material name="lr33_J7_HUELLE_A6.stl">
				<color rgba="0.4891 0.5125 0.5281 1.0"/>
			</material>
		</visual>
		<inertial>
			<inertia ixx="0.0033670847" ixy="-2.9504052e-05" ixz="3.2410535e-05" iyy="0.0032316552" iyz="-6.3747473e-06" izz="0.0031108301"/>
			<origin rpy="0 0 0" xyz="7.2398148e-05 -0.0071472053 -0.005423184"/>
			<mass value="1.7235874"/>
		</inertial>
	</link>
	<link name="right_arm7_link">
		<collision>
			<geometry>
				<mesh filename="file://../meshes/lr33_J8_HUELLE_A7_collision.stl" scale="0.001 0.001 0.001"/>
			</geometry>
			<origin rpy="0 0 0" xyz="0 0 0"/>
		</collision>
		<visual>
			<geometry>
				<mesh filename="file://../meshes/lr33_J8_HUELLE_A7.stl" scale="0.001 0.001 0.001"/>
			</geometry>
			<origin rpy="0 0 0" xyz="0 0 0"/>
			<material name="lr33_J8_HUELLE_A7.stl">
				<color rgba="0.4891 0.5125 0.5281 1.0"/>
			</material>
		</visual>
		<inertial>
			<inertia ixx="0.0042361593" ixy="-4.0254012e-05" ixz="-5.1878093e-05" iyy="0.0051254662" iyz="-5.6277947e-05" izz="0.0046714051"/>
			<origin rpy="0 0 0" xyz="0.0076743134 -0.0043922068 0.013334192"/>
			<mass value="2.104096"/>
		</inertial>
	</link>
	<link name="rightarm7">
		<inertial>
			<inertia ixx="0.0001" ixy="0" ixz="0" iyy="0" iyz="0.0001" izz="0"/>
			<origin rpy="0 0 0" xyz="0 0 0"/>
			<mass value="0.0001"/>
		</inertial>
	</link>
	<link name="right_arm_palm_link">
		<inertial>
			<inertia ixx="0.0001" ixy="0" ixz="0" iyy="0" iyz="0.0001" izz="0"/>
			<origin rpy="0 0 0" xyz="0 0 0"/>
			<mass value="0.0001"/>
		</inertial>
	</link>
	<link name="right_hand_base_link">
		<collision>
			<geometry>
				<mesh filename="file://../meshes/hand2_export_Base_SWA_collision.stl" scale="0.001 0.001 0.001"/>
			</geometry>
			<origin rpy="0 0 0" xyz="0 0 0"/>
		</collision>
		<visual>
			<geometry>
				<mesh filename="file://../meshes/hand2_export_Base_SWA.stl" scale="0.001 0.001 0.001"/>
			</geometry>
			<origin rpy="0 0 0" xyz="0 0 0"/>
			<material name="hand2_export_Base_SWA.stl">
				<color rgba="0.4891 0.5125 0.5281 1.0"/>
			</material>
		</visual>
		<inertial>
			<inertia ixx="0.0035511189" ixy="-0.00069950772" ixz="0.00065224296" iyy="0.0028340681" iyz="0.00021691074" izz="0.0033156226"/>
			<origin rpy="0 0 0" xyz="-0.015598331 0.00094869872 0.070182511"/>
			<mass value="1.3667323"/>
		</inertial>
	</link>
	<link name="right_1thumb_add">
		<collision>
			<geometry>
				<mesh filename="file://../meshes/hand2_export_D_MP_AB1_collision.stl" scale="0.001 0.001 0.001"/>
			</geometry>
			<origin rpy="0 0 0" xyz="0 0 0"/>
		</collision>
		<visual>
			<geometry>
				<mesh filename="file://../meshes/hand2_export_D_MP_AB1.stl" scale="0.001 0.001 0.001"/>
			</geometry>
			<origin rpy="0 0 0" xyz="0 0 0"/>
			<material name="hand2_export_D_MP_AB1.stl">
				<color rgba="0.4891 0.5125 0.5281 1.0"/>
			</material>
		</visual>
		<inertial>
			<inertia ixx="1.949143e-06" ixy="2.4745663e-10" ixz="8.9904553e-12" iyy="8.0708486e-07" iyz="-2.9286257e-08" izz="1.9444923e-06"/>
			<origin rpy="0 0 0" xyz="1.3835101e-06 -0.0059423057 0.00026898567"/>
			<mass value="0.018320891"/>
		</inertial>
	</link>
	<link name="right_1thumb_prox">
		<collision>
			<geometry>
				<mesh filename="file://../meshes/hand2_export_D_MP_AB2_collision.stl" scale="0.001 0.001 0.001"/>
			</geometry>
			<origin rpy="0 0 0" xyz="0 0 0"/>
		</collision>
		<visual>
			<geometry>
				<mesh filename="file://../meshes/hand2_export_D_MP_AB2.stl" scale="0.001 0.001 0.001"/>
			</geometry>
			<origin rpy="0 0 0" xyz="0 0 0"/>
			<material name="hand2_export_D_MP_AB2.stl">
				<color rgba="0.4891 0.5125 0.5281 1.0"/>
			</material>
		</visual>
		<inertial>
			<inertia ixx="1.949143e-06" ixy="2.4745663e-10" ixz="8.9904553e-12" iyy="8.0708486e-07" iyz="-2.9286257e-08" izz="1.9444923e-06"/>
			<origin rpy="0 0 0" xyz="1.3835101e-06 -0.0059423057 0.00026898567"/>
			<mass value="0.018320891"/>
		</inertial>
	</link>
	<link name="right_1thumb_middle">
		<collision>
			<geometry>
				<mesh filename="file://../meshes/hand2_export_D_PIP_collision.stl" scale="0.001 0.001 0.001"/>
			</geometry>
			<origin rpy="0 0 0" xyz="0 0 0"/>
		</collision>
		<visual>
			<geometry>
				<mesh filename="file://../meshes/hand2_export_D_PIP.stl" scale="0.001 0.001 0.001"/>
			</geometry>
			<origin rpy="0 0 0" xyz="0 0 0"/>
			<material name="hand2_export_D_PIP.stl">
				<color rgba="0.4891 0.5125 0.5281 1.0"/>
			</material>
		</visual>
		<inertial>
			<inertia ixx="5.7707856e-06" ixy="-3.6758294e-08" ixz="1.9920182e-08" iyy="4.8783569e-06" iyz="9.7768728e-08" izz="3.3119598e-06"/>
			<origin rpy="0 0 0" xyz="-0.0021607212 0.0009400435 0.018235868"/>
			<mass value="0.020456522"/>
		</inertial>
	</link>
	<link name="right_1thumb_distal">
		<collision>
			<geometry>
				<mesh filename="file://../meshes/hand2_export_D_DIP_collision.stl" scale="0.001 0.001 0.001"/>
			</geometry>
			<origin rpy="0 0 0" xyz="0 0 0"/>
		</collision>
		<visual>
			<geometry>
				<mesh filename="file://../meshes/hand2_export_D_DIP.stl" scale="0.001 0.001 0.001"/>
			</geometry>
			<origin rpy="0 0 0" xyz="0 0 0"/>
			<material name="hand2_export_D_DIP.stl">
				<color rgba="0.4891 0.5125 0.5281 1.0"/>
			</material>
		</visual>
		<inertial>
			<inertia ixx="4.166899e-06" ixy="-1.6240197e-09" ixz="-4.2351411e-07" iyy="3.7857981e-06" iyz="-3.5147089e-07" izz="1.6537203e-06"/>
			<origin rpy="0 0 0" xyz="0.0012768682 -0.00065735241 0.020717137"/>
			<mass value="0.022882065"/>
		</inertial>
	</link>
	<link name="right_2index_add">
		<collision>
			<geometry>
				<mesh filename="file://../meshes/hand2_export_ZF_MP_AB1_collision.stl" scale="0.001 0.001 0.001"/>
			</geometry>
			<origin rpy="0 0 0" xyz="0 0 0"/>
		</collision>
		<visual>
			<geometry>
				<mesh filename="file://../meshes/hand2_export_ZF_MP_AB1.stl" scale="0.001 0.001 0.001"/>
			</geometry>
			<origin rpy="0 0 0" xyz="0 0 0"/>
			<material name="hand2_export_ZF_MP_AB1.stl">
				<color rgba="0.4891 0.5125 0.5281 1.0"/>
			</material>
		</visual>
		<inertial>
			<inertia ixx="1.949143e-06" ixy="2.4745663e-10" ixz="8.9904553e-12" iyy="8.0708486e-07" iyz="-2.9286257e-08" izz="1.9444923e-06"/>
			<origin rpy="0 0 0" xyz="1.3835101e-06 -0.0059423057 0.00026898567"/>
			<mass value="0.018320891"/>
		</inertial>
	</link>
	<link name="right_2index_prox">
		<collision>
			<geometry>
				<mesh filename="file://../meshes/hand2_export_ZF_MP_AB2_collision.stl" scale="0.001 0.001 0.001"/>
			</geometry>
			<origin rpy="0 0 0" xyz="0 0 0"/>
		</collision>
		<visual>
			<geometry>
				<mesh filename="file://../meshes/hand2_export_ZF_MP_AB2.stl" scale="0.001 0.001 0.001"/>
			</geometry>
			<origin rpy="0 0 0" xyz="0 0 0"/>
			<material name="hand2_export_ZF_MP_AB2.stl">
				<color rgba="0.4891 0.5125 0.5281 1.0"/>
			</material>
		</visual>
		<inertial>
			<inertia ixx="7.5834551e-05" ixy="-7.6746395e-08" ixz="-9.622489e-07" iyy="7.2780187e-05" iyz="4.0732308e-06" izz="1.2437971e-05"/>
			<origin rpy="0 0 0" xyz="-0.00070620183 0.0014898078 0.045419352"/>
			<mass value="0.1042168"/>
		</inertial>
	</link>
	<link name="right_2index_middle">
		<collision>
			<geometry>
				<mesh filename="file://../meshes/hand2_export_ZF_PIP_collision.stl" scale="0.001 0.001 0.001"/>
			</geometry>
			<origin rpy="0 0 0" xyz="0 0 0"/>
		</collision>
		<visual>
			<geometry>
				<mesh filename="file://../meshes/hand2_export_ZF_PIP.stl" scale="0.001 0.001 0.001"/>
			</geometry>
			<origin rpy="0 0 0" xyz="0 0 0"/>
			<material name="hand2_export_ZF_PIP.stl">
				<color rgba="0.4891 0.5125 0.5281 1.0"/>
			</material>
		</visual>
		<inertial>
			<inertia ixx="5.7707856e-06" ixy="-3.6758294e-08" ixz="1.9920182e-08" iyy="4.8783569e-06" iyz="9.7768728e-08" izz="3.3119598e-06"/>
			<origin rpy="0 0 0" xyz="-0.0021607212 0.0009400435 0.018235868"/>
			<mass value="0.020456522"/>
		</inertial>
	</link>
	<link name="right_2index_distal">
		<collision>
			<geometry>
				<mesh filename="file://../meshes/hand2_export_ZF_DIP_collision.stl" scale="0.001 0.001 0.001"/>
			</geometry>
			<origin rpy="0 0 0" xyz="0 0 0"/>
		</collision>
		<visual>
			<geometry>
				<mesh filename="file://../meshes/hand2_export_ZF_DIP.stl" scale="0.001 0.001 0.001"/>
			</geometry>
			<origin rpy="0 0 0" xyz="0 0 0"/>
			<material name="hand2_export_ZF_DIP.stl">
				<color rgba="0.4891 0.5125 0.5281 1.0"/>
			</material>
		</visual>
		<inertial>
			<inertia ixx="4.166899e-06" ixy="-1.6240197e-09" ixz="-4.2351411e-07" iyy="3.7857981e-06" iyz="-3.5147089e-07" izz="1.6537203e-06"/>
			<origin rpy="0 0 0" xyz="0.0012768682 -0.00065735241 0.020717137"/>
			<mass value="0.022882065"/>
		</inertial>
	</link>
	<link name="right_3middle_add">
		<collision>
			<geometry>
				<mesh filename="file://../meshes/hand2_export_MF_MP_AB1_collision.stl" scale="0.001 0.001 0.001"/>
			</geometry>
			<origin rpy="0 0 0" xyz="0 0 0"/>
		</collision>
		<visual>
			<geometry>
				<mesh filename="file://../meshes/hand2_export_MF_MP_AB1.stl" scale="0.001 0.001 0.001"/>
			</geometry>
			<origin rpy="0 0 0" xyz="0 0 0"/>
			<material name="hand2_export_MF_MP_AB1.stl">
				<color rgba="0.4891 0.5125 0.5281 1.0"/>
			</material>
		</visual>
		<inertial>
			<inertia ixx="1.949143e-06" ixy="2.4745663e-10" ixz="8.9904554e-12" iyy="8.0708486e-07" iyz="-2.9286257e-08" izz="1.9444923e-06"/>
			<origin rpy="0 0 0" xyz="1.3835101e-06 -0.0059423057 0.00026898567"/>
			<mass value="0.018320891"/>
		</inertial>
	</link>
	<link name="right_3middle_prox">
		<collision>
			<geometry>
				<mesh filename="file://../meshes/hand2_export_MF_MP_AB2_collision.stl" scale="0.001 0.001 0.001"/>
			</geometry>
			<origin rpy="0 0 0" xyz="0 0 0"/>
		</collision>
		<visual>
			<geometry>
				<mesh filename="file://../meshes/hand2_export_MF_MP_AB2.stl" scale="0.001 0.001 0.001"/>
			</geometry>
			<origin rpy="0 0 0" xyz="0 0 0"/>
			<material name="hand2_export_MF_MP_AB2.stl">
				<color rgba="0.4891 0.5125 0.5281 1.0"/>
			</material>
		</visual>
		<inertial>
			<inertia ixx="7.5834551e-05" ixy="-7.6746395e-08" ixz="-9.622489e-07" iyy="7.2780187e-05" iyz="4.0732308e-06" izz="1.2437971e-05"/>
			<origin rpy="0 0 0" xyz="-0.00070620183 0.0014898078 0.045419352"/>
			<mass value="0.1042168"/>
		</inertial>
	</link>
	<link name="right_3middle_middle">
		<collision>
			<geometry>
				<mesh filename="file://../meshes/hand2_export_MF_PIP_collision.stl" scale="0.001 0.001 0.001"/>
			</geometry>
			<origin rpy="0 0 0" xyz="0 0 0"/>
		</collision>
		<visual>
			<geometry>
				<mesh filename="file://../meshes/hand2_export_MF_PIP.stl" scale="0.001 0.001 0.001"/>
			</geometry>
			<origin rpy="0 0 0" xyz="0 0 0"/>
			<material name="hand2_export_MF_PIP.stl">
				<color rgba="0.4891 0.5125 0.5281 1.0"/>
			</material>
		</visual>
		<inertial>
			<inertia ixx="5.7707856e-06" ixy="-3.6758294e-08" ixz="1.9920182e-08" iyy="4.8783569e-06" iyz="9.7768728e-08" izz="3.3119598e-06"/>
			<origin rpy="0 0 0" xyz="-0.0021607212 0.0009400435 0.018235868"/>
			<mass value="0.020456522"/>
		</inertial>
	</link>
	<link name="right_3middle_distal">
		<collision>
			<geometry>
				<mesh filename="file://../meshes/hand2_export_MF_DIP_collision.stl" scale="0.001 0.001 0.001"/>
			</geometry>
			<origin rpy="0 0 0" xyz="0 0 0"/>
		</collision>
		<visual>
			<geometry>
				<mesh filename="file://../meshes/hand2_export_MF_DIP.stl" scale="0.001 0.001 0.001"/>
			</geometry>
			<origin rpy="0 0 0" xyz="0 0 0"/>
			<material name="hand2_export_MF_DIP.stl">
				<color rgba="0.4891 0.5125 0.5281 1.0"/>
			</material>
		</visual>
		<inertial>
			<inertia ixx="4.166899e-06" ixy="-1.6240197e-09" ixz="-4.2351411e-07" iyy="3.7857981e-06" iyz="-3.5147089e-07" izz="1.6537203e-06"/>
			<origin rpy="0 0 0" xyz="0.0012768682 -0.00065735241 0.020717137"/>
			<mass value="0.022882065"/>
		</inertial>
	</link>
	<link name="right_4ring_add">
		<collision>
			<geometry>
				<mesh filename="file://../meshes/hand2_export_RF_MP_AB1_collision.stl" scale="0.001 0.001 0.001"/>
			</geometry>
			<origin rpy="0 0 0" xyz="0 0 0"/>
		</collision>
		<visual>
			<geometry>
				<mesh filename="file://../meshes/hand2_export_RF_MP_AB1.stl" scale="0.001 0.001 0.001"/>
			</geometry>
			<origin rpy="0 0 0" xyz="0 0 0"/>
			<material name="hand2_export_RF_MP_AB1.stl">
				<color rgba="0.4891 0.5125 0.5281 1.0"/>
			</material>
		</visual>
		<inertial>
			<inertia ixx="1.949143e-06" ixy="2.4745663e-10" ixz="8.9904552e-12" iyy="8.0708486e-07" iyz="-2.9286257e-08" izz="1.9444923e-06"/>
			<origin rpy="0 0 0" xyz="1.3835101e-06 -0.0059423057 0.00026898567"/>
			<mass value="0.018320891"/>
		</inertial>
	</link>
	<link name="right_4ring_prox">
		<collision>
			<geometry>
				<mesh filename="file://../meshes/hand2_export_RF_MP_AB2_collision.stl" scale="0.001 0.001 0.001"/>
			</geometry>
			<origin rpy="0 0 0" xyz="0 0 0"/>
		</collision>
		<visual>
			<geometry>
				<mesh filename="file://../meshes/hand2_export_RF_MP_AB2.stl" scale="0.001 0.001 0.001"/>
			</geometry>
			<origin rpy="0 0 0" xyz="0 0 0"/>
			<material name="hand2_export_RF_MP_AB2.stl">
				<color rgba="0.4891 0.5125 0.5281 1.0"/>
			</material>
		</visual>
		<inertial>
			<inertia ixx="7.5834551e-05" ixy="-7.6746395e-08" ixz="-9.622489e-07" iyy="7.2780187e-05" iyz="4.0732308e-06" izz="1.2437971e-05"/>
			<origin rpy="0 0 0" xyz="-0.00070620183 0.0014898078 0.045419352"/>
			<mass value="0.1042168"/>
		</inertial>
	</link>
	<link name="right_4ring_middle">
		<collision>
			<geometry>
				<mesh filename="file://../meshes/hand2_export_RF_PIP_collision.stl" scale="0.001 0.001 0.001"/>
			</geometry>
			<origin rpy="0 0 0" xyz="0 0 0"/>
		</collision>
		<visual>
			<geometry>
				<mesh filename="file://../meshes/hand2_export_RF_PIP.stl" scale="0.001 0.001 0.001"/>
			</geometry>
			<origin rpy="0 0 0" xyz="0 0 0"/>
			<material name="hand2_export_RF_PIP.stl">
				<color rgba="0.4891 0.5125 0.5281 1.0"/>
			</material>
		</visual>
		<inertial>
			<inertia ixx="5.7707856e-06" ixy="-3.6758294e-08" ixz="1.9920182e-08" iyy="4.8783569e-06" iyz="9.7768728e-08" izz="3.3119598e-06"/>
			<origin rpy="0 0 0" xyz="-0.0021607212 0.0009400435 0.018235868"/>
			<mass value="0.020456522"/>
		</inertial>
	</link>
	<link name="right_4ring_distal">
		<collision>
			<geometry>
				<mesh filename="file://../meshes/hand2_export_RF_DIP_collision.stl" scale="0.001 0.001 0.001"/>
			</geometry>
			<origin rpy="0 0 0" xyz="0 0 0"/>
		</collision>
		<visual>
			<geometry>
				<mesh filename="file://../meshes/hand2_export_RF_DIP.stl" scale="0.001 0.001 0.001"/>
			</geometry>
			<origin rpy="0 0 0" xyz="0 0 0"/>
			<material name="hand2_export_RF_DIP.stl">
				<color rgba="0.4891 0.5125 0.5281 1.0"/>
			</material>
		</visual>
		<inertial>
			<inertia ixx="4.166899e-06" ixy="-1.6240197e-09" ixz="-4.2351411e-07" iyy="3.7857981e-06" iyz="-3.5147089e-07" izz="1.6537203e-06"/>
			<origin rpy="0 0 0" xyz="0.0012768682 -0.00065735241 0.020717137"/>
			<mass value="0.022882065"/>
		</inertial>
	</link>
	<link name="right_arm">
		<inertial>
			<inertia ixx="0.0001" ixy="0" ixz="0" iyy="0" iyz="0.0001" izz="0"/>
			<origin rpy="0 0 0" xyz="0 0 0"/>
			<mass value="0.0001"/>
		</inertial>
	</link>
	<link name="head_base_link">
		<collision>
			<geometry>
				<mesh filename="file://../meshes/justin_rj_kopf_HALS_EINBAU_collision.stl" scale="0.001 0.001 0.001"/>
			</geometry>
			<origin rpy="0 0 0" xyz="0 0 0"/>
		</collision>
		<visual>
			<geometry>
				<mesh filename="file://../meshes/justin_rj_kopf_HALS_EINBAU.stl" scale="0.001 0.001 0.001"/>
			</geometry>
			<origin rpy="0 0 0" xyz="0 0 0"/>
			<material name="justin_rj_kopf_HALS_EINBAU.stl">
				<color rgba="0.4891 0.5125 0.5281 1.0"/>
			</material>
		</visual>
		<inertial>
			<inertia ixx="5.9259822e-05" ixy="4.7994572e-09" ixz="-2.2359864e-08" iyy="0.00010223276" iyz="2.0227406e-08" izz="5.9028063e-05"/>
			<origin rpy="0 0 0" xyz="6.6467819e-06 -0.0057325972 -7.8349893e-05"/>
			<mass value="0.1416278"/>
		</inertial>
	</link>
	<link name="head1_link">
		<collision>
			<geometry>
				<mesh filename="file://../meshes/justin_rj_kopf_HALS_ROT_collision.stl" scale="0.001 0.001 0.001"/>
			</geometry>
			<origin rpy="0 0 0" xyz="0 0 0"/>
		</collision>
		<visual>
			<geometry>
				<mesh filename="file://../meshes/justin_rj_kopf_HALS_ROT.stl" scale="0.001 0.001 0.001"/>
			</geometry>
			<origin rpy="0 0 0" xyz="0 0 0"/>
			<material name="justin_rj_kopf_HALS_ROT.stl">
				<color rgba="0.4891 0.5125 0.5281 1.0"/>
			</material>
		</visual>
		<inertial>
			<inertia ixx="0.0010509203" ixy="-2.995426e-05" ixz="1.4804585e-06" iyy="0.00060151038" iyz="-3.5202362e-06" izz="0.0011601499"/>
			<origin rpy="0 0 0" xyz="-0.00082190018 -0.024636671 0.0001346736"/>
			<mass value="0.66623727"/>
		</inertial>
	</link>
	<link name="head2_link">
		<collision>
			<geometry>
				<mesh filename="file://../meshes/justin_rj_kopf_HALS_KNICK_collision.stl" scale="0.001 0.001 0.001"/>
			</geometry>
			<origin rpy="0 0 0" xyz="0 0 0"/>
		</collision>
		<visual>
			<geometry>
				<mesh filename="file://../meshes/justin_rj_kopf_HALS_KNICK.stl" scale="0.001 0.001 0.001"/>
			</geometry>
			<origin rpy="0 0 0" xyz="0 0 0"/>
			<material name="justin_rj_kopf_HALS_KNICK.stl">
				<color rgba="0.4891 0.5125 0.5281 1.0"/>
			</material>
		</visual>
		<inertial>
			<inertia ixx="0.019809012" ixy="-0.003196468" ixz="-7.2683857e-05" iyy="0.012383785" iyz="2.0267451e-05" izz="0.024137242"/>
			<origin rpy="0 0 0" xyz="-0.037703164 -0.1356722 0.0004117653"/>
			<mass value="2.7802787"/>
		</inertial>
	</link>
	<link name="head2">
		<inertial>
			<inertia ixx="0" ixy="0" ixz="0" iyy="0" iyz="0" izz="0"/>
			<origin rpy="0 0 0" xyz="0 0 0"/>
			<mass value="0"/>
		</inertial>
	</link>
	<link name="head_realsense">
		<inertial>
			<inertia ixx="0.0001" ixy="0" ixz="0" iyy="0" iyz="0.0001" izz="0"/>
			<origin rpy="0 0 0" xyz="0 0 0"/>
			<mass value="0.0001"/>
		</inertial>
	</link>
	<joint name="fixed_base_platform" type="fixed">
		<parent link="base_link"/>
		<child link="platform_link"/>
		<axis xyz="0 0 1"/>
		<origin rpy="0 0 0" xyz="0 0 0"/>
	</joint>
	<joint name="wheel_rf" type="fixed">
		<parent link="platform_link"/>
		<child link="wheel_rf_link"/>
		<axis xyz="0 1 0"/>
		<limit effort="100000000000000000" lower="-3.141592653589793" upper="3.141592653589793" velocity="100000000000000000"/>
		<origin rpy="-1.5707963267948966 0 0.7853896781302238" xyz="0.3427 -0.25714 0.0289"/>
	</joint>
	<joint name="wheel_lf" type="fixed">
		<parent link="platform_link"/>
		<child link="wheel_lf_link"/>
		<axis xyz="0 1 0"/>
		<limit effort="100000000000000000" lower="-3.141592653589793" upper="3.141592653589793" velocity="100000000000000000"/>
		<origin rpy="-1.5707963267948966 0 2.3561860049251204" xyz="0.34199 0.25784 0.0289"/>
	</joint>
	<joint name="wheel_lb" type="fixed">
		<parent link="platform_link"/>
		<child link="wheel_rb_link"/>
		<axis xyz="0 1 0"/>
		<limit effort="100000000000000000" lower="-3.141592653589793" upper="3.141592653589793" velocity="100000000000000000"/>
		<origin rpy="-1.5707963267948966 0 -2.3562029754595697" xyz="-0.3427 0.25714 0.0289"/>
	</joint>
	<joint name="wheel_rb" type="fixed">
		<parent link="platform_link"/>
		<child link="wheel_lb_link"/>
		<axis xyz="0 1 0"/>
		<limit effort="100000000000000000" lower="-3.141592653589793" upper="3.141592653589793" velocity="100000000000000000"/>
		<origin rpy="-1.570796326794897 0 -0.7854066486646727" xyz="-0.34199 -0.25784 0.0289"/>
	</joint>
	<joint name="fixed_platform_torso" type="fixed">
		<parent link="platform_link"/>
		<child link="torso_base_link"/>
		<axis xyz="0 0 1"/>
		<origin rpy="0 0 1.5707963267948966" xyz="0 0 0.5936"/>
	</joint>
	<joint name="torso1" type="revolute">
		<parent link="torso_base_link"/>
		<child link="torso1_link"/>
		<axis xyz="0 0 1"/>
		<limit effort="145" lower="-1.74533" upper="3.31613" velocity="1"/>
		<origin rpy="2.0222662488590783e-21 -2.220446049250313e-16 -1.5707963267948966" xyz="0 0 0"/>
	</joint>
	<joint name="torso2" type="revolute">
		<parent link="torso1_link"/>
		<child link="torso2_link"/>
		<axis xyz="0 0 1"/>
		<limit effort="150" lower="-1.22173" upper="0.5236" velocity="1"/>
		<origin rpy="-1.5707963267948966 -1.5707963118937354 0" xyz="2.5024426975051024e-17 2.2790940624780724e-22 0.1127"/>
	</joint>
	<joint name="torso3" type="revolute">
		<parent link="torso2_link"/>
		<child link="torso3_link"/>
		<axis xyz="0 0 1"/>
		<limit effort="150" lower="0.174533" upper="2.33874" velocity="1"/>
		<origin rpy="2.220446049250314e-16 0 5.403877991017463e-16" xyz="0.3 -2.455409127005593e-16 -9.184547653667767e-18"/>
	</joint>
	<joint name="torso4" type="revolute">
		<parent link="torso3_link"/>
		<child link="torso4_link"/>
		<axis xyz="0 0 1"/>
		<limit effort="150" lower="-1.57" upper="0.1" velocity="1"/>
		<origin rpy="-4.996833070539357e-33 0 -1.3057147528115987e-15" xyz="0.3 -4.076572524310834e-16 -4.59227382683355e-18"/>
	</joint>
	<joint name="fixed_torso_left" type="fixed">
		<parent link="torso4_link"/>
		<child link="left_base_link"/>
		<axis xyz="0 0 1"/>
		<origin rpy="0 0.5235989774905888 0" xyz="0.035 0.088 -0.0126628"/>
	</joint>
	<joint name="left_arm1" type="revolute">
		<parent link="left_base_link"/>
		<child link="left_arm1_link"/>
		<axis xyz="0 0 -1"/>
		<limit effort="145" lower="-2.9670597283903604" upper="2.9670597283903604" velocity="1"/>
		<origin rpy="0 0 0" xyz="0 0 0.31"/>
	</joint>
	<joint name="left_arm2" type="revolute">
		<parent link="left_arm1_link"/>
		<child link="left_arm2_link"/>
		<axis xyz="0 0 -1"/>
		<limit effort="145" lower="-2.0943951023931953" upper="2.0943951023931953" velocity="1"/>
		<origin rpy="1.5707963267948966 0 0" xyz="0 0 0"/>
	</joint>
	<joint name="left_arm3" type="revolute">
		<parent link="left_arm2_link"/>
		<child link="left_arm3_link"/>
		<axis xyz="0 0 -1"/>
		<limit effort="100" lower="-2.9670597283903604" upper="2.9670597283903604" velocity="1.75"/>
		<origin rpy="-1.5707963267948966 1.5707963267948966 0" xyz="0 0.4 2.4492127076447546e-17"/>
	</joint>
	<joint name="left_arm4" type="revolute">
		<parent link="left_arm3_link"/>
		<child link="left_arm4_link"/>
		<axis xyz="0 0 -1"/>
		<limit effort="100" lower="-2.0943951023931953" upper="2.0943951023931953" velocity="1.75"/>
		<origin rpy="1.5707963267948966 0 0" xyz="0 0 0"/>
	</joint>
	<joint name="left_arm5" type="revolute">
		<parent link="left_arm4_link"/>
		<child link="left_arm5_link"/>
		<axis xyz="0 0 -1"/>
		<limit effort="100" lower="-2.9670597283903604" upper="2.9670597283903604" velocity="1.75"/>
		<origin rpy="1.5707963267948966 0 -3.141592653589793" xyz="0 0.39 0"/>
	</joint>
	<joint name="left_arm6" type="revolute">
		<parent link="left_arm5_link"/>
		<child link="left_arm6_link"/>
		<axis xyz="0 0 -1"/>
		<limit effort="40" lower="-0.785398" upper="1.39626" velocity="2.25"/>
		<origin rpy="1.5707963267948966 1.5707963267948966 0" xyz="0 0 0"/>
	</joint>
	<joint name="left_arm7" type="revolute">
		<parent link="left_arm6_link"/>
		<child link="left_arm7_link"/>
		<axis xyz="0 0 -1"/>
		<limit effort="40" lower="-0.785398" upper="2.35619" velocity="2.25"/>
		<origin rpy="-1.5707963267948966 0 -3.141592653589793" xyz="0 0 0"/>
	</joint>
	<joint name="leftarm7_fixed" type="fixed">
		<parent link="left_arm7_link"/>
		<child link="leftarm7"/>
		<axis xyz="0 0 1"/>
		<origin rpy="3.141592653589793 0 1.5707963267948966" xyz="0 0 0"/>
	</joint>
	<joint name="left_arm_palm_fixed" type="fixed">
		<parent link="leftarm7"/>
		<child link="left_arm_palm_link"/>
		<axis xyz="0 0 1"/>
		<origin rpy="3.141592653589793 0 1.5707963267948966" xyz="0 0 0"/>
	</joint>
	<joint name="fixed_left_hand" type="fixed">
		<parent link="left_arm_palm_link"/>
		<child link="left_hand_base_link"/>
		<axis xyz="0 0 1"/>
		<origin rpy="-1.5707963267948966 0 -1.5707963267948966" xyz="0.1026 0 0"/>
	</joint>
	<joint name="left_1thumb1" type="revolute">
		<parent link="left_hand_base_link"/>
		<child link="left_1thumb_add"/>
		<axis xyz="1 0 0"/>
		<limit effort="3.5" lower="-0.5235987755982988" upper="0.5235987755982988" velocity="4.15"/>
		<origin rpy="0.11756489868620836 -0.5691514524717884 2.873775944948715" xyz="0.05033498062244876 -0.046195028989132546 0.10090469078507158"/>
	</joint>
	<joint name="left_1thumb2" type="revolute">
		<parent link="left_1thumb_add"/>
		<child link="left_1thumb_prox"/>
		<axis xyz="0 1 0"/>
		<limit effort="3.5" lower="-0.5235987755982988" upper="1.5707963267948966" velocity="4.15"/>
		<origin rpy="2.1244375792393457e-17 0 -3.840257275199336e-19" xyz="0 0 0"/>
	</joint>
	<joint name="left_1thumb3" type="revolute">
		<parent link="left_1thumb_prox"/>
		<child link="left_1thumb_middle"/>
		<axis xyz="0 1 0"/>
		<limit effort="1.75" lower="-0.5235987755982988" upper="1.5707963267948966" velocity="4.15"/>
		<origin rpy="6.3843140496453e-18 0 3.840257275199337e-19" xyz="-2.769701445433981e-06 -8.753794566587203e-07 0.07549897543385913"/>
	</joint>
	<joint name="left_1thumb4" type="revolute">
		<parent link="left_1thumb_middle"/>
		<child link="left_1thumb_distal"/>
		<axis xyz="0 1 0"/>
		<limit effort="1.75" lower="-0.5235987755982988" upper="1.5707963267948966" velocity="4.15"/>
		<origin rpy="2.124437579239346e-17 0 -3.840257275199336e-19" xyz="2.825969516351279e-08 -1.941029532304128e-06 0.03999918119451454"/>
		<mimic joint="left_1thumb3" multiplier="1" offset="0"/>
	</joint>
	<joint name="left_2index1" type="revolute">
		<parent link="left_hand_base_link"/>
		<child link="left_2index_add"/>
		<axis xyz="1 0 0"/>
		<limit effort="3.5" lower="-0.5235987755982988" upper="0.5235987755982988" velocity="4.15"/>
		<origin rpy="-0.08901053067170119 -0.21616361004050422 -0.12603411517028018" xyz="-0.04822095089723907 -0.023581950027742687 0.13884264700536036"/>
	</joint>
	<joint name="left_2index2" type="revolute">
		<parent link="left_2index_add"/>
		<child link="left_2index_prox"/>
		<axis xyz="0 1 0"/>
		<limit effort="3.5" lower="-0.5235987755982988" upper="1.5707963267948966" velocity="4.15"/>
		<origin rpy="0 0 0" xyz="0 0 0"/>
	</joint>
	<joint name="left_2index3" type="revolute">
		<parent link="left_2index_prox"/>
		<child link="left_2index_middle"/>
		<axis xyz="0 1 0"/>
		<limit effort="1.75" lower="-0.5235987755982988" upper="1.5707963267948966" velocity="4.15"/>
		<origin rpy="0 0 0" xyz="-2.74376920977204e-06 2.104298657137349e-06 0.07499294758871436"/>
	</joint>
	<joint name="left_2index4" type="revolute">
		<parent link="left_2index_middle"/>
		<child link="left_2index_distal"/>
		<axis xyz="0 1 0"/>
		<limit effort="1.75" lower="-0.5235987755982988" upper="1.5707963267948966" velocity="4.15"/>
		<origin rpy="0 0 0" xyz="4.990901720134389e-07 7.203348627598417e-06 0.040003106727636524"/>
		<mimic joint="left_2index3" multiplier="1" offset="0"/>
	</joint>
	<joint name="left_3middle1" type="revolute">
		<parent link="left_hand_base_link"/>
		<child link="left_3middle_add"/>
		<axis xyz="1 0 0"/>
		<limit effort="3.5" lower="-0.5235987755982988" upper="0.5235987755982988" velocity="4.15"/>
		<origin rpy="-0.08901053067170119 -0.21616361004050422 -0.12603411517028018" xyz="-0.046912475355711004 0.01625622951721701 0.13329804221324246"/>
	</joint>
	<joint name="left_3middle2" type="revolute">
		<parent link="left_3middle_add"/>
		<child link="left_3middle_prox"/>
		<axis xyz="0 1 0"/>
		<limit effort="3.5" lower="-0.5235987755982988" upper="1.5707963267948966" velocity="4.15"/>
		<origin rpy="0 0 0" xyz="0 0 0"/>
	</joint>
	<joint name="left_3middle3" type="revolute">
		<parent link="left_3middle_prox"/>
		<child link="left_3middle_middle"/>
		<axis xyz="0 1 0"/>
		<limit effort="1.75" lower="-0.5235987755982988" upper="1.5707963267948966" velocity="4.15"/>
		<origin rpy="0 0 0" xyz="-2.7437692097578293e-06 2.104298657142678e-06 0.07499294758871435"/>
	</joint>
	<joint name="left_3middle4" type="revolute">
		<parent link="left_3middle_middle"/>
		<child link="left_3middle_distal"/>
		<axis xyz="0 1 0"/>
		<limit effort="1.75" lower="-0.5235987755982988" upper="1.5707963267948966" velocity="4.15"/>
		<origin rpy="0 0 0" xyz="-1.159829617066066e-06 -2.644729653201061e-06 0.0400025935616705"/>
		<mimic joint="left_3middle3" multiplier="1" offset="0"/>
	</joint>
	<joint name="left_4ring1" type="revolute">
		<parent link="left_hand_base_link"/>
		<child link="left_4ring_add"/>
		<axis xyz="1 0 0"/>
		<limit effort="3.5" lower="-0.5235987755982988" upper="0.5235987755982988" velocity="4.15"/>
		<origin rpy="-0.039750687030621616 -0.16742168412219294 -0.23311275596711079" xyz="-0.03744445293322672 0.062331309897796894 0.12780100489024404"/>
	</joint>
	<joint name="left_4ring2" type="revolute">
		<parent link="left_4ring_add"/>
		<child link="left_4ring_prox"/>
		<axis xyz="0 1 0"/>
		<limit effort="3.5" lower="-0.5235987755982988" upper="1.5707963267948966" velocity="4.15"/>
		<origin rpy="0 0 0" xyz="0 0 0"/>
	</joint>
	<joint name="left_4ring3" type="revolute">
		<parent link="left_4ring_prox"/>
		<child link="left_4ring_middle"/>
		<axis xyz="0 1 0"/>
		<limit effort="1.75" lower="-0.5235987755982988" upper="1.5707963267948966" velocity="4.15"/>
		<origin rpy="0 0 0" xyz="-2.127009579012906e-06 -6.785803148403602e-07 0.07499859595362679"/>
	</joint>
	<joint name="left_4ring4" type="revolute">
		<parent link="left_4ring_middle"/>
		<child link="left_4ring_distal"/>
		<axis xyz="0 1 0"/>
		<limit effort="1.75" lower="-0.5235987755982988" upper="1.5707963267948966" velocity="4.15"/>
		<origin rpy="0 0 0" xyz="7.282319976098961e-06 6.307909274745783e-06 0.04000447983886423"/>
		<mimic joint="left_4ring3" multiplier="1" offset="0"/>
	</joint>
	<joint name="left_arm_fixed" type="fixed">
		<parent link="leftarm7"/>
		<child link="left_arm"/>
		<axis xyz="0 0 1"/>
		<origin rpy="-1.5707963267948966 0 3.141592653589793" xyz="0 0.1131 0"/>
	</joint>
	<joint name="fixed_torso_right" type="fixed">
		<parent link="torso4_link"/>
		<child link="right_base_link"/>
		<axis xyz="0 0 1"/>
		<origin rpy="3.141592653589793 -0.5235989774905888 0" xyz="0.035 0.088 0.0126628"/>
	</joint>
	<joint name="right_arm1" type="revolute">
		<parent link="right_base_link"/>
		<child link="right_arm1_link"/>
		<axis xyz="0 0 1"/>
		<limit effort="145" lower="-2.9670597283903604" upper="2.9670597283903604" velocity="1"/>
		<origin rpy="0 0 3.141592653589793" xyz="0 0 0.31"/>
	</joint>
	<joint name="right_arm2" type="revolute">
		<parent link="right_arm1_link"/>
		<child link="right_arm2_link"/>
		<axis xyz="0 0 1"/>
		<limit effort="145" lower="-2.0943951023931953" upper="2.0943951023931953" velocity="1"/>
		<origin rpy="1.5707963267948966 0 2.465190328815662e-32" xyz="0 0 0"/>
	</joint>
	<joint name="right_arm3" type="revolute">
		<parent link="right_arm2_link"/>
		<child link="right_arm3_link"/>
		<axis xyz="0 0 1"/>
		<limit effort="100" lower="-2.9670597283903604" upper="2.9670597283903604" velocity="1.75"/>
		<origin rpy="-1.5707963267948968 -1.5707963267948966 0" xyz="0 0.4 2.4492935982947065e-17"/>
	</joint>
	<joint name="right_arm4" type="revolute">
		<parent link="right_arm3_link"/>
		<child link="right_arm4_link"/>
		<axis xyz="0 0 1"/>
		<limit effort="100" lower="-2.0943951023931953" upper="2.0943951023931953" velocity="1.75"/>
		<origin rpy="1.5707963267948966 0 -2.465190328815662e-32" xyz="0 0 0"/>
	</joint>
	<joint name="right_arm5" type="revolute">
		<parent link="right_arm4_link"/>
		<child link="right_arm5_link"/>
		<axis xyz="0 0 1"/>
		<limit effort="100" lower="-2.9670597283903604" upper="2.9670597283903604" velocity="1.75"/>
		<origin rpy="1.5707963267948966 0 -3.141592653589793" xyz="0 0.39 4.776122516674679e-17"/>
	</joint>
	<joint name="right_arm6" type="revolute">
		<parent link="right_arm5_link"/>
		<child link="right_arm6_link"/>
		<axis xyz="0 0 1"/>
		<limit effort="40" lower="-0.785398" upper="1.39626" velocity="2.25"/>
		<origin rpy="1.5707963267948966 -1.5707963267948966 0" xyz="0 0 0"/>
	</joint>
	<joint name="right_arm7" type="revolute">
		<parent link="right_arm6_link"/>
		<child link="right_arm7_link"/>
		<axis xyz="0 0 1"/>
		<limit effort="40" lower="-0.785398" upper="2.35619" velocity="2.25"/>
		<origin rpy="1.5707963267948966 0 2.465190328815662e-32" xyz="0 0 0"/>
	</joint>
	<joint name="rightarm7_fixed" type="fixed">
		<parent link="right_arm7_link"/>
		<child link="rightarm7"/>
		<axis xyz="0 0 1"/>
		<origin rpy="0 0 -1.5707963267948966" xyz="0 0 0"/>
	</joint>
	<joint name="right_arm_palm_fixed" type="fixed">
		<parent link="rightarm7"/>
		<child link="right_arm_palm_link"/>
		<axis xyz="0 0 1"/>
		<origin rpy="0 0 1.5707963267948966" xyz="0 0 0"/>
	</joint>
	<joint name="fixed_right_hand" type="fixed">
		<parent link="right_arm_palm_link"/>
		<child link="right_hand_base_link"/>
		<axis xyz="0 0 1"/>
		<origin rpy="1.5707963267948966 0 1.5707963267948966" xyz="0.1011 0 0"/>
	</joint>
	<joint name="right_1thumb1" type="revolute">
		<parent link="right_hand_base_link"/>
		<child link="right_1thumb_add"/>
		<axis xyz="1 0 0"/>
		<limit effort="3.5" lower="-0.5235987755982988" upper="0.5235987755982988" velocity="4.15"/>
		<origin rpy="-0.11756462984176261 -0.569151446235467 -2.873776419599191" xyz="0.050334980621345456 0.04619502898752697 0.10090469078635703"/>
	</joint>
	<joint name="right_1thumb2" type="revolute">
		<parent link="right_1thumb_add"/>
		<child link="right_1thumb_prox"/>
		<axis xyz="0 1 0"/>
		<limit effort="3.5" lower="-0.5235987755982988" upper="1.5707963267948966" velocity="4.15"/>
		<origin rpy="7.37257477290143e-18 0 1.3010426069826055e-18" xyz="0 0 0"/>
	</joint>
	<joint name="right_1thumb3" type="revolute">
		<parent link="right_1thumb_prox"/>
		<child link="right_1thumb_middle"/>
		<axis xyz="0 1 0"/>
		<limit effort="1.75" lower="-0.5235987755982988" upper="1.5707963267948966" velocity="4.15"/>
		<origin rpy="2.0500964971138965e-17 0 -1.2861661317627465e-18" xyz="-2.77370882784922e-06 8.763642004367966e-07 0.07549897543370059"/>
	</joint>
	<joint name="right_1thumb4" type="revolute">
		<parent link="right_1thumb_middle"/>
		<child link="right_1thumb_distal"/>
		<axis xyz="0 1 0"/>
		<limit effort="1.75" lower="-0.5235987755982988" upper="1.5707963267948966" velocity="4.15"/>
		<origin rpy="2.78735397440404e-17 0 1.4876475219858982e-20" xyz="2.6136007800658944e-08 1.9415518400407452e-06 0.039999181194490675"/>
		<mimic joint="right_1thumb3" multiplier="1" offset="0"/>
	</joint>
	<joint name="right_2index1" type="revolute">
		<parent link="right_hand_base_link"/>
		<child link="right_2index_add"/>
		<axis xyz="1 0 0"/>
		<limit effort="3.5" lower="-0.5235987755982988" upper="0.5235987755982988" velocity="4.15"/>
		<origin rpy="0.0890105306884541 -0.21616361004954587 0.12603411515977514" xyz="-0.04822095089899155 0.023581950026222067 0.13884264700501"/>
	</joint>
	<joint name="right_2index2" type="revolute">
		<parent link="right_2index_add"/>
		<child link="right_2index_prox"/>
		<axis xyz="0 1 0"/>
		<limit effort="3.5" lower="-0.5235987755982988" upper="1.5707963267948966" velocity="4.15"/>
		<origin rpy="1.8015933064328514e-17 0 1.1788874373720433e-17" xyz="0 0 0"/>
	</joint>
	<joint name="right_2index3" type="revolute">
		<parent link="right_2index_prox"/>
		<child link="right_2index_middle"/>
		<axis xyz="0 1 0"/>
		<limit effort="1.75" lower="-0.5235987755982988" upper="1.5707963267948966" velocity="4.15"/>
		<origin rpy="9.708153694012547e-18 0 2.079856855441704e-18" xyz="-2.6549096624819413e-06 -6.452137256800938e-06 0.07549382790216286"/>
	</joint>
	<joint name="right_2index4" type="revolute">
		<parent link="right_2index_middle"/>
		<child link="right_2index_distal"/>
		<axis xyz="0 1 0"/>
		<limit effort="1.75" lower="-0.5235987755982988" upper="1.5707963267948966" velocity="4.15"/>
		<origin rpy="0 0 0" xyz="-1.1598298525541395e-06 2.644729846970506e-06 0.04000259356167047"/>
		<mimic joint="right_2index3" multiplier="1" offset="0"/>
	</joint>
	<joint name="right_3middle1" type="revolute">
		<parent link="right_hand_base_link"/>
		<child link="right_3middle_add"/>
		<axis xyz="1 0 0"/>
		<limit effort="3.5" lower="-0.5235987755982988" upper="0.5235987755982988" velocity="4.15"/>
		<origin rpy="0.08901053068845396 -0.21616361004954587 0.1260341151597752" xyz="-0.0469124753576215 -0.016256229518673292 0.13329804221239253"/>
	</joint>
	<joint name="right_3middle2" type="revolute">
		<parent link="right_3middle_add"/>
		<child link="right_3middle_prox"/>
		<axis xyz="0 1 0"/>
		<limit effort="3.5" lower="-0.5235987755982988" upper="1.5707963267948966" velocity="4.15"/>
		<origin rpy="2.9418591540227334e-18 0 2.289653856716339e-17" xyz="0 0 0"/>
	</joint>
	<joint name="right_3middle3" type="revolute">
		<parent link="right_3middle_prox"/>
		<child link="right_3middle_middle"/>
		<axis xyz="0 1 0"/>
		<limit effort="1.75" lower="-0.5235987755982988" upper="1.5707963267948966" velocity="4.15"/>
		<origin rpy="-1.2477413484117865e-17 0 -4.159713710883408e-18" xyz="-4.313829451575658e-06 3.395941023974558e-06 0.07549331473619675"/>
	</joint>
	<joint name="right_3middle4" type="revolute">
		<parent link="right_3middle_middle"/>
		<child link="right_3middle_distal"/>
		<axis xyz="0 1 0"/>
		<limit effort="1.75" lower="-0.5235987755982988" upper="1.5707963267948966" velocity="4.15"/>
		<origin rpy="-9.708153694012546e-18 0 -2.0798568554417027e-18" xyz="-1.1598298525399286e-06 2.644729846959848e-06 0.040002593561670435"/>
		<mimic joint="right_3middle3" multiplier="1" offset="0"/>
	</joint>
	<joint name="right_4ring1" type="revolute">
		<parent link="right_hand_base_link"/>
		<child link="right_4ring_add"/>
		<axis xyz="1 0 0"/>
		<limit effort="3.5" lower="-0.5235987755982988" upper="0.5235987755982988" velocity="4.15"/>
		<origin rpy="0.03975087157211012 -0.16742168836981652 0.23311316081366845" xyz="-0.03744445293533241 -0.06233130989923727 0.1278010048889246"/>
	</joint>
	<joint name="right_4ring2" type="revolute">
		<parent link="right_4ring_add"/>
		<child link="right_4ring_prox"/>
		<axis xyz="0 1 0"/>
		<limit effort="3.5" lower="-0.5235987755982988" upper="1.5707963267948966" velocity="4.15"/>
		<origin rpy="3.0575011821382455e-18 0 1.1218317891300019e-18" xyz="0 0 0"/>
	</joint>
	<joint name="right_4ring3" type="revolute">
		<parent link="right_4ring_prox"/>
		<child link="right_4ring_middle"/>
		<axis xyz="0 1 0"/>
		<limit effort="1.75" lower="-0.5235987755982988" upper="1.5707963267948966" velocity="4.15"/>
		<origin rpy="3.0575011821382455e-18 0 1.1218317891300019e-18" xyz="4.239479981109184e-06 -4.270954609417288e-06 0.07550221760839716"/>
	</joint>
	<joint name="right_4ring4" type="revolute">
		<parent link="right_4ring_middle"/>
		<child link="right_4ring_distal"/>
		<axis xyz="0 1 0"/>
		<limit effort="1.75" lower="-0.5235987755982988" upper="1.5707963267948966" velocity="4.15"/>
		<origin rpy="0 0 0" xyz="-9.464939957979368e-07 3.0124202248060783e-06 0.039997726060733416"/>
		<mimic joint="right_4ring3" multiplier="1" offset="0"/>
	</joint>
	<joint name="right_arm_fixed" type="fixed">
		<parent link="rightarm7"/>
		<child link="right_arm"/>
		<axis xyz="0 0 1"/>
		<origin rpy="-1.5707963267948966 0 3.141592653589793" xyz="0 0.1131 0"/>
	</joint>
	<joint name="fixed_torso_head" type="fixed">
		<parent link="torso4_link"/>
		<child link="head_base_link"/>
		<axis xyz="0 0 1"/>
		<origin rpy="-1.5707963267948966 1.5707963267948966 0" xyz="0.135686 0.0879997 0"/>
	</joint>
	<joint name="head1" type="revolute">
		<parent link="head_base_link"/>
		<child link="head1_link"/>
		<axis xyz="0 -1 0"/>
		<limit effort="25" lower="-0.785398" upper="0.785398" velocity="1"/>
		<origin rpy="0 0 0" xyz="1.8368364793028456e-18 -0.02999781619617545 4.843601286374622e-06"/>
	</joint>
	<joint name="head2_joint" type="revolute">
		<parent link="head1_link"/>
		<child link="head2_link"/>
		<axis xyz="0 0 -1"/>
		<limit effort="25" lower="-0.436332" upper="0.785398" velocity="1"/>
		<origin rpy="-6.306685021560677e-17 1.5707963057214722 0" xyz="4.2462890300213046e-18 -0.0693471625121257 -7.177522291691219e-06"/>
	</joint>
	<joint name="head2_fixed" type="fixed">
		<parent link="head2_link"/>
		<child link="head2"/>
		<axis xyz="0 0 1"/>
		<origin rpy="-1.5707963267948966 0 -3.141592653589793" xyz="0 0 0"/>
	</joint>
	<joint name="head_realsense_fixed" type="fixed">
		<parent link="head2_link"/>
		<child link="head_realsense"/>
		<axis xyz="0 0 1"/>
		<origin rpy="-0.2617961426783598 -1.5707963267948966 0" xyz="-0.128261 -0.232639 -0.0175"/>
	</joint>
</robot>
