<?xml version="1.0" ?>
<robot name="ur5e_ref_with_cubes" version="1.0">
  <link name="ur5e_ref_with_cubes"/>
  <joint name="ur5e_joint" type="fixed">
    <origin xyz="0.0 0.0 0.0" rpy="0.0 0.0 0.0"/>
    <parent link="ur5e_ref_with_cubes"/>
    <child link="ur5e"/>
  </joint>
  <link name="ur5e"/>
  <joint name="base_link_joint" type="fixed">
    <origin xyz="0.0 0.0 0.0" rpy="0.0 0.0 1.5707963705062866"/>
    <parent link="ur5e"/>
    <child link="base_link"/>
  </joint>
  <link name="base_link">
    <inertial>
      <origin xyz="0.0 0.0 0.0" rpy="0.0 0.0 0.0"/>
      <mass value="4.0"/>
      <inertia ixx="0.004433331545442343" ixy="0.0" ixz="0.0" iyy="0.004433331545442343" iyz="0.0" izz="0.007199999876320362"/>
    </inertial>
    <visual name="geom_0">
      <origin xyz="6.729613346578844e-07 -3.6582437701326853e-07 0.09357351809740067" rpy="-1.471882700920105 -1.5707855224609375 -2.9583795070648193"/>
      <geometry>
        <mesh filename="file://ur5e/meshes/obj/base_0.obj" scale="1.0 1.0 1.0"/>
      </geometry>
    </visual>
    <visual name="geom_1">
      <origin xyz="1.5050970603169844e-07 5.029438057135849e-07 0.031134091317653656" rpy="-1.398999571800232 -1.5707749128341675 -1.087612509727478"/>
      <geometry>
        <mesh filename="file://ur5e/meshes/obj/base_1.obj" scale="1.0 1.0 1.0"/>
      </geometry>
    </visual>
  </link>
  <joint name="shoulder_pan_joint" type="revolute">
    <origin xyz="0.0 0.0 0.16300000250339508" rpy="0.0 0.0 0.0"/>
    <axis xyz="0.0 0.0 1.0"/>
    <parent link="base_link"/>
    <child link="shoulder_link"/>
    <limit effort="1000.0" lower="-6.2831902503967285" upper="6.2831902503967285" velocity="1000.0"/>
  </joint>
  <link name="shoulder_link">
    <inertial>
      <origin xyz="0.0 0.0 0.0" rpy="0.0 0.0 0.0"/>
      <mass value="3.700000047683716"/>
      <inertia ixx="0.010267499834299088" ixy="0.0" ixz="0.0" iyy="0.010267499834299088" iyz="0.0" izz="0.006659999955445528"/>
    </inertial>
    <visual name="geom_2">
      <origin xyz="0.00015791990153957158 -0.008422926999628544 0.04825544357299805" rpy="2.9720499515533447 -1.2403403520584106 -1.5664480924606323"/>
      <geometry>
        <mesh filename="file://ur5e/meshes/obj/shoulder_0.obj" scale="1.0 1.0 1.0"/>
      </geometry>
    </visual>
    <visual name="geom_3">
      <origin xyz="1.022160290631291e-06 0.06888462603092194 -0.0005032847984693944" rpy="0.16997294127941132 -1.5622872524545528e-05 1.5708061456680298"/>
      <geometry>
        <mesh filename="file://ur5e/meshes/obj/shoulder_1.obj" scale="1.0 1.0 1.0"/>
      </geometry>
    </visual>
    <visual name="geom_4">
      <origin xyz="-4.987111606169492e-05 0.0005636150017380714 -0.018757717683911324" rpy="1.6252845525741577 0.7431999444961548 1.5734658241271973"/>
      <geometry>
        <mesh filename="file://ur5e/meshes/obj/shoulder_2.obj" scale="1.0 1.0 1.0"/>
      </geometry>
    </visual>
    <collision name="geom_5">
      <origin xyz="0.0 0.0 -0.03999999910593033" rpy="0.0 0.0 0.0"/>
      <geometry>
        <cylinder radius="0.05999999865889549" length="0.11999999731779099"/>
      </geometry>
    </collision>
  </link>
  <joint name="shoulder_lift_joint" type="revolute">
    <origin xyz="0.0 0.1379999965429306 0.0" rpy="-0.0 1.570796251296997 0.0"/>
    <axis xyz="0.0 1.0 0.0"/>
    <parent link="shoulder_link"/>
    <child link="upper_arm_link"/>
    <limit effort="1000.0" lower="-6.2831902503967285" upper="6.2831902503967285" velocity="1000.0"/>
  </joint>
  <link name="upper_arm_link">
    <inertial>
      <origin xyz="0.0 0.0 0.21250000596046448" rpy="0.0 0.0 0.0"/>
      <mass value="8.392999649047852"/>
      <inertia ixx="0.13388599455356598" ixy="0.0" ixz="0.0" iyy="0.13388599455356598" iyz="0.0" izz="0.01510739978402853"/>
    </inertial>
    <visual name="geom_6">
      <origin xyz="-3.57606450052117e-06 -0.00019999968935735524 0.2121351808309555" rpy="-0.000330544076859951 -1.484942572460568e-06 -0.35511940717697144"/>
      <geometry>
        <mesh filename="file://ur5e/meshes/obj/upperarm_0.obj" scale="1.0 1.0 1.0"/>
      </geometry>
    </visual>
    <visual name="geom_7">
      <origin xyz="-7.533427037742513e-07 -0.02455902472138405 0.2981274724006653" rpy="0.17716176807880402 7.970340811880305e-05 -0.0004820288741029799"/>
      <geometry>
        <mesh filename="file://ur5e/meshes/obj/upperarm_1.obj" scale="1.0 1.0 1.0"/>
      </geometry>
    </visual>
    <visual name="geom_8">
      <origin xyz="1.2475194125727285e-05 -0.020613765344023705 0.21354779601097107" rpy="-4.278980122762732e-05 -0.009396328590810299 1.572607159614563"/>
      <geometry>
        <mesh filename="file://ur5e/meshes/obj/upperarm_2.obj" scale="1.0 1.0 1.0"/>
      </geometry>
    </visual>
    <visual name="geom_9">
      <origin xyz="-1.6738860722398385e-05 0.04530972242355347 0.21224045753479004" rpy="-1.1170384823344648e-05 -0.0003347325837239623 1.571274757385254"/>
      <geometry>
        <mesh filename="file://ur5e/meshes/obj/upperarm_3.obj" scale="1.0 1.0 1.0"/>
      </geometry>
    </visual>
    <collision name="geom_10">
      <origin xyz="0.0 -0.03999999910593033 0.0" rpy="1.5707963705062866 0.0 0.0"/>
      <geometry>
        <cylinder radius="0.05999999865889549" length="0.11999999731779099"/>
      </geometry>
    </collision>
    <collision name="geom_11">
      <origin xyz="0.0 0.0 0.20000000298023224" rpy="0.0 0.0 0.0"/>
      <geometry>
        <cylinder radius="0.05000000074505806" length="0.4000000059604645"/>
      </geometry>
    </collision>
  </link>
  <joint name="elbow_joint" type="revolute">
    <origin xyz="0.0 -0.13099999725818634 0.42500001192092896" rpy="0.0 0.0 0.0"/>
    <axis xyz="0.0 1.0 0.0"/>
    <parent link="upper_arm_link"/>
    <child link="forearm_link"/>
    <limit effort="1000.0" lower="-3.1414999961853027" upper="3.1414999961853027" velocity="1000.0"/>
  </joint>
  <link name="forearm_link">
    <inertial>
      <origin xyz="0.0 0.0 0.19599999487400055" rpy="0.0 0.0 0.0"/>
      <mass value="2.2750000953674316"/>
      <inertia ixx="0.031179599463939667" ixy="0.0" ixz="0.0" iyy="0.031179599463939667" iyz="0.0" izz="0.004095000214874744"/>
    </inertial>
    <visual name="geom_12">
      <origin xyz="2.620744999148883e-05 -0.0398692786693573 0.39588937163352966" rpy="0.14899666607379913 0.31085216999053955 1.5710805654525757"/>
      <geometry>
        <mesh filename="file://ur5e/meshes/obj/forearm_0.obj" scale="1.0 1.0 1.0"/>
      </geometry>
    </visual>
    <visual name="geom_13">
      <origin xyz="-2.3636832338524982e-05 -0.000434091140050441 0.20434308052062988" rpy="0.0003357935056556016 -0.0005516118253581226 1.3332977294921875"/>
      <geometry>
        <mesh filename="file://ur5e/meshes/obj/forearm_1.obj" scale="1.0 1.0 1.0"/>
      </geometry>
    </visual>
    <visual name="geom_14">
      <origin xyz="-9.661516742198728e-06 0.016976509243249893 0.2550390362739563" rpy="-0.14630161225795746 0.0006538606830872595 0.004920260049402714"/>
      <geometry>
        <mesh filename="file://ur5e/meshes/obj/forearm_2.obj" scale="1.0 1.0 1.0"/>
      </geometry>
    </visual>
    <visual name="geom_15">
      <origin xyz="2.975203187816078e-06 0.011960668489336967 0.1636168211698532" rpy="2.978463817271404e-05 0.02032513916492462 1.5715676546096802"/>
      <geometry>
        <mesh filename="file://ur5e/meshes/obj/forearm_3.obj" scale="1.0 1.0 1.0"/>
      </geometry>
    </visual>
    <collision name="geom_16">
      <origin xyz="0.0 0.07999999821186066 0.0" rpy="1.5707963705062866 0.0 0.0"/>
      <geometry>
        <cylinder radius="0.054999999701976776" length="0.11999999731779099"/>
      </geometry>
    </collision>
    <collision name="geom_17">
      <origin xyz="0.0 0.0 0.20000000298023224" rpy="0.0 0.0 0.0"/>
      <geometry>
        <cylinder radius="0.03799999877810478" length="0.3799999952316284"/>
      </geometry>
    </collision>
  </link>
  <joint name="wrist_1_joint" type="revolute">
    <origin xyz="2.7755575615628914e-17 8.673617379884035e-19 0.3919999897480011" rpy="-0.0 1.570796251296997 0.0"/>
    <axis xyz="0.0 1.0 0.0"/>
    <parent link="forearm_link"/>
    <child link="wrist_1_link"/>
    <limit effort="1000.0" lower="-6.2831902503967285" upper="6.2831902503967285" velocity="1000.0"/>
  </joint>
  <link name="wrist_1_link">
    <inertial>
      <origin xyz="0.0 0.12700000405311584 0.0" rpy="0.0 0.0 0.0"/>
      <mass value="1.218999981880188"/>
      <inertia ixx="0.002559900050982833" ixy="0.0" ixz="0.0" iyy="0.002559900050982833" iyz="0.0" izz="0.0021941999439150095"/>
    </inertial>
    <visual name="geom_18">
      <origin xyz="-2.324781598872505e-05 0.1262851357460022 0.048975057899951935" rpy="-1.926666498184204 -1.570583701133728 -0.813883364200592"/>
      <geometry>
        <mesh filename="file://ur5e/meshes/obj/wrist1_0.obj" scale="1.0 1.0 1.0"/>
      </geometry>
    </visual>
    <visual name="geom_19">
      <origin xyz="-3.664461473817937e-05 0.13040179014205933 -0.03970348834991455" rpy="-3.0659677982330322 -1.261343002319336 -1.5694034099578857"/>
      <geometry>
        <mesh filename="file://ur5e/meshes/obj/wrist1_1.obj" scale="1.0 1.0 1.0"/>
      </geometry>
    </visual>
    <visual name="geom_20">
      <origin xyz="-2.099102403008146e-06 0.11289621889591217 0.012388333678245544" rpy="-3.1400976181030273 -1.0305078029632568 -1.5723310708999634"/>
      <geometry>
        <mesh filename="file://ur5e/meshes/obj/wrist1_2.obj" scale="1.0 1.0 1.0"/>
      </geometry>
    </visual>
    <collision name="geom_21">
      <origin xyz="0.0 0.05000000074505806 0.0" rpy="1.5707963705062866 0.0 0.0"/>
      <geometry>
        <cylinder radius="0.03999999910593033" length="0.14000000059604645"/>
      </geometry>
    </collision>
  </link>
  <joint name="wrist_2_joint" type="revolute">
    <origin xyz="0.0 0.12700000405311584 0.0" rpy="0.0 0.0 0.0"/>
    <axis xyz="0.0 0.0 1.0"/>
    <parent link="wrist_1_link"/>
    <child link="wrist_2_link"/>
    <limit effort="1000.0" lower="-6.2831902503967285" upper="6.2831902503967285" velocity="1000.0"/>
  </joint>
  <link name="wrist_2_link">
    <inertial>
      <origin xyz="0.0 0.0 0.10000000149011612" rpy="0.0 0.0 0.0"/>
      <mass value="1.218999981880188"/>
      <inertia ixx="0.002559900050982833" ixy="0.0" ixz="0.0" iyy="0.002559900050982833" iyz="0.0" izz="0.0021941999439150095"/>
    </inertial>
    <visual name="geom_22">
      <origin xyz="-3.8001244320184924e-06 0.04853645712137222 0.09943580627441406" rpy="0.17748303711414337 2.0002689780085348e-06 1.570776104927063"/>
      <geometry>
        <mesh filename="file://ur5e/meshes/obj/wrist2_0.obj" scale="1.0 1.0 1.0"/>
      </geometry>
    </visual>
    <visual name="geom_23">
      <origin xyz="3.1696421501692384e-05 -0.04020605608820915 0.1035911962389946" rpy="0.11116553843021393 0.3094663619995117 1.5711748600006104"/>
      <geometry>
        <mesh filename="file://ur5e/meshes/obj/wrist2_1.obj" scale="1.0 1.0 1.0"/>
      </geometry>
    </visual>
    <visual name="geom_24">
      <origin xyz="9.00023621852597e-07 0.01605665497481823 0.09663180261850357" rpy="-3.141105890274048 -0.8028358221054077 -1.5708829164505005"/>
      <geometry>
        <mesh filename="file://ur5e/meshes/obj/wrist2_2.obj" scale="1.0 1.0 1.0"/>
      </geometry>
    </visual>
    <collision name="geom_25">
      <origin xyz="0.0 0.0 0.03999999910593033" rpy="0.0 0.0 0.0"/>
      <geometry>
        <cylinder radius="0.03999999910593033" length="0.11999999731779099"/>
      </geometry>
    </collision>
    <collision name="geom_26">
      <origin xyz="0.0 0.019999999552965164 0.10000000149011612" rpy="1.5707963705062866 0.0 0.0"/>
      <geometry>
        <cylinder radius="0.03999999910593033" length="0.07999999821186066"/>
      </geometry>
    </collision>
  </link>
  <joint name="wrist_3_joint" type="revolute">
    <origin xyz="1.1102230246251565e-16 0.0 0.10000000149011612" rpy="0.0 0.0 0.0"/>
    <axis xyz="0.0 1.0 0.0"/>
    <parent link="wrist_2_link"/>
    <child link="wrist_3_link"/>
    <limit effort="1000.0" lower="-6.2831902503967285" upper="6.2831902503967285" velocity="1000.0"/>
  </joint>
  <link name="wrist_3_link">
    <inertial>
      <origin xyz="0.0 0.0771683007478714 0.0" rpy="0.0 0.0 1.5707963705062866"/>
      <mass value="0.18889999389648438"/>
      <inertia ixx="0.0001321339950663969" ixy="0.0" ixz="0.0" iyy="9.908629726851359e-05" iyz="0.0" izz="9.908629726851359e-05"/>
    </inertial>
    <visual name="geom_27">
      <origin xyz="1.3730400496569928e-05 0.07930911332368851 -0.0005378685309551656" rpy="0.22606076300144196 0.004863637965172529 1.5703150033950806"/>
      <geometry>
        <mesh filename="file://ur5e/meshes/obj/wrist3.obj" scale="1.0 1.0 1.0"/>
      </geometry>
    </visual>
    <collision name="geom_28">
      <origin xyz="0.0 0.07999999821186066 0.0" rpy="1.5707963705062866 0.0 0.0"/>
      <geometry>
        <cylinder radius="0.03999999910593033" length="0.03999999910593033"/>
      </geometry>
    </collision>
  </link>
  <joint name="gripper_2F_85_joint" type="fixed">
    <origin xyz="0.0 0.1 0.0" rpy="-1.5707963705062866 0.0 0.0"/>
    <parent link="wrist_3_link"/>
    <child link="gripper_2F_85"/>
  </joint>
  <link name="gripper_2F_85">
    <inertial>
      <origin xyz="0.0 0.10000000149011612 0.0" rpy="-1.5707963705062866 0.0 0.0"/>
      <mass value="0.0"/>
      <inertia ixx="0.0" ixy="0.0" ixz="0.0" iyy="0.0" iyz="0.0" izz="0.0"/>
    </inertial>
  </link>
  <joint name="base_mount_joint" type="fixed">
    <origin xyz="0.0 0.0 0.007" rpy="0.0 0.0 0.0"/>
    <parent link="gripper_2F_85"/>
    <child link="base_mount"/>
  </joint>
  <link name="base_mount">
    <inertial>
      <origin xyz="-0.0003605835954658687 8.536274981452152e-05 -5.91993702983018e-05" rpy="0.010714340023696423 -1.5679504871368408 3.132357358932495"/>
      <mass value="0.1500028520822525"/>
      <inertia ixx="0.00010234548972221091" ixy="0.0" ixz="0.0" iyy="5.359968781704083e-05" iyz="0.0" izz="5.21717629453633e-05"/>
    </inertial>
    <visual name="gripper_2F_85_geom_0">
      <origin xyz="-0.0003605835954658687 8.536274981452152e-05 -5.91993702983018e-05" rpy="0.010714522562921047 -1.5679504871368408 3.132357120513916"/>
      <geometry>
        <mesh filename="file://ur5e/meshes/obj/base_mount.obj" scale="1.0 1.0 1.0"/>
      </geometry>
    </visual>
    <collision name="gripper_2F_85_geom_1">
      <origin xyz="-0.0003605835954658687 8.536274981452152e-05 -5.91993702983018e-05" rpy="0.010714522562921047 -1.5679504871368408 3.132357120513916"/>
      <geometry>
        <mesh filename="file://ur5e/meshes/stl/base_mount.stl" scale="1.0 1.0 1.0"/>
      </geometry>
    </collision>
  </link>
  <joint name="base_joint" type="fixed">
    <origin xyz="0.0 0.0 0.0038" rpy="0.0 0.0 -1.5707963705062866"/>
    <parent link="base_mount"/>
    <child link="base"/>
  </joint>
  <link name="base">
    <inertial>
      <origin xyz="0.0 -2.7039399355999194e-05 0.03546750172972679" rpy="-0.003056977642700076 0.0 0.0"/>
      <mass value="0.7774410247802734"/>
      <inertia ixx="0.00026028501451946795" ixy="0.0" ixz="0.0" iyy="0.00022538099437952042" iyz="0.0" izz="0.00015270800213329494"/>
    </inertial>
    <visual name="gripper_2F_85_geom_2">
      <origin xyz="9.197026429319521e-08 -2.703939208004158e-05 0.0354674831032753" rpy="-0.003056990448385477 7.76175497207987e-08 2.5390105292899534e-05"/>
      <geometry>
        <mesh filename="file://ur5e/meshes/obj/base.obj" scale="1.0 1.0 1.0"/>
      </geometry>
    </visual>
    <collision name="gripper_2F_85_geom_3">
      <origin xyz="9.197026429319521e-08 -2.703939208004158e-05 0.0354674831032753" rpy="-0.003056990448385477 7.76175497207987e-08 2.5390105292899534e-05"/>
      <geometry>
        <mesh filename="file://ur5e/meshes/stl/base.stl" scale="1.0 1.0 1.0"/>
      </geometry>
    </collision>
  </link>
  <joint name="right_driver_joint" type="revolute">
    <origin xyz="0.0 0.030601099133491516 0.05490399897098541" rpy="0.0 0.0 0.0"/>
    <axis xyz="1.0 0.0 0.0"/>
    <parent link="base"/>
    <child link="right_driver"/>
    <limit effort="1000.0" lower="0.0" upper="0.800000011920929" velocity="1000.0"/>
  </joint>
  <link name="right_driver">
    <inertial>
      <origin xyz="2.9693099107969134e-12 0.017754700034856796 0.0010731399524956942" rpy="1.6425151824951172 0.0 0.0"/>
      <mass value="0.008995629847049713"/>
      <inertia ixx="1.7235199720744276e-06" ixy="0.0" ixz="0.0" iyy="1.609059950169467e-06" iyz="0.0" izz="3.220060023068072e-07"/>
    </inertial>
    <visual name="gripper_2F_85_geom_4">
      <origin xyz="2.9693094771160444e-12 0.0177546925842762 0.0010731416987255216" rpy="1.6425158977508545 0.0 0.0"/>
      <geometry>
        <mesh filename="file://ur5e/meshes/obj/driver.obj" scale="1.0 1.0 1.0"/>
      </geometry>
    </visual>
    <collision name="gripper_2F_85_geom_5">
      <origin xyz="2.9693094771160444e-12 0.0177546925842762 0.0010731416987255216" rpy="1.6425158977508545 0.0 0.0"/>
      <geometry>
        <mesh filename="file://ur5e/meshes/stl/driver.stl" scale="1.0 1.0 1.0"/>
      </geometry>
    </collision>
  </link>
  <joint name="right_coupler_joint" type="revolute">
    <origin xyz="-1.3877787807814457e-17 0.03150000050663948 -0.004100000020116568" rpy="0.0 0.0 0.0"/>
    <axis xyz="1.0 0.0 0.0"/>
    <parent link="right_driver"/>
    <child link="right_coupler"/>
    <limit effort="1000.0" lower="-1.5700000524520874" upper="0.0" velocity="1000.0"/>
  </joint>
  <link name="right_coupler">
    <inertial>
      <origin xyz="0.0 0.003012089990079403 0.023217499256134033" rpy="0.0 0.12903854250907898 1.5707963705062866"/>
      <mass value="0.01409740000963211"/>
      <inertia ixx="4.162060122325784e-06" ixy="0.0" ixz="0.0" iyy="3.5221598864154657e-06" iyz="0.0" izz="8.881310122887953e-07"/>
    </inertial>
    <visual name="gripper_2F_85_geom_6">
      <origin xyz="8.458042209322225e-13 0.00301208533346653 0.023217538371682167" rpy="1.399413406969249e-17 0.1290387511253357 1.5707963705062866"/>
      <geometry>
        <mesh filename="file://ur5e/meshes/obj/coupler.obj" scale="1.0 1.0 1.0"/>
      </geometry>
    </visual>
    <collision name="gripper_2F_85_geom_7">
      <origin xyz="8.458042209322225e-13 0.00301208533346653 0.023217538371682167" rpy="1.399413406969249e-17 0.1290387511253357 1.5707963705062866"/>
      <geometry>
        <mesh filename="file://ur5e/meshes/stl/coupler.stl" scale="1.0 1.0 1.0"/>
      </geometry>
    </collision>
  </link>
  <joint name="right_spring_link_joint" type="revolute">
    <origin xyz="0.0 0.013199999928474426 0.0608999989926815" rpy="0.0 0.0 0.0"/>
    <axis xyz="1.0 0.0 0.0"/>
    <parent link="base"/>
    <child link="right_spring_link"/>
    <limit effort="1000.0" lower="-0.296705961227417" upper="0.800000011920929" velocity="1000.0"/>
  </joint>
  <link name="right_spring_link">
    <inertial>
      <origin xyz="-8.650049565517293e-09 0.018162399530410767 0.021265799179673195" rpy="0.0 0.7068443298339844 1.5707963705062866"/>
      <mass value="0.022164199501276016"/>
      <inertia ixx="8.96852998266695e-06" ixy="0.0" ixz="0.0" iyy="6.717330052197212e-06" iyz="0.0" izz="2.6393099687993526e-06"/>
    </inertial>
    <visual name="gripper_2F_85_geom_8">
      <origin xyz="-8.650050453695712e-09 0.018162399530410767 0.02126581035554409" rpy="0.0 0.7068434953689575 1.5707963705062866"/>
      <geometry>
        <mesh filename="file://ur5e/meshes/obj/spring_link.obj" scale="1.0 1.0 1.0"/>
      </geometry>
    </visual>
    <collision name="gripper_2F_85_geom_9">
      <origin xyz="-8.650050453695712e-09 0.018162399530410767 0.02126581035554409" rpy="0.0 0.7068434953689575 1.5707963705062866"/>
      <geometry>
        <mesh filename="file://ur5e/meshes/stl/spring_link.stl" scale="1.0 1.0 1.0"/>
      </geometry>
    </collision>
  </link>
  <joint name="right_follower_joint" type="revolute">
    <origin xyz="0.0 0.03700000047683716 0.04399999976158142" rpy="0.0 0.0 0.0"/>
    <axis xyz="1.0 0.0 0.0"/>
    <parent link="right_spring_link"/>
    <child link="right_follower"/>
    <limit effort="1000.0" lower="-0.8726640343666077" upper="0.8726640343666077" velocity="1000.0"/>
  </joint>
  <link name="right_follower">
    <inertial>
      <origin xyz="0.0 -0.02904600091278553 0.018978599458932877" rpy="0.32977840304374695 0.0 0.0"/>
      <mass value="0.012522200122475624"/>
      <inertia ixx="2.674149982340168e-06" ixy="0.0" ixz="0.0" iyy="2.4558999029977713e-06" iyz="0.0" izz="6.02030979734991e-07"/>
    </inertial>
    <visual name="gripper_2F_85_geom_10">
      <origin xyz="-8.221781655493032e-08 0.006954035256057978 0.0059786406345665455" rpy="0.33435606956481934 1.157242695626337e-05 4.020253072667401e-06"/>
      <geometry>
        <mesh filename="file://ur5e/meshes/obj/follower.obj" scale="1.0 1.0 1.0"/>
      </geometry>
    </visual>
    <collision name="gripper_2F_85_geom_11">
      <origin xyz="-8.221781655493032e-08 0.006954035256057978 0.0059786406345665455" rpy="0.33435606956481934 1.157242695626337e-05 4.020253072667401e-06"/>
      <geometry>
        <mesh filename="file://ur5e/meshes/stl/follower.stl" scale="1.0 1.0 1.0"/>
      </geometry>
    </collision>
  </link>
  <joint name="right_pad_joint" type="fixed">
    <origin xyz="0.0 -0.0009 0.00702" rpy="0.0 0.0 0.0"/>
    <parent link="right_follower"/>
    <child link="right_pad"/>
  </joint>
  <link name="right_pad">
    <inertial>
      <origin xyz="0.0 -0.0024999999441206455 0.01850000023841858" rpy="0.0 0.0 1.5707963705062866"/>
      <mass value="0.0035000001080334187"/>
      <inertia ixx="4.7395801061611564e-07" ixy="0.0" ixz="0.0" iyy="3.645830020104768e-07" iyz="0.0" izz="1.2395800297326787e-07"/>
    </inertial>
    <collision name="gripper_2F_85_right_pad1">
      <origin xyz="0.0 -0.0026000000070780516 0.02812499925494194" rpy="0.0 0.0 0.0"/>
      <geometry>
        <box size="0.02199999988079071 0.00800000037997961 0.01875000074505806"/>
      </geometry>
    </collision>
    <collision name="gripper_2F_85_right_pad2">
      <origin xyz="0.0 -0.0026000000070780516 0.00937500037252903" rpy="0.0 0.0 0.0"/>
      <geometry>
        <box size="0.02199999988079071 0.00800000037997961 0.01875000074505806"/>
      </geometry>
    </collision>
    <visual name="gripper_2F_85_geom_14">
      <origin xyz="1.9278732459721525e-14 -0.0024999999441206455 0.018517374992370605" rpy="0.0 0.0 1.5707963705062866"/>
      <geometry>
        <mesh filename="file://ur5e/meshes/stl/pad.stl" scale="1.0 1.0 1.0"/>
      </geometry>
    </visual>
  </link>
  <joint name="right_silicone_pad_joint" type="fixed">
    <origin xyz="0.0 0.0 0.0" rpy="0.0 0.0 0.0"/>
    <parent link="right_pad"/>
    <child link="right_silicone_pad"/>
  </joint>
  <link name="right_silicone_pad">
    <inertial>
      <origin xyz="1.9279010286528224e-14 -0.005799999926239252 0.018517374992370605" rpy="0.0 0.0 1.5707963705062866"/>
      <mass value="0.0013028120156377554"/>
      <inertia ixx="2.0080436513580935e-07" ixy="0.0" ixz="0.0" iyy="1.4953603511003166e-07" iyz="0.0" izz="5.182418760796281e-08"/>
    </inertial>
    <visual name="gripper_2F_85_geom_15">
      <origin xyz="1.9279010286528224e-14 -0.005799999926239252 0.018517374992370605" rpy="0.0 0.0 1.5707963705062866"/>
      <geometry>
        <mesh filename="file://ur5e/meshes/obj/silicone_pad.obj" scale="1.0 1.0 1.0"/>
      </geometry>
    </visual>
  </link>
  <joint name="left_driver_joint" type="revolute">
    <origin xyz="0.0 -0.030601099133491516 0.05490399897098541" rpy="0.0 0.0 3.1415927410125732"/>
    <axis xyz="1.0 0.0 0.0"/>
    <parent link="base"/>
    <child link="left_driver"/>
    <limit effort="1000.0" lower="0.0" upper="0.800000011920929" velocity="1000.0"/>
  </joint>
  <link name="left_driver">
    <inertial>
      <origin xyz="0.0 0.017754700034856796 0.0010731399524956942" rpy="1.6425151824951172 0.0 0.0"/>
      <mass value="0.008995629847049713"/>
      <inertia ixx="1.7235199720744276e-06" ixy="0.0" ixz="0.0" iyy="1.609059950169467e-06" iyz="0.0" izz="3.220060023068072e-07"/>
    </inertial>
    <visual name="gripper_2F_85_geom_16">
      <origin xyz="2.9693094771160444e-12 0.0177546925842762 0.0010731416987255216" rpy="1.6425158977508545 0.0 0.0"/>
      <geometry>
        <mesh filename="file://ur5e/meshes/obj/driver.obj" scale="1.0 1.0 1.0"/>
      </geometry>
    </visual>
    <collision name="gripper_2F_85_geom_17">
      <origin xyz="2.9693094771160444e-12 0.0177546925842762 0.0010731416987255216" rpy="1.6425158977508545 0.0 0.0"/>
      <geometry>
        <mesh filename="file://ur5e/meshes/stl/driver.stl" scale="1.0 1.0 1.0"/>
      </geometry>
    </collision>
  </link>
  <joint name="left_coupler_joint" type="revolute">
    <origin xyz="1.3877787807814457e-17 0.03150000050663948 -0.004100000020116568" rpy="0.0 0.0 0.0"/>
    <axis xyz="1.0 0.0 0.0"/>
    <parent link="left_driver"/>
    <child link="left_coupler"/>
    <limit effort="1000.0" lower="-1.5700000524520874" upper="0.0" velocity="1000.0"/>
  </joint>
  <link name="left_coupler">
    <inertial>
      <origin xyz="0.0 0.003012089990079403 0.023217499256134033" rpy="0.0 0.12903854250907898 1.5707963705062866"/>
      <mass value="0.01409740000963211"/>
      <inertia ixx="4.162060122325784e-06" ixy="0.0" ixz="0.0" iyy="3.5221598864154657e-06" iyz="0.0" izz="8.881310122887953e-07"/>
    </inertial>
    <visual name="gripper_2F_85_geom_18">
      <origin xyz="8.458042209322225e-13 0.00301208533346653 0.023217538371682167" rpy="1.399413406969249e-17 0.1290387511253357 1.5707963705062866"/>
      <geometry>
        <mesh filename="file://ur5e/meshes/obj/coupler.obj" scale="1.0 1.0 1.0"/>
      </geometry>
    </visual>
    <collision name="gripper_2F_85_geom_19">
      <origin xyz="8.458042209322225e-13 0.00301208533346653 0.023217538371682167" rpy="1.399413406969249e-17 0.1290387511253357 1.5707963705062866"/>
      <geometry>
        <mesh filename="file://ur5e/meshes/stl/coupler.stl" scale="1.0 1.0 1.0"/>
      </geometry>
    </collision>
  </link>
  <joint name="left_spring_link_joint" type="revolute">
    <origin xyz="0.0 -0.013199999928474426 0.0608999989926815" rpy="0.0 0.0 3.1415927410125732"/>
    <axis xyz="1.0 0.0 0.0"/>
    <parent link="base"/>
    <child link="left_spring_link"/>
    <limit effort="1000.0" lower="-0.296705961227417" upper="0.800000011920929" velocity="1000.0"/>
  </joint>
  <link name="left_spring_link">
    <inertial>
      <origin xyz="-8.650049565517293e-09 0.018162399530410767 0.021265799179673195" rpy="0.0 0.7068443298339844 1.5707963705062866"/>
      <mass value="0.022164199501276016"/>
      <inertia ixx="8.96852998266695e-06" ixy="0.0" ixz="0.0" iyy="6.717330052197212e-06" iyz="0.0" izz="2.6393099687993526e-06"/>
    </inertial>
    <visual name="gripper_2F_85_geom_20">
      <origin xyz="-8.650050453695712e-09 0.018162399530410767 0.02126581035554409" rpy="0.0 0.7068434953689575 1.5707963705062866"/>
      <geometry>
        <mesh filename="file://ur5e/meshes/obj/spring_link.obj" scale="1.0 1.0 1.0"/>
      </geometry>
    </visual>
    <collision name="gripper_2F_85_geom_21">
      <origin xyz="-8.650050453695712e-09 0.018162399530410767 0.02126581035554409" rpy="0.0 0.7068434953689575 1.5707963705062866"/>
      <geometry>
        <mesh filename="file://ur5e/meshes/stl/spring_link.stl" scale="1.0 1.0 1.0"/>
      </geometry>
    </collision>
  </link>
  <joint name="left_follower_joint" type="revolute">
    <origin xyz="0.0 0.03700000047683716 0.04399999976158142" rpy="0.0 0.0 0.0"/>
    <axis xyz="1.0 0.0 0.0"/>
    <parent link="left_spring_link"/>
    <child link="left_follower"/>
    <limit effort="1000.0" lower="-0.8726640343666077" upper="0.8726640343666077" velocity="1000.0"/>
  </joint>
  <link name="left_follower">
    <inertial>
      <origin xyz="0.0 -0.02904600091278553 0.018978599458932877" rpy="0.32977840304374695 0.0 0.0"/>
      <mass value="0.012522200122475624"/>
      <inertia ixx="2.674149982340168e-06" ixy="0.0" ixz="0.0" iyy="2.4558999029977713e-06" iyz="0.0" izz="6.02030979734991e-07"/>
    </inertial>
    <visual name="gripper_2F_85_geom_22">
      <origin xyz="-8.221781655493032e-08 0.006954035256057978 0.0059786406345665455" rpy="0.33435606956481934 1.157242695626337e-05 4.020253072667401e-06"/>
      <geometry>
        <mesh filename="file://ur5e/meshes/obj/follower.obj" scale="1.0 1.0 1.0"/>
      </geometry>
    </visual>
    <collision name="gripper_2F_85_geom_23">
      <origin xyz="-8.221781655493032e-08 0.006954035256057978 0.0059786406345665455" rpy="0.33435606956481934 1.157242695626337e-05 4.020253072667401e-06"/>
      <geometry>
        <mesh filename="file://ur5e/meshes/stl/follower.stl" scale="1.0 1.0 1.0"/>
      </geometry>
    </collision>
  </link>
  <joint name="left_pad_joint" type="fixed">
    <origin xyz="0.0 -0.0009 0.00702" rpy="0.0 0.0 0.0"/>
    <parent link="left_follower"/>
    <child link="left_pad"/>
  </joint>
  <link name="left_pad">
    <inertial>
      <origin xyz="0.0 -0.0024999999441206455 0.01850000023841858" rpy="0.0 0.0 1.5707963705062866"/>
      <mass value="0.0035000001080334187"/>
      <inertia ixx="4.7395801061611564e-07" ixy="0.0" ixz="0.0" iyy="3.645830020104768e-07" iyz="0.0" izz="1.2395800297326787e-07"/>
    </inertial>
    <collision name="gripper_2F_85_left_pad1">
      <origin xyz="0.0 -0.0026000000070780516 0.02812499925494194" rpy="0.0 0.0 0.0"/>
      <geometry>
        <box size="0.02199999988079071 0.00800000037997961 0.01875000074505806"/>
      </geometry>
    </collision>
    <collision name="gripper_2F_85_left_pad2">
      <origin xyz="0.0 -0.0026000000070780516 0.00937500037252903" rpy="0.0 0.0 0.0"/>
      <geometry>
        <box size="0.02199999988079071 0.00800000037997961 0.01875000074505806"/>
      </geometry>
    </collision>
    <visual name="gripper_2F_85_geom_26">
      <origin xyz="1.9278732459721525e-14 -0.0024999999441206455 0.018517374992370605" rpy="0.0 0.0 1.5707963705062866"/>
      <geometry>
        <mesh filename="file://ur5e/meshes/stl/pad.stl" scale="1.0 1.0 1.0"/>
      </geometry>
    </visual>
  </link>
  <joint name="left_silicone_pad_joint" type="fixed">
    <origin xyz="0.0 0.0 0.0" rpy="0.0 0.0 0.0"/>
    <parent link="left_pad"/>
    <child link="left_silicone_pad"/>
  </joint>
  <link name="left_silicone_pad">
    <inertial>
      <origin xyz="1.9279010286528224e-14 -0.005799999926239252 0.018517374992370605" rpy="0.0 0.0 1.5707963705062866"/>
      <mass value="0.0013028120156377554"/>
      <inertia ixx="2.0080436513580935e-07" ixy="0.0" ixz="0.0" iyy="1.4953603511003166e-07" iyz="0.0" izz="5.182418760796281e-08"/>
    </inertial>
    <visual name="gripper_2F_85_geom_27">
      <origin xyz="1.9279010286528224e-14 -0.005799999926239252 0.018517374992370605" rpy="0.0 0.0 1.5707963705062866"/>
      <geometry>
        <mesh filename="file://ur5e/meshes/obj/silicone_pad.obj" scale="1.0 1.0 1.0"/>
      </geometry>
    </visual>
  </link>
</robot>