<?xml version="1.0" ?>
<robot name="ur5e" version="1.0">
  <link name="base_link"/>
  <joint name="base_link-base_link_inertia" type="fixed">
    <origin xyz="0.0 0.0 0.0" rpy="0.0 0.0 3.141592653589793"/>
    <parent link="base_link"/>
    <child link="base_link_inertia"/>
  </joint>
  <link name="base_link_inertia">
    <inertial>
      <origin xyz="0.0 0.0 0.0" rpy="0.0 0.0 0.0"/>
      <mass value="4.0"/>
      <inertia ixx="0.00443333156" ixy="0.0" ixz="0.0" iyy="0.00443333156" iyz="0.0" izz="0.0072"/>
    </inertial>
    <visual>
      <origin xyz="0.0 0.0 0.0" rpy="0.0 0.0 3.141592653589793"/>
      <geometry>
        <mesh filename="package://multiverse_parser/examples/output/ur5e/urdf/ur5e/obj/base.obj"/>
      </geometry>
      <material name="LightGrey">
        <color rgba="0.7 0.7 0.7 1.0"/>
      </material>
    </visual>
    <collision>
      <origin xyz="0.0 0.0 0.0" rpy="0.0 0.0 3.141592653589793"/>
      <geometry>
        <mesh filename="package://multiverse_parser/examples/output/ur5e/urdf/ur5e/stl/base.stl"/>
      </geometry>
    </collision>
  </link>
  <joint name="shoulder_pan_joint" type="revolute">
    <origin xyz="0.0 0.0 0.1625" rpy="0.0 0.0 0.0"/>
    <axis xyz="0.0 0.0 1.0"/>
    <parent link="base_link_inertia"/>
    <child link="shoulder_link"/>
    <limit effort="150.0" lower="0.0" upper="3.141592653589793" velocity="3.141592653589793"/>
    <dynamics damping="0.0" friction="0.0"/>
  </joint>
  <link name="shoulder_link">
    <inertial>
      <origin xyz="0.0 0.0 0.0" rpy="0.0 0.0 0.0"/>
      <mass value="3.7"/>
      <inertia ixx="0.010267495893" ixy="0.0" ixz="0.0" iyy="0.010267495893" iyz="0.0" izz="0.00666"/>
    </inertial>
    <visual>
      <origin xyz="0.0 0.0 0.0" rpy="0.0 0.0 3.141592653589793"/>
      <geometry>
        <mesh filename="package://multiverse_parser/examples/output/ur5e/urdf/ur5e/obj/shoulder.obj"/>
      </geometry>
      <material name="LightGrey">
        <color rgba="0.7 0.7 0.7 1.0"/>
      </material>
    </visual>
    <collision>
      <origin xyz="0.0 0.0 0.0" rpy="0.0 0.0 3.141592653589793"/>
      <geometry>
        <mesh filename="package://multiverse_parser/examples/output/ur5e/urdf/ur5e/stl/shoulder.stl"/>
      </geometry>
    </collision>
  </link>
  <joint name="shoulder_lift_joint" type="revolute">
    <origin xyz="0.0 0.0 0.0" rpy="1.570796327 0.0 0.0"/>
    <axis xyz="0.0 0.0 1.0"/>
    <parent link="shoulder_link"/>
    <child link="upper_arm_link"/>
    <limit effort="150.0" lower="-3.141592653589793" upper="0.0" velocity="3.141592653589793"/>
    <dynamics damping="0.0" friction="0.0"/>
  </joint>
  <link name="upper_arm_link">
    <inertial>
      <origin xyz="-0.2125 0.0 0.138" rpy="0.0 1.5707963267948966 0.0"/>
      <mass value="8.393"/>
      <inertia ixx="0.1338857818623325" ixy="0.0" ixz="0.0" iyy="0.1338857818623325" iyz="0.0" izz="0.0151074"/>
    </inertial>
    <visual>
      <origin xyz="0.0 0.0 0.138" rpy="1.5707963267948966 0.0 -1.5707963267948966"/>
      <geometry>
        <mesh filename="package://multiverse_parser/examples/output/ur5e/urdf/ur5e/obj/upperarm.obj"/>
      </geometry>
      <material name="LightGrey">
        <color rgba="0.7 0.7 0.7 1.0"/>
      </material>
    </visual>
    <collision>
      <origin xyz="0.0 0.0 0.138" rpy="1.5707963267948966 0.0 -1.5707963267948966"/>
      <geometry>
        <mesh filename="package://multiverse_parser/examples/output/ur5e/urdf/ur5e/stl/upperarm.stl"/>
      </geometry>
    </collision>
  </link>
  <joint name="elbow_joint" type="revolute">
    <origin xyz="-0.425 0.0 0.0" rpy="0.0 0.0 0.0"/>
    <axis xyz="0.0 0.0 1.0"/>
    <parent link="upper_arm_link"/>
    <child link="forearm_link"/>
    <limit effort="150.0" lower="0.0" upper="2.792526803190927" velocity="3.141592653589793"/>
    <dynamics damping="0.0" friction="0.0"/>
  </joint>
  <link name="forearm_link">
    <inertial>
      <origin xyz="-0.1961 0.0 0.007" rpy="0.0 1.5707963267948966 0.0"/>
      <mass value="2.275"/>
      <inertia ixx="0.031209355099586295" ixy="0.0" ixz="0.0" iyy="0.031209355099586295" iyz="0.0" izz="0.004095"/>
    </inertial>
    <visual>
      <origin xyz="0.0 0.0 0.007" rpy="1.5707963267948966 0.0 -1.5707963267948966"/>
      <geometry>
        <mesh filename="package://multiverse_parser/examples/output/ur5e/urdf/ur5e/obj/forearm.obj"/>
      </geometry>
      <material name="LightGrey">
        <color rgba="0.7 0.7 0.7 1.0"/>
      </material>
    </visual>
    <collision>
      <origin xyz="0.0 0.0 0.007" rpy="1.5707963267948966 0.0 -1.5707963267948966"/>
      <geometry>
        <mesh filename="package://multiverse_parser/examples/output/ur5e/urdf/ur5e/stl/forearm.stl"/>
      </geometry>
    </collision>
  </link>
  <joint name="wrist_1_joint" type="revolute">
    <origin xyz="-0.3922 0.0 0.1333" rpy="0.0 0.0 0.0"/>
    <axis xyz="0.0 0.0 1.0"/>
    <parent link="forearm_link"/>
    <child link="wrist_1_link"/>
    <limit effort="28.0" lower="-3.141592653589793" upper="1.3962634015954636" velocity="3.141592653589793"/>
    <dynamics damping="0.0" friction="0.0"/>
  </joint>
  <link name="wrist_1_link">
    <inertial>
      <origin xyz="0.0 0.0 0.0" rpy="0.0 0.0 0.0"/>
      <mass value="1.219"/>
      <inertia ixx="0.0025598989760400002" ixy="0.0" ixz="0.0" iyy="0.0025598989760400002" iyz="0.0" izz="0.0021942"/>
    </inertial>
    <visual>
      <origin xyz="0.0 0.0 -0.127" rpy="1.5707963267948966 0.0 0.0"/>
      <geometry>
        <mesh filename="package://multiverse_parser/examples/output/ur5e/urdf/ur5e/obj/wrist1.obj"/>
      </geometry>
      <material name="LightGrey">
        <color rgba="0.7 0.7 0.7 1.0"/>
      </material>
    </visual>
    <collision>
      <origin xyz="0.0 0.0 -0.127" rpy="1.5707963267948966 0.0 0.0"/>
      <geometry>
        <mesh filename="package://multiverse_parser/examples/output/ur5e/urdf/ur5e/stl/wrist1.stl"/>
      </geometry>
    </collision>
  </link>
  <joint name="wrist_2_joint" type="revolute">
    <origin xyz="0.0 -0.0997 -2.044881182297852e-11" rpy="1.570796327 0.0 0.0"/>
    <axis xyz="0.0 0.0 1.0"/>
    <parent link="wrist_1_link"/>
    <child link="wrist_2_link"/>
    <limit effort="28.0" lower="-0.17453292519943295" upper="6.283185307179586" velocity="3.141592653589793"/>
    <dynamics damping="0.0" friction="0.0"/>
  </joint>
  <link name="wrist_2_link">
    <inertial>
      <origin xyz="0.0 0.0 0.0" rpy="0.0 0.0 0.0"/>
      <mass value="1.219"/>
      <inertia ixx="0.0025598989760400002" ixy="0.0" ixz="0.0" iyy="0.0025598989760400002" iyz="0.0" izz="0.0021942"/>
    </inertial>
    <visual>
      <origin xyz="0.0 0.0 -0.0997" rpy="0.0 0.0 0.0"/>
      <geometry>
        <mesh filename="package://multiverse_parser/examples/output/ur5e/urdf/ur5e/obj/wrist2.obj"/>
      </geometry>
      <material name="LightGrey">
        <color rgba="0.7 0.7 0.7 1.0"/>
      </material>
    </visual>
    <collision>
      <origin xyz="0.0 0.0 -0.0997" rpy="0.0 0.0 0.0"/>
      <geometry>
        <mesh filename="package://multiverse_parser/examples/output/ur5e/urdf/ur5e/stl/wrist2.stl"/>
      </geometry>
    </collision>
  </link>
  <joint name="wrist_3_joint" type="revolute">
    <origin xyz="0.0 0.0996 -2.042830148012698e-11" rpy="1.570796326589793 3.141592653589793 3.141592653589793"/>
    <axis xyz="0.0 0.0 1.0"/>
    <parent link="wrist_2_link"/>
    <child link="wrist_3_link"/>
    <limit effort="28.0" lower="-1.5707963267948966" upper="1.5707963267948966" velocity="3.141592653589793"/>
    <dynamics damping="0.0" friction="0.0"/>
  </joint>
  <link name="wrist_3_link">
    <inertial>
      <origin xyz="0.0 0.0 -0.0229" rpy="0.0 0.0 0.0"/>
      <mass value="0.1879"/>
      <inertia ixx="9.890410052167731e-05" ixy="0.0" ixz="0.0" iyy="9.890410052167731e-05" iyz="0.0" izz="0.0001321171875"/>
    </inertial>
    <visual>
      <origin xyz="0.0 0.0 -0.0989" rpy="1.5707963267948966 0.0 0.0"/>
      <geometry>
        <mesh filename="package://multiverse_parser/examples/output/ur5e/urdf/ur5e/obj/wrist3.obj"/>
      </geometry>
      <material name="LightGrey">
        <color rgba="0.7 0.7 0.7 1.0"/>
      </material>
    </visual>
    <collision>
      <origin xyz="0.0 0.0 -0.0989" rpy="1.5707963267948966 0.0 0.0"/>
      <geometry>
        <mesh filename="package://multiverse_parser/examples/output/ur5e/urdf/ur5e/stl/wrist3.stl"/>
      </geometry>
    </collision>
  </link>
  <joint name="base_link-base_fixed_joint" type="fixed">
    <origin xyz="0.0 0.0 0.0" rpy="0.0 0.0 3.141592653589793"/>
    <parent link="base_link"/>
    <child link="base"/>
  </joint>
  <link name="base"/>
  <joint name="wrist_3-flange" type="fixed">
    <origin xyz="0.0 0.0 0.0" rpy="0.0 -1.5707963267948966 -1.5707963267948966"/>
    <parent link="wrist_3_link"/>
    <child link="flange"/>
  </joint>
  <link name="flange"/>
  <joint name="flange-tool0" type="fixed">
    <origin xyz="0.0 0.0 0.0" rpy="1.5707963267948966 0.0 1.5707963267948966"/>
    <parent link="flange"/>
    <child link="tool0"/>
  </joint>
  <link name="tool0"/>
  <joint name="gripper_hand_e_base_joint" type="fixed">
    <origin xyz="0.0 0.0 0.0" rpy="1.5707963267948966 0.0 0.0"/>
    <parent link="tool0"/>
    <child link="gripper_hand_e_base"/>
  </joint>
  <link name="gripper_hand_e_base">
    <visual>
      <geometry>
        <mesh filename="package://multiverse_parser/examples/output/ur5e/urdf/ur5e/obj/robotiq_hand_e_base.obj"/>
      </geometry>
    </visual>
    <collision>
      <origin xyz="0.0 0.01655 0.0" rpy="1.5707963267948966 0.0 0.0"/>
      <geometry>
        <cylinder radius="0.0375" length="0.0331"/>
      </geometry>
    </collision>
    <collision>
      <origin xyz="0.0 0.101861 0.0" rpy="1.5707963267948966 0.0 0.0"/>
      <geometry>
        <cylinder radius="0.0375" length="0.021878"/>
      </geometry>
    </collision>
    <collision>
      <origin xyz="0.0 0.062011 0.0" rpy="1.5707963267948966 0.0 0.0"/>
      <geometry>
        <cylinder radius="0.025" length="0.057822"/>
      </geometry>
    </collision>
  </link>
  <joint name="gripper_hand_e_finger_1_joint" type="prismatic">
    <axis xyz="0.0 0.0 -1.0"/>
    <parent link="gripper_hand_e_base"/>
    <child link="gripper_hand_e_finger_1"/>
    <limit effort="1000.0" lower="0.0" upper="0.025" velocity="1000.0"/>
  </joint>
  <link name="gripper_hand_e_finger_1">
    <visual>
      <geometry>
        <mesh filename="package://multiverse_parser/examples/output/ur5e/urdf/ur5e/obj/robotiq_hand_e_finger_1.obj"/>
      </geometry>
    </visual>
    <collision>
      <origin xyz="0.0 0.13705 0.027498" rpy="0.0 0.0 0.0"/>
      <geometry>
        <box size="0.02 0.0455 0.006"/>
      </geometry>
    </collision>
  </link>
  <joint name="gripper_hand_e_finger_2_joint" type="prismatic">
    <axis xyz="0.0 0.0 1.0"/>
    <parent link="gripper_hand_e_base"/>
    <child link="gripper_hand_e_finger_2"/>
    <limit effort="1000.0" lower="0.0" upper="0.025" velocity="1000.0"/>
    <mimic joint="gripper_hand_e_finger_1_joint"/>
  </joint>
  <link name="gripper_hand_e_finger_2">
    <visual>
      <geometry>
        <mesh filename="package://multiverse_parser/examples/output/ur5e/urdf/ur5e/obj/robotiq_hand_e_finger_2.obj"/>
      </geometry>
    </visual>
    <collision>
      <origin xyz="0.0 0.13705 -0.028502" rpy="0.0 0.0 0.0"/>
      <geometry>
        <box size="0.02 0.0455 0.006"/>
      </geometry>
    </collision>
  </link>
</robot>