<mujoco model="kitchen">
    <compiler angle="radian" meshdir="/media/giangnguyen/Storage/Multiverse/multiverse_ws/src/multiverse_core/multiverse_parser/examples/urdf_to_mjcf/mjcf/kitchen/stl/" autolimits="true" fusestatic="false" balanceinertia="true" discardvisual="true" boundmass="0.000001" boundinertia="0.000001"/>
    <statistic meansize="0.809444" extent="10.7837" center="-0.598586 1.59493 1.25"/>
    <asset>
        <mesh name="geom_12" file="geom_12.stl"/>
        <mesh name="geom_13" file="geom_13.stl"/>
        <mesh name="geom_14" file="geom_14.stl"/>
        <mesh name="geom_15" file="geom_15.stl"/>
        <mesh name="geom_16" file="geom_16.stl"/>
        <mesh name="geom_17" file="geom_17.stl"/>
        <mesh name="geom_18" file="geom_18.stl"/>
        <mesh name="geom_19" file="geom_19.stl"/>
        <mesh name="geom_20" file="geom_20.stl"/>
        <mesh name="geom_21" file="geom_21.stl"/>
        <mesh name="geom_22" file="geom_22.stl"/>
        <mesh name="geom_23" file="geom_23.stl"/>
        <mesh name="geom_24" file="geom_24.stl"/>
        <mesh name="geom_25" file="geom_25.stl"/>
        <mesh name="geom_26" file="geom_26.stl"/>
        <mesh name="geom_27" file="geom_27.stl"/>
        <mesh name="geom_28" file="geom_28.stl"/>
        <mesh name="geom_29" file="geom_29.stl"/>
        <mesh name="geom_30" file="geom_30.stl"/>
        <mesh name="geom_31" file="geom_31.stl"/>
        <mesh name="geom_32" file="geom_32.stl"/>
        <mesh name="geom_33" file="geom_33.stl"/>
        <mesh name="geom_34" file="geom_34.stl"/>
        <mesh name="geom_35" file="geom_35.stl"/>
        <mesh name="geom_36" file="geom_36.stl"/>
        <mesh name="geom_37" file="geom_37.stl"/>
        <mesh name="geom_38" file="geom_38.stl"/>
        <mesh name="geom_39" file="geom_39.stl"/>
        <mesh name="geom_40" file="geom_40.stl"/>
        <mesh name="geom_41" file="geom_41.stl"/>
        <mesh name="geom_42" file="geom_42.stl"/>
        <mesh name="geom_43" file="geom_43.stl"/>
        <mesh name="geom_44" file="geom_44.stl"/>
        <mesh name="geom_45" file="geom_45.stl"/>
        <mesh name="geom_46" file="geom_46.stl"/>
        <mesh name="geom_47" file="geom_47.stl" scale="1 1 1"/>
        <mesh name="geom_48" file="geom_48.stl" scale="1 1 1"/>
        <mesh name="geom_49" file="geom_49.stl"/>
        <mesh name="geom_50" file="geom_50.stl"/>
        <mesh name="geom_51" file="geom_51.stl"/>
        <mesh name="geom_52" file="geom_52.stl"/>
        <mesh name="geom_53" file="geom_53.stl"/>
        <mesh name="geom_54" file="geom_54.stl"/>
        <mesh name="geom_55" file="geom_55.stl" scale="1 1 1"/>
        <mesh name="geom_56" file="geom_56.stl"/>
        <mesh name="geom_57" file="geom_57.stl"/>
        <mesh name="geom_58" file="geom_58.stl"/>
        <mesh name="geom_59" file="geom_59.stl"/>
        <mesh name="geom_60" file="geom_60.stl"/>
        <mesh name="geom_61" file="geom_61.stl"/>
        <mesh name="geom_62" file="geom_62.stl"/>
        <mesh name="geom_63" file="geom_63.stl"/>
        <mesh name="geom_64" file="geom_64.stl"/>
        <mesh name="geom_65" file="geom_65.stl"/>
        <mesh name="geom_66" file="geom_66.stl"/>
        <mesh name="geom_67" file="geom_67.stl"/>
        <mesh name="geom_68" file="geom_68.stl"/>
        <mesh name="geom_69" file="geom_69.stl"/>
        <mesh name="geom_70" file="geom_70.stl"/>
        <mesh name="geom_71" file="geom_71.stl"/>
        <mesh name="geom_72" file="geom_72.stl" scale="1 1 1"/>
        <mesh name="geom_73" file="geom_73.stl"/>
        <mesh name="geom_74" file="geom_74.stl"/>
        <mesh name="geom_75" file="geom_75.stl"/>
        <mesh name="geom_76" file="geom_76.stl"/>
        <mesh name="geom_77" file="geom_77.stl"/>
        <mesh name="geom_78" file="geom_78.stl"/>
        <mesh name="geom_79" file="geom_79.stl"/>
        <mesh name="geom_80" file="geom_80.stl"/>
        <mesh name="geom_81" file="geom_81.stl"/>
        <mesh name="geom_82" file="geom_82.stl" scale="1 1 1"/>
        <mesh name="geom_83" file="geom_83.stl"/>
        <mesh name="geom_84" file="geom_84.stl"/>
        <mesh name="geom_85" file="geom_85.stl"/>
        <mesh name="geom_86" file="geom_86.stl"/>
        <mesh name="geom_87" file="geom_87.stl"/>
        <mesh name="geom_88" file="geom_88.stl"/>
        <mesh name="geom_89" file="geom_89.stl"/>
        <mesh name="geom_90" file="geom_90.stl"/>
        <mesh name="geom_91" file="geom_91.stl"/>
        <mesh name="geom_92" file="geom_92.stl"/>
        <mesh name="geom_93" file="geom_93.stl"/>
        <mesh name="geom_94" file="geom_94.stl"/>
        <mesh name="geom_95" file="geom_95.stl"/>
        <mesh name="geom_96" file="geom_96.stl"/>
        <mesh name="geom_97" file="geom_97.stl"/>
        <mesh name="geom_98" file="geom_98.stl"/>
        <mesh name="geom_99" file="geom_99.stl"/>
        <mesh name="geom_100" file="geom_100.stl" scale="1 1 1"/>
        <mesh name="geom_101" file="geom_101.stl"/>
        <mesh name="geom_102" file="geom_102.stl"/>
        <mesh name="geom_103" file="geom_103.stl"/>
        <mesh name="geom_104" file="geom_104.stl"/>
        <mesh name="geom_105" file="geom_105.stl"/>
        <mesh name="geom_106" file="geom_106.stl"/>
        <mesh name="geom_107" file="geom_107.stl"/>
        <mesh name="geom_108" file="geom_108.stl"/>
        <mesh name="geom_109" file="geom_109.stl"/>
        <mesh name="geom_110" file="geom_110.stl"/>
        <mesh name="geom_111" file="geom_111.stl" scale="1 1 1"/>
        <mesh name="geom_112" file="geom_112.stl"/>
        <mesh name="geom_113" file="geom_113.stl"/>
        <mesh name="geom_114" file="geom_114.stl"/>
        <mesh name="geom_115" file="geom_115.stl"/>
        <mesh name="geom_116" file="geom_116.stl"/>
        <mesh name="geom_117" file="geom_117.stl"/>
        <mesh name="geom_118" file="geom_118.stl"/>
        <mesh name="geom_119" file="geom_119.stl"/>
        <mesh name="geom_120" file="geom_120.stl"/>
        <mesh name="geom_121" file="geom_121.stl"/>
        <mesh name="geom_122" file="geom_122.stl"/>
        <mesh name="geom_123" file="geom_123.stl"/>
        <mesh name="geom_124" file="geom_124.stl"/>
        <mesh name="geom_125" file="geom_125.stl"/>
        <mesh name="geom_126" file="geom_126.stl"/>
        <mesh name="geom_127" file="geom_127.stl"/>
        <mesh name="geom_128" file="geom_128.stl"/>
        <mesh name="geom_129" file="geom_129.stl"/>
        <mesh name="geom_130" file="geom_130.stl"/>
        <mesh name="geom_131" file="geom_131.stl"/>
        <mesh name="geom_132" file="geom_132.stl"/>
        <mesh name="geom_133" file="geom_133.stl"/>
        <mesh name="geom_134" file="geom_134.stl"/>
        <mesh name="geom_135" file="geom_135.stl"/>
        <mesh name="geom_136" file="geom_136.stl"/>
        <mesh name="geom_137" file="geom_137.stl"/>
        <mesh name="geom_138" file="geom_138.stl"/>
        <mesh name="geom_139" file="geom_139.stl"/>
        <mesh name="geom_140" file="geom_140.stl"/>
        <mesh name="geom_141" file="geom_141.stl"/>
        <mesh name="geom_142" file="geom_142.stl"/>
        <mesh name="geom_143" file="geom_143.stl"/>
        <mesh name="geom_144" file="geom_144.stl"/>
        <mesh name="geom_145" file="geom_145.stl"/>
        <mesh name="geom_146" file="geom_146.stl" scale="1 1 1"/>
        <mesh name="geom_147" file="geom_147.stl"/>
        <mesh name="geom_148" file="geom_148.stl"/>
        <mesh name="geom_149" file="geom_149.stl"/>
        <mesh name="geom_150" file="geom_150.stl" scale="1 1 1"/>
        <mesh name="geom_151" file="geom_151.stl"/>
        <mesh name="geom_152" file="geom_152.stl"/>
        <mesh name="geom_153" file="geom_153.stl"/>
        <mesh name="geom_154" file="geom_154.stl"/>
        <mesh name="geom_155" file="geom_155.stl"/>
        <mesh name="geom_156" file="geom_156.stl"/>
        <mesh name="geom_157" file="geom_157.stl"/>
        <mesh name="geom_158" file="geom_158.stl"/>
        <mesh name="geom_159" file="geom_159.stl"/>
        <mesh name="geom_160" file="geom_160.stl"/>
        <mesh name="geom_161" file="geom_161.stl"/>
        <mesh name="geom_162" file="geom_162.stl"/>
        <mesh name="geom_163" file="geom_163.stl"/>
        <mesh name="geom_164" file="geom_164.stl"/>
        <mesh name="geom_165" file="geom_165.stl"/>
        <mesh name="geom_166" file="geom_166.stl"/>
        <mesh name="geom_167" file="geom_167.stl"/>
        <mesh name="geom_168" file="geom_168.stl"/>
        <mesh name="geom_169" file="geom_169.stl"/>
        <mesh name="geom_170" file="geom_170.stl"/>
        <mesh name="geom_171" file="geom_171.stl"/>
        <mesh name="geom_172" file="geom_172.stl"/>
        <mesh name="geom_173" file="geom_173.stl"/>
        <mesh name="geom_174" file="geom_174.stl"/>
        <mesh name="geom_175" file="geom_175.stl"/>
        <mesh name="geom_176" file="geom_176.stl"/>
        <mesh name="geom_177" file="geom_177.stl"/>
        <mesh name="geom_178" file="geom_178.stl"/>
        <mesh name="geom_187" file="geom_187.stl"/>
        <mesh name="geom_188" file="geom_188.stl"/>
        <mesh name="geom_189" file="geom_189.stl"/>
        <mesh name="geom_190" file="geom_190.stl"/>
        <mesh name="geom_191" file="geom_191.stl"/>
        <mesh name="geom_192" file="geom_192.stl"/>
        <mesh name="geom_193" file="geom_193.stl"/>
        <mesh name="geom_194" file="geom_194.stl"/>
        <mesh name="geom_195" file="geom_195.stl"/>
        <mesh name="geom_196" file="geom_196.stl"/>
        <mesh name="geom_197" file="geom_197.stl"/>
        <mesh name="geom_198" file="geom_198.stl"/>
        <mesh name="geom_199" file="geom_199.stl"/>
        <mesh name="geom_200" file="geom_200.stl"/>
        <mesh name="geom_201" file="geom_201.stl"/>
        <mesh name="geom_202" file="geom_202.stl"/>
        <mesh name="geom_203" file="geom_203.stl"/>
        <mesh name="geom_204" file="geom_204.stl"/>
        <mesh name="geom_205" file="geom_205.stl"/>
        <mesh name="geom_206" file="geom_206.stl"/>
        <mesh name="geom_207" file="geom_207.stl"/>
        <mesh name="geom_208" file="geom_208.stl"/>
        <mesh name="geom_209" file="geom_209.stl"/>
        <mesh name="geom_210" file="geom_210.stl"/>
        <mesh name="geom_211" file="geom_211.stl"/>
        <mesh name="geom_212" file="geom_212.stl"/>
        <mesh name="geom_213" file="geom_213.stl"/>
        <mesh name="geom_214" file="geom_214.stl"/>
        <mesh name="geom_215" file="geom_215.stl"/>
        <mesh name="geom_216" file="geom_216.stl"/>
        <mesh name="geom_217" file="geom_217.stl"/>
        <mesh name="geom_218" file="geom_218.stl"/>
        <mesh name="geom_219" file="geom_219.stl"/>
        <mesh name="geom_220" file="geom_220.stl"/>
        <mesh name="geom_221" file="geom_221.stl"/>
        <mesh name="geom_222" file="geom_222.stl"/>
        <mesh name="geom_223" file="geom_223.stl"/>
        <mesh name="geom_224" file="geom_224.stl"/>
        <mesh name="geom_225" file="geom_225.stl"/>
        <mesh name="geom_226" file="geom_226.stl"/>
        <mesh name="geom_227" file="geom_227.stl"/>
        <mesh name="geom_228" file="geom_228.stl"/>
        <mesh name="geom_229" file="geom_229.stl"/>
        <mesh name="geom_230" file="geom_230.stl"/>
        <mesh name="geom_231" file="geom_231.stl"/>
        <mesh name="geom_232" file="geom_232.stl"/>
        <mesh name="geom_233" file="geom_233.stl"/>
        <mesh name="geom_234" file="geom_234.stl"/>
        <mesh name="geom_235" file="geom_235.stl"/>
        <mesh name="geom_236" file="geom_236.stl"/>
        <mesh name="geom_237" file="geom_237.stl"/>
        <mesh name="geom_238" file="geom_238.stl"/>
        <mesh name="geom_239" file="geom_239.stl"/>
        <mesh name="geom_240" file="geom_240.stl"/>
        <mesh name="geom_241" file="geom_241.stl"/>
        <mesh name="geom_242" file="geom_242.stl"/>
        <mesh name="geom_243" file="geom_243.stl"/>
        <mesh name="geom_244" file="geom_244.stl"/>
        <mesh name="geom_245" file="geom_245.stl"/>
        <mesh name="geom_246" file="geom_246.stl"/>
        <mesh name="geom_247" file="geom_247.stl"/>
        <mesh name="geom_248" file="geom_248.stl"/>
        <mesh name="geom_249" file="geom_249.stl"/>
        <mesh name="geom_250" file="geom_250.stl"/>
        <mesh name="geom_251" file="geom_251.stl"/>
        <mesh name="geom_252" file="geom_252.stl"/>
        <mesh name="geom_253" file="geom_253.stl"/>
        <mesh name="geom_254" file="geom_254.stl"/>
        <mesh name="geom_255" file="geom_255.stl"/>
        <mesh name="geom_256" file="geom_256.stl"/>
        <mesh name="geom_257" file="geom_257.stl"/>
        <mesh name="geom_258" file="geom_258.stl"/>
        <mesh name="geom_259" file="geom_259.stl"/>
        <mesh name="geom_260" file="geom_260.stl"/>
        <mesh name="geom_261" file="geom_261.stl"/>
        <mesh name="geom_262" file="geom_262.stl"/>
        <mesh name="geom_263" file="geom_263.stl"/>
        <mesh name="geom_264" file="geom_264.stl"/>
        <mesh name="geom_265" file="geom_265.stl"/>
        <mesh name="geom_266" file="geom_266.stl"/>
        <mesh name="geom_267" file="geom_267.stl"/>
        <mesh name="geom_268" file="geom_268.stl"/>
        <mesh name="geom_269" file="geom_269.stl"/>
        <mesh name="geom_270" file="geom_270.stl"/>
        <mesh name="geom_271" file="geom_271.stl"/>
        <mesh name="geom_272" file="geom_272.stl"/>
        <mesh name="geom_273" file="geom_273.stl"/>
        <mesh name="geom_274" file="geom_274.stl"/>
        <mesh name="geom_275" file="geom_275.stl"/>
        <mesh name="geom_276" file="geom_276.stl"/>
        <mesh name="geom_277" file="geom_277.stl"/>
        <mesh name="geom_278" file="geom_278.stl"/>
        <mesh name="geom_279" file="geom_279.stl"/>
        <mesh name="geom_280" file="geom_280.stl"/>
        <mesh name="geom_281" file="geom_281.stl"/>
        <mesh name="geom_282" file="geom_282.stl"/>
        <mesh name="geom_283" file="geom_283.stl"/>
        <mesh name="geom_284" file="geom_284.stl"/>
        <mesh name="geom_285" file="geom_285.stl"/>
        <mesh name="geom_286" file="geom_286.stl"/>
        <mesh name="geom_287" file="geom_287.stl"/>
        <mesh name="geom_288" file="geom_288.stl"/>
        <mesh name="geom_289" file="geom_289.stl"/>
        <mesh name="geom_290" file="geom_290.stl"/>
        <mesh name="geom_291" file="geom_291.stl"/>
        <mesh name="geom_292" file="geom_292.stl"/>
        <mesh name="geom_293" file="geom_293.stl"/>
        <mesh name="geom_294" file="geom_294.stl"/>
        <mesh name="geom_295" file="geom_295.stl"/>
        <mesh name="geom_296" file="geom_296.stl"/>
        <mesh name="geom_297" file="geom_297.stl"/>
        <mesh name="geom_298" file="geom_298.stl"/>
        <mesh name="geom_299" file="geom_299.stl" scale="1 1 1"/>
        <mesh name="geom_300" file="geom_300.stl"/>
        <mesh name="geom_301" file="geom_301.stl"/>
        <mesh name="geom_302" file="geom_302.stl"/>
        <mesh name="geom_303" file="geom_303.stl" scale="1 1 1"/>
        <mesh name="geom_304" file="geom_304.stl"/>
        <mesh name="geom_305" file="geom_305.stl"/>
        <mesh name="geom_306" file="geom_306.stl"/>
        <mesh name="geom_307" file="geom_307.stl"/>
        <mesh name="geom_308" file="geom_308.stl" scale="1 1 1"/>
        <mesh name="geom_309" file="geom_309.stl"/>
        <mesh name="geom_310" file="geom_310.stl"/>
        <mesh name="geom_311" file="geom_311.stl"/>
        <mesh name="geom_312" file="geom_312.stl" scale="1 1 1"/>
        <mesh name="geom_331" file="geom_331.stl"/>
        <mesh name="geom_332" file="geom_332.stl"/>
        <mesh name="geom_333" file="geom_333.stl"/>
        <mesh name="geom_352" file="geom_352.stl"/>
        <mesh name="geom_353" file="geom_353.stl"/>
        <mesh name="geom_354" file="geom_354.stl"/>
        <mesh name="geom_355" file="geom_355.stl" scale="1 1 1"/>
        <mesh name="geom_356" file="geom_356.stl"/>
        <mesh name="geom_357" file="geom_357.stl"/>
        <mesh name="geom_358" file="geom_358.stl"/>
        <mesh name="geom_359" file="geom_359.stl"/>
        <mesh name="geom_360" file="geom_360.stl" scale="1 1 1"/>
        <mesh name="geom_361" file="geom_361.stl"/>
        <mesh name="geom_362" file="geom_362.stl"/>
        <mesh name="geom_363" file="geom_363.stl"/>
        <mesh name="geom_364" file="geom_364.stl" scale="1 1 1"/>
        <mesh name="geom_365" file="geom_365.stl" scale="1 1 1"/>
        <mesh name="geom_366" file="geom_366.stl"/>
        <mesh name="geom_367" file="geom_367.stl"/>
        <mesh name="geom_368" file="geom_368.stl"/>
        <mesh name="geom_369" file="geom_369.stl"/>
        <mesh name="geom_370" file="geom_370.stl" scale="1 1 1"/>
        <mesh name="geom_371" file="geom_371.stl"/>
        <mesh name="geom_372" file="geom_372.stl"/>
        <mesh name="geom_373" file="geom_373.stl"/>
        <mesh name="geom_374" file="geom_374.stl" scale="1 1 1"/>
        <mesh name="geom_375" file="geom_375.stl"/>
        <mesh name="geom_376" file="geom_376.stl"/>
        <mesh name="geom_377" file="geom_377.stl"/>
        <mesh name="geom_378" file="geom_378.stl"/>
        <mesh name="geom_379" file="geom_379.stl"/>
        <mesh name="geom_380" file="geom_380.stl"/>
        <mesh name="geom_381" file="geom_381.stl"/>
        <mesh name="geom_382" file="geom_382.stl"/>
        <mesh name="geom_383" file="geom_383.stl"/>
        <mesh name="geom_384" file="geom_384.stl"/>
        <mesh name="geom_385" file="geom_385.stl"/>
        <mesh name="geom_386" file="geom_386.stl"/>
        <mesh name="geom_387" file="geom_387.stl"/>
        <mesh name="geom_388" file="geom_388.stl"/>
        <mesh name="geom_389" file="geom_389.stl"/>
        <mesh name="geom_390" file="geom_390.stl"/>
        <mesh name="geom_391" file="geom_391.stl" scale="1 1 1"/>
        <mesh name="geom_392" file="geom_392.stl"/>
        <mesh name="geom_393" file="geom_393.stl"/>
        <mesh name="geom_394" file="geom_394.stl"/>
        <mesh name="geom_395" file="geom_395.stl"/>
        <mesh name="geom_396" file="geom_396.stl" scale="1 1 1"/>
        <mesh name="geom_397" file="geom_397.stl"/>
        <mesh name="geom_398" file="geom_398.stl"/>
        <mesh name="geom_399" file="geom_399.stl"/>
        <mesh name="geom_400" file="geom_400.stl" scale="1 1 1"/>
        <mesh name="geom_401" file="geom_401.stl" scale="1 1 1"/>
        <mesh name="geom_402" file="geom_402.stl"/>
        <mesh name="geom_403" file="geom_403.stl"/>
        <mesh name="geom_404" file="geom_404.stl"/>
        <mesh name="geom_405" file="geom_405.stl"/>
        <mesh name="geom_406" file="geom_406.stl" scale="1 1 1"/>
        <mesh name="geom_407" file="geom_407.stl"/>
        <mesh name="geom_408" file="geom_408.stl"/>
        <mesh name="geom_409" file="geom_409.stl"/>
        <mesh name="geom_410" file="geom_410.stl" scale="1 1 1"/>
        <mesh name="geom_411" file="geom_411.stl" scale="1 1 1"/>
        <mesh name="geom_412" file="geom_412.stl"/>
        <mesh name="geom_413" file="geom_413.stl"/>
        <mesh name="geom_414" file="geom_414.stl"/>
        <mesh name="geom_415" file="geom_415.stl"/>
        <mesh name="geom_416" file="geom_416.stl" scale="1 1 1"/>
        <mesh name="geom_417" file="geom_417.stl"/>
        <mesh name="geom_418" file="geom_418.stl"/>
        <mesh name="geom_419" file="geom_419.stl"/>
        <mesh name="geom_420" file="geom_420.stl" scale="1 1 1"/>
        <mesh name="geom_437" file="geom_437.stl"/>
        <mesh name="geom_438" file="geom_438.stl"/>
        <mesh name="geom_439" file="geom_439.stl"/>
        <mesh name="geom_440" file="geom_440.stl"/>
    </asset>
    <worldbody>
        <body name="kitchen">
            <body name="kitchen">
                <inertial pos="0.028714 1.22615 0.994512" mass="1e-06" diaginertia="53549.6 36894.3 23144.2"/>
                <geom size="0.2875 0.8 0.01" pos="1.565 0.525 0.84" quat="0 0 0 1" type="box"/>
                <geom size="0.4 1.225 0.01" pos="-1.0655 1.7492 0.841" type="box"/>
                <geom size="0.145 0.25 0.005" pos="1.565 -1 1" quat="0 0 0 1" type="box"/>
                <geom size="0.28 0.25 0.065" pos="1.555 -1 1.43" quat="0 0 0 1" type="box"/>
                <geom size="0.5688 0.075 1.25" pos="1.42151 -1.836 1.25" quat="1.32679e-06 0 0 1" type="box"/>
                <geom size="2.591 0.075 1.25" pos="1.91551 0.68 1.25" quat="0.707105 0 0 0.707108" type="box"/>
                <geom size="2.9505 0.075 1.25" pos="-0.96 3.196 1.25" quat="1.32679e-06 0 0 1" type="box"/>
                <geom size="2.125 0.075 0.35" pos="-3.83549 1.146 0.35" quat="0.707105 0 0 -0.707108" type="box"/>
                <geom size="1.13664 0.075 0.35" pos="-2.77385 -1.02376 0.35" quat="1 0 0 7.85e-05" type="box"/>
                <geom size="0.5 0.075 0.35" pos="-1.61 -1.44851 0.35" quat="0.707105 0 0 -0.707108" type="box"/>
                <geom size="0.8 0.075 0.375" pos="0.05271 -1.876 0.375" quat="1.32679e-06 0 0 1" type="box"/>
                <geom pos="1.56466 1.31445 0.439002" quat="0.707103 -0.00195169 -0.00121914 -0.707107" type="mesh" mesh="geom_12"/>
                <geom pos="1.56466 0.953322 0.093323" quat="0.5 -0.5 -0.5 -0.5" type="mesh" mesh="geom_13"/>
                <geom pos="1.56466 -0.712623 0.305988" quat="0.49714 0.502836 -0.495782 -0.50419" type="mesh" mesh="geom_14"/>
                <geom pos="1.82618 -0.169597 0.836352" quat="-0.497028 0.496896 0.503103 0.502937" type="mesh" mesh="geom_15"/>
                <geom pos="1.56466 1.2633 0.834235" quat="0.707034 -0.0101583 -0.707034 0.0101583" type="mesh" mesh="geom_16"/>
                <geom pos="1.57503 0.50047 0.459672" quat="0.707107 0 0 -0.707107" type="mesh" mesh="geom_17"/>
                <geom pos="1.56499 0.701256 0.834619" quat="0.500659 -0.499451 -0.499701 -0.500189" type="mesh" mesh="geom_18"/>
                <geom pos="1.56466 -0.712097 0.71067" quat="0.506249 0.493672 -0.506249 -0.493672" type="mesh" mesh="geom_19"/>
                <geom pos="1.57056 0.396878 0.0953426" quat="0.706987 0.0105981 -0.707109 0.00725085" type="mesh" mesh="geom_20"/>
                <geom pos="1.30112 -0.236726 0.836391" quat="0.502772 -0.50111 -0.498926 -0.497174" type="mesh" mesh="geom_21"/>
                <geom pos="1.57042 -0.249244 0.0952734" quat="0.497681 -0.502251 -0.496793 -0.503244" type="mesh" mesh="geom_22"/>
                <geom pos="1.57498 -0.10094 0.466272" quat="0.707107 0.000453089 -0.000453089 -0.707107" type="mesh" mesh="geom_23"/>
                <geom pos="1.59854 -0.62788 0.836434" quat="0.707114 0.00233443 -0.70709 0.00276354" type="mesh" mesh="geom_24"/>
                <geom pos="1.56466 0.3 0.0414725" quat="0.5 -0.5 -0.5 -0.5" type="mesh" mesh="geom_25"/>
                <geom pos="1.55934 -0.250162 0.795092" quat="0.500198 0.499793 -0.499806 -0.500202" type="mesh" mesh="geom_26"/>
                <geom pos="1.76301 -0.257476 0.741311" quat="0.633031 -0.0350833 0.0228061 -0.772995" type="mesh" mesh="geom_27"/>
                <geom pos="1.35156 -0.255431 0.777202" quat="0.731799 0.03364 -0.0547757 -0.678482" type="mesh" mesh="geom_28"/>
                <geom pos="1.31199 -0.170243 0.836522" quat="0 0 0.707118 0.707096" type="mesh" mesh="geom_29"/>
                <geom pos="1.80557 -0.107291 0.839429" quat="-0.0770135 0.0788726 -0.700048 -0.705536" type="mesh" mesh="geom_30"/>
                <geom pos="1.76462 -0.405649 0.73639" quat="0.0339398 -0.0339398 -0.706292 -0.706292" type="mesh" mesh="geom_31"/>
                <geom pos="1.57375 0.257849 0.837389" quat="0.493259 0.505642 -0.491786 -0.509086" type="mesh" mesh="geom_32"/>
                <geom pos="1.35404 -0.406903 0.760418" quat="0.0339518 -0.0336917 0.708956 0.703629" type="mesh" mesh="geom_33"/>
                <geom pos="1.77387 -0.392954 0.835027" quat="0.0768029 -0.0723674 -0.705812 -0.700496" type="mesh" mesh="geom_34"/>
                <geom pos="1.54887 -0.563445 0.833855" quat="0.454281 0.539953 -0.453804 -0.544189" type="mesh" mesh="geom_35"/>
                <geom pos="1.54643 -0.580666 0.853514" quat="0.707088 -0.00715173 -0.707082 -0.00322187" type="mesh" mesh="geom_36"/>
                <geom pos="1.5622 -0.557157 0.734855" quat="0.484309 0.515214 -0.484309 -0.515214" type="mesh" mesh="geom_37"/>
                <geom pos="1.55492 0.0073685 0.853532" quat="0.5 -0.5 -0.5 -0.5" type="mesh" mesh="geom_38"/>
                <geom pos="1.55977 -0.405649 0.6689" quat="0.707107 0 -0.707107 0" type="mesh" mesh="geom_39"/>
                <geom pos="1.55767 -0.243707 0.84332" quat="0.524475 0.474253 -0.524013 -0.474785" type="mesh" mesh="geom_40"/>
                <geom pos="1.76702 -0.557912 0.778579" quat="0.120395 0.0344661 -0.0227583 0.991866" type="mesh" mesh="geom_41"/>
                <geom pos="1.3569 -0.556212 0.759063" quat="0.546491 0.0320935 0.00127103 -0.836849" type="mesh" mesh="geom_42"/>
                <geom pos="1.55447 -0.595387 0.838808" quat="0.534566 0.461058 -0.531865 -0.467744" type="mesh" mesh="geom_43"/>
                <geom pos="1.79435 -0.573582 0.841314" quat="0.868135 0.0530686 -0.493227 0.0158682" type="mesh" mesh="geom_44"/>
                <geom pos="1.33307 -0.406465 0.851953" quat="0.524222 -0.523837 -0.474992 -0.47452" type="mesh" mesh="geom_45"/>
                <geom pos="1.55977 -0.256981 0.71242" quat="0.510667 0.4891 -0.510667 -0.4891" type="mesh" mesh="geom_46"/>
                <geom pos="1.79956 -0.400791 0.851956" quat="0.524187 -0.524187 -0.474582 -0.474582" type="mesh" mesh="geom_47"/>
                <geom pos="1.28472 -0.400001 0.765224" quat="5.53654e-07 2.77138e-06 0.707107 0.707106" type="mesh" mesh="geom_48"/>
                <geom pos="1.56349 0.317937 0.794274" quat="0.707616 -0.00470599 -0.706577 -0.00245549" type="mesh" mesh="geom_49"/>
                <geom pos="1.5476 -0.040601 0.323552" quat="0.5 0.5 -0.5 -0.5" type="mesh" mesh="geom_50"/>
                <geom pos="1.56314 -0.0390297 0.649185" quat="0.503986 0.496744 -0.497357 -0.501876" type="mesh" mesh="geom_51"/>
                <geom pos="1.82483 0.320051 0.469987" quat="0.00363311 0 0 -0.999993" type="mesh" mesh="geom_52"/>
                <geom pos="1.5476 0.440851 0.469987" quat="0.707107 0 0 -0.707107" type="mesh" mesh="geom_53"/>
                <geom pos="1.5476 0.078388 0.795847" quat="0.707107 0 -0.707107 0" type="mesh" mesh="geom_54"/>
                <geom pos="1.82487 0.0784784 0.651758" quat="0.000158994 0.00297316 -0.000465969 -0.999995" type="mesh" mesh="geom_55"/>
                <geom pos="1.82481 0.0605167 0.323552" quat="0.00427542 0 0 0.999991" type="mesh" mesh="geom_56"/>
                <geom pos="1.56041 0.199195 0.145979" quat="0.707107 0 -0.707107 0" type="mesh" mesh="geom_57"/>
                <geom pos="1.5577 2.51854 0.708974" quat="0.706887 0.00283881 -0.00445087 -0.707307" type="mesh" mesh="geom_58"/>
                <geom pos="1.5597 1.34506 0.666263" quat="0.70767 0.0072659 -0.00238954 -0.706501" type="mesh" mesh="geom_59"/>
                <geom pos="1.59028 1.93628 0.076652" quat="-0.49982 0.499835 0.500182 0.500163" type="mesh" mesh="geom_60"/>
                <geom pos="1.60301 2.22026 0.777585" quat="0.707107 0 0 -0.707107" type="mesh" mesh="geom_61"/>
                <geom pos="1.56817 2.22025 1.46031" quat="0.504652 0.495304 -0.495291 -0.504665" type="mesh" mesh="geom_62"/>
                <geom pos="1.55428 2.39188 1.49211" quat="0.707004 -0.00439787 -0.707185 0.00391972" type="mesh" mesh="geom_63"/>
                <geom pos="1.60301 1.64271 0.80985" quat="0.707107 0 0 -0.707107" type="mesh" mesh="geom_64"/>
                <geom pos="1.55538 1.74068 1.4893" quat="0.502312 -0.498001 -0.498041 -0.501629" type="mesh" mesh="geom_65"/>
                <geom pos="1.55939 1.92916 1.4107" quat="0.707107 0 -0.707107 0" type="mesh" mesh="geom_66"/>
                <geom pos="1.54541 1.81737 0.883714" quat="0.707107 0 -0.707107 0" type="mesh" mesh="geom_67"/>
                <geom pos="1.54543 1.68762 1.16118" quat="0.5 0.5 -0.5 -0.5" type="mesh" mesh="geom_68"/>
                <geom pos="1.54543 2.0599 0.884833" quat="0.7071 0.00306651 -0.7071 -0.00306651" type="mesh" mesh="geom_69"/>
                <geom pos="1.54542 2.17068 1.12526" quat="0.499963 0.500037 -0.500037 -0.499963" type="mesh" mesh="geom_70"/>
                <geom pos="1.54543 1.68891 0.920176" quat="0.494215 0.505718 -0.494215 -0.505718" type="mesh" mesh="geom_71"/>
                <geom pos="1.82289 1.92917 1.10928" quat="6.61997e-07 6.62279e-07 0.706956 0.707257" type="mesh" mesh="geom_72"/>
                <geom pos="1.2849 1.93 1.42001" quat="1.38112e-07 1.36418e-06 -0.707109 -0.707105" type="mesh" mesh="geom_73"/>
                <geom pos="-1.08223 1.18017 0.0520771" quat="0.488031 0.512543 -0.486534 0.512259" type="mesh" mesh="geom_74"/>
                <geom pos="-1.08211 2.3492 0.0521001" quat="0.51369 0.486759 -0.513468 0.485324" type="mesh" mesh="geom_75"/>
                <geom pos="-1.07983 0.63729 0.459375" quat="0.712009 0 0 0.70217" type="mesh" mesh="geom_76"/>
                <geom pos="-1.07185 2.86313 0.459163" quat="0.704689 0.000676966 0.000766351 0.709516" type="mesh" mesh="geom_77"/>
                <geom pos="-1.3505 1.22645 0.459375" quat="0.707107 0.707107 -6.3509e-05 -6.3509e-05" type="mesh" mesh="geom_78"/>
                <geom pos="-1.08672 1.24939 0.459375" quat="0.707107 0 0 0.707107" type="mesh" mesh="geom_79"/>
                <geom pos="-1.35048 2.30638 0.459375" quat="0.707107 0.707107 0.000165732 0.000165732" type="mesh" mesh="geom_80"/>
                <geom pos="-1.08672 2.25276 0.459375" quat="0.707107 0 0 0.707107" type="mesh" mesh="geom_81"/>
                <geom pos="-1.06629 1.74542 0.834702" quat="0.500032 0.500025 -0.49997 0.499973" type="mesh" mesh="geom_82"/>
                <geom pos="-1.06547 2.515 0.852623" quat="0.5 0.5 -0.5 0.5" type="mesh" mesh="geom_83"/>
                <geom pos="-0.79272 0.949201 0.750224" quat="0.707106 0.707107 -2.77138e-06 -5.53654e-07" type="mesh" mesh="geom_84"/>
                <geom pos="-0.792832 1.7492 0.750044" quat="0.707108 0.707105 7.27146e-07 -7.27149e-07" type="mesh" mesh="geom_85"/>
                <geom pos="-0.79272 2.5492 0.750224" quat="0.707106 0.707107 -2.77138e-06 -5.53654e-07" type="mesh" mesh="geom_86"/>
                <geom pos="1.55526 -0.846235 1.49451" quat="0.707098 -0.00350209 -0.707098 0.00350209" type="mesh" mesh="geom_87"/>
                <geom pos="1.55831 -1.28899 0.810907" quat="0.7077 0.000922863 -0.000500289 -0.706512" type="mesh" mesh="geom_88"/>
                <geom pos="1.55524 -1.15824 1.49451" quat="0.707098 0.00357117 -0.707098 -0.00357117" type="mesh" mesh="geom_89"/>
                <geom pos="1.58869 -0.867151 0.0752171" quat="0.707111 -2.55903e-06 -0.707103 2.48189e-05" type="mesh" mesh="geom_90"/>
                <geom pos="1.57634 -1.15669 0.0776816" quat="0.710937 0.00140309 -0.703042 0.017241" type="mesh" mesh="geom_91"/>
                <geom pos="1.63327 -1.00087 0.515407" quat="0.5 -0.5 -0.5 -0.5" type="mesh" mesh="geom_92"/>
                <geom pos="1.55916 -0.713259 0.721011" quat="0.706673 0.00248755 -0.00362386 -0.707526" type="mesh" mesh="geom_93"/>
                <geom pos="1.52431 -0.994457 1.46303" quat="-0.498837 0.50116 0.50116 0.498837" type="mesh" mesh="geom_94"/>
                <geom pos="1.52431 -1.16184 0.553147" quat="0.707099 -0.00321682 -0.707099 0.00321682" type="mesh" mesh="geom_95"/>
                <geom pos="1.52431 -1.28328 0.78686" quat="0.5 0.5 -0.5 -0.5" type="mesh" mesh="geom_96"/>
                <geom pos="1.52431 -0.874772 0.553147" quat="0.707099 0.00321698 -0.707099 -0.00321698" type="mesh" mesh="geom_97"/>
                <geom pos="1.52431 -0.753331 1.00804" quat="0.707107 0 0 -0.707107" type="mesh" mesh="geom_98"/>
                <geom pos="1.52431 -1.28202 1.24647" quat="0.707104 -0.00180057 -0.00180057 -0.707104" type="mesh" mesh="geom_99"/>
                <geom pos="1.77316 -1.0183 1.00803" quat="5.10617e-06 -1.75669e-06 1.96734e-05 -1" type="mesh" mesh="geom_100"/>
                <geom pos="-2.40009 -1.75936 0.705812" quat="0.707098 0.00288501 -0.707103 -0.00289507" type="mesh" mesh="geom_101"/>
                <geom pos="-1.65018 -1.11623 0.342537" quat="0.908314 0 0 -0.41829" type="mesh" mesh="geom_102"/>
                <geom pos="-3.14982 -1.11623 0.342537" quat="0.418289 0 0 -0.908314" type="mesh" mesh="geom_103"/>
                <geom pos="-1.65019 -1.82391 0.341425" quat="0.514251 0.000247536 0.000282093 -0.857639" type="mesh" mesh="geom_104"/>
                <geom pos="-3.14981 -1.82391 0.343649" quat="0.85764 -0.000282094 -0.000247536 -0.514251" type="mesh" mesh="geom_105"/>
                <geom pos="-2.40002 -1.34905 0.705961" quat="0.707105 -0.00134326 -0.707106 0.00126408" type="mesh" mesh="geom_106"/>
                <geom pos="-3.75318 -0.302263 0.299527" quat="0.0108558 -8.82929e-07 -7.55587e-07 -0.999941" type="mesh" mesh="geom_107"/>
                <geom pos="-3.75318 0.922263 0.299527" quat="0.0109585 -8.83641e-07 -7.55562e-07 -0.99994" type="mesh" mesh="geom_108"/>
                <geom pos="-3.00507 -0.303101 0.368028" quat="0.717801 0.00148562 4.49968e-05 0.696247" type="mesh" mesh="geom_109"/>
                <geom pos="-3.00227 0.310007 0.703057" quat="0.0123782 -0.0123782 0.706998 0.706999" type="mesh" mesh="geom_110"/>
                <geom pos="-3.41561 0.925611 0.69859" quat="0.503519 0.491391 0.506044 0.498922" type="mesh" mesh="geom_111"/>
                <geom pos="-3.00507 0.923099 0.368168" quat="0.824115 -0.000242799 0.00144626 0.566421" type="mesh" mesh="geom_112"/>
                <geom pos="-3.43517 -0.305314 0.698457" quat="0.497701 0.50728 0.490317 0.504529" type="mesh" mesh="geom_113"/>
                <geom pos="-3.38619 0.309946 0.745461" quat="0.499989 -0.500011 -0.499989 -0.500011" type="mesh" mesh="geom_114"/>
                <geom pos="-3.76237 0.344305 0.698585" quat="-0.0167118 0.0169565 -0.707709 -0.706103" type="mesh" mesh="geom_115"/>
                <geom pos="-3.17776 -0.914325 0.295698" quat="0.00403438 -0.00093953 0.0542792 0.998517" type="mesh" mesh="geom_116"/>
                <geom pos="-3.59418 -0.65586 0.515025" quat="0.0181929 0.0102016 -0.70328 -0.710607" type="mesh" mesh="geom_117"/>
                <geom pos="-3.15411 -0.451668 0.236253" quat="0.707107 0 0 0.707107" type="mesh" mesh="geom_118"/>
                <geom pos="-3.37996 -0.446375 0.513895" quat="0.552163 0.441751 0.552103 0.441762" type="mesh" mesh="geom_119"/>
                <geom pos="-3.60595 -0.451668 0.236258" quat="0.707107 -1.46843e-06 -1.46843e-06 0.707107" type="mesh" mesh="geom_120"/>
                <geom pos="-3.17787 -0.894912 0.811821" quat="0.0768846 0.00102314 0.00759747 -0.997011" type="mesh" mesh="geom_121"/>
                <geom pos="-3.38003 -0.892614 0.516316" quat="0.535158 0.462175 0.535158 0.462175" type="mesh" mesh="geom_122"/>
                <geom pos="-3.38004 -0.89654 1.0656" quat="0.499998 0.500003 0.500011 0.499988" type="mesh" mesh="geom_123"/>
                <geom pos="-3.58286 -0.913948 0.299199" quat="0.00282529 -0.00233188 -0.0542508 -0.998521" type="mesh" mesh="geom_124"/>
                <geom pos="-3.5822 -0.894793 0.811446" quat="0.0512226 0.000847506 -0.00781962 0.998656" type="mesh" mesh="geom_125"/>
                <geom pos="-3.16512 -0.668266 0.502421" quat="0.0186631 0.018558 0.706878 0.706846" type="mesh" mesh="geom_126"/>
                <geom pos="-3.35256 -0.666284 0.542247" quat="0.059839 -0.705221 -0.0596829 -0.703933" type="mesh" mesh="geom_127"/>
                <geom pos="-3.38003 -0.889818 0.832298" quat="0.497039 0.502944 0.497039 0.502944" type="mesh" mesh="geom_128"/>
                <geom pos="-3.58224 1.53433 0.295698" quat="0.998517 0.0542792 0.00093953 -0.00403438" type="mesh" mesh="geom_129"/>
                <geom pos="-3.16582 1.27586 0.515025" quat="0.710607 0.70328 0.0102016 0.0181929" type="mesh" mesh="geom_130"/>
                <geom pos="-3.60589 1.07167 0.236253" quat="0.707107 0 0 -0.707107" type="mesh" mesh="geom_131"/>
                <geom pos="-3.38004 1.06637 0.513895" quat="0.441762 0.552103 -0.441751 -0.552163" type="mesh" mesh="geom_132"/>
                <geom pos="-3.15405 1.07167 0.236258" quat="0.707107 -1.46843e-06 1.46843e-06 -0.707107" type="mesh" mesh="geom_133"/>
                <geom pos="-3.58213 1.51491 0.811821" quat="0.997011 -0.00759747 0.00102314 0.0768846" type="mesh" mesh="geom_134"/>
                <geom pos="-3.37997 1.51261 0.516316" quat="0.462175 0.535158 -0.462175 -0.535158" type="mesh" mesh="geom_135"/>
                <geom pos="-3.37996 1.51654 1.0656" quat="0.499988 0.500011 -0.500003 -0.499998" type="mesh" mesh="geom_136"/>
                <geom pos="-3.17714 1.53395 0.299199" quat="0.998521 0.0542508 -0.00233188 0.00282529" type="mesh" mesh="geom_137"/>
                <geom pos="-3.1778 1.51479 0.811446" quat="0.998656 -0.00781962 -0.000847506 -0.0512226" type="mesh" mesh="geom_138"/>
                <geom pos="-3.59488 1.28827 0.502421" quat="0.706846 0.706878 -0.018558 -0.0186631" type="mesh" mesh="geom_139"/>
                <geom pos="-3.40744 1.28628 0.542247" quat="0.703933 0.0596829 -0.705221 0.059839" type="mesh" mesh="geom_140"/>
                <geom pos="-3.37997 1.50982 0.832298" quat="0.502944 0.497039 -0.502944 -0.497039" type="mesh" mesh="geom_141"/>
                <body name="sink_area_trash_drawer_main" pos="1.555 -0.4 0.395" quat="0 -0.707107 0 0.707107">
                    <inertial pos="0.185 0 0.125" mass="2" diaginertia="2.0997 2.0997 2"/>
                    <joint name="sink_area_trash_drawer_main_joint" pos="0 0 0" axis="0 0 1" type="slide" range="0 0.48"/>
                    <geom pos="-0.00144724 -2.17245e-05 -0.268031" quat="0.707108 2.95432e-05 -0.707106 2.6219e-05" type="mesh" mesh="geom_142"/>
                    <geom pos="-0.0134195 0.239368 0.000402511" quat="0.653281 -0.270598 -0.270598 0.653281" type="mesh" mesh="geom_143"/>
                    <geom pos="0.254034 -0.149929 0.000402495" quat="0.00451208 1.71141e-08 7.7221e-11 0.99999" type="mesh" mesh="geom_144"/>
                    <geom pos="-0.0134195 -0.239368 0.000402511" quat="0.653281 -0.270598 -0.270598 0.653281" type="mesh" mesh="geom_145"/>
                    <geom pos="0.254063 0.108289 0.000408977" quat="0.00312425 -1.71142e-08 5.34693e-11 -0.999995" type="mesh" mesh="geom_146"/>
                    <geom pos="0.000166038 -3.40689e-06 0.269017" quat="0.499978 0.500001 -0.499998 0.500023" type="mesh" mesh="geom_147"/>
                    <geom pos="-0.24991 -4.97357e-06 0.370088" quat="-1.21016e-08 -1.21016e-08 0.707108 -0.707106" type="mesh" mesh="geom_148"/>
                    <geom pos="-0.24991 0.244922 0.34752" quat="-4.43976e-11 -1.71142e-08 0.00259419 -0.999997" type="mesh" mesh="geom_149"/>
                    <geom pos="-0.24991 -0.244922 0.34752" quat="-4.43976e-11 1.71142e-08 0.00259419 0.999997" type="mesh" mesh="geom_150"/>
                </body>
                <body name="sink_area_left_upper_drawer_main" pos="1.555 0.9 0.755" quat="0 -0.707107 0 0.707107">
                    <inertial pos="0.17625 0 0.00875" mass="2" diaginertia="2.06228 2.06228 2"/>
                    <joint name="sink_area_left_upper_drawer_main_joint" pos="0 0 0" axis="0 0 1" type="slide" range="0 0.48"/>
                    <geom pos="-9.40912e-05 -0.0137171 -0.268614" quat="0.498808 0.497725 -0.501923 0.501532" type="mesh" mesh="geom_151"/>
                    <geom pos="-5.2899e-05 0.33867 -0.0139055" quat="0.709506 0.000431728 0.00104578 0.704698" type="mesh" mesh="geom_152"/>
                    <geom pos="0.000544651 -0.338981 0.000810005" quat="0.701241 1.22012e-08 1.20012e-08 0.712925" type="mesh" mesh="geom_153"/>
                    <geom pos="0.03416 -5.7615e-06 0.000806205" quat="1.21016e-08 1.21016e-08 -0.707107 0.707107" type="mesh" mesh="geom_154"/>
                    <geom pos="-0.000460236 -5.8831e-06 0.269067" quat="0.5 0.5 -0.5 0.5" type="mesh" mesh="geom_155"/>
                    <geom pos="-0.0175805 -1.65026e-05 0.352452" quat="0.499999 0.500001 -0.500001 0.499999" type="mesh" mesh="geom_156"/>
                    <geom pos="-0.0175804 0.344735 0.329918" quat="0.000198645 5.9138e-07 -0.0028909 0.999996" type="mesh" mesh="geom_157"/>
                    <geom pos="-0.0175805 -0.344735 0.329918" quat="4.94954e-11 -1.71142e-08 -0.00289205 -0.999996" type="mesh" mesh="geom_158"/>
                </body>
                <body name="sink_area_left_middle_drawer_main" pos="1.555 0.9 0.53" quat="0 -0.707107 0 0.707107">
                    <inertial pos="0.17625 0 0.055" mass="2" diaginertia="2.06818 2.06818 2"/>
                    <joint name="sink_area_left_middle_drawer_main_joint" pos="0 0 0" axis="0 0 1" type="slide" range="0 0.48"/>
                    <geom pos="0.00111909 -0.338539 -0.0155413" quat="0.706078 0.00324505 0.0023713 0.708123" type="mesh" mesh="geom_159"/>
                    <geom pos="0.000996621 0.015009 -0.268074" quat="-0.497747 -0.500773 0.499716 -0.501755" type="mesh" mesh="geom_160"/>
                    <geom pos="0.00281653 0.338996 0.000677492" quat="0.709479 1.20609e-08 1.21422e-08 0.704727" type="mesh" mesh="geom_161"/>
                    <geom pos="0.110639 -1.0677e-05 0.000669166" quat="-1.21028e-08 -1.21004e-08 0.707176 -0.707037" type="mesh" mesh="geom_162"/>
                    <geom pos="-0.000113565 5.30745e-06 0.269402" quat="0.499998 0.500002 -0.499998 0.500002" type="mesh" mesh="geom_163"/>
                    <geom pos="-0.11008 -1.65026e-05 0.352452" quat="0.499999 0.500001 -0.500001 0.499999" type="mesh" mesh="geom_164"/>
                    <geom pos="-0.11008 0.344735 0.329918" quat="0.000198645 5.9138e-07 -0.0028909 0.999996" type="mesh" mesh="geom_165"/>
                    <geom pos="-0.11008 -0.344735 0.329918" quat="4.94954e-11 -1.71142e-08 -0.00289205 -0.999996" type="mesh" mesh="geom_166"/>
                </body>
                <body name="sink_area_left_bottom_drawer_main" pos="1.555 0.9 0.23" quat="0 -0.707107 0 0.707107">
                    <inertial pos="0.17625 0 0.055" mass="2" diaginertia="2.06818 2.06818 2"/>
                    <joint name="sink_area_left_bottom_drawer_main_joint" pos="0 0 0" axis="0 0 1" type="slide" range="0 0.48"/>
                    <geom pos="0.00111909 -0.338539 -0.0155413" quat="0.706078 0.00324505 0.0023713 0.708123" type="mesh" mesh="geom_167"/>
                    <geom pos="0.000996621 0.015009 -0.268074" quat="-0.497747 -0.500773 0.499716 -0.501755" type="mesh" mesh="geom_168"/>
                    <geom pos="0.00281653 0.338996 0.000677492" quat="0.709479 1.20609e-08 1.21422e-08 0.704727" type="mesh" mesh="geom_169"/>
                    <geom pos="0.110639 -1.0677e-05 0.000669166" quat="-1.21028e-08 -1.21004e-08 0.707176 -0.707037" type="mesh" mesh="geom_170"/>
                    <geom pos="-0.000113565 5.30745e-06 0.269402" quat="0.499998 0.500002 -0.499998 0.500002" type="mesh" mesh="geom_171"/>
                    <geom pos="-0.11008 -1.65026e-05 0.352452" quat="0.499999 0.500001 -0.500001 0.499999" type="mesh" mesh="geom_172"/>
                    <geom pos="-0.11008 0.344735 0.329918" quat="0.000198645 5.9138e-07 -0.0028909 0.999996" type="mesh" mesh="geom_173"/>
                    <geom pos="-0.11008 -0.344735 0.329918" quat="4.94954e-11 -1.71142e-08 -0.00289205 -0.999996" type="mesh" mesh="geom_174"/>
                </body>
                <body name="sink_area_dish_washer_door" pos="1.285 0.2 0.185" quat="0 0 -0.707107 0.707107">
                    <inertial pos="0.0425 -0.2875 0" mass="2" diaginertia="2.16892 2.16892 2"/>
                    <joint name="sink_area_dish_washer_door_joint" pos="0 0 0" axis="0 0 1" range="0 1.5708"/>
                    <geom pos="-0.000137998 -0.27 -0.0004054" quat="0.707148 0.707065 -8.44664e-07 8.44763e-07" type="mesh" mesh="geom_175"/>
                    <geom pos="0.085088 -0.57509 4.97357e-06" quat="0.707107 -7.47401e-07 -7.47401e-07 0.707107" type="mesh" mesh="geom_176"/>
                    <geom pos="0.06252 -0.57509 -0.244922" quat="0.501295 0.498701 0.498701 0.501295" type="mesh" mesh="geom_177"/>
                    <geom pos="0.06252 -0.57509 0.244922" quat="0.498701 0.501295 0.501295 0.498701" type="mesh" mesh="geom_178"/>
                </body>
                <body name="sink_area_dish_washer_tray_bottom" pos="1.635 0.2 0.62" quat="0 -0.707107 0 0.707107">
                    <inertial pos="0.000600849 -0.000276009 0.0112505" mass="9.42" diaginertia="0.314663 0.230516 0.107649"/>
                    <joint name="sink_area_dish_washer_tray_main" pos="0 0 0" axis="0 0 1" type="slide" range="0 0.48"/>
                    <geom size="0.16 0.25 0.025" quat="0.707107 0 -0.707107 0" type="box"/>
                    <geom size="0.16 0.0025 0.085" pos="-0.075 -0.25 2.56714e-09" quat="0.707107 0 -0.707107 0" type="box"/>
                    <geom size="0.16 0.0025 0.085" pos="-0.075 0.25 2.56714e-09" quat="0.707107 0 -0.707107 0" type="box"/>
                    <geom size="0.0025 0.25 0.085" pos="-0.075 0 -0.16" quat="0.707107 0 -0.707107 0" type="box"/>
                    <geom size="0.0025 0.25 0.085" pos="-0.075 0 0.16" quat="0.707107 0 -0.707107 0" type="box"/>
                    <geom size="0.005 0.1 0.005" pos="-0.055 -0.1 0.22" quat="0.707107 0 -0.707107 0" type="box"/>
                    <geom size="0.015 0.005 0.005" pos="-0.055 -0.2 0.21" quat="0.707107 0 -0.707107 0" type="box"/>
                    <geom size="0.015 0.005 0.005" pos="-0.055 0 0.21" quat="0.707107 0 -0.707107 0" type="box"/>
                </body>
                <body name="oven_area_oven_door" pos="1.2813 1.93 0.9086" quat="0 0 -0.707107 0.707107">
                    <inertial pos="0.02938 -0.199015 0" mass="2" diaginertia="2.08094 2.08094 2"/>
                    <joint name="oven_area_oven_door_joint" pos="0 0 0" axis="0 0 1" range="0 1.5708"/>
                    <geom pos="-0.00398802 -0.204578 -0.000263059" quat="0.00322077 -0.999995 4.86132e-09 -1.50936e-06" type="mesh" mesh="geom_187"/>
                    <geom pos="0.058848 -0.39812 4.97357e-06" quat="0.707107 -7.47401e-07 -7.47401e-07 0.707107" type="mesh" mesh="geom_188"/>
                    <geom pos="0.03628 -0.39812 -0.244922" quat="0.501295 0.498701 0.498701 0.501295" type="mesh" mesh="geom_189"/>
                    <geom pos="0.03628 -0.39812 0.244922" quat="0.498701 0.501295 0.501295 0.498701" type="mesh" mesh="geom_190"/>
                </body>
                <body name="oven_area_oven_knob_stove_2" pos="1.285 2.07 1.4149" quat="0 -0.707107 0 -0.707107">
                    <inertial pos="0 0 0" mass="1" diaginertia="1 1 1"/>
                    <joint name="oven_area_oven_knob_stove_2_joint" pos="0 0 0" axis="0 0 1" range="0 3.14159"/>
                    <geom pos="-0.011613 0.00524818 -0.0187594" quat="0.552534 0.48855 0.458901 0.495414" type="mesh" mesh="geom_191"/>
                    <geom pos="-0.0191092 0.000440277 -0.012022" quat="0.0169368 0.99985 -0.00311017 0.00173849" type="mesh" mesh="geom_192"/>
                    <geom pos="0.0191441 -0.000424701 -0.0104723" quat="0.0238724 -0.999711 0.00261369 0.000490809" type="mesh" mesh="geom_193"/>
                    <geom pos="-0.0136398 -0.0134702 -0.00727484" quat="0.64769 0.658834 0.272885 0.26827" type="mesh" mesh="geom_194"/>
                    <geom pos="-0.000673491 -0.0191572 -0.0072805" quat="0.501617 0.501617 0.498378 0.498378" type="mesh" mesh="geom_195"/>
                    <geom pos="0.00914419 0.00487662 -0.015126" quat="0.706644 0.0497834 0.705352 0.0255674" type="mesh" mesh="geom_196"/>
                    <geom pos="0.0135247 -0.0135848 -0.00728855" quat="0.64929 0.65727 -0.27222 -0.268915" type="mesh" mesh="geom_197"/>
                    <geom pos="-0.000408391 0.00380818 -0.0188402" quat="0.536376 0.54201 0.459836 0.455056" type="mesh" mesh="geom_198"/>
                    <geom pos="0.00242412 -0.00542105 -0.0151142" quat="0.708553 -0.0452506 0.704014 -0.0164264" type="mesh" mesh="geom_199"/>
                    <geom pos="-0.0137379 -0.00511201 -0.0198944" quat="0.496372 0.474117 0.480468 0.545873" type="mesh" mesh="geom_200"/>
                    <geom pos="0.0123736 0.000355798 -0.0223279" quat="0.686362 -0.00202535 0.727254 0.00214602" type="mesh" mesh="geom_201"/>
                    <geom pos="-0.0134454 0.0136645 -0.0072742" quat="0.658929 0.647598 -0.268226 -0.272919" type="mesh" mesh="geom_202"/>
                    <geom pos="0.000612308 0.0191577 -0.0072805" quat="0.501609 0.501609 0.498385 0.498385" type="mesh" mesh="geom_203"/>
                    <geom pos="0.012276 -0.00257056 -0.018866" quat="0.497513 0.492733 0.487452 0.521618" type="mesh" mesh="geom_204"/>
                    <geom pos="-0.000720131 0.0118473 -0.0147701" quat="0.706825 -0.0199544 0.706825 0.0199544" type="mesh" mesh="geom_205"/>
                    <geom pos="-0.000696577 -0.00383435 -0.0190342" quat="0.472092 0.447085 0.522426 0.551648" type="mesh" mesh="geom_206"/>
                    <geom pos="0.0138854 0.0131877 -0.0072805" quat="0.65371 0.65371 0.269562 0.269562" type="mesh" mesh="geom_207"/>
                    <geom pos="0.0120758 0.00251114 -0.018896" quat="0.507981 0.510429 0.491798 0.48944" type="mesh" mesh="geom_208"/>
                    <geom pos="-0.0125623 0.000311681 -0.0228805" quat="0.707107 0 0.707107 0" type="mesh" mesh="geom_209"/>
                    <geom pos="-0.000436675 -8.22712e-05 -0.0223539" quat="0.733332 -0.00611057 0.679819 0.00566467" type="mesh" mesh="geom_210"/>
                    <geom pos="9.51069e-07 -0.0127874 -0.0147687" quat="0.707107 0.00058399 0.707107 -0.00058399" type="mesh" mesh="geom_211"/>
                </body>
                <body name="oven_area_oven_knob_stove_1" pos="1.285 2.14 1.4149" quat="0 -0.707107 0 -0.707107">
                    <inertial pos="0 0 0" mass="1" diaginertia="1 1 1"/>
                    <joint name="oven_area_oven_knob_stove_1_joint" pos="0 0 0" axis="0 0 1" range="0 3.14159"/>
                    <geom pos="-0.011613 0.00524818 -0.0187594" quat="0.552534 0.48855 0.458901 0.495414" type="mesh" mesh="geom_212"/>
                    <geom pos="-0.0191092 0.000440277 -0.012022" quat="0.0169368 0.99985 -0.00311017 0.00173849" type="mesh" mesh="geom_213"/>
                    <geom pos="0.0191441 -0.000424701 -0.0104723" quat="0.0238724 -0.999711 0.00261369 0.000490809" type="mesh" mesh="geom_214"/>
                    <geom pos="-0.0136398 -0.0134702 -0.00727484" quat="0.64769 0.658834 0.272885 0.26827" type="mesh" mesh="geom_215"/>
                    <geom pos="-0.000673491 -0.0191572 -0.0072805" quat="0.501617 0.501617 0.498378 0.498378" type="mesh" mesh="geom_216"/>
                    <geom pos="0.00914419 0.00487662 -0.015126" quat="0.706644 0.0497834 0.705352 0.0255674" type="mesh" mesh="geom_217"/>
                    <geom pos="0.0135247 -0.0135848 -0.00728855" quat="0.64929 0.65727 -0.27222 -0.268915" type="mesh" mesh="geom_218"/>
                    <geom pos="-0.000408391 0.00380818 -0.0188402" quat="0.536376 0.54201 0.459836 0.455056" type="mesh" mesh="geom_219"/>
                    <geom pos="0.00242412 -0.00542105 -0.0151142" quat="0.708553 -0.0452506 0.704014 -0.0164264" type="mesh" mesh="geom_220"/>
                    <geom pos="-0.0137379 -0.00511201 -0.0198944" quat="0.496372 0.474117 0.480468 0.545873" type="mesh" mesh="geom_221"/>
                    <geom pos="0.0123736 0.000355798 -0.0223279" quat="0.686362 -0.00202535 0.727254 0.00214602" type="mesh" mesh="geom_222"/>
                    <geom pos="-0.0134454 0.0136645 -0.0072742" quat="0.658929 0.647598 -0.268226 -0.272919" type="mesh" mesh="geom_223"/>
                    <geom pos="0.000612308 0.0191577 -0.0072805" quat="0.501609 0.501609 0.498385 0.498385" type="mesh" mesh="geom_224"/>
                    <geom pos="0.012276 -0.00257056 -0.018866" quat="0.497513 0.492733 0.487452 0.521618" type="mesh" mesh="geom_225"/>
                    <geom pos="-0.000720131 0.0118473 -0.0147701" quat="0.706825 -0.0199544 0.706825 0.0199544" type="mesh" mesh="geom_226"/>
                    <geom pos="-0.000696577 -0.00383435 -0.0190342" quat="0.472092 0.447085 0.522426 0.551648" type="mesh" mesh="geom_227"/>
                    <geom pos="0.0138854 0.0131877 -0.0072805" quat="0.65371 0.65371 0.269562 0.269562" type="mesh" mesh="geom_228"/>
                    <geom pos="0.0120758 0.00251114 -0.018896" quat="0.507981 0.510429 0.491798 0.48944" type="mesh" mesh="geom_229"/>
                    <geom pos="-0.0125623 0.000311681 -0.0228805" quat="0.707107 0 0.707107 0" type="mesh" mesh="geom_230"/>
                    <geom pos="-0.000436675 -8.22712e-05 -0.0223539" quat="0.733332 -0.00611057 0.679819 0.00566467" type="mesh" mesh="geom_231"/>
                    <geom pos="9.51069e-07 -0.0127874 -0.0147687" quat="0.707107 0.00058399 0.707107 -0.00058399" type="mesh" mesh="geom_232"/>
                </body>
                <body name="oven_area_oven_knob_stove_3" pos="1.285 2 1.4149" quat="0 -0.707107 0 -0.707107">
                    <inertial pos="0 0 0" mass="1" diaginertia="1 1 1"/>
                    <joint name="oven_area_oven_knob_stove_3_joint" pos="0 0 0" axis="0 0 1" range="0 3.14159"/>
                    <geom pos="-0.011613 0.00524818 -0.0187594" quat="0.552534 0.48855 0.458901 0.495414" type="mesh" mesh="geom_233"/>
                    <geom pos="-0.0191092 0.000440277 -0.012022" quat="0.0169368 0.99985 -0.00311017 0.00173849" type="mesh" mesh="geom_234"/>
                    <geom pos="0.0191441 -0.000424701 -0.0104723" quat="0.0238724 -0.999711 0.00261369 0.000490809" type="mesh" mesh="geom_235"/>
                    <geom pos="-0.0136398 -0.0134702 -0.00727484" quat="0.64769 0.658834 0.272885 0.26827" type="mesh" mesh="geom_236"/>
                    <geom pos="-0.000673491 -0.0191572 -0.0072805" quat="0.501617 0.501617 0.498378 0.498378" type="mesh" mesh="geom_237"/>
                    <geom pos="0.00914419 0.00487662 -0.015126" quat="0.706644 0.0497834 0.705352 0.0255674" type="mesh" mesh="geom_238"/>
                    <geom pos="0.0135247 -0.0135848 -0.00728855" quat="0.64929 0.65727 -0.27222 -0.268915" type="mesh" mesh="geom_239"/>
                    <geom pos="-0.000408391 0.00380818 -0.0188402" quat="0.536376 0.54201 0.459836 0.455056" type="mesh" mesh="geom_240"/>
                    <geom pos="0.00242412 -0.00542105 -0.0151142" quat="0.708553 -0.0452506 0.704014 -0.0164264" type="mesh" mesh="geom_241"/>
                    <geom pos="-0.0137379 -0.00511201 -0.0198944" quat="0.496372 0.474117 0.480468 0.545873" type="mesh" mesh="geom_242"/>
                    <geom pos="0.0123736 0.000355798 -0.0223279" quat="0.686362 -0.00202535 0.727254 0.00214602" type="mesh" mesh="geom_243"/>
                    <geom pos="-0.0134454 0.0136645 -0.0072742" quat="0.658929 0.647598 -0.268226 -0.272919" type="mesh" mesh="geom_244"/>
                    <geom pos="0.000612308 0.0191577 -0.0072805" quat="0.501609 0.501609 0.498385 0.498385" type="mesh" mesh="geom_245"/>
                    <geom pos="0.012276 -0.00257056 -0.018866" quat="0.497513 0.492733 0.487452 0.521618" type="mesh" mesh="geom_246"/>
                    <geom pos="-0.000720131 0.0118473 -0.0147701" quat="0.706825 -0.0199544 0.706825 0.0199544" type="mesh" mesh="geom_247"/>
                    <geom pos="-0.000696577 -0.00383435 -0.0190342" quat="0.472092 0.447085 0.522426 0.551648" type="mesh" mesh="geom_248"/>
                    <geom pos="0.0138854 0.0131877 -0.0072805" quat="0.65371 0.65371 0.269562 0.269562" type="mesh" mesh="geom_249"/>
                    <geom pos="0.0120758 0.00251114 -0.018896" quat="0.507981 0.510429 0.491798 0.48944" type="mesh" mesh="geom_250"/>
                    <geom pos="-0.0125623 0.000311681 -0.0228805" quat="0.707107 0 0.707107 0" type="mesh" mesh="geom_251"/>
                    <geom pos="-0.000436675 -8.22712e-05 -0.0223539" quat="0.733332 -0.00611057 0.679819 0.00566467" type="mesh" mesh="geom_252"/>
                    <geom pos="9.51069e-07 -0.0127874 -0.0147687" quat="0.707107 0.00058399 0.707107 -0.00058399" type="mesh" mesh="geom_253"/>
                </body>
                <body name="oven_area_oven_knob_stove_4" pos="1.285 1.93 1.4149" quat="0 -0.707107 0 -0.707107">
                    <inertial pos="0 0 0" mass="1" diaginertia="1 1 1"/>
                    <joint name="oven_area_oven_knob_stove_4_joint" pos="0 0 0" axis="0 0 1" range="0 3.14159"/>
                    <geom pos="-0.011613 0.00524818 -0.0187594" quat="0.552534 0.48855 0.458901 0.495414" type="mesh" mesh="geom_254"/>
                    <geom pos="-0.0191092 0.000440277 -0.012022" quat="0.0169368 0.99985 -0.00311017 0.00173849" type="mesh" mesh="geom_255"/>
                    <geom pos="0.0191441 -0.000424701 -0.0104723" quat="0.0238724 -0.999711 0.00261369 0.000490809" type="mesh" mesh="geom_256"/>
                    <geom pos="-0.0136398 -0.0134702 -0.00727484" quat="0.64769 0.658834 0.272885 0.26827" type="mesh" mesh="geom_257"/>
                    <geom pos="-0.000673491 -0.0191572 -0.0072805" quat="0.501617 0.501617 0.498378 0.498378" type="mesh" mesh="geom_258"/>
                    <geom pos="0.00914419 0.00487662 -0.015126" quat="0.706644 0.0497834 0.705352 0.0255674" type="mesh" mesh="geom_259"/>
                    <geom pos="0.0135247 -0.0135848 -0.00728855" quat="0.64929 0.65727 -0.27222 -0.268915" type="mesh" mesh="geom_260"/>
                    <geom pos="-0.000408391 0.00380818 -0.0188402" quat="0.536376 0.54201 0.459836 0.455056" type="mesh" mesh="geom_261"/>
                    <geom pos="0.00242412 -0.00542105 -0.0151142" quat="0.708553 -0.0452506 0.704014 -0.0164264" type="mesh" mesh="geom_262"/>
                    <geom pos="-0.0137379 -0.00511201 -0.0198944" quat="0.496372 0.474117 0.480468 0.545873" type="mesh" mesh="geom_263"/>
                    <geom pos="0.0123736 0.000355798 -0.0223279" quat="0.686362 -0.00202535 0.727254 0.00214602" type="mesh" mesh="geom_264"/>
                    <geom pos="-0.0134454 0.0136645 -0.0072742" quat="0.658929 0.647598 -0.268226 -0.272919" type="mesh" mesh="geom_265"/>
                    <geom pos="0.000612308 0.0191577 -0.0072805" quat="0.501609 0.501609 0.498385 0.498385" type="mesh" mesh="geom_266"/>
                    <geom pos="0.012276 -0.00257056 -0.018866" quat="0.497513 0.492733 0.487452 0.521618" type="mesh" mesh="geom_267"/>
                    <geom pos="-0.000720131 0.0118473 -0.0147701" quat="0.706825 -0.0199544 0.706825 0.0199544" type="mesh" mesh="geom_268"/>
                    <geom pos="-0.000696577 -0.00383435 -0.0190342" quat="0.472092 0.447085 0.522426 0.551648" type="mesh" mesh="geom_269"/>
                    <geom pos="0.0138854 0.0131877 -0.0072805" quat="0.65371 0.65371 0.269562 0.269562" type="mesh" mesh="geom_270"/>
                    <geom pos="0.0120758 0.00251114 -0.018896" quat="0.507981 0.510429 0.491798 0.48944" type="mesh" mesh="geom_271"/>
                    <geom pos="-0.0125623 0.000311681 -0.0228805" quat="0.707107 0 0.707107 0" type="mesh" mesh="geom_272"/>
                    <geom pos="-0.000436675 -8.22712e-05 -0.0223539" quat="0.733332 -0.00611057 0.679819 0.00566467" type="mesh" mesh="geom_273"/>
                    <geom pos="9.51069e-07 -0.0127874 -0.0147687" quat="0.707107 0.00058399 0.707107 -0.00058399" type="mesh" mesh="geom_274"/>
                </body>
                <body name="oven_area_oven_knob_oven" pos="1.285 1.77 1.4149" quat="0 -0.707107 0 -0.707107">
                    <inertial pos="0 0 0" mass="1" diaginertia="1 1 1"/>
                    <joint name="oven_area_oven_knob_oven_joint" pos="0 0 0" axis="0 0 1" range="0 3.14159"/>
                    <geom pos="-0.011613 0.00524818 -0.0187594" quat="0.552534 0.48855 0.458901 0.495414" type="mesh" mesh="geom_275"/>
                    <geom pos="-0.0191092 0.000440277 -0.012022" quat="0.0169368 0.99985 -0.00311017 0.00173849" type="mesh" mesh="geom_276"/>
                    <geom pos="0.0191441 -0.000424701 -0.0104723" quat="0.0238724 -0.999711 0.00261369 0.000490809" type="mesh" mesh="geom_277"/>
                    <geom pos="-0.0136398 -0.0134702 -0.00727484" quat="0.64769 0.658834 0.272885 0.26827" type="mesh" mesh="geom_278"/>
                    <geom pos="-0.000673491 -0.0191572 -0.0072805" quat="0.501617 0.501617 0.498378 0.498378" type="mesh" mesh="geom_279"/>
                    <geom pos="0.00914419 0.00487662 -0.015126" quat="0.706644 0.0497834 0.705352 0.0255674" type="mesh" mesh="geom_280"/>
                    <geom pos="0.0135247 -0.0135848 -0.00728855" quat="0.64929 0.65727 -0.27222 -0.268915" type="mesh" mesh="geom_281"/>
                    <geom pos="-0.000408391 0.00380818 -0.0188402" quat="0.536376 0.54201 0.459836 0.455056" type="mesh" mesh="geom_282"/>
                    <geom pos="0.00242412 -0.00542105 -0.0151142" quat="0.708553 -0.0452506 0.704014 -0.0164264" type="mesh" mesh="geom_283"/>
                    <geom pos="-0.0137379 -0.00511201 -0.0198944" quat="0.496372 0.474117 0.480468 0.545873" type="mesh" mesh="geom_284"/>
                    <geom pos="0.0123736 0.000355798 -0.0223279" quat="0.686362 -0.00202535 0.727254 0.00214602" type="mesh" mesh="geom_285"/>
                    <geom pos="-0.0134454 0.0136645 -0.0072742" quat="0.658929 0.647598 -0.268226 -0.272919" type="mesh" mesh="geom_286"/>
                    <geom pos="0.000612308 0.0191577 -0.0072805" quat="0.501609 0.501609 0.498385 0.498385" type="mesh" mesh="geom_287"/>
                    <geom pos="0.012276 -0.00257056 -0.018866" quat="0.497513 0.492733 0.487452 0.521618" type="mesh" mesh="geom_288"/>
                    <geom pos="-0.000720131 0.0118473 -0.0147701" quat="0.706825 -0.0199544 0.706825 0.0199544" type="mesh" mesh="geom_289"/>
                    <geom pos="-0.000696577 -0.00383435 -0.0190342" quat="0.472092 0.447085 0.522426 0.551648" type="mesh" mesh="geom_290"/>
                    <geom pos="0.0138854 0.0131877 -0.0072805" quat="0.65371 0.65371 0.269562 0.269562" type="mesh" mesh="geom_291"/>
                    <geom pos="0.0120758 0.00251114 -0.018896" quat="0.507981 0.510429 0.491798 0.48944" type="mesh" mesh="geom_292"/>
                    <geom pos="-0.0125623 0.000311681 -0.0228805" quat="0.707107 0 0.707107 0" type="mesh" mesh="geom_293"/>
                    <geom pos="-0.000436675 -8.22712e-05 -0.0223539" quat="0.733332 -0.00611057 0.679819 0.00566467" type="mesh" mesh="geom_294"/>
                    <geom pos="9.51069e-07 -0.0127874 -0.0147687" quat="0.707107 0.00058399 0.707107 -0.00058399" type="mesh" mesh="geom_295"/>
                </body>
                <body name="oven_area_area_middle_upper_drawer_main" pos="1.555 1.93 0.8" quat="0 -0.707107 0 0.707107">
                    <inertial pos="0.17625 0 0.00875" mass="2" diaginertia="2.06228 2.06228 2"/>
                    <joint name="oven_area_area_middle_upper_drawer_main_joint" pos="0 0 0" axis="0 0 1" type="slide" range="0 0.48"/>
                    <geom pos="-0.000285009 0 -0.268702" quat="0.5 0.5 -0.5 0.5" type="mesh" mesh="geom_296"/>
                    <geom pos="0.000620538 0.238963 -7.40008e-05" quat="0.712833 1.20028e-08 1.21996e-08 0.701334" type="mesh" mesh="geom_297"/>
                    <geom pos="0.000620538 -0.238963 -7.39975e-05" quat="0.701334 1.21996e-08 1.20028e-08 0.712833" type="mesh" mesh="geom_298"/>
                    <geom pos="0.0348625 0 -7.40004e-05" quat="0 1.71143e-08 0 1" type="mesh" mesh="geom_299"/>
                    <geom pos="-0.000285222 5.59981e-06 0.268826" quat="-0.499999 -0.5 0.500001 -0.5" type="mesh" mesh="geom_300"/>
                    <geom pos="-0.0174105 -4.97357e-06 0.352588" quat="-1.21016e-08 -1.21016e-08 0.707108 -0.707106" type="mesh" mesh="geom_301"/>
                    <geom pos="-0.0174105 0.244922 0.33002" quat="-4.43976e-11 -1.71142e-08 0.00259419 -0.999997" type="mesh" mesh="geom_302"/>
                    <geom pos="-0.0174105 -0.244922 0.33002" quat="-4.43976e-11 1.71142e-08 0.00259419 0.999997" type="mesh" mesh="geom_303"/>
                </body>
                <body name="oven_area_area_middle_lower_drawer_main" pos="1.555 1.93 0.44" quat="0 -0.707107 0 0.707107">
                    <inertial pos="0.185 0 0.125" mass="2" diaginertia="2.0997 2.0997 2"/>
                    <joint name="oven_area_area_middle_lower_drawer_main_joint" pos="0 0 0" axis="0 0 1" type="slide" range="0 0.48"/>
                    <geom pos="-0.00144724 -2.17245e-05 -0.268031" quat="0.707108 2.95432e-05 -0.707106 2.6219e-05" type="mesh" mesh="geom_304"/>
                    <geom pos="-0.0134195 0.239368 0.000402511" quat="0.653281 -0.270598 -0.270598 0.653281" type="mesh" mesh="geom_305"/>
                    <geom pos="0.254034 -0.149929 0.000402495" quat="0.00451208 1.71141e-08 7.7221e-11 0.99999" type="mesh" mesh="geom_306"/>
                    <geom pos="-0.0134195 -0.239368 0.000402511" quat="0.653281 -0.270598 -0.270598 0.653281" type="mesh" mesh="geom_307"/>
                    <geom pos="0.254063 0.108289 0.000408977" quat="0.00312425 -1.71142e-08 5.34693e-11 -0.999995" type="mesh" mesh="geom_308"/>
                    <geom pos="0.000166038 -3.40689e-06 0.269017" quat="0.499978 0.500001 -0.499998 0.500023" type="mesh" mesh="geom_309"/>
                    <geom pos="-0.24991 -4.97357e-06 0.370088" quat="-1.21016e-08 -1.21016e-08 0.707108 -0.707106" type="mesh" mesh="geom_310"/>
                    <geom pos="-0.24991 0.244922 0.34752" quat="-4.43976e-11 -1.71142e-08 0.00259419 -0.999997" type="mesh" mesh="geom_311"/>
                    <geom pos="-0.24991 -0.244922 0.34752" quat="-4.43976e-11 1.71142e-08 0.00259419 0.999997" type="mesh" mesh="geom_312"/>
                </body>
                <body name="oven_area_area_left_drawer_main" pos="1.265 2.38 0.825" quat="0 -0.707107 0 0.707107">
                    <inertial pos="-0.255684 0 -0.0718947" mass="19" diaginertia="21.5967 21.2668 19.5131"/>
                    <joint name="oven_area_area_left_drawer_main_joint" pos="0 0 0" axis="0 0 1" type="slide" range="0 0.48"/>
                    <geom size="0.0125 0.15 0.665" quat="0.707107 0 -0.707107 0" type="box"/>
                    <geom size="0.03 0.15 0.665" pos="-1.02686e-09 0 -0.03" quat="0.707107 0 -0.707107 0" type="box"/>
                    <geom size="0.245 0.125 0.018" pos="0.6 0 -0.25" quat="0.707107 0 -0.707107 0" type="box"/>
                    <geom size="0.245 0.018 0.05" pos="0.568 -0.107 -0.25" quat="0.707107 0 -0.707107 0" type="box"/>
                    <geom size="0.245 0.018 0.05" pos="0.568 0.107 -0.25" quat="0.707107 0 -0.707107 0" type="box"/>
                    <geom size="0.018 0.125 0.05" pos="0.568 0 -0.477" quat="0.707107 0 -0.707107 0" type="box"/>
                    <geom size="0.245 0.125 0.018" pos="0.28 0 -0.25" quat="0.707107 0 -0.707107 0" type="box"/>
                    <geom size="0.245 0.018 0.05" pos="0.248 -0.107 -0.25" quat="0.707107 0 -0.707107 0" type="box"/>
                    <geom size="0.245 0.018 0.05" pos="0.248 0.107 -0.25" quat="0.707107 0 -0.707107 0" type="box"/>
                    <geom size="0.018 0.125 0.05" pos="0.248 0 -0.477" quat="0.707107 0 -0.707107 0" type="box"/>
                    <geom size="0.245 0.125 0.018" pos="-0.05 0 -0.25" quat="0.707107 0 -0.707107 0" type="box"/>
                    <geom size="0.245 0.018 0.05" pos="-0.082 -0.107 -0.25" quat="0.707107 0 -0.707107 0" type="box"/>
                    <geom size="0.245 0.018 0.05" pos="-0.082 0.107 -0.25" quat="0.707107 0 -0.707107 0" type="box"/>
                    <geom size="0.018 0.125 0.05" pos="-0.082 0 -0.477" quat="0.707107 0 -0.707107 0" type="box"/>
                    <geom size="0.245 0.125 0.018" pos="-0.38 0 -0.25" quat="0.707107 0 -0.707107 0" type="box"/>
                    <geom size="0.245 0.018 0.05" pos="-0.412 -0.107 -0.25" quat="0.707107 0 -0.707107 0" type="box"/>
                    <geom size="0.245 0.018 0.05" pos="-0.412 0.107 -0.25" quat="0.707107 0 -0.707107 0" type="box"/>
                    <geom size="0.018 0.125 0.05" pos="-0.412 0 -0.477" quat="0.707107 0 -0.707107 0" type="box"/>
                    <geom pos="-0.05 8.37501e-05 0.0820562" quat="0.704812 0.0569257 -0.704812 -0.0569257" type="mesh" mesh="geom_331"/>
                    <geom pos="0.559688 8.32443e-05 0.0595606" quat="0.707252 -0.00251147 -0.0025227 0.706953" type="mesh" mesh="geom_332"/>
                    <geom pos="-0.05 0 0.0641696" quat="0.5 -0.5 -0.5 0.5" type="mesh" mesh="geom_333"/>
                </body>
                <body name="oven_area_area_right_drawer_main" pos="1.265 1.48 0.825" quat="0 -0.707107 0 0.707107">
                    <inertial pos="-0.255684 0 -0.0718947" mass="19" diaginertia="21.5967 21.2668 19.5131"/>
                    <joint name="oven_area_area_right_drawer_main_joint" pos="0 0 0" axis="0 0 1" type="slide" range="0 0.48"/>
                    <geom size="0.0125 0.15 0.665" quat="0.707107 0 -0.707107 0" type="box"/>
                    <geom size="0.03 0.15 0.665" pos="-1.02686e-09 0 -0.03" quat="0.707107 0 -0.707107 0" type="box"/>
                    <geom size="0.245 0.125 0.018" pos="0.6 0 -0.25" quat="0.707107 0 -0.707107 0" type="box"/>
                    <geom size="0.245 0.018 0.05" pos="0.568 -0.107 -0.25" quat="0.707107 0 -0.707107 0" type="box"/>
                    <geom size="0.245 0.018 0.05" pos="0.568 0.107 -0.25" quat="0.707107 0 -0.707107 0" type="box"/>
                    <geom size="0.018 0.125 0.05" pos="0.568 0 -0.477" quat="0.707107 0 -0.707107 0" type="box"/>
                    <geom size="0.245 0.125 0.018" pos="0.28 0 -0.25" quat="0.707107 0 -0.707107 0" type="box"/>
                    <geom size="0.245 0.018 0.05" pos="0.248 -0.107 -0.25" quat="0.707107 0 -0.707107 0" type="box"/>
                    <geom size="0.245 0.018 0.05" pos="0.248 0.107 -0.25" quat="0.707107 0 -0.707107 0" type="box"/>
                    <geom size="0.018 0.125 0.05" pos="0.248 0 -0.477" quat="0.707107 0 -0.707107 0" type="box"/>
                    <geom size="0.245 0.125 0.018" pos="-0.05 0 -0.25" quat="0.707107 0 -0.707107 0" type="box"/>
                    <geom size="0.245 0.018 0.05" pos="-0.082 -0.107 -0.25" quat="0.707107 0 -0.707107 0" type="box"/>
                    <geom size="0.245 0.018 0.05" pos="-0.082 0.107 -0.25" quat="0.707107 0 -0.707107 0" type="box"/>
                    <geom size="0.018 0.125 0.05" pos="-0.082 0 -0.477" quat="0.707107 0 -0.707107 0" type="box"/>
                    <geom size="0.245 0.125 0.018" pos="-0.38 0 -0.25" quat="0.707107 0 -0.707107 0" type="box"/>
                    <geom size="0.245 0.018 0.05" pos="-0.412 -0.107 -0.25" quat="0.707107 0 -0.707107 0" type="box"/>
                    <geom size="0.245 0.018 0.05" pos="-0.412 0.107 -0.25" quat="0.707107 0 -0.707107 0" type="box"/>
                    <geom size="0.018 0.125 0.05" pos="-0.412 0 -0.477" quat="0.707107 0 -0.707107 0" type="box"/>
                    <geom pos="-0.05 8.37501e-05 0.0820562" quat="0.704812 0.0569257 -0.704812 -0.0569257" type="mesh" mesh="geom_352"/>
                    <geom pos="0.559688 8.32443e-05 0.0595606" quat="0.707252 -0.00251147 -0.0025227 0.706953" type="mesh" mesh="geom_353"/>
                    <geom pos="-0.05 0 0.0641696" quat="0.5 -0.5 -0.5 0.5" type="mesh" mesh="geom_354"/>
                </body>
                <body name="kitchen_island_left_upper_drawer_main" pos="-1.063 0.9492 0.535" quat="0.707107 0 0.707107 0">
                    <inertial pos="0.17625 0 0.055" mass="2" diaginertia="2.06818 2.06818 2"/>
                    <joint name="kitchen_island_left_upper_drawer_main_joint" pos="0 0 0" axis="0 0 1" type="slide" range="0 0.48"/>
                    <geom pos="0.114365 -0.128613 -0.0145505" quat="0.00135569 0.000581636 -0.00350631 0.999993" type="mesh" mesh="geom_355"/>
                    <geom pos="0.00196185 0.238198 -0.014549" quat="0.708039 0.00215748 0.00298418 0.706163" type="mesh" mesh="geom_356"/>
                    <geom pos="-0.0119165 -0.130098 -0.269292" quat="0.501557 0.498438 -0.498438 0.501557" type="mesh" mesh="geom_357"/>
                    <geom pos="-0.0119165 -0.239417 0.000499994" quat="0.707107 1.21016e-08 1.21016e-08 0.707107" type="mesh" mesh="geom_358"/>
                    <geom pos="0.00347432 0.110511 -0.269295" quat="-0.704953 0 0.709254 0" type="mesh" mesh="geom_359"/>
                    <geom pos="0.115583 0.110511 0.00049999" quat="0 1.71143e-08 0 1" type="mesh" mesh="geom_360"/>
                    <geom pos="-0.000516453 1.91383e-05 0.269849" quat="0.500029 0.500029 -0.499971 0.499971" type="mesh" mesh="geom_361"/>
                    <geom pos="-0.10991 -4.97357e-06 0.352588" quat="-1.21016e-08 -1.21016e-08 0.707108 -0.707106" type="mesh" mesh="geom_362"/>
                    <geom pos="-0.10991 0.244922 0.33002" quat="-4.43976e-11 -1.71142e-08 0.00259419 -0.999997" type="mesh" mesh="geom_363"/>
                    <geom pos="-0.10991 -0.244922 0.33002" quat="-4.43976e-11 1.71142e-08 0.00259419 0.999997" type="mesh" mesh="geom_364"/>
                </body>
                <body name="kitchen_island_left_lower_drawer_main" pos="-1.063 0.9492 0.245" quat="0.707107 0 0.707107 0">
                    <inertial pos="0.17625 0 0.055" mass="2" diaginertia="2.06818 2.06818 2"/>
                    <joint name="kitchen_island_left_lower_drawer_main_joint" pos="0 0 0" axis="0 0 1" type="slide" range="0 0.48"/>
                    <geom pos="0.114365 -0.128613 -0.0145505" quat="0.00135569 0.000581636 -0.00350631 0.999993" type="mesh" mesh="geom_365"/>
                    <geom pos="0.00196185 0.238198 -0.014549" quat="0.708039 0.00215748 0.00298418 0.706163" type="mesh" mesh="geom_366"/>
                    <geom pos="-0.0119165 -0.130098 -0.269292" quat="0.501557 0.498438 -0.498438 0.501557" type="mesh" mesh="geom_367"/>
                    <geom pos="-0.0119165 -0.239417 0.000499994" quat="0.707107 1.21016e-08 1.21016e-08 0.707107" type="mesh" mesh="geom_368"/>
                    <geom pos="0.00347432 0.110511 -0.269295" quat="-0.704953 0 0.709254 0" type="mesh" mesh="geom_369"/>
                    <geom pos="0.115583 0.110511 0.00049999" quat="0 1.71143e-08 0 1" type="mesh" mesh="geom_370"/>
                    <geom pos="-0.000516453 1.91383e-05 0.269849" quat="0.500029 0.500029 -0.499971 0.499971" type="mesh" mesh="geom_371"/>
                    <geom pos="-0.10991 -4.97357e-06 0.352588" quat="-1.21016e-08 -1.21016e-08 0.707108 -0.707106" type="mesh" mesh="geom_372"/>
                    <geom pos="-0.10991 0.244922 0.33002" quat="-4.43976e-11 -1.71142e-08 0.00259419 -0.999997" type="mesh" mesh="geom_373"/>
                    <geom pos="-0.10991 -0.244922 0.33002" quat="-4.43976e-11 1.71142e-08 0.00259419 0.999997" type="mesh" mesh="geom_374"/>
                </body>
                <body name="kitchen_island_middle_upper_drawer_main" pos="-1.063 1.7492 0.535" quat="0.707107 0 0.707107 0">
                    <inertial pos="0.17625 0 0.055" mass="2" diaginertia="2.06818 2.06818 2"/>
                    <joint name="kitchen_island_middle_upper_drawer_main_joint" pos="0 0 0" axis="0 0 1" type="slide" range="0 0.48"/>
                    <geom pos="0.000600992 0 -0.268033" quat="0.5 0.5 -0.5 0.5" type="mesh" mesh="geom_375"/>
                    <geom pos="0.00361464 0.438416 0.000377998" quat="0.709703 1.2057e-08 1.21461e-08 0.704501" type="mesh" mesh="geom_376"/>
                    <geom pos="0.00361464 -0.438416 0.000377998" quat="0.704501 1.21461e-08 1.2057e-08 0.709703" type="mesh" mesh="geom_377"/>
                    <geom pos="0.115146 0 0.000373494" quat="1.21016e-08 1.21016e-08 -0.707107 0.707107" type="mesh" mesh="geom_378"/>
                    <geom pos="0.000600893 1.91914e-05 0.268953" quat="0.5 0.5 -0.5 0.5" type="mesh" mesh="geom_379"/>
                    <geom pos="-0.110099 7.55006e-07 0.352583" quat="0.5 0.5 -0.5 0.5" type="mesh" mesh="geom_380"/>
                    <geom pos="-0.110099 0.4472 0.330007" quat="5.33382e-11 1.71142e-08 -0.00311659 0.999995" type="mesh" mesh="geom_381"/>
                    <geom pos="-0.110099 -0.447221 0.330007" quat="-5.33357e-11 1.71142e-08 0.00311645 0.999995" type="mesh" mesh="geom_382"/>
                </body>
                <body name="kitchen_island_middle_lower_drawer_main" pos="-1.063 1.7492 0.245" quat="0.707107 0 0.707107 0">
                    <inertial pos="0.17625 0 0.055" mass="2" diaginertia="2.06818 2.06818 2"/>
                    <joint name="kitchen_island_middle_lower_drawer_main_joint" pos="0 0 0" axis="0 0 1" type="slide" range="0 0.48"/>
                    <geom pos="0.000600992 0 -0.268033" quat="0.5 0.5 -0.5 0.5" type="mesh" mesh="geom_383"/>
                    <geom pos="0.00361464 0.438416 0.000377998" quat="0.709703 1.2057e-08 1.21461e-08 0.704501" type="mesh" mesh="geom_384"/>
                    <geom pos="0.00361464 -0.438416 0.000377998" quat="0.704501 1.21461e-08 1.2057e-08 0.709703" type="mesh" mesh="geom_385"/>
                    <geom pos="0.115146 0 0.000373494" quat="1.21016e-08 1.21016e-08 -0.707107 0.707107" type="mesh" mesh="geom_386"/>
                    <geom pos="0.000600893 1.91914e-05 0.268953" quat="0.5 0.5 -0.5 0.5" type="mesh" mesh="geom_387"/>
                    <geom pos="-0.110099 7.55006e-07 0.352583" quat="0.5 0.5 -0.5 0.5" type="mesh" mesh="geom_388"/>
                    <geom pos="-0.110099 0.4472 0.330007" quat="5.33382e-11 1.71142e-08 -0.00311659 0.999995" type="mesh" mesh="geom_389"/>
                    <geom pos="-0.110099 -0.447221 0.330007" quat="-5.33357e-11 1.71142e-08 0.00311645 0.999995" type="mesh" mesh="geom_390"/>
                </body>
                <body name="kitchen_island_right_upper_drawer_main" pos="-1.063 2.5492 0.535" quat="0.707107 0 0.707107 0">
                    <inertial pos="0.17625 0 0.055" mass="2" diaginertia="2.06818 2.06818 2"/>
                    <joint name="kitchen_island_right_upper_drawer_main_joint" pos="0 0 0" axis="0 0 1" type="slide" range="0 0.48"/>
                    <geom pos="0.114365 -0.128613 -0.0145505" quat="0.00135569 0.000581636 -0.00350631 0.999993" type="mesh" mesh="geom_391"/>
                    <geom pos="0.00196185 0.238198 -0.014549" quat="0.708039 0.00215748 0.00298418 0.706163" type="mesh" mesh="geom_392"/>
                    <geom pos="-0.0119165 -0.130098 -0.269292" quat="0.501557 0.498438 -0.498438 0.501557" type="mesh" mesh="geom_393"/>
                    <geom pos="-0.0119165 -0.239417 0.000499994" quat="0.707107 1.21016e-08 1.21016e-08 0.707107" type="mesh" mesh="geom_394"/>
                    <geom pos="0.00347432 0.110511 -0.269295" quat="-0.704953 0 0.709254 0" type="mesh" mesh="geom_395"/>
                    <geom pos="0.115583 0.110511 0.00049999" quat="0 1.71143e-08 0 1" type="mesh" mesh="geom_396"/>
                    <geom pos="-0.000516453 1.91383e-05 0.269849" quat="0.500029 0.500029 -0.499971 0.499971" type="mesh" mesh="geom_397"/>
                    <geom pos="-0.10991 -4.97357e-06 0.352588" quat="-1.21016e-08 -1.21016e-08 0.707108 -0.707106" type="mesh" mesh="geom_398"/>
                    <geom pos="-0.10991 0.244922 0.33002" quat="-4.43976e-11 -1.71142e-08 0.00259419 -0.999997" type="mesh" mesh="geom_399"/>
                    <geom pos="-0.10991 -0.244922 0.33002" quat="-4.43976e-11 1.71142e-08 0.00259419 0.999997" type="mesh" mesh="geom_400"/>
                </body>
                <body name="kitchen_island_right_lower_drawer_main" pos="-1.063 2.5492 0.245" quat="0.707107 0 0.707107 0">
                    <inertial pos="0.17625 0 0.055" mass="2" diaginertia="2.06818 2.06818 2"/>
                    <joint name="kitchen_island_right_lower_drawer_main_joint" pos="0 0 0" axis="0 0 1" type="slide" range="0 0.48"/>
                    <geom pos="0.114365 -0.128613 -0.0145505" quat="0.00135569 0.000581636 -0.00350631 0.999993" type="mesh" mesh="geom_401"/>
                    <geom pos="0.00196185 0.238198 -0.014549" quat="0.708039 0.00215748 0.00298418 0.706163" type="mesh" mesh="geom_402"/>
                    <geom pos="-0.0119165 -0.130098 -0.269292" quat="0.501557 0.498438 -0.498438 0.501557" type="mesh" mesh="geom_403"/>
                    <geom pos="-0.0119165 -0.239417 0.000499994" quat="0.707107 1.21016e-08 1.21016e-08 0.707107" type="mesh" mesh="geom_404"/>
                    <geom pos="0.00347432 0.110511 -0.269295" quat="-0.704953 0 0.709254 0" type="mesh" mesh="geom_405"/>
                    <geom pos="0.115583 0.110511 0.00049999" quat="0 1.71143e-08 0 1" type="mesh" mesh="geom_406"/>
                    <geom pos="-0.000516453 1.91383e-05 0.269849" quat="0.500029 0.500029 -0.499971 0.499971" type="mesh" mesh="geom_407"/>
                    <geom pos="-0.10991 -4.97357e-06 0.352588" quat="-1.21016e-08 -1.21016e-08 0.707108 -0.707106" type="mesh" mesh="geom_408"/>
                    <geom pos="-0.10991 0.244922 0.33002" quat="-4.43976e-11 -1.71142e-08 0.00259419 -0.999997" type="mesh" mesh="geom_409"/>
                    <geom pos="-0.10991 -0.244922 0.33002" quat="-4.43976e-11 1.71142e-08 0.00259419 0.999997" type="mesh" mesh="geom_410"/>
                </body>
                <body name="fridge_area_lower_drawer_main" pos="1.555 -1 0.3225" quat="0 -0.707107 0 0.707107">
                    <inertial pos="0.17625 0 0.055" mass="2" diaginertia="2.06818 2.06818 2"/>
                    <joint name="fridge_area_lower_drawer_main_joint" pos="0 0 0" axis="0 0 1" type="slide" range="0 0.48"/>
                    <geom pos="0.114365 -0.128613 -0.0145505" quat="0.00135569 0.000581636 -0.00350631 0.999993" type="mesh" mesh="geom_411"/>
                    <geom pos="0.00196185 0.238198 -0.014549" quat="0.708039 0.00215748 0.00298418 0.706163" type="mesh" mesh="geom_412"/>
                    <geom pos="-0.0119165 -0.130098 -0.269292" quat="0.501557 0.498438 -0.498438 0.501557" type="mesh" mesh="geom_413"/>
                    <geom pos="-0.0119165 -0.239417 0.000499994" quat="0.707107 1.21016e-08 1.21016e-08 0.707107" type="mesh" mesh="geom_414"/>
                    <geom pos="0.00347432 0.110511 -0.269295" quat="-0.704953 0 0.709254 0" type="mesh" mesh="geom_415"/>
                    <geom pos="0.115583 0.110511 0.00049999" quat="0 1.71143e-08 0 1" type="mesh" mesh="geom_416"/>
                    <geom pos="-0.000516453 1.91383e-05 0.269849" quat="0.500029 0.500029 -0.499971 0.499971" type="mesh" mesh="geom_417"/>
                    <geom pos="-0.10991 -4.97357e-06 0.352588" quat="-1.21016e-08 -1.21016e-08 0.707108 -0.707106" type="mesh" mesh="geom_418"/>
                    <geom pos="-0.10991 0.244922 0.33002" quat="-4.43976e-11 -1.71142e-08 0.00259419 -0.999997" type="mesh" mesh="geom_419"/>
                    <geom pos="-0.10991 -0.244922 0.33002" quat="-4.43976e-11 1.71142e-08 0.00259419 0.999997" type="mesh" mesh="geom_420"/>
                </body>
                <body name="iai_fridge_door" pos="1.265 -1.3 0.99" quat="0 0 0 1">
                    <inertial pos="-0.0376957 -0.271113 -0.0142711" mass="26.9596" diaginertia="4.3785 3.62753 2.84647"/>
                    <joint name="iai_fridge_door_joint" pos="0 0 0" axis="0 0 1" range="0 1.5708"/>
                    <geom size="0.02 0.2615 0.44" pos="-0.025 -0.27 -0.01" type="box"/>
                    <geom size="0.03 0.0075 0.365" pos="-0.0675 -0.4925 0" type="box"/>
                    <geom size="0.03 0.0075 0.365" pos="-0.0675 -0.0475 0" type="box"/>
                    <geom size="0.0225 0.23 0.005" pos="-0.055 -0.27 0.36" type="box"/>
                    <geom size="0.05 0.175 0.005" pos="-0.095 -0.27 -0.3625" type="box"/>
                    <geom size="0.0575 0.03 0.05" pos="-0.0975 -0.47 -0.3175" type="box"/>
                    <geom size="0.0575 0.03 0.05" pos="-0.0975 -0.07 -0.3175" type="box"/>
                    <geom size="0.005 0.175 0.05" pos="-0.145 -0.27 -0.3175" type="box"/>
                    <geom size="0.05 0.175 0.005" pos="-0.095 -0.27 0.01" type="box"/>
                    <geom size="0.0575 0.03 0.0325" pos="-0.0975 -0.47 0.0375" type="box"/>
                    <geom size="0.0575 0.03 0.0325" pos="-0.0975 -0.07 0.0375" type="box"/>
                    <geom size="0.005 0.175 0.0325" pos="-0.145 -0.27 0.0375" type="box"/>
                    <geom size="0.05 0.175 0.005" pos="-0.095 -0.27 0.22" type="box"/>
                    <geom size="0.0575 0.03 0.0325" pos="-0.0975 -0.47 0.2475" type="box"/>
                    <geom size="0.0575 0.03 0.0325" pos="-0.0975 -0.07 0.2475" type="box"/>
                    <geom size="0.005 0.175 0.0325" pos="-0.145 -0.27 0.2475" type="box"/>
                    <geom pos="-0.00539301 -0.300418 -2.65755e-06" quat="1 8.18654e-06 0 0" type="mesh" mesh="geom_437"/>
                    <geom pos="0.0699846 -0.569952 -4.35584e-06" quat="0.707107 0 0 0.707107" type="mesh" mesh="geom_438"/>
                    <geom pos="0.047541 -0.569952 -0.429851" quat="0.501515 0.49848 0.49848 0.501515" type="mesh" mesh="geom_439"/>
                    <geom pos="0.047541 -0.569952 0.429851" quat="0.49848 0.501515 0.501515 0.49848" type="mesh" mesh="geom_440"/>
                </body>
            </body>
        </body>
    </worldbody>
    <equality/>
    <contact>
        <exclude body1="kitchen" body2="kitchen"/>
        <exclude body1="kitchen" body2="sink_area_trash_drawer_main"/>
        <exclude body1="kitchen" body2="sink_area_left_upper_drawer_main"/>
        <exclude body1="kitchen" body2="sink_area_left_middle_drawer_main"/>
        <exclude body1="kitchen" body2="sink_area_left_bottom_drawer_main"/>
        <exclude body1="kitchen" body2="sink_area_dish_washer_door"/>
        <exclude body1="kitchen" body2="sink_area_dish_washer_tray_bottom"/>
        <exclude body1="kitchen" body2="oven_area_oven_door"/>
        <exclude body1="kitchen" body2="oven_area_oven_knob_stove_2"/>
        <exclude body1="kitchen" body2="oven_area_oven_knob_stove_1"/>
        <exclude body1="kitchen" body2="oven_area_oven_knob_stove_3"/>
        <exclude body1="kitchen" body2="oven_area_oven_knob_stove_4"/>
        <exclude body1="kitchen" body2="oven_area_oven_knob_oven"/>
        <exclude body1="kitchen" body2="oven_area_area_middle_upper_drawer_main"/>
        <exclude body1="kitchen" body2="oven_area_area_middle_lower_drawer_main"/>
        <exclude body1="kitchen" body2="oven_area_area_left_drawer_main"/>
        <exclude body1="kitchen" body2="oven_area_area_right_drawer_main"/>
        <exclude body1="kitchen" body2="kitchen_island_left_upper_drawer_main"/>
        <exclude body1="kitchen" body2="kitchen_island_left_lower_drawer_main"/>
        <exclude body1="kitchen" body2="kitchen_island_middle_upper_drawer_main"/>
        <exclude body1="kitchen" body2="kitchen_island_middle_lower_drawer_main"/>
        <exclude body1="kitchen" body2="kitchen_island_right_upper_drawer_main"/>
        <exclude body1="kitchen" body2="kitchen_island_right_lower_drawer_main"/>
        <exclude body1="kitchen" body2="fridge_area_lower_drawer_main"/>
        <exclude body1="kitchen" body2="iai_fridge_door"/>
    </contact>
</mujoco>
