<?xml version="1.0" ?>
<robot name="pr2" version="1.0">
  <link name="pr2"/>
  <joint name="base_footprint_joint" type="fixed">
    <origin xyz="0.0 0.0 0.0" rpy="0.0 0.0 0.0"/>
    <parent link="pr2"/>
    <child link="base_footprint"/>
  </joint>
  <link name="base_footprint">
    <inertial>
      <origin xyz="0.0 0.0 0.0" rpy="0.0 0.0 0.0"/>
      <mass value="0.0"/>
      <inertia ixx="0.0" ixy="0.0" ixz="0.0" iyy="0.0" iyz="0.0" izz="0.0"/>
    </inertial>
    <visual name="SM_base_footprint_visual_0">
      <origin xyz="0.0 0.0 0.0" rpy="0.0 0.0 0.0"/>
      <geometry>
        <box size="0.009999999776482582 0.009999999776482582 0.009999999776482582"/>
      </geometry>
    </visual>
    <collision name="SM_base_footprint_collision_0">
      <origin xyz="0.0 0.0 0.07100000232458115" rpy="0.0 0.0 0.0"/>
      <geometry>
        <box size="0.0010000000474974513 0.0010000000474974513 0.0010000000474974513"/>
      </geometry>
    </collision>
  </link>
  <joint name="base_link_joint" type="fixed">
    <origin xyz="0.0 0.0 0.051" rpy="0.0 0.0 0.0"/>
    <parent link="base_footprint"/>
    <child link="base_link"/>
  </joint>
  <link name="base_link">
    <inertial>
      <origin xyz="-0.061000000685453415 0.0 0.14650000631809235" rpy="0.01743166893720627 1.1106020212173462 -0.0019665705040097237"/>
      <mass value="116.0"/>
      <inertia ixx="3.0417723655700684" ixy="0.0" ixz="0.0" iyy="5.66924524307251" iyz="0.0" izz="6.293884754180908"/>
    </inertial>
    <visual name="SM_base_link_visual_0">
      <origin xyz="0.0 0.0 0.0" rpy="0.0 0.0 0.0"/>
      <geometry>
        <mesh filename="file://pr2/meshes/obj/base.obj"/>
      </geometry>
    </visual>
    <collision name="SM_base_link_collision_0">
      <origin xyz="0.0 0.0 0.0" rpy="0.0 0.0 0.0"/>
      <geometry>
        <mesh filename="file://pr2/meshes/stl/base_L.stl"/>
      </geometry>
    </collision>
  </link>
  <joint name="base_bellow_link_joint" type="fixed">
    <origin xyz="-0.29 0.0 0.8" rpy="0.0 0.0 0.0"/>
    <parent link="base_link"/>
    <child link="base_bellow_link"/>
  </joint>
  <link name="base_bellow_link">
    <inertial>
      <origin xyz="0.0 0.0 0.0" rpy="0.0 0.0 0.0"/>
      <mass value="1.0"/>
      <inertia ixx="0.009999999776482582" ixy="0.0" ixz="0.0" iyy="0.009999999776482582" iyz="0.0" izz="0.009999999776482582"/>
    </inertial>
    <visual name="SM_base_bellow_link_visual_0">
      <origin xyz="0.0 0.0 0.0" rpy="0.0 0.0 0.0"/>
      <geometry>
        <box size="0.05000000074505806 0.3700000047683716 0.30000001192092896"/>
      </geometry>
    </visual>
    <collision name="SM_base_bellow_link_collision_0">
      <origin xyz="0.0 0.0 0.0" rpy="0.0 0.0 0.0"/>
      <geometry>
        <box size="0.05000000074505806 0.3700000047683716 0.30000001192092896"/>
      </geometry>
    </collision>
  </link>
  <joint name="base_laser_link_joint" type="fixed">
    <origin xyz="0.275 0.0 0.252" rpy="0.0 0.0 0.0"/>
    <parent link="base_link"/>
    <child link="base_laser_link"/>
  </joint>
  <link name="base_laser_link">
    <inertial>
      <origin xyz="0.0 0.0 0.0" rpy="0.0 0.0 -1.5707963705062866"/>
      <mass value="0.0010000000474974513"/>
      <inertia ixx="9.999999974752427e-07" ixy="0.0" ixz="0.0" iyy="9.999999747378752e-05" iyz="0.0" izz="9.999999747378752e-05"/>
    </inertial>
  </link>
  <joint name="fl_caster_rotation_joint" type="continuous">
    <origin xyz="0.22460000216960907 0.22460000216960907 0.028200000524520874" rpy="0.0 0.0 0.0"/>
    <axis xyz="0.0 0.0 1.0"/>
    <parent link="base_link"/>
    <child link="fl_caster_rotation_link"/>
  </joint>
  <link name="fl_caster_rotation_link">
    <inertial>
      <origin xyz="0.0 0.0 0.07000000029802322" rpy="1.6352778673171997 -1.0139516592025757 -2.9563724994659424"/>
      <mass value="3.4730820655822754"/>
      <inertia ixx="0.011456840671598911" ixy="0.0" ixz="0.0" iyy="0.012544593773782253" iyz="0.0" izz="0.015392469242215157"/>
    </inertial>
    <visual name="SM_fl_caster_rotation_link_visual_0">
      <origin xyz="0.0 0.0 0.0" rpy="0.0 0.0 0.0"/>
      <geometry>
        <mesh filename="file://pr2/meshes/stl/caster.stl"/>
      </geometry>
    </visual>
    <collision name="SM_fl_caster_rotation_link_collision_0">
      <origin xyz="0.0 0.0 0.0" rpy="0.0 0.0 0.0"/>
      <geometry>
        <mesh filename="file://pr2/meshes/stl/caster_L.stl"/>
      </geometry>
    </collision>
  </link>
  <joint name="fl_caster_l_wheel_joint" type="continuous">
    <origin xyz="0.0 0.04899999871850014 0.0" rpy="0.0 0.0 0.0"/>
    <axis xyz="0.0 1.0 0.0"/>
    <parent link="fl_caster_rotation_link"/>
    <child link="fl_caster_l_wheel_link"/>
  </joint>
  <link name="fl_caster_l_wheel_link">
    <inertial>
      <origin xyz="0.0 0.0 0.0" rpy="1.6352778673171997 -1.0139516592025757 -2.9563724994659424"/>
      <mass value="0.44036000967025757"/>
      <inertia ixx="0.011456840671598911" ixy="0.0" ixz="0.0" iyy="0.012544593773782253" iyz="0.0" izz="0.015392469242215157"/>
    </inertial>
    <visual name="SM_fl_caster_l_wheel_link_visual_0">
      <origin xyz="0.0 0.0 0.0" rpy="0.0 0.0 0.0"/>
      <geometry>
        <mesh filename="file://pr2/meshes/obj/wheel.obj"/>
      </geometry>
    </visual>
    <collision name="SM_fl_caster_l_wheel_link_collision_0">
      <origin xyz="0.0 0.0 0.0" rpy="1.5707963705062866 0.0 0.0"/>
      <geometry>
        <cylinder radius="0.07479199767112732" length="0.03400000184774399"/>
      </geometry>
    </collision>
  </link>
  <joint name="fl_caster_r_wheel_joint" type="continuous">
    <origin xyz="0.0 -0.04899999871850014 0.0" rpy="0.0 0.0 0.0"/>
    <axis xyz="0.0 1.0 0.0"/>
    <parent link="fl_caster_rotation_link"/>
    <child link="fl_caster_r_wheel_link"/>
  </joint>
  <link name="fl_caster_r_wheel_link">
    <inertial>
      <origin xyz="0.0 0.0 0.0" rpy="1.6352778673171997 -1.0139516592025757 -2.9563724994659424"/>
      <mass value="0.44036000967025757"/>
      <inertia ixx="0.011456840671598911" ixy="0.0" ixz="0.0" iyy="0.012544593773782253" iyz="0.0" izz="0.015392469242215157"/>
    </inertial>
    <visual name="SM_fl_caster_r_wheel_link_visual_0">
      <origin xyz="0.0 0.0 0.0" rpy="0.0 0.0 0.0"/>
      <geometry>
        <mesh filename="file://pr2/meshes/obj/wheel.obj"/>
      </geometry>
    </visual>
    <collision name="SM_fl_caster_r_wheel_link_collision_0">
      <origin xyz="0.0 0.0 0.0" rpy="1.5707963705062866 0.0 0.0"/>
      <geometry>
        <cylinder radius="0.07479199767112732" length="0.03400000184774399"/>
      </geometry>
    </collision>
  </link>
  <joint name="fr_caster_rotation_joint" type="continuous">
    <origin xyz="0.22460000216960907 -0.22460000216960907 0.028200000524520874" rpy="0.0 0.0 0.0"/>
    <axis xyz="0.0 0.0 1.0"/>
    <parent link="base_link"/>
    <child link="fr_caster_rotation_link"/>
  </joint>
  <link name="fr_caster_rotation_link">
    <inertial>
      <origin xyz="0.0 0.0 0.07000000029802322" rpy="1.6352778673171997 -1.0139516592025757 -2.9563724994659424"/>
      <mass value="3.4730820655822754"/>
      <inertia ixx="0.011456840671598911" ixy="0.0" ixz="0.0" iyy="0.012544593773782253" iyz="0.0" izz="0.015392469242215157"/>
    </inertial>
    <visual name="SM_fr_caster_rotation_link_visual_0">
      <origin xyz="0.0 0.0 0.0" rpy="0.0 0.0 0.0"/>
      <geometry>
        <mesh filename="file://pr2/meshes/stl/caster.stl"/>
      </geometry>
    </visual>
    <collision name="SM_fr_caster_rotation_link_collision_0">
      <origin xyz="0.0 0.0 0.0" rpy="0.0 0.0 0.0"/>
      <geometry>
        <mesh filename="file://pr2/meshes/stl/caster_L.stl"/>
      </geometry>
    </collision>
  </link>
  <joint name="fr_caster_l_wheel_joint" type="continuous">
    <origin xyz="0.0 0.04899999871850014 0.0" rpy="0.0 0.0 0.0"/>
    <axis xyz="0.0 1.0 0.0"/>
    <parent link="fr_caster_rotation_link"/>
    <child link="fr_caster_l_wheel_link"/>
  </joint>
  <link name="fr_caster_l_wheel_link">
    <inertial>
      <origin xyz="0.0 0.0 0.0" rpy="1.6352778673171997 -1.0139516592025757 -2.9563724994659424"/>
      <mass value="0.44036000967025757"/>
      <inertia ixx="0.011456840671598911" ixy="0.0" ixz="0.0" iyy="0.012544593773782253" iyz="0.0" izz="0.015392469242215157"/>
    </inertial>
    <visual name="SM_fr_caster_l_wheel_link_visual_0">
      <origin xyz="0.0 0.0 0.0" rpy="0.0 0.0 0.0"/>
      <geometry>
        <mesh filename="file://pr2/meshes/obj/wheel.obj"/>
      </geometry>
    </visual>
    <collision name="SM_fr_caster_l_wheel_link_collision_0">
      <origin xyz="0.0 0.0 0.0" rpy="1.5707963705062866 0.0 0.0"/>
      <geometry>
        <cylinder radius="0.07479199767112732" length="0.03400000184774399"/>
      </geometry>
    </collision>
  </link>
  <joint name="fr_caster_r_wheel_joint" type="continuous">
    <origin xyz="0.0 -0.04899999871850014 0.0" rpy="0.0 0.0 0.0"/>
    <axis xyz="0.0 1.0 0.0"/>
    <parent link="fr_caster_rotation_link"/>
    <child link="fr_caster_r_wheel_link"/>
  </joint>
  <link name="fr_caster_r_wheel_link">
    <inertial>
      <origin xyz="0.0 0.0 0.0" rpy="1.6352778673171997 -1.0139516592025757 -2.9563724994659424"/>
      <mass value="0.44036000967025757"/>
      <inertia ixx="0.011456840671598911" ixy="0.0" ixz="0.0" iyy="0.012544593773782253" iyz="0.0" izz="0.015392469242215157"/>
    </inertial>
    <visual name="SM_fr_caster_r_wheel_link_visual_0">
      <origin xyz="0.0 0.0 0.0" rpy="0.0 0.0 0.0"/>
      <geometry>
        <mesh filename="file://pr2/meshes/obj/wheel.obj"/>
      </geometry>
    </visual>
    <collision name="SM_fr_caster_r_wheel_link_collision_0">
      <origin xyz="0.0 0.0 0.0" rpy="1.5707963705062866 0.0 0.0"/>
      <geometry>
        <cylinder radius="0.07479199767112732" length="0.03400000184774399"/>
      </geometry>
    </collision>
  </link>
  <joint name="bl_caster_rotation_joint" type="continuous">
    <origin xyz="-0.22460000216960907 0.22460000216960907 0.028200000524520874" rpy="0.0 0.0 0.0"/>
    <axis xyz="0.0 0.0 1.0"/>
    <parent link="base_link"/>
    <child link="bl_caster_rotation_link"/>
  </joint>
  <link name="bl_caster_rotation_link">
    <inertial>
      <origin xyz="0.0 0.0 0.07000000029802322" rpy="1.6352778673171997 -1.0139516592025757 -2.9563724994659424"/>
      <mass value="3.4730820655822754"/>
      <inertia ixx="0.011456840671598911" ixy="0.0" ixz="0.0" iyy="0.012544593773782253" iyz="0.0" izz="0.015392469242215157"/>
    </inertial>
    <visual name="SM_bl_caster_rotation_link_visual_0">
      <origin xyz="0.0 0.0 0.0" rpy="0.0 0.0 0.0"/>
      <geometry>
        <mesh filename="file://pr2/meshes/stl/caster.stl"/>
      </geometry>
    </visual>
    <collision name="SM_bl_caster_rotation_link_collision_0">
      <origin xyz="0.0 0.0 0.0" rpy="0.0 0.0 0.0"/>
      <geometry>
        <mesh filename="file://pr2/meshes/stl/caster_L.stl"/>
      </geometry>
    </collision>
  </link>
  <joint name="bl_caster_l_wheel_joint" type="continuous">
    <origin xyz="0.0 0.04899999871850014 0.0" rpy="0.0 0.0 0.0"/>
    <axis xyz="0.0 1.0 0.0"/>
    <parent link="bl_caster_rotation_link"/>
    <child link="bl_caster_l_wheel_link"/>
  </joint>
  <link name="bl_caster_l_wheel_link">
    <inertial>
      <origin xyz="0.0 0.0 0.0" rpy="1.6352778673171997 -1.0139516592025757 -2.9563724994659424"/>
      <mass value="0.44036000967025757"/>
      <inertia ixx="0.011456840671598911" ixy="0.0" ixz="0.0" iyy="0.012544593773782253" iyz="0.0" izz="0.015392469242215157"/>
    </inertial>
    <visual name="SM_bl_caster_l_wheel_link_visual_0">
      <origin xyz="0.0 0.0 0.0" rpy="0.0 0.0 0.0"/>
      <geometry>
        <mesh filename="file://pr2/meshes/obj/wheel.obj"/>
      </geometry>
    </visual>
    <collision name="SM_bl_caster_l_wheel_link_collision_0">
      <origin xyz="0.0 0.0 0.0" rpy="1.5707963705062866 0.0 0.0"/>
      <geometry>
        <cylinder radius="0.07479199767112732" length="0.03400000184774399"/>
      </geometry>
    </collision>
  </link>
  <joint name="bl_caster_r_wheel_joint" type="continuous">
    <origin xyz="0.0 -0.04899999871850014 0.0" rpy="0.0 0.0 0.0"/>
    <axis xyz="0.0 1.0 0.0"/>
    <parent link="bl_caster_rotation_link"/>
    <child link="bl_caster_r_wheel_link"/>
  </joint>
  <link name="bl_caster_r_wheel_link">
    <inertial>
      <origin xyz="0.0 0.0 0.0" rpy="1.6352778673171997 -1.0139516592025757 -2.9563724994659424"/>
      <mass value="0.44036000967025757"/>
      <inertia ixx="0.011456840671598911" ixy="0.0" ixz="0.0" iyy="0.012544593773782253" iyz="0.0" izz="0.015392469242215157"/>
    </inertial>
    <visual name="SM_bl_caster_r_wheel_link_visual_0">
      <origin xyz="0.0 0.0 0.0" rpy="0.0 0.0 0.0"/>
      <geometry>
        <mesh filename="file://pr2/meshes/obj/wheel.obj"/>
      </geometry>
    </visual>
    <collision name="SM_bl_caster_r_wheel_link_collision_0">
      <origin xyz="0.0 0.0 0.0" rpy="1.5707963705062866 0.0 0.0"/>
      <geometry>
        <cylinder radius="0.07479199767112732" length="0.03400000184774399"/>
      </geometry>
    </collision>
  </link>
  <joint name="br_caster_rotation_joint" type="continuous">
    <origin xyz="-0.22460000216960907 -0.22460000216960907 0.028200000524520874" rpy="0.0 0.0 0.0"/>
    <axis xyz="0.0 0.0 1.0"/>
    <parent link="base_link"/>
    <child link="br_caster_rotation_link"/>
  </joint>
  <link name="br_caster_rotation_link">
    <inertial>
      <origin xyz="0.0 0.0 0.07000000029802322" rpy="1.6352778673171997 -1.0139516592025757 -2.9563724994659424"/>
      <mass value="3.4730820655822754"/>
      <inertia ixx="0.011456840671598911" ixy="0.0" ixz="0.0" iyy="0.012544593773782253" iyz="0.0" izz="0.015392469242215157"/>
    </inertial>
    <visual name="SM_br_caster_rotation_link_visual_0">
      <origin xyz="0.0 0.0 0.0" rpy="0.0 0.0 0.0"/>
      <geometry>
        <mesh filename="file://pr2/meshes/stl/caster.stl"/>
      </geometry>
    </visual>
    <collision name="SM_br_caster_rotation_link_collision_0">
      <origin xyz="0.0 0.0 0.0" rpy="0.0 0.0 0.0"/>
      <geometry>
        <mesh filename="file://pr2/meshes/stl/caster_L.stl"/>
      </geometry>
    </collision>
  </link>
  <joint name="br_caster_l_wheel_joint" type="continuous">
    <origin xyz="0.0 0.04899999871850014 0.0" rpy="0.0 0.0 0.0"/>
    <axis xyz="0.0 1.0 0.0"/>
    <parent link="br_caster_rotation_link"/>
    <child link="br_caster_l_wheel_link"/>
  </joint>
  <link name="br_caster_l_wheel_link">
    <inertial>
      <origin xyz="0.0 0.0 0.0" rpy="1.6352778673171997 -1.0139516592025757 -2.9563724994659424"/>
      <mass value="0.44036000967025757"/>
      <inertia ixx="0.011456840671598911" ixy="0.0" ixz="0.0" iyy="0.012544593773782253" iyz="0.0" izz="0.015392469242215157"/>
    </inertial>
    <visual name="SM_br_caster_l_wheel_link_visual_0">
      <origin xyz="0.0 0.0 0.0" rpy="0.0 0.0 0.0"/>
      <geometry>
        <mesh filename="file://pr2/meshes/obj/wheel.obj"/>
      </geometry>
    </visual>
    <collision name="SM_br_caster_l_wheel_link_collision_0">
      <origin xyz="0.0 0.0 0.0" rpy="1.5707963705062866 0.0 0.0"/>
      <geometry>
        <cylinder radius="0.07479199767112732" length="0.03400000184774399"/>
      </geometry>
    </collision>
  </link>
  <joint name="br_caster_r_wheel_joint" type="continuous">
    <origin xyz="0.0 -0.04899999871850014 0.0" rpy="0.0 0.0 0.0"/>
    <axis xyz="0.0 1.0 0.0"/>
    <parent link="br_caster_rotation_link"/>
    <child link="br_caster_r_wheel_link"/>
  </joint>
  <link name="br_caster_r_wheel_link">
    <inertial>
      <origin xyz="0.0 0.0 0.0" rpy="1.6352778673171997 -1.0139516592025757 -2.9563724994659424"/>
      <mass value="0.44036000967025757"/>
      <inertia ixx="0.011456840671598911" ixy="0.0" ixz="0.0" iyy="0.012544593773782253" iyz="0.0" izz="0.015392469242215157"/>
    </inertial>
    <visual name="SM_br_caster_r_wheel_link_visual_0">
      <origin xyz="0.0 0.0 0.0" rpy="0.0 0.0 0.0"/>
      <geometry>
        <mesh filename="file://pr2/meshes/obj/wheel.obj"/>
      </geometry>
    </visual>
    <collision name="SM_br_caster_r_wheel_link_collision_0">
      <origin xyz="0.0 0.0 0.0" rpy="1.5707963705062866 0.0 0.0"/>
      <geometry>
        <cylinder radius="0.07479199767112732" length="0.03400000184774399"/>
      </geometry>
    </collision>
  </link>
  <joint name="torso_lift_joint" type="prismatic">
    <origin xyz="-0.05000000074505806 0.0 0.739674985408783" rpy="0.0 0.0 0.0"/>
    <axis xyz="0.0 0.0 1.0"/>
    <parent link="base_link"/>
    <child link="torso_lift_link"/>
    <limit effort="10000.0" lower="0.0" upper="0.33000001311302185" velocity="0.013000000268220901"/>
  </joint>
  <link name="torso_lift_link">
    <inertial>
      <origin xyz="-0.10000000149011612 0.0 -0.0885000005364418" rpy="2.9259960651397705 1.4982527494430542 2.933424234390259"/>
      <mass value="36.248046875"/>
      <inertia ixx="0.5145807266235352" ixy="0.0" ixz="0.0" iyy="2.5104501247406006" iyz="0.0" izz="2.7830748558044434"/>
    </inertial>
    <visual name="SM_torso_lift_link_visual_0">
      <origin xyz="0.0 0.0 0.0" rpy="0.0 0.0 0.0"/>
      <geometry>
        <mesh filename="file://pr2/meshes/obj/torso_lift.obj"/>
      </geometry>
    </visual>
    <collision name="SM_torso_lift_link_collision_0">
      <origin xyz="0.0 0.0 0.0" rpy="0.0 0.0 0.0"/>
      <geometry>
        <mesh filename="file://pr2/meshes/stl/torso_lift_L.stl"/>
      </geometry>
    </collision>
  </link>
  <joint name="l_torso_lift_side_plate_link_joint" type="fixed">
    <origin xyz="0.0535 0.209285 0.176625" rpy="0.0 0.0 0.0"/>
    <parent link="torso_lift_link"/>
    <child link="l_torso_lift_side_plate_link"/>
  </joint>
  <link name="l_torso_lift_side_plate_link">
    <inertial>
      <origin xyz="-0.0625 0.0 0.05000000074505806" rpy="0.0 0.0 0.0"/>
      <mass value="0.10000000149011612"/>
      <inertia ixx="0.0010000000474974513" ixy="0.0" ixz="0.0" iyy="0.0010000000474974513" iyz="0.0" izz="0.0010000000474974513"/>
    </inertial>
  </link>
  <joint name="r_torso_lift_side_plate_link_joint" type="fixed">
    <origin xyz="0.0535 -0.209285 0.176625" rpy="0.0 0.0 0.0"/>
    <parent link="torso_lift_link"/>
    <child link="r_torso_lift_side_plate_link"/>
  </joint>
  <link name="r_torso_lift_side_plate_link">
    <inertial>
      <origin xyz="-0.0625 0.0 0.05000000074505806" rpy="0.0 0.0 0.0"/>
      <mass value="0.10000000149011612"/>
      <inertia ixx="0.0010000000474974513" ixy="0.0" ixz="0.0" iyy="0.0010000000474974513" iyz="0.0" izz="0.0010000000474974513"/>
    </inertial>
  </link>
  <joint name="imu_link_joint" type="fixed">
    <origin xyz="-0.02977 -0.1497 0.164" rpy="3.1415927410125732 2.220446049250313e-16 3.1415927410125732"/>
    <parent link="torso_lift_link"/>
    <child link="imu_link"/>
  </joint>
  <link name="imu_link">
    <inertial>
      <origin xyz="0.0 0.0 0.0" rpy="0.0 0.0 -1.5707963705062866"/>
      <mass value="0.0010000000474974513"/>
      <inertia ixx="9.999999974752427e-07" ixy="0.0" ixz="0.0" iyy="9.999999747378752e-05" iyz="0.0" izz="9.999999747378752e-05"/>
    </inertial>
  </link>
  <joint name="head_pan_joint" type="revolute">
    <origin xyz="-0.017069999128580093 0.0 0.38144999742507935" rpy="0.0 0.0 0.0"/>
    <axis xyz="0.0 0.0 1.0"/>
    <parent link="torso_lift_link"/>
    <child link="head_pan_link"/>
    <limit effort="2.6449999809265137" lower="-3.006999969482422" upper="3.006999969482422" velocity="6.0"/>
  </joint>
  <link name="head_pan_link">
    <inertial>
      <origin xyz="0.010906999930739403 0.031693000346422195 0.09050700068473816" rpy="0.1921418011188507 0.10689982771873474 -0.0625552237033844"/>
      <mass value="6.339000225067139"/>
      <inertia ixx="0.03217979893088341" ixy="0.0" ixz="0.0" iyy="0.04612261801958084" iyz="0.0" izz="0.05839352682232857"/>
    </inertial>
    <visual name="SM_head_pan_link_visual_0">
      <origin xyz="0.0 0.0 0.0" rpy="0.0 0.0 0.0"/>
      <geometry>
        <mesh filename="file://pr2/meshes/obj/head_pan.obj"/>
      </geometry>
    </visual>
    <collision name="SM_head_pan_link_collision_0">
      <origin xyz="0.0 0.0 0.0" rpy="0.0 0.0 0.0"/>
      <geometry>
        <mesh filename="file://pr2/meshes/stl/head_pan_L.stl"/>
      </geometry>
    </collision>
  </link>
  <joint name="head_tilt_joint" type="revolute">
    <origin xyz="0.06800000369548798 0.0 0.0" rpy="0.0 0.0 0.0"/>
    <axis xyz="0.0 1.0 0.0"/>
    <parent link="head_pan_link"/>
    <child link="head_tilt_link"/>
    <limit effort="18.0" lower="-0.47123798727989197" upper="1.3962600231170654" velocity="5.0"/>
  </joint>
  <link name="head_tilt_link">
    <inertial>
      <origin xyz="0.0017160000279545784 -0.01955600082874298 0.05500200018286705" rpy="-0.2091677188873291 -0.0035893525928258896 -0.020666146650910378"/>
      <mass value="4.479000091552734"/>
      <inertia ixx="0.024210046976804733" ixy="0.0" ixz="0.0" iyy="0.05414252355694771" iyz="0.0" izz="0.06790011376142502"/>
    </inertial>
    <visual name="SM_head_tilt_link_visual_0">
      <origin xyz="0.0 0.0 0.0" rpy="0.0 0.0 0.0"/>
      <geometry>
        <mesh filename="file://pr2/meshes/obj/head_tilt.obj"/>
      </geometry>
    </visual>
    <collision name="SM_head_tilt_link_collision_0">
      <origin xyz="0.0 0.0 0.0" rpy="0.0 0.0 0.0"/>
      <geometry>
        <mesh filename="file://pr2/meshes/stl/head_tilt_L.stl"/>
      </geometry>
    </collision>
  </link>
  <joint name="head_plate_frame_joint" type="fixed">
    <origin xyz="0.0232 0.0 0.0645" rpy="0.0 0.0 0.0"/>
    <parent link="head_tilt_link"/>
    <child link="head_plate_frame"/>
  </joint>
  <link name="head_plate_frame">
    <inertial>
      <origin xyz="0.0 0.0 0.0" rpy="0.0 0.0 0.0"/>
      <mass value="0.009999999776482582"/>
      <inertia ixx="0.0010000000474974513" ixy="0.0" ixz="0.0" iyy="0.0010000000474974513" iyz="0.0" izz="0.0010000000474974513"/>
    </inertial>
    <visual name="SM_head_plate_frame_visual_0">
      <origin xyz="0.0 0.0 0.0" rpy="0.0 0.0 0.0"/>
      <geometry>
        <box size="0.009999999776482582 0.009999999776482582 0.009999999776482582"/>
      </geometry>
    </visual>
    <collision name="SM_head_plate_frame_collision_0">
      <origin xyz="0.0 0.0 0.0" rpy="0.0 0.0 0.0"/>
      <geometry>
        <box size="0.009999999776482582 0.009999999776482582 0.009999999776482582"/>
      </geometry>
    </collision>
  </link>
  <joint name="sensor_mount_link_joint" type="fixed">
    <origin xyz="0.0 0.0 0.0" rpy="0.0 0.0 0.0"/>
    <parent link="head_plate_frame"/>
    <child link="sensor_mount_link"/>
  </joint>
  <link name="sensor_mount_link">
    <inertial>
      <origin xyz="0.0 0.0 0.0" rpy="0.0 0.0 0.0"/>
      <mass value="0.05000000074505806"/>
      <inertia ixx="0.0010000000474974513" ixy="0.0" ixz="0.0" iyy="0.0010000000474974513" iyz="0.0" izz="0.009999999776482582"/>
    </inertial>
  </link>
  <joint name="high_def_frame_joint" type="fixed">
    <origin xyz="0.046457 -0.11 0.0546" rpy="0.0 0.0 0.0"/>
    <parent link="sensor_mount_link"/>
    <child link="high_def_frame"/>
  </joint>
  <link name="high_def_frame">
    <inertial>
      <origin xyz="0.0 0.0 0.0" rpy="0.0 0.0 0.0"/>
      <mass value="0.009999999776482582"/>
      <inertia ixx="0.0010000000474974513" ixy="0.0" ixz="0.0" iyy="0.0010000000474974513" iyz="0.0" izz="0.0010000000474974513"/>
    </inertial>
  </link>
  <joint name="high_def_optical_frame_joint" type="fixed">
    <origin xyz="0.0 0.0 0.0" rpy="-1.5707963705062866 0.0 -1.5707963705062866"/>
    <parent link="high_def_frame"/>
    <child link="high_def_optical_frame"/>
  </joint>
  <link name="high_def_optical_frame">
    <inertial>
      <origin xyz="0.0 0.0 0.0" rpy="0.0 0.0 0.0"/>
      <mass value="0.009999999776482582"/>
      <inertia ixx="0.0010000000474974513" ixy="0.0" ixz="0.0" iyy="0.0010000000474974513" iyz="0.0" izz="0.0010000000474974513"/>
    </inertial>
  </link>
  <joint name="double_stereo_link_joint" type="fixed">
    <origin xyz="0.0 0.0 0.0" rpy="0.0 0.0 0.0"/>
    <parent link="sensor_mount_link"/>
    <child link="double_stereo_link"/>
  </joint>
  <link name="double_stereo_link">
    <inertial>
      <origin xyz="0.0 0.0 0.0" rpy="0.0 0.0 0.0"/>
      <mass value="0.10000000149011612"/>
      <inertia ixx="0.0010000000474974513" ixy="0.0" ixz="0.0" iyy="0.0010000000474974513" iyz="0.0" izz="0.009999999776482582"/>
    </inertial>
  </link>
  <joint name="wide_stereo_link_joint" type="fixed">
    <origin xyz="0.045 0.03 0.0501" rpy="0.0 0.0 0.0"/>
    <parent link="double_stereo_link"/>
    <child link="wide_stereo_link"/>
  </joint>
  <link name="wide_stereo_link">
    <inertial>
      <origin xyz="0.0 0.0 0.0" rpy="0.0 0.0 0.0"/>
      <mass value="0.10000000149011612"/>
      <inertia ixx="0.009999999776482582" ixy="0.0" ixz="0.0" iyy="0.009999999776482582" iyz="0.0" izz="0.009999999776482582"/>
    </inertial>
  </link>
  <joint name="wide_stereo_optical_frame_joint" type="fixed">
    <origin xyz="0.0 0.0 0.0" rpy="-1.5707963705062866 0.0 -1.5707963705062866"/>
    <parent link="wide_stereo_link"/>
    <child link="wide_stereo_optical_frame"/>
  </joint>
  <link name="wide_stereo_optical_frame">
    <inertial>
      <origin xyz="0.0 0.0 0.0" rpy="0.0 0.0 0.0"/>
      <mass value="0.0"/>
      <inertia ixx="0.0" ixy="0.0" ixz="0.0" iyy="0.0" iyz="0.0" izz="0.0"/>
    </inertial>
  </link>
  <joint name="wide_stereo_l_stereo_camera_frame_joint" type="fixed">
    <origin xyz="0.0 0.0 0.0" rpy="0.0 0.0 0.0"/>
    <parent link="wide_stereo_link"/>
    <child link="wide_stereo_l_stereo_camera_frame"/>
  </joint>
  <link name="wide_stereo_l_stereo_camera_frame">
    <inertial>
      <origin xyz="0.0 0.0 0.0" rpy="0.0 0.0 0.0"/>
      <mass value="0.009999999776482582"/>
      <inertia ixx="0.0010000000474974513" ixy="0.0" ixz="0.0" iyy="0.0010000000474974513" iyz="0.0" izz="0.0010000000474974513"/>
    </inertial>
  </link>
  <joint name="wide_stereo_l_stereo_camera_optical_frame_joint" type="fixed">
    <origin xyz="0.0 0.0 0.0" rpy="-1.5707963705062866 0.0 -1.5707963705062866"/>
    <parent link="wide_stereo_l_stereo_camera_frame"/>
    <child link="wide_stereo_l_stereo_camera_optical_frame"/>
  </joint>
  <link name="wide_stereo_l_stereo_camera_optical_frame">
    <inertial>
      <origin xyz="0.0 0.0 0.0" rpy="0.0 0.0 0.0"/>
      <mass value="0.0"/>
      <inertia ixx="0.0" ixy="0.0" ixz="0.0" iyy="0.0" iyz="0.0" izz="0.0"/>
    </inertial>
  </link>
  <joint name="wide_stereo_r_stereo_camera_frame_joint" type="fixed">
    <origin xyz="0.0 -0.09 0.0" rpy="0.0 0.0 0.0"/>
    <parent link="wide_stereo_l_stereo_camera_frame"/>
    <child link="wide_stereo_r_stereo_camera_frame"/>
  </joint>
  <link name="wide_stereo_r_stereo_camera_frame">
    <inertial>
      <origin xyz="0.0 0.0 0.0" rpy="0.0 0.0 0.0"/>
      <mass value="0.009999999776482582"/>
      <inertia ixx="0.0010000000474974513" ixy="0.0" ixz="0.0" iyy="0.0010000000474974513" iyz="0.0" izz="0.0010000000474974513"/>
    </inertial>
  </link>
  <joint name="wide_stereo_r_stereo_camera_optical_frame_joint" type="fixed">
    <origin xyz="0.0 0.0 0.0" rpy="-1.5707963705062866 0.0 -1.5707963705062866"/>
    <parent link="wide_stereo_r_stereo_camera_frame"/>
    <child link="wide_stereo_r_stereo_camera_optical_frame"/>
  </joint>
  <link name="wide_stereo_r_stereo_camera_optical_frame">
    <inertial>
      <origin xyz="0.0 0.0 0.0" rpy="0.0 0.0 0.0"/>
      <mass value="0.0"/>
      <inertia ixx="0.0" ixy="0.0" ixz="0.0" iyy="0.0" iyz="0.0" izz="0.0"/>
    </inertial>
  </link>
  <joint name="narrow_stereo_link_joint" type="fixed">
    <origin xyz="0.045 0.06 0.0501" rpy="0.0 0.0 0.0"/>
    <parent link="double_stereo_link"/>
    <child link="narrow_stereo_link"/>
  </joint>
  <link name="narrow_stereo_link">
    <inertial>
      <origin xyz="0.0 0.0 0.0" rpy="0.0 0.0 0.0"/>
      <mass value="0.10000000149011612"/>
      <inertia ixx="0.009999999776482582" ixy="0.0" ixz="0.0" iyy="0.009999999776482582" iyz="0.0" izz="0.009999999776482582"/>
    </inertial>
  </link>
  <joint name="narrow_stereo_optical_frame_joint" type="fixed">
    <origin xyz="0.0 0.0 0.0" rpy="-1.5707963705062866 0.0 -1.5707963705062866"/>
    <parent link="narrow_stereo_link"/>
    <child link="narrow_stereo_optical_frame"/>
  </joint>
  <link name="narrow_stereo_optical_frame">
    <inertial>
      <origin xyz="0.0 0.0 0.0" rpy="0.0 0.0 0.0"/>
      <mass value="0.0"/>
      <inertia ixx="0.0" ixy="0.0" ixz="0.0" iyy="0.0" iyz="0.0" izz="0.0"/>
    </inertial>
  </link>
  <joint name="narrow_stereo_l_stereo_camera_frame_joint" type="fixed">
    <origin xyz="0.0 0.0 0.0" rpy="0.0 0.0 0.0"/>
    <parent link="narrow_stereo_link"/>
    <child link="narrow_stereo_l_stereo_camera_frame"/>
  </joint>
  <link name="narrow_stereo_l_stereo_camera_frame">
    <inertial>
      <origin xyz="0.0 0.0 0.0" rpy="0.0 0.0 0.0"/>
      <mass value="0.009999999776482582"/>
      <inertia ixx="0.0010000000474974513" ixy="0.0" ixz="0.0" iyy="0.0010000000474974513" iyz="0.0" izz="0.0010000000474974513"/>
    </inertial>
  </link>
  <joint name="narrow_stereo_l_stereo_camera_optical_frame_joint" type="fixed">
    <origin xyz="0.0 0.0 0.0" rpy="-1.5707963705062866 0.0 -1.5707963705062866"/>
    <parent link="narrow_stereo_l_stereo_camera_frame"/>
    <child link="narrow_stereo_l_stereo_camera_optical_frame"/>
  </joint>
  <link name="narrow_stereo_l_stereo_camera_optical_frame">
    <inertial>
      <origin xyz="0.0 0.0 0.0" rpy="0.0 0.0 0.0"/>
      <mass value="0.0"/>
      <inertia ixx="0.0" ixy="0.0" ixz="0.0" iyy="0.0" iyz="0.0" izz="0.0"/>
    </inertial>
  </link>
  <joint name="narrow_stereo_r_stereo_camera_frame_joint" type="fixed">
    <origin xyz="0.0 -0.09 0.0" rpy="0.0 0.0 0.0"/>
    <parent link="narrow_stereo_l_stereo_camera_frame"/>
    <child link="narrow_stereo_r_stereo_camera_frame"/>
  </joint>
  <link name="narrow_stereo_r_stereo_camera_frame">
    <inertial>
      <origin xyz="0.0 0.0 0.0" rpy="0.0 0.0 0.0"/>
      <mass value="0.009999999776482582"/>
      <inertia ixx="0.0010000000474974513" ixy="0.0" ixz="0.0" iyy="0.0010000000474974513" iyz="0.0" izz="0.0010000000474974513"/>
    </inertial>
  </link>
  <joint name="narrow_stereo_r_stereo_camera_optical_frame_joint" type="fixed">
    <origin xyz="0.0 0.0 0.0" rpy="-1.5707963705062866 0.0 -1.5707963705062866"/>
    <parent link="narrow_stereo_r_stereo_camera_frame"/>
    <child link="narrow_stereo_r_stereo_camera_optical_frame"/>
  </joint>
  <link name="narrow_stereo_r_stereo_camera_optical_frame">
    <inertial>
      <origin xyz="0.0 0.0 0.0" rpy="0.0 0.0 0.0"/>
      <mass value="0.0"/>
      <inertia ixx="0.0" ixy="0.0" ixz="0.0" iyy="0.0" iyz="0.0" izz="0.0"/>
    </inertial>
  </link>
  <joint name="projector_wg6802418_frame_joint" type="fixed">
    <origin xyz="0.0 0.11 0.0546" rpy="0.0 0.0 0.0"/>
    <parent link="head_plate_frame"/>
    <child link="projector_wg6802418_frame"/>
  </joint>
  <link name="projector_wg6802418_frame">
    <inertial>
      <origin xyz="0.0 0.0 0.0" rpy="0.0 0.0 0.0"/>
      <mass value="0.009999999776482582"/>
      <inertia ixx="0.0010000000474974513" ixy="0.0" ixz="0.0" iyy="0.0010000000474974513" iyz="0.0" izz="0.0010000000474974513"/>
    </inertial>
  </link>
  <joint name="projector_wg6802418_child_frame_joint" type="fixed">
    <origin xyz="0.0 0.0 0.0" rpy="0.0 -1.5707963705062866 0.0"/>
    <parent link="projector_wg6802418_frame"/>
    <child link="projector_wg6802418_child_frame"/>
  </joint>
  <link name="projector_wg6802418_child_frame">
    <inertial>
      <origin xyz="0.0 0.0 0.0" rpy="0.0 0.0 0.0"/>
      <mass value="0.009999999776482582"/>
      <inertia ixx="0.0010000000474974513" ixy="0.0" ixz="0.0" iyy="0.0010000000474974513" iyz="0.0" izz="0.0010000000474974513"/>
    </inertial>
  </link>
  <joint name="laser_tilt_mount_joint" type="revolute">
    <origin xyz="0.0989300012588501 0.0 0.22699999809265137" rpy="0.0 0.0 0.0"/>
    <axis xyz="0.0 1.0 0.0"/>
    <parent link="torso_lift_link"/>
    <child link="laser_tilt_mount_link"/>
    <limit effort="0.6499999761581421" lower="-0.7853999733924866" upper="1.483530044555664" velocity="10.0"/>
  </joint>
  <link name="laser_tilt_mount_link">
    <inertial>
      <origin xyz="-0.0011360000353306532 0.0016700000269338489 -0.0071299998089671135" rpy="-0.6898918151855469 -1.431308388710022 -2.227118968963623"/>
      <mass value="0.5910000205039978"/>
      <inertia ixx="0.0007879214826971292" ixy="0.0" ixz="0.0" iyy="0.001081750146113336" iyz="0.0" izz="0.0012045714538544416"/>
    </inertial>
    <visual name="SM_laser_tilt_mount_link_visual_0">
      <origin xyz="0.0 0.0 0.0" rpy="0.0 0.0 0.0"/>
      <geometry>
        <mesh filename="file://pr2/meshes/obj/tilting_hokuyo.obj"/>
      </geometry>
    </visual>
    <collision name="SM_laser_tilt_mount_link_collision_0">
      <origin xyz="0.0 0.0 0.0" rpy="0.0 0.0 0.0"/>
      <geometry>
        <mesh filename="file://pr2/meshes/stl/tilting_hokuyo_L.stl"/>
      </geometry>
    </collision>
  </link>
  <joint name="laser_tilt_link_joint" type="fixed">
    <origin xyz="0.0 0.0 0.03" rpy="0.0 0.0 0.0"/>
    <parent link="laser_tilt_mount_link"/>
    <child link="laser_tilt_link"/>
  </joint>
  <link name="laser_tilt_link">
    <inertial>
      <origin xyz="0.0 0.0 0.0" rpy="0.0 0.0 -1.5707963705062866"/>
      <mass value="0.0010000000474974513"/>
      <inertia ixx="9.999999974752427e-07" ixy="0.0" ixz="0.0" iyy="9.999999747378752e-05" iyz="0.0" izz="9.999999747378752e-05"/>
    </inertial>
  </link>
  <joint name="r_shoulder_pan_joint" type="revolute">
    <origin xyz="0.0 -0.18799999356269836 0.0" rpy="0.0 0.0 0.0"/>
    <axis xyz="0.0 0.0 1.0"/>
    <parent link="torso_lift_link"/>
    <child link="r_shoulder_pan_link"/>
    <limit effort="30.0" lower="-2.285398244857788" upper="0.7146018147468567" velocity="2.0880000591278076"/>
  </joint>
  <link name="r_shoulder_pan_link">
    <inertial>
      <origin xyz="-0.0012009999481961131 0.0245130006223917 -0.0982310026884079" rpy="1.905988335609436 -1.3407824039459229 0.5029529929161072"/>
      <mass value="25.7993221282959"/>
      <inertia ixx="0.24203263223171234" ixy="0.0" ixz="0.0" iyy="0.8377005457878113" iyz="0.0" izz="0.9342013597488403"/>
    </inertial>
    <visual name="SM_r_shoulder_pan_link_visual_0">
      <origin xyz="0.0 0.0 0.0" rpy="0.0 0.0 0.0"/>
      <geometry>
        <mesh filename="file://pr2/meshes/obj/shoulder_pan.obj"/>
      </geometry>
    </visual>
    <collision name="SM_r_shoulder_pan_link_collision_0">
      <origin xyz="0.0 0.0 0.0" rpy="0.0 0.0 0.0"/>
      <geometry>
        <mesh filename="file://pr2/meshes/stl/shoulder_pan.stl"/>
      </geometry>
    </collision>
  </link>
  <joint name="r_shoulder_lift_joint" type="revolute">
    <origin xyz="0.10000000149011612 0.0 0.0" rpy="0.0 0.0 0.0"/>
    <axis xyz="0.0 1.0 0.0"/>
    <parent link="r_shoulder_pan_link"/>
    <child link="r_shoulder_lift_link"/>
    <limit effort="30.0" lower="-0.5235999822616577" upper="1.396299958229065" velocity="2.0820000171661377"/>
  </joint>
  <link name="r_shoulder_lift_link">
    <inertial>
      <origin xyz="0.021950000897049904 -0.026639999821782112 -0.03127000108361244" rpy="1.4646769762039185 -0.44314050674438477 -0.7496954798698425"/>
      <mass value="2.749880075454712"/>
      <inertia ixx="0.015168089419603348" ixy="0.0" ixz="0.0" iyy="0.020730163902044296" iyz="0.0" izz="0.026187369599938393"/>
    </inertial>
    <visual name="SM_r_shoulder_lift_link_visual_0">
      <origin xyz="0.0 0.0 0.0" rpy="0.0 0.0 0.0"/>
      <geometry>
        <mesh filename="file://pr2/meshes/obj/shoulder_lift.obj"/>
      </geometry>
    </visual>
    <collision name="SM_r_shoulder_lift_link_collision_0">
      <origin xyz="0.0 0.0 0.0" rpy="0.0 0.0 0.0"/>
      <geometry>
        <mesh filename="file://pr2/meshes/stl/shoulder_lift.stl"/>
      </geometry>
    </collision>
  </link>
  <joint name="r_upper_arm_roll_joint" type="revolute">
    <origin xyz="0.0 0.0 0.0" rpy="0.0 0.0 0.0"/>
    <axis xyz="1.0 0.0 0.0"/>
    <parent link="r_shoulder_lift_link"/>
    <child link="r_upper_arm_roll_link"/>
    <limit effort="30.0" lower="-3.9000000953674316" upper="0.800000011920929" velocity="3.2699999809265137"/>
  </joint>
  <link name="r_upper_arm_roll_link">
    <inertial>
      <origin xyz="0.0 0.0 0.0" rpy="0.0 0.0 0.0"/>
      <mass value="0.10000000149011612"/>
      <inertia ixx="0.009999999776482582" ixy="0.0" ixz="0.0" iyy="0.009999999776482582" iyz="0.0" izz="0.009999999776482582"/>
    </inertial>
    <visual name="SM_r_upper_arm_roll_link_visual_0">
      <origin xyz="0.0 0.0 0.0" rpy="0.0 0.0 0.0"/>
      <geometry>
        <mesh filename="file://pr2/meshes/stl/upper_arm_roll.stl"/>
      </geometry>
    </visual>
    <collision name="SM_r_upper_arm_roll_link_collision_0">
      <origin xyz="0.0 0.0 0.0" rpy="0.0 0.0 0.0"/>
      <geometry>
        <mesh filename="file://pr2/meshes/stl/upper_arm_roll_L.stl"/>
      </geometry>
    </collision>
  </link>
  <joint name="r_upper_arm_link_joint" type="fixed">
    <origin xyz="0.0 0.0 0.0" rpy="0.0 0.0 0.0"/>
    <parent link="r_upper_arm_roll_link"/>
    <child link="r_upper_arm_link"/>
  </joint>
  <link name="r_upper_arm_link">
    <inertial>
      <origin xyz="0.21398000419139862 -0.016209999099373817 -0.00019999999494757503" rpy="0.18961568176746368 -0.011415306478738785 -0.06291697919368744"/>
      <mass value="6.017690181732178"/>
      <inertia ixx="0.015132686123251915" ixy="0.0" ixz="0.0" iyy="0.07493065297603607" iyz="0.0" izz="0.07613848894834518"/>
    </inertial>
    <visual name="SM_r_upper_arm_link_visual_0">
      <origin xyz="0.0 0.0 0.0" rpy="0.0 0.0 0.0"/>
      <geometry>
        <mesh filename="file://pr2/meshes/obj/upper_arm.obj"/>
      </geometry>
    </visual>
    <collision name="SM_r_upper_arm_link_collision_0">
      <origin xyz="0.0 0.0 0.0" rpy="0.0 0.0 0.0"/>
      <geometry>
        <mesh filename="file://pr2/meshes/stl/upper_arm.stl"/>
      </geometry>
    </collision>
  </link>
  <joint name="r_elbow_flex_joint" type="revolute">
    <origin xyz="0.4000000059604645 0.0 0.0" rpy="0.0 0.0 0.0"/>
    <axis xyz="0.0 1.0 0.0"/>
    <parent link="r_upper_arm_link"/>
    <child link="r_elbow_flex_link"/>
    <limit effort="30.0" lower="-2.3213000297546387" upper="0.0" velocity="3.299999952316284"/>
  </joint>
  <link name="r_elbow_flex_link">
    <inertial>
      <origin xyz="0.01013999991118908 0.00031999999191612005 -0.012109999544918537" rpy="1.5263210535049438 0.7122388482093811 -0.056482091546058655"/>
      <mass value="1.9032700061798096"/>
      <inertia ixx="0.003089768812060356" ixy="0.0" ixz="0.0" iyy="0.003964767791330814" iyz="0.0" izz="0.00441851606592536"/>
    </inertial>
    <visual name="SM_r_elbow_flex_link_visual_0">
      <origin xyz="0.0 0.0 0.0" rpy="0.0 0.0 0.0"/>
      <geometry>
        <mesh filename="file://pr2/meshes/obj/elbow_flex.obj"/>
      </geometry>
    </visual>
    <collision name="SM_r_elbow_flex_link_collision_0">
      <origin xyz="0.0 0.0 0.0" rpy="0.0 0.0 0.0"/>
      <geometry>
        <mesh filename="file://pr2/meshes/stl/elbow_flex.stl"/>
      </geometry>
    </collision>
  </link>
  <joint name="r_forearm_roll_joint" type="continuous">
    <origin xyz="0.0 0.0 0.0" rpy="0.0 0.0 0.0"/>
    <axis xyz="1.0 0.0 0.0"/>
    <parent link="r_elbow_flex_link"/>
    <child link="r_forearm_roll_link"/>
  </joint>
  <link name="r_forearm_roll_link">
    <inertial>
      <origin xyz="0.0 0.0 0.0" rpy="0.0 0.0 0.0"/>
      <mass value="0.10000000149011612"/>
      <inertia ixx="0.009999999776482582" ixy="0.0" ixz="0.0" iyy="0.009999999776482582" iyz="0.0" izz="0.009999999776482582"/>
    </inertial>
    <visual name="SM_r_forearm_roll_link_visual_0">
      <origin xyz="0.0 0.0 0.0" rpy="0.0 0.0 0.0"/>
      <geometry>
        <mesh filename="file://pr2/meshes/stl/forearm_roll.stl"/>
      </geometry>
    </visual>
    <collision name="SM_r_forearm_roll_link_collision_0">
      <origin xyz="0.0 0.0 0.0" rpy="0.0 0.0 0.0"/>
      <geometry>
        <mesh filename="file://pr2/meshes/stl/forearm_roll_L.stl"/>
      </geometry>
    </collision>
  </link>
  <joint name="r_forearm_link_joint" type="fixed">
    <origin xyz="0.0 0.0 0.0" rpy="0.0 0.0 0.0"/>
    <parent link="r_forearm_roll_link"/>
    <child link="r_forearm_link"/>
  </joint>
  <link name="r_forearm_link">
    <inertial>
      <origin xyz="0.18791000545024872 -0.00016999999934341758 -0.009119999594986439" rpy="0.006317686755210161 0.055042218416929245 -0.00461096316576004"/>
      <mass value="2.5796799659729004"/>
      <inertia ixx="0.0036089171189814806" ixy="0.0" ixz="0.0" iyy="0.015077545307576656" iyz="0.0" izz="0.01663258671760559"/>
    </inertial>
    <visual name="SM_r_forearm_link_visual_0">
      <origin xyz="0.0 0.0 0.0" rpy="0.0 0.0 0.0"/>
      <geometry>
        <mesh filename="file://pr2/meshes/obj/forearm.obj"/>
      </geometry>
    </visual>
    <collision name="SM_r_forearm_link_collision_0">
      <origin xyz="0.0 0.0 0.0" rpy="0.0 0.0 0.0"/>
      <geometry>
        <mesh filename="file://pr2/meshes/stl/forearm.stl"/>
      </geometry>
    </collision>
  </link>
  <joint name="r_wrist_flex_joint" type="revolute">
    <origin xyz="0.32100000977516174 0.0 0.0" rpy="0.0 0.0 0.0"/>
    <axis xyz="0.0 1.0 0.0"/>
    <parent link="r_forearm_link"/>
    <child link="r_wrist_flex_link"/>
    <limit effort="10.0" lower="-2.180000066757202" upper="0.0" velocity="3.078000068664551"/>
  </joint>
  <link name="r_wrist_flex_link">
    <inertial>
      <origin xyz="-0.0015699999639764428 0.0 -0.000750000006519258" rpy="1.92262864112854 0.0005117869004607201 -1.5701563358306885"/>
      <mass value="0.6140199899673462"/>
      <inertia ixx="0.00019824413175228983" ixy="0.0" ixz="0.0" iyy="0.0006433910457417369" iyz="0.0" izz="0.0006527714431285858"/>
    </inertial>
    <visual name="SM_r_wrist_flex_link_visual_0">
      <origin xyz="0.0 0.0 0.0" rpy="0.0 0.0 0.0"/>
      <geometry>
        <mesh filename="file://pr2/meshes/obj/wrist_flex.obj"/>
      </geometry>
    </visual>
    <collision name="SM_r_wrist_flex_link_collision_0">
      <origin xyz="0.0 0.0 0.0" rpy="0.0 0.0 0.0"/>
      <geometry>
        <mesh filename="file://pr2/meshes/stl/wrist_flex.stl"/>
      </geometry>
    </collision>
  </link>
  <joint name="r_wrist_roll_joint" type="continuous">
    <origin xyz="0.0 0.0 0.0" rpy="0.0 0.0 0.0"/>
    <axis xyz="1.0 0.0 0.0"/>
    <parent link="r_wrist_flex_link"/>
    <child link="r_wrist_roll_link"/>
  </joint>
  <link name="r_wrist_roll_link">
    <inertial>
      <origin xyz="0.0 0.0 0.0" rpy="0.0 0.0 0.0"/>
      <mass value="0.10000000149011612"/>
      <inertia ixx="0.009999999776482582" ixy="0.0" ixz="0.0" iyy="0.009999999776482582" iyz="0.0" izz="0.009999999776482582"/>
    </inertial>
    <visual name="SM_r_wrist_roll_link_visual_0">
      <origin xyz="0.0 0.0 0.0" rpy="0.0 0.0 0.0"/>
      <geometry>
        <mesh filename="file://pr2/meshes/stl/wrist_roll.stl"/>
      </geometry>
    </visual>
    <collision name="SM_r_wrist_roll_link_collision_0">
      <origin xyz="0.0 0.0 0.0" rpy="0.0 0.0 0.0"/>
      <geometry>
        <mesh filename="file://pr2/meshes/stl/wrist_roll_L.stl"/>
      </geometry>
    </collision>
  </link>
  <joint name="r_gripper_palm_link_joint" type="fixed">
    <origin xyz="0.0 0.0 0.0" rpy="0.0 0.0 0.0"/>
    <parent link="r_wrist_roll_link"/>
    <child link="r_gripper_palm_link"/>
  </joint>
  <link name="r_gripper_palm_link">
    <inertial>
      <origin xyz="0.06622999906539917 0.0005300000193528831 -0.0011899999808520079" rpy="0.0029361415654420853 -0.0018384623108431697 0.0484548881649971"/>
      <mass value="0.5800700187683105"/>
      <inertia ixx="0.000351471098838374" ixy="0.0" ixz="0.0" iyy="0.0006781778647564352" iyz="0.0" izz="0.0008656365098431706"/>
    </inertial>
    <visual name="SM_r_gripper_palm_link_visual_0">
      <origin xyz="0.0 0.0 0.0" rpy="0.0 0.0 0.0"/>
      <geometry>
        <mesh filename="file://pr2/meshes/obj/gripper_palm.obj"/>
      </geometry>
    </visual>
    <collision name="SM_r_gripper_palm_link_collision_0">
      <origin xyz="0.0 0.0 0.0" rpy="0.0 0.0 0.0"/>
      <geometry>
        <mesh filename="file://pr2/meshes/stl/gripper_palm.stl"/>
      </geometry>
    </collision>
  </link>
  <joint name="r_gripper_led_frame_joint" type="fixed">
    <origin xyz="0.0513 0.0 0.0244" rpy="0.0 0.0 0.0"/>
    <parent link="r_gripper_palm_link"/>
    <child link="r_gripper_led_frame"/>
  </joint>
  <link name="r_gripper_led_frame">
    <inertial>
      <origin xyz="0.0 0.0 0.0" rpy="0.0 0.0 0.0"/>
      <mass value="0.0"/>
      <inertia ixx="0.0" ixy="0.0" ixz="0.0" iyy="0.0" iyz="0.0" izz="0.0"/>
    </inertial>
  </link>
  <joint name="r_gripper_motor_accelerometer_link_joint" type="fixed">
    <origin xyz="0.0 0.0 0.0" rpy="0.0 0.0 0.0"/>
    <parent link="r_gripper_palm_link"/>
    <child link="r_gripper_motor_accelerometer_link"/>
  </joint>
  <link name="r_gripper_motor_accelerometer_link">
    <inertial>
      <origin xyz="0.0 0.0 0.0" rpy="0.0 0.0 0.0"/>
      <mass value="0.0010000000474974513"/>
      <inertia ixx="0.0010000000474974513" ixy="0.0" ixz="0.0" iyy="0.0010000000474974513" iyz="0.0" izz="0.0010000000474974513"/>
    </inertial>
    <visual name="SM_r_gripper_motor_accelerometer_link_visual_0">
      <origin xyz="0.0 0.0 0.0" rpy="0.0 0.0 0.0"/>
      <geometry>
        <box size="0.0010000000474974513 0.0010000000474974513 0.0010000000474974513"/>
      </geometry>
    </visual>
    <collision name="SM_r_gripper_motor_accelerometer_link_collision_0">
      <origin xyz="0.0 0.0 0.0" rpy="0.0 0.0 0.0"/>
      <geometry>
        <box size="0.0010000000474974513 0.0010000000474974513 0.0010000000474974513"/>
      </geometry>
    </collision>
  </link>
  <joint name="r_gripper_tool_frame_joint" type="fixed">
    <origin xyz="0.18 0.0 0.0" rpy="0.0 0.0 0.0"/>
    <parent link="r_gripper_palm_link"/>
    <child link="r_gripper_tool_frame"/>
  </joint>
  <link name="r_gripper_tool_frame">
    <inertial>
      <origin xyz="0.0 0.0 0.0" rpy="0.0 0.0 0.0"/>
      <mass value="0.0"/>
      <inertia ixx="0.0" ixy="0.0" ixz="0.0" iyy="0.0" iyz="0.0" izz="0.0"/>
    </inertial>
  </link>
  <joint name="r_gripper_motor_slider_joint" type="fixed">
    <origin xyz="0.1682800054550171 0.0 0.0" rpy="0.0 0.0 0.0"/>
    <parent link="r_gripper_palm_link"/>
    <child link="r_gripper_motor_slider_link"/>
  </joint>
  <link name="r_gripper_motor_slider_link">
    <inertial>
      <origin xyz="0.0 0.0 0.0" rpy="0.0 0.0 0.0"/>
      <mass value="0.009999999776482582"/>
      <inertia ixx="0.0010000000474974513" ixy="0.0" ixz="0.0" iyy="0.0010000000474974513" iyz="0.0" izz="0.0010000000474974513"/>
    </inertial>
  </link>
  <joint name="r_gripper_motor_screw_joint" type="fixed">
    <origin xyz="0.0 0.0 0.0" rpy="0.0 0.0 0.0"/>
    <parent link="r_gripper_motor_slider_link"/>
    <child link="r_gripper_motor_screw_link"/>
  </joint>
  <link name="r_gripper_motor_screw_link">
    <inertial>
      <origin xyz="0.0 0.0 0.0" rpy="0.0 0.0 0.0"/>
      <mass value="0.009999999776482582"/>
      <inertia ixx="9.999999747378752e-05" ixy="0.0" ixz="0.0" iyy="9.999999747378752e-05" iyz="0.0" izz="9.999999747378752e-05"/>
    </inertial>
  </link>
  <joint name="r_gripper_l_finger_joint" type="revolute">
    <origin xyz="0.07690999656915665 0.009999999776482582 0.0" rpy="0.0 0.0 0.0"/>
    <axis xyz="0.0 0.0 1.0"/>
    <parent link="r_gripper_palm_link"/>
    <child link="r_gripper_l_finger_link"/>
    <limit effort="1000.0" lower="0.0" upper="0.5479999780654907" velocity="0.5"/>
  </joint>
  <link name="r_gripper_l_finger_link">
    <inertial>
      <origin xyz="0.03598000109195709 0.01730000041425228 -0.0016400000313296914" rpy="-1.769425868988037 -0.09359461069107056 -0.009991270489990711"/>
      <mass value="0.17125999927520752"/>
      <inertia ixx="7.662394637009129e-05" ixy="0.0" ixz="0.0" iyy="0.0001813359122024849" iyz="0.0" izz="0.00019773963140323758"/>
    </inertial>
    <visual name="SM_r_gripper_l_finger_link_visual_0">
      <origin xyz="0.0 0.0 0.0" rpy="0.0 0.0 0.0"/>
      <geometry>
        <mesh filename="file://pr2/meshes/obj/l_finger.obj"/>
      </geometry>
    </visual>
    <collision name="SM_r_gripper_l_finger_link_collision_0">
      <origin xyz="0.0 0.0 0.0" rpy="0.0 0.0 0.0"/>
      <geometry>
        <mesh filename="file://pr2/meshes/stl/l_finger.stl"/>
      </geometry>
    </collision>
  </link>
  <joint name="r_gripper_l_finger_tip_joint" type="revolute">
    <origin xyz="0.09137000143527985 0.00494999997317791 0.0" rpy="0.0 0.0 0.0"/>
    <axis xyz="0.0 0.0 -1.0"/>
    <parent link="r_gripper_l_finger_link"/>
    <child link="r_gripper_l_finger_tip_link"/>
    <limit effort="1000.0" lower="0.0" upper="0.5479999780654907" velocity="0.5"/>
  </joint>
  <link name="r_gripper_l_finger_tip_link">
    <inertial>
      <origin xyz="0.004230000078678131 0.002839999971911311 0.0" rpy="0.0 0.0 -0.7214871644973755"/>
      <mass value="0.044190000742673874"/>
      <inertia ixx="3.236244992876891e-06" ixy="0.0" ixz="0.0" iyy="1.5004895431047771e-05" iyz="0.0" izz="1.5417679605889134e-05"/>
    </inertial>
    <visual name="SM_r_gripper_l_finger_tip_link_visual_0">
      <origin xyz="0.0 0.0 0.0" rpy="0.0 0.0 0.0"/>
      <geometry>
        <mesh filename="file://pr2/meshes/obj/l_finger_tip.obj"/>
      </geometry>
    </visual>
    <collision name="SM_r_gripper_l_finger_tip_link_collision_0">
      <origin xyz="0.0 0.0 0.0" rpy="0.0 0.0 0.0"/>
      <geometry>
        <mesh filename="file://pr2/meshes/stl/l_finger_tip.stl"/>
      </geometry>
    </collision>
  </link>
  <joint name="r_gripper_r_finger_joint" type="revolute">
    <origin xyz="0.07690999656915665 -0.009999999776482582 0.0" rpy="0.0 0.0 0.0"/>
    <axis xyz="0.0 0.0 -1.0"/>
    <parent link="r_gripper_palm_link"/>
    <child link="r_gripper_r_finger_link"/>
    <limit effort="1000.0" lower="0.0" upper="0.5479999780654907" velocity="0.5"/>
  </joint>
  <link name="r_gripper_r_finger_link">
    <inertial>
      <origin xyz="0.035760000348091125 -0.01735999993979931 -0.0009500000160187483" rpy="1.7210417985916138 -0.07956461608409882 0.015573489479720592"/>
      <mass value="0.17388999462127686"/>
      <inertia ixx="7.668467151233926e-05" ixy="0.0" ixz="0.0" iyy="0.00018134000129066408" iyz="0.0" izz="0.00019890314433723688"/>
    </inertial>
    <visual name="SM_r_gripper_r_finger_link_visual_0">
      <origin xyz="0.0 0.0 0.0" rpy="3.1415927410125732 0.0 0.0"/>
      <geometry>
        <mesh filename="file://pr2/meshes/obj/l_finger.obj"/>
      </geometry>
    </visual>
    <collision name="SM_r_gripper_r_finger_link_collision_0">
      <origin xyz="0.0 0.0 0.0" rpy="3.1415927410125732 0.0 0.0"/>
      <geometry>
        <mesh filename="file://pr2/meshes/stl/l_finger.stl"/>
      </geometry>
    </collision>
  </link>
  <joint name="r_gripper_r_finger_tip_joint" type="revolute">
    <origin xyz="0.09137000143527985 -0.00494999997317791 0.0" rpy="0.0 0.0 0.0"/>
    <axis xyz="0.0 0.0 1.0"/>
    <parent link="r_gripper_r_finger_link"/>
    <child link="r_gripper_r_finger_tip_link"/>
    <limit effort="1000.0" lower="0.0" upper="0.5479999780654907" velocity="0.5"/>
  </joint>
  <link name="r_gripper_r_finger_tip_link">
    <inertial>
      <origin xyz="0.004230000078678131 -0.002839999971911311 0.0" rpy="0.0 0.0 0.7214871644973755"/>
      <mass value="0.044190000742673874"/>
      <inertia ixx="3.236244992876891e-06" ixy="0.0" ixz="0.0" iyy="1.5004895431047771e-05" iyz="0.0" izz="1.5417679605889134e-05"/>
    </inertial>
    <visual name="SM_r_gripper_r_finger_tip_link_visual_0">
      <origin xyz="0.0 0.0 0.0" rpy="3.1415927410125732 0.0 0.0"/>
      <geometry>
        <mesh filename="file://pr2/meshes/obj/l_finger_tip.obj"/>
      </geometry>
    </visual>
    <collision name="SM_r_gripper_r_finger_tip_link_collision_0">
      <origin xyz="0.0 0.0 0.0" rpy="3.1415927410125732 0.0 0.0"/>
      <geometry>
        <mesh filename="file://pr2/meshes/stl/l_finger_tip.stl"/>
      </geometry>
    </collision>
  </link>
  <joint name="r_gripper_joint" type="fixed">
    <origin xyz="0 0 0" rpy="0 0 0"/>
    <parent link="r_gripper_r_finger_tip_link"/>
    <child link="r_gripper_l_finger_tip_frame"/>
  </joint>
  <link name="r_gripper_l_finger_tip_frame">
    <inertial>
      <origin xyz="0.0 0.0 0.0" rpy="0.0 0.0 0.0"/>
      <mass value="0.0"/>
      <inertia ixx="0.0" ixy="0.0" ixz="0.0" iyy="0.0" iyz="0.0" izz="0.0"/>
    </inertial>
  </link>
  <joint name="r_forearm_cam_frame_joint" type="fixed">
    <origin xyz="0.135 0.0 0.044" rpy="1.5707963705062866 -0.5628686547279358 0.0"/>
    <parent link="r_forearm_roll_link"/>
    <child link="r_forearm_cam_frame"/>
  </joint>
  <link name="r_forearm_cam_frame">
    <inertial>
      <origin xyz="0.0 0.0 0.0" rpy="0.0 0.0 0.0"/>
      <mass value="0.009999999776482582"/>
      <inertia ixx="0.0010000000474974513" ixy="0.0" ixz="0.0" iyy="0.0010000000474974513" iyz="0.0" izz="0.0010000000474974513"/>
    </inertial>
  </link>
  <joint name="r_forearm_cam_optical_frame_joint" type="fixed">
    <origin xyz="0.0 0.0 0.0" rpy="-1.5707963705062866 0.0 -1.5707963705062866"/>
    <parent link="r_forearm_cam_frame"/>
    <child link="r_forearm_cam_optical_frame"/>
  </joint>
  <link name="r_forearm_cam_optical_frame">
    <inertial>
      <origin xyz="0.0 0.0 0.0" rpy="0.0 0.0 0.0"/>
      <mass value="0.0"/>
      <inertia ixx="0.0" ixy="0.0" ixz="0.0" iyy="0.0" iyz="0.0" izz="0.0"/>
    </inertial>
  </link>
  <joint name="l_shoulder_pan_joint" type="revolute">
    <origin xyz="0.0 0.18799999356269836 0.0" rpy="0.0 0.0 0.0"/>
    <axis xyz="0.0 0.0 1.0"/>
    <parent link="torso_lift_link"/>
    <child link="l_shoulder_pan_link"/>
    <limit effort="30.0" lower="-0.7146018147468567" upper="2.285398244857788" velocity="2.0880000591278076"/>
  </joint>
  <link name="l_shoulder_pan_link">
    <inertial>
      <origin xyz="-0.0012009999481961131 0.0245130006223917 -0.0982310026884079" rpy="1.905988335609436 -1.3407824039459229 0.5029529929161072"/>
      <mass value="25.7993221282959"/>
      <inertia ixx="0.24203263223171234" ixy="0.0" ixz="0.0" iyy="0.8377005457878113" iyz="0.0" izz="0.9342013597488403"/>
    </inertial>
    <visual name="SM_l_shoulder_pan_link_visual_0">
      <origin xyz="0.0 0.0 0.0" rpy="0.0 0.0 0.0"/>
      <geometry>
        <mesh filename="file://pr2/meshes/obj/shoulder_pan.obj"/>
      </geometry>
    </visual>
    <collision name="SM_l_shoulder_pan_link_collision_0">
      <origin xyz="0.0 0.0 0.0" rpy="0.0 0.0 0.0"/>
      <geometry>
        <mesh filename="file://pr2/meshes/stl/shoulder_pan.stl"/>
      </geometry>
    </collision>
  </link>
  <joint name="l_shoulder_lift_joint" type="revolute">
    <origin xyz="0.10000000149011612 0.0 0.0" rpy="0.0 0.0 0.0"/>
    <axis xyz="0.0 1.0 0.0"/>
    <parent link="l_shoulder_pan_link"/>
    <child link="l_shoulder_lift_link"/>
    <limit effort="30.0" lower="-0.5235999822616577" upper="1.396299958229065" velocity="2.0820000171661377"/>
  </joint>
  <link name="l_shoulder_lift_link">
    <inertial>
      <origin xyz="0.021950000897049904 -0.026639999821782112 -0.03127000108361244" rpy="1.4646769762039185 -0.44314050674438477 -0.7496954798698425"/>
      <mass value="2.749880075454712"/>
      <inertia ixx="0.015168089419603348" ixy="0.0" ixz="0.0" iyy="0.020730163902044296" iyz="0.0" izz="0.026187369599938393"/>
    </inertial>
    <visual name="SM_l_shoulder_lift_link_visual_0">
      <origin xyz="0.0 0.0 0.0" rpy="0.0 0.0 0.0"/>
      <geometry>
        <mesh filename="file://pr2/meshes/obj/shoulder_lift.obj"/>
      </geometry>
    </visual>
    <collision name="SM_l_shoulder_lift_link_collision_0">
      <origin xyz="0.0 0.0 0.0" rpy="0.0 0.0 0.0"/>
      <geometry>
        <mesh filename="file://pr2/meshes/stl/shoulder_lift.stl"/>
      </geometry>
    </collision>
  </link>
  <joint name="l_upper_arm_roll_joint" type="revolute">
    <origin xyz="0.0 0.0 0.0" rpy="0.0 0.0 0.0"/>
    <axis xyz="1.0 0.0 0.0"/>
    <parent link="l_shoulder_lift_link"/>
    <child link="l_upper_arm_roll_link"/>
    <limit effort="30.0" lower="-0.800000011920929" upper="3.9000000953674316" velocity="3.2699999809265137"/>
  </joint>
  <link name="l_upper_arm_roll_link">
    <inertial>
      <origin xyz="0.0 0.0 0.0" rpy="0.0 0.0 0.0"/>
      <mass value="0.10000000149011612"/>
      <inertia ixx="0.009999999776482582" ixy="0.0" ixz="0.0" iyy="0.009999999776482582" iyz="0.0" izz="0.009999999776482582"/>
    </inertial>
    <visual name="SM_l_upper_arm_roll_link_visual_0">
      <origin xyz="0.0 0.0 0.0" rpy="0.0 0.0 0.0"/>
      <geometry>
        <mesh filename="file://pr2/meshes/stl/upper_arm_roll.stl"/>
      </geometry>
    </visual>
    <collision name="SM_l_upper_arm_roll_link_collision_0">
      <origin xyz="0.0 0.0 0.0" rpy="0.0 0.0 0.0"/>
      <geometry>
        <mesh filename="file://pr2/meshes/stl/upper_arm_roll_L.stl"/>
      </geometry>
    </collision>
  </link>
  <joint name="l_upper_arm_link_joint" type="fixed">
    <origin xyz="0.0 0.0 0.0" rpy="0.0 0.0 0.0"/>
    <parent link="l_upper_arm_roll_link"/>
    <child link="l_upper_arm_link"/>
  </joint>
  <link name="l_upper_arm_link">
    <inertial>
      <origin xyz="0.21404999494552612 0.016580000519752502 -0.0005699999746866524" rpy="0.20228567719459534 0.00977403949946165 0.05681125447154045"/>
      <mass value="6.017690181732178"/>
      <inertia ixx="0.0151071073487401" ixy="0.0" ixz="0.0" iyy="0.07488211989402771" iyz="0.0" izz="0.07606969773769379"/>
    </inertial>
    <visual name="SM_l_upper_arm_link_visual_0">
      <origin xyz="0.0 0.0 0.0" rpy="0.0 0.0 0.0"/>
      <geometry>
        <mesh filename="file://pr2/meshes/obj/upper_arm.obj"/>
      </geometry>
    </visual>
    <collision name="SM_l_upper_arm_link_collision_0">
      <origin xyz="0.0 0.0 0.0" rpy="0.0 0.0 0.0"/>
      <geometry>
        <mesh filename="file://pr2/meshes/stl/upper_arm.stl"/>
      </geometry>
    </collision>
  </link>
  <joint name="l_elbow_flex_joint" type="revolute">
    <origin xyz="0.4000000059604645 0.0 0.0" rpy="0.0 0.0 0.0"/>
    <axis xyz="0.0 1.0 0.0"/>
    <parent link="l_upper_arm_link"/>
    <child link="l_elbow_flex_link"/>
    <limit effort="30.0" lower="-2.3213000297546387" upper="0.0" velocity="3.299999952316284"/>
  </joint>
  <link name="l_elbow_flex_link">
    <inertial>
      <origin xyz="0.01013999991118908 0.00031999999191612005 -0.012109999544918537" rpy="1.5263210535049438 0.7122388482093811 -0.056482091546058655"/>
      <mass value="1.9032700061798096"/>
      <inertia ixx="0.003089768812060356" ixy="0.0" ixz="0.0" iyy="0.003964767791330814" iyz="0.0" izz="0.00441851606592536"/>
    </inertial>
    <visual name="SM_l_elbow_flex_link_visual_0">
      <origin xyz="0.0 0.0 0.0" rpy="0.0 0.0 0.0"/>
      <geometry>
        <mesh filename="file://pr2/meshes/obj/elbow_flex.obj"/>
      </geometry>
    </visual>
    <collision name="SM_l_elbow_flex_link_collision_0">
      <origin xyz="0.0 0.0 0.0" rpy="0.0 0.0 0.0"/>
      <geometry>
        <mesh filename="file://pr2/meshes/stl/elbow_flex.stl"/>
      </geometry>
    </collision>
  </link>
  <joint name="l_forearm_roll_joint" type="continuous">
    <origin xyz="0.0 0.0 0.0" rpy="0.0 0.0 0.0"/>
    <axis xyz="1.0 0.0 0.0"/>
    <parent link="l_elbow_flex_link"/>
    <child link="l_forearm_roll_link"/>
  </joint>
  <link name="l_forearm_roll_link">
    <inertial>
      <origin xyz="0.0 0.0 0.0" rpy="0.0 0.0 0.0"/>
      <mass value="0.10000000149011612"/>
      <inertia ixx="0.009999999776482582" ixy="0.0" ixz="0.0" iyy="0.009999999776482582" iyz="0.0" izz="0.009999999776482582"/>
    </inertial>
    <visual name="SM_l_forearm_roll_link_visual_0">
      <origin xyz="0.0 0.0 0.0" rpy="0.0 0.0 0.0"/>
      <geometry>
        <mesh filename="file://pr2/meshes/stl/forearm_roll.stl"/>
      </geometry>
    </visual>
    <collision name="SM_l_forearm_roll_link_collision_0">
      <origin xyz="0.0 0.0 0.0" rpy="0.0 0.0 0.0"/>
      <geometry>
        <mesh filename="file://pr2/meshes/stl/forearm_roll_L.stl"/>
      </geometry>
    </collision>
  </link>
  <joint name="l_forearm_link_joint" type="fixed">
    <origin xyz="0.0 0.0 0.0" rpy="0.0 0.0 0.0"/>
    <parent link="l_forearm_roll_link"/>
    <child link="l_forearm_link"/>
  </joint>
  <link name="l_forearm_link">
    <inertial>
      <origin xyz="0.18791000545024872 -0.00016999999934341758 -0.009119999594986439" rpy="0.006317686755210161 0.055042218416929245 -0.00461096316576004"/>
      <mass value="2.5796799659729004"/>
      <inertia ixx="0.0036089171189814806" ixy="0.0" ixz="0.0" iyy="0.015077545307576656" iyz="0.0" izz="0.01663258671760559"/>
    </inertial>
    <visual name="SM_l_forearm_link_visual_0">
      <origin xyz="0.0 0.0 0.0" rpy="0.0 0.0 0.0"/>
      <geometry>
        <mesh filename="file://pr2/meshes/obj/forearm.obj"/>
      </geometry>
    </visual>
    <collision name="SM_l_forearm_link_collision_0">
      <origin xyz="0.0 0.0 0.0" rpy="0.0 0.0 0.0"/>
      <geometry>
        <mesh filename="file://pr2/meshes/stl/forearm.stl"/>
      </geometry>
    </collision>
  </link>
  <joint name="l_wrist_flex_joint" type="revolute">
    <origin xyz="0.32100000977516174 0.0 0.0" rpy="0.0 0.0 0.0"/>
    <axis xyz="0.0 1.0 0.0"/>
    <parent link="l_forearm_link"/>
    <child link="l_wrist_flex_link"/>
    <limit effort="10.0" lower="-2.180000066757202" upper="0.0" velocity="3.078000068664551"/>
  </joint>
  <link name="l_wrist_flex_link">
    <inertial>
      <origin xyz="-0.0015699999639764428 0.0 -0.000750000006519258" rpy="1.92262864112854 0.0005117869004607201 -1.5701563358306885"/>
      <mass value="0.6140199899673462"/>
      <inertia ixx="0.00019824413175228983" ixy="0.0" ixz="0.0" iyy="0.0006433910457417369" iyz="0.0" izz="0.0006527714431285858"/>
    </inertial>
    <visual name="SM_l_wrist_flex_link_visual_0">
      <origin xyz="0.0 0.0 0.0" rpy="0.0 0.0 0.0"/>
      <geometry>
        <mesh filename="file://pr2/meshes/obj/wrist_flex.obj"/>
      </geometry>
    </visual>
    <collision name="SM_l_wrist_flex_link_collision_0">
      <origin xyz="0.0 0.0 0.0" rpy="0.0 0.0 0.0"/>
      <geometry>
        <mesh filename="file://pr2/meshes/stl/wrist_flex.stl"/>
      </geometry>
    </collision>
  </link>
  <joint name="l_wrist_roll_joint" type="continuous">
    <origin xyz="0.0 0.0 0.0" rpy="0.0 0.0 0.0"/>
    <axis xyz="1.0 0.0 0.0"/>
    <parent link="l_wrist_flex_link"/>
    <child link="l_wrist_roll_link"/>
  </joint>
  <link name="l_wrist_roll_link">
    <inertial>
      <origin xyz="0.0 0.0 0.0" rpy="0.0 0.0 0.0"/>
      <mass value="0.10000000149011612"/>
      <inertia ixx="0.009999999776482582" ixy="0.0" ixz="0.0" iyy="0.009999999776482582" iyz="0.0" izz="0.009999999776482582"/>
    </inertial>
    <visual name="SM_l_wrist_roll_link_visual_0">
      <origin xyz="0.0 0.0 0.0" rpy="0.0 0.0 0.0"/>
      <geometry>
        <mesh filename="file://pr2/meshes/stl/wrist_roll.stl"/>
      </geometry>
    </visual>
    <collision name="SM_l_wrist_roll_link_collision_0">
      <origin xyz="0.0 0.0 0.0" rpy="0.0 0.0 0.0"/>
      <geometry>
        <mesh filename="file://pr2/meshes/stl/wrist_roll_L.stl"/>
      </geometry>
    </collision>
  </link>
  <joint name="l_gripper_palm_link_joint" type="fixed">
    <origin xyz="0.0 0.0 0.0" rpy="0.0 0.0 0.0"/>
    <parent link="l_wrist_roll_link"/>
    <child link="l_gripper_palm_link"/>
  </joint>
  <link name="l_gripper_palm_link">
    <inertial>
      <origin xyz="0.06622999906539917 0.0005300000193528831 -0.0011899999808520079" rpy="0.0029361415654420853 -0.0018384623108431697 0.0484548881649971"/>
      <mass value="0.5800700187683105"/>
      <inertia ixx="0.000351471098838374" ixy="0.0" ixz="0.0" iyy="0.0006781778647564352" iyz="0.0" izz="0.0008656365098431706"/>
    </inertial>
    <visual name="SM_l_gripper_palm_link_visual_0">
      <origin xyz="0.0 0.0 0.0" rpy="0.0 0.0 0.0"/>
      <geometry>
        <mesh filename="file://pr2/meshes/obj/gripper_palm.obj"/>
      </geometry>
    </visual>
    <collision name="SM_l_gripper_palm_link_collision_0">
      <origin xyz="0.0 0.0 0.0" rpy="0.0 0.0 0.0"/>
      <geometry>
        <mesh filename="file://pr2/meshes/stl/gripper_palm.stl"/>
      </geometry>
    </collision>
  </link>
  <joint name="l_gripper_led_frame_joint" type="fixed">
    <origin xyz="0.0513 0.0 0.0244" rpy="0.0 0.0 0.0"/>
    <parent link="l_gripper_palm_link"/>
    <child link="l_gripper_led_frame"/>
  </joint>
  <link name="l_gripper_led_frame">
    <inertial>
      <origin xyz="0.0 0.0 0.0" rpy="0.0 0.0 0.0"/>
      <mass value="0.0"/>
      <inertia ixx="0.0" ixy="0.0" ixz="0.0" iyy="0.0" iyz="0.0" izz="0.0"/>
    </inertial>
  </link>
  <joint name="l_gripper_motor_accelerometer_link_joint" type="fixed">
    <origin xyz="0.0 0.0 0.0" rpy="0.0 0.0 0.0"/>
    <parent link="l_gripper_palm_link"/>
    <child link="l_gripper_motor_accelerometer_link"/>
  </joint>
  <link name="l_gripper_motor_accelerometer_link">
    <inertial>
      <origin xyz="0.0 0.0 0.0" rpy="0.0 0.0 0.0"/>
      <mass value="0.0010000000474974513"/>
      <inertia ixx="0.0010000000474974513" ixy="0.0" ixz="0.0" iyy="0.0010000000474974513" iyz="0.0" izz="0.0010000000474974513"/>
    </inertial>
    <visual name="SM_l_gripper_motor_accelerometer_link_visual_0">
      <origin xyz="0.0 0.0 0.0" rpy="0.0 0.0 0.0"/>
      <geometry>
        <box size="0.0010000000474974513 0.0010000000474974513 0.0010000000474974513"/>
      </geometry>
    </visual>
    <collision name="SM_l_gripper_motor_accelerometer_link_collision_0">
      <origin xyz="0.0 0.0 0.0" rpy="0.0 0.0 0.0"/>
      <geometry>
        <box size="0.0010000000474974513 0.0010000000474974513 0.0010000000474974513"/>
      </geometry>
    </collision>
  </link>
  <joint name="l_gripper_tool_frame_joint" type="fixed">
    <origin xyz="0.18 0.0 0.0" rpy="0.0 0.0 0.0"/>
    <parent link="l_gripper_palm_link"/>
    <child link="l_gripper_tool_frame"/>
  </joint>
  <link name="l_gripper_tool_frame">
    <inertial>
      <origin xyz="0.0 0.0 0.0" rpy="0.0 0.0 0.0"/>
      <mass value="0.0"/>
      <inertia ixx="0.0" ixy="0.0" ixz="0.0" iyy="0.0" iyz="0.0" izz="0.0"/>
    </inertial>
  </link>
  <joint name="l_gripper_motor_slider_joint" type="fixed">
    <origin xyz="0.1682800054550171 0.0 0.0" rpy="0.0 0.0 0.0"/>
    <parent link="l_gripper_palm_link"/>
    <child link="l_gripper_motor_slider_link"/>
  </joint>
  <link name="l_gripper_motor_slider_link">
    <inertial>
      <origin xyz="0.0 0.0 0.0" rpy="0.0 0.0 0.0"/>
      <mass value="0.009999999776482582"/>
      <inertia ixx="0.0010000000474974513" ixy="0.0" ixz="0.0" iyy="0.0010000000474974513" iyz="0.0" izz="0.0010000000474974513"/>
    </inertial>
  </link>
  <joint name="l_gripper_motor_screw_joint" type="fixed">
    <origin xyz="0.0 0.0 0.0" rpy="0.0 0.0 0.0"/>
    <parent link="l_gripper_motor_slider_link"/>
    <child link="l_gripper_motor_screw_link"/>
  </joint>
  <link name="l_gripper_motor_screw_link">
    <inertial>
      <origin xyz="0.0 0.0 0.0" rpy="0.0 0.0 0.0"/>
      <mass value="0.009999999776482582"/>
      <inertia ixx="9.999999747378752e-05" ixy="0.0" ixz="0.0" iyy="9.999999747378752e-05" iyz="0.0" izz="9.999999747378752e-05"/>
    </inertial>
  </link>
  <joint name="l_gripper_l_finger_joint" type="revolute">
    <origin xyz="0.07690999656915665 0.009999999776482582 0.0" rpy="0.0 0.0 0.0"/>
    <axis xyz="0.0 0.0 1.0"/>
    <parent link="l_gripper_palm_link"/>
    <child link="l_gripper_l_finger_link"/>
    <limit effort="1000.0" lower="0.0" upper="0.5479999780654907" velocity="0.5"/>
  </joint>
  <link name="l_gripper_l_finger_link">
    <inertial>
      <origin xyz="0.03598000109195709 0.01730000041425228 -0.0016400000313296914" rpy="-1.769425868988037 -0.09359461069107056 -0.009991270489990711"/>
      <mass value="0.17125999927520752"/>
      <inertia ixx="7.662394637009129e-05" ixy="0.0" ixz="0.0" iyy="0.0001813359122024849" iyz="0.0" izz="0.00019773963140323758"/>
    </inertial>
    <visual name="SM_l_gripper_l_finger_link_visual_0">
      <origin xyz="0.0 0.0 0.0" rpy="0.0 0.0 0.0"/>
      <geometry>
        <mesh filename="file://pr2/meshes/obj/l_finger.obj"/>
      </geometry>
    </visual>
    <collision name="SM_l_gripper_l_finger_link_collision_0">
      <origin xyz="0.0 0.0 0.0" rpy="0.0 0.0 0.0"/>
      <geometry>
        <mesh filename="file://pr2/meshes/stl/l_finger.stl"/>
      </geometry>
    </collision>
  </link>
  <joint name="l_gripper_l_finger_tip_joint" type="revolute">
    <origin xyz="0.09137000143527985 0.00494999997317791 0.0" rpy="0.0 0.0 0.0"/>
    <axis xyz="0.0 0.0 -1.0"/>
    <parent link="l_gripper_l_finger_link"/>
    <child link="l_gripper_l_finger_tip_link"/>
    <limit effort="1000.0" lower="0.0" upper="0.5479999780654907" velocity="0.5"/>
  </joint>
  <link name="l_gripper_l_finger_tip_link">
    <inertial>
      <origin xyz="0.004230000078678131 0.002839999971911311 0.0" rpy="0.0 0.0 -0.7214871644973755"/>
      <mass value="0.044190000742673874"/>
      <inertia ixx="3.236244992876891e-06" ixy="0.0" ixz="0.0" iyy="1.5004895431047771e-05" iyz="0.0" izz="1.5417679605889134e-05"/>
    </inertial>
    <visual name="SM_l_gripper_l_finger_tip_link_visual_0">
      <origin xyz="0.0 0.0 0.0" rpy="0.0 0.0 0.0"/>
      <geometry>
        <mesh filename="file://pr2/meshes/obj/l_finger_tip.obj"/>
      </geometry>
    </visual>
    <collision name="SM_l_gripper_l_finger_tip_link_collision_0">
      <origin xyz="0.0 0.0 0.0" rpy="0.0 0.0 0.0"/>
      <geometry>
        <mesh filename="file://pr2/meshes/stl/l_finger_tip.stl"/>
      </geometry>
    </collision>
  </link>
  <joint name="l_gripper_r_finger_joint" type="revolute">
    <origin xyz="0.07690999656915665 -0.009999999776482582 0.0" rpy="0.0 0.0 0.0"/>
    <axis xyz="0.0 0.0 -1.0"/>
    <parent link="l_gripper_palm_link"/>
    <child link="l_gripper_r_finger_link"/>
    <limit effort="1000.0" lower="0.0" upper="0.5479999780654907" velocity="0.5"/>
  </joint>
  <link name="l_gripper_r_finger_link">
    <inertial>
      <origin xyz="0.035760000348091125 -0.01735999993979931 -0.0009500000160187483" rpy="1.7210417985916138 -0.07956461608409882 0.015573489479720592"/>
      <mass value="0.17388999462127686"/>
      <inertia ixx="7.668467151233926e-05" ixy="0.0" ixz="0.0" iyy="0.00018134000129066408" iyz="0.0" izz="0.00019890314433723688"/>
    </inertial>
    <visual name="SM_l_gripper_r_finger_link_visual_0">
      <origin xyz="0.0 0.0 0.0" rpy="3.1415927410125732 0.0 0.0"/>
      <geometry>
        <mesh filename="file://pr2/meshes/obj/l_finger.obj"/>
      </geometry>
    </visual>
    <collision name="SM_l_gripper_r_finger_link_collision_0">
      <origin xyz="0.0 0.0 0.0" rpy="3.1415927410125732 0.0 0.0"/>
      <geometry>
        <mesh filename="file://pr2/meshes/stl/l_finger.stl"/>
      </geometry>
    </collision>
  </link>
  <joint name="l_gripper_r_finger_tip_joint" type="revolute">
    <origin xyz="0.09137000143527985 -0.00494999997317791 0.0" rpy="0.0 0.0 0.0"/>
    <axis xyz="0.0 0.0 1.0"/>
    <parent link="l_gripper_r_finger_link"/>
    <child link="l_gripper_r_finger_tip_link"/>
    <limit effort="1000.0" lower="0.0" upper="0.5479999780654907" velocity="0.5"/>
  </joint>
  <link name="l_gripper_r_finger_tip_link">
    <inertial>
      <origin xyz="0.004230000078678131 -0.002839999971911311 0.0" rpy="0.0 0.0 0.7214871644973755"/>
      <mass value="0.044190000742673874"/>
      <inertia ixx="3.236244992876891e-06" ixy="0.0" ixz="0.0" iyy="1.5004895431047771e-05" iyz="0.0" izz="1.5417679605889134e-05"/>
    </inertial>
    <visual name="SM_l_gripper_r_finger_tip_link_visual_0">
      <origin xyz="0.0 0.0 0.0" rpy="3.1415927410125732 0.0 0.0"/>
      <geometry>
        <mesh filename="file://pr2/meshes/obj/l_finger_tip.obj"/>
      </geometry>
    </visual>
    <collision name="SM_l_gripper_r_finger_tip_link_collision_0">
      <origin xyz="0.0 0.0 0.0" rpy="3.1415927410125732 0.0 0.0"/>
      <geometry>
        <mesh filename="file://pr2/meshes/stl/l_finger_tip.stl"/>
      </geometry>
    </collision>
  </link>
  <joint name="l_gripper_joint" type="fixed">
    <origin xyz="0 0 0" rpy="0 0 0"/>
    <parent link="l_gripper_r_finger_tip_link"/>
    <child link="l_gripper_l_finger_tip_frame"/>
  </joint>
  <link name="l_gripper_l_finger_tip_frame">
    <inertial>
      <origin xyz="0.0 0.0 0.0" rpy="0.0 0.0 0.0"/>
      <mass value="0.0"/>
      <inertia ixx="0.0" ixy="0.0" ixz="0.0" iyy="0.0" iyz="0.0" izz="0.0"/>
    </inertial>
  </link>
  <joint name="l_forearm_cam_frame_joint" type="fixed">
    <origin xyz="0.135 0.0 0.044" rpy="-1.5707963705062866 -0.5628686547279358 0.0"/>
    <parent link="l_forearm_roll_link"/>
    <child link="l_forearm_cam_frame"/>
  </joint>
  <link name="l_forearm_cam_frame">
    <inertial>
      <origin xyz="0.0 0.0 0.0" rpy="0.0 0.0 0.0"/>
      <mass value="0.009999999776482582"/>
      <inertia ixx="0.0010000000474974513" ixy="0.0" ixz="0.0" iyy="0.0010000000474974513" iyz="0.0" izz="0.0010000000474974513"/>
    </inertial>
  </link>
  <joint name="l_forearm_cam_optical_frame_joint" type="fixed">
    <origin xyz="0.0 0.0 0.0" rpy="-1.5707963705062866 0.0 -1.5707963705062866"/>
    <parent link="l_forearm_cam_frame"/>
    <child link="l_forearm_cam_optical_frame"/>
  </joint>
  <link name="l_forearm_cam_optical_frame">
    <inertial>
      <origin xyz="0.0 0.0 0.0" rpy="0.0 0.0 0.0"/>
      <mass value="0.0"/>
      <inertia ixx="0.0" ixy="0.0" ixz="0.0" iyy="0.0" iyz="0.0" izz="0.0"/>
    </inertial>
  </link>
  <joint name="torso_lift_motor_screw_joint" type="fixed">
    <origin xyz="-0.15000000596046448 0.0 0.699999988079071" rpy="0.0 0.0 0.0"/>
    <parent link="base_link"/>
    <child link="torso_lift_motor_screw_link"/>
  </joint>
  <link name="torso_lift_motor_screw_link">
    <inertial>
      <origin xyz="0.0 0.0 0.0" rpy="0.0 0.0 0.0"/>
      <mass value="1.0"/>
      <inertia ixx="0.0010000000474974513" ixy="0.0" ixz="0.0" iyy="0.0010000000474974513" iyz="0.0" izz="0.0010000000474974513"/>
    </inertial>
  </link>
</robot>