<?xml version="1.0" ?>
<mujoco model="pr2">
	<compiler meshdir="pr2/meshes" texturedir="pr2/textures" angle="radian" autolimits="true" balanceinertia="true" inertiafromgeom="true" />
	<default>
		<default class="pr2_visual">
			<geom contype="0" conaffinity="0"/>
		</default>
		<default class="pr2_collision">
			<geom rgba="0.9 0.9 0.9 1.0" friction="0.7" solimp="0.95 0.99 0.001" solref="0.004 1"/>
		</default>
	</default>
	<asset>
		<mesh name="base_L" file="stl/base_L.stl" scale="1.0 1.0 1.0"/>
		<mesh name="caster_L" file="stl/caster_L.stl" scale="1.0 1.0 1.0"/>
		<mesh name="torso_lift_L" file="stl/torso_lift_L.stl" scale="1.0 1.0 1.0"/>
		<mesh name="head_pan_L" file="stl/head_pan_L.stl" scale="1.0 1.0 1.0"/>
		<mesh name="head_tilt_L" file="stl/head_tilt_L.stl" scale="1.0 1.0 1.0"/>
		<mesh name="tilting_hokuyo_L" file="stl/tilting_hokuyo_L.stl" scale="1.0 1.0 1.0"/>
		<mesh name="shoulder_pan" file="stl/shoulder_pan.stl" scale="1.0 1.0 1.0"/>
		<mesh name="shoulder_lift" file="stl/shoulder_lift.stl" scale="1.0 1.0 1.0"/>
		<mesh name="upper_arm_roll_L" file="stl/upper_arm_roll_L.stl" scale="1.0 1.0 1.0"/>
		<mesh name="upper_arm" file="stl/upper_arm.stl" scale="1.0 1.0 1.0"/>
		<mesh name="elbow_flex" file="stl/elbow_flex.stl" scale="1.0 1.0 1.0"/>
		<mesh name="forearm_roll_L" file="stl/forearm_roll_L.stl" scale="1.0 1.0 1.0"/>
		<mesh name="forearm" file="stl/forearm.stl" scale="1.0 1.0 1.0"/>
		<mesh name="wrist_flex" file="stl/wrist_flex.stl" scale="1.0 1.0 1.0"/>
		<mesh name="wrist_roll_L" file="stl/wrist_roll_L.stl" scale="1.0 1.0 1.0"/>
		<mesh name="gripper_palm" file="stl/gripper_palm.stl" scale="1.0 1.0 1.0"/>
		<mesh name="l_finger" file="stl/l_finger.stl" scale="1.0 1.0 1.0"/>
		<mesh name="l_finger_tip" file="stl/l_finger_tip.stl" scale="1.0 1.0 1.0"/>
	</asset>
	<worldbody>
		<body name="pr2" pos="0 0 0" quat="1.0 0.0 0.0 0.0" gravcomp="1">
			<joint name="odom_vel_lin_x_joint" type="slide" axis="1.0 0.0 0.0"/>
			<joint name="odom_vel_lin_y_joint" type="slide" axis="0.0 1.0 0.0"/>
			<joint name="odom_vel_ang_z_joint" type="hinge" axis="0.0 0.0 1.0"/>
			<body name="base_footprint" pos="0.0 0.0 0.0" quat="1.0 0.0 0.0 0.0" gravcomp="1">
				<inertial mass="1.0000001111620804e-06" pos="0.0 0.0 0.07100000232458115" quat="0.7071067690849304 0.0 0.7071067690849304 0.0" diaginertia="1.6666670214077195e-13 5.041167927544166e-09 5.041167927544166e-09" />
				<geom name="SM_base_footprint_collision_0" type="box" pos="0.0 0.0 0.07100000232458115" quat="1.0 0.0 0.0 0.0" size="0.0005000000237487257 0.0005000000237487257 0.0005000000237487257" class="pr2_collision" />
				<body name="base_link" pos="0.0 0.0 0.050999999046325684" quat="1.0 0.0 0.0 0.0" gravcomp="1">
					<geom name="SM_base_link_collision_0" type="mesh" pos="0.0 0.0 0.0" quat="1.0 0.0 0.0 0.0" mesh="base_L" class="pr2_collision" />
					<body name="base_laser_link" pos="0.2750000059604645 0.0 0.25200000405311584" quat="1.0 0.0 0.0 0.0" gravcomp="1">
						<inertial mass="0.0" pos="0.0 0.0 0.0" quat="1.0 0.0 0.0 0.0" diaginertia="0.0 0.0 0.0" />
					</body>
					<body name="fr_caster_rotation_link" pos="0.22460000216960907 -0.22460000216960907 0.028200000524520874" quat="1.0 0.0 0.0 0.0" gravcomp="1">
						<inertial mass="2.2135562896728516" pos="-0.0059445747174322605 1.1481000594670832e-09 0.08382795006036758" quat="0.5099974274635315 0.5099974274635315 0.48979854583740234 -0.48979854583740234" diaginertia="0.006514224223792553 0.025800351053476334 0.02824961021542549" />
						<geom name="SM_fr_caster_rotation_link_collision_0" type="mesh" pos="0.0 0.0 0.0" quat="1.0 0.0 0.0 0.0" mesh="caster_L" class="pr2_collision" />
						<joint name="fr_caster_rotation_joint" type="hinge" pos="0.0 0.0 6.938893903907228e-18" axis="0.0 0.0 1.0" />
						<body name="fr_caster_r_wheel_link" pos="0.0 -0.04899999871850014 0.0" quat="1.0 0.0 0.0 0.0" gravcomp="1">
							<inertial mass="0.5975016355514526" pos="0.0 0.0 0.0" quat="0.0 0.0 0.7071067690849304 -0.7071067690849304" diaginertia="0.0008931418415158987 0.0008931418415158987 0.0016711651114746928" />
							<geom name="SM_fr_caster_r_wheel_link_collision_0" type="cylinder" pos="0.0 0.0 0.0" quat="0.7071067690849304 0.7071067690849304 0.0 0.0" size="0.07479199767112732 0.017000000923871994 0.0" class="pr2_collision" />
							<joint name="fr_caster_r_wheel_joint" type="hinge" pos="0.0 0.0 0.0" axis="0.0 1.0 0.0" />
						</body>
						<body name="fr_caster_l_wheel_link" pos="0.0 0.04899999871850014 0.0" quat="1.0 0.0 0.0 0.0" gravcomp="1">
							<inertial mass="0.5975016355514526" pos="0.0 0.0 0.0" quat="0.0 0.0 0.7071067690849304 -0.7071067690849304" diaginertia="0.0008931418415158987 0.0008931418415158987 0.0016711651114746928" />
							<geom name="SM_fr_caster_l_wheel_link_collision_0" type="cylinder" pos="0.0 0.0 0.0" quat="0.7071067690849304 0.7071067690849304 0.0 0.0" size="0.07479199767112732 0.017000000923871994 0.0" class="pr2_collision" />
							<joint name="fr_caster_l_wheel_joint" type="hinge" pos="0.0 0.0 0.0" axis="0.0 1.0 0.0" />
						</body>
					</body>
					<body name="br_caster_rotation_link" pos="-0.22460000216960907 -0.22460000216960907 0.028200000524520874" quat="1.0 0.0 0.0 0.0" gravcomp="1">
						<inertial mass="2.2135562896728516" pos="-0.0059445747174322605 1.1481000594670832e-09 0.08382795006036758" quat="0.5099974274635315 0.5099974274635315 0.48979854583740234 -0.48979854583740234" diaginertia="0.006514224223792553 0.025800351053476334 0.02824961021542549" />
						<geom name="SM_br_caster_rotation_link_collision_0" type="mesh" pos="0.0 0.0 0.0" quat="1.0 0.0 0.0 0.0" mesh="caster_L" class="pr2_collision" />
						<joint name="br_caster_rotation_joint" type="hinge" pos="0.0 0.0 6.938893903907228e-18" axis="0.0 0.0 1.0" />
						<body name="br_caster_r_wheel_link" pos="0.0 -0.04899999871850014 0.0" quat="1.0 0.0 0.0 0.0" gravcomp="1">
							<inertial mass="0.5975016355514526" pos="0.0 0.0 0.0" quat="0.0 0.0 0.7071067690849304 -0.7071067690849304" diaginertia="0.0008931418415158987 0.0008931418415158987 0.0016711651114746928" />
							<geom name="SM_br_caster_r_wheel_link_collision_0" type="cylinder" pos="0.0 0.0 0.0" quat="0.7071067690849304 0.7071067690849304 0.0 0.0" size="0.07479199767112732 0.017000000923871994 0.0" class="pr2_collision" />
							<joint name="br_caster_r_wheel_joint" type="hinge" pos="0.0 0.0 0.0" axis="0.0 1.0 0.0" />
						</body>
						<body name="br_caster_l_wheel_link" pos="0.0 0.04899999871850014 0.0" quat="1.0 0.0 0.0 0.0" gravcomp="1">
							<inertial mass="0.5975016355514526" pos="0.0 0.0 0.0" quat="0.0 0.0 0.7071067690849304 -0.7071067690849304" diaginertia="0.0008931418415158987 0.0008931418415158987 0.0016711651114746928" />
							<geom name="SM_br_caster_l_wheel_link_collision_0" type="cylinder" pos="0.0 0.0 0.0" quat="0.7071067690849304 0.7071067690849304 0.0 0.0" size="0.07479199767112732 0.017000000923871994 0.0" class="pr2_collision" />
							<joint name="br_caster_l_wheel_joint" type="hinge" pos="0.0 0.0 0.0" axis="0.0 1.0 0.0" />
						</body>
					</body>
					<body name="torso_lift_motor_screw_link" pos="-0.15000000596046448 0.0 0.699999988079071" quat="1.0 0.0 0.0 0.0" gravcomp="1">
					</body>
					<body name="base_bellow_link" pos="-0.28999999165534973 0.0 0.800000011920929" quat="1.0 0.0 0.0 0.0" gravcomp="1">
						<inertial mass="5.550000190734863" pos="0.0 0.0 0.0" quat="0.5 0.5 0.5 0.5" diaginertia="0.04278125613927841 0.0644725039601326 0.10494126379489899" />
						<geom name="SM_base_bellow_link_collision_0" type="box" pos="0.0 0.0 0.0" quat="1.0 0.0 0.0 0.0" size="0.02500000037252903 0.1850000023841858 0.15000000596046448" class="pr2_collision" />
					</body>
					<body name="fl_caster_rotation_link" pos="0.22460000216960907 0.22460000216960907 0.028200000524520874" quat="1.0 0.0 0.0 0.0" gravcomp="1">
						<inertial mass="2.2135562896728516" pos="-0.0059445747174322605 1.1481000594670832e-09 0.08382795006036758" quat="0.5099974274635315 0.5099974274635315 0.48979854583740234 -0.48979854583740234" diaginertia="0.006514224223792553 0.025800351053476334 0.02824961021542549" />
						<geom name="SM_fl_caster_rotation_link_collision_0" type="mesh" pos="0.0 0.0 0.0" quat="1.0 0.0 0.0 0.0" mesh="caster_L" class="pr2_collision" />
						<joint name="fl_caster_rotation_joint" type="hinge" pos="0.0 0.0 6.938893903907228e-18" axis="0.0 0.0 1.0" />
						<body name="fl_caster_r_wheel_link" pos="0.0 -0.04899999871850014 0.0" quat="1.0 0.0 0.0 0.0" gravcomp="1">
							<inertial mass="0.5975016355514526" pos="0.0 0.0 0.0" quat="0.0 0.0 0.7071067690849304 -0.7071067690849304" diaginertia="0.0008931418415158987 0.0008931418415158987 0.0016711651114746928" />
							<geom name="SM_fl_caster_r_wheel_link_collision_0" type="cylinder" pos="0.0 0.0 0.0" quat="0.7071067690849304 0.7071067690849304 0.0 0.0" size="0.07479199767112732 0.017000000923871994 0.0" class="pr2_collision" />
							<joint name="fl_caster_r_wheel_joint" type="hinge" pos="0.0 0.0 0.0" axis="0.0 1.0 0.0" />
						</body>
						<body name="fl_caster_l_wheel_link" pos="0.0 0.04899999871850014 0.0" quat="1.0 0.0 0.0 0.0" gravcomp="1">
							<inertial mass="0.5975016355514526" pos="0.0 0.0 0.0" quat="0.0 0.0 0.7071067690849304 -0.7071067690849304" diaginertia="0.0008931418415158987 0.0008931418415158987 0.0016711651114746928" />
							<geom name="SM_fl_caster_l_wheel_link_collision_0" type="cylinder" pos="0.0 0.0 0.0" quat="0.7071067690849304 0.7071067690849304 0.0 0.0" size="0.07479199767112732 0.017000000923871994 0.0" class="pr2_collision" />
							<joint name="fl_caster_l_wheel_joint" type="hinge" pos="0.0 0.0 0.0" axis="0.0 1.0 0.0" />
						</body>
					</body>
					<body name="torso_lift_link" pos="-0.05000000074505806 0.0 0.739674985408783" quat="1.0 0.0 0.0 0.0" gravcomp="1">
						<inertial mass="51.778282165527344" pos="-0.1308211237192154 4.029592215459843e-09 0.016045676544308662" quat="-0.47259053587913513 -0.47259053587913513 -0.5259830951690674 0.5259830951690674" diaginertia="1.7747341394424438 3.3517322540283203 4.134549617767334" />
						<geom name="SM_torso_lift_link_collision_0" type="mesh" pos="0.0 0.0 0.0" quat="1.0 0.0 0.0 0.0" mesh="torso_lift_L" class="pr2_collision" />
						<joint name="torso_lift_joint" type="slide" pos="0.0 0.0 0.0" range="0.0 0.33000001311302185" axis="0.0 0.0 1.0" />
						<body name="r_torso_lift_side_plate_link" pos="0.05350000038743019 -0.20928500592708588 0.17662499845027924" quat="1.0 0.0 0.0 0.0" gravcomp="1">
							<inertial mass="0.0" pos="0.0 0.0 0.0" quat="1.0 0.0 0.0 0.0" diaginertia="0.0 0.0 0.0" />
						</body>
						<body name="head_pan_link" pos="-0.017069999128580093 0.0 0.38144999742507935" quat="1.0 0.0 0.0 0.0" gravcomp="1">
							<inertial mass="7.458215713500977" pos="0.031194353476166725 0.00014981458662077785 -0.00551903061568737" quat="0.041526779532432556 -0.7037166357040405 0.7080620527267456 -0.04131028428673744" diaginertia="0.04139060527086258 0.07164635509252548 0.095054991543293" />
							<geom name="SM_head_pan_link_collision_0" type="mesh" pos="0.0 0.0 0.0" quat="1.0 0.0 0.0 0.0" mesh="head_pan_L" class="pr2_collision" />
							<joint name="head_pan_joint" type="hinge" pos="0.0 0.0 -1.1102230246251565e-16" range="-3.006999969482422 3.006999969482422" axis="0.0 0.0 1.0" />
							<body name="head_tilt_link" pos="0.06800000369548798 0.0 0.0" quat="1.0 0.0 0.0 0.0" gravcomp="1">
								<inertial mass="5.654116153717041" pos="-0.05152539536356926 -1.8105554318026407e-06 0.114493727684021" quat="-1.3094496353005525e-05 0.4793747067451477 2.0897408830933273e-05 0.8776103258132935" diaginertia="0.06123911961913109 0.12264703214168549 0.13844925165176392" />
								<geom name="SM_head_tilt_link_collision_0" type="mesh" pos="0.0 0.0 0.0" quat="1.0 0.0 0.0 0.0" mesh="head_tilt_L" class="pr2_collision" />
								<joint name="head_tilt_joint" type="hinge" pos="0.0 0.0 0.0" range="-0.47123798727989197 1.3962600231170654" axis="0.0 1.0 0.0" />
								<body name="head_plate_frame" pos="0.02319999970495701 0.0 0.06449999660253525" quat="1.0 0.0 0.0 0.0" gravcomp="1">
									<inertial mass="0.0009999999310821295" pos="0.0 0.0 0.0" quat="1.0 0.0 0.0 0.0" diaginertia="1.666666449295917e-08 1.666666449295917e-08 1.666666449295917e-08" />
									<geom name="SM_head_plate_frame_collision_0" type="box" pos="0.0 0.0 0.0" quat="1.0 0.0 0.0 0.0" size="0.004999999888241291 0.004999999888241291 0.004999999888241291" class="pr2_collision" />
									<body name="projector_wg6802418_frame" pos="0.0 0.10999999940395355 0.05460000038146973" quat="1.0 0.0 0.0 0.0" gravcomp="1">
										<inertial mass="0.0" pos="0.0 0.0 0.0" quat="1.0 0.0 0.0 0.0" diaginertia="0.0 0.0 0.0" />
										<body name="projector_wg6802418_child_frame" pos="0.0 0.0 0.0" quat="-0.7071067690849304 0.0 0.7071067690849304 0.0" gravcomp="1">
											<inertial mass="0.0" pos="0.0 0.0 0.0" quat="1.0 0.0 0.0 0.0" diaginertia="0.0 0.0 0.0" />
										</body>
									</body>
									<body name="sensor_mount_link" pos="0.0 0.0 0.0" quat="1.0 0.0 0.0 0.0" gravcomp="1">
										<inertial mass="0.0" pos="0.0 0.0 0.0" quat="1.0 0.0 0.0 0.0" diaginertia="0.0 0.0 0.0" />
										<body name="double_stereo_link" pos="0.0 0.0 0.0" quat="1.0 0.0 0.0 0.0" gravcomp="1">
											<inertial mass="0.0" pos="0.0 0.0 0.0" quat="1.0 0.0 0.0 0.0" diaginertia="0.0 0.0 0.0" />
											<body name="narrow_stereo_link" pos="0.04500000178813934 0.05999999865889549 0.05009999871253967" quat="1.0 0.0 0.0 0.0" gravcomp="1">
												<inertial mass="0.0" pos="0.0 0.0 0.0" quat="1.0 0.0 0.0 0.0" diaginertia="0.0 0.0 0.0" />
												<body name="narrow_stereo_l_stereo_camera_frame" pos="0.0 0.0 0.0" quat="1.0 0.0 0.0 0.0" gravcomp="1">
													<inertial mass="0.0" pos="0.0 0.0 0.0" quat="1.0 0.0 0.0 0.0" diaginertia="0.0 0.0 0.0" />
													<body name="narrow_stereo_r_stereo_camera_frame" pos="0.0 -0.09000000357627869 0.0" quat="1.0 0.0 0.0 0.0" gravcomp="1">
														<inertial mass="0.0" pos="0.0 0.0 0.0" quat="1.0 0.0 0.0 0.0" diaginertia="0.0 0.0 0.0" />
														<body name="narrow_stereo_r_stereo_camera_optical_frame" pos="0.0 0.0 0.0" quat="0.4999999701976776 -0.5 0.5 -0.5" gravcomp="1">
															<inertial mass="0.0" pos="0.0 0.0 0.0" quat="1.0 0.0 0.0 0.0" diaginertia="0.0 0.0 0.0" />
														</body>
													</body>
													<body name="narrow_stereo_l_stereo_camera_optical_frame" pos="0.0 0.0 0.0" quat="0.4999999701976776 -0.5 0.5 -0.5" gravcomp="1">
														<inertial mass="0.0" pos="0.0 0.0 0.0" quat="1.0 0.0 0.0 0.0" diaginertia="0.0 0.0 0.0" />
													</body>
												</body>
												<body name="narrow_stereo_optical_frame" pos="0.0 0.0 0.0" quat="0.4999999701976776 -0.5 0.5 -0.5" gravcomp="1">
													<inertial mass="0.0" pos="0.0 0.0 0.0" quat="1.0 0.0 0.0 0.0" diaginertia="0.0 0.0 0.0" />
												</body>
											</body>
											<body name="wide_stereo_link" pos="0.04500000178813934 0.029999999329447746 0.05009999871253967" quat="1.0 0.0 0.0 0.0" gravcomp="1">
												<inertial mass="0.0" pos="0.0 0.0 0.0" quat="1.0 0.0 0.0 0.0" diaginertia="0.0 0.0 0.0" />
												<body name="wide_stereo_l_stereo_camera_frame" pos="0.0 0.0 0.0" quat="1.0 0.0 0.0 0.0" gravcomp="1">
													<inertial mass="0.0" pos="0.0 0.0 0.0" quat="1.0 0.0 0.0 0.0" diaginertia="0.0 0.0 0.0" />
													<body name="wide_stereo_r_stereo_camera_frame" pos="0.0 -0.09000000357627869 0.0" quat="1.0 0.0 0.0 0.0" gravcomp="1">
														<inertial mass="0.0" pos="0.0 0.0 0.0" quat="1.0 0.0 0.0 0.0" diaginertia="0.0 0.0 0.0" />
														<body name="wide_stereo_r_stereo_camera_optical_frame" pos="0.0 0.0 0.0" quat="0.4999999701976776 -0.5 0.5 -0.5" gravcomp="1">
															<inertial mass="0.0" pos="0.0 0.0 0.0" quat="1.0 0.0 0.0 0.0" diaginertia="0.0 0.0 0.0" />
														</body>
													</body>
													<body name="wide_stereo_l_stereo_camera_optical_frame" pos="0.0 0.0 0.0" quat="0.4999999701976776 -0.5 0.5 -0.5" gravcomp="1">
														<inertial mass="0.0" pos="0.0 0.0 0.0" quat="1.0 0.0 0.0 0.0" diaginertia="0.0 0.0 0.0" />
													</body>
												</body>
												<body name="wide_stereo_optical_frame" pos="0.0 0.0 0.0" quat="0.4999999701976776 -0.5 0.5 -0.5" gravcomp="1">
													<inertial mass="0.0" pos="0.0 0.0 0.0" quat="1.0 0.0 0.0 0.0" diaginertia="0.0 0.0 0.0" />
												</body>
											</body>
										</body>
										<body name="high_def_frame" pos="0.04645700007677078 -0.10999999940395355 0.05460000038146973" quat="1.0 0.0 0.0 0.0" gravcomp="1">
											<inertial mass="0.0" pos="0.0 0.0 0.0" quat="1.0 0.0 0.0 0.0" diaginertia="0.0 0.0 0.0" />
											<body name="high_def_optical_frame" pos="0.0 0.0 0.0" quat="0.4999999701976776 -0.5 0.5 -0.5" gravcomp="1">
												<inertial mass="0.0" pos="0.0 0.0 0.0" quat="1.0 0.0 0.0 0.0" diaginertia="0.0 0.0 0.0" />
											</body>
										</body>
									</body>
								</body>
							</body>
						</body>
						<body name="laser_tilt_mount_link" pos="0.0989300012588501 0.0 0.22699999809265137" quat="1.0 0.0 0.0 0.0" gravcomp="1">
							<inertial mass="1.5732203722000122" pos="-0.006016708444803953 3.2764393975703854e-10 0.0022414783015847206" quat="-0.3104150593280792 0.6353286504745483 0.6353286504745483 -0.3104150593280792" diaginertia="0.002926282351836562 0.004535055253654718 0.005101508926600218" />
							<geom name="SM_laser_tilt_mount_link_collision_0" type="mesh" pos="0.0 0.0 0.0" quat="1.0 0.0 0.0 0.0" mesh="tilting_hokuyo_L" class="pr2_collision" />
							<joint name="laser_tilt_mount_joint" type="hinge" pos="0.0 0.0 -1.1102230246251565e-16" range="-0.7853999733924866 1.483530044555664" axis="0.0 1.0 0.0" />
							<body name="laser_tilt_link" pos="0.0 0.0 0.029999999329447746" quat="1.0 0.0 0.0 0.0" gravcomp="1">
								<inertial mass="0.0" pos="0.0 0.0 0.0" quat="1.0 0.0 0.0 0.0" diaginertia="0.0 0.0 0.0" />
							</body>
						</body>
						<body name="r_shoulder_pan_link" pos="0.0 -0.18799999356269836 0.0" quat="1.0 0.0 0.0 0.0" gravcomp="1">
							<inertial mass="27.858089447021484" pos="-0.007217532955110073 -1.2285015145607758e-05 -0.15199442207813263" quat="0.00025214478955604136 -0.6800189018249512 0.0002595585829112679 0.7331945300102234" diaginertia="0.2705267369747162 1.7231812477111816 1.7425432205200195" />
							<geom name="SM_r_shoulder_pan_link_collision_0" type="mesh" pos="0.0 0.0 0.0" quat="1.0 0.0 0.0 0.0" mesh="shoulder_pan" class="pr2_collision" />
							<joint name="r_shoulder_pan_joint" type="hinge" pos="0.0 0.0 0.0" range="-2.285398244857788 0.7146018147468567" axis="0.0 0.0 1.0" />
							<body name="r_shoulder_lift_link" pos="0.10000000149011612 0.0 0.0" quat="1.0 0.0 0.0 0.0" gravcomp="1">
								<inertial mass="0.32213330268859863" pos="-0.011961976066231728 0.0005128994234837592 0.0035168323665857315" quat="-0.5297175049781799 0.5324012637138367 0.4633755385875702 0.4703523814678192" diaginertia="0.002866726601496339 0.0035295477136969566 0.005175495985895395" />
								<geom name="SM_r_shoulder_lift_link_collision_0" type="mesh" pos="0.0 0.0 0.0" quat="1.0 0.0 0.0 0.0" mesh="shoulder_lift" class="pr2_collision" />
								<joint name="r_shoulder_lift_joint" type="hinge" pos="0.0 0.0 0.0" range="-0.5235999822616577 1.3963000774383545" axis="0.0 1.0 0.0" />
								<body name="r_upper_arm_roll_link" pos="0.0 0.0 0.0" quat="1.0 0.0 0.0 0.0" gravcomp="1">
									<inertial mass="0.07235559076070786" pos="0.12487796694040298 -2.818719167407835e-06 -1.3431765637506032e-06" quat="-0.7070866227149963 0.7071269154548645 -1.2402690117596649e-05 3.837394160655094e-06" diaginertia="0.00022902380442246795 0.0011928267776966095 0.0012989923125132918" />
									<geom name="SM_r_upper_arm_roll_link_collision_0" type="mesh" pos="0.0 0.0 0.0" quat="1.0 0.0 0.0 0.0" mesh="upper_arm_roll_L" class="pr2_collision" />
									<joint name="r_upper_arm_roll_joint" type="hinge" pos="0.0 0.0 0.0" range="-3.9000000953674316 0.800000011920929" axis="1.0 0.0 0.0" />
									<body name="r_upper_arm_link" pos="0.0 0.0 0.0" quat="1.0 0.0 0.0 0.0" gravcomp="1">
										<inertial mass="5.2022385597229" pos="0.2734791040420532 -3.200087303412147e-05 -0.010643254034221172" quat="0.7068957090377808 0.7070910930633545 0.01264550257474184 -0.012677999213337898" diaginertia="0.016427578404545784 0.453969269990921 0.4549430012702942" />
										<geom name="SM_r_upper_arm_link_collision_0" type="mesh" pos="0.0 0.0 0.0" quat="1.0 0.0 0.0 0.0" mesh="upper_arm" class="pr2_collision" />
										<body name="r_elbow_flex_link" pos="0.4000000059604645 0.0 0.0" quat="1.0 0.0 0.0 0.0" gravcomp="1">
											<inertial mass="0.18842573463916779" pos="0.06674972921609879 -0.0002075084048556164 -0.012235036119818687" quat="0.7037703990936279 0.7038841247558594 0.06714816391468048 -0.06888704746961594" diaginertia="0.00034694798523560166 0.00123549101408571 0.0014423702377825975" />
											<geom name="SM_r_elbow_flex_link_collision_0" type="mesh" pos="0.0 0.0 0.0" quat="1.0 0.0 0.0 0.0" mesh="elbow_flex" class="pr2_collision" />
											<joint name="r_elbow_flex_joint" type="hinge" pos="0.0 0.0 0.0" range="-2.3213002681732178 0.0" axis="0.0 1.0 0.0" />
											<body name="r_forearm_roll_link" pos="0.0 0.0 0.0" quat="1.0 0.0 0.0 0.0" gravcomp="1">
												<inertial mass="0.05108305439352989" pos="0.06429405510425568 1.1574408745218534e-05 0.003290909342467785" quat="0.9995561838150024 0.00023118837270885706 -0.02978873811662197 0.00011263530905125663" diaginertia="2.3116032025427558e-05 0.00030341188539750874 0.00030664115911349654" />
												<geom name="SM_r_forearm_roll_link_collision_0" type="mesh" pos="0.0 0.0 0.0" quat="1.0 0.0 0.0 0.0" mesh="forearm_roll_L" class="pr2_collision" />
												<joint name="r_forearm_roll_joint" type="hinge" pos="0.0 0.0 0.0" axis="1.0 0.0 0.0" />
												<body name="r_forearm_cam_frame" pos="0.13500000536441803 0.0 0.04399999976158142" quat="0.6792877912521362 0.679287850856781 -0.19638746976852417 0.19638748466968536" gravcomp="1">
													<inertial mass="0.0" pos="0.0 0.0 0.0" quat="1.0 0.0 0.0 0.0" diaginertia="0.0 0.0 0.0" />
													<body name="r_forearm_cam_optical_frame" pos="0.0 0.0 -2.7755575615628914e-17" quat="0.4999999701976776 -0.5 0.5 -0.5" gravcomp="1">
														<inertial mass="0.0" pos="0.0 0.0 0.0" quat="1.0 0.0 0.0 0.0" diaginertia="0.0 0.0 0.0" />
													</body>
												</body>
												<body name="r_forearm_link" pos="0.0 0.0 0.0" quat="1.0 0.0 0.0 0.0" gravcomp="1">
													<inertial mass="2.0103166103363037" pos="0.201139897108078 1.223308117914712e-05 -0.004733517300337553" quat="-4.6840552386129275e-05 0.9998863339424133 2.6327637897338718e-05 -0.015078271739184856" diaginertia="0.003459537634626031 0.09273631125688553 0.09368810802698135" />
													<geom name="SM_r_forearm_link_collision_0" type="mesh" pos="0.0 0.0 0.0" quat="1.0 0.0 0.0 0.0" mesh="forearm" class="pr2_collision" />
													<body name="r_wrist_flex_link" pos="0.32100000977516174 0.0 0.0" quat="1.0 0.0 0.0 0.0" gravcomp="1">
														<inertial mass="0.1802304983139038" pos="-0.0017590946517884731 1.8078018229061854e-06 -0.0012588765239343047" quat="0.5507289171218872 0.5508716106414795 0.44338276982307434 -0.44345223903656006" diaginertia="8.03590810392052e-05 9.936121932696551e-05 0.000124882732052356" />
														<geom name="SM_r_wrist_flex_link_collision_0" type="mesh" pos="0.0 0.0 0.0" quat="1.0 0.0 0.0 0.0" mesh="wrist_flex" class="pr2_collision" />
														<joint name="r_wrist_flex_joint" type="hinge" pos="0.0 0.0 0.0" range="-2.180000066757202 0.0" axis="0.0 1.0 0.0" />
														<body name="r_wrist_roll_link" pos="0.0 0.0 0.0" quat="1.0 0.0 0.0 0.0" gravcomp="1">
															<inertial mass="0.011862936429679394" pos="0.03189396485686302 -1.0933553312497679e-05 -9.648863397160312e-07" quat="0.9961433410644531 0.0877404734492302 4.841649570153095e-06 -0.0001755533885443583" diaginertia="1.4964700767450267e-06 1.311536743742181e-05 1.311776304646628e-05" />
															<geom name="SM_r_wrist_roll_link_collision_0" type="mesh" pos="0.0 0.0 0.0" quat="1.0 0.0 0.0 0.0" mesh="wrist_roll_L" class="pr2_collision" />
															<joint name="r_wrist_roll_joint" type="hinge" pos="0.0 0.0 0.0" axis="1.0 0.0 0.0" />
															<body name="r_gripper_palm_link" pos="0.0 0.0 0.0" quat="1.0 0.0 0.0 0.0" gravcomp="1">
																<inertial mass="0.346778929233551" pos="0.08001227676868439 -1.348753926322388e-06 2.0504555777733913e-06" quat="-6.546391523443162e-05 1.0 -1.1079485375375953e-05 1.3545548426918685e-05" diaginertia="0.0002749123377725482 0.0024741138331592083 0.002621866762638092" />
																<geom name="SM_r_gripper_palm_link_collision_0" type="mesh" pos="0.0 0.0 0.0" quat="1.0 0.0 0.0 0.0" mesh="gripper_palm" class="pr2_collision" />
																<body name="r_gripper_motor_accelerometer_link" pos="0.0 0.0 0.0" quat="1.0 0.0 0.0 0.0" gravcomp="1">
																	<inertial mass="1.0000001111620804e-06" pos="0.0 0.0 0.0" quat="1.0 0.0 0.0 0.0" diaginertia="1.6666670214077195e-13 1.6666670214077195e-13 1.6666670214077195e-13" />
																	<geom name="SM_r_gripper_motor_accelerometer_link_collision_0" type="box" pos="0.0 0.0 0.0" quat="1.0 0.0 0.0 0.0" size="0.0005000000237487257 0.0005000000237487257 0.0005000000237487257" class="pr2_collision" />
																</body>
																<body name="r_gripper_motor_slider_link" pos="0.1682800054550171 0.0 0.0" quat="1.0 0.0 0.0 0.0" gravcomp="1">
																	<body name="r_gripper_motor_screw_link" pos="0.0 0.0 0.0" quat="1.0 0.0 0.0 0.0" gravcomp="1">
																	</body>
																</body>
																<body name="r_gripper_l_finger_link" pos="0.07690999656915665 0.009999999776482582 0.0" quat="1.0 0.0 0.0 0.0" gravcomp="1">
																	<inertial mass="0.18087133765220642" pos="0.031097745522856712 0.017811013385653496 6.266719196901249e-07" quat="0.9800462126731873 0.0005514603690244257 0.00012912458623759449 0.1987690031528473" diaginertia="7.974637992447242e-05 0.0003700049710460007 0.0003738711238838732" />
																	<geom name="SM_r_gripper_l_finger_link_collision_0" type="mesh" pos="0.0 0.0 0.0" quat="1.0 0.0 0.0 0.0" mesh="l_finger" class="pr2_collision" />
																	<joint name="r_gripper_l_finger_joint" type="hinge" pos="0.0 0.0 0.0" range="0.0 0.5479999780654907" axis="0.0 0.0 1.0" />
																	<body name="r_gripper_l_finger_tip_link" pos="0.09137000143527985 0.00494999997317791 0.0" quat="1.0 0.0 0.0 0.0" gravcomp="1">
																		<inertial mass="0.019972020760178566" pos="0.004215516149997711 0.0014496605144813657 -2.577246050350368e-06" quat="0.9347647428512573 -0.0006915477570146322 0.00018482831364963204 -0.35526666045188904" diaginertia="1.6885959439605358e-06 6.2432159211311955e-06 6.715718882333022e-06" />
																		<geom name="SM_r_gripper_l_finger_tip_link_collision_0" type="mesh" pos="0.0 0.0 0.0" quat="1.0 0.0 0.0 0.0" mesh="l_finger_tip" class="pr2_collision" />
																		<joint name="r_gripper_l_finger_tip_joint" type="hinge" pos="0.0 0.0 0.0" range="0.0 0.5479999780654907" axis="0.0 0.0 -1.0" />
																	</body>
																</body>
																<body name="r_gripper_r_finger_link" pos="0.07690999656915665 -0.009999999776482582 0.0" quat="1.0 0.0 0.0 0.0" gravcomp="1">
																	<inertial mass="0.18087133765220642" pos="0.031097745522856712 -0.017811013385653496 -6.282289746195602e-07" quat="0.9800462126731873 0.0005515032098628581 -0.00012911589874420315 -0.1987690031528473" diaginertia="7.974637992447242e-05 0.0003700049710460007 0.0003738711238838732" />
																	<geom name="SM_r_gripper_r_finger_link_collision_0" type="mesh" pos="0.0 0.0 0.0" quat="-4.371138828673793e-08 1.0 0.0 0.0" mesh="l_finger" class="pr2_collision" />
																	<joint name="r_gripper_r_finger_joint" type="hinge" pos="0.0 0.0 0.0" range="0.0 0.5479999780654907" axis="0.0 0.0 -1.0" />
																	<body name="r_gripper_r_finger_tip_link" pos="0.09137000143527985 -0.00494999997317791 0.0" quat="1.0 0.0 0.0 0.0" gravcomp="1">
																		<inertial mass="0.019972020760178566" pos="0.004215516149997711 -0.0014496605144813657 2.577119403213146e-06" quat="0.9347647428512573 -0.000691506895236671 -0.00018484385509509593 0.35526666045188904" diaginertia="1.6885959439605358e-06 6.2432159211311955e-06 6.715718882333022e-06" />
																		<geom name="SM_r_gripper_r_finger_tip_link_collision_0" type="mesh" pos="0.0 0.0 0.0" quat="-4.371138828673793e-08 1.0 0.0 0.0" mesh="l_finger_tip" class="pr2_collision" />
																		<joint name="r_gripper_r_finger_tip_joint" type="hinge" pos="0.0 0.0 0.0" range="0.0 0.5479999780654907" axis="0.0 0.0 1.0" />
																		<body name="r_gripper_l_finger_tip_frame" pos="0.0 0.0 0.0" quat="1.0 0.0 0.0 0.0" gravcomp="1">
																		</body>
																	</body>
																</body>
																<body name="r_gripper_led_frame" pos="0.05130000039935112 0.0 0.024399999529123306" quat="1.0 0.0 0.0 0.0" gravcomp="1">
																	<inertial mass="0.0" pos="0.0 0.0 0.0" quat="1.0 0.0 0.0 0.0" diaginertia="0.0 0.0 0.0" />
																</body>
																<body name="r_gripper_tool_frame" pos="0.18000000715255737 0.0 0.0" quat="1.0 0.0 0.0 0.0" gravcomp="1">
																	<inertial mass="0.0" pos="0.0 0.0 0.0" quat="1.0 0.0 0.0 0.0" diaginertia="0.0 0.0 0.0" />
																</body>
															</body>
														</body>
													</body>
												</body>
											</body>
										</body>
									</body>
								</body>
							</body>
						</body>
						<body name="l_shoulder_pan_link" pos="0.0 0.18799999356269836 0.0" quat="1.0 0.0 0.0 0.0" gravcomp="1">
							<inertial mass="27.858089447021484" pos="-0.007217532955110073 -1.2285015145607758e-05 -0.15199442207813263" quat="0.00025214478955604136 -0.6800189018249512 0.0002595585829112679 0.7331945300102234" diaginertia="0.2705267369747162 1.7231812477111816 1.7425432205200195" />
							<geom name="SM_l_shoulder_pan_link_collision_0" type="mesh" pos="0.0 0.0 0.0" quat="1.0 0.0 0.0 0.0" mesh="shoulder_pan" class="pr2_collision" />
							<joint name="l_shoulder_pan_joint" type="hinge" pos="0.0 0.0 0.0" range="-0.7146018147468567 2.285398244857788" axis="0.0 0.0 1.0" />
							<body name="l_shoulder_lift_link" pos="0.10000000149011612 0.0 0.0" quat="1.0 0.0 0.0 0.0" gravcomp="1">
								<inertial mass="0.32213330268859863" pos="-0.011961976066231728 0.0005128994234837592 0.0035168323665857315" quat="-0.5297175049781799 0.5324012637138367 0.4633755385875702 0.4703523814678192" diaginertia="0.002866726601496339 0.0035295477136969566 0.005175495985895395" />
								<geom name="SM_l_shoulder_lift_link_collision_0" type="mesh" pos="0.0 0.0 0.0" quat="1.0 0.0 0.0 0.0" mesh="shoulder_lift" class="pr2_collision" />
								<joint name="l_shoulder_lift_joint" type="hinge" pos="0.0 0.0 0.0" range="-0.5235999822616577 1.3963000774383545" axis="0.0 1.0 0.0" />
								<body name="l_upper_arm_roll_link" pos="0.0 0.0 0.0" quat="1.0 0.0 0.0 0.0" gravcomp="1">
									<inertial mass="0.07235559076070786" pos="0.12487796694040298 -2.818719167407835e-06 -1.3431765637506032e-06" quat="-0.7070866227149963 0.7071269154548645 -1.2402690117596649e-05 3.837394160655094e-06" diaginertia="0.00022902380442246795 0.0011928267776966095 0.0012989923125132918" />
									<geom name="SM_l_upper_arm_roll_link_collision_0" type="mesh" pos="0.0 0.0 0.0" quat="1.0 0.0 0.0 0.0" mesh="upper_arm_roll_L" class="pr2_collision" />
									<joint name="l_upper_arm_roll_joint" type="hinge" pos="0.0 0.0 0.0" range="-0.800000011920929 3.9000000953674316" axis="1.0 0.0 0.0" />
									<body name="l_upper_arm_link" pos="0.0 0.0 0.0" quat="1.0 0.0 0.0 0.0" gravcomp="1">
										<inertial mass="5.2022385597229" pos="0.2734791040420532 -3.200087303412147e-05 -0.010643254034221172" quat="0.7068957090377808 0.7070910930633545 0.01264550257474184 -0.012677999213337898" diaginertia="0.016427578404545784 0.453969269990921 0.4549430012702942" />
										<geom name="SM_l_upper_arm_link_collision_0" type="mesh" pos="0.0 0.0 0.0" quat="1.0 0.0 0.0 0.0" mesh="upper_arm" class="pr2_collision" />
										<body name="l_elbow_flex_link" pos="0.4000000059604645 0.0 0.0" quat="1.0 0.0 0.0 0.0" gravcomp="1">
											<inertial mass="0.18842573463916779" pos="0.06674972921609879 -0.0002075084048556164 -0.012235036119818687" quat="0.7037703990936279 0.7038841247558594 0.06714816391468048 -0.06888704746961594" diaginertia="0.00034694798523560166 0.00123549101408571 0.0014423702377825975" />
											<geom name="SM_l_elbow_flex_link_collision_0" type="mesh" pos="0.0 0.0 0.0" quat="1.0 0.0 0.0 0.0" mesh="elbow_flex" class="pr2_collision" />
											<joint name="l_elbow_flex_joint" type="hinge" pos="0.0 0.0 0.0" range="-2.3213002681732178 0.0" axis="0.0 1.0 0.0" />
											<body name="l_forearm_roll_link" pos="0.0 0.0 0.0" quat="1.0 0.0 0.0 0.0" gravcomp="1">
												<inertial mass="0.05108305439352989" pos="0.06429405510425568 1.1574408745218534e-05 0.003290909342467785" quat="0.9995561838150024 0.00023118837270885706 -0.02978873811662197 0.00011263530905125663" diaginertia="2.3116032025427558e-05 0.00030341188539750874 0.00030664115911349654" />
												<geom name="SM_l_forearm_roll_link_collision_0" type="mesh" pos="0.0 0.0 0.0" quat="1.0 0.0 0.0 0.0" mesh="forearm_roll_L" class="pr2_collision" />
												<joint name="l_forearm_roll_joint" type="hinge" pos="0.0 0.0 0.0" axis="1.0 0.0 0.0" />
												<body name="l_forearm_cam_frame" pos="0.13500000536441803 0.0 0.04399999976158142" quat="-0.6792877912521362 0.679287850856781 0.19638746976852417 0.19638748466968536" gravcomp="1">
													<inertial mass="0.0" pos="0.0 0.0 0.0" quat="1.0 0.0 0.0 0.0" diaginertia="0.0 0.0 0.0" />
													<body name="l_forearm_cam_optical_frame" pos="0.0 0.0 -2.7755575615628914e-17" quat="0.4999999701976776 -0.5 0.5 -0.5" gravcomp="1">
														<inertial mass="0.0" pos="0.0 0.0 0.0" quat="1.0 0.0 0.0 0.0" diaginertia="0.0 0.0 0.0" />
													</body>
												</body>
												<body name="l_forearm_link" pos="0.0 0.0 0.0" quat="1.0 0.0 0.0 0.0" gravcomp="1">
													<inertial mass="2.0103166103363037" pos="0.201139897108078 1.223308117914712e-05 -0.004733517300337553" quat="-4.6840552386129275e-05 0.9998863339424133 2.6327637897338718e-05 -0.015078271739184856" diaginertia="0.003459537634626031 0.09273631125688553 0.09368810802698135" />
													<geom name="SM_l_forearm_link_collision_0" type="mesh" pos="0.0 0.0 0.0" quat="1.0 0.0 0.0 0.0" mesh="forearm" class="pr2_collision" />
													<body name="l_wrist_flex_link" pos="0.32100000977516174 0.0 0.0" quat="1.0 0.0 0.0 0.0" gravcomp="1">
														<inertial mass="0.1802304983139038" pos="-0.0017590946517884731 1.8078018229061854e-06 -0.0012588765239343047" quat="0.5507289171218872 0.5508716106414795 0.44338276982307434 -0.44345223903656006" diaginertia="8.03590810392052e-05 9.936121932696551e-05 0.000124882732052356" />
														<geom name="SM_l_wrist_flex_link_collision_0" type="mesh" pos="0.0 0.0 0.0" quat="1.0 0.0 0.0 0.0" mesh="wrist_flex" class="pr2_collision" />
														<joint name="l_wrist_flex_joint" type="hinge" pos="0.0 0.0 0.0" range="-2.180000066757202 0.0" axis="0.0 1.0 0.0" />
														<body name="l_wrist_roll_link" pos="0.0 0.0 0.0" quat="1.0 0.0 0.0 0.0" gravcomp="1">
															<inertial mass="0.011862936429679394" pos="0.03189396485686302 -1.0933553312497679e-05 -9.648863397160312e-07" quat="0.9961433410644531 0.0877404734492302 4.841649570153095e-06 -0.0001755533885443583" diaginertia="1.4964700767450267e-06 1.311536743742181e-05 1.311776304646628e-05" />
															<geom name="SM_l_wrist_roll_link_collision_0" type="mesh" pos="0.0 0.0 0.0" quat="1.0 0.0 0.0 0.0" mesh="wrist_roll_L" class="pr2_collision" />
															<joint name="l_wrist_roll_joint" type="hinge" pos="0.0 0.0 0.0" axis="1.0 0.0 0.0" />
															<body name="l_gripper_palm_link" pos="0.0 0.0 0.0" quat="1.0 0.0 0.0 0.0" gravcomp="1">
																<inertial mass="0.346778929233551" pos="0.08001227676868439 -1.348753926322388e-06 2.0504555777733913e-06" quat="-6.546391523443162e-05 1.0 -1.1079485375375953e-05 1.3545548426918685e-05" diaginertia="0.0002749123377725482 0.0024741138331592083 0.002621866762638092" />
																<geom name="SM_l_gripper_palm_link_collision_0" type="mesh" pos="0.0 0.0 0.0" quat="1.0 0.0 0.0 0.0" mesh="gripper_palm" class="pr2_collision" />
																<body name="l_gripper_motor_accelerometer_link" pos="0.0 0.0 0.0" quat="1.0 0.0 0.0 0.0" gravcomp="1">
																	<inertial mass="1.0000001111620804e-06" pos="0.0 0.0 0.0" quat="1.0 0.0 0.0 0.0" diaginertia="1.6666670214077195e-13 1.6666670214077195e-13 1.6666670214077195e-13" />
																	<geom name="SM_l_gripper_motor_accelerometer_link_collision_0" type="box" pos="0.0 0.0 0.0" quat="1.0 0.0 0.0 0.0" size="0.0005000000237487257 0.0005000000237487257 0.0005000000237487257" class="pr2_collision" />
																</body>
																<body name="l_gripper_motor_slider_link" pos="0.1682800054550171 0.0 0.0" quat="1.0 0.0 0.0 0.0" gravcomp="1">
																	<body name="l_gripper_motor_screw_link" pos="0.0 0.0 0.0" quat="1.0 0.0 0.0 0.0" gravcomp="1">
																	</body>
																</body>
																<body name="l_gripper_l_finger_link" pos="0.07690999656915665 0.009999999776482582 0.0" quat="1.0 0.0 0.0 0.0" gravcomp="1">
																	<inertial mass="0.18087133765220642" pos="0.031097745522856712 0.017811013385653496 6.266719196901249e-07" quat="0.9800462126731873 0.0005514603690244257 0.00012912458623759449 0.1987690031528473" diaginertia="7.974637992447242e-05 0.0003700049710460007 0.0003738711238838732" />
																	<geom name="SM_l_gripper_l_finger_link_collision_0" type="mesh" pos="0.0 0.0 0.0" quat="1.0 0.0 0.0 0.0" mesh="l_finger" class="pr2_collision" />
																	<joint name="l_gripper_l_finger_joint" type="hinge" pos="0.0 0.0 0.0" range="0.0 0.5479999780654907" axis="0.0 0.0 1.0" />
																	<body name="l_gripper_l_finger_tip_link" pos="0.09137000143527985 0.00494999997317791 0.0" quat="1.0 0.0 0.0 0.0" gravcomp="1">
																		<inertial mass="0.019972020760178566" pos="0.004215516149997711 0.0014496605144813657 -2.577246050350368e-06" quat="0.9347647428512573 -0.0006915477570146322 0.00018482831364963204 -0.35526666045188904" diaginertia="1.6885959439605358e-06 6.2432159211311955e-06 6.715718882333022e-06" />
																		<geom name="SM_l_gripper_l_finger_tip_link_collision_0" type="mesh" pos="0.0 0.0 0.0" quat="1.0 0.0 0.0 0.0" mesh="l_finger_tip" class="pr2_collision" />
																		<joint name="l_gripper_l_finger_tip_joint" type="hinge" pos="0.0 0.0 0.0" range="0.0 0.5479999780654907" axis="0.0 0.0 -1.0" />
																	</body>
																</body>
																<body name="l_gripper_r_finger_link" pos="0.07690999656915665 -0.009999999776482582 0.0" quat="1.0 0.0 0.0 0.0" gravcomp="1">
																	<inertial mass="0.18087133765220642" pos="0.031097745522856712 -0.017811013385653496 -6.282289746195602e-07" quat="0.9800462126731873 0.0005515032098628581 -0.00012911589874420315 -0.1987690031528473" diaginertia="7.974637992447242e-05 0.0003700049710460007 0.0003738711238838732" />
																	<geom name="SM_l_gripper_r_finger_link_collision_0" type="mesh" pos="0.0 0.0 0.0" quat="-4.371138828673793e-08 1.0 0.0 0.0" mesh="l_finger" class="pr2_collision" />
																	<joint name="l_gripper_r_finger_joint" type="hinge" pos="0.0 0.0 0.0" range="0.0 0.5479999780654907" axis="0.0 0.0 -1.0" />
																	<body name="l_gripper_r_finger_tip_link" pos="0.09137000143527985 -0.00494999997317791 0.0" quat="1.0 0.0 0.0 0.0" gravcomp="1">
																		<inertial mass="0.019972020760178566" pos="0.004215516149997711 -0.0014496605144813657 2.577119403213146e-06" quat="0.9347647428512573 -0.000691506895236671 -0.00018484385509509593 0.35526666045188904" diaginertia="1.6885959439605358e-06 6.2432159211311955e-06 6.715718882333022e-06" />
																		<geom name="SM_l_gripper_r_finger_tip_link_collision_0" type="mesh" pos="0.0 0.0 0.0" quat="-4.371138828673793e-08 1.0 0.0 0.0" mesh="l_finger_tip" class="pr2_collision" />
																		<joint name="l_gripper_r_finger_tip_joint" type="hinge" pos="0.0 0.0 0.0" range="0.0 0.5479999780654907" axis="0.0 0.0 1.0" />
																		<body name="l_gripper_l_finger_tip_frame" pos="0.0 0.0 0.0" quat="1.0 0.0 0.0 0.0" gravcomp="1">
																		</body>
																	</body>
																</body>
																<body name="l_gripper_led_frame" pos="0.05130000039935112 0.0 0.024399999529123306" quat="1.0 0.0 0.0 0.0" gravcomp="1">
																	<inertial mass="0.0" pos="0.0 0.0 0.0" quat="1.0 0.0 0.0 0.0" diaginertia="0.0 0.0 0.0" />
																</body>
																<body name="l_gripper_tool_frame" pos="0.18000000715255737 0.0 0.0" quat="1.0 0.0 0.0 0.0" gravcomp="1">
																	<inertial mass="0.0" pos="0.0 0.0 0.0" quat="1.0 0.0 0.0 0.0" diaginertia="0.0 0.0 0.0" />
																</body>
															</body>
														</body>
													</body>
												</body>
											</body>
										</body>
									</body>
								</body>
							</body>
						</body>
						<body name="l_torso_lift_side_plate_link" pos="0.05350000038743019 0.20928500592708588 0.17662499845027924" quat="1.0 0.0 0.0 0.0" gravcomp="1">
							<inertial mass="0.0" pos="0.0 0.0 0.0" quat="1.0 0.0 0.0 0.0" diaginertia="0.0 0.0 0.0" />
						</body>
						<body name="imu_link" pos="-0.029769999906420708 -0.14970000088214874 0.164000004529953" quat="2.0217079793854575e-15 -4.371138828673793e-08 1.0 -4.371138828673793e-08" gravcomp="1">
							<inertial mass="0.0" pos="0.0 0.0 0.0" quat="1.0 0.0 0.0 0.0" diaginertia="0.0 0.0 0.0" />
						</body>
					</body>
					<body name="bl_caster_rotation_link" pos="-0.22460000216960907 0.22460000216960907 0.028200000524520874" quat="1.0 0.0 0.0 0.0" gravcomp="1">
						<inertial mass="2.2135562896728516" pos="-0.0059445747174322605 1.1481000594670832e-09 0.08382795006036758" quat="0.5099974274635315 0.5099974274635315 0.48979854583740234 -0.48979854583740234" diaginertia="0.006514224223792553 0.025800351053476334 0.02824961021542549" />
						<geom name="SM_bl_caster_rotation_link_collision_0" type="mesh" pos="0.0 0.0 0.0" quat="1.0 0.0 0.0 0.0" mesh="caster_L" class="pr2_collision" />
						<joint name="bl_caster_rotation_joint" type="hinge" pos="0.0 0.0 6.938893903907228e-18" axis="0.0 0.0 1.0" />
						<body name="bl_caster_r_wheel_link" pos="0.0 -0.04899999871850014 0.0" quat="1.0 0.0 0.0 0.0" gravcomp="1">
							<inertial mass="0.5975016355514526" pos="0.0 0.0 0.0" quat="0.0 0.0 0.7071067690849304 -0.7071067690849304" diaginertia="0.0008931418415158987 0.0008931418415158987 0.0016711651114746928" />
							<geom name="SM_bl_caster_r_wheel_link_collision_0" type="cylinder" pos="0.0 0.0 0.0" quat="0.7071067690849304 0.7071067690849304 0.0 0.0" size="0.07479199767112732 0.017000000923871994 0.0" class="pr2_collision" />
							<joint name="bl_caster_r_wheel_joint" type="hinge" pos="0.0 0.0 0.0" axis="0.0 1.0 0.0" />
						</body>
						<body name="bl_caster_l_wheel_link" pos="0.0 0.04899999871850014 0.0" quat="1.0 0.0 0.0 0.0" gravcomp="1">
							<inertial mass="0.5975016355514526" pos="0.0 0.0 0.0" quat="0.0 0.0 0.7071067690849304 -0.7071067690849304" diaginertia="0.0008931418415158987 0.0008931418415158987 0.0016711651114746928" />
							<geom name="SM_bl_caster_l_wheel_link_collision_0" type="cylinder" pos="0.0 0.0 0.0" quat="0.7071067690849304 0.7071067690849304 0.0 0.0" size="0.07479199767112732 0.017000000923871994 0.0" class="pr2_collision" />
							<joint name="bl_caster_l_wheel_joint" type="hinge" pos="0.0 0.0 0.0" axis="0.0 1.0 0.0" />
						</body>
					</body>
				</body>
			</body>
		</body>
	</worldbody>
	<equality/>

	<contact>
        <exclude name="base_link_br_caster_rotation_link" body1="base_link" body2="br_caster_rotation_link"/>
        <exclude name="base_link_fl_caster_rotation_link" body1="base_link" body2="fl_caster_rotation_link"/>
        <exclude name="base_link_r_shoulder_pan_link" body1="base_link" body2="r_shoulder_pan_link"/>
        <exclude name="base_link_l_shoulder_pan_link" body1="base_link" body2="l_shoulder_pan_link"/>
        <exclude name="base_link_bl_caster_rotation_link" body1="base_link" body2="bl_caster_rotation_link"/>
        <exclude name="base_link_torso_lift_link" body1="base_link" body2="torso_lift_link"/>
        <exclude name="base_link_fr_caster_rotation_link" body1="base_link" body2="fr_caster_rotation_link"/>
        <exclude name="fr_caster_r_wheel_link_base_link" body1="fr_caster_r_wheel_link" body2="base_link"/>
        <exclude name="fr_caster_l_wheel_link_base_link" body1="fr_caster_l_wheel_link" body2="base_link"/>
        <exclude name="br_caster_r_wheel_link_base_link" body1="br_caster_r_wheel_link" body2="base_link"/>
        <exclude name="br_caster_l_wheel_link_base_link" body1="br_caster_l_wheel_link" body2="base_link"/>
        <exclude name="fl_caster_r_wheel_link_base_link" body1="fl_caster_r_wheel_link" body2="base_link"/>
        <exclude name="fl_caster_l_wheel_link_base_link" body1="fl_caster_l_wheel_link" body2="base_link"/>
        <exclude name="bl_caster_r_wheel_link_base_link" body1="bl_caster_r_wheel_link" body2="base_link"/>
        <exclude name="bl_caster_l_wheel_link_base_link" body1="bl_caster_l_wheel_link" body2="base_link"/>
        <exclude name="base_bellow_link_torso_lift_link" body1="base_bellow_link" body2="torso_lift_link"/>
        <exclude name="torso_lift_link_l_shoulder_lift_link" body1="torso_lift_link" body2="l_shoulder_lift_link"/>
        <exclude name="torso_lift_link_r_shoulder_lift_link" body1="torso_lift_link" body2="r_shoulder_lift_link"/>
        <exclude name="r_shoulder_pan_link_r_upper_arm_link" body1="r_shoulder_pan_link" body2="r_upper_arm_link"/>
        <exclude name="r_shoulder_pan_link_r_upper_arm_roll_link" body1="r_shoulder_pan_link" body2="r_upper_arm_roll_link"/>
        <exclude name="r_upper_arm_link_r_forearm_roll_link" body1="r_upper_arm_link" body2="r_forearm_roll_link"/>
        <exclude name="r_forearm_link_r_wrist_roll_link" body1="r_forearm_link" body2="r_wrist_roll_link"/>
        <exclude name="r_forearm_link_r_gripper_palm_link" body1="r_forearm_link" body2="r_gripper_palm_link"/>
        <exclude name="r_gripper_motor_accelerometer_link_r_forearm_link" body1="r_gripper_motor_accelerometer_link" body2="r_forearm_link"/>
        <exclude name="r_gripper_l_finger_tip_link_r_gripper_r_finger_tip_link" body1="r_gripper_l_finger_tip_link" body2="r_gripper_r_finger_tip_link"/>
        <exclude name="l_shoulder_pan_link_l_upper_arm_link" body1="l_shoulder_pan_link" body2="l_upper_arm_link"/>
        <exclude name="l_shoulder_pan_link_l_upper_arm_roll_link" body1="l_shoulder_pan_link" body2="l_upper_arm_roll_link"/>
        <exclude name="l_upper_arm_link_l_forearm_roll_link" body1="l_upper_arm_link" body2="l_forearm_roll_link"/>
        <exclude name="l_forearm_link_l_wrist_roll_link" body1="l_forearm_link" body2="l_wrist_roll_link"/>
        <exclude name="l_forearm_link_l_gripper_palm_link" body1="l_forearm_link" body2="l_gripper_palm_link"/>
        <exclude name="l_gripper_motor_accelerometer_link_l_forearm_link" body1="l_gripper_motor_accelerometer_link" body2="l_forearm_link"/>
        <exclude name="l_gripper_l_finger_tip_link_l_gripper_r_finger_tip_link" body1="l_gripper_l_finger_tip_link" body2="l_gripper_r_finger_tip_link"/>
    </contact>

	<equality>
		<joint name="l_gripper_l_finger_joint_l_gripper_r_finger_joint" joint1="l_gripper_l_finger_joint" joint2="l_gripper_r_finger_joint"/>
		<joint name="l_gripper_l_finger_joint_l_gripper_l_finger_tip_joint" joint1="l_gripper_l_finger_joint" joint2="l_gripper_l_finger_tip_joint"/>
		<joint name="l_gripper_l_finger_joint_l_l_gripper_r_finger_tip_joint" joint1="l_gripper_l_finger_joint" joint2="l_gripper_r_finger_tip_joint"/>

		<joint name="r_gripper_l_finger_joint_r_gripper_r_finger_joint" joint1="r_gripper_l_finger_joint" joint2="r_gripper_r_finger_joint"/>
		<joint name="r_gripper_l_finger_joint_r_gripper_l_finger_tip_joint" joint1="r_gripper_l_finger_joint" joint2="r_gripper_l_finger_tip_joint"/>
		<joint name="r_gripper_l_finger_joint_l_r_gripper_r_finger_tip_joint" joint1="r_gripper_l_finger_joint" joint2="r_gripper_r_finger_tip_joint"/>
	</equality>

	<actuator>
		<position name="r_shoulder_pan_actuator" joint="r_shoulder_pan_joint" kp="2000" kv="500" forcerange="-1500 1500" ctrlrange="-2.285398244857788 0.7146018147468567" />
		<position name="r_shoulder_lift_actuator" joint="r_shoulder_lift_joint" kp="2000" kv="500" forcerange="-1500 1500" ctrlrange="-0.5235999822616577 1.3963000774383545" />
		<position name="r_upper_arm_roll_actuator" joint="r_upper_arm_roll_joint" kp="400" kv="10" forcerange="-500 500" ctrlrange="-3.9000000953674316 0.800000011920929" />
		<position name="r_elbow_flex_actuator" joint="r_elbow_flex_joint" kp="100" kv="20" forcerange="-500 500" ctrlrange="-2.3213002681732178 0.0" />
		<position name="r_forearm_roll_actuator" joint="r_forearm_roll_joint" kp="40" kv="2" forcerange="-1500 1500" />
		<position name="r_wrist_flex_actuator" joint="r_wrist_flex_joint" kp="40" kv="2" forcerange="-50 50" ctrlrange="-2.180000066757202 0.0" />
		<position name="r_wrist_roll_actuator" joint="r_wrist_roll_joint" kp="20" kv="0.1" forcerange="-50 50" />

		<position name="l_shoulder_pan_actuator" joint="l_shoulder_pan_joint" kp="2000" kv="500" forcerange="-1500 1500" ctrlrange="-0.7146018147468567 2.285398244857788" />
		<position name="l_shoulder_lift_actuator" joint="l_shoulder_lift_joint" kp="2000" kv="500" forcerange="-1500 1500" ctrlrange="-0.5235999822616577 1.3963000774383545" />
		<position name="l_upper_arm_roll_actuator" joint="l_upper_arm_roll_joint" kp="400" kv="10" forcerange="-500 500" ctrlrange="-0.800000011920929 3.9000000953674316" />
		<position name="l_elbow_flex_actuator" joint="l_elbow_flex_joint" kp="100" kv="20" forcerange="-500 500" ctrlrange="-2.3213002681732178 0.0" />
		<position name="l_forearm_roll_actuator" joint="l_forearm_roll_joint" kp="40" kv="2" forcerange="-500 500" />
		<position name="l_wrist_flex_actuator" joint="l_wrist_flex_joint" kp="40" kv="2" forcerange="-50 50" ctrlrange="-2.180000066757202 0.0" />
		<position name="l_wrist_roll_actuator" joint="l_wrist_roll_joint" kp="20" kv="0.1" forcerange="-50 50" />

		<position name="torso_lift_actuator" joint="torso_lift_joint" kp="5000" kv="2000" forcerange="-5000 5000" ctrlrange="0.0 0.33000001311302185"/>

		<position name="head_pan_actuator" joint="head_pan_joint" kp="500" kv="20" forcerange="-500 500" ctrlrange="-3.006999969482422 3.006999969482422"/>
		<position name="head_tilt_actuator" joint="head_tilt_joint" kp="500" kv="20" forcerange="-500 500" ctrlrange="-0.47123798727989197 1.3962600231170654"/>

		<position name="l_gripper_actuator" joint="l_gripper_l_finger_joint" kp="20" kv="0.1" forcerange="-50 50" ctrlrange="0 0.5479999780654907"/>
		<position name="r_gripper_actuator" joint="r_gripper_l_finger_joint" kp="20" kv="0.1" forcerange="-50 50" ctrlrange="0 0.5479999780654907"/>
	</actuator>

	<include file="milk.xml"/>
</mujoco>
