<?xml version="1.0" ?>
<robot name="iCub" version="1.0">
  <link name="iCub"/>
  <joint name="root_link_joint" type="fixed">
    <origin xyz="0.0 0.0 0.0" rpy="0.0 0.0 0.0"/>
    <parent link="iCub"/>
    <child link="root_link"/>
  </joint>
  <link name="root_link">
    <inertial>
      <origin xyz="0.02561270073056221 0.00017707300139591098 -0.044533900916576385" rpy="1.813501000404358 -1.5622903108596802 -0.5995895862579346"/>
      <mass value="5.127389907836914"/>
      <inertia ixx="0.014542383141815662" ixy="0.0" ixz="0.0" iyy="0.01996362954378128" iyz="0.0" izz="0.025951389223337173"/>
    </inertial>
    <visual name="SM_root_link_visual_0">
      <origin xyz="-0.036400001496076584 0.0 0.03200000151991844" rpy="1.5707963705062866 0.0 -1.5707963705062866"/>
      <geometry>
        <mesh filename="file://iCub/meshes/stl/sim_sea_2-5_root_link_prt-binary.stl" scale="0.0010000000474974513 0.0010000000474974513 0.0010000000474974513"/>
      </geometry>
    </visual>
    <collision name="SM_root_link_collision_0">
      <origin xyz="-0.036400001496076584 0.0 0.03200000151991844" rpy="1.5707963705062866 0.0 -1.5707963705062866"/>
      <geometry>
        <mesh filename="file://iCub/meshes/stl/sim_sea_2-5_root_link_prt-binary.stl" scale="0.0010000000474974513 0.0010000000474974513 0.0010000000474974513"/>
      </geometry>
    </collision>
  </link>
  <joint name="root_link_ems_gyro_eb5_joint" type="fixed">
    <origin xyz="0.0493308 -0.012577100000000023 -0.11569100000000002" rpy="3.1415927410125732 1.2915440797805786 3.1415927410125732"/>
    <parent link="root_link"/>
    <child link="root_link_ems_gyro_eb5"/>
  </joint>
  <link name="root_link_ems_gyro_eb5">
    <inertial>
      <origin xyz="0.0 0.0 0.0" rpy="0.0 0.0 0.0"/>
      <mass value="0.0"/>
      <inertia ixx="0.0" ixy="0.0" ixz="0.0" iyy="0.0" iyz="0.0" izz="0.0"/>
    </inertial>
  </link>
  <joint name="root_link_imu_acc_joint" type="fixed">
    <origin xyz="0.08515499999999998 -0.011000000000000022 -0.11230899999999999" rpy="-2.094395160675049 2.220446049250313e-16 -1.5707963705062866"/>
    <parent link="root_link"/>
    <child link="root_link_imu_acc"/>
  </joint>
  <link name="root_link_imu_acc">
    <inertial>
      <origin xyz="0.0 0.0 0.0" rpy="0.0 0.0 0.0"/>
      <mass value="0.0"/>
      <inertia ixx="0.0" ixy="0.0" ixz="0.0" iyy="0.0" iyz="0.0" izz="0.0"/>
    </inertial>
  </link>
  <joint name="torso_pitch" type="revolute">
    <origin xyz="0.0 0.026934800669550896 0.0" rpy="1.5707963705062866 0.0 -1.5707963705062866"/>
    <axis xyz="1.0 0.0 0.0"/>
    <parent link="root_link"/>
    <child link="torso_1"/>
    <limit effort="50000.0" lower="-0.3490658402442932" upper="1.2217304706573486" velocity="50000.0"/>
  </joint>
  <link name="torso_1">
    <inertial>
      <origin xyz="0.02698063664138317 0.029147980734705925 -0.0004398000019136816" rpy="1.4134413003921509 -1.4941972494125366 -1.4587478637695312"/>
      <mass value="0.6714400053024292"/>
      <inertia ixx="0.00029893990722484887" ixy="0.0" ixz="0.0" iyy="0.000384586863219738" iyz="0.0" izz="0.00040916920988820493"/>
    </inertial>
    <visual name="SM_torso_1_visual_0">
      <origin xyz="0.026934800669550896 0.03200000151991844 0.036400001496076584" rpy="0.0 0.0 0.0"/>
      <geometry>
        <mesh filename="file://iCub/meshes/stl/sim_sea_2-5_lap_belt_1_prt-binary.stl" scale="0.0010000000474974513 0.0010000000474974513 0.0010000000474974513"/>
      </geometry>
    </visual>
    <collision name="SM_torso_1_collision_0">
      <origin xyz="0.026934800669550896 0.03200000151991844 0.036400001496076584" rpy="0.0 0.0 0.0"/>
      <geometry>
        <mesh filename="file://iCub/meshes/stl/sim_sea_2-5_lap_belt_1_prt-binary.stl" scale="0.0010000000474974513 0.0010000000474974513 0.0010000000474974513"/>
      </geometry>
    </collision>
  </link>
  <joint name="torso_roll" type="revolute">
    <origin xyz="0.026934800669550896 0.03200000151991844 -0.057344600558280945" rpy="0.0 0.0 0.0"/>
    <axis xyz="0.0 0.0 -1.0"/>
    <parent link="torso_1"/>
    <child link="torso_2"/>
    <limit effort="50000.0" lower="-0.5235987901687622" upper="0.5235987901687622" velocity="50000.0"/>
  </joint>
  <link name="torso_2">
    <inertial>
      <origin xyz="-0.00011350781278451905 0.03615250065922737 0.05709629878401756" rpy="1.5712084770202637 0.0010388368973508477 -1.5707356929779053"/>
      <mass value="0.42568498849868774"/>
      <inertia ixx="0.00043651682790368795" ixy="0.0" ixz="0.0" iyy="0.0006048021605238318" iyz="0.0" izz="0.0008292340207844973"/>
    </inertial>
    <visual name="SM_torso_2_visual_0">
      <origin xyz="0.0 0.14329999685287476 0.03865310177206993" rpy="0.0 0.0 0.0"/>
      <geometry>
        <mesh filename="file://iCub/meshes/stl/sim_sea_2-5_lap_belt_2_prt-binary.stl" scale="0.0010000000474974513 0.0010000000474974513 0.0010000000474974513"/>
      </geometry>
    </visual>
    <collision name="SM_torso_2_collision_0">
      <origin xyz="0.0 0.14329999685287476 0.03865310177206993" rpy="0.0 0.0 0.0"/>
      <geometry>
        <mesh filename="file://iCub/meshes/stl/sim_sea_2-5_lap_belt_2_prt-binary.stl" scale="0.0010000000474974513 0.0010000000474974513 0.0010000000474974513"/>
      </geometry>
    </collision>
  </link>
  <joint name="torso_yaw" type="revolute">
    <origin xyz="0.0 0.05000000074505806 0.06284210085868835" rpy="0.0 0.0 0.0"/>
    <axis xyz="0.0 -1.0 0.0"/>
    <parent link="torso_2"/>
    <child link="chest"/>
    <limit effort="50000.0" lower="-0.8726646304130554" upper="0.8726646304130554" velocity="50000.0"/>
  </joint>
  <link name="chest">
    <inertial>
      <origin xyz="0.0001886191894300282 0.07309100031852722 -0.047238100320100784" rpy="0.44752785563468933 1.5446816682815552 -1.1465060710906982"/>
      <mass value="7.638000011444092"/>
      <inertia ixx="0.026044152677059174" ixy="0.0" ixz="0.0" iyy="0.04303387179970741" iyz="0.0" izz="0.04409436136484146"/>
    </inertial>
    <visual name="SM_chest_visual_0">
      <origin xyz="0.0 0.09279999881982803 -0.024188999086618423" rpy="0.0 0.0 0.0"/>
      <geometry>
        <mesh filename="file://iCub/meshes/stl/sim_sea_2-5_chest_bb_prt-binary.stl" scale="0.0010000000474974513 0.0010000000474974513 0.0010000000474974513"/>
      </geometry>
    </visual>
    <collision name="SM_chest_collision_0">
      <origin xyz="0.0 0.09279999881982803 -0.024188999086618423" rpy="0.0 0.0 0.0"/>
      <geometry>
        <mesh filename="file://iCub/meshes/stl/sim_sea_2-5_chest_bb_prt-binary.stl" scale="0.0010000000474974513 0.0010000000474974513 0.0010000000474974513"/>
      </geometry>
    </collision>
  </link>
  <joint name="chest_ems_gyro_eb1_joint" type="fixed">
    <origin xyz="0.069201600190735 0.06454800000000001 -0.0635258" rpy="3.141516923904419 -0.26179930567741394 0.00029264186741784215"/>
    <parent link="chest"/>
    <child link="chest_ems_gyro_eb1"/>
  </joint>
  <link name="chest_ems_gyro_eb1">
    <inertial>
      <origin xyz="0.0 0.0 0.0" rpy="0.0 0.0 0.0"/>
      <mass value="0.0"/>
      <inertia ixx="0.0" ixy="0.0" ixz="0.0" iyy="0.0" iyz="0.0" izz="0.0"/>
    </inertial>
  </link>
  <joint name="chest_ems_gyro_eb2_joint" type="fixed">
    <origin xyz="0.016037100190735 0.08755899999999998 -0.0653479" rpy="3.1415905952453613 0.26179930567741394 3.1415843963623047"/>
    <parent link="chest"/>
    <child link="chest_ems_gyro_eb2"/>
  </joint>
  <link name="chest_ems_gyro_eb2">
    <inertial>
      <origin xyz="0.0 0.0 0.0" rpy="0.0 0.0 0.0"/>
      <mass value="0.0"/>
      <inertia ixx="0.0" ixy="0.0" ixz="0.0" iyy="0.0" iyz="0.0" izz="0.0"/>
    </inertial>
  </link>
  <joint name="chest_ems_gyro_eb3_joint" type="fixed">
    <origin xyz="-0.018641699809265 0.064521 -0.0770785" rpy="3.1411092281341553 0.26110053062438965 -0.0003090714744757861"/>
    <parent link="chest"/>
    <child link="chest_ems_gyro_eb3"/>
  </joint>
  <link name="chest_ems_gyro_eb3">
    <inertial>
      <origin xyz="0.0 0.0 0.0" rpy="0.0 0.0 0.0"/>
      <mass value="0.0"/>
      <inertia ixx="0.0" ixy="0.0" ixz="0.0" iyy="0.0" iyz="0.0" izz="0.0"/>
    </inertial>
  </link>
  <joint name="chest_ems_gyro_eb4_joint" type="fixed">
    <origin xyz="-0.06657839980926501 0.08755899999999998 -0.0518054" rpy="-3.1415905952453613 -0.26179930567741394 3.1415843963623047"/>
    <parent link="chest"/>
    <child link="chest_ems_gyro_eb4"/>
  </joint>
  <link name="chest_ems_gyro_eb4">
    <inertial>
      <origin xyz="0.0 0.0 0.0" rpy="0.0 0.0 0.0"/>
      <mass value="0.0"/>
      <inertia ixx="0.0" ixy="0.0" ixz="0.0" iyy="0.0" iyz="0.0" izz="0.0"/>
    </inertial>
  </link>
  <joint name="neck_pitch" type="revolute">
    <origin xyz="-0.014299999922513962 0.17279699444770813 0.005311800166964531" rpy="0.0 0.0 0.0"/>
    <axis xyz="-1.0 0.0 0.0"/>
    <parent link="chest"/>
    <child link="neck_1"/>
    <limit effort="50000.0" lower="-0.6981316804885864" upper="0.3839724361896515" velocity="50000.0"/>
  </joint>
  <link name="neck_1">
    <inertial>
      <origin xyz="0.014370560646057129 0.006566999945789576 -0.0063841999508440495" rpy="-0.012176013551652431 -0.7853439450263977 -1.5581969022750854"/>
      <mass value="0.125792995095253"/>
      <inertia ixx="0.009990601800382137" ixy="0.0" ixz="0.0" iyy="0.010000000707805157" iyz="0.0" izz="0.010009396821260452"/>
    </inertial>
    <visual name="SM_neck_1_visual_0">
      <origin xyz="0.014299999922513962 -0.0799970030784607 -0.029500799253582954" rpy="0.0 0.0 0.0"/>
      <geometry>
        <mesh filename="file://iCub/meshes/stl/sim_sea_2-5_neck_1_prt-binary.stl" scale="0.0010000000474974513 0.0010000000474974513 0.0010000000474974513"/>
      </geometry>
    </visual>
    <collision name="SM_neck_1_collision_0">
      <origin xyz="0.014299999922513962 -0.0799970030784607 -0.029500799253582954" rpy="0.0 0.0 0.0"/>
      <geometry>
        <mesh filename="file://iCub/meshes/stl/sim_sea_2-5_neck_1_prt-binary.stl" scale="0.0010000000474974513 0.0010000000474974513 0.0010000000474974513"/>
      </geometry>
    </collision>
  </link>
  <joint name="neck_roll" type="revolute">
    <origin xyz="0.014299999922513962 0.009499999694526196 0.020799970254302025" rpy="0.0 0.0 0.0"/>
    <axis xyz="0.0 0.0 1.0"/>
    <parent link="neck_1"/>
    <child link="neck_2"/>
    <limit effort="50000.0" lower="-0.3490658402442932" upper="0.3490658402442932" velocity="50000.0"/>
  </joint>
  <link name="neck_2">
    <inertial>
      <origin xyz="-8.857301145326346e-05 0.035225000232458115 -0.01954527013003826" rpy="0.07507078349590302 -0.7827273011207581 -1.671195387840271"/>
      <mass value="0.1770869940519333"/>
      <inertia ixx="0.009990135207772255" ixy="0.0" ixz="0.0" iyy="0.010000050067901611" iyz="0.0" izz="0.010009814985096455"/>
    </inertial>
    <visual name="SM_neck_2_visual_0">
      <origin xyz="0.0 -0.08949699997901917 -0.05030076950788498" rpy="0.0 0.0 0.0"/>
      <geometry>
        <mesh filename="file://iCub/meshes/stl/sim_sea_2-5_neck_2_prt-binary.stl" scale="0.0010000000474974513 0.0010000000474974513 0.0010000000474974513"/>
      </geometry>
    </visual>
    <collision name="SM_neck_2_collision_0">
      <origin xyz="0.0 -0.08949699997901917 -0.05030076950788498" rpy="0.0 0.0 0.0"/>
      <geometry>
        <mesh filename="file://iCub/meshes/stl/sim_sea_2-5_neck_2_prt-binary.stl" scale="0.0010000000474974513 0.0010000000474974513 0.0010000000474974513"/>
      </geometry>
    </collision>
  </link>
  <joint name="neck_yaw" type="revolute">
    <origin xyz="0.0 -0.02234400063753128 -0.020799970254302025" rpy="0.0 0.0 0.0"/>
    <axis xyz="0.0 1.0 0.0"/>
    <parent link="neck_2"/>
    <child link="head"/>
    <limit effort="50000.0" lower="-0.8726646304130554" upper="0.8726646304130554" velocity="50000.0"/>
  </joint>
  <link name="head">
    <inertial>
      <origin xyz="-0.0005741578061133623 0.11351100355386734 -0.007539200130850077" rpy="1.7597109079360962 -1.3887102603912354 -1.7698891162872314"/>
      <mass value="1.506909966468811"/>
      <inertia ixx="0.004725789185613394" ixy="0.0" ixz="0.0" iyy="0.006400040816515684" iyz="0.0" izz="0.006807469762861729"/>
    </inertial>
    <visual name="SM_head_visual_0">
      <origin xyz="0.0 -0.06715299934148788 -0.029500799253582954" rpy="0.0 0.0 0.0"/>
      <geometry>
        <mesh filename="file://iCub/meshes/stl/sim_sea_2-5_head_prt-binary.stl" scale="0.0010000000474974513 0.0010000000474974513 0.0010000000474974513"/>
      </geometry>
    </visual>
    <collision name="SM_head_collision_0">
      <origin xyz="0.0 -0.06715299934148788 -0.029500799253582954" rpy="0.0 0.0 0.0"/>
      <geometry>
        <mesh filename="file://iCub/meshes/stl/sim_sea_2-5_head_prt-binary.stl" scale="0.0010000000474974513 0.0010000000474974513 0.0010000000474974513"/>
      </geometry>
    </collision>
  </link>
  <joint name="head_imu_0_joint" type="fixed">
    <origin xyz="0.009500000190735 0.133444 0.009299999999999996" rpy="-1.5707963705062866 1.5707963705062866 0.0"/>
    <parent link="head"/>
    <child link="head_imu_0"/>
  </joint>
  <link name="head_imu_0">
    <inertial>
      <origin xyz="0.0 0.0 0.0" rpy="0.0 0.0 0.0"/>
      <mass value="0.0"/>
      <inertia ixx="0.0" ixy="0.0" ixz="0.0" iyy="0.0" iyz="0.0" izz="0.0"/>
    </inertial>
  </link>
  <joint name="r_shoulder_pitch" type="revolute">
    <origin xyz="-0.12001600116491318 0.09279999881982803 0.007969300262629986" rpy="0.0 -0.5235989093780518 3.1415927410125732"/>
    <axis xyz="-0.965925931930542 0.0 0.2588192820549011"/>
    <parent link="chest"/>
    <child link="r_shoulder_1"/>
    <limit effort="50000.0" lower="-1.6667894124984741" upper="0.1745329201221466" velocity="50000.0"/>
  </joint>
  <link name="r_shoulder_1">
    <inertial>
      <origin xyz="-0.012265601195394993 3.199999991920777e-05 -0.0032106428407132626" rpy="3.1350295543670654 -0.7853473424911499 0.021884895861148834"/>
      <mass value="0.11486200243234634"/>
      <inertia ixx="0.009996443055570126" ixy="0.0" ixz="0.0" iyy="0.010000000707805157" iyz="0.0" izz="0.010003556497395039"/>
    </inertial>
    <visual name="SM_r_shoulder_1_visual_0">
      <origin xyz="0.09900792688131332 0.0 -0.02652924880385399" rpy="0.0 0.0 0.0"/>
      <geometry>
        <mesh filename="file://iCub/meshes/stl/sim_sea_2-5_r_shoulder_1_prt-binary.stl" scale="0.0010000000474974513 0.0010000000474974513 0.0010000000474974513"/>
      </geometry>
    </visual>
    <collision name="SM_r_shoulder_1_collision_0">
      <origin xyz="0.09900792688131332 0.0 -0.02652924880385399" rpy="0.0 0.0 0.0"/>
      <geometry>
        <mesh filename="file://iCub/meshes/stl/sim_sea_2-5_r_shoulder_1_prt-binary.stl" scale="0.0010000000474974513 0.0010000000474974513 0.0010000000474974513"/>
      </geometry>
    </collision>
  </link>
  <joint name="r_shoulder_roll" type="revolute">
    <origin xyz="-0.007580465637147427 0.0 0.014210246503353119" rpy="-0.2705976068973541 -0.2526801526546478 -1.5015567541122437"/>
    <axis xyz="-0.25881901383399963 -2.028522643996249e-17 -0.9659259915351868"/>
    <parent link="r_shoulder_1"/>
    <child link="r_shoulder_2"/>
    <limit effort="50000.0" lower="0.0" upper="2.8064894676208496" velocity="50000.0"/>
  </joint>
  <link name="r_shoulder_2">
    <inertial>
      <origin xyz="-0.021414170041680336 0.00027172526461072266 -0.01944023370742798" rpy="0.014926671981811523 0.7847174406051636 0.12677408754825592"/>
      <mass value="0.23816199600696564"/>
      <inertia ixx="0.009989659301936626" ixy="0.0" ixz="0.0" iyy="0.010000025853514671" iyz="0.0" izz="0.010010315105319023"/>
    </inertial>
    <visual name="SM_r_shoulder_2_visual_0">
      <origin xyz="0.10658780485391617 2.3191471143491071e-07 -0.040739212185144424" rpy="0.0 0.0 0.0"/>
      <geometry>
        <mesh filename="file://iCub/meshes/stl/sim_sea_2-5_r_shoulder_2_prt-binary.stl" scale="0.0010000000474974513 0.0010000000474974513 0.0010000000474974513"/>
      </geometry>
    </visual>
    <collision name="SM_r_shoulder_2_collision_0">
      <origin xyz="0.10658780485391617 2.3191471143491071e-07 -0.040739212185144424" rpy="0.0 0.0 0.0"/>
      <geometry>
        <mesh filename="file://iCub/meshes/stl/sim_sea_2-5_r_shoulder_2_prt-binary.stl" scale="0.0010000000474974513 0.0010000000474974513 0.0010000000474974513"/>
      </geometry>
    </collision>
  </link>
  <joint name="r_shoulder_yaw" type="revolute">
    <origin xyz="-0.025346070528030396 2.3275042337900231e-07 -0.00538764800876379" rpy="-0.25268954038619995 0.008518618531525135 0.06703989207744598"/>
    <axis xyz="0.9659258723258972 -2.220446049250313e-16 -0.25881898403167725"/>
    <parent link="r_shoulder_2"/>
    <child link="r_shoulder_3"/>
    <limit effort="50000.0" lower="-0.6457718014717102" upper="1.3962633609771729" velocity="50000.0"/>
  </joint>
  <link name="r_shoulder_3">
    <inertial>
      <origin xyz="-0.02676207758486271 -7.000000096013537e-06 0.014699921011924744" rpy="3.13128662109375 0.7853912115097046 -0.0019101197831332684"/>
      <mass value="0.35912999510765076"/>
      <inertia ixx="0.009950555860996246" ixy="0.0" ixz="0.0" iyy="0.009999996051192284" iyz="0.0" izz="0.010049448348581791"/>
    </inertial>
    <visual name="SM_r_shoulder_3_visual_0">
      <origin xyz="0.13193388283252716 0.0 -0.03535156697034836" rpy="0.0 0.0 0.0"/>
      <geometry>
        <mesh filename="file://iCub/meshes/stl/sim_sea_2-5_r_upper_arm_prt-binary.stl" scale="0.0010000000474974513 0.0010000000474974513 0.0010000000474974513"/>
      </geometry>
    </visual>
    <collision name="SM_r_shoulder_3_collision_0">
      <origin xyz="0.13193388283252716 0.0 -0.03535156697034836" rpy="0.0 0.0 0.0"/>
      <geometry>
        <mesh filename="file://iCub/meshes/stl/sim_sea_2-5_r_upper_arm_prt-binary.stl" scale="0.0010000000474974513 0.0010000000474974513 0.0010000000474974513"/>
      </geometry>
    </collision>
  </link>
  <joint name="r_arm_ft_imu_joint" type="fixed">
    <origin xyz="-0.05089730176650909 0.0 0.029167029620599215" rpy="0.0 -1.3089970350265503 0.0"/>
    <parent link="r_shoulder_3"/>
    <child link="r_arm_ft_imu"/>
  </joint>
  <link name="r_arm_ft_imu">
    <inertial>
      <origin xyz="0.0 0.0 0.0" rpy="0.0 0.0 0.0"/>
      <mass value="0.0"/>
      <inertia ixx="0.0" ixy="0.0" ixz="0.0" iyy="0.0" iyz="0.0" izz="0.0"/>
    </inertial>
  </link>
  <joint name="r_upper_arm_joint" type="fixed">
    <origin xyz="-0.05089730176650909 0.0 0.029167029620599215" rpy="0.0 -1.3089970350265503 0.0"/>
    <parent link="r_shoulder_3"/>
    <child link="r_upper_arm"/>
  </joint>
  <link name="r_upper_arm">
    <inertial>
      <origin xyz="-0.006087000016123056 0.00012599999899975955 0.029312100261449814" rpy="-1.6465784311294556 1.436828374862671 3.0796029567718506"/>
      <mass value="0.7451040148735046"/>
      <inertia ixx="0.0005080046830698848" ixy="0.0" ixz="0.0" iyy="0.0006007513729855418" iyz="0.0" izz="0.0006685119587928057"/>
    </inertial>
    <visual name="SM_r_upper_arm_visual_0">
      <origin xyz="-0.014999999664723873 0.0 -0.19329999387264252" rpy="0.0 1.3089970350265503 0.0"/>
      <geometry>
        <mesh filename="file://iCub/meshes/stl/sim_sea_2-5_r_elbow_prt-binary.stl" scale="0.0010000000474974513 0.0010000000474974513 0.0010000000474974513"/>
      </geometry>
    </visual>
    <collision name="SM_r_upper_arm_collision_0">
      <origin xyz="-0.014999999664723873 0.0 -0.19329999387264252" rpy="0.0 1.3089970350265503 0.0"/>
      <geometry>
        <mesh filename="file://iCub/meshes/stl/sim_sea_2-5_r_elbow_prt-binary.stl" scale="0.0010000000474974513 0.0010000000474974513 0.0010000000474974513"/>
      </geometry>
    </collision>
  </link>
  <joint name="r_elbow" type="revolute">
    <origin xyz="0.0 -0.022499900311231613 0.07925999909639359" rpy="0.0 1.3089970350265503 0.0"/>
    <axis xyz="2.220446049250313e-16 1.0 0.0"/>
    <parent link="r_upper_arm"/>
    <child link="r_elbow_1"/>
    <limit effort="50000.0" lower="0.2617993950843811" upper="1.8500490188598633" velocity="50000.0"/>
  </joint>
  <link name="r_elbow_1">
    <inertial>
      <origin xyz="-0.006739129312336445 0.018801899626851082 -0.004657692275941372" rpy="-2.406513214111328 -0.6272498369216919 -0.63404381275177"/>
      <mass value="0.26790300011634827"/>
      <inertia ixx="0.009985174983739853" ixy="0.0" ixz="0.0" iyy="0.010003650560975075" iyz="0.0" izz="0.010011174716055393"/>
    </inertial>
    <visual name="SM_r_elbow_1_visual_0">
      <origin xyz="0.2593904733657837 0.022499900311231613 -0.08503258973360062" rpy="0.0 0.0 0.0"/>
      <geometry>
        <mesh filename="file://iCub/meshes/stl/sim_sea_2-5_r_elbow_prosup_prt-binary.stl" scale="0.0010000000474974513 0.0010000000474974513 0.0010000000474974513"/>
      </geometry>
    </visual>
    <collision name="SM_r_elbow_1_collision_0">
      <origin xyz="0.2593904733657837 0.022499900311231613 -0.08503258973360062" rpy="0.0 0.0 0.0"/>
      <geometry>
        <mesh filename="file://iCub/meshes/stl/sim_sea_2-5_r_elbow_prosup_prt-binary.stl" scale="0.0010000000474974513 0.0010000000474974513 0.0010000000474974513"/>
      </geometry>
    </collision>
  </link>
  <joint name="r_wrist_prosup" type="revolute">
    <origin xyz="-0.038462430238723755 0.022499900311231613 -0.005223168060183525" rpy="0.0 0.0 0.0"/>
    <axis xyz="0.9659258723258972 -2.220446049250313e-16 -0.25881898403167725"/>
    <parent link="r_elbow_1"/>
    <child link="r_forearm"/>
    <limit effort="50000.0" lower="-1.0471975803375244" upper="1.0471975803375244" velocity="50000.0"/>
  </joint>
  <link name="r_forearm">
    <inertial>
      <origin xyz="-0.04043911397457123 -0.0003279999946244061 0.005327334627509117" rpy="-1.5631664991378784 0.42708972096443176 0.00621217954903841"/>
      <mass value="0.6347000002861023"/>
      <inertia ixx="0.00032207401818595827" ixy="0.0" ixz="0.0" iyy="0.0006015939870849252" iyz="0.0" izz="0.0006722920225001872"/>
    </inertial>
    <visual name="SM_r_forearm_visual_0">
      <origin xyz="0.29688698053359985 0.0 -0.079550601541996" rpy="0.0 0.0 0.0"/>
      <geometry>
        <mesh filename="file://iCub/meshes/stl/sim_sea_2-5_r_forearm_prt-binary.stl" scale="0.0010000000474974513 0.0010000000474974513 0.0010000000474974513"/>
      </geometry>
    </visual>
    <collision name="SM_r_forearm_collision_0">
      <origin xyz="0.29688698053359985 0.0 -0.079550601541996" rpy="0.0 0.0 0.0"/>
      <geometry>
        <mesh filename="file://iCub/meshes/stl/sim_sea_2-5_r_forearm_prt-binary.stl" scale="0.0010000000474974513 0.0010000000474974513 0.0010000000474974513"/>
      </geometry>
    </collision>
  </link>
  <joint name="r_forearm_skin_0_joint" type="fixed">
    <origin xyz="-0.04544932866182965 0.030076999999999993 -0.006286560379014218" rpy="1.6918152570724487 -0.27102673053741455 -3.0688042640686035"/>
    <parent link="r_forearm"/>
    <child link="r_forearm_skin_0"/>
  </joint>
  <link name="r_forearm_skin_0">
    <inertial>
      <origin xyz="0.0 0.0 0.0" rpy="0.0 0.0 0.0"/>
      <mass value="0.0"/>
      <inertia ixx="0.0" ixy="0.0" ixz="0.0" iyy="0.0" iyz="0.0" izz="0.0"/>
    </inertial>
  </link>
  <joint name="r_forearm_skin_1_joint" type="fixed">
    <origin xyz="-0.03337289358257035 0.02882600000000002 -0.019845686771095515" rpy="1.8669402599334717 -0.27444252371788025 -3.0994696617126465"/>
    <parent link="r_forearm"/>
    <child link="r_forearm_skin_1"/>
  </joint>
  <link name="r_forearm_skin_1">
    <inertial>
      <origin xyz="0.0 0.0 0.0" rpy="0.0 0.0 0.0"/>
      <mass value="0.0"/>
      <inertia ixx="0.0" ixy="0.0" ixz="0.0" iyy="0.0" iyz="0.0" izz="0.0"/>
    </inertial>
  </link>
  <joint name="r_forearm_skin_2_joint" type="fixed">
    <origin xyz="-0.014698892985226357 0.031278999999999973 -0.016011733837060345" rpy="1.7284728288650513 -0.26401522755622864 -3.1273326873779297"/>
    <parent link="r_forearm"/>
    <child link="r_forearm_skin_2"/>
  </joint>
  <link name="r_forearm_skin_2">
    <inertial>
      <origin xyz="0.0 0.0 0.0" rpy="0.0 0.0 0.0"/>
      <mass value="0.0"/>
      <inertia ixx="0.0" ixy="0.0" ixz="0.0" iyy="0.0" iyz="0.0" izz="0.0"/>
    </inertial>
  </link>
  <joint name="r_forearm_skin_3_joint" type="fixed">
    <origin xyz="-0.04556729362200617 -0.030891000000000002 -0.006330009293506465" rpy="-1.6948728561401367 -0.2697577178478241 3.0795974731445312"/>
    <parent link="r_forearm"/>
    <child link="r_forearm_skin_3"/>
  </joint>
  <link name="r_forearm_skin_3">
    <inertial>
      <origin xyz="0.0 0.0 0.0" rpy="0.0 0.0 0.0"/>
      <mass value="0.0"/>
      <inertia ixx="0.0" ixy="0.0" ixz="0.0" iyy="0.0" iyz="0.0" izz="0.0"/>
    </inertial>
  </link>
  <joint name="r_forearm_skin_4_joint" type="fixed">
    <origin xyz="-0.06353263329961753 -0.02811630000000001 -0.008997842580659854" rpy="-1.8073495626449585 -0.0393131785094738 2.9799764156341553"/>
    <parent link="r_forearm"/>
    <child link="r_forearm_skin_4"/>
  </joint>
  <link name="r_forearm_skin_4">
    <inertial>
      <origin xyz="0.0 0.0 0.0" rpy="0.0 0.0 0.0"/>
      <mass value="0.0"/>
      <inertia ixx="0.0" ixy="0.0" ixz="0.0" iyy="0.0" iyz="0.0" izz="0.0"/>
    </inertial>
  </link>
  <joint name="r_forearm_skin_5_joint" type="fixed">
    <origin xyz="-0.06882119419679653 -0.0179483 -0.023113336179072505" rpy="-2.5410475730895996 -0.38562726974487305 3.0548698902130127"/>
    <parent link="r_forearm"/>
    <child link="r_forearm_skin_5"/>
  </joint>
  <link name="r_forearm_skin_5">
    <inertial>
      <origin xyz="0.0 0.0 0.0" rpy="0.0 0.0 0.0"/>
      <mass value="0.0"/>
      <inertia ixx="0.0" ixy="0.0" ixz="0.0" iyy="0.0" iyz="0.0" izz="0.0"/>
    </inertial>
  </link>
  <joint name="r_forearm_skin_6_joint" type="fixed">
    <origin xyz="-0.033394843625473715 -0.029547900000000002 -0.019832558343293956" rpy="-1.8662816286087036 -0.27288633584976196 3.1044857501983643"/>
    <parent link="r_forearm"/>
    <child link="r_forearm_skin_6"/>
  </joint>
  <link name="r_forearm_skin_6">
    <inertial>
      <origin xyz="0.0 0.0 0.0" rpy="0.0 0.0 0.0"/>
      <mass value="0.0"/>
      <inertia ixx="0.0" ixy="0.0" ixz="0.0" iyy="0.0" iyz="0.0" izz="0.0"/>
    </inertial>
  </link>
  <joint name="r_forearm_skin_7_joint" type="fixed">
    <origin xyz="-0.014722426007426966 -0.031942200000000004 -0.015932648270323382" rpy="-1.7256463766098022 -0.26399290561676025 3.1272125244140625"/>
    <parent link="r_forearm"/>
    <child link="r_forearm_skin_7"/>
  </joint>
  <link name="r_forearm_skin_7">
    <inertial>
      <origin xyz="0.0 0.0 0.0" rpy="0.0 0.0 0.0"/>
      <mass value="0.0"/>
      <inertia ixx="0.0" ixy="0.0" ixz="0.0" iyy="0.0" iyz="0.0" izz="0.0"/>
    </inertial>
  </link>
  <joint name="r_forearm_skin_8_joint" type="fixed">
    <origin xyz="-0.0228528628554271 -0.009786200000000009 -0.041885146374950645" rpy="-2.9480197429656982 -0.27060508728027344 3.139805555343628"/>
    <parent link="r_forearm"/>
    <child link="r_forearm_skin_8"/>
  </joint>
  <link name="r_forearm_skin_8">
    <inertial>
      <origin xyz="0.0 0.0 0.0" rpy="0.0 0.0 0.0"/>
      <mass value="0.0"/>
      <inertia ixx="0.0" ixy="0.0" ixz="0.0" iyy="0.0" iyz="0.0" izz="0.0"/>
    </inertial>
  </link>
  <joint name="r_forearm_skin_9_joint" type="fixed">
    <origin xyz="-0.03760327346828466 -0.018955000000000014 -0.03401633711864639" rpy="-2.5840651988983154 -0.29332172870635986 3.121284008026123"/>
    <parent link="r_forearm"/>
    <child link="r_forearm_skin_9"/>
  </joint>
  <link name="r_forearm_skin_9">
    <inertial>
      <origin xyz="0.0 0.0 0.0" rpy="0.0 0.0 0.0"/>
      <mass value="0.0"/>
      <inertia ixx="0.0" ixy="0.0" ixz="0.0" iyy="0.0" iyz="0.0" izz="0.0"/>
    </inertial>
  </link>
  <joint name="r_forearm_skin_10_joint" type="fixed">
    <origin xyz="-0.05422852108875307 -0.009786099999999992 -0.03214690828659369" rpy="-2.9412331581115723 -0.3283044695854187 3.127626419067383"/>
    <parent link="r_forearm"/>
    <child link="r_forearm_skin_10"/>
  </joint>
  <link name="r_forearm_skin_10">
    <inertial>
      <origin xyz="0.0 0.0 0.0" rpy="0.0 0.0 0.0"/>
      <mass value="0.0"/>
      <inertia ixx="0.0" ixy="0.0" ixz="0.0" iyy="0.0" iyz="0.0" izz="0.0"/>
    </inertial>
  </link>
  <joint name="r_forearm_skin_11_joint" type="fixed">
    <origin xyz="-0.05422409120236691 0.00904300000000001 -0.03214312594517525" rpy="2.939298391342163 -0.3291013836860657 -3.127319097518921"/>
    <parent link="r_forearm"/>
    <child link="r_forearm_skin_11"/>
  </joint>
  <link name="r_forearm_skin_11">
    <inertial>
      <origin xyz="0.0 0.0 0.0" rpy="0.0 0.0 0.0"/>
      <mass value="0.0"/>
      <inertia ixx="0.0" ixy="0.0" ixz="0.0" iyy="0.0" iyz="0.0" izz="0.0"/>
    </inertial>
  </link>
  <joint name="r_forearm_skin_12_joint" type="fixed">
    <origin xyz="-0.03759946338683661 0.01821600000000001 -0.034019117996090566" rpy="2.5830349922180176 -0.2948305010795593 -3.1202657222747803"/>
    <parent link="r_forearm"/>
    <child link="r_forearm_skin_12"/>
  </joint>
  <link name="r_forearm_skin_12">
    <inertial>
      <origin xyz="0.0 0.0 0.0" rpy="0.0 0.0 0.0"/>
      <mass value="0.0"/>
      <inertia ixx="0.0" ixy="0.0" ixz="0.0" iyy="0.0" iyz="0.0" izz="0.0"/>
    </inertial>
  </link>
  <joint name="r_forearm_skin_13_joint" type="fixed">
    <origin xyz="-0.022855086840518728 0.009047999999999987 -0.04189190092085042" rpy="2.9489667415618896 -0.27058395743370056 -3.1398189067840576"/>
    <parent link="r_forearm"/>
    <child link="r_forearm_skin_13"/>
  </joint>
  <link name="r_forearm_skin_13">
    <inertial>
      <origin xyz="0.0 0.0 0.0" rpy="0.0 0.0 0.0"/>
      <mass value="0.0"/>
      <inertia ixx="0.0" ixy="0.0" ixz="0.0" iyy="0.0" iyz="0.0" izz="0.0"/>
    </inertial>
  </link>
  <joint name="r_forearm_skin_14_joint" type="fixed">
    <origin xyz="-0.06877032763640067 0.01716000000000001 -0.02302395585107192" rpy="2.480449914932251 -0.29554256796836853 -2.9187734127044678"/>
    <parent link="r_forearm"/>
    <child link="r_forearm_skin_14"/>
  </joint>
  <link name="r_forearm_skin_14">
    <inertial>
      <origin xyz="0.0 0.0 0.0" rpy="0.0 0.0 0.0"/>
      <mass value="0.0"/>
      <inertia ixx="0.0" ixy="0.0" ixz="0.0" iyy="0.0" iyz="0.0" izz="0.0"/>
    </inertial>
  </link>
  <joint name="r_forearm_skin_15_joint" type="fixed">
    <origin xyz="-0.06337864196616988 0.027145000000000002 -0.008794054555439966" rpy="1.8049277067184448 -0.2897832691669464 -3.0276589393615723"/>
    <parent link="r_forearm"/>
    <child link="r_forearm_skin_15"/>
  </joint>
  <link name="r_forearm_skin_15">
    <inertial>
      <origin xyz="0.0 0.0 0.0" rpy="0.0 0.0 0.0"/>
      <mass value="0.0"/>
      <inertia ixx="0.0" ixy="0.0" ixz="0.0" iyy="0.0" iyz="0.0" izz="0.0"/>
    </inertial>
  </link>
  <joint name="r_forearm_skin_16_joint" type="fixed">
    <origin xyz="-0.03792482186997503 0.030487000000000014 0.020636950360473926" rpy="1.4128000736236572 -0.25082463026046753 -3.065727472305298"/>
    <parent link="r_forearm"/>
    <child link="r_forearm_skin_16"/>
  </joint>
  <link name="r_forearm_skin_16">
    <inertial>
      <origin xyz="0.0 0.0 0.0" rpy="0.0 0.0 0.0"/>
      <mass value="0.0"/>
      <inertia ixx="0.0" ixy="0.0" ixz="0.0" iyy="0.0" iyz="0.0" izz="0.0"/>
    </inertial>
  </link>
  <joint name="r_forearm_skin_17_joint" type="fixed">
    <origin xyz="-0.05431705488213744 0.027725000000000027 0.030329124017862287" rpy="1.2722371816635132 -0.23059304058551788 -3.0319554805755615"/>
    <parent link="r_forearm"/>
    <child link="r_forearm_skin_17"/>
  </joint>
  <link name="r_forearm_skin_17">
    <inertial>
      <origin xyz="0.0 0.0 0.0" rpy="0.0 0.0 0.0"/>
      <mass value="0.0"/>
      <inertia ixx="0.0" ixy="0.0" ixz="0.0" iyy="0.0" iyz="0.0" izz="0.0"/>
    </inertial>
  </link>
  <joint name="r_forearm_skin_19_joint" type="fixed">
    <origin xyz="-0.038126610713769264 -0.03129409999999999 0.02069060539304483" rpy="-1.4156088829040527 -0.2525692880153656 3.0771522521972656"/>
    <parent link="r_forearm"/>
    <child link="r_forearm_skin_19"/>
  </joint>
  <link name="r_forearm_skin_19">
    <inertial>
      <origin xyz="0.0 0.0 0.0" rpy="0.0 0.0 0.0"/>
      <mass value="0.0"/>
      <inertia ixx="0.0" ixy="0.0" ixz="0.0" iyy="0.0" iyz="0.0" izz="0.0"/>
    </inertial>
  </link>
  <joint name="r_forearm_skin_22_joint" type="fixed">
    <origin xyz="-0.05441739504212798 -0.028722300000000006 0.030603751660850165" rpy="-1.265824317932129 -0.23432815074920654 3.0478832721710205"/>
    <parent link="r_forearm"/>
    <child link="r_forearm_skin_22"/>
  </joint>
  <link name="r_forearm_skin_22">
    <inertial>
      <origin xyz="0.0 0.0 0.0" rpy="0.0 0.0 0.0"/>
      <mass value="0.0"/>
      <inertia ixx="0.0" ixy="0.0" ixz="0.0" iyy="0.0" iyz="0.0" izz="0.0"/>
    </inertial>
  </link>
  <joint name="r_forearm_skin_24_joint" type="fixed">
    <origin xyz="-0.07003453195640522 -0.009716399999999986 0.05006910871401307" rpy="-0.23489327728748322 -0.03881729766726494 3.086763381958008"/>
    <parent link="r_forearm"/>
    <child link="r_forearm_skin_24"/>
  </joint>
  <link name="r_forearm_skin_24">
    <inertial>
      <origin xyz="0.0 0.0 0.0" rpy="0.0 0.0 0.0"/>
      <mass value="0.0"/>
      <inertia ixx="0.0" ixy="0.0" ixz="0.0" iyy="0.0" iyz="0.0" izz="0.0"/>
    </inertial>
  </link>
  <joint name="r_forearm_skin_25_joint" type="fixed">
    <origin xyz="-0.053599921629492835 -0.018223800000000012 0.04546981250452139" rpy="-0.5642955303192139 -0.13698026537895203 3.059631824493408"/>
    <parent link="r_forearm"/>
    <child link="r_forearm_skin_25"/>
  </joint>
  <link name="r_forearm_skin_25">
    <inertial>
      <origin xyz="0.0 0.0 0.0" rpy="0.0 0.0 0.0"/>
      <mass value="0.0"/>
      <inertia ixx="0.0" ixy="0.0" ixz="0.0" iyy="0.0" iyz="0.0" izz="0.0"/>
    </inertial>
  </link>
  <joint name="r_forearm_skin_28_joint" type="fixed">
    <origin xyz="-0.05358592721475829 0.01741200000000001 0.04535203739698063" rpy="0.5907706618309021 -0.05316072329878807 3.105970859527588"/>
    <parent link="r_forearm"/>
    <child link="r_forearm_skin_28"/>
  </joint>
  <link name="r_forearm_skin_28">
    <inertial>
      <origin xyz="0.0 0.0 0.0" rpy="0.0 0.0 0.0"/>
      <mass value="0.0"/>
      <inertia ixx="0.0" ixy="0.0" ixz="0.0" iyy="0.0" iyz="0.0" izz="0.0"/>
    </inertial>
  </link>
  <joint name="r_forearm_skin_29_joint" type="fixed">
    <origin xyz="-0.07003558050313372 0.008954000000000018 0.05001110362329029" rpy="0.24863098561763763 -0.03831365704536438 -3.0832901000976562"/>
    <parent link="r_forearm"/>
    <child link="r_forearm_skin_29"/>
  </joint>
  <link name="r_forearm_skin_29">
    <inertial>
      <origin xyz="0.0 0.0 0.0" rpy="0.0 0.0 0.0"/>
      <mass value="0.0"/>
      <inertia ixx="0.0" ixy="0.0" ixz="0.0" iyy="0.0" iyz="0.0" izz="0.0"/>
    </inertial>
  </link>
  <joint name="r_forearm_dh_frame_joint" type="fixed">
    <origin xyz="-0.1028711023733811 7.000000000020878e-06 0.027564221311064674" rpy="-0.26179930567741394 0.0 -1.5707963705062866"/>
    <parent link="r_forearm"/>
    <child link="r_forearm_dh_frame"/>
  </joint>
  <link name="r_forearm_dh_frame">
    <inertial>
      <origin xyz="0.0 0.0 0.0" rpy="0.0 0.0 0.0"/>
      <mass value="0.0"/>
      <inertia ixx="0.0" ixy="0.0" ixz="0.0" iyy="0.0" iyz="0.0" izz="0.0"/>
    </inertial>
  </link>
  <joint name="r_wrist_pitch" type="revolute">
    <origin xyz="-0.1035052090883255 7.000000096013537e-06 0.025197703391313553" rpy="0.0 0.0 0.0"/>
    <axis xyz="0.25881898403167725 0.0 0.9659258723258972"/>
    <parent link="r_forearm"/>
    <child link="r_wrist_1"/>
    <limit effort="50000.0" lower="-1.3962633609771729" upper="0.4363323152065277" velocity="50000.0"/>
  </joint>
  <link name="r_wrist_1">
    <inertial>
      <origin xyz="0.0009861019207164645 -0.0011759999906644225 0.004101327154785395" rpy="3.098438262939453 -0.7822778224945068 0.19757810235023499"/>
      <mass value="0.03626149892807007"/>
      <inertia ixx="0.00999903678894043" ixy="0.0" ixz="0.0" iyy="0.010000010021030903" iyz="0.0" izz="0.010000953450798988"/>
    </inertial>
    <visual name="SM_r_wrist_1_visual_0">
      <origin xyz="0.40039217472076416 -7.000000096013537e-06 -0.10474830120801926" rpy="0.0 0.0 0.0"/>
      <geometry>
        <mesh filename="file://iCub/meshes/stl/sim_sea_2-5_r_wrist_pitch_prt-binary.stl" scale="0.0010000000474974513 0.0010000000474974513 0.0010000000474974513"/>
      </geometry>
    </visual>
    <collision name="SM_r_wrist_1_collision_0">
      <origin xyz="0.40039217472076416 -7.000000096013537e-06 -0.10474830120801926" rpy="0.0 0.0 0.0"/>
      <geometry>
        <mesh filename="file://iCub/meshes/stl/sim_sea_2-5_r_wrist_pitch_prt-binary.stl" scale="0.0010000000474974513 0.0010000000474974513 0.0010000000474974513"/>
      </geometry>
    </collision>
  </link>
  <joint name="r_wrist_yaw" type="revolute">
    <origin xyz="0.0006341065163724124 -0.019499899819493294 0.0023665183689445257" rpy="0.0 0.0 0.0"/>
    <axis xyz="-2.220446049250313e-16 -1.0 0.0"/>
    <parent link="r_wrist_1"/>
    <child link="r_hand"/>
    <limit effort="50000.0" lower="-0.3490658402442932" upper="0.4363323152065277" velocity="50000.0"/>
  </joint>
  <link name="r_hand">
    <inertial>
      <origin xyz="-0.06466816365718842 0.005600200034677982 0.02268129400908947" rpy="-0.040082745254039764 -0.7728509306907654 -2.5946850776672363"/>
      <mass value="0.24828900396823883"/>
      <inertia ixx="0.009957289323210716" ixy="0.0" ixz="0.0" iyy="0.01000202912837267" iyz="0.0" izz="0.010040681809186935"/>
    </inertial>
    <visual name="SM_r_hand_visual_0">
      <origin xyz="0.39975807070732117 0.019492899999022484 -0.10711482167243958" rpy="0.0 0.0 0.0"/>
      <geometry>
        <mesh filename="file://iCub/meshes/stl/sim_sea_2-5_r_hand_prt-binary.stl" scale="0.0010000000474974513 0.0010000000474974513 0.0010000000474974513"/>
      </geometry>
    </visual>
    <collision name="SM_r_hand_collision_0">
      <origin xyz="0.39975807070732117 0.019492899999022484 -0.10711482167243958" rpy="0.0 0.0 0.0"/>
      <geometry>
        <mesh filename="file://iCub/meshes/stl/sim_sea_2-5_r_hand_prt-binary.stl" scale="0.0010000000474974513 0.0010000000474974513 0.0010000000474974513"/>
      </geometry>
    </collision>
  </link>
  <joint name="r_hand_dh_frame_joint" type="fixed">
    <origin xyz="-0.05765429784284365 -0.005556799999999987 0.013693832308330513" rpy="-1.5707963705062866 -0.26179930567741394 3.1415927410125732"/>
    <parent link="r_hand"/>
    <child link="r_hand_dh_frame"/>
  </joint>
  <link name="r_hand_dh_frame">
    <inertial>
      <origin xyz="0.0 0.0 0.0" rpy="0.0 0.0 0.0"/>
      <mass value="0.0"/>
      <inertia ixx="0.0" ixy="0.0" ixz="0.0" iyy="0.0" iyz="0.0" izz="0.0"/>
    </inertial>
  </link>
  <joint name="l_shoulder_pitch" type="revolute">
    <origin xyz="0.12001600116491318 0.09279999881982803 0.007969300262629986" rpy="0.0 0.0 0.0"/>
    <axis xyz="0.9659259915351868 0.0 0.25881901383399963"/>
    <parent link="chest"/>
    <child link="l_shoulder_1"/>
    <limit effort="50000.0" lower="-1.6667894124984741" upper="0.1745329201221466" velocity="50000.0"/>
  </joint>
  <link name="l_shoulder_1">
    <inertial>
      <origin xyz="-0.008984999731183052 -3.300000025774352e-05 -0.008899799548089504" rpy="0.00702841579914093 0.785339891910553 0.023440945893526077"/>
      <mass value="0.11488199979066849"/>
      <inertia ixx="0.009996439330279827" ixy="0.0" ixz="0.0" iyy="0.010000000707805157" iyz="0.0" izz="0.010003560222685337"/>
    </inertial>
    <visual name="SM_l_shoulder_1_visual_0">
      <origin xyz="-0.12025748193264008 0.0 -0.03222300112247467" rpy="0.0 0.0 0.0"/>
      <geometry>
        <mesh filename="file://iCub/meshes/stl/sim_sea_2-5_l_shoulder_1_prt-binary.stl" scale="0.0010000000474974513 0.0010000000474974513 0.0010000000474974513"/>
      </geometry>
    </visual>
    <collision name="SM_l_shoulder_1_collision_0">
      <origin xyz="-0.12025748193264008 0.0 -0.03222300112247467" rpy="0.0 0.0 0.0"/>
      <geometry>
        <mesh filename="file://iCub/meshes/stl/sim_sea_2-5_l_shoulder_1_prt-binary.stl" scale="0.0010000000474974513 0.0010000000474974513 0.0010000000474974513"/>
      </geometry>
    </collision>
  </link>
  <joint name="l_shoulder_roll" type="revolute">
    <origin xyz="-0.013670999556779861 0.0 0.008520400151610374" rpy="0.27059730887413025 0.2526801824569702 -1.5015568733215332"/>
    <axis xyz="-0.25881901383399963 2.028522643996249e-17 0.9659259915351868"/>
    <parent link="l_shoulder_1"/>
    <child link="l_shoulder_2"/>
    <limit effort="50000.0" lower="0.0" upper="2.8064894676208496" velocity="50000.0"/>
  </joint>
  <link name="l_shoulder_2">
    <inertial>
      <origin xyz="0.021474594250321388 0.0002689578977879137 -0.019410736858844757" rpy="3.128822088241577 0.7849355340003967 3.0402283668518066"/>
      <mass value="0.23816199600696564"/>
      <inertia ixx="0.00998696405440569" ixy="0.0" ixz="0.0" iyy="0.010000022128224373" iyz="0.0" izz="0.010013014078140259"/>
    </inertial>
    <visual name="SM_l_shoulder_2_visual_0">
      <origin xyz="-0.10658669471740723 1.108009328731896e-07 -0.0407433807849884" rpy="0.0 0.0 0.0"/>
      <geometry>
        <mesh filename="file://iCub/meshes/stl/sim_sea_2-5_l_shoulder_2_prt-binary.stl" scale="0.0010000000474974513 0.0010000000474974513 0.0010000000474974513"/>
      </geometry>
    </visual>
    <collision name="SM_l_shoulder_2_collision_0">
      <origin xyz="-0.10658669471740723 1.108009328731896e-07 -0.0407433807849884" rpy="0.0 0.0 0.0"/>
      <geometry>
        <mesh filename="file://iCub/meshes/stl/sim_sea_2-5_l_shoulder_2_prt-binary.stl" scale="0.0010000000474974513 0.0010000000474974513 0.0010000000474974513"/>
      </geometry>
    </collision>
  </link>
  <joint name="l_shoulder_yaw" type="revolute">
    <origin xyz="0.025314345955848694 1.1163643875988782e-07 -0.005400616675615311" rpy="-0.25268954038619995 -0.008518618531525135 -0.06703989207744598"/>
    <axis xyz="0.9659258723258972 2.220446049250313e-16 0.25881898403167725"/>
    <parent link="l_shoulder_2"/>
    <child link="l_shoulder_3"/>
    <limit effort="50000.0" lower="-0.6457718014717102" upper="1.3962633609771729" velocity="50000.0"/>
  </joint>
  <link name="l_shoulder_3">
    <inertial>
      <origin xyz="0.026798412203788757 -1.5999999959603883e-05 0.01469568070024252" rpy="0.006344161462038755 0.7853929400444031 -3.139275312423706"/>
      <mass value="0.35912999510765076"/>
      <inertia ixx="0.00995041523128748" ixy="0.0" ixz="0.0" iyy="0.009999998845160007" iyz="0.0" izz="0.01004958525300026"/>
    </inertial>
    <visual name="SM_l_shoulder_3_visual_0">
      <origin xyz="-0.13190104067325592 0.0 -0.03534276783466339" rpy="0.0 0.0 0.0"/>
      <geometry>
        <mesh filename="file://iCub/meshes/stl/sim_sea_2-5_l_upper_arm_prt-binary.stl" scale="0.0010000000474974513 0.0010000000474974513 0.0010000000474974513"/>
      </geometry>
    </visual>
    <collision name="SM_l_shoulder_3_collision_0">
      <origin xyz="-0.13190104067325592 0.0 -0.03534276783466339" rpy="0.0 0.0 0.0"/>
      <geometry>
        <mesh filename="file://iCub/meshes/stl/sim_sea_2-5_l_upper_arm_prt-binary.stl" scale="0.0010000000474974513 0.0010000000474974513 0.0010000000474974513"/>
      </geometry>
    </collision>
  </link>
  <joint name="l_arm_ft_imu_joint" type="fixed">
    <origin xyz="0.05093014324520106 0.0 0.029175829465900395" rpy="3.5054707338047475e-16 -1.3089970350265503 3.1415927410125732"/>
    <parent link="l_shoulder_3"/>
    <child link="l_arm_ft_imu"/>
  </joint>
  <link name="l_arm_ft_imu">
    <inertial>
      <origin xyz="0.0 0.0 0.0" rpy="0.0 0.0 0.0"/>
      <mass value="0.0"/>
      <inertia ixx="0.0" ixy="0.0" ixz="0.0" iyy="0.0" iyz="0.0" izz="0.0"/>
    </inertial>
  </link>
  <joint name="l_upper_arm_joint" type="fixed">
    <origin xyz="0.05093014324520106 0.0 0.029175829465900395" rpy="3.5054707338047475e-16 -1.3089970350265503 3.1415927410125732"/>
    <parent link="l_shoulder_3"/>
    <child link="l_upper_arm"/>
  </joint>
  <link name="l_upper_arm">
    <inertial>
      <origin xyz="-0.006120999809354544 -0.00018899999849963933 0.02936840057373047" rpy="1.5985809564590454 -1.180384874343872 -3.124069929122925"/>
      <mass value="0.7467989921569824"/>
      <inertia ixx="0.0005081744748167694" ixy="0.0" ixz="0.0" iyy="0.0006026190239936113" iyz="0.0" izz="0.0006709994631819427"/>
    </inertial>
    <visual name="SM_l_upper_arm_visual_0">
      <origin xyz="-0.014999999664723873 0.0 -0.19329999387264252" rpy="0.0 -1.3089970350265503 -3.1415927410125732"/>
      <geometry>
        <mesh filename="file://iCub/meshes/stl/sim_sea_2-5_l_elbow_prt-binary.stl" scale="0.0010000000474974513 0.0010000000474974513 0.0010000000474974513"/>
      </geometry>
    </visual>
    <collision name="SM_l_upper_arm_collision_0">
      <origin xyz="-0.014999999664723873 0.0 -0.19329999387264252" rpy="0.0 -1.3089970350265503 -3.1415927410125732"/>
      <geometry>
        <mesh filename="file://iCub/meshes/stl/sim_sea_2-5_l_elbow_prt-binary.stl" scale="0.0010000000474974513 0.0010000000474974513 0.0010000000474974513"/>
      </geometry>
    </collision>
  </link>
  <joint name="l_elbow" type="revolute">
    <origin xyz="0.0 0.03399990126490593 0.07925999909639359" rpy="0.0 -1.3089970350265503 -3.1415927410125732"/>
    <axis xyz="2.220446049250313e-16 -1.0 0.0"/>
    <parent link="l_upper_arm"/>
    <child link="l_elbow_1"/>
    <limit effort="50000.0" lower="0.2617993950843811" upper="1.8500490188598633" velocity="50000.0"/>
  </joint>
  <link name="l_elbow_1">
    <inertial>
      <origin xyz="0.006739129312336445 0.030301900580525398 -0.004657692275941372" rpy="-0.7352255582809448 -0.6271970272064209 -2.5072667598724365"/>
      <mass value="0.26790300011634827"/>
      <inertia ixx="0.009985172189772129" ixy="0.0" ixz="0.0" iyy="0.010003657080233097" iyz="0.0" izz="0.010011170990765095"/>
    </inertial>
    <visual name="SM_l_elbow_1_visual_0">
      <origin xyz="-0.2593904733657837 0.03399990126490593 -0.08503258973360062" rpy="0.0 0.0 0.0"/>
      <geometry>
        <mesh filename="file://iCub/meshes/stl/sim_sea_2-5_l_elbow_prosup_prt-binary.stl" scale="0.0010000000474974513 0.0010000000474974513 0.0010000000474974513"/>
      </geometry>
    </visual>
    <collision name="SM_l_elbow_1_collision_0">
      <origin xyz="-0.2593904733657837 0.03399990126490593 -0.08503258973360062" rpy="0.0 0.0 0.0"/>
      <geometry>
        <mesh filename="file://iCub/meshes/stl/sim_sea_2-5_l_elbow_prosup_prt-binary.stl" scale="0.0010000000474974513 0.0010000000474974513 0.0010000000474974513"/>
      </geometry>
    </collision>
  </link>
  <joint name="l_wrist_prosup" type="revolute">
    <origin xyz="0.038462430238723755 0.03399990126490593 -0.005223168060183525" rpy="0.0 0.0 0.0"/>
    <axis xyz="0.9659258723258972 2.220446049250313e-16 0.25881898403167725"/>
    <parent link="l_elbow_1"/>
    <child link="l_forearm"/>
    <limit effort="50000.0" lower="-1.0471975803375244" upper="1.0471975803375244" velocity="50000.0"/>
  </joint>
  <link name="l_forearm">
    <inertial>
      <origin xyz="0.040451183915138245 -0.0006859999848529696 0.005323632154613733" rpy="-1.5361489057540894 -0.4255067706108093 -0.017619412392377853"/>
      <mass value="0.6361849904060364"/>
      <inertia ixx="0.0003233828756492585" ixy="0.0" ixz="0.0" iyy="0.000605036795604974" iyz="0.0" izz="0.000674371316563338"/>
    </inertial>
    <visual name="SM_l_forearm_visual_0">
      <origin xyz="-0.29688698053359985 0.0 -0.079550601541996" rpy="0.0 0.0 0.0"/>
      <geometry>
        <mesh filename="file://iCub/meshes/stl/sim_sea_2-5_l_forearm_prt-binary.stl" scale="0.0010000000474974513 0.0010000000474974513 0.0010000000474974513"/>
      </geometry>
    </visual>
    <collision name="SM_l_forearm_collision_0">
      <origin xyz="-0.29688698053359985 0.0 -0.079550601541996" rpy="0.0 0.0 0.0"/>
      <geometry>
        <mesh filename="file://iCub/meshes/stl/sim_sea_2-5_l_forearm_prt-binary.stl" scale="0.0010000000474974513 0.0010000000474974513 0.0010000000474974513"/>
      </geometry>
    </collision>
  </link>
  <joint name="l_forearm_skin_0_joint" type="fixed">
    <origin xyz="0.045449328661829665 -0.032316899999999996 -0.006286560379014218" rpy="1.6918152570724487 -0.27102673053741455 0.07278826832771301"/>
    <parent link="l_forearm"/>
    <child link="l_forearm_skin_0"/>
  </joint>
  <link name="l_forearm_skin_0">
    <inertial>
      <origin xyz="0.0 0.0 0.0" rpy="0.0 0.0 0.0"/>
      <mass value="0.0"/>
      <inertia ixx="0.0" ixy="0.0" ixz="0.0" iyy="0.0" iyz="0.0" izz="0.0"/>
    </inertial>
  </link>
  <joint name="l_forearm_skin_1_joint" type="fixed">
    <origin xyz="0.03337289358257036 -0.031066200000000016 -0.019845686771095515" rpy="1.8669402599334717 -0.27444252371788025 0.04212287440896034"/>
    <parent link="l_forearm"/>
    <child link="l_forearm_skin_1"/>
  </joint>
  <link name="l_forearm_skin_1">
    <inertial>
      <origin xyz="0.0 0.0 0.0" rpy="0.0 0.0 0.0"/>
      <mass value="0.0"/>
      <inertia ixx="0.0" ixy="0.0" ixz="0.0" iyy="0.0" iyz="0.0" izz="0.0"/>
    </inertial>
  </link>
  <joint name="l_forearm_skin_2_joint" type="fixed">
    <origin xyz="0.01469889298522637 -0.033518400000000004 -0.016011733837060345" rpy="1.7284728288650513 -0.26401522755622864 0.014260047115385532"/>
    <parent link="l_forearm"/>
    <child link="l_forearm_skin_2"/>
  </joint>
  <link name="l_forearm_skin_2">
    <inertial>
      <origin xyz="0.0 0.0 0.0" rpy="0.0 0.0 0.0"/>
      <mass value="0.0"/>
      <inertia ixx="0.0" ixy="0.0" ixz="0.0" iyy="0.0" iyz="0.0" izz="0.0"/>
    </inertial>
  </link>
  <joint name="l_forearm_skin_3_joint" type="fixed">
    <origin xyz="0.04556729362200616 0.02865100000000001 -0.006330009293506465" rpy="-1.6948728561401367 -0.2697577178478241 -0.06199521943926811"/>
    <parent link="l_forearm"/>
    <child link="l_forearm_skin_3"/>
  </joint>
  <link name="l_forearm_skin_3">
    <inertial>
      <origin xyz="0.0 0.0 0.0" rpy="0.0 0.0 0.0"/>
      <mass value="0.0"/>
      <inertia ixx="0.0" ixy="0.0" ixz="0.0" iyy="0.0" iyz="0.0" izz="0.0"/>
    </inertial>
  </link>
  <joint name="l_forearm_skin_4_joint" type="fixed">
    <origin xyz="0.0635326332996175 0.02587700000000001 -0.008997842580659854" rpy="-1.8174786567687988 -0.28740689158439636 -0.09983161836862564"/>
    <parent link="l_forearm"/>
    <child link="l_forearm_skin_4"/>
  </joint>
  <link name="l_forearm_skin_4">
    <inertial>
      <origin xyz="0.0 0.0 0.0" rpy="0.0 0.0 0.0"/>
      <mass value="0.0"/>
      <inertia ixx="0.0" ixy="0.0" ixz="0.0" iyy="0.0" iyz="0.0" izz="0.0"/>
    </inertial>
  </link>
  <joint name="l_forearm_skin_5_joint" type="fixed">
    <origin xyz="0.06882119419679653 0.015709 -0.023113336179072505" rpy="-2.5410475730895996 -0.38562726974487305 -0.08672275394201279"/>
    <parent link="l_forearm"/>
    <child link="l_forearm_skin_5"/>
  </joint>
  <link name="l_forearm_skin_5">
    <inertial>
      <origin xyz="0.0 0.0 0.0" rpy="0.0 0.0 0.0"/>
      <mass value="0.0"/>
      <inertia ixx="0.0" ixy="0.0" ixz="0.0" iyy="0.0" iyz="0.0" izz="0.0"/>
    </inertial>
  </link>
  <joint name="l_forearm_skin_6_joint" type="fixed">
    <origin xyz="0.0333948436254737 0.027308000000000027 -0.019832558343293956" rpy="-1.8662816286087036 -0.27288633584976196 -0.03710680454969406"/>
    <parent link="l_forearm"/>
    <child link="l_forearm_skin_6"/>
  </joint>
  <link name="l_forearm_skin_6">
    <inertial>
      <origin xyz="0.0 0.0 0.0" rpy="0.0 0.0 0.0"/>
      <mass value="0.0"/>
      <inertia ixx="0.0" ixy="0.0" ixz="0.0" iyy="0.0" iyz="0.0" izz="0.0"/>
    </inertial>
  </link>
  <joint name="l_forearm_skin_7_joint" type="fixed">
    <origin xyz="0.014722426007426952 0.02970199999999998 -0.015932648270323382" rpy="-1.7256463766098022 -0.26399290561676025 -0.01438011135905981"/>
    <parent link="l_forearm"/>
    <child link="l_forearm_skin_7"/>
  </joint>
  <link name="l_forearm_skin_7">
    <inertial>
      <origin xyz="0.0 0.0 0.0" rpy="0.0 0.0 0.0"/>
      <mass value="0.0"/>
      <inertia ixx="0.0" ixy="0.0" ixz="0.0" iyy="0.0" iyz="0.0" izz="0.0"/>
    </inertial>
  </link>
  <joint name="l_forearm_skin_8_joint" type="fixed">
    <origin xyz="0.0228528628554271 0.007545999999999997 -0.041885146374950645" rpy="-2.9480197429656982 -0.27060508728027344 -0.0017870807787403464"/>
    <parent link="l_forearm"/>
    <child link="l_forearm_skin_8"/>
  </joint>
  <link name="l_forearm_skin_8">
    <inertial>
      <origin xyz="0.0 0.0 0.0" rpy="0.0 0.0 0.0"/>
      <mass value="0.0"/>
      <inertia ixx="0.0" ixy="0.0" ixz="0.0" iyy="0.0" iyz="0.0" izz="0.0"/>
    </inertial>
  </link>
  <joint name="l_forearm_skin_9_joint" type="fixed">
    <origin xyz="0.03760327346828466 0.016715000000000008 -0.03401633711864639" rpy="-2.5840651988983154 -0.29332172870635986 -0.02030858024954796"/>
    <parent link="l_forearm"/>
    <child link="l_forearm_skin_9"/>
  </joint>
  <link name="l_forearm_skin_9">
    <inertial>
      <origin xyz="0.0 0.0 0.0" rpy="0.0 0.0 0.0"/>
      <mass value="0.0"/>
      <inertia ixx="0.0" ixy="0.0" ixz="0.0" iyy="0.0" iyz="0.0" izz="0.0"/>
    </inertial>
  </link>
  <joint name="l_forearm_skin_10_joint" type="fixed">
    <origin xyz="0.05422852108875307 0.007546000000000011 -0.03214690828659369" rpy="-2.9412331581115723 -0.3283044695854187 -0.013966278173029423"/>
    <parent link="l_forearm"/>
    <child link="l_forearm_skin_10"/>
  </joint>
  <link name="l_forearm_skin_10">
    <inertial>
      <origin xyz="0.0 0.0 0.0" rpy="0.0 0.0 0.0"/>
      <mass value="0.0"/>
      <inertia ixx="0.0" ixy="0.0" ixz="0.0" iyy="0.0" iyz="0.0" izz="0.0"/>
    </inertial>
  </link>
  <joint name="l_forearm_skin_11_joint" type="fixed">
    <origin xyz="0.05422409120236691 -0.011283199999999993 -0.03214312594517525" rpy="2.939298391342163 -0.3291013836860657 0.014273488894104958"/>
    <parent link="l_forearm"/>
    <child link="l_forearm_skin_11"/>
  </joint>
  <link name="l_forearm_skin_11">
    <inertial>
      <origin xyz="0.0 0.0 0.0" rpy="0.0 0.0 0.0"/>
      <mass value="0.0"/>
      <inertia ixx="0.0" ixy="0.0" ixz="0.0" iyy="0.0" iyz="0.0" izz="0.0"/>
    </inertial>
  </link>
  <joint name="l_forearm_skin_12_joint" type="fixed">
    <origin xyz="0.037599463386836625 -0.020455600000000018 -0.034019117996090566" rpy="2.5830349922180176 -0.2948305010795593 0.021326851099729538"/>
    <parent link="l_forearm"/>
    <child link="l_forearm_skin_12"/>
  </joint>
  <link name="l_forearm_skin_12">
    <inertial>
      <origin xyz="0.0 0.0 0.0" rpy="0.0 0.0 0.0"/>
      <mass value="0.0"/>
      <inertia ixx="0.0" ixy="0.0" ixz="0.0" iyy="0.0" iyz="0.0" izz="0.0"/>
    </inertial>
  </link>
  <joint name="l_forearm_skin_13_joint" type="fixed">
    <origin xyz="0.022855086840518728 -0.0112878 -0.04189190092085042" rpy="2.9489667415618896 -0.27058395743370056 0.0017738500609993935"/>
    <parent link="l_forearm"/>
    <child link="l_forearm_skin_13"/>
  </joint>
  <link name="l_forearm_skin_13">
    <inertial>
      <origin xyz="0.0 0.0 0.0" rpy="0.0 0.0 0.0"/>
      <mass value="0.0"/>
      <inertia ixx="0.0" ixy="0.0" ixz="0.0" iyy="0.0" iyz="0.0" izz="0.0"/>
    </inertial>
  </link>
  <joint name="l_forearm_skin_14_joint" type="fixed">
    <origin xyz="0.06877032763640067 -0.019399899999999998 -0.02302395585107192" rpy="2.5246224403381348 -0.38779452443122864 0.09129241108894348"/>
    <parent link="l_forearm"/>
    <child link="l_forearm_skin_14"/>
  </joint>
  <link name="l_forearm_skin_14">
    <inertial>
      <origin xyz="0.0 0.0 0.0" rpy="0.0 0.0 0.0"/>
      <mass value="0.0"/>
      <inertia ixx="0.0" ixy="0.0" ixz="0.0" iyy="0.0" iyz="0.0" izz="0.0"/>
    </inertial>
  </link>
  <joint name="l_forearm_skin_15_joint" type="fixed">
    <origin xyz="0.06337864196616988 -0.029384300000000002 -0.008794054555439966" rpy="1.8049277067184448 -0.2897832691669464 0.1139337420463562"/>
    <parent link="l_forearm"/>
    <child link="l_forearm_skin_15"/>
  </joint>
  <link name="l_forearm_skin_15">
    <inertial>
      <origin xyz="0.0 0.0 0.0" rpy="0.0 0.0 0.0"/>
      <mass value="0.0"/>
      <inertia ixx="0.0" ixy="0.0" ixz="0.0" iyy="0.0" iyz="0.0" izz="0.0"/>
    </inertial>
  </link>
  <joint name="l_forearm_skin_16_joint" type="fixed">
    <origin xyz="0.03792482186997504 -0.0327268 0.020636950360473926" rpy="1.4128000736236572 -0.25082463026046753 0.0758652314543724"/>
    <parent link="l_forearm"/>
    <child link="l_forearm_skin_16"/>
  </joint>
  <link name="l_forearm_skin_16">
    <inertial>
      <origin xyz="0.0 0.0 0.0" rpy="0.0 0.0 0.0"/>
      <mass value="0.0"/>
      <inertia ixx="0.0" ixy="0.0" ixz="0.0" iyy="0.0" iyz="0.0" izz="0.0"/>
    </inertial>
  </link>
  <joint name="l_forearm_skin_17_joint" type="fixed">
    <origin xyz="0.05431705488213746 -0.029964599999999994 0.030329124017862287" rpy="1.2722371816635132 -0.23059304058551788 0.10963722318410873"/>
    <parent link="l_forearm"/>
    <child link="l_forearm_skin_17"/>
  </joint>
  <link name="l_forearm_skin_17">
    <inertial>
      <origin xyz="0.0 0.0 0.0" rpy="0.0 0.0 0.0"/>
      <mass value="0.0"/>
      <inertia ixx="0.0" ixy="0.0" ixz="0.0" iyy="0.0" iyz="0.0" izz="0.0"/>
    </inertial>
  </link>
  <joint name="l_forearm_skin_19_joint" type="fixed">
    <origin xyz="0.03812661071376925 0.029053999999999996 0.02069060539304483" rpy="-1.4156088829040527 -0.2525692880153656 -0.06444047391414642"/>
    <parent link="l_forearm"/>
    <child link="l_forearm_skin_19"/>
  </joint>
  <link name="l_forearm_skin_19">
    <inertial>
      <origin xyz="0.0 0.0 0.0" rpy="0.0 0.0 0.0"/>
      <mass value="0.0"/>
      <inertia ixx="0.0" ixy="0.0" ixz="0.0" iyy="0.0" iyz="0.0" izz="0.0"/>
    </inertial>
  </link>
  <joint name="l_forearm_skin_22_joint" type="fixed">
    <origin xyz="0.05441739504212797 0.026483000000000007 0.030603751660850165" rpy="-1.265824317932129 -0.23432815074920654 -0.09370947629213333"/>
    <parent link="l_forearm"/>
    <child link="l_forearm_skin_22"/>
  </joint>
  <link name="l_forearm_skin_22">
    <inertial>
      <origin xyz="0.0 0.0 0.0" rpy="0.0 0.0 0.0"/>
      <mass value="0.0"/>
      <inertia ixx="0.0" ixy="0.0" ixz="0.0" iyy="0.0" iyz="0.0" izz="0.0"/>
    </inertial>
  </link>
  <joint name="l_forearm_skin_24_joint" type="fixed">
    <origin xyz="0.07003453195640522 0.007477000000000011 0.05006910871401307" rpy="-0.23489327728748322 -0.03881729766726494 -0.054829198867082596"/>
    <parent link="l_forearm"/>
    <child link="l_forearm_skin_24"/>
  </joint>
  <link name="l_forearm_skin_24">
    <inertial>
      <origin xyz="0.0 0.0 0.0" rpy="0.0 0.0 0.0"/>
      <mass value="0.0"/>
      <inertia ixx="0.0" ixy="0.0" ixz="0.0" iyy="0.0" iyz="0.0" izz="0.0"/>
    </inertial>
  </link>
  <joint name="l_forearm_skin_25_joint" type="fixed">
    <origin xyz="0.05359992162949282 0.015984000000000026 0.04546981250452139" rpy="-0.5642955303192139 -0.13698026537895203 -0.08196082711219788"/>
    <parent link="l_forearm"/>
    <child link="l_forearm_skin_25"/>
  </joint>
  <link name="l_forearm_skin_25">
    <inertial>
      <origin xyz="0.0 0.0 0.0" rpy="0.0 0.0 0.0"/>
      <mass value="0.0"/>
      <inertia ixx="0.0" ixy="0.0" ixz="0.0" iyy="0.0" iyz="0.0" izz="0.0"/>
    </inertial>
  </link>
  <joint name="l_forearm_skin_28_joint" type="fixed">
    <origin xyz="0.05358592721475831 -0.01965220000000001 0.04535203739698063" rpy="0.5793111324310303 -0.13399431109428406 0.0867597833275795"/>
    <parent link="l_forearm"/>
    <child link="l_forearm_skin_28"/>
  </joint>
  <link name="l_forearm_skin_28">
    <inertial>
      <origin xyz="0.0 0.0 0.0" rpy="0.0 0.0 0.0"/>
      <mass value="0.0"/>
      <inertia ixx="0.0" ixy="0.0" ixz="0.0" iyy="0.0" iyz="0.0" izz="0.0"/>
    </inertial>
  </link>
  <joint name="l_forearm_skin_29_joint" type="fixed">
    <origin xyz="0.07003558050313372 -0.011193599999999984 0.05001110362329029" rpy="0.24863098561763763 -0.03831365704536438 0.05830266326665878"/>
    <parent link="l_forearm"/>
    <child link="l_forearm_skin_29"/>
  </joint>
  <link name="l_forearm_skin_29">
    <inertial>
      <origin xyz="0.0 0.0 0.0" rpy="0.0 0.0 0.0"/>
      <mass value="0.0"/>
      <inertia ixx="0.0" ixy="0.0" ixz="0.0" iyy="0.0" iyz="0.0" izz="0.0"/>
    </inertial>
  </link>
  <joint name="l_forearm_dh_frame_joint" type="fixed">
    <origin xyz="0.1028711023733811 7.000000000020878e-06 0.027564221311064674" rpy="2.879793405532837 0.0 1.5707963705062866"/>
    <parent link="l_forearm"/>
    <child link="l_forearm_dh_frame"/>
  </joint>
  <link name="l_forearm_dh_frame">
    <inertial>
      <origin xyz="0.0 0.0 0.0" rpy="0.0 0.0 0.0"/>
      <mass value="0.0"/>
      <inertia ixx="0.0" ixy="0.0" ixz="0.0" iyy="0.0" iyz="0.0" izz="0.0"/>
    </inertial>
  </link>
  <joint name="l_wrist_pitch" type="revolute">
    <origin xyz="0.10342756658792496 7.000000096013537e-06 0.02548748068511486" rpy="0.0 0.0 0.0"/>
    <axis xyz="0.25881898403167725 0.0 -0.9659258723258972"/>
    <parent link="l_forearm"/>
    <child link="l_wrist_1"/>
    <limit effort="50000.0" lower="-1.3962633609771729" upper="0.4363323152065277" velocity="50000.0"/>
  </joint>
  <link name="l_wrist_1">
    <inertial>
      <origin xyz="-0.0009813137585297227 -0.0011780000058934093 0.0040834578685462475" rpy="0.042986080050468445 -0.7822980284690857 2.944495677947998"/>
      <mass value="0.036215201020240784"/>
      <inertia ixx="0.009999038651585579" ixy="0.0" ixz="0.0" iyy="0.010000010021030903" iyz="0.0" izz="0.010000950656831264"/>
    </inertial>
    <visual name="SM_l_wrist_1_visual_0">
      <origin xyz="-0.4003145396709442 -7.000000096013537e-06 -0.10503808408975601" rpy="0.0 0.0 0.0"/>
      <geometry>
        <mesh filename="file://iCub/meshes/stl/sim_sea_2-5_l_wrist_pitch_prt-binary.stl" scale="0.0010000000474974513 0.0010000000474974513 0.0010000000474974513"/>
      </geometry>
    </visual>
    <collision name="SM_l_wrist_1_collision_0">
      <origin xyz="-0.4003145396709442 -7.000000096013537e-06 -0.10503808408975601" rpy="0.0 0.0 0.0"/>
      <geometry>
        <mesh filename="file://iCub/meshes/stl/sim_sea_2-5_l_wrist_pitch_prt-binary.stl" scale="0.0010000000474974513 0.0010000000474974513 0.0010000000474974513"/>
      </geometry>
    </collision>
  </link>
  <joint name="l_wrist_yaw" type="revolute">
    <origin xyz="-0.0006341065163724124 -0.019499899819493294 0.0023665183689445257" rpy="0.0 0.0 0.0"/>
    <axis xyz="-2.220446049250313e-16 1.0 0.0"/>
    <parent link="l_wrist_1"/>
    <child link="l_hand"/>
    <limit effort="50000.0" lower="-0.3490658402442932" upper="0.4363323152065277" velocity="50000.0"/>
  </joint>
  <link name="l_hand">
    <inertial>
      <origin xyz="0.06476802378892899 0.0056304000318050385 0.02266022004187107" rpy="-3.090332269668579 -0.7698649168014526 -0.5445988178253174"/>
      <mass value="0.24780599772930145"/>
      <inertia ixx="0.00995639432221651" ixy="0.0" ixz="0.0" iyy="0.010002526454627514" iyz="0.0" izz="0.01004108041524887"/>
    </inertial>
    <visual name="SM_l_hand_visual_0">
      <origin xyz="-0.3996804356575012 0.019492899999022484 -0.10740459710359573" rpy="0.0 0.0 0.0"/>
      <geometry>
        <mesh filename="file://iCub/meshes/stl/sim_sea_2-5_l_hand_prt-binary.stl" scale="0.0010000000474974513 0.0010000000474974513 0.0010000000474974513"/>
      </geometry>
    </visual>
    <collision name="SM_l_hand_collision_0">
      <origin xyz="-0.3996804356575012 0.019492899999022484 -0.10740459710359573" rpy="0.0 0.0 0.0"/>
      <geometry>
        <mesh filename="file://iCub/meshes/stl/sim_sea_2-5_l_hand_prt-binary.stl" scale="0.0010000000474974513 0.0010000000474974513 0.0010000000474974513"/>
      </geometry>
    </collision>
  </link>
  <joint name="l_hand_dh_frame_joint" type="fixed">
    <origin xyz="0.05765429784284365 -0.005556799999999987 0.013693832308330513" rpy="-1.5707963705062866 -0.26179930567741394 -2.873468614565078e-17"/>
    <parent link="l_hand"/>
    <child link="l_hand_dh_frame"/>
  </joint>
  <link name="l_hand_dh_frame">
    <inertial>
      <origin xyz="0.0 0.0 0.0" rpy="0.0 0.0 0.0"/>
      <mass value="0.0"/>
      <inertia ixx="0.0" ixy="0.0" ixz="0.0" iyy="0.0" iyz="0.0" izz="0.0"/>
    </inertial>
  </link>
  <joint name="r_hip_pitch" type="revolute">
    <origin xyz="0.006451500114053488 0.026000000536441803 -0.1199129968881607" rpy="0.0 0.0 -3.1415927410125732"/>
    <axis xyz="-2.220446049250313e-16 -1.0 0.0"/>
    <parent link="root_link"/>
    <child link="r_hip_1"/>
    <limit effort="55.5" lower="-0.7853981852531433" upper="2.3387413024902344" velocity="5.099999904632568"/>
  </joint>
  <link name="r_hip_1">
    <inertial>
      <origin xyz="-0.0005145000177435577 -0.03807530179619789 -7.100000220816582e-05" rpy="-2.417318344116211 1.5610781908035278 2.438248634338379"/>
      <mass value="0.9199780225753784"/>
      <inertia ixx="0.000404251622967422" ixy="0.0" ixz="0.0" iyy="0.000574638310354203" iyz="0.0" izz="0.000580144056584686"/>
    </inertial>
    <visual name="SM_r_hip_1_visual_0">
      <origin xyz="0.04285150021314621 0.026000000536441803 0.15191300213336945" rpy="1.5707963705062866 0.0 1.5707963705062866"/>
      <geometry>
        <mesh filename="file://iCub/meshes/stl/sim_sea_2-5_r_hip_1_prt-binary.stl" scale="0.0010000000474974513 0.0010000000474974513 0.0010000000474974513"/>
      </geometry>
    </visual>
    <collision name="SM_r_hip_1_collision_0">
      <origin xyz="0.04285150021314621 0.026000000536441803 0.15191300213336945" rpy="1.5707963705062866 0.0 1.5707963705062866"/>
      <geometry>
        <mesh filename="file://iCub/meshes/stl/sim_sea_2-5_r_hip_1_prt-binary.stl" scale="0.0010000000474974513 0.0010000000474974513 0.0010000000474974513"/>
      </geometry>
    </collision>
  </link>
  <joint name="r_hip_roll" type="revolute">
    <origin xyz="0.0 -0.04410000145435333 0.0" rpy="0.0 0.0 0.0"/>
    <axis xyz="-1.0 0.0 -2.220446049250313e-16"/>
    <parent link="r_hip_1"/>
    <child link="r_hip_2"/>
    <limit effort="37.0" lower="-0.3490658402442932" upper="2.094395160675049" velocity="7.639999866485596"/>
  </joint>
  <link name="r_hip_2">
    <inertial>
      <origin xyz="-0.0013753999955952168 3.5000000480067683e-06 -0.04428200051188469" rpy="-0.00048286753008142114 -0.0015391104388982058 -0.35069724917411804"/>
      <mass value="0.41836100816726685"/>
      <inertia ixx="0.00028160656802356243" ixy="0.0" ixz="0.0" iyy="0.0003196659090463072" iyz="0.0" izz="0.00048786652041599154"/>
    </inertial>
    <visual name="SM_r_hip_2_visual_0">
      <origin xyz="0.04285150021314621 0.07010000199079514 0.15191300213336945" rpy="1.5707963705062866 0.0 1.5707963705062866"/>
      <geometry>
        <mesh filename="file://iCub/meshes/stl/sim_sea_2-5_r_hip_2_prt-binary.stl" scale="0.0010000000474974513 0.0010000000474974513 0.0010000000474974513"/>
      </geometry>
    </visual>
    <collision name="SM_r_hip_2_collision_0">
      <origin xyz="0.04285150021314621 0.07010000199079514 0.15191300213336945" rpy="1.5707963705062866 0.0 1.5707963705062866"/>
      <geometry>
        <mesh filename="file://iCub/meshes/stl/sim_sea_2-5_r_hip_2_prt-binary.stl" scale="0.0010000000474974513 0.0010000000474974513 0.0010000000474974513"/>
      </geometry>
    </collision>
  </link>
  <joint name="r_hip_3_joint" type="fixed">
    <origin xyz="-0.0008575000000000041 0.0 -0.07429999999999995" rpy="3.1415927410125732 0.0 0.0"/>
    <parent link="r_hip_2"/>
    <child link="r_hip_3"/>
  </joint>
  <link name="r_hip_3">
    <inertial>
      <origin xyz="-0.0001230000052601099 -0.00028229999588802457 0.008717999793589115" rpy="2.9681975841522217 0.7768762707710266 3.0034334659576416"/>
      <mass value="0.1262120008468628"/>
      <inertia ixx="0.009999729692935944" ixy="0.0" ixz="0.0" iyy="0.010000000707805157" iyz="0.0" izz="0.01000026986002922"/>
    </inertial>
    <visual name="SM_r_hip_3_visual_0">
      <origin xyz="0.04370899870991707 -0.07010000199079514 -0.2262129932641983" rpy="-1.5707963705062866 0.0 -1.5707963705062866"/>
      <geometry>
        <mesh filename="file://iCub/meshes/stl/sim_sea_2-5_r_upper_thigh_prt-binary.stl" scale="0.0010000000474974513 0.0010000000474974513 0.0010000000474974513"/>
      </geometry>
    </visual>
    <collision name="SM_r_hip_3_collision_0">
      <origin xyz="0.04370899870991707 -0.07010000199079514 -0.2262129932641983" rpy="-1.5707963705062866 0.0 -1.5707963705062866"/>
      <geometry>
        <mesh filename="file://iCub/meshes/stl/sim_sea_2-5_r_upper_thigh_prt-binary.stl" scale="0.0010000000474974513 0.0010000000474974513 0.0010000000474974513"/>
      </geometry>
    </collision>
  </link>
  <joint name="r_leg_ft_joint" type="fixed">
    <origin xyz="0.0 0.0 0.0" rpy="0.0 0.0 0.0"/>
    <parent link="r_hip_3"/>
    <child link="r_leg_ft"/>
  </joint>
  <link name="r_leg_ft">
    <inertial>
      <origin xyz="0.0 0.0 0.0" rpy="0.0 0.0 0.0"/>
      <mass value="0.0"/>
      <inertia ixx="0.0" ixy="0.0" ixz="0.0" iyy="0.0" iyz="0.0" izz="0.0"/>
    </inertial>
  </link>
  <joint name="r_hip_yaw" type="revolute">
    <origin xyz="0.0 0.0 0.014399999752640724" rpy="-3.1415927410125732 0.0 0.0"/>
    <axis xyz="0.0 -2.220446049250313e-16 -1.0"/>
    <parent link="r_hip_3"/>
    <child link="r_upper_leg"/>
    <limit effort="37.0" lower="-1.3962633609771729" upper="1.3962633609771729" velocity="7.639999866485596"/>
  </joint>
  <link name="r_upper_leg">
    <inertial>
      <origin xyz="0.0033998999278992414 -2.9099999665049836e-05 -0.07895399630069733" rpy="-0.18700486421585083 0.025800323113799095 0.02726290002465248"/>
      <mass value="1.8035000562667847"/>
      <inertia ixx="0.0014523080317303538" ixy="0.0" ixz="0.0" iyy="0.006470563821494579" iyz="0.0" izz="0.006481229327619076"/>
    </inertial>
    <visual name="SM_r_upper_leg_visual_0">
      <origin xyz="0.04370899870991707 0.07010000199079514 0.2408130019903183" rpy="1.5707963705062866 0.0 1.5707963705062866"/>
      <geometry>
        <mesh filename="file://iCub/meshes/stl/sim_sea_2-5_r_thigh_prt-binary.stl" scale="0.0010000000474974513 0.0010000000474974513 0.0010000000474974513"/>
      </geometry>
    </visual>
    <collision name="SM_r_upper_leg_collision_0">
      <origin xyz="0.04370899870991707 0.07010000199079514 0.2408130019903183" rpy="1.5707963705062866 0.0 1.5707963705062866"/>
      <geometry>
        <mesh filename="file://iCub/meshes/stl/sim_sea_2-5_r_thigh_prt-binary.stl" scale="0.0010000000474974513 0.0010000000474974513 0.0010000000474974513"/>
      </geometry>
    </collision>
  </link>
  <joint name="r_upper_leg_ems_gyro_eb8_joint" type="fixed">
    <origin xyz="-0.01307899999999998 0.04040719999999998 -0.035654999999999964" rpy="1.5707963705062866 1.5707963705062866 0.0"/>
    <parent link="r_upper_leg"/>
    <child link="r_upper_leg_ems_gyro_eb8"/>
  </joint>
  <link name="r_upper_leg_ems_gyro_eb8">
    <inertial>
      <origin xyz="0.0 0.0 0.0" rpy="0.0 0.0 0.0"/>
      <mass value="0.0"/>
      <inertia ixx="0.0" ixy="0.0" ixz="0.0" iyy="0.0" iyz="0.0" izz="0.0"/>
    </inertial>
  </link>
  <joint name="r_upper_leg_ems_gyro_eb11_joint" type="fixed">
    <origin xyz="-0.013081000000000002 -0.04040700000000001 -0.087979" rpy="1.5707963705062866 1.5707963705062866 0.0"/>
    <parent link="r_upper_leg"/>
    <child link="r_upper_leg_ems_gyro_eb11"/>
  </joint>
  <link name="r_upper_leg_ems_gyro_eb11">
    <inertial>
      <origin xyz="0.0 0.0 0.0" rpy="0.0 0.0 0.0"/>
      <mass value="0.0"/>
      <inertia ixx="0.0" ixy="0.0" ixz="0.0" iyy="0.0" iyz="0.0" izz="0.0"/>
    </inertial>
  </link>
  <joint name="r_upper_leg_back_contact_joint" type="fixed">
    <origin xyz="-0.05119989999999999 0.0 0.014599999999999946" rpy="-0.0 1.5707963705062866 0.0"/>
    <parent link="r_upper_leg"/>
    <child link="r_upper_leg_back_contact"/>
  </joint>
  <link name="r_upper_leg_back_contact">
    <inertial>
      <origin xyz="0.0 0.0 0.0" rpy="0.0 0.0 0.0"/>
      <mass value="0.0"/>
      <inertia ixx="0.0" ixy="0.0" ixz="0.0" iyy="0.0" iyz="0.0" izz="0.0"/>
    </inertial>
  </link>
  <joint name="r_upper_leg_dh_frame_joint" type="fixed">
    <origin xyz="0.0 0.0 -0.14582499999999995" rpy="1.5707963705062866 0.0 0.0"/>
    <parent link="r_upper_leg"/>
    <child link="r_upper_leg_dh_frame"/>
  </joint>
  <link name="r_upper_leg_dh_frame">
    <inertial>
      <origin xyz="0.0 0.0 0.0" rpy="0.0 0.0 0.0"/>
      <mass value="0.0"/>
      <inertia ixx="0.0" ixy="0.0" ixz="0.0" iyy="0.0" iyz="0.0" izz="0.0"/>
    </inertial>
  </link>
  <joint name="r_knee" type="revolute">
    <origin xyz="0.0 0.0 -0.14582499861717224" rpy="0.0 0.0 0.0"/>
    <axis xyz="-2.220446049250313e-16 -1.0 0.0"/>
    <parent link="r_upper_leg"/>
    <child link="r_lower_leg"/>
    <limit effort="37.0" lower="-2.164208173751831" upper="0.06981316953897476" velocity="7.639999866485596"/>
  </joint>
  <link name="r_lower_leg">
    <inertial>
      <origin xyz="0.0012362999841570854 -0.00351310009136796 -0.08879400044679642" rpy="-1.7788795232772827 0.08076141774654388 0.08373112976551056"/>
      <mass value="1.472000002861023"/>
      <inertia ixx="0.0014801976503804326" ixy="0.0" ixz="0.0" iyy="0.004242227412760258" iyz="0.0" izz="0.00461204256862402"/>
    </inertial>
    <visual name="SM_r_lower_leg_visual_0">
      <origin xyz="0.04370899870991707 0.07010000199079514 0.38663798570632935" rpy="1.5707963705062866 0.0 1.5707963705062866"/>
      <geometry>
        <mesh filename="file://iCub/meshes/stl/sim_sea_2-5_r_shank_prt-binary.stl" scale="0.0010000000474974513 0.0010000000474974513 0.0010000000474974513"/>
      </geometry>
    </visual>
    <collision name="SM_r_lower_leg_collision_0">
      <origin xyz="0.04370899870991707 0.07010000199079514 0.38663798570632935" rpy="1.5707963705062866 0.0 1.5707963705062866"/>
      <geometry>
        <mesh filename="file://iCub/meshes/stl/sim_sea_2-5_r_shank_prt-binary.stl" scale="0.0010000000474974513 0.0010000000474974513 0.0010000000474974513"/>
      </geometry>
    </collision>
  </link>
  <joint name="r_lower_leg_ems_gyro_eb9_joint" type="fixed">
    <origin xyz="0.044503292 0.014343499999999974 -0.08830099999999996" rpy="-3.1415927410125732 -1.3526297807693481 4.293419691916712e-16"/>
    <parent link="r_lower_leg"/>
    <child link="r_lower_leg_ems_gyro_eb9"/>
  </joint>
  <link name="r_lower_leg_ems_gyro_eb9">
    <inertial>
      <origin xyz="0.0 0.0 0.0" rpy="0.0 0.0 0.0"/>
      <mass value="0.0"/>
      <inertia ixx="0.0" ixy="0.0" ixz="0.0" iyy="0.0" iyz="0.0" izz="0.0"/>
    </inertial>
  </link>
  <joint name="r_lower_leg_skin_0_joint" type="fixed">
    <origin xyz="0.054411699999999986 -0.031213999999999992 -0.002634000000000025" rpy="2.0917379970342154e-06 -1.415306806564331 2.4864845275878906"/>
    <parent link="r_lower_leg"/>
    <child link="r_lower_leg_skin_0"/>
  </joint>
  <link name="r_lower_leg_skin_0">
    <inertial>
      <origin xyz="0.0 0.0 0.0" rpy="0.0 0.0 0.0"/>
      <mass value="0.0"/>
      <inertia ixx="0.0" ixy="0.0" ixz="0.0" iyy="0.0" iyz="0.0" izz="0.0"/>
    </inertial>
  </link>
  <joint name="r_lower_leg_skin_3_joint" type="fixed">
    <origin xyz="0.051578780000000005 0.03042049999999999 -0.0028429999999999844" rpy="-1.971049903425493e-15 -1.4295105934143066 -2.303914785385132"/>
    <parent link="r_lower_leg"/>
    <child link="r_lower_leg_skin_3"/>
  </joint>
  <link name="r_lower_leg_skin_3">
    <inertial>
      <origin xyz="0.0 0.0 0.0" rpy="0.0 0.0 0.0"/>
      <mass value="0.0"/>
      <inertia ixx="0.0" ixy="0.0" ixz="0.0" iyy="0.0" iyz="0.0" izz="0.0"/>
    </inertial>
  </link>
  <joint name="r_lower_leg_skin_4_joint" type="fixed">
    <origin xyz="0.058310299999999995 0.016783599999999996 0.007272000000000001" rpy="-2.9863636541449523e-07 -1.2563674449920654 -2.7589237689971924"/>
    <parent link="r_lower_leg"/>
    <child link="r_lower_leg_skin_4"/>
  </joint>
  <link name="r_lower_leg_skin_4">
    <inertial>
      <origin xyz="0.0 0.0 0.0" rpy="0.0 0.0 0.0"/>
      <mass value="0.0"/>
      <inertia ixx="0.0" ixy="0.0" ixz="0.0" iyy="0.0" iyz="0.0" izz="0.0"/>
    </inertial>
  </link>
  <joint name="r_lower_leg_skin_5_joint" type="fixed">
    <origin xyz="0.06365029999999999 0.00030940000000000134 -0.0019720000000000293" rpy="-7.396333674840638e-20 -1.3865221738815308 -3.1414716243743896"/>
    <parent link="r_lower_leg"/>
    <child link="r_lower_leg_skin_5"/>
  </joint>
  <link name="r_lower_leg_skin_5">
    <inertial>
      <origin xyz="0.0 0.0 0.0" rpy="0.0 0.0 0.0"/>
      <mass value="0.0"/>
      <inertia ixx="0.0" ixy="0.0" ixz="0.0" iyy="0.0" iyz="0.0" izz="0.0"/>
    </inertial>
  </link>
  <joint name="r_lower_leg_skin_6_joint" type="fixed">
    <origin xyz="0.05208552 0.03044339999999998 -0.022148999999999974" rpy="-3.1415891647338867 -1.4678512811660767 0.8374928832054138"/>
    <parent link="r_lower_leg"/>
    <child link="r_lower_leg_skin_6"/>
  </joint>
  <link name="r_lower_leg_skin_6">
    <inertial>
      <origin xyz="0.0 0.0 0.0" rpy="0.0 0.0 0.0"/>
      <mass value="0.0"/>
      <inertia ixx="0.0" ixy="0.0" ixz="0.0" iyy="0.0" iyz="0.0" izz="0.0"/>
    </inertial>
  </link>
  <joint name="r_lower_leg_skin_9_joint" type="fixed">
    <origin xyz="0.0598214 0.016797299999999987 -0.03096199999999999" rpy="-3.141592025756836 -1.3422476053237915 0.3792944848537445"/>
    <parent link="r_lower_leg"/>
    <child link="r_lower_leg_skin_9"/>
  </joint>
  <link name="r_lower_leg_skin_9">
    <inertial>
      <origin xyz="0.0 0.0 0.0" rpy="0.0 0.0 0.0"/>
      <mass value="0.0"/>
      <inertia ixx="0.0" ixy="0.0" ixz="0.0" iyy="0.0" iyz="0.0" izz="0.0"/>
    </inertial>
  </link>
  <joint name="r_lower_leg_skin_10_joint" type="fixed">
    <origin xyz="0.0644607 0.00034239999999997883 -0.021204999999999974" rpy="3.1415927410125732 -1.4709579944610596 0.0004300216678529978"/>
    <parent link="r_lower_leg"/>
    <child link="r_lower_leg_skin_10"/>
  </joint>
  <link name="r_lower_leg_skin_10">
    <inertial>
      <origin xyz="0.0 0.0 0.0" rpy="0.0 0.0 0.0"/>
      <mass value="0.0"/>
      <inertia ixx="0.0" ixy="0.0" ixz="0.0" iyy="0.0" iyz="0.0" izz="0.0"/>
    </inertial>
  </link>
  <joint name="r_lower_leg_skin_11_joint" type="fixed">
    <origin xyz="0.06071079999999999 -0.01609160000000001 -0.030884999999999996" rpy="-3.141592264175415 -1.328118085861206 -0.2721383571624756"/>
    <parent link="r_lower_leg"/>
    <child link="r_lower_leg_skin_11"/>
  </joint>
  <link name="r_lower_leg_skin_11">
    <inertial>
      <origin xyz="0.0 0.0 0.0" rpy="0.0 0.0 0.0"/>
      <mass value="0.0"/>
      <inertia ixx="0.0" ixy="0.0" ixz="0.0" iyy="0.0" iyz="0.0" izz="0.0"/>
    </inertial>
  </link>
  <joint name="r_lower_leg_skin_14_joint" type="fixed">
    <origin xyz="0.05504769999999999 -0.03117600000000001 -0.02190000000000003" rpy="-3.141591787338257 -1.4650273323059082 -0.6540334224700928"/>
    <parent link="r_lower_leg"/>
    <child link="r_lower_leg_skin_14"/>
  </joint>
  <link name="r_lower_leg_skin_14">
    <inertial>
      <origin xyz="0.0 0.0 0.0" rpy="0.0 0.0 0.0"/>
      <mass value="0.0"/>
      <inertia ixx="0.0" ixy="0.0" ixz="0.0" iyy="0.0" iyz="0.0" izz="0.0"/>
    </inertial>
  </link>
  <joint name="r_lower_leg_skin_15_joint" type="fixed">
    <origin xyz="0.05917079999999999 -0.016178800000000007 0.0072429999999999994" rpy="4.2748425244099053e-07 -1.2520363330841064 2.8679885864257812"/>
    <parent link="r_lower_leg"/>
    <child link="r_lower_leg_skin_15"/>
  </joint>
  <link name="r_lower_leg_skin_15">
    <inertial>
      <origin xyz="0.0 0.0 0.0" rpy="0.0 0.0 0.0"/>
      <mass value="0.0"/>
      <inertia ixx="0.0" ixy="0.0" ixz="0.0" iyy="0.0" iyz="0.0" izz="0.0"/>
    </inertial>
  </link>
  <joint name="r_lower_leg_skin_16_joint" type="fixed">
    <origin xyz="0.027287499999999985 -0.050287 -0.004549000000000025" rpy="1.3307591871125624e-05 -1.5326085090637207 1.9628024101257324"/>
    <parent link="r_lower_leg"/>
    <child link="r_lower_leg_skin_16"/>
  </joint>
  <link name="r_lower_leg_skin_16">
    <inertial>
      <origin xyz="0.0 0.0 0.0" rpy="0.0 0.0 0.0"/>
      <mass value="0.0"/>
      <inertia ixx="0.0" ixy="0.0" ixz="0.0" iyy="0.0" iyz="0.0" izz="0.0"/>
    </inertial>
  </link>
  <joint name="r_lower_leg_skin_17_joint" type="fixed">
    <origin xyz="0.027874999999999987 -0.05031200000000001 -0.023882000000000014" rpy="-3.1415646076202393 -1.5636624097824097 -1.180225133895874"/>
    <parent link="r_lower_leg"/>
    <child link="r_lower_leg_skin_17"/>
  </joint>
  <link name="r_lower_leg_skin_17">
    <inertial>
      <origin xyz="0.0 0.0 0.0" rpy="0.0 0.0 0.0"/>
      <mass value="0.0"/>
      <inertia ixx="0.0" ixy="0.0" ixz="0.0" iyy="0.0" iyz="0.0" izz="0.0"/>
    </inertial>
  </link>
  <joint name="r_lower_leg_skin_19_joint" type="fixed">
    <origin xyz="0.035753400000000005 0.04106279999999999 0.006064999999999987" rpy="-8.908777431315684e-07 -1.43498694896698 -2.1586360931396484"/>
    <parent link="r_lower_leg"/>
    <child link="r_lower_leg_skin_19"/>
  </joint>
  <link name="r_lower_leg_skin_19">
    <inertial>
      <origin xyz="0.0 0.0 0.0" rpy="0.0 0.0 0.0"/>
      <mass value="0.0"/>
      <inertia ixx="0.0" ixy="0.0" ixz="0.0" iyy="0.0" iyz="0.0" izz="0.0"/>
    </inertial>
  </link>
  <joint name="r_lower_leg_skin_20_joint" type="fixed">
    <origin xyz="0.023441900000000012 0.04799079999999998 -0.004952000000000012" rpy="-3.2055654628493357e-06 -1.5001550912857056 -1.8675509691238403"/>
    <parent link="r_lower_leg"/>
    <child link="r_lower_leg_skin_20"/>
  </joint>
  <link name="r_lower_leg_skin_20">
    <inertial>
      <origin xyz="0.0 0.0 0.0" rpy="0.0 0.0 0.0"/>
      <mass value="0.0"/>
      <inertia ixx="0.0" ixy="0.0" ixz="0.0" iyy="0.0" iyz="0.0" izz="0.0"/>
    </inertial>
  </link>
  <joint name="r_lower_leg_skin_21_joint" type="fixed">
    <origin xyz="0.02427040000000001 0.04853779999999998 -0.024276999999999993" rpy="2.2967115000938065e-05 -1.5554550886154175 -1.874119758605957"/>
    <parent link="r_lower_leg"/>
    <child link="r_lower_leg_skin_21"/>
  </joint>
  <link name="r_lower_leg_skin_21">
    <inertial>
      <origin xyz="0.0 0.0 0.0" rpy="0.0 0.0 0.0"/>
      <mass value="0.0"/>
      <inertia ixx="0.0" ixy="0.0" ixz="0.0" iyy="0.0" iyz="0.0" izz="0.0"/>
    </inertial>
  </link>
  <joint name="r_lower_leg_skin_28_joint" type="fixed">
    <origin xyz="0.04087214999999999 -0.04244000000000002 -0.03275600000000001" rpy="3.141580820083618 -1.5225245952606201 -0.9296810030937195"/>
    <parent link="r_lower_leg"/>
    <child link="r_lower_leg_skin_28"/>
  </joint>
  <link name="r_lower_leg_skin_28">
    <inertial>
      <origin xyz="0.0 0.0 0.0" rpy="0.0 0.0 0.0"/>
      <mass value="0.0"/>
      <inertia ixx="0.0" ixy="0.0" ixz="0.0" iyy="0.0" iyz="0.0" izz="0.0"/>
    </inertial>
  </link>
  <joint name="r_lower_leg_skin_29_joint" type="fixed">
    <origin xyz="0.038466369999999986 -0.04351600000000001 -0.05242000000000002" rpy="3.141580104827881 -1.5342984199523926 -0.915436327457428"/>
    <parent link="r_lower_leg"/>
    <child link="r_lower_leg_skin_29"/>
  </joint>
  <link name="r_lower_leg_skin_29">
    <inertial>
      <origin xyz="0.0 0.0 0.0" rpy="0.0 0.0 0.0"/>
      <mass value="0.0"/>
      <inertia ixx="0.0" ixy="0.0" ixz="0.0" iyy="0.0" iyz="0.0" izz="0.0"/>
    </inertial>
  </link>
  <joint name="r_lower_leg_skin_31_joint" type="fixed">
    <origin xyz="0.03914637999999999 -0.04227099999999999 0.006327000000000027" rpy="-6.583817366845324e-07 -1.418649435043335 2.2085304260253906"/>
    <parent link="r_lower_leg"/>
    <child link="r_lower_leg_skin_31"/>
  </joint>
  <link name="r_lower_leg_skin_31">
    <inertial>
      <origin xyz="0.0 0.0 0.0" rpy="0.0 0.0 0.0"/>
      <mass value="0.0"/>
      <inertia ixx="0.0" ixy="0.0" ixz="0.0" iyy="0.0" iyz="0.0" izz="0.0"/>
    </inertial>
  </link>
  <joint name="r_lower_leg_skin_32_joint" type="fixed">
    <origin xyz="0.045983010000000005 0.032584699999999966 -0.080733" rpy="-3.141590118408203 -1.5223828554153442 0.645940363407135"/>
    <parent link="r_lower_leg"/>
    <child link="r_lower_leg_skin_32"/>
  </joint>
  <link name="r_lower_leg_skin_32">
    <inertial>
      <origin xyz="0.0 0.0 0.0" rpy="0.0 0.0 0.0"/>
      <mass value="0.0"/>
      <inertia ixx="0.0" ixy="0.0" ixz="0.0" iyy="0.0" iyz="0.0" izz="0.0"/>
    </inertial>
  </link>
  <joint name="r_lower_leg_skin_35_joint" type="fixed">
    <origin xyz="0.047748659999999984 -0.031231999999999996 -0.08011299999999999" rpy="-3.1415867805480957 -1.5175846815109253 -0.5415324568748474"/>
    <parent link="r_lower_leg"/>
    <child link="r_lower_leg_skin_35"/>
  </joint>
  <link name="r_lower_leg_skin_35">
    <inertial>
      <origin xyz="0.0 0.0 0.0" rpy="0.0 0.0 0.0"/>
      <mass value="0.0"/>
      <inertia ixx="0.0" ixy="0.0" ixz="0.0" iyy="0.0" iyz="0.0" izz="0.0"/>
    </inertial>
  </link>
  <joint name="r_lower_leg_skin_36_joint" type="fixed">
    <origin xyz="0.05322408999999999 -0.01560180000000004 -0.088362" rpy="-3.1415903568267822 -1.515872597694397 -0.20740734040737152"/>
    <parent link="r_lower_leg"/>
    <child link="r_lower_leg_skin_36"/>
  </joint>
  <link name="r_lower_leg_skin_36">
    <inertial>
      <origin xyz="0.0 0.0 0.0" rpy="0.0 0.0 0.0"/>
      <mass value="0.0"/>
      <inertia ixx="0.0" ixy="0.0" ixz="0.0" iyy="0.0" iyz="0.0" izz="0.0"/>
    </inertial>
  </link>
  <joint name="r_lower_leg_skin_37_joint" type="fixed">
    <origin xyz="0.05525719999999999 0.0009643999999999903 -0.078318" rpy="-3.1415817737579346 -1.5231833457946777 0.007524505723267794"/>
    <parent link="r_lower_leg"/>
    <child link="r_lower_leg_skin_37"/>
  </joint>
  <link name="r_lower_leg_skin_37">
    <inertial>
      <origin xyz="0.0 0.0 0.0" rpy="0.0 0.0 0.0"/>
      <mass value="0.0"/>
      <inertia ixx="0.0" ixy="0.0" ixz="0.0" iyy="0.0" iyz="0.0" izz="0.0"/>
    </inertial>
  </link>
  <joint name="r_lower_leg_skin_38_joint" type="fixed">
    <origin xyz="0.04880466999999999 -0.031263 -0.060757000000000005" rpy="3.1415865421295166 -1.5157299041748047 -0.5421535968780518"/>
    <parent link="r_lower_leg"/>
    <child link="r_lower_leg_skin_38"/>
  </joint>
  <link name="r_lower_leg_skin_38">
    <inertial>
      <origin xyz="0.0 0.0 0.0" rpy="0.0 0.0 0.0"/>
      <mass value="0.0"/>
      <inertia ixx="0.0" ixy="0.0" ixz="0.0" iyy="0.0" iyz="0.0" izz="0.0"/>
    </inertial>
  </link>
  <joint name="r_lower_leg_skin_41_joint" type="fixed">
    <origin xyz="0.05660089999999999 -0.01591290000000002 -0.049853999999999954" rpy="-3.141592025756836 -1.406813383102417 -0.24823309481143951"/>
    <parent link="r_lower_leg"/>
    <child link="r_lower_leg_skin_41"/>
  </joint>
  <link name="r_lower_leg_skin_41">
    <inertial>
      <origin xyz="0.0 0.0 0.0" rpy="0.0 0.0 0.0"/>
      <mass value="0.0"/>
      <inertia ixx="0.0" ixy="0.0" ixz="0.0" iyy="0.0" iyz="0.0" izz="0.0"/>
    </inertial>
  </link>
  <joint name="r_lower_leg_skin_42_joint" type="fixed">
    <origin xyz="0.057010599999999995 0.000796199999999983 -0.059079999999999966" rpy="3.141589641571045 -1.435247540473938 0.006879436317831278"/>
    <parent link="r_lower_leg"/>
    <child link="r_lower_leg_skin_42"/>
  </joint>
  <link name="r_lower_leg_skin_42">
    <inertial>
      <origin xyz="0.0 0.0 0.0" rpy="0.0 0.0 0.0"/>
      <mass value="0.0"/>
      <inertia ixx="0.0" ixy="0.0" ixz="0.0" iyy="0.0" iyz="0.0" izz="0.0"/>
    </inertial>
  </link>
  <joint name="r_lower_leg_skin_43_joint" type="fixed">
    <origin xyz="0.04712542 0.03236529999999998 -0.06136200000000003" rpy="-3.1415913105010986 -1.5384303331375122 0.6242175102233887"/>
    <parent link="r_lower_leg"/>
    <child link="r_lower_leg_skin_43"/>
  </joint>
  <link name="r_lower_leg_skin_43">
    <inertial>
      <origin xyz="0.0 0.0 0.0" rpy="0.0 0.0 0.0"/>
      <mass value="0.0"/>
      <inertia ixx="0.0" ixy="0.0" ixz="0.0" iyy="0.0" iyz="0.0" izz="0.0"/>
    </inertial>
  </link>
  <joint name="r_lower_leg_skin_46_joint" type="fixed">
    <origin xyz="0.0558156 0.01721639999999998 -0.05018" rpy="-3.141589879989624 -1.4275988340377808 0.3256077170372009"/>
    <parent link="r_lower_leg"/>
    <child link="r_lower_leg_skin_46"/>
  </joint>
  <link name="r_lower_leg_skin_46">
    <inertial>
      <origin xyz="0.0 0.0 0.0" rpy="0.0 0.0 0.0"/>
      <mass value="0.0"/>
      <inertia ixx="0.0" ixy="0.0" ixz="0.0" iyy="0.0" iyz="0.0" izz="0.0"/>
    </inertial>
  </link>
  <joint name="r_lower_leg_skin_47_joint" type="fixed">
    <origin xyz="0.052641629999999995 0.01763889999999997 -0.08886" rpy="3.141589641571045 -1.5169055461883545 0.26264041662216187"/>
    <parent link="r_lower_leg"/>
    <child link="r_lower_leg_skin_47"/>
  </joint>
  <link name="r_lower_leg_skin_47">
    <inertial>
      <origin xyz="0.0 0.0 0.0" rpy="0.0 0.0 0.0"/>
      <mass value="0.0"/>
      <inertia ixx="0.0" ixy="0.0" ixz="0.0" iyy="0.0" iyz="0.0" izz="0.0"/>
    </inertial>
  </link>
  <joint name="r_lower_leg_skin_49_joint" type="fixed">
    <origin xyz="0.04113137 0.032438499999999953 -0.138859" rpy="-3.141589403152466 -1.4899613857269287 0.7297635674476624"/>
    <parent link="r_lower_leg"/>
    <child link="r_lower_leg_skin_49"/>
  </joint>
  <link name="r_lower_leg_skin_49">
    <inertial>
      <origin xyz="0.0 0.0 0.0" rpy="0.0 0.0 0.0"/>
      <mass value="0.0"/>
      <inertia ixx="0.0" ixy="0.0" ixz="0.0" iyy="0.0" iyz="0.0" izz="0.0"/>
    </inertial>
  </link>
  <joint name="r_lower_leg_skin_50_joint" type="fixed">
    <origin xyz="0.04301694700000001 0.03252729999999996 -0.11946899999999999" rpy="3.1415905952453613 -1.4990073442459106 0.6957840323448181"/>
    <parent link="r_lower_leg"/>
    <child link="r_lower_leg_skin_50"/>
  </joint>
  <link name="r_lower_leg_skin_50">
    <inertial>
      <origin xyz="0.0 0.0 0.0" rpy="0.0 0.0 0.0"/>
      <mass value="0.0"/>
      <inertia ixx="0.0" ixy="0.0" ixz="0.0" iyy="0.0" iyz="0.0" izz="0.0"/>
    </inertial>
  </link>
  <joint name="r_lower_leg_skin_51_joint" type="fixed">
    <origin xyz="0.051415829999999996 0.017758999999999962 -0.10820600000000002" rpy="-3.1415889263153076 -1.5062847137451172 0.2720799446105957"/>
    <parent link="r_lower_leg"/>
    <child link="r_lower_leg_skin_51"/>
  </joint>
  <link name="r_lower_leg_skin_51">
    <inertial>
      <origin xyz="0.0 0.0 0.0" rpy="0.0 0.0 0.0"/>
      <mass value="0.0"/>
      <inertia ixx="0.0" ixy="0.0" ixz="0.0" iyy="0.0" iyz="0.0" izz="0.0"/>
    </inertial>
  </link>
  <joint name="r_lower_leg_skin_52_joint" type="fixed">
    <origin xyz="0.052998319999999995 0.0012663999999999592 -0.11689500000000003" rpy="-3.1415915489196777 -1.5031867027282715 0.010871726088225842"/>
    <parent link="r_lower_leg"/>
    <child link="r_lower_leg_skin_52"/>
  </joint>
  <link name="r_lower_leg_skin_52">
    <inertial>
      <origin xyz="0.0 0.0 0.0" rpy="0.0 0.0 0.0"/>
      <mass value="0.0"/>
      <inertia ixx="0.0" ixy="0.0" ixz="0.0" iyy="0.0" iyz="0.0" izz="0.0"/>
    </inertial>
  </link>
  <joint name="r_lower_leg_skin_53_joint" type="fixed">
    <origin xyz="0.05207311999999999 -0.015433900000000042 -0.10765399999999997" rpy="3.1415905952453613 -1.505953073501587 -0.21140731871128082"/>
    <parent link="r_lower_leg"/>
    <child link="r_lower_leg_skin_53"/>
  </joint>
  <link name="r_lower_leg_skin_53">
    <inertial>
      <origin xyz="0.0 0.0 0.0" rpy="0.0 0.0 0.0"/>
      <mass value="0.0"/>
      <inertia ixx="0.0" ixy="0.0" ixz="0.0" iyy="0.0" iyz="0.0" izz="0.0"/>
    </inertial>
  </link>
  <joint name="r_lower_leg_skin_54_joint" type="fixed">
    <origin xyz="0.045127079999999986 -0.030749000000000026 -0.11878700000000003" rpy="3.1415882110595703 -1.4974514245986938 -0.5751153826713562"/>
    <parent link="r_lower_leg"/>
    <child link="r_lower_leg_skin_54"/>
  </joint>
  <link name="r_lower_leg_skin_54">
    <inertial>
      <origin xyz="0.0 0.0 0.0" rpy="0.0 0.0 0.0"/>
      <mass value="0.0"/>
      <inertia ixx="0.0" ixy="0.0" ixz="0.0" iyy="0.0" iyz="0.0" izz="0.0"/>
    </inertial>
  </link>
  <joint name="r_lower_leg_skin_55_joint" type="fixed">
    <origin xyz="0.04350266299999999 -0.030489000000000016 -0.13814300000000007" rpy="3.1415891647338867 -1.4899579286575317 -0.5972199440002441"/>
    <parent link="r_lower_leg"/>
    <child link="r_lower_leg_skin_55"/>
  </joint>
  <link name="r_lower_leg_skin_55">
    <inertial>
      <origin xyz="0.0 0.0 0.0" rpy="0.0 0.0 0.0"/>
      <mass value="0.0"/>
      <inertia ixx="0.0" ixy="0.0" ixz="0.0" iyy="0.0" iyz="0.0" izz="0.0"/>
    </inertial>
  </link>
  <joint name="r_lower_leg_skin_56_joint" type="fixed">
    <origin xyz="0.049268389999999995 -0.015121000000000051 -0.1462179999999999" rpy="-3.1415891647338867 -1.4912482500076294 -0.22348447144031525"/>
    <parent link="r_lower_leg"/>
    <child link="r_lower_leg_skin_56"/>
  </joint>
  <link name="r_lower_leg_skin_56">
    <inertial>
      <origin xyz="0.0 0.0 0.0" rpy="0.0 0.0 0.0"/>
      <mass value="0.0"/>
      <inertia ixx="0.0" ixy="0.0" ixz="0.0" iyy="0.0" iyz="0.0" izz="0.0"/>
    </inertial>
  </link>
  <joint name="r_lower_leg_skin_60_joint" type="fixed">
    <origin xyz="0.04836967 0.01805599999999996 -0.14693799999999996" rpy="-3.141591787338257 -1.489859700202942 0.3029518723487854"/>
    <parent link="r_lower_leg"/>
    <child link="r_lower_leg_skin_60"/>
  </joint>
  <link name="r_lower_leg_skin_60">
    <inertial>
      <origin xyz="0.0 0.0 0.0" rpy="0.0 0.0 0.0"/>
      <mass value="0.0"/>
      <inertia ixx="0.0" ixy="0.0" ixz="0.0" iyy="0.0" iyz="0.0" izz="0.0"/>
    </inertial>
  </link>
  <joint name="r_lower_leg_skin_61_joint" type="fixed">
    <origin xyz="0.051619519999999995 0.0014265999999999723 -0.13616899999999993" rpy="-3.1415910720825195 -1.4960209131240845 0.013201427645981312"/>
    <parent link="r_lower_leg"/>
    <child link="r_lower_leg_skin_61"/>
  </joint>
  <link name="r_lower_leg_skin_61">
    <inertial>
      <origin xyz="0.0 0.0 0.0" rpy="0.0 0.0 0.0"/>
      <mass value="0.0"/>
      <inertia ixx="0.0" ixy="0.0" ixz="0.0" iyy="0.0" iyz="0.0" izz="0.0"/>
    </inertial>
  </link>
  <joint name="r_ankle_pitch" type="revolute">
    <origin xyz="0.0 0.0 -0.2004999965429306" rpy="0.0 0.2617991864681244 0.0"/>
    <axis xyz="-6.661338147750939e-16 1.0 4.440892098500626e-16"/>
    <parent link="r_lower_leg"/>
    <child link="r_ankle_1"/>
    <limit effort="37.0" lower="-0.8726646304130554" upper="0.3490658402442932" velocity="7.639999866485596"/>
  </joint>
  <link name="r_ankle_1">
    <inertial>
      <origin xyz="0.01514340564608574 -0.0008684999775141478 4.285908289602958e-05" rpy="1.4822107553482056 -0.5298506021499634 1.884317398071289"/>
      <mass value="0.6802999973297119"/>
      <inertia ixx="0.00029954113415442407" ixy="0.0" ixz="0.0" iyy="0.00041326656355522573" iyz="0.0" izz="0.00044868089025840163"/>
    </inertial>
    <visual name="SM_r_ankle_1_visual_0">
      <origin xyz="-0.10974272340536118 0.07010000199079514 0.5784444808959961" rpy="1.3089971542358398 0.0 1.5707963705062866"/>
      <geometry>
        <mesh filename="file://iCub/meshes/stl/sim_sea_2-5_r_ankle_prt-binary.stl" scale="0.0010000000474974513 0.0010000000474974513 0.0010000000474974513"/>
      </geometry>
    </visual>
    <collision name="SM_r_ankle_1_collision_0">
      <origin xyz="-0.10974272340536118 0.07010000199079514 0.5784444808959961" rpy="1.3089971542358398 0.0 1.5707963705062866"/>
      <geometry>
        <mesh filename="file://iCub/meshes/stl/sim_sea_2-5_r_ankle_prt-binary.stl" scale="0.0010000000474974513 0.0010000000474974513 0.0010000000474974513"/>
      </geometry>
    </collision>
  </link>
  <joint name="r_ankle_roll" type="revolute">
    <origin xyz="0.0 0.0 0.0" rpy="0.0 0.0 0.0"/>
    <axis xyz="-1.0000001192092896 -6.013653875237346e-16 1.197939525354741e-07"/>
    <parent link="r_ankle_1"/>
    <child link="r_ankle_2"/>
    <limit effort="37.0" lower="-0.4363323152065277" upper="0.4363323152065277" velocity="7.639999866485596"/>
  </joint>
  <link name="r_ankle_2">
    <inertial>
      <origin xyz="0.0011452158214524388 -8.300000445160549e-06 -0.03851185366511345" rpy="1.3860836029052734 -0.1811043918132782 2.3729615211486816"/>
      <mass value="0.2653369903564453"/>
      <inertia ixx="0.009979299269616604" ixy="0.0" ixz="0.0" iyy="0.009999999776482582" iyz="0.0" izz="0.010020701214671135"/>
    </inertial>
    <visual name="SM_r_ankle_2_visual_0">
      <origin xyz="-0.10974272340536118 0.07010000199079514 0.5784444808959961" rpy="1.3089971542358398 0.0 1.5707963705062866"/>
      <geometry>
        <mesh filename="file://iCub/meshes/stl/sim_sea_2-5_r_foot_prt-binary.stl" scale="0.0010000000474974513 0.0010000000474974513 0.0010000000474974513"/>
      </geometry>
    </visual>
    <collision name="SM_r_ankle_2_collision_0">
      <origin xyz="-0.10974272340536118 0.07010000199079514 0.5784444808959961" rpy="1.3089971542358398 0.0 1.5707963705062866"/>
      <geometry>
        <mesh filename="file://iCub/meshes/stl/sim_sea_2-5_r_foot_prt-binary.stl" scale="0.0010000000474974513 0.0010000000474974513 0.0010000000474974513"/>
      </geometry>
    </collision>
  </link>
  <joint name="r_foot_joint" type="fixed">
    <origin xyz="-0.0034999280659716164 0.0 -0.060500343280208146" rpy="3.1415927410125732 0.0 0.0"/>
    <parent link="r_ankle_2"/>
    <child link="r_foot"/>
  </joint>
  <link name="r_foot">
    <inertial>
      <origin xyz="0.03977974131703377 0.004553699865937233 -0.00631181662902236" rpy="1.5750600099563599 0.21987584233283997 -1.5657944679260254"/>
      <mass value="0.35788100957870483"/>
      <inertia ixx="0.00021378160454332829" ixy="0.0" ixz="0.0" iyy="0.0010976609773933887" iyz="0.0" izz="0.0012570865219458938"/>
    </inertial>
    <visual name="SM_r_foot_visual_0">
      <origin xyz="-0.10624279826879501 -0.07010000199079514 -0.6387448310852051" rpy="-1.8325954675674438 0.0 -1.5707963705062866"/>
      <geometry>
        <mesh filename="file://iCub/meshes/stl/sim_sea_2-5_r_sole_prt-binary.stl" scale="0.0010000000474974513 0.0010000000474974513 0.0010000000474974513"/>
      </geometry>
    </visual>
    <collision name="SM_r_foot_collision_0">
      <origin xyz="0.04178579896688461 0.004997800104320049 0.000725075020454824" rpy="3.1415927410125732 0.2617991864681244 0.0"/>
      <geometry>
        <box size="0.1599999964237213 0.07199999690055847 0.0010000000474974513"/>
      </geometry>
    </collision>
  </link>
  <joint name="r_sole_joint" type="fixed">
    <origin xyz="0.021450226059648816 0.0 0.006691276652475264" rpy="-3.1415927410125732 0.2617991864681244 1.0208611252569277e-31"/>
    <parent link="r_foot"/>
    <child link="r_sole"/>
  </joint>
  <link name="r_sole">
    <inertial>
      <origin xyz="0.0 0.0 0.0" rpy="0.0 0.0 0.0"/>
      <mass value="0.0"/>
      <inertia ixx="0.0" ixy="0.0" ixz="0.0" iyy="0.0" iyz="0.0" izz="0.0"/>
    </inertial>
  </link>
  <joint name="r_foot_ft_joint" type="fixed">
    <origin xyz="0.0 0.0 0.0" rpy="0.0 0.0 0.0"/>
    <parent link="r_foot"/>
    <child link="r_foot_ft"/>
  </joint>
  <link name="r_foot_ft">
    <inertial>
      <origin xyz="0.0 0.0 0.0" rpy="0.0 0.0 0.0"/>
      <mass value="0.0"/>
      <inertia ixx="0.0" ixy="0.0" ixz="0.0" iyy="0.0" iyz="0.0" izz="0.0"/>
    </inertial>
  </link>
  <joint name="r_foot_dh_frame_joint" type="fixed">
    <origin xyz="0.0 0.0 0.004" rpy="3.1415927410125732 1.5707926750183105 3.1415927410125732"/>
    <parent link="r_foot"/>
    <child link="r_foot_dh_frame"/>
  </joint>
  <link name="r_foot_dh_frame">
    <inertial>
      <origin xyz="0.0 0.0 0.0" rpy="0.0 0.0 0.0"/>
      <mass value="0.0"/>
      <inertia ixx="0.0" ixy="0.0" ixz="0.0" iyy="0.0" iyz="0.0" izz="0.0"/>
    </inertial>
  </link>
  <joint name="l_hip_pitch" type="revolute">
    <origin xyz="0.006451500114053488 -0.026000000536441803 -0.1199129968881607" rpy="0.0 0.0 -3.1415927410125732"/>
    <axis xyz="-2.220446049250313e-16 -1.0 0.0"/>
    <parent link="root_link"/>
    <child link="l_hip_1"/>
    <limit effort="55.5" lower="-0.7853981852531433" upper="2.3387413024902344" velocity="5.099999904632568"/>
  </joint>
  <link name="l_hip_1">
    <inertial>
      <origin xyz="-0.0005107999895699322 0.03809230029582977 -8.299999899463728e-05" rpy="2.416644334793091 -1.5619136095046997 2.4758877754211426"/>
      <mass value="0.9197250008583069"/>
      <inertia ixx="0.00040452543180435896" ixy="0.0" ixz="0.0" iyy="0.0005731289857067168" iyz="0.0" izz="0.0005791815929114819"/>
    </inertial>
    <visual name="SM_l_hip_1_visual_0">
      <origin xyz="0.04285150021314621 -0.026000000536441803 0.15191300213336945" rpy="1.5707963705062866 0.0 1.5707963705062866"/>
      <geometry>
        <mesh filename="file://iCub/meshes/stl/sim_sea_2-5_l_hip_1_prt-binary.stl" scale="0.0010000000474974513 0.0010000000474974513 0.0010000000474974513"/>
      </geometry>
    </visual>
    <collision name="SM_l_hip_1_collision_0">
      <origin xyz="0.04285150021314621 -0.026000000536441803 0.15191300213336945" rpy="1.5707963705062866 0.0 1.5707963705062866"/>
      <geometry>
        <mesh filename="file://iCub/meshes/stl/sim_sea_2-5_l_hip_1_prt-binary.stl" scale="0.0010000000474974513 0.0010000000474974513 0.0010000000474974513"/>
      </geometry>
    </collision>
  </link>
  <joint name="l_hip_roll" type="revolute">
    <origin xyz="0.0 0.04410000145435333 0.0" rpy="0.0 0.0 0.0"/>
    <axis xyz="1.0 0.0 2.220446049250313e-16"/>
    <parent link="l_hip_1"/>
    <child link="l_hip_2"/>
    <limit effort="37.0" lower="-0.3490658402442932" upper="2.094395160675049" velocity="7.639999866485596"/>
  </joint>
  <link name="l_hip_2">
    <inertial>
      <origin xyz="-0.0015762000111863017 -1.9400000383029692e-05 -0.04405299946665764" rpy="0.0006649777060374618 0.0010127705754712224 -0.39533376693725586"/>
      <mass value="0.4211060106754303"/>
      <inertia ixx="0.00028235267382115126" ixy="0.0" ixz="0.0" iyy="0.0003253910399507731" iyz="0.0" izz="0.0004942842642776668"/>
    </inertial>
    <visual name="SM_l_hip_2_visual_0">
      <origin xyz="0.04285150021314621 -0.07010000199079514 0.15191300213336945" rpy="1.5707963705062866 0.0 1.5707963705062866"/>
      <geometry>
        <mesh filename="file://iCub/meshes/stl/sim_sea_2-5_l_hip_2_prt-binary.stl" scale="0.0010000000474974513 0.0010000000474974513 0.0010000000474974513"/>
      </geometry>
    </visual>
    <collision name="SM_l_hip_2_collision_0">
      <origin xyz="0.04285150021314621 -0.07010000199079514 0.15191300213336945" rpy="1.5707963705062866 0.0 1.5707963705062866"/>
      <geometry>
        <mesh filename="file://iCub/meshes/stl/sim_sea_2-5_l_hip_2_prt-binary.stl" scale="0.0010000000474974513 0.0010000000474974513 0.0010000000474974513"/>
      </geometry>
    </collision>
  </link>
  <joint name="l_hip_3_joint" type="fixed">
    <origin xyz="-0.0008575000000000041 0.0 -0.07429999999999995" rpy="3.1415927410125732 0.0 0.0"/>
    <parent link="l_hip_2"/>
    <child link="l_hip_3"/>
  </joint>
  <link name="l_hip_3">
    <inertial>
      <origin xyz="-0.0001230000052601099 -0.00028229999588802457 0.008717999793589115" rpy="2.9681975841522217 0.7768762707710266 3.0034334659576416"/>
      <mass value="0.1262120008468628"/>
      <inertia ixx="0.009999729692935944" ixy="0.0" ixz="0.0" iyy="0.010000000707805157" iyz="0.0" izz="0.01000026986002922"/>
    </inertial>
    <visual name="SM_l_hip_3_visual_0">
      <origin xyz="0.04370899870991707 0.07010000199079514 -0.2262129932641983" rpy="-1.5707963705062866 0.0 -1.5707963705062866"/>
      <geometry>
        <mesh filename="file://iCub/meshes/stl/sim_sea_2-5_l_upper_thigh_prt-binary.stl" scale="0.0010000000474974513 0.0010000000474974513 0.0010000000474974513"/>
      </geometry>
    </visual>
    <collision name="SM_l_hip_3_collision_0">
      <origin xyz="0.04370899870991707 0.07010000199079514 -0.2262129932641983" rpy="-1.5707963705062866 0.0 -1.5707963705062866"/>
      <geometry>
        <mesh filename="file://iCub/meshes/stl/sim_sea_2-5_l_upper_thigh_prt-binary.stl" scale="0.0010000000474974513 0.0010000000474974513 0.0010000000474974513"/>
      </geometry>
    </collision>
  </link>
  <joint name="l_leg_ft_joint" type="fixed">
    <origin xyz="0.0 0.0 0.0" rpy="0.0 0.0 0.0"/>
    <parent link="l_hip_3"/>
    <child link="l_leg_ft"/>
  </joint>
  <link name="l_leg_ft">
    <inertial>
      <origin xyz="0.0 0.0 0.0" rpy="0.0 0.0 0.0"/>
      <mass value="0.0"/>
      <inertia ixx="0.0" ixy="0.0" ixz="0.0" iyy="0.0" iyz="0.0" izz="0.0"/>
    </inertial>
  </link>
  <joint name="l_hip_yaw" type="revolute">
    <origin xyz="0.0 0.0 0.014399999752640724" rpy="-3.1415927410125732 0.0 0.0"/>
    <axis xyz="0.0 2.220446049250313e-16 1.0"/>
    <parent link="l_hip_3"/>
    <child link="l_upper_leg"/>
    <limit effort="37.0" lower="-1.3962633609771729" upper="1.3962633609771729" velocity="7.639999866485596"/>
  </joint>
  <link name="l_upper_leg">
    <inertial>
      <origin xyz="0.0033867999445647 0.00010179999662796035 -0.07891599833965302" rpy="0.07041729241609573 -0.02470424771308899 0.027264749631285667"/>
      <mass value="1.80840003490448"/>
      <inertia ixx="0.0014557037502527237" ixy="0.0" ixz="0.0" iyy="0.006479881703853607" iyz="0.0" izz="0.006488238926976919"/>
    </inertial>
    <visual name="SM_l_upper_leg_visual_0">
      <origin xyz="0.04370899870991707 -0.07010000199079514 0.2408130019903183" rpy="1.5707963705062866 0.0 1.5707963705062866"/>
      <geometry>
        <mesh filename="file://iCub/meshes/stl/sim_sea_2-5_l_thigh_prt-binary.stl" scale="0.0010000000474974513 0.0010000000474974513 0.0010000000474974513"/>
      </geometry>
    </visual>
    <collision name="SM_l_upper_leg_collision_0">
      <origin xyz="0.04370899870991707 -0.07010000199079514 0.2408130019903183" rpy="1.5707963705062866 0.0 1.5707963705062866"/>
      <geometry>
        <mesh filename="file://iCub/meshes/stl/sim_sea_2-5_l_thigh_prt-binary.stl" scale="0.0010000000474974513 0.0010000000474974513 0.0010000000474974513"/>
      </geometry>
    </collision>
  </link>
  <joint name="l_upper_leg_ems_gyro_eb6_joint" type="fixed">
    <origin xyz="-0.013081000000000002 -0.040407200000000004 -0.087979" rpy="1.5707963705062866 1.5707963705062866 0.0"/>
    <parent link="l_upper_leg"/>
    <child link="l_upper_leg_ems_gyro_eb6"/>
  </joint>
  <link name="l_upper_leg_ems_gyro_eb6">
    <inertial>
      <origin xyz="0.0 0.0 0.0" rpy="0.0 0.0 0.0"/>
      <mass value="0.0"/>
      <inertia ixx="0.0" ixy="0.0" ixz="0.0" iyy="0.0" iyz="0.0" izz="0.0"/>
    </inertial>
  </link>
  <joint name="l_upper_leg_ems_gyro_eb10_joint" type="fixed">
    <origin xyz="-0.013078999999999986 0.040407 -0.035654999999999964" rpy="-1.5707963705062866 -1.5707963705062866 0.0"/>
    <parent link="l_upper_leg"/>
    <child link="l_upper_leg_ems_gyro_eb10"/>
  </joint>
  <link name="l_upper_leg_ems_gyro_eb10">
    <inertial>
      <origin xyz="0.0 0.0 0.0" rpy="0.0 0.0 0.0"/>
      <mass value="0.0"/>
      <inertia ixx="0.0" ixy="0.0" ixz="0.0" iyy="0.0" iyz="0.0" izz="0.0"/>
    </inertial>
  </link>
  <joint name="l_upper_leg_back_contact_joint" type="fixed">
    <origin xyz="-0.05125669999999998 0.0 0.014599999999999946" rpy="-0.0 1.5707963705062866 0.0"/>
    <parent link="l_upper_leg"/>
    <child link="l_upper_leg_back_contact"/>
  </joint>
  <link name="l_upper_leg_back_contact">
    <inertial>
      <origin xyz="0.0 0.0 0.0" rpy="0.0 0.0 0.0"/>
      <mass value="0.0"/>
      <inertia ixx="0.0" ixy="0.0" ixz="0.0" iyy="0.0" iyz="0.0" izz="0.0"/>
    </inertial>
  </link>
  <joint name="l_upper_leg_dh_frame_joint" type="fixed">
    <origin xyz="0.0 0.0 -0.14582499999999995" rpy="1.5707963705062866 0.0 0.0"/>
    <parent link="l_upper_leg"/>
    <child link="l_upper_leg_dh_frame"/>
  </joint>
  <link name="l_upper_leg_dh_frame">
    <inertial>
      <origin xyz="0.0 0.0 0.0" rpy="0.0 0.0 0.0"/>
      <mass value="0.0"/>
      <inertia ixx="0.0" ixy="0.0" ixz="0.0" iyy="0.0" iyz="0.0" izz="0.0"/>
    </inertial>
  </link>
  <joint name="l_knee" type="revolute">
    <origin xyz="0.0 0.0 -0.14582499861717224" rpy="0.0 0.0 0.0"/>
    <axis xyz="-2.220446049250313e-16 -1.0 0.0"/>
    <parent link="l_upper_leg"/>
    <child link="l_lower_leg"/>
    <limit effort="37.0" lower="-2.164208173751831" upper="0.06981316953897476" velocity="7.639999866485596"/>
  </joint>
  <link name="l_lower_leg">
    <inertial>
      <origin xyz="0.0009997000452131033 0.0034968999680131674 -0.08856700360774994" rpy="-1.3326681852340698 -0.08481254428625107 0.07356049865484238"/>
      <mass value="1.4723999500274658"/>
      <inertia ixx="0.0014846056001260877" ixy="0.0" ixz="0.0" iyy="0.004236162174493074" iyz="0.0" izz="0.0046085030771791935"/>
    </inertial>
    <visual name="SM_l_lower_leg_visual_0">
      <origin xyz="0.04370899870991707 -0.07010000199079514 0.38663798570632935" rpy="1.5707963705062866 0.0 1.5707963705062866"/>
      <geometry>
        <mesh filename="file://iCub/meshes/stl/sim_sea_2-5_l_shank_prt-binary.stl" scale="0.0010000000474974513 0.0010000000474974513 0.0010000000474974513"/>
      </geometry>
    </visual>
    <collision name="SM_l_lower_leg_collision_0">
      <origin xyz="0.04370899870991707 -0.07010000199079514 0.38663798570632935" rpy="1.5707963705062866 0.0 1.5707963705062866"/>
      <geometry>
        <mesh filename="file://iCub/meshes/stl/sim_sea_2-5_l_shank_prt-binary.stl" scale="0.0010000000474974513 0.0010000000474974513 0.0010000000474974513"/>
      </geometry>
    </collision>
  </link>
  <joint name="l_lower_leg_ems_gyro_eb7_joint" type="fixed">
    <origin xyz="0.04450329199999999 0.011818499999999968 -0.08830099999999996" rpy="-3.1415927410125732 -1.3526297807693481 4.293419691916712e-16"/>
    <parent link="l_lower_leg"/>
    <child link="l_lower_leg_ems_gyro_eb7"/>
  </joint>
  <link name="l_lower_leg_ems_gyro_eb7">
    <inertial>
      <origin xyz="0.0 0.0 0.0" rpy="0.0 0.0 0.0"/>
      <mass value="0.0"/>
      <inertia ixx="0.0" ixy="0.0" ixz="0.0" iyy="0.0" iyz="0.0" izz="0.0"/>
    </inertial>
  </link>
  <joint name="l_ankle_pitch" type="revolute">
    <origin xyz="0.0 0.0 -0.2004999965429306" rpy="0.0 0.2617991864681244 0.0"/>
    <axis xyz="-6.661338147750939e-16 1.0 4.440892098500626e-16"/>
    <parent link="l_lower_leg"/>
    <child link="l_ankle_1"/>
    <limit effort="37.0" lower="-0.8726646304130554" upper="0.3490658402442932" velocity="7.639999866485596"/>
  </joint>
  <link name="l_ankle_1">
    <inertial>
      <origin xyz="0.01515297219157219 0.0009021000005304813 4.2316554754506797e-05" rpy="1.5150388479232788 0.028715670108795166 1.8408795595169067"/>
      <mass value="0.6797999739646912"/>
      <inertia ixx="0.00029876577900722623" ixy="0.0" ixz="0.0" iyy="0.0004132568428758532" iyz="0.0" izz="0.00044794302084483206"/>
    </inertial>
    <visual name="SM_l_ankle_1_visual_0">
      <origin xyz="-0.10974272340536118 -0.07010000199079514 0.5784444808959961" rpy="1.3089971542358398 0.0 1.5707963705062866"/>
      <geometry>
        <mesh filename="file://iCub/meshes/stl/sim_sea_2-5_l_ankle_prt-binary.stl" scale="0.0010000000474974513 0.0010000000474974513 0.0010000000474974513"/>
      </geometry>
    </visual>
    <collision name="SM_l_ankle_1_collision_0">
      <origin xyz="-0.10974272340536118 -0.07010000199079514 0.5784444808959961" rpy="1.3089971542358398 0.0 1.5707963705062866"/>
      <geometry>
        <mesh filename="file://iCub/meshes/stl/sim_sea_2-5_l_ankle_prt-binary.stl" scale="0.0010000000474974513 0.0010000000474974513 0.0010000000474974513"/>
      </geometry>
    </collision>
  </link>
  <joint name="l_ankle_roll" type="revolute">
    <origin xyz="0.0 0.0 0.0" rpy="0.0 0.0 0.0"/>
    <axis xyz="1.0000001192092896 6.013653875237346e-16 -1.197939525354741e-07"/>
    <parent link="l_ankle_1"/>
    <child link="l_ankle_2"/>
    <limit effort="37.0" lower="-0.4363323152065277" upper="0.4363323152065277" velocity="7.639999866485596"/>
  </joint>
  <link name="l_ankle_2">
    <inertial>
      <origin xyz="0.0011452158214524388 -8.300000445160549e-06 -0.03851185366511345" rpy="1.3860836029052734 -0.1811043918132782 2.3729615211486816"/>
      <mass value="0.2653369903564453"/>
      <inertia ixx="0.009979299269616604" ixy="0.0" ixz="0.0" iyy="0.009999999776482582" iyz="0.0" izz="0.010020701214671135"/>
    </inertial>
    <visual name="SM_l_ankle_2_visual_0">
      <origin xyz="-0.10974272340536118 -0.07010000199079514 0.5784444808959961" rpy="1.3089971542358398 0.0 1.5707963705062866"/>
      <geometry>
        <mesh filename="file://iCub/meshes/stl/sim_sea_2-5_l_foot_prt-binary.stl" scale="0.0010000000474974513 0.0010000000474974513 0.0010000000474974513"/>
      </geometry>
    </visual>
    <collision name="SM_l_ankle_2_collision_0">
      <origin xyz="-0.10974272340536118 -0.07010000199079514 0.5784444808959961" rpy="1.3089971542358398 0.0 1.5707963705062866"/>
      <geometry>
        <mesh filename="file://iCub/meshes/stl/sim_sea_2-5_l_foot_prt-binary.stl" scale="0.0010000000474974513 0.0010000000474974513 0.0010000000474974513"/>
      </geometry>
    </collision>
  </link>
  <joint name="l_foot_joint" type="fixed">
    <origin xyz="-0.0034999280659716164 0.0 -0.060500343280208146" rpy="-3.1415927410125732 0.0 0.0"/>
    <parent link="l_ankle_2"/>
    <child link="l_foot"/>
  </joint>
  <link name="l_foot">
    <inertial>
      <origin xyz="0.03975093364715576 -0.004553699865937233 -0.006325837690383196" rpy="1.569191336631775 0.303692102432251 -1.5657004117965698"/>
      <mass value="0.35788100957870483"/>
      <inertia ixx="0.00021397951059043407" ixy="0.0" ixz="0.0" iyy="0.0010967772686854005" iyz="0.0" izz="0.001256016199477017"/>
    </inertial>
    <visual name="SM_l_foot_visual_0">
      <origin xyz="-0.10624280571937561 0.07010000199079514 -0.6387448310852051" rpy="-1.8325954675674438 0.0 -1.5707963705062866"/>
      <geometry>
        <mesh filename="file://iCub/meshes/stl/sim_sea_2-5_l_sole_prt-binary.stl" scale="0.0010000000474974513 0.0010000000474974513 0.0010000000474974513"/>
      </geometry>
    </visual>
    <collision name="SM_l_foot_collision_0">
      <origin xyz="0.04178579896688461 -0.004997800104320049 0.000725075020454824" rpy="3.1415927410125732 0.2617991864681244 0.0"/>
      <geometry>
        <box size="0.1599999964237213 0.07199999690055847 0.0010000000474974513"/>
      </geometry>
    </collision>
  </link>
  <joint name="l_sole_joint" type="fixed">
    <origin xyz="0.021450226059648844 0.0 0.006691276652475486" rpy="-3.1415927410125732 0.2617991864681244 8.166889002055422e-31"/>
    <parent link="l_foot"/>
    <child link="l_sole"/>
  </joint>
  <link name="l_sole">
    <inertial>
      <origin xyz="0.0 0.0 0.0" rpy="0.0 0.0 0.0"/>
      <mass value="0.0"/>
      <inertia ixx="0.0" ixy="0.0" ixz="0.0" iyy="0.0" iyz="0.0" izz="0.0"/>
    </inertial>
  </link>
  <joint name="l_foot_ft_joint" type="fixed">
    <origin xyz="0.0 0.0 0.0" rpy="0.0 0.0 0.0"/>
    <parent link="l_foot"/>
    <child link="l_foot_ft"/>
  </joint>
  <link name="l_foot_ft">
    <inertial>
      <origin xyz="0.0 0.0 0.0" rpy="0.0 0.0 0.0"/>
      <mass value="0.0"/>
      <inertia ixx="0.0" ixy="0.0" ixz="0.0" iyy="0.0" iyz="0.0" izz="0.0"/>
    </inertial>
  </link>
  <joint name="l_foot_dh_frame_joint" type="fixed">
    <origin xyz="0.0 0.0 0.004" rpy="3.1415927410125732 1.5707926750183105 3.1415927410125732"/>
    <parent link="l_foot"/>
    <child link="l_foot_dh_frame"/>
  </joint>
  <link name="l_foot_dh_frame">
    <inertial>
      <origin xyz="0.0 0.0 0.0" rpy="0.0 0.0 0.0"/>
      <mass value="0.0"/>
      <inertia ixx="0.0" ixy="0.0" ixz="0.0" iyy="0.0" iyz="0.0" izz="0.0"/>
    </inertial>
  </link>
  <joint name="base_link_joint" type="fixed">
    <origin xyz="0.0 0.0 0.0" rpy="0.0 0.0 0.0"/>
    <parent link="root_link"/>
    <child link="base_link"/>
  </joint>
  <link name="base_link">
    <inertial>
      <origin xyz="0.0 0.0 0.0" rpy="0.0 0.0 0.0"/>
      <mass value="0.0"/>
      <inertia ixx="0.0" ixy="0.0" ixz="0.0" iyy="0.0" iyz="0.0" izz="0.0"/>
    </inertial>
  </link>
</robot>