<?xml version="1.0" ?>
<robot name="ur5e" version="1.0">
  <link name="ur5e"/>
  <joint name="base_link_joint" type="fixed">
    <origin xyz="0.0 0.0 0.0" rpy="0.0 -0.0 0.0"/>
    <parent link="ur5e"/>
    <child link="base_link"/>
  </joint>
  <link name="base_link"/>
  <joint name="base_link_inertia_joint" type="fixed">
    <origin xyz="0.0 0.0 0.0" rpy="0.0 -0.0 3.141592653589793"/>
    <parent link="base_link"/>
    <child link="base_link_inertia"/>
  </joint>
  <link name="base_link_inertia">
    <visual name="base">
      <origin xyz="0.0 0.0 0.0" rpy="0.0 -0.0 3.141592653589793"/>
      <geometry>
        <mesh filename="package://multiverse_control/resources/universal_robot/ur5e/meshes/obj/base.obj" scale="1.0000000000000007 1.0000000000000002 1.0"/>
      </geometry>
    </visual>
    <collision name="base">
      <origin xyz="0.0 0.0 0.0" rpy="0.0 -0.0 3.141592653589793"/>
      <geometry>
        <mesh filename="package://multiverse_control/resources/universal_robot/ur5e/meshes/stl/base.stl" scale="1.0000000000000007 1.0000000000000002 1.0"/>
      </geometry>
    </collision>
  </link>
  <joint name="shoulder_pan_joint" type="revolute">
    <origin xyz="0.0 0.0 0.16249999403953552" rpy="0.0 -0.0 0.0"/>
    <axis xyz="0 0 1"/>
    <parent link="base_link_inertia"/>
    <child link="shoulder_link"/>
    <limit effort="1000" lower="0.0" upper="3.141592653589793" velocity="1000"/>
  </joint>
  <link name="shoulder_link">
    <visual name="shoulder">
      <origin xyz="0.0 0.0 0.0" rpy="0.0 -0.0 3.141592653589793"/>
      <geometry>
        <mesh filename="package://multiverse_control/resources/universal_robot/ur5e/meshes/obj/shoulder.obj" scale="1.0000000000000007 1.0000000000000002 1.0"/>
      </geometry>
    </visual>
    <collision name="shoulder">
      <origin xyz="0.0 0.0 0.0" rpy="0.0 -0.0 3.141592653589793"/>
      <geometry>
        <mesh filename="package://multiverse_control/resources/universal_robot/ur5e/meshes/stl/shoulder.stl" scale="1.0000000000000007 1.0000000000000002 1.0"/>
      </geometry>
    </collision>
  </link>
  <joint name="shoulder_lift_joint" type="revolute">
    <origin xyz="0.0 0.0 0.0" rpy="1.5707963267948966 -0.0 0.0"/>
    <axis xyz="0 0 1"/>
    <parent link="shoulder_link"/>
    <child link="upper_arm_link"/>
    <limit effort="1000" lower="-3.141592653589793" upper="0.0" velocity="1000"/>
  </joint>
  <link name="upper_arm_link">
    <visual name="upperarm">
      <origin xyz="0.0 0.0 0.138" rpy="1.5707963267948966 -0.0 -1.5707963267948966"/>
      <geometry>
        <mesh filename="package://multiverse_control/resources/universal_robot/ur5e/meshes/obj/upperarm.obj" scale="1.0 1.0000000000000002 1.0"/>
      </geometry>
    </visual>
    <collision name="upperarm">
      <origin xyz="0.0 0.0 0.138" rpy="1.5707963267948966 -0.0 -1.5707963267948966"/>
      <geometry>
        <mesh filename="package://multiverse_control/resources/universal_robot/ur5e/meshes/stl/upperarm.stl" scale="1.0 1.0000000000000002 1.0"/>
      </geometry>
    </collision>
  </link>
  <joint name="elbow_joint" type="revolute">
    <origin xyz="-0.42500001192092896 0.0 0.0" rpy="0.0 -0.0 0.0"/>
    <axis xyz="0 0 1"/>
    <parent link="upper_arm_link"/>
    <child link="forearm_link"/>
    <limit effort="1000" lower="0.0" upper="2.792526803190927" velocity="1000"/>
  </joint>
  <link name="forearm_link">
    <visual name="forearm">
      <origin xyz="0.0 0.0 0.007" rpy="1.5707963267948966 -0.0 -1.5707963267948966"/>
      <geometry>
        <mesh filename="package://multiverse_control/resources/universal_robot/ur5e/meshes/obj/forearm.obj" scale="1.0 1.0000000000000002 1.0"/>
      </geometry>
    </visual>
    <collision name="forearm">
      <origin xyz="0.0 0.0 0.007" rpy="1.5707963267948966 -0.0 -1.5707963267948966"/>
      <geometry>
        <mesh filename="package://multiverse_control/resources/universal_robot/ur5e/meshes/stl/forearm.stl" scale="1.0 1.0000000000000002 1.0"/>
      </geometry>
    </collision>
  </link>
  <joint name="wrist_1_joint" type="revolute">
    <origin xyz="-0.3921999931335449 0.0 0.13330000638961792" rpy="0.0 -0.0 0.0"/>
    <axis xyz="0 0 1"/>
    <parent link="forearm_link"/>
    <child link="wrist_1_link"/>
    <limit effort="1000" lower="-3.141592653589793" upper="1.3962634015954636" velocity="1000"/>
  </joint>
  <link name="wrist_1_link">
    <collision name="wrist1">
      <origin xyz="0.0 0.0 -0.127" rpy="1.5707963267948966 -0.0 0.0"/>
      <geometry>
        <mesh filename="package://multiverse_control/resources/universal_robot/ur5e/meshes/stl/wrist1.stl" scale="1.0 1.0000000000000002 1.0000000000000002"/>
      </geometry>
    </collision>
    <visual name="wrist1">
      <origin xyz="0.0 0.0 -0.127" rpy="1.5707963267948966 -0.0 0.0"/>
      <geometry>
        <mesh filename="package://multiverse_control/resources/universal_robot/ur5e/meshes/obj/wrist1.obj" scale="1.0 1.0000000000000002 1.0000000000000002"/>
      </geometry>
    </visual>
  </link>
  <joint name="wrist_2_joint" type="revolute">
    <origin xyz="0.0 -0.09969999641180038 -2.0448811047235615e-11" rpy="1.5707963267948966 -0.0 0.0"/>
    <axis xyz="0 0 1"/>
    <parent link="wrist_1_link"/>
    <child link="wrist_2_link"/>
    <limit effort="1000" lower="-0.17453292519943295" upper="6.283185307179586" velocity="1000"/>
  </joint>
  <link name="wrist_2_link">
    <collision name="wrist2">
      <origin xyz="0.0 0.0 -0.0997" rpy="0.0 -0.0 0.0"/>
      <geometry>
        <mesh filename="package://multiverse_control/resources/universal_robot/ur5e/meshes/stl/wrist2.stl" scale="1.0 1.0 1.0"/>
      </geometry>
    </collision>
    <visual name="wrist2">
      <origin xyz="0.0 0.0 -0.0997" rpy="0.0 -0.0 0.0"/>
      <geometry>
        <mesh filename="package://multiverse_control/resources/universal_robot/ur5e/meshes/obj/wrist2.obj" scale="1.0 1.0 1.0"/>
      </geometry>
    </visual>
  </link>
  <joint name="wrist_3_joint" type="revolute">
    <origin xyz="0.0 0.09960000216960907 -2.0428301411579142e-11" rpy="-1.5707963267948966 1.2246468260402848e-16 -1.2246468257891056e-16"/>
    <axis xyz="0 0 1"/>
    <parent link="wrist_2_link"/>
    <child link="wrist_3_link"/>
    <limit effort="1000" lower="-1.5707963267948966" upper="1.5707963267948966" velocity="1000"/>
  </joint>
  <link name="wrist_3_link">
    <visual name="wrist3">
      <origin xyz="0.0 0.0 -0.0989" rpy="1.5707963267948966 -0.0 0.0"/>
      <geometry>
        <mesh filename="package://multiverse_control/resources/universal_robot/ur5e/meshes/obj/wrist3.obj" scale="1.0 1.0000000000000002 1.0000000000000002"/>
      </geometry>
    </visual>
    <collision name="wrist3">
      <origin xyz="0.0 0.0 -0.0989" rpy="1.5707963267948966 -0.0 0.0"/>
      <geometry>
        <mesh filename="package://multiverse_control/resources/universal_robot/ur5e/meshes/stl/wrist3.stl" scale="1.0 1.0000000000000002 1.0000000000000002"/>
      </geometry>
    </collision>
  </link>
  <joint name="flange_joint" type="fixed">
    <origin xyz="0.0 0.0 0.0" rpy="-1.5707963267948966 -1.5707963267948963 0.0"/>
    <parent link="wrist_3_link"/>
    <child link="flange"/>
  </joint>
  <link name="flange"/>
  <joint name="tool0_joint" type="fixed">
    <origin xyz="0.0 0.0 0.0" rpy="1.5707963267948966 -0.0 1.5707963267948966"/>
    <parent link="flange"/>
    <child link="tool0"/>
  </joint>
  <link name="tool0"/>
  <joint name="gripper_hand_e_base_joint" type="fixed">
    <origin xyz="0.0 0.0 0.0" rpy="1.5707963267948966 -0.0 0.0"/>
    <parent link="tool0"/>
    <child link="gripper_hand_e_base"/>
  </joint>
  <link name="gripper_hand_e_base">
    <visual name="robotiq_hand_e_base">
      <origin xyz="0.0 0.0 0.0" rpy="0.0 -0.0 0.0"/>
      <geometry>
        <mesh filename="package://multiverse_control/resources/universal_robot/ur5e/meshes/obj/robotiq_hand_e_base.obj" scale="1.0 1.0 1.0"/>
      </geometry>
    </visual>
    <collision name="gripper_hand_e_base_collision_0">
      <origin xyz="0.0 0.01655 0.0" rpy="1.5707963267948966 -0.0 0.0"/>
      <geometry>
        <cylinder radius="0.0375" length="0.0331"/>
      </geometry>
    </collision>
    <collision name="gripper_hand_e_base_collision_2">
      <origin xyz="0.0 0.062011 0.0" rpy="1.5707963267948966 -0.0 0.0"/>
      <geometry>
        <cylinder radius="0.025" length="0.057822"/>
      </geometry>
    </collision>
    <collision name="gripper_hand_e_base_collision_1">
      <origin xyz="0.0 0.101861 0.0" rpy="1.5707963267948966 -0.0 0.0"/>
      <geometry>
        <cylinder radius="0.0375" length="0.021878"/>
      </geometry>
    </collision>
  </link>
  <joint name="gripper_hand_e_finger_1_joint" type="prismatic">
    <origin xyz="0.0 0.0 0.0" rpy="0.0 -0.0 0.0"/>
    <axis xyz="0 0 -1"/>
    <parent link="gripper_hand_e_base"/>
    <child link="gripper_hand_e_finger_1"/>
    <limit effort="1000" lower="0.0" upper="0.02500000037252903" velocity="1000"/>
  </joint>
  <link name="gripper_hand_e_finger_1">
    <collision name="gripper_hand_e_finger_1_collision_0">
      <origin xyz="0.0 0.13705 0.027498" rpy="0.0 -0.0 0.0"/>
      <geometry>
        <box size="0.02 0.0455 0.006"/>
      </geometry>
    </collision>
    <visual name="robotiq_hand_e_finger_1">
      <origin xyz="0.0 0.0 0.0" rpy="0.0 -0.0 0.0"/>
      <geometry>
        <mesh filename="package://multiverse_control/resources/universal_robot/ur5e/meshes/obj/robotiq_hand_e_finger_1.obj" scale="1.0 1.0 1.0"/>
      </geometry>
    </visual>
  </link>
  <joint name="gripper_hand_e_finger_2_joint" type="prismatic">
    <origin xyz="0.0 0.0 0.0" rpy="0.0 -0.0 0.0"/>
    <axis xyz="0 0 1"/>
    <parent link="gripper_hand_e_base"/>
    <child link="gripper_hand_e_finger_2"/>
    <limit effort="1000" lower="0.0" upper="0.02500000037252903" velocity="1000"/>
  </joint>
  <link name="gripper_hand_e_finger_2">
    <visual name="robotiq_hand_e_finger_2">
      <origin xyz="0.0 0.0 0.0" rpy="0.0 -0.0 0.0"/>
      <geometry>
        <mesh filename="package://multiverse_control/resources/universal_robot/ur5e/meshes/obj/robotiq_hand_e_finger_2.obj" scale="1.0 1.0 1.0"/>
      </geometry>
    </visual>
    <collision name="gripper_hand_e_finger_2_collision_0">
      <origin xyz="0.0 0.13705 -0.028502" rpy="0.0 -0.0 0.0"/>
      <geometry>
        <box size="0.02 0.0455 0.006"/>
      </geometry>
    </collision>
  </link>
  <joint name="base_joint" type="fixed">
    <origin xyz="0.0 0.0 0.0" rpy="0.0 -0.0 3.141592653589793"/>
    <parent link="base_link"/>
    <child link="base"/>
  </joint>
  <link name="base"/>
</robot>