<?xml version="1.0" ?>
<robot name="pr2">
  <joint name="bl_caster_rotation_joint" type="revolute">
    <parent link="base_footprint"/>
    <child link="bl_caster_rotation_link"/>
    <origin xyz="-0.2246  0.2246  0.0792" rpy="0 0 0"/>
    <axis xyz="0 0 1"/>
    <limit lower="-1e+16" upper="1e+16" effort="6.5" velocity="10.0"/>
  </joint>
  <joint name="bl_caster_l_wheel_joint" type="revolute">
    <parent link="bl_caster_rotation_link"/>
    <child link="bl_caster_l_wheel_link"/>
    <origin xyz="0.2246 -0.1756 -0.0792" rpy="0 0 0"/>
    <axis xyz="0 1 0"/>
    <limit lower="-1e+16" upper="1e+16" effort="7.0" velocity="15.0"/>
  </joint>
  <joint name="bl_caster_r_wheel_joint" type="revolute">
    <parent link="bl_caster_rotation_link"/>
    <child link="bl_caster_r_wheel_link"/>
    <origin xyz="0.2246 -0.2736 -0.0792" rpy="0 0 0"/>
    <axis xyz="0 1 0"/>
    <limit lower="-1e+16" upper="1e+16" effort="7.0" velocity="15.0"/>
  </joint>
  <joint name="br_caster_rotation_joint" type="revolute">
    <parent link="base_footprint"/>
    <child link="br_caster_rotation_link"/>
    <origin xyz="-0.2246 -0.2246  0.0792" rpy="0 0 0"/>
    <axis xyz="0 0 1"/>
    <limit lower="-1e+16" upper="1e+16" effort="6.5" velocity="10.0"/>
  </joint>
  <joint name="br_caster_l_wheel_joint" type="revolute">
    <parent link="br_caster_rotation_link"/>
    <child link="br_caster_l_wheel_link"/>
    <origin xyz="0.2246  0.2736 -0.0792" rpy="0 0 0"/>
    <axis xyz="0 1 0"/>
    <limit lower="-1e+16" upper="1e+16" effort="7.0" velocity="15.0"/>
  </joint>
  <joint name="br_caster_r_wheel_joint" type="revolute">
    <parent link="br_caster_rotation_link"/>
    <child link="br_caster_r_wheel_link"/>
    <origin xyz="0.2246  0.1756 -0.0792" rpy="0 0 0"/>
    <axis xyz="0 1 0"/>
    <limit lower="-1e+16" upper="1e+16" effort="7.0" velocity="15.0"/>
  </joint>
  <joint name="fl_caster_rotation_joint" type="revolute">
    <parent link="base_footprint"/>
    <child link="fl_caster_rotation_link"/>
    <origin xyz="0.2246 0.2246 0.0792" rpy="0 0 0"/>
    <axis xyz="0 0 1"/>
    <limit lower="-1e+16" upper="1e+16" effort="6.5" velocity="10.0"/>
  </joint>
  <joint name="fl_caster_l_wheel_joint" type="revolute">
    <parent link="fl_caster_rotation_link"/>
    <child link="fl_caster_l_wheel_link"/>
    <origin xyz="-0.2246 -0.1756 -0.0792" rpy="0 0 0"/>
    <axis xyz="0 1 0"/>
    <limit lower="-1e+16" upper="1e+16" effort="7.0" velocity="15.0"/>
  </joint>
  <joint name="fl_caster_r_wheel_joint" type="revolute">
    <parent link="fl_caster_rotation_link"/>
    <child link="fl_caster_r_wheel_link"/>
    <origin xyz="-0.2246 -0.2736 -0.0792" rpy="0 0 0"/>
    <axis xyz="0 1 0"/>
    <limit lower="-1e+16" upper="1e+16" effort="7.0" velocity="15.0"/>
  </joint>
  <joint name="fr_caster_rotation_joint" type="revolute">
    <parent link="base_footprint"/>
    <child link="fr_caster_rotation_link"/>
    <origin xyz="0.2246 -0.2246  0.0792" rpy="0 0 0"/>
    <axis xyz="0 0 1"/>
    <limit lower="-1e+16" upper="1e+16" effort="6.5" velocity="10.0"/>
  </joint>
  <joint name="fr_caster_l_wheel_joint" type="revolute">
    <parent link="fr_caster_rotation_link"/>
    <child link="fr_caster_l_wheel_link"/>
    <origin xyz="-0.2246  0.2736 -0.0792" rpy="0 0 0"/>
    <axis xyz="0 1 0"/>
    <limit lower="-1e+16" upper="1e+16" effort="7.0" velocity="15.0"/>
  </joint>
  <joint name="fr_caster_r_wheel_joint" type="revolute">
    <parent link="fr_caster_rotation_link"/>
    <child link="fr_caster_r_wheel_link"/>
    <origin xyz="-0.2246  0.1756 -0.0792" rpy="0 0 0"/>
    <axis xyz="0 1 0"/>
    <limit lower="-1e+16" upper="1e+16" effort="7.0" velocity="15.0"/>
  </joint>
  <joint name="torso_lift_joint" type="prismatic">
    <parent link="base_footprint"/>
    <child link="torso_lift_link"/>
    <origin xyz="-0.05     0       0.79067" rpy="0 0 0"/>
    <axis xyz="0 0 1"/>
    <limit lower="0.0" upper="0.33" effort="10000.0" velocity="0.013"/>
  </joint>
  <joint name="head_pan_joint" type="revolute">
    <parent link="torso_lift_link"/>
    <child link="head_pan_link"/>
    <origin xyz="0.03293  0      -0.40922" rpy="0 0 0"/>
    <axis xyz="0 0 1"/>
    <limit lower="-3.007" upper="3.007" effort="2.645" velocity="6.0"/>
  </joint>
  <joint name="head_tilt_joint" type="revolute">
    <parent link="head_pan_link"/>
    <child link="head_tilt_link"/>
    <origin xyz="0.08507  0      -0.38145" rpy="0 0 0"/>
    <axis xyz="0 1 0"/>
    <limit lower="-0.471238" upper="1.39626" effort="18.0" velocity="5.0"/>
  </joint>
  <joint name="l_shoulder_pan_joint" type="revolute">
    <parent link="torso_lift_link"/>
    <child link="l_shoulder_pan_link"/>
    <origin xyz="0.05     0.188   -0.79067" rpy="0 0 0"/>
    <axis xyz="0 0 1"/>
    <limit lower="-0.714602" upper="2.2854" effort="30.0" velocity="2.088"/>
  </joint>
  <joint name="l_shoulder_lift_joint" type="revolute">
    <parent link="l_shoulder_pan_link"/>
    <child link="l_shoulder_lift_link"/>
    <origin xyz="0.1   -0.188  0" rpy="0 0 0"/>
    <axis xyz="0 1 0"/>
    <limit lower="-0.5236" upper="1.3963" effort="30.0" velocity="2.082"/>
  </joint>
  <joint name="l_upper_arm_roll_joint" type="revolute">
    <parent link="l_shoulder_lift_link"/>
    <child link="l_upper_arm_roll_link"/>
    <origin xyz="-0.1  0   0" rpy="0 0 0"/>
    <axis xyz="1 0 0"/>
    <limit lower="-0.8" upper="3.9" effort="30.0" velocity="3.27"/>
  </joint>
  <joint name="l_elbow_flex_joint" type="revolute">
    <parent link="l_upper_arm_roll_link"/>
    <child link="l_elbow_flex_link"/>
    <origin xyz="0.4 0  0" rpy="0 0 0"/>
    <axis xyz="0 1 0"/>
    <limit lower="-2.3213" upper="0.0" effort="30.0" velocity="3.3"/>
  </joint>
  <joint name="l_forearm_roll_joint" type="revolute">
    <parent link="l_elbow_flex_link"/>
    <child link="l_forearm_roll_link"/>
    <origin xyz="-0.4  0   0" rpy="0 0 0"/>
    <axis xyz="1 0 0"/>
    <limit lower="-1e+16" upper="1e+16" effort="30.0" velocity="3.6"/>
  </joint>
  <joint name="l_wrist_flex_joint" type="revolute">
    <parent link="l_forearm_roll_link"/>
    <child link="l_wrist_flex_link"/>
    <origin xyz="0.321 0    0" rpy="0 0 0"/>
    <axis xyz="0 1 0"/>
    <limit lower="-2.18" upper="0.0" effort="10.0" velocity="3.078"/>
  </joint>
  <joint name="l_wrist_roll_joint" type="revolute">
    <parent link="l_wrist_flex_link"/>
    <child link="l_wrist_roll_link"/>
    <origin xyz="-0.321  0     0" rpy="0 0 0"/>
    <axis xyz="1 0 0"/>
    <limit lower="-1e+16" upper="1e+16" effort="10.0" velocity="3.6"/>
  </joint>
  <joint name="l_gripper_l_finger_joint" type="revolute">
    <parent link="l_wrist_roll_link"/>
    <child link="l_gripper_l_finger_link"/>
    <origin xyz="0.01799 -0.021    0" rpy="0 0 0"/>
    <axis xyz="0 0 1"/>
    <limit lower="0.0" upper="0.548" effort="1000.0" velocity="0.5"/>
  </joint>
  <joint name="l_gripper_l_finger_tip_joint" type="revolute">
    <parent link="l_gripper_l_finger_link"/>
    <child link="l_gripper_l_finger_tip_link"/>
    <origin xyz="0.01446 -0.00505  0" rpy="0 0 0"/>
    <axis xyz="0  0 -1"/>
    <limit lower="0.0" upper="0.548" effort="1000.0" velocity="0.5"/>
  </joint>
  <joint name="l_gripper_motor_slider_joint" type="prismatic">
    <parent link="l_wrist_roll_link"/>
    <child link="l_gripper_motor_slider_link"/>
    <origin xyz="0.10937 -0.031    0" rpy="0 0 0"/>
    <axis xyz="1 0 0"/>
    <limit lower="-0.1" upper="0.1" effort="1000.0" velocity="0.2"/>
  </joint>
  <joint name="l_gripper_motor_screw_joint" type="revolute">
    <parent link="l_gripper_motor_slider_link"/>
    <child link="l_gripper_motor_screw_link"/>
    <origin xyz="-0.16828  0       0" rpy="0 0 0"/>
    <axis xyz="0 1 0"/>
    <limit lower="-1e+16" upper="1e+16" effort="0.0" velocity="0.0"/>
  </joint>
  <joint name="l_gripper_r_finger_joint" type="revolute">
    <parent link="l_wrist_roll_link"/>
    <child link="l_gripper_r_finger_link"/>
    <origin xyz="0.01799 -0.041    0" rpy="0 0 0"/>
    <axis xyz="0  0 -1"/>
    <limit lower="0.0" upper="0.548" effort="1000.0" velocity="0.5"/>
  </joint>
  <joint name="l_gripper_r_finger_tip_joint" type="revolute">
    <parent link="l_gripper_r_finger_link"/>
    <child link="l_gripper_r_finger_tip_link"/>
    <origin xyz="0.01446 0.00505 0" rpy="0 0 0"/>
    <axis xyz="0 0 1"/>
    <limit lower="0.0" upper="0.548" effort="1000.0" velocity="0.5"/>
  </joint>
  <joint name="laser_tilt_mount_joint" type="revolute">
    <parent link="torso_lift_link"/>
    <child link="laser_tilt_mount_link"/>
    <origin xyz="0.14893  0      -0.56367" rpy="0 0 0"/>
    <axis xyz="0 1 0"/>
    <limit lower="-0.7854" upper="1.48353" effort="0.65" velocity="10.0"/>
  </joint>
  <joint name="r_shoulder_pan_joint" type="revolute">
    <parent link="torso_lift_link"/>
    <child link="r_shoulder_pan_link"/>
    <origin xyz="0.05    -0.188   -0.79067" rpy="0 0 0"/>
    <axis xyz="0 0 1"/>
    <limit lower="-2.2854" upper="0.714602" effort="30.0" velocity="2.088"/>
  </joint>
  <joint name="r_shoulder_lift_joint" type="revolute">
    <parent link="r_shoulder_pan_link"/>
    <child link="r_shoulder_lift_link"/>
    <origin xyz="0.1   0.188 0" rpy="0 0 0"/>
    <axis xyz="0 1 0"/>
    <limit lower="-0.5236" upper="1.3963" effort="30.0" velocity="2.082"/>
  </joint>
  <joint name="r_upper_arm_roll_joint" type="revolute">
    <parent link="r_shoulder_lift_link"/>
    <child link="r_upper_arm_roll_link"/>
    <origin xyz="-0.1  0   0" rpy="0 0 0"/>
    <axis xyz="1 0 0"/>
    <limit lower="-3.9" upper="0.8" effort="30.0" velocity="3.27"/>
  </joint>
  <joint name="r_elbow_flex_joint" type="revolute">
    <parent link="r_upper_arm_roll_link"/>
    <child link="r_elbow_flex_link"/>
    <origin xyz="0.4 0  0" rpy="0 0 0"/>
    <axis xyz="0 1 0"/>
    <limit lower="-2.3213" upper="0.0" effort="30.0" velocity="3.3"/>
  </joint>
  <joint name="r_forearm_roll_joint" type="revolute">
    <parent link="r_elbow_flex_link"/>
    <child link="r_forearm_roll_link"/>
    <origin xyz="-0.4  0   0" rpy="0 0 0"/>
    <axis xyz="1 0 0"/>
    <limit lower="-1e+16" upper="1e+16" effort="30.0" velocity="3.6"/>
  </joint>
  <joint name="r_wrist_flex_joint" type="revolute">
    <parent link="r_forearm_roll_link"/>
    <child link="r_wrist_flex_link"/>
    <origin xyz="0.321 0    0" rpy="0 0 0"/>
    <axis xyz="0 1 0"/>
    <limit lower="-2.18" upper="0.0" effort="10.0" velocity="3.078"/>
  </joint>
  <joint name="r_wrist_roll_joint" type="revolute">
    <parent link="r_wrist_flex_link"/>
    <child link="r_wrist_roll_link"/>
    <origin xyz="-0.321  0     0" rpy="0 0 0"/>
    <axis xyz="1 0 0"/>
    <limit lower="-1e+16" upper="1e+16" effort="10.0" velocity="3.6"/>
  </joint>
  <joint name="r_gripper_l_finger_joint" type="revolute">
    <parent link="r_wrist_roll_link"/>
    <child link="r_gripper_l_finger_link"/>
    <origin xyz="0.01799 -0.021    0" rpy="0 0 0"/>
    <axis xyz="0 0 1"/>
    <limit lower="0.0" upper="0.548" effort="1000.0" velocity="0.5"/>
  </joint>
  <joint name="r_gripper_l_finger_tip_joint" type="revolute">
    <parent link="r_gripper_l_finger_link"/>
    <child link="r_gripper_l_finger_tip_link"/>
    <origin xyz="0.01446 -0.00505  0" rpy="0 0 0"/>
    <axis xyz="0  0 -1"/>
    <limit lower="0.0" upper="0.548" effort="1000.0" velocity="0.5"/>
  </joint>
  <joint name="r_gripper_motor_slider_joint" type="prismatic">
    <parent link="r_wrist_roll_link"/>
    <child link="r_gripper_motor_slider_link"/>
    <origin xyz="0.10937 -0.031    0" rpy="0 0 0"/>
    <axis xyz="1 0 0"/>
    <limit lower="-0.1" upper="0.1" effort="1000.0" velocity="0.2"/>
  </joint>
  <joint name="r_gripper_motor_screw_joint" type="revolute">
    <parent link="r_gripper_motor_slider_link"/>
    <child link="r_gripper_motor_screw_link"/>
    <origin xyz="-0.16828  0       0" rpy="0 0 0"/>
    <axis xyz="0 1 0"/>
    <limit lower="-1e+16" upper="1e+16" effort="0.0" velocity="0.0"/>
  </joint>
  <joint name="r_gripper_r_finger_joint" type="revolute">
    <parent link="r_wrist_roll_link"/>
    <child link="r_gripper_r_finger_link"/>
    <origin xyz="0.01799 -0.041    0" rpy="0 0 0"/>
    <axis xyz="0  0 -1"/>
    <limit lower="0.0" upper="0.548" effort="1000.0" velocity="0.5"/>
  </joint>
  <joint name="r_gripper_r_finger_tip_joint" type="revolute">
    <parent link="r_gripper_r_finger_link"/>
    <child link="r_gripper_r_finger_tip_link"/>
    <origin xyz="0.01446 0.00505 0" rpy="0 0 0"/>
    <axis xyz="0 0 1"/>
    <limit lower="0.0" upper="0.548" effort="1000.0" velocity="0.5"/>
  </joint>
  <joint name="torso_lift_motor_screw_joint" type="revolute">
    <parent link="base_footprint"/>
    <child link="torso_lift_motor_screw_link"/>
    <origin xyz="-0.15   0     0.751" rpy="0 0 0"/>
    <axis xyz="0 0 1"/>
    <limit lower="-1e+16" upper="1e+16" effort="0.0" velocity="0.0"/>
  </joint>
  <joint name="torso_lift_screw_torso_lift_joint" type="screw">
    <parent link="torso_lift_link"/>
    <child link="torso_lift_motor_screw_link"/>
    <origin xyz="0.05     0      -0.79067" rpy="0 0 0"/>
    <axis xyz="0 0 1"/>
    <limit lower="-1e+16" upper="1e+16" effort="0.0" velocity="0.0"/>
  </joint>
  <joint name="r_gripper_r_screw_screw_joint" type="screw">
    <parent link="r_gripper_r_finger_tip_link"/>
    <child link="r_gripper_motor_screw_link"/>
    <origin xyz="0.01799 0.021   0" rpy="0 0 0"/>
    <axis xyz="0 1 0"/>
    <limit lower="-1e+16" upper="1e+16" effort="0.0" velocity="0.0"/>
  </joint>
  <joint name="r_gripper_l_screw_screw_joint" type="screw">
    <parent link="r_gripper_l_finger_tip_link"/>
    <child link="r_gripper_motor_screw_link"/>
    <origin xyz="0 0 0" rpy="0 0 0"/>
    <axis xyz="0 1 0"/>
    <limit lower="-1e+16" upper="1e+16" effort="0.0" velocity="0.0"/>
  </joint>
  <joint name="r_gripper_r_parallel_root_joint" type="revolute">
    <parent link="r_gripper_r_parallel_link"/>
    <child link="r_wrist_roll_link"/>
    <origin xyz="0.05891 -0.031    0" rpy="0 0 0"/>
    <axis xyz="0  0 -1"/>
    <limit lower="-1e+16" upper="1e+16" effort="0.0" velocity="0.0"/>
  </joint>
  <joint name="r_gripper_l_parallel_root_joint" type="revolute">
    <parent link="r_gripper_l_parallel_link"/>
    <child link="r_wrist_roll_link"/>
    <origin xyz="0.05891 0.031   0" rpy="0 0 0"/>
    <axis xyz="0 0 1"/>
    <limit lower="-1e+16" upper="1e+16" effort="0.0" velocity="0.0"/>
  </joint>
  <joint name="r_gripper_r_parallel_tip_joint" type="revolute">
    <parent link="r_gripper_r_parallel_link"/>
    <child link="r_gripper_r_finger_tip_link"/>
    <origin xyz="-0.01799 -0.021    0" rpy="0 0 0"/>
    <axis xyz="0 0 1"/>
    <limit lower="-1e+16" upper="1e+16" effort="0.0" velocity="0.0"/>
  </joint>
  <joint name="r_gripper_l_parallel_tip_joint" type="revolute">
    <parent link="r_gripper_l_parallel_link"/>
    <child link="r_gripper_l_finger_tip_link"/>
    <origin xyz="-0.01799  0.021    0" rpy="0 0 0"/>
    <axis xyz="0 0 1"/>
    <limit lower="-1e+16" upper="1e+16" effort="0.0" velocity="0.0"/>
  </joint>
  <joint name="r_gripper_joint" type="prismatic">
    <parent link="r_gripper_r_finger_tip_link"/>
    <child link="r_gripper_l_finger_tip_link"/>
    <origin xyz="0.01799 0.021   0" rpy="0 0 0"/>
    <axis xyz="0 1 0"/>
    <limit lower="-1e+16" upper="1e+16" effort="0.0" velocity="0.0"/>
  </joint>
  <joint name="l_gripper_r_screw_screw_joint" type="screw">
    <parent link="l_gripper_r_finger_tip_link"/>
    <child link="l_gripper_motor_screw_link"/>
    <origin xyz="0.01799 0.021   0" rpy="0 0 0"/>
    <axis xyz="0 1 0"/>
    <limit lower="-1e+16" upper="1e+16" effort="0.0" velocity="0.0"/>
  </joint>
  <joint name="l_gripper_l_screw_screw_joint" type="screw">
    <parent link="l_gripper_l_finger_tip_link"/>
    <child link="l_gripper_motor_screw_link"/>
    <origin xyz="0 0 0" rpy="0 0 0"/>
    <axis xyz="0 1 0"/>
    <limit lower="-1e+16" upper="1e+16" effort="0.0" velocity="0.0"/>
  </joint>
  <joint name="l_gripper_r_parallel_root_joint" type="revolute">
    <parent link="l_gripper_r_parallel_link"/>
    <child link="l_wrist_roll_link"/>
    <origin xyz="0.05891 -0.031    0" rpy="0 0 0"/>
    <axis xyz="0  0 -1"/>
    <limit lower="-1e+16" upper="1e+16" effort="0.0" velocity="0.0"/>
  </joint>
  <joint name="l_gripper_l_parallel_root_joint" type="revolute">
    <parent link="l_gripper_l_parallel_link"/>
    <child link="l_wrist_roll_link"/>
    <origin xyz="0.05891 0.031   0" rpy="0 0 0"/>
    <axis xyz="0 0 1"/>
    <limit lower="-1e+16" upper="1e+16" effort="0.0" velocity="0.0"/>
  </joint>
  <joint name="l_gripper_r_parallel_tip_joint" type="revolute">
    <parent link="l_gripper_r_parallel_link"/>
    <child link="l_gripper_r_finger_tip_link"/>
    <origin xyz="-0.01799 -0.021    0" rpy="0 0 0"/>
    <axis xyz="0 0 1"/>
    <limit lower="-1e+16" upper="1e+16" effort="0.0" velocity="0.0"/>
  </joint>
  <joint name="l_gripper_l_parallel_tip_joint" type="revolute">
    <parent link="l_gripper_l_parallel_link"/>
    <child link="l_gripper_l_finger_tip_link"/>
    <origin xyz="-0.01799  0.021    0" rpy="0 0 0"/>
    <axis xyz="0 0 1"/>
    <limit lower="-1e+16" upper="1e+16" effort="0.0" velocity="0.0"/>
  </joint>
  <joint name="l_gripper_joint" type="prismatic">
    <parent link="l_gripper_r_finger_tip_link"/>
    <child link="l_gripper_l_finger_tip_link"/>
    <origin xyz="0.01799 0.021   0" rpy="0 0 0"/>
    <axis xyz="0 1 0"/>
    <limit lower="-1e+16" upper="1e+16" effort="0.0" velocity="0.0"/>
  </joint>
  <link name="base_footprint">
    <inertial>
      <mass value="117.001"/>
      <origin xyz="-0.06295  0       0.20308" rpy="0 0 0"/>
      <inertia ixx="6.08575" ixy="-0.00971993" ixz="1.44233" iyy="6.155" iyz="-0.00737958" izz="3.7454"/>
    </inertial>
    <collision name="base_footprint_collision">
      <origin xyz="0      0      0.07099" rpy="0 0 0"/>
      <geometry>
        <box size="0.001 0.001 0.001"/>
      </geometry>
    </collision>
    <collision name="base_footprint_fixed_joint_lump__base_link_collision_1">
      <origin xyz="0    0    0.051" rpy="0 0 0"/>
      <geometry>
        <mesh filename="package://multiverse_parser/examples/sdf_to_urdf/sdf/pr2/meshes/base_v0/base_L.stl" scale="1 1 1"/>
      </geometry>
    </collision>
    <collision name="base_footprint_fixed_joint_lump__base_bellow_link_collision_2">
      <origin xyz="-0.28999  0       0.851" rpy="0 0 0"/>
      <geometry>
        <box size="0.05 0.37 0.3"/>
      </geometry>
    </collision>
    <visual name="base_footprint_visual">
      <origin xyz="0 0 0" rpy="0 0 0"/>
      <geometry>
        <box size="0.01 0.01 0.01"/>
      </geometry>
    </visual>
    <visual name="base_footprint_fixed_joint_lump__base_link_visual_1">
      <origin xyz="0    0    0.051" rpy="0 0 0"/>
      <geometry>
        <mesh filename="package://multiverse_parser/examples/sdf_to_urdf/sdf/pr2/meshes/base_v0/base.dae" scale="1 1 1"/>
      </geometry>
    </visual>
    <visual name="base_footprint_fixed_joint_lump__base_bellow_link_visual_2">
      <origin xyz="-0.28999  0       0.851" rpy="0 0 0"/>
      <geometry>
        <box size="0.05 0.37 0.3"/>
      </geometry>
    </visual>
  </link>
  <link name="bl_caster_rotation_link">
    <inertial>
      <mass value="3.47308"/>
      <origin xyz="0   0   0.07" rpy="0 0 0"/>
      <inertia ixx="0.0124118" ixy="-0.000711734" ixz="0.00050273" iyy="0.0152182" iyz="-4.27347e-06" izz="0.011764"/>
    </inertial>
    <collision name="bl_caster_rotation_link_collision">
      <origin xyz="0.2246 -0.2246 -0.0792" rpy="0 0 0"/>
      <geometry>
        <mesh filename="package://multiverse_parser/examples/sdf_to_urdf/sdf/pr2/meshes/base_v0/caster_L.stl" scale="1 1 1"/>
      </geometry>
    </collision>
    <visual name="bl_caster_rotation_link_visual">
      <origin xyz="0.2246 -0.2246 -0.0792" rpy="0 0 0"/>
      <geometry>
        <mesh filename="package://multiverse_parser/examples/sdf_to_urdf/sdf/pr2/meshes/base_v0/caster.stl" scale="1 1 1"/>
      </geometry>
    </visual>
  </link>
  <link name="bl_caster_l_wheel_link">
    <inertial>
      <mass value="0.44036"/>
      <origin xyz="0 0 0" rpy="0 0 0"/>
      <inertia ixx="0.0124118" ixy="-0.000711734" ixz="0.00050273" iyy="0.0152182" iyz="-4.27347e-06" izz="0.011764"/>
    </inertial>
    <collision name="bl_caster_l_wheel_link_collision">
      <origin xyz="0    -0.049  0" rpy="1.5708 0     0"/>
      <geometry>
        <cylinder radius="0.074792" length="0.034"/>
      </geometry>
    </collision>
    <visual name="bl_caster_l_wheel_link_visual">
      <origin xyz="0    -0.049  0" rpy="0 0 0"/>
      <geometry>
        <mesh filename="package://multiverse_parser/examples/sdf_to_urdf/sdf/pr2/meshes/base_v0/wheel.dae" scale="1 1 1"/>
      </geometry>
    </visual>
  </link>
  <link name="bl_caster_r_wheel_link">
    <inertial>
      <mass value="0.44036"/>
      <origin xyz="0 0 0" rpy="0 0 0"/>
      <inertia ixx="0.0124118" ixy="-0.000711734" ixz="0.00050273" iyy="0.0152182" iyz="-4.27347e-06" izz="0.011764"/>
    </inertial>
    <collision name="bl_caster_r_wheel_link_collision">
      <origin xyz="0    0.049 0" rpy="1.5708 0     0"/>
      <geometry>
        <cylinder radius="0.074792" length="0.034"/>
      </geometry>
    </collision>
    <visual name="bl_caster_r_wheel_link_visual">
      <origin xyz="0    0.049 0" rpy="0 0 0"/>
      <geometry>
        <mesh filename="package://multiverse_parser/examples/sdf_to_urdf/sdf/pr2/meshes/base_v0/wheel.dae" scale="1 1 1"/>
      </geometry>
    </visual>
  </link>
  <link name="br_caster_rotation_link">
    <inertial>
      <mass value="3.47308"/>
      <origin xyz="0   0   0.07" rpy="0 0 0"/>
      <inertia ixx="0.0124118" ixy="-0.000711734" ixz="0.00050273" iyy="0.0152182" iyz="-4.27347e-06" izz="0.011764"/>
    </inertial>
    <collision name="br_caster_rotation_link_collision">
      <origin xyz="0.2246  0.2246 -0.0792" rpy="0 0 0"/>
      <geometry>
        <mesh filename="package://multiverse_parser/examples/sdf_to_urdf/sdf/pr2/meshes/base_v0/caster_L.stl" scale="1 1 1"/>
      </geometry>
    </collision>
    <visual name="br_caster_rotation_link_visual">
      <origin xyz="0.2246  0.2246 -0.0792" rpy="0 0 0"/>
      <geometry>
        <mesh filename="package://multiverse_parser/examples/sdf_to_urdf/sdf/pr2/meshes/base_v0/caster.stl" scale="1 1 1"/>
      </geometry>
    </visual>
  </link>
  <link name="br_caster_l_wheel_link">
    <inertial>
      <mass value="0.44036"/>
      <origin xyz="0 0 0" rpy="0 0 0"/>
      <inertia ixx="0.0124118" ixy="-0.000711734" ixz="0.00050273" iyy="0.0152182" iyz="-4.27347e-06" izz="0.011764"/>
    </inertial>
    <collision name="br_caster_l_wheel_link_collision">
      <origin xyz="0    -0.049  0" rpy="1.5708 0     0"/>
      <geometry>
        <cylinder radius="0.074792" length="0.034"/>
      </geometry>
    </collision>
    <visual name="br_caster_l_wheel_link_visual">
      <origin xyz="0    -0.049  0" rpy="0 0 0"/>
      <geometry>
        <mesh filename="package://multiverse_parser/examples/sdf_to_urdf/sdf/pr2/meshes/base_v0/wheel.dae" scale="1 1 1"/>
      </geometry>
    </visual>
  </link>
  <link name="br_caster_r_wheel_link">
    <inertial>
      <mass value="0.44036"/>
      <origin xyz="0 0 0" rpy="0 0 0"/>
      <inertia ixx="0.0124118" ixy="-0.000711734" ixz="0.00050273" iyy="0.0152182" iyz="-4.27347e-06" izz="0.011764"/>
    </inertial>
    <collision name="br_caster_r_wheel_link_collision">
      <origin xyz="0    0.049 0" rpy="1.5708 0     0"/>
      <geometry>
        <cylinder radius="0.074792" length="0.034"/>
      </geometry>
    </collision>
    <visual name="br_caster_r_wheel_link_visual">
      <origin xyz="0    0.049 0" rpy="0 0 0"/>
      <geometry>
        <mesh filename="package://multiverse_parser/examples/sdf_to_urdf/sdf/pr2/meshes/base_v0/wheel.dae" scale="1 1 1"/>
      </geometry>
    </visual>
  </link>
  <link name="fl_caster_rotation_link">
    <inertial>
      <mass value="3.47308"/>
      <origin xyz="0   0   0.07" rpy="0 0 0"/>
      <inertia ixx="0.0124118" ixy="-0.000711734" ixz="0.00050273" iyy="0.0152182" iyz="-4.27347e-06" izz="0.011764"/>
    </inertial>
    <collision name="fl_caster_rotation_link_collision">
      <origin xyz="-0.2246 -0.2246 -0.0792" rpy="0 0 0"/>
      <geometry>
        <mesh filename="package://multiverse_parser/examples/sdf_to_urdf/sdf/pr2/meshes/base_v0/caster_L.stl" scale="1 1 1"/>
      </geometry>
    </collision>
    <visual name="fl_caster_rotation_link_visual">
      <origin xyz="-0.2246 -0.2246 -0.0792" rpy="0 0 0"/>
      <geometry>
        <mesh filename="package://multiverse_parser/examples/sdf_to_urdf/sdf/pr2/meshes/base_v0/caster.stl" scale="1 1 1"/>
      </geometry>
    </visual>
  </link>
  <link name="fl_caster_l_wheel_link">
    <inertial>
      <mass value="0.44036"/>
      <origin xyz="0 0 0" rpy="0 0 0"/>
      <inertia ixx="0.0124118" ixy="-0.000711734" ixz="0.00050273" iyy="0.0152182" iyz="-4.27347e-06" izz="0.011764"/>
    </inertial>
    <collision name="fl_caster_l_wheel_link_collision">
      <origin xyz="0    -0.049  0" rpy="1.5708 0     0"/>
      <geometry>
        <cylinder radius="0.074792" length="0.034"/>
      </geometry>
    </collision>
    <visual name="fl_caster_l_wheel_link_visual">
      <origin xyz="0    -0.049  0" rpy="0 0 0"/>
      <geometry>
        <mesh filename="package://multiverse_parser/examples/sdf_to_urdf/sdf/pr2/meshes/base_v0/wheel.dae" scale="1 1 1"/>
      </geometry>
    </visual>
  </link>
  <link name="fl_caster_r_wheel_link">
    <inertial>
      <mass value="0.44036"/>
      <origin xyz="0 0 0" rpy="0 0 0"/>
      <inertia ixx="0.0124118" ixy="-0.000711734" ixz="0.00050273" iyy="0.0152182" iyz="-4.27347e-06" izz="0.011764"/>
    </inertial>
    <collision name="fl_caster_r_wheel_link_collision">
      <origin xyz="0    0.049 0" rpy="1.5708 0     0"/>
      <geometry>
        <cylinder radius="0.074792" length="0.034"/>
      </geometry>
    </collision>
    <visual name="fl_caster_r_wheel_link_visual">
      <origin xyz="0    0.049 0" rpy="0 0 0"/>
      <geometry>
        <mesh filename="package://multiverse_parser/examples/sdf_to_urdf/sdf/pr2/meshes/base_v0/wheel.dae" scale="1 1 1"/>
      </geometry>
    </visual>
  </link>
  <link name="fr_caster_rotation_link">
    <inertial>
      <mass value="3.47308"/>
      <origin xyz="0   0   0.07" rpy="0 0 0"/>
      <inertia ixx="0.0124118" ixy="-0.000711734" ixz="0.00050273" iyy="0.0152182" iyz="-4.27347e-06" izz="0.011764"/>
    </inertial>
    <collision name="fr_caster_rotation_link_collision">
      <origin xyz="-0.2246  0.2246 -0.0792" rpy="0 0 0"/>
      <geometry>
        <mesh filename="package://multiverse_parser/examples/sdf_to_urdf/sdf/pr2/meshes/base_v0/caster_L.stl" scale="1 1 1"/>
      </geometry>
    </collision>
    <visual name="fr_caster_rotation_link_visual">
      <origin xyz="-0.2246  0.2246 -0.0792" rpy="0 0 0"/>
      <geometry>
        <mesh filename="package://multiverse_parser/examples/sdf_to_urdf/sdf/pr2/meshes/base_v0/caster.stl" scale="1 1 1"/>
      </geometry>
    </visual>
  </link>
  <link name="fr_caster_l_wheel_link">
    <inertial>
      <mass value="0.44036"/>
      <origin xyz="0 0 0" rpy="0 0 0"/>
      <inertia ixx="0.0124118" ixy="-0.000711734" ixz="0.00050273" iyy="0.0152182" iyz="-4.27347e-06" izz="0.011764"/>
    </inertial>
    <collision name="fr_caster_l_wheel_link_collision">
      <origin xyz="0    -0.049  0" rpy="1.5708 0     0"/>
      <geometry>
        <cylinder radius="0.074792" length="0.034"/>
      </geometry>
    </collision>
    <visual name="fr_caster_l_wheel_link_visual">
      <origin xyz="0    -0.049  0" rpy="0 0 0"/>
      <geometry>
        <mesh filename="package://multiverse_parser/examples/sdf_to_urdf/sdf/pr2/meshes/base_v0/wheel.dae" scale="1 1 1"/>
      </geometry>
    </visual>
  </link>
  <link name="fr_caster_r_wheel_link">
    <inertial>
      <mass value="0.44036"/>
      <origin xyz="0 0 0" rpy="0 0 0"/>
      <inertia ixx="0.0124118" ixy="-0.000711734" ixz="0.00050273" iyy="0.0152182" iyz="-4.27347e-06" izz="0.011764"/>
    </inertial>
    <collision name="fr_caster_r_wheel_link_collision">
      <origin xyz="0    0.049 0" rpy="1.5708 0     0"/>
      <geometry>
        <cylinder radius="0.074792" length="0.034"/>
      </geometry>
    </collision>
    <visual name="fr_caster_r_wheel_link_visual">
      <origin xyz="0    0.049 0" rpy="0 0 0"/>
      <geometry>
        <mesh filename="package://multiverse_parser/examples/sdf_to_urdf/sdf/pr2/meshes/base_v0/wheel.dae" scale="1 1 1"/>
      </geometry>
    </visual>
  </link>
  <link name="torso_lift_link">
    <inertial>
      <mass value="36.449"/>
      <origin xyz="-0.09949  0      -0.08676" rpy="0 0 0"/>
      <inertia ixx="2.80235" ixy="0.00429496" ixz="-0.16614" iyy="2.53349" iyz="0.029702" izz="0.538967"/>
    </inertial>
    <collision name="torso_lift_link_fixed_joint_lump__torso_lift_collision_collision">
      <origin xyz="0.05     0      -0.79067" rpy="0 0 0"/>
      <geometry>
        <mesh filename="package://multiverse_parser/examples/sdf_to_urdf/sdf/pr2/meshes/torso_v0/torso_lift_L.stl" scale="1 1 1"/>
      </geometry>
    </collision>
    <visual name="torso_lift_link_visual">
      <origin xyz="0.05     0      -0.79067" rpy="0 0 0"/>
      <geometry>
        <mesh filename="package://multiverse_parser/examples/sdf_to_urdf/sdf/pr2/meshes/torso_v0/torso_lift.dae" scale="1 1 1"/>
      </geometry>
    </visual>
  </link>
  <link name="head_pan_link">
    <inertial>
      <mass value="6.339"/>
      <origin xyz="0.0109  0.03169 0.0905" rpy="0 0 0"/>
      <inertia ixx="0.0324976" ixy="0.000636041" ixz="0.00258515" iyy="0.0465456" iyz="-0.00245343" izz="0.0576527"/>
    </inertial>
    <collision name="head_pan_link_collision">
      <origin xyz="0.01706  0      -0.38145" rpy="0 0 0"/>
      <geometry>
        <mesh filename="package://multiverse_parser/examples/sdf_to_urdf/sdf/pr2/meshes/head_v0/head_pan_L.stl" scale="1 1 1"/>
      </geometry>
    </collision>
    <visual name="head_pan_link_visual">
      <origin xyz="0.01706  0      -0.38145" rpy="0 0 0"/>
      <geometry>
        <mesh filename="package://multiverse_parser/examples/sdf_to_urdf/sdf/pr2/meshes/head_v0/head_pan.dae" scale="1 1 1"/>
      </geometry>
    </visual>
  </link>
  <link name="head_tilt_link">
    <inertial>
      <mass value="4.919"/>
      <origin xyz="0.00602 -0.01597  0.05874" rpy="0 0 0"/>
      <inertia ixx="0.057667" ixy="-0.000213944" ixz="-0.00111597" iyy="0.0878306" iyz="0.00196687" izz="0.118933"/>
    </inertial>
    <collision name="head_tilt_link_collision">
      <origin xyz="-0.068  0     0" rpy="0 0 0"/>
      <geometry>
        <mesh filename="package://multiverse_parser/examples/sdf_to_urdf/sdf/pr2/meshes/head_v0/head_tilt_L.stl" scale="1 1 1"/>
      </geometry>
    </collision>
    <collision name="head_tilt_link_fixed_joint_lump__head_plate_frame_collision_1">
      <origin xyz="-0.0448  0      0.0645" rpy="0 0 0"/>
      <geometry>
        <box size="0.01 0.01 0.01"/>
      </geometry>
    </collision>
    <visual name="head_tilt_link_visual">
      <origin xyz="-0.068  0     0" rpy="0 0 0"/>
      <geometry>
        <mesh filename="package://multiverse_parser/examples/sdf_to_urdf/sdf/pr2/meshes/head_v0/head_tilt.dae" scale="1 1 1"/>
      </geometry>
    </visual>
    <visual name="head_tilt_link_fixed_joint_lump__head_plate_frame_visual_1">
      <origin xyz="-0.0448  0      0.0645" rpy="0 0 0"/>
      <geometry>
        <box size="0.01 0.01 0.01"/>
      </geometry>
    </visual>
  </link>
  <link name="l_shoulder_pan_link">
    <inertial>
      <mass value="25.7993"/>
      <origin xyz="-0.0012   0.02451 -0.09823" rpy="0 0 0"/>
      <inertia ixx="0.866179" ixy="-0.0608651" ixz="-0.121181" iyy="0.874217" iyz="-0.0588661" izz="0.273538"/>
    </inertial>
    <collision name="l_shoulder_pan_link_collision">
      <origin xyz="0    -0.188  0" rpy="0 0 0"/>
      <geometry>
        <mesh filename="package://multiverse_parser/examples/sdf_to_urdf/sdf/pr2/meshes/shoulder_v0/shoulder_pan.stl" scale="1 1 1"/>
      </geometry>
    </collision>
    <visual name="l_shoulder_pan_link_visual">
      <origin xyz="0    -0.188  0" rpy="0 0 0"/>
      <geometry>
        <mesh filename="package://multiverse_parser/examples/sdf_to_urdf/sdf/pr2/meshes/shoulder_v0/shoulder_pan.dae" scale="1 1 1"/>
      </geometry>
    </visual>
  </link>
  <link name="l_shoulder_lift_link">
    <inertial>
      <mass value="2.74988"/>
      <origin xyz="0.02195 -0.02664 -0.03127" rpy="0 0 0"/>
      <inertia ixx="0.0210558" ixy="0.00496704" ixz="-0.00194809" iyy="0.0212722" iyz="0.00110425" izz="0.0197575"/>
    </inertial>
    <collision name="l_shoulder_lift_link_collision">
      <origin xyz="-0.1  0   0" rpy="0 0 0"/>
      <geometry>
        <mesh filename="package://multiverse_parser/examples/sdf_to_urdf/sdf/pr2/meshes/shoulder_v0/shoulder_lift.stl" scale="1 1 1"/>
      </geometry>
    </collision>
    <visual name="l_shoulder_lift_link_visual">
      <origin xyz="-0.1  0   0" rpy="0 0 0"/>
      <geometry>
        <mesh filename="package://multiverse_parser/examples/sdf_to_urdf/sdf/pr2/meshes/shoulder_v0/shoulder_lift.dae" scale="1 1 1"/>
      </geometry>
    </visual>
  </link>
  <link name="l_upper_arm_roll_link">
    <inertial>
      <mass value="6.11769"/>
      <origin xyz="0.21055  0.0163  -0.00056" rpy="0 0 0"/>
      <inertia ixx="0.0253331" ixy="-0.00374234" ixz="0.000619656" iyy="0.0892438" iyz="-0.000198608" izz="0.0905498"/>
    </inertial>
    <collision name="l_upper_arm_roll_link_collision">
      <origin xyz="0 0 0" rpy="0 0 0"/>
      <geometry>
        <mesh filename="package://multiverse_parser/examples/sdf_to_urdf/sdf/pr2/meshes/shoulder_v0/upper_arm_roll_L.stl" scale="1 1 1"/>
      </geometry>
    </collision>
    <collision name="l_upper_arm_roll_link_fixed_joint_lump__l_upper_arm_link_collision_1">
      <origin xyz="0 0 0" rpy="0 0 0"/>
      <geometry>
        <mesh filename="package://multiverse_parser/examples/sdf_to_urdf/sdf/pr2/meshes/upper_arm_v0/upper_arm.stl" scale="1 1 1"/>
      </geometry>
    </collision>
    <visual name="l_upper_arm_roll_link_visual">
      <origin xyz="0 0 0" rpy="0 0 0"/>
      <geometry>
        <mesh filename="package://multiverse_parser/examples/sdf_to_urdf/sdf/pr2/meshes/shoulder_v0/upper_arm_roll.stl" scale="1 1 1"/>
      </geometry>
    </visual>
    <visual name="l_upper_arm_roll_link_fixed_joint_lump__l_upper_arm_link_visual_1">
      <origin xyz="0 0 0" rpy="0 0 0"/>
      <geometry>
        <mesh filename="package://multiverse_parser/examples/sdf_to_urdf/sdf/pr2/meshes/upper_arm_v0/upper_arm.dae" scale="1 1 1"/>
      </geometry>
    </visual>
  </link>
  <link name="l_elbow_flex_link">
    <inertial>
      <mass value="1.90327"/>
      <origin xyz="0.01014  0.00032 -0.01211" rpy="0 0 0"/>
      <inertia ixx="0.00346542" ixy="4.06683e-05" ixz="0.000431716" iyy="0.00441606" iyz="-3.96891e-05" izz="0.00359157"/>
    </inertial>
    <collision name="l_elbow_flex_link_collision">
      <origin xyz="-0.4  0   0" rpy="0 0 0"/>
      <geometry>
        <mesh filename="package://multiverse_parser/examples/sdf_to_urdf/sdf/pr2/meshes/upper_arm_v0/elbow_flex.stl" scale="1 1 1"/>
      </geometry>
    </collision>
    <visual name="l_elbow_flex_link_visual">
      <origin xyz="-0.4  0   0" rpy="0 0 0"/>
      <geometry>
        <mesh filename="package://multiverse_parser/examples/sdf_to_urdf/sdf/pr2/meshes/upper_arm_v0/elbow_flex.dae" scale="1 1 1"/>
      </geometry>
    </visual>
  </link>
  <link name="l_forearm_roll_link">
    <inertial>
      <mass value="2.68968"/>
      <origin xyz="1.8072e-01 -1.6000e-04 -8.5800e-03" rpy="0 0 0"/>
      <inertia ixx="0.0146843" ixy="5.53089e-05" ixz="0.000904462" iyy="0.0295334" iyz="-1.3343e-05" izz="0.0310133"/>
    </inertial>
    <collision name="l_forearm_roll_link_collision">
      <origin xyz="0 0 0" rpy="0 0 0"/>
      <geometry>
        <mesh filename="package://multiverse_parser/examples/sdf_to_urdf/sdf/pr2/meshes/upper_arm_v0/forearm_roll_L.stl" scale="1 1 1"/>
      </geometry>
    </collision>
    <collision name="l_forearm_roll_link_fixed_joint_lump__l_forearm_link_collision_1">
      <origin xyz="0 0 0" rpy="0 0 0"/>
      <geometry>
        <mesh filename="package://multiverse_parser/examples/sdf_to_urdf/sdf/pr2/meshes/forearm_v0/forearm.stl" scale="1 1 1"/>
      </geometry>
    </collision>
    <visual name="l_forearm_roll_link_visual">
      <origin xyz="0 0 0" rpy="0 0 0"/>
      <geometry>
        <mesh filename="package://multiverse_parser/examples/sdf_to_urdf/sdf/pr2/meshes/upper_arm_v0/forearm_roll.stl" scale="1 1 1"/>
      </geometry>
    </visual>
    <visual name="l_forearm_roll_link_fixed_joint_lump__l_forearm_link_visual_1">
      <origin xyz="0 0 0" rpy="0 0 0"/>
      <geometry>
        <mesh filename="package://multiverse_parser/examples/sdf_to_urdf/sdf/pr2/meshes/forearm_v0/forearm.dae" scale="1 1 1"/>
      </geometry>
    </visual>
  </link>
  <link name="l_wrist_flex_link">
    <inertial>
      <mass value="0.61402"/>
      <origin xyz="-0.00157  0      -0.00075" rpy="0 0 0"/>
      <inertia ixx="0.000651657" ixy="2.8864e-07" ixz="3.03477e-06" iyy="0.000198244" iyz="-2.2645e-07" izz="0.000644505"/>
    </inertial>
    <collision name="l_wrist_flex_link_collision">
      <origin xyz="-0.321  0     0" rpy="0 0 0"/>
      <geometry>
        <mesh filename="package://multiverse_parser/examples/sdf_to_urdf/sdf/pr2/meshes/forearm_v0/wrist_flex.stl" scale="1 1 1"/>
      </geometry>
    </collision>
    <visual name="l_wrist_flex_link_visual">
      <origin xyz="-0.321  0     0" rpy="0 0 0"/>
      <geometry>
        <mesh filename="package://multiverse_parser/examples/sdf_to_urdf/sdf/pr2/meshes/forearm_v0/wrist_flex.dae" scale="1 1 1"/>
      </geometry>
    </visual>
  </link>
  <link name="l_wrist_roll_link">
    <inertial>
      <mass value="0.68107"/>
      <origin xyz="0.0564   0.00045 -0.00101" rpy="0 0 0"/>
      <inertia ixx="0.0113524" ixy="-1.88243e-05" ixz="5.86222e-06" iyy="0.0120549" iyz="-5.41286e-07" izz="0.012243"/>
    </inertial>
    <collision name="l_wrist_roll_link_collision">
      <origin xyz="-0.05891 -0.031    0" rpy="0 0 0"/>
      <geometry>
        <mesh filename="package://multiverse_parser/examples/sdf_to_urdf/sdf/pr2/meshes/forearm_v0/wrist_roll_L.stl" scale="1 1 1"/>
      </geometry>
    </collision>
    <collision name="l_wrist_roll_link_fixed_joint_lump__l_gripper_palm_link_collision_1">
      <origin xyz="-0.05891 -0.031    0" rpy="0 0 0"/>
      <geometry>
        <mesh filename="package://multiverse_parser/examples/sdf_to_urdf/sdf/pr2/meshes/gripper_v0/gripper_palm.stl" scale="1 1 1"/>
      </geometry>
    </collision>
    <collision name="l_wrist_roll_link_fixed_joint_lump__l_gripper_motor_accelerometer_link_collision_2">
      <origin xyz="-0.05891 -0.031    0" rpy="0 0 0"/>
      <geometry>
        <box size="0.001 0.001 0.001"/>
      </geometry>
    </collision>
    <visual name="l_wrist_roll_link_visual">
      <origin xyz="-0.05891 -0.031    0" rpy="0 0 0"/>
      <geometry>
        <mesh filename="package://multiverse_parser/examples/sdf_to_urdf/sdf/pr2/meshes/forearm_v0/wrist_roll.stl" scale="1 1 1"/>
      </geometry>
    </visual>
    <visual name="l_wrist_roll_link_fixed_joint_lump__l_gripper_palm_link_visual_1">
      <origin xyz="-0.05891 -0.031    0" rpy="0 0 0"/>
      <geometry>
        <mesh filename="package://multiverse_parser/examples/sdf_to_urdf/sdf/pr2/meshes/gripper_v0/gripper_palm.dae" scale="1 1 1"/>
      </geometry>
    </visual>
    <visual name="l_wrist_roll_link_fixed_joint_lump__l_gripper_motor_accelerometer_link_visual_2">
      <origin xyz="-0.05891 -0.031    0" rpy="0 0 0"/>
      <geometry>
        <box size="0.001 0.001 0.001"/>
      </geometry>
    </visual>
  </link>
  <link name="l_gripper_l_finger_link">
    <inertial>
      <mass value="0.17126"/>
      <origin xyz="0.03598  0.0173  -0.00164" rpy="0 0 0"/>
      <inertia ixx="7.7562e-05" ixy="1.49095e-06" ixz="-9.83385e-06" iyy="0.000197083" iyz="-3.06125e-06" izz="0.000181054"/>
    </inertial>
    <collision name="l_gripper_l_finger_link_collision">
      <origin xyz="-0.07691 -0.01     0" rpy="0 0 0"/>
      <geometry>
        <mesh filename="package://multiverse_parser/examples/sdf_to_urdf/sdf/pr2/meshes/gripper_v0/l_finger.stl" scale="1 1 1"/>
      </geometry>
    </collision>
    <visual name="l_gripper_l_finger_link_visual">
      <origin xyz="-0.07691 -0.01     0" rpy="0 0 0"/>
      <geometry>
        <mesh filename="package://multiverse_parser/examples/sdf_to_urdf/sdf/pr2/meshes/gripper_v0/l_finger.dae" scale="1 1 1"/>
      </geometry>
    </visual>
  </link>
  <link name="l_gripper_l_finger_tip_link">
    <inertial>
      <mass value="0.04419"/>
      <origin xyz="0.00423 0.00284 0" rpy="0 0 0"/>
      <inertia ixx="8.37047e-06" ixy="5.83632e-06" ixz="0" iyy="9.87067e-06" iyz="0" izz="1.54177e-05"/>
    </inertial>
    <collision name="l_gripper_l_finger_tip_link_collision">
      <origin xyz="0 0 0" rpy="0 0 0"/>
      <geometry>
        <mesh filename="package://multiverse_parser/examples/sdf_to_urdf/sdf/pr2/meshes/gripper_v0/l_finger_tip.stl" scale="1 1 1"/>
      </geometry>
    </collision>
    <visual name="l_gripper_l_finger_tip_link_visual">
      <origin xyz="0 0 0" rpy="0 0 0"/>
      <geometry>
        <mesh filename="package://multiverse_parser/examples/sdf_to_urdf/sdf/pr2/meshes/gripper_v0/l_finger_tip.dae" scale="1 1 1"/>
      </geometry>
    </visual>
  </link>
  <link name="l_gripper_motor_slider_link">
    <inertial>
      <mass value="0.01"/>
      <origin xyz="0 0 0" rpy="0 0 0"/>
      <inertia ixx="0.001" ixy="0" ixz="0" iyy="0.001" iyz="0" izz="0.001"/>
    </inertial>
  </link>
  <link name="l_gripper_motor_screw_link">
    <inertial>
      <mass value="0.01"/>
      <origin xyz="0 0 0" rpy="0 0 0"/>
      <inertia ixx="0.0001" ixy="0" ixz="0" iyy="0.0001" iyz="0" izz="0.0001"/>
    </inertial>
  </link>
  <link name="l_gripper_r_finger_link">
    <inertial>
      <mass value="0.17389"/>
      <origin xyz="0.03576 -0.01736 -0.00095" rpy="0 0 0"/>
      <inertia ixx="7.73841e-05" ixy="-2.09309e-06" ixz="-8.36228e-06" iyy="0.000198474" iyz="2.4611e-06" izz="0.00018107"/>
    </inertial>
    <collision name="l_gripper_r_finger_link_collision">
      <origin xyz="-0.07691  0.01     0" rpy="3.14159 0      0"/>
      <geometry>
        <mesh filename="package://multiverse_parser/examples/sdf_to_urdf/sdf/pr2/meshes/gripper_v0/l_finger.stl" scale="1 1 1"/>
      </geometry>
    </collision>
    <visual name="l_gripper_r_finger_link_visual">
      <origin xyz="-0.07691  0.01     0" rpy="3.14159 0      0"/>
      <geometry>
        <mesh filename="package://multiverse_parser/examples/sdf_to_urdf/sdf/pr2/meshes/gripper_v0/l_finger.dae" scale="1 1 1"/>
      </geometry>
    </visual>
  </link>
  <link name="l_gripper_r_finger_tip_link">
    <inertial>
      <mass value="0.04419"/>
      <origin xyz="0.00423 -0.00284  0" rpy="0 0 0"/>
      <inertia ixx="8.37047e-06" ixy="-5.83632e-06" ixz="0" iyy="9.87067e-06" iyz="0" izz="1.54177e-05"/>
    </inertial>
    <collision name="l_gripper_r_finger_tip_link_collision">
      <origin xyz="0.01799 0.021   0" rpy="3.14159 0      0"/>
      <geometry>
        <mesh filename="package://multiverse_parser/examples/sdf_to_urdf/sdf/pr2/meshes/gripper_v0/l_finger_tip.stl" scale="1 1 1"/>
      </geometry>
    </collision>
    <visual name="l_gripper_r_finger_tip_link_visual">
      <origin xyz="0.01799 0.021   0" rpy="3.14159 0      0"/>
      <geometry>
        <mesh filename="package://multiverse_parser/examples/sdf_to_urdf/sdf/pr2/meshes/gripper_v0/l_finger_tip.dae" scale="1 1 1"/>
      </geometry>
    </visual>
  </link>
  <link name="laser_tilt_mount_link">
    <inertial>
      <mass value="0.592"/>
      <origin xyz="-0.00113  0.00166 -0.00706" rpy="0 0 0"/>
      <inertia ixx="0.00129665" ixy="2.30889e-05" ixz="3.74249e-05" iyy="0.00108633" iyz="3.49679e-05" izz="0.000895018"/>
    </inertial>
    <collision name="laser_tilt_mount_link_collision">
      <origin xyz="-0.09893  0      -0.227" rpy="0 0 0"/>
      <geometry>
        <mesh filename="package://multiverse_parser/examples/sdf_to_urdf/sdf/pr2/meshes/tilting_laser_v0/tilting_hokuyo_L.stl" scale="1 1 1"/>
      </geometry>
    </collision>
    <visual name="laser_tilt_mount_link_visual">
      <origin xyz="-0.09893  0      -0.227" rpy="0 0 0"/>
      <geometry>
        <mesh filename="package://multiverse_parser/examples/sdf_to_urdf/sdf/pr2/meshes/tilting_laser_v0/tilting_hokuyo.dae" scale="1 1 1"/>
      </geometry>
    </visual>
  </link>
  <link name="r_shoulder_pan_link">
    <inertial>
      <mass value="25.7993"/>
      <origin xyz="-0.0012   0.02451 -0.09823" rpy="0 0 0"/>
      <inertia ixx="0.866179" ixy="-0.0608651" ixz="-0.121181" iyy="0.874217" iyz="-0.0588661" izz="0.273538"/>
    </inertial>
    <collision name="r_shoulder_pan_link_collision">
      <origin xyz="0    0.188 0" rpy="0 0 0"/>
      <geometry>
        <mesh filename="package://multiverse_parser/examples/sdf_to_urdf/sdf/pr2/meshes/shoulder_v0/shoulder_pan.stl" scale="1 1 1"/>
      </geometry>
    </collision>
    <visual name="r_shoulder_pan_link_visual">
      <origin xyz="0    0.188 0" rpy="0 0 0"/>
      <geometry>
        <mesh filename="package://multiverse_parser/examples/sdf_to_urdf/sdf/pr2/meshes/shoulder_v0/shoulder_pan.dae" scale="1 1 1"/>
      </geometry>
    </visual>
  </link>
  <link name="r_shoulder_lift_link">
    <inertial>
      <mass value="2.74988"/>
      <origin xyz="0.02195 -0.02664 -0.03127" rpy="0 0 0"/>
      <inertia ixx="0.0210558" ixy="0.00496704" ixz="-0.00194809" iyy="0.0212722" iyz="0.00110425" izz="0.0197575"/>
    </inertial>
    <collision name="r_shoulder_lift_link_collision">
      <origin xyz="-0.1  0   0" rpy="0 0 0"/>
      <geometry>
        <mesh filename="package://multiverse_parser/examples/sdf_to_urdf/sdf/pr2/meshes/shoulder_v0/shoulder_lift.stl" scale="1 1 1"/>
      </geometry>
    </collision>
    <visual name="r_shoulder_lift_link_visual">
      <origin xyz="-0.1  0   0" rpy="0 0 0"/>
      <geometry>
        <mesh filename="package://multiverse_parser/examples/sdf_to_urdf/sdf/pr2/meshes/shoulder_v0/shoulder_lift.dae" scale="1 1 1"/>
      </geometry>
    </visual>
  </link>
  <link name="r_upper_arm_roll_link">
    <inertial>
      <mass value="6.11769"/>
      <origin xyz="2.1048e-01 -1.5940e-02 -1.9000e-04" rpy="0 0 0"/>
      <inertia ixx="0.0254033" ixy="0.0040983" ixz="-0.000704319" iyy="0.0892406" iyz="-0.000179683" izz="0.0906174"/>
    </inertial>
    <collision name="r_upper_arm_roll_link_collision">
      <origin xyz="0 0 0" rpy="0 0 0"/>
      <geometry>
        <mesh filename="package://multiverse_parser/examples/sdf_to_urdf/sdf/pr2/meshes/shoulder_v0/upper_arm_roll_L.stl" scale="1 1 1"/>
      </geometry>
    </collision>
    <collision name="r_upper_arm_roll_link_fixed_joint_lump__r_upper_arm_link_collision_1">
      <origin xyz="0 0 0" rpy="0 0 0"/>
      <geometry>
        <mesh filename="package://multiverse_parser/examples/sdf_to_urdf/sdf/pr2/meshes/upper_arm_v0/upper_arm.stl" scale="1 1 1"/>
      </geometry>
    </collision>
    <visual name="r_upper_arm_roll_link_visual">
      <origin xyz="0 0 0" rpy="0 0 0"/>
      <geometry>
        <mesh filename="package://multiverse_parser/examples/sdf_to_urdf/sdf/pr2/meshes/shoulder_v0/upper_arm_roll.stl" scale="1 1 1"/>
      </geometry>
    </visual>
    <visual name="r_upper_arm_roll_link_fixed_joint_lump__r_upper_arm_link_visual_1">
      <origin xyz="0 0 0" rpy="0 0 0"/>
      <geometry>
        <mesh filename="package://multiverse_parser/examples/sdf_to_urdf/sdf/pr2/meshes/upper_arm_v0/upper_arm.dae" scale="1 1 1"/>
      </geometry>
    </visual>
  </link>
  <link name="r_elbow_flex_link">
    <inertial>
      <mass value="1.90327"/>
      <origin xyz="0.01014  0.00032 -0.01211" rpy="0 0 0"/>
      <inertia ixx="0.00346542" ixy="4.06683e-05" ixz="0.000431716" iyy="0.00441606" iyz="-3.96891e-05" izz="0.00359157"/>
    </inertial>
    <collision name="r_elbow_flex_link_collision">
      <origin xyz="-0.4  0   0" rpy="0 0 0"/>
      <geometry>
        <mesh filename="package://multiverse_parser/examples/sdf_to_urdf/sdf/pr2/meshes/upper_arm_v0/elbow_flex.stl" scale="1 1 1"/>
      </geometry>
    </collision>
    <visual name="r_elbow_flex_link_visual">
      <origin xyz="-0.4  0   0" rpy="0 0 0"/>
      <geometry>
        <mesh filename="package://multiverse_parser/examples/sdf_to_urdf/sdf/pr2/meshes/upper_arm_v0/elbow_flex.dae" scale="1 1 1"/>
      </geometry>
    </visual>
  </link>
  <link name="r_forearm_roll_link">
    <inertial>
      <mass value="2.68968"/>
      <origin xyz="1.8072e-01 -1.6000e-04 -8.5800e-03" rpy="0 0 0"/>
      <inertia ixx="0.0146843" ixy="5.53089e-05" ixz="0.000904462" iyy="0.0295334" iyz="-1.3343e-05" izz="0.0310133"/>
    </inertial>
    <collision name="r_forearm_roll_link_collision">
      <origin xyz="0 0 0" rpy="0 0 0"/>
      <geometry>
        <mesh filename="package://multiverse_parser/examples/sdf_to_urdf/sdf/pr2/meshes/upper_arm_v0/forearm_roll_L.stl" scale="1 1 1"/>
      </geometry>
    </collision>
    <collision name="r_forearm_roll_link_fixed_joint_lump__r_forearm_link_collision_1">
      <origin xyz="0 0 0" rpy="0 0 0"/>
      <geometry>
        <mesh filename="package://multiverse_parser/examples/sdf_to_urdf/sdf/pr2/meshes/forearm_v0/forearm.stl" scale="1 1 1"/>
      </geometry>
    </collision>
    <visual name="r_forearm_roll_link_visual">
      <origin xyz="0 0 0" rpy="0 0 0"/>
      <geometry>
        <mesh filename="package://multiverse_parser/examples/sdf_to_urdf/sdf/pr2/meshes/upper_arm_v0/forearm_roll.stl" scale="1 1 1"/>
      </geometry>
    </visual>
    <visual name="r_forearm_roll_link_fixed_joint_lump__r_forearm_link_visual_1">
      <origin xyz="0 0 0" rpy="0 0 0"/>
      <geometry>
        <mesh filename="package://multiverse_parser/examples/sdf_to_urdf/sdf/pr2/meshes/forearm_v0/forearm.dae" scale="1 1 1"/>
      </geometry>
    </visual>
  </link>
  <link name="r_wrist_flex_link">
    <inertial>
      <mass value="0.61402"/>
      <origin xyz="-0.00157  0      -0.00075" rpy="0 0 0"/>
      <inertia ixx="0.000651657" ixy="2.8864e-07" ixz="3.03477e-06" iyy="0.000198244" iyz="-2.2645e-07" izz="0.000644505"/>
    </inertial>
    <collision name="r_wrist_flex_link_collision">
      <origin xyz="-0.321  0     0" rpy="0 0 0"/>
      <geometry>
        <mesh filename="package://multiverse_parser/examples/sdf_to_urdf/sdf/pr2/meshes/forearm_v0/wrist_flex.stl" scale="1 1 1"/>
      </geometry>
    </collision>
    <visual name="r_wrist_flex_link_visual">
      <origin xyz="-0.321  0     0" rpy="0 0 0"/>
      <geometry>
        <mesh filename="package://multiverse_parser/examples/sdf_to_urdf/sdf/pr2/meshes/forearm_v0/wrist_flex.dae" scale="1 1 1"/>
      </geometry>
    </visual>
  </link>
  <link name="r_wrist_roll_link">
    <inertial>
      <mass value="0.68107"/>
      <origin xyz="0.0564   0.00045 -0.00101" rpy="0 0 0"/>
      <inertia ixx="0.0113524" ixy="-1.88243e-05" ixz="5.86222e-06" iyy="0.0120549" iyz="-5.41286e-07" izz="0.012243"/>
    </inertial>
    <collision name="r_wrist_roll_link_collision">
      <origin xyz="-0.05891 -0.031    0" rpy="0 0 0"/>
      <geometry>
        <mesh filename="package://multiverse_parser/examples/sdf_to_urdf/sdf/pr2/meshes/forearm_v0/wrist_roll_L.stl" scale="1 1 1"/>
      </geometry>
    </collision>
    <collision name="r_wrist_roll_link_fixed_joint_lump__r_gripper_palm_link_collision_1">
      <origin xyz="-0.05891 -0.031    0" rpy="0 0 0"/>
      <geometry>
        <mesh filename="package://multiverse_parser/examples/sdf_to_urdf/sdf/pr2/meshes/gripper_v0/gripper_palm.stl" scale="1 1 1"/>
      </geometry>
    </collision>
    <collision name="r_wrist_roll_link_fixed_joint_lump__r_gripper_motor_accelerometer_link_collision_2">
      <origin xyz="-0.05891 -0.031    0" rpy="0 0 0"/>
      <geometry>
        <box size="0.001 0.001 0.001"/>
      </geometry>
    </collision>
    <visual name="r_wrist_roll_link_visual">
      <origin xyz="-0.05891 -0.031    0" rpy="0 0 0"/>
      <geometry>
        <mesh filename="package://multiverse_parser/examples/sdf_to_urdf/sdf/pr2/meshes/forearm_v0/wrist_roll.stl" scale="1 1 1"/>
      </geometry>
    </visual>
    <visual name="r_wrist_roll_link_fixed_joint_lump__r_gripper_palm_link_visual_1">
      <origin xyz="-0.05891 -0.031    0" rpy="0 0 0"/>
      <geometry>
        <mesh filename="package://multiverse_parser/examples/sdf_to_urdf/sdf/pr2/meshes/gripper_v0/gripper_palm.dae" scale="1 1 1"/>
      </geometry>
    </visual>
    <visual name="r_wrist_roll_link_fixed_joint_lump__r_gripper_motor_accelerometer_link_visual_2">
      <origin xyz="-0.05891 -0.031    0" rpy="0 0 0"/>
      <geometry>
        <box size="0.001 0.001 0.001"/>
      </geometry>
    </visual>
  </link>
  <link name="r_gripper_l_finger_link">
    <inertial>
      <mass value="0.17126"/>
      <origin xyz="0.03598  0.0173  -0.00164" rpy="0 0 0"/>
      <inertia ixx="7.7562e-05" ixy="1.49095e-06" ixz="-9.83385e-06" iyy="0.000197083" iyz="-3.06125e-06" izz="0.000181054"/>
    </inertial>
    <collision name="r_gripper_l_finger_link_collision">
      <origin xyz="-0.07691 -0.01     0" rpy="0 0 0"/>
      <geometry>
        <mesh filename="package://multiverse_parser/examples/sdf_to_urdf/sdf/pr2/meshes/gripper_v0/l_finger.stl" scale="1 1 1"/>
      </geometry>
    </collision>
    <visual name="r_gripper_l_finger_link_visual">
      <origin xyz="-0.07691 -0.01     0" rpy="0 0 0"/>
      <geometry>
        <mesh filename="package://multiverse_parser/examples/sdf_to_urdf/sdf/pr2/meshes/gripper_v0/l_finger.dae" scale="1 1 1"/>
      </geometry>
    </visual>
  </link>
  <link name="r_gripper_l_finger_tip_link">
    <inertial>
      <mass value="0.04419"/>
      <origin xyz="0.00423 0.00284 0" rpy="0 0 0"/>
      <inertia ixx="8.37047e-06" ixy="5.83632e-06" ixz="0" iyy="9.87067e-06" iyz="0" izz="1.54177e-05"/>
    </inertial>
    <collision name="r_gripper_l_finger_tip_link_collision">
      <origin xyz="0 0 0" rpy="0 0 0"/>
      <geometry>
        <mesh filename="package://multiverse_parser/examples/sdf_to_urdf/sdf/pr2/meshes/gripper_v0/l_finger_tip.stl" scale="1 1 1"/>
      </geometry>
    </collision>
    <visual name="r_gripper_l_finger_tip_link_visual">
      <origin xyz="0 0 0" rpy="0 0 0"/>
      <geometry>
        <mesh filename="package://multiverse_parser/examples/sdf_to_urdf/sdf/pr2/meshes/gripper_v0/l_finger_tip.dae" scale="1 1 1"/>
      </geometry>
    </visual>
  </link>
  <link name="r_gripper_motor_slider_link">
    <inertial>
      <mass value="0.01"/>
      <origin xyz="0 0 0" rpy="0 0 0"/>
      <inertia ixx="0.001" ixy="0" ixz="0" iyy="0.001" iyz="0" izz="0.001"/>
    </inertial>
  </link>
  <link name="r_gripper_motor_screw_link">
    <inertial>
      <mass value="0.01"/>
      <origin xyz="0 0 0" rpy="0 0 0"/>
      <inertia ixx="0.0001" ixy="0" ixz="0" iyy="0.0001" iyz="0" izz="0.0001"/>
    </inertial>
  </link>
  <link name="r_gripper_r_finger_link">
    <inertial>
      <mass value="0.17389"/>
      <origin xyz="0.03576 -0.01736 -0.00095" rpy="0 0 0"/>
      <inertia ixx="7.73841e-05" ixy="-2.09309e-06" ixz="-8.36228e-06" iyy="0.000198474" iyz="2.4611e-06" izz="0.00018107"/>
    </inertial>
    <collision name="r_gripper_r_finger_link_collision">
      <origin xyz="-0.07691  0.01     0" rpy="3.14159 0      0"/>
      <geometry>
        <mesh filename="package://multiverse_parser/examples/sdf_to_urdf/sdf/pr2/meshes/gripper_v0/l_finger.stl" scale="1 1 1"/>
      </geometry>
    </collision>
    <visual name="r_gripper_r_finger_link_visual">
      <origin xyz="-0.07691  0.01     0" rpy="3.14159 0      0"/>
      <geometry>
        <mesh filename="package://multiverse_parser/examples/sdf_to_urdf/sdf/pr2/meshes/gripper_v0/l_finger.dae" scale="1 1 1"/>
      </geometry>
    </visual>
  </link>
  <link name="r_gripper_r_finger_tip_link">
    <inertial>
      <mass value="0.04419"/>
      <origin xyz="0.00423 -0.00284  0" rpy="0 0 0"/>
      <inertia ixx="8.37047e-06" ixy="-5.83632e-06" ixz="0" iyy="9.87067e-06" iyz="0" izz="1.54177e-05"/>
    </inertial>
    <collision name="r_gripper_r_finger_tip_link_collision">
      <origin xyz="0.01799 0.021   0" rpy="3.14159 0      0"/>
      <geometry>
        <mesh filename="package://multiverse_parser/examples/sdf_to_urdf/sdf/pr2/meshes/gripper_v0/l_finger_tip.stl" scale="1 1 1"/>
      </geometry>
    </collision>
    <visual name="r_gripper_r_finger_tip_link_visual">
      <origin xyz="0.01799 0.021   0" rpy="3.14159 0      0"/>
      <geometry>
        <mesh filename="package://multiverse_parser/examples/sdf_to_urdf/sdf/pr2/meshes/gripper_v0/l_finger_tip.dae" scale="1 1 1"/>
      </geometry>
    </visual>
  </link>
  <link name="torso_lift_motor_screw_link">
    <inertial>
      <mass value="1"/>
      <origin xyz="0 0 0" rpy="0 0 0"/>
      <inertia ixx="0.001" ixy="0" ixz="0" iyy="0.001" iyz="0" izz="0.001"/>
    </inertial>
  </link>
  <link name="r_gripper_l_parallel_link">
    <inertial>
      <mass value="0.17126"/>
      <origin xyz="0.03598  0.0173  -0.00164" rpy="0 0 0"/>
      <inertia ixx="7.7562e-05" ixy="1.49095e-06" ixz="-9.83385e-06" iyy="0.000197083" iyz="-3.06125e-06" izz="0.000181054"/>
    </inertial>
  </link>
  <link name="r_gripper_r_parallel_link">
    <inertial>
      <mass value="0.17389"/>
      <origin xyz="0.03576 -0.01736 -0.00095" rpy="0 0 0"/>
      <inertia ixx="7.73841e-05" ixy="-2.09309e-06" ixz="-8.36228e-06" iyy="0.000198474" iyz="2.4611e-06" izz="0.00018107"/>
    </inertial>
  </link>
  <link name="l_gripper_l_parallel_link">
    <inertial>
      <mass value="0.17126"/>
      <origin xyz="0.03598  0.0173  -0.00164" rpy="0 0 0"/>
      <inertia ixx="7.7562e-05" ixy="1.49095e-06" ixz="-9.83385e-06" iyy="0.000197083" iyz="-3.06125e-06" izz="0.000181054"/>
    </inertial>
  </link>
  <link name="l_gripper_r_parallel_link">
    <inertial>
      <mass value="0.17389"/>
      <origin xyz="0.03576 -0.01736 -0.00095" rpy="0 0 0"/>
      <inertia ixx="7.73841e-05" ixy="-2.09309e-06" ixz="-8.36228e-06" iyy="0.000198474" iyz="2.4611e-06" izz="0.00018107"/>
    </inertial>
  </link>
</robot>
