<?xml version="1.0" ?>
<!-- =================================================================================== -->
<!-- |    This document was autogenerated by xacro from src/epsilon_crane/epsilon_crane_description/urdf/crane.urdf.xacro | -->
<!-- |    EDITING THIS FILE BY HAND IS NOT RECOMMENDED                                 | -->
<!-- =================================================================================== -->
<robot name="crane_model">
  <material name="black">
    <color rgba="0.1 0.1 0.1 1.0"/>
  </material>
  <material name="blue">
    <color rgba="0.0 0.0 0.8 1.0"/>
  </material>
  <material name="green">
    <color rgba="0.0 0.8 0.0 1.0"/>
  </material>
  <material name="grey">
    <color rgba="0.4 0.4 0.4 1.0"/>
  </material>
  <material name="orange">
    <color rgba="1.0 0.4235294117647059 0.0392156862745098 1.0"/>
  </material>
  <material name="brown">
    <color rgba="0.8705882352941177 0.8117647058823529 0.7647058823529411 1.0"/>
  </material>
  <material name="AITred">
    <color rgba="0.4745098039215686 0.043137254901960784 0.10196078431372549 1.0"/>
  </material>
  <material name="white">
    <color rgba="1.0 1.0 1.0 1.0"/>
  </material>
  <!-- Die Namen der dh-Joints sind auch im simpleCraneController.hpp hinterlegt,
  werden die Namen also geändert, müssen sie auch dort geändert werden-->
  <joint name="dh_trans1" type="fixed">
    <origin rpy="1.570796327 0 0" xyz="-0.18 0 2.425"/>
    <parent link="moved_with_q1"/>
    <child link="K1_slewing_column"/>
  </joint>
  <joint name="dh_trans2" type="fixed">
    <origin rpy="0 0 0" xyz="3.49288333 0 0"/>
    <parent link="moved_with_q2"/>
    <child link="K2_boom"/>
  </joint>
  <joint name="dh_trans3" type="fixed">
    <origin rpy="1.570796327 0 0" xyz="-0.3925 0 0"/>
    <parent link="moved_with_q3"/>
    <child link="K3_arm"/>
  </joint>
  <joint name="dh_trans4" type="fixed">
    <origin rpy="0 0 0" xyz="0 0 3.157001602823000"/>
    <parent link="moved_with_q4"/>
    <child link="K4_outer_telescope"/>
  </joint>
  <joint name="dh_trans5" type="fixed">
    <origin rpy="-1.570796327 0 0" xyz="0 0 0"/>
    <parent link="moved_with_q5"/>
    <child link="K5_inner_telescope"/>
  </joint>
  <joint name="dh_trans6" type="fixed">
    <origin rpy="-1.570796327 0 0" xyz="-0.213000000000000 0 0"/>
    <parent link="moved_with_q6"/>
    <child link="K6_double_joint_link"/>
  </joint>
  <joint name="dh_trans7" type="fixed">
    <origin rpy="-1.570796327 0 0" xyz="0 0 0"/>
    <parent link="moved_with_q7"/>
    <child link="K7_rotator_upper_part"/>
  </joint>
  <!-- In der zum Zeitpunkt der Erstellung verwendenten Version von
  Gazebo ist der inital_position tag leider ohne Funktion, ebeneso
  ist leider das Service der ROS2 API zum Setzen der Joint Positions
  nicht implementiert, cf. set_model_configuration in
  https://github.com/ros-simulation/gazebo_ros_pkgs/issues/779 or
  https://answers.gazebosim.org/question/27584/ros2-setting-initial-joint-position-at-spawn/

  Aus diesem Grund müssen die initalen Winkel direkt
  im Joint gesetzt werden.
  if xacro argument gazebo==false, the original definition is used -->
  <joint name="theta1_slewing_joint" type="revolute">
    <origin rpy="0 0 0" xyz="0 0 0"/>
    <limit effort="3.1809e+04" lower="-3.71" upper="3.71" velocity="15.7"/>
    <parent link="K0_mounting_base"/>
    <child link="moved_with_q1"/>
    <axis xyz="0 0 1"/>
    <dynamics damping="7500"/>
  </joint>
  <joint name="theta2_boom_joint" type="revolute">
    <origin rpy="0 0 0" xyz="0 0 0"/>
    <limit effort="2e5" lower="-1.2" upper="1.563" velocity="15.7"/>
	<!--<limit effort="2e7" lower="-1.2" upper="1.563" velocity="15.7"/>-->
    <parent link="K1_slewing_column"/>
    <child link="moved_with_q2"/>
    <axis xyz="0 0 1"/>
    <dynamics damping="9000"/>
  </joint>
  <joint name="theta3_arm_joint" type="revolute">
    <origin rpy="0 0 0" xyz="0 0 0"/>
    <!--<limit effort="1e7" lower="-0.91" upper="4.6" velocity="15.7"/>-->
	<limit effort="1e5" lower="-0.91" upper="4.6" velocity="15.7"/>
    <parent link="K2_boom"/>
    <child link="moved_with_q3"/>
    <axis xyz="0 0 1"/>
    <dynamics damping="8000"/>
  </joint>
  <joint name="q4_big_telescope" type="prismatic">
    <origin rpy="0 0 0" xyz="0 0 0"/>
    <limit effort="1e5" lower="0" upper="2.236" velocity="10"/>
    <parent link="K3_arm"/>
    <child link="moved_with_q4"/>
    <axis xyz="0 0 1"/>
    <dynamics damping="5900"/>
  </joint>
  <joint name="theta6_tip_joint" type="revolute">
    <origin rpy="0 0 0" xyz="0 0 0"/>
    <limit effort="1e5" lower="-1.57" upper="1.57" velocity="15.7"/>
    <parent link="K5_inner_telescope"/>
    <child link="moved_with_q6"/>
    <axis xyz="0 0 1"/>
    <dynamics damping="200"/>
  </joint>
  <joint name="theta7_tilt_joint" type="revolute">
    <origin rpy="0 0 0" xyz="0 0 0"/>
    <limit effort="1e5" lower="0.785398" upper="2.35619" velocity="15.7"/>
    <parent link="K6_double_joint_link"/>
    <child link="moved_with_q7"/>
    <axis xyz="0 0 1"/>
    <dynamics damping="200"/>
  </joint>
  <link name="world"/>
  <joint name="world_fixed" type="fixed">
    <origin rpy="0 0 0" xyz="0 0 0.52"/>
    <parent link="world"/>
    <child link="truck_cab"/>
  </joint>
  <link name="truck_cab">
    <inertial>
      <origin rpy="0 0 0" xyz="0 0 0"/>
      <mass value="200"/>
      <inertia ixx="10" ixy="0" ixz="0" iyy="10" iyz="0" izz="10"/>
    </inertial>
    <visual>
      <geometry>
        <mesh filename="file://../meshes/visual/lkw_fahrerkabine_rote_teile.stl" />
      </geometry>
    </visual>
    <collision>
      <geometry>
        <mesh filename="file://../meshes/collision/lkw_fahrerkabine_rote_teile.stl" />
      </geometry>
    </collision>
  </link>
  <joint name="truck_assembly_1" type="fixed">
    <origin rpy="0 0 0" xyz="0 0 0"/>
    <parent link="truck_cab"/>
    <child link="tr_black"/>
  </joint>
  <link name="tr_black">
    <inertial>
      <origin rpy="0 0 0" xyz="0 0 0"/>
      <mass value="200"/>
      <inertia ixx="10" ixy="0" ixz="0" iyy="10" iyz="0" izz="10"/>
    </inertial>
    <visual>
      <geometry>
        <mesh filename="file://../meshes/visual/lkw_vorderachse_und_fahrerkabine_schwarze_teile.stl"/>
      </geometry>
    </visual>
    <collision>
      <geometry>
        <mesh filename="file://../meshes/collision/lkw_vorderachse_und_fahrerkabine_schwarze_teile.stl"/>
      </geometry>
    </collision>
  </link>
  <joint name="truck_assembly_2" type="fixed">
    <origin rpy="0 0 0" xyz="0 0 0"/>
    <parent link="truck_cab"/>
    <child link="tr_grey"/>
  </joint>
  <link name="tr_grey">
    <inertial>
      <origin rpy="0 0 0" xyz="0 0 0"/>
      <mass value="200"/>
      <inertia ixx="10" ixy="0" ixz="0" iyy="10" iyz="0" izz="10"/>
    </inertial>
    <visual>
      <geometry>
        <mesh filename="file://../meshes/visual/lkw_vorderraeder_graue_teile.stl"/>
      </geometry>
    </visual>
  </link>
  <joint name="truck_assembly_3" type="fixed">
    <origin rpy="0 0 0" xyz="0 0 0"/>
    <parent link="truck_cab"/>
    <child link="tr_white"/>
  </joint>
  <link name="tr_white">
    <inertial>
      <origin rpy="0 0 0" xyz="0 0 0"/>
      <mass value="200"/>
      <inertia ixx="10" ixy="0" ixz="0" iyy="10" iyz="0" izz="10"/>
    </inertial>
    <visual>
      <geometry>
        <mesh filename="file://../meshes/visual/lkw_fahrerkabine_weisse_teile.stl"/>
      </geometry>
    </visual>
  </link>
  <joint name="truck_assembly_4" type="fixed">
    <origin rpy="0 0 0" xyz="0 0 0"/>
    <parent link="truck_cab"/>
    <child link="tr_rr_wheels"/>
  </joint>
  <joint name="truck_assembly_5" type="fixed">
    <origin rpy="0 0 0" xyz="0 0 0"/>
    <parent link="truck_cab"/>
    <child link="tr_rr_rims"/>
  </joint>
  <joint name="truck_assembly_6" type="fixed">
    <origin rpy="0 0 0" xyz="0 0 0"/>
    <parent link="truck_cab"/>
    <child link="cab_fender"/>
  </joint>
  <joint name="truck_assembly_7" type="fixed">
    <origin rpy="0 0 0" xyz="0 0 0"/>
    <parent link="truck_cab"/>
    <child link="tr_bed"/>
  </joint>
  <joint name="truck_assembly_8" type="fixed">
    <origin rpy="0 0 0" xyz="0 0 0"/>
    <parent link="truck_cab"/>
    <child link="tr_tank"/>
  </joint>
  <joint name="truck_assembly_9" type="fixed">
    <origin rpy="0 0 0" xyz="0 0 0"/>
    <parent link="truck_cab"/>
    <child link="tr_rr_fender"/>
  </joint>
  <joint name="truck_assembly_10" type="fixed">
    <origin rpy="0 0 0" xyz="0 0 0"/>
    <parent link="truck_cab"/>
    <child link="tr_rungen"/>
  </joint>
  <joint name="truck_assembly_11" type="fixed">
    <origin rpy="0 0 0" xyz="-6.85 0 0.55"/>
    <parent link="truck_cab"/>
    <child link="tr_crane_frameplate"/>
  </joint>
  <link name="tr_rr_wheels">
    <inertial>
      <origin rpy="0 0 0" xyz="0 0 0"/>
      <mass value="200"/>
      <inertia ixx="10" ixy="0" ixz="0" iyy="10" iyz="0" izz="10"/>
    </inertial>
    <visual>
      <origin xyz="-3.7 0 0"/>
      <geometry>
        <mesh filename="file://../meshes/visual/lkw_hinterraeder_schwarze_teile.stl"/>
      </geometry>
    </visual>
    <collision>
      <origin xyz="-3.7 0 0"/>
      <geometry>
        <mesh filename="file://../meshes/collision/lkw_hinterraeder_schwarze_teile.stl"/>
      </geometry>
    </collision>
  </link>
  <link name="tr_rr_fender">
    <inertial>
      <origin rpy="0 0 0" xyz="0 0 0"/>
      <mass value="200"/>
      <inertia ixx="10" ixy="0" ixz="0" iyy="10" iyz="0" izz="10"/>
    </inertial>
    <visual>
      <geometry>
        <mesh filename="file://../meshes/visual/lkw_kotfluegel_hinten_schwarz.stl" />
      </geometry>
    </visual>
  </link>
  <link name="tr_rr_rims">
    <inertial>
      <origin rpy="0 0 0" xyz="0 0 0"/>
      <mass value="200"/>
      <inertia ixx="10" ixy="0" ixz="0" iyy="10" iyz="0" izz="10"/>
    </inertial>
    <visual>
      <origin xyz="-3.7 0 0"/>
      <geometry>
        <mesh filename="file://../meshes/visual/lkw_hinterraeder_graue_teile.stl"/>
      </geometry>
    </visual>
  </link>
  <link name="cab_fender">
    <inertial>
      <origin rpy="0 0 0" xyz="0 0 0"/>
      <mass value="200"/>
      <inertia ixx="10" ixy="0" ixz="0" iyy="10" iyz="0" izz="10"/>
    </inertial>
    <visual>
      <geometry>
        <mesh filename="file://../meshes/visual/lkw_kotfluegel_vorne_rot.stl"/>
      </geometry>
    </visual>
  </link>
  <link name="tr_bed">
    <inertial>
      <origin rpy="0 0 0" xyz="0 0 0"/>
      <mass value="200"/>
      <inertia ixx="10" ixy="0" ixz="0" iyy="10" iyz="0" izz="10"/>
    </inertial>
    <visual>
      <geometry>
        <mesh filename="file://../meshes/visual/lkw_ladeflaeche_mit_rammschutz_seitlich.stl"/>
      </geometry>
    </visual>
    <collision>
      <geometry>
        <mesh filename="file://../meshes/collision/lkw_ladeflaeche_mit_rammschutz_seitlich_001.stl"/>
      </geometry>
    </collision>
    <collision>
      <geometry>
        <mesh filename="file://../meshes/collision/lkw_ladeflaeche_mit_rammschutz_seitlich_002.stl"/>
      </geometry>
    </collision>
    <collision>
      <geometry>
        <mesh filename="file://../meshes/collision/lkw_ladeflaeche_mit_rammschutz_seitlich_003.stl"/>
      </geometry>
    </collision>
    <collision>
      <geometry>
        <mesh filename="file://../meshes/collision/lkw_ladeflaeche_mit_rammschutz_seitlich_004.stl"/>
      </geometry>
    </collision>
    <collision>
      <geometry>
        <mesh filename="file://../meshes/collision/lkw_ladeflaeche_mit_rammschutz_seitlich_005.stl"/>
      </geometry>
    </collision>
  </link>
  <link name="tr_tank">
    <inertial>
      <origin rpy="0 0 0" xyz="0 0 0"/>
      <mass value="200"/>
      <inertia ixx="10" ixy="0" ixz="0" iyy="10" iyz="0" izz="10"/>
    </inertial>
    <visual>
      <geometry>
        <mesh filename="file://../meshes/visual/lkw_tank.stl" />
      </geometry>
    </visual>
  </link>
  <link name="tr_rungen">
    <inertial>
      <origin rpy="0 0 0" xyz="0 0 0"/>
      <mass value="200"/>
      <inertia ixx="10" ixy="0" ixz="0" iyy="10" iyz="0" izz="10"/>
    </inertial>
    <visual>
      <geometry>
        <mesh filename="file://../meshes/visual/lkw_rungen.stl" />
      </geometry>
    </visual>
    <collision>
      <geometry>
        <mesh filename="file://../meshes/collision/lkw_rungen_001.stl"/>
      </geometry>
    </collision>
    <collision>
      <geometry>
        <mesh filename="file://../meshes/collision/lkw_rungen_002.stl"/>
      </geometry>
    </collision>
    <collision>
      <geometry>
        <mesh filename="file://../meshes/collision/lkw_rungen_003.stl"/>
      </geometry>
    </collision>
    <collision>
      <geometry>
        <mesh filename="file://../meshes/collision/lkw_rungen_004.stl"/>
      </geometry>
    </collision>
    <collision>
      <geometry>
        <mesh filename="file://../meshes/collision/lkw_rungen_005.stl"/>
      </geometry>
    </collision>
    <collision>
      <geometry>
        <mesh filename="file://../meshes/collision/lkw_rungen_006.stl"/>
      </geometry>
    </collision>
    <collision>
      <geometry>
        <mesh filename="file://../meshes/collision/lkw_rungen_007.stl"/>
      </geometry>
    </collision>
    <collision>
      <geometry>
        <mesh filename="file://../meshes/collision/lkw_rungen_008.stl"/>
      </geometry>
    </collision>
    <collision>
      <geometry>
        <mesh filename="file://../meshes/collision/lkw_rungen_009.stl"/>
      </geometry>
    </collision>
    <collision>
      <geometry>
        <mesh filename="file://../meshes/collision/lkw_rungen_010.stl"/>
      </geometry>
    </collision>
  </link>
  <link name="tr_crane_frameplate">
    <inertial>
      <mass value="0.001"/>
      <!--must not be zero-->
      <inertia ixx="1e-6" ixy="0" ixz="0" iyy="1e-6" iyz="0" izz="1e-6"/>
      <!--tag must exist-->
    </inertial>
    <visual>
      <origin rpy="0 0 0" xyz="0 0 0"/>
      <geometry>
        <box size="0.95 0.71 0.18"/>
      </geometry>
    </visual>
  </link>
  <joint name="support_front" type="fixed">
    <origin rpy="0 0 3.141592654" xyz="-0.80 0.35 0.6207"/>
    <parent link="truck_cab"/>
    <child link="support_front"/>
  </joint>
  <link name="support_front">
    <inertial>
      <origin rpy="1.570796327 0 0" xyz="-0.315 0.35 0.1485"/>
      <mass value="200"/>
      <!--dummy mass-->
      <inertia ixx="10" ixy="0" ixz="0" iyy="10" iyz="0" izz="10"/>
    </inertial>
    <visual>
      <origin xyz="-0.315 0.35 0.1485"/>
      <geometry>
        <mesh filename="file://../meshes/visual/support_front.stl" />
      </geometry>
    </visual>
    <collision>
      <origin xyz="-0.315 0.35 0.1485"/>
      <geometry>
        <mesh filename="file://../meshes/collision/support_front.stl" />
      </geometry>
    </collision>
  </link>
  <joint name="mounting_on_truck" type="fixed">
    <origin rpy="0 0 3.141592654" xyz="-6.93852 0.35 0.6207"/>
    <parent link="truck_cab"/>
    <child link="K0_mounting_base"/>
  </joint>
  <link name="K0_mounting_base">
    <inertial>
      <origin rpy="1.570796327 0 0" xyz="-0.315 0.35 0.1485"/>
      <mass value="200"/>
      <!--dummy mass-->
      <inertia ixx="10" ixy="0" ixz="0" iyy="10" iyz="0" izz="10"/>
    </inertial>
    <visual>
      <origin xyz="-0.315 0.35 0.1485"/>
      <geometry>
        <mesh filename="file://../meshes/visual/mounting_base.stl" />
      </geometry>
    </visual>
    <collision>
      <origin xyz="-0.315 0.35 0.1485"/>
      <geometry>
        <mesh filename="file://../meshes/collision/mounting_base.stl"/>
      </geometry>
    </collision>
  </link>
  <link name="moved_with_q1"/>
  <link name="K1_slewing_column">
    <!-- Already with cylinder+boom 13+14, underseat cover m23, drawbar -->
    <inertial>
      <origin rpy="0 0 0" xyz="0.207137965519557 -1.159583405601666 0.001640171843259"/>
      <mass value="5.154880063747235e+02"/>
      <inertia ixx="2.827605713015819e+02" ixy="19.110745995034847" ixz="1.396808240454494" iyy="31.470391589468022" iyz="-1.826777157256440" izz="3.054707726021946e+02"/>
    </inertial>
    <visual>
      <origin xyz="0.18 -2.3652 0"/>
      <geometry>
        <mesh filename="file://../meshes/visual/slewing_column.stl" />
      </geometry>
    </visual>
    <collision>
      <origin xyz="0.18 -2.3652 0"/>
      <geometry>
        <mesh filename="file://../meshes/collision/slewing_column.stl" />
      </geometry>
    </collision>
  </link>
  <link name="control_box">
    <inertial>
      <origin rpy="0 0 0" xyz="0 0 0"/>
      <mass value="150"/>
      <inertia ixx="13" ixy="0" ixz="0" iyy="20" iyz="0" izz="9"/>
    </inertial>
    <visual>
      <geometry>
        <mesh filename="file://../meshes/visual/control_box.stl" />
      </geometry>
      <material name="grey"/>
    </visual>
    <collision>
      <origin rpy="0 0 0" xyz="0 -0.04 0"/>
      <geometry>
        <box size="0.8 0.45 1.1"/>
      </geometry>
    </collision>
  </link>
  <joint name="mounting_control_box" type="fixed">
    <origin rpy="-1.5707 3.1415 0" xyz="0.03 -0.91 -0.50"/>
    <parent link="K1_slewing_column"/>
    <child link="control_box"/>
  </joint>
  <link name="hydraulic_block">
    <inertial>
      <origin rpy="0 0 0" xyz="0 0 0"/>
      <mass value="150"/>
      <inertia ixx="10" ixy="0" ixz="0" iyy="6" iyz="0" izz="8"/>
    </inertial>
    <visual>
      <origin rpy="0 0 0" xyz="0 0 0"/>
      <geometry>
        <box size="0.4 0.68 0.62"/>
      </geometry>
      <material name="black"/>
    </visual>
    <collision>
      <origin rpy="0 0 0" xyz="0 0 0"/>
      <geometry>
        <box size="0.4 0.68 0.62"/>
      </geometry>
    </collision>
  </link>
  <joint name="mounting_hydraulic_block" type="fixed">
    <origin rpy="0 0 0.1" xyz="-0.3 -0.74 0"/>
    <parent link="K1_slewing_column"/>
    <child link="hydraulic_block"/>
  </joint>
  <link name="moved_with_q2"/>
  <link name="K2_boom">
    <inertial>
      <origin rpy="0 0 0" xyz="-1.882843488598119 0.039036403598836 0.003796838800000"/>
      <mass value="407.665"/>
      <!--Cylinder missing-->
      <inertia ixx="12.9635546037319" ixy="25.9663258534317" ixz="2.04135504691337" iyy="482.038840396268" iyz="-0.028651226435221" izz="482.51832"/>
    </inertial>
    <visual>
      <origin rpy="0 0 -0.101235" xyz="-3.49288333 0 0"/>
      <geometry>
        <mesh filename="file://../meshes/visual/boom.stl" />
      </geometry>
    </visual>
    <collision>
      <origin rpy="0 0 -0.101235" xyz="-3.49288333 0 0"/>
      <geometry>
        <mesh filename="file://../meshes/collision/boom.stl" />
      </geometry>
    </collision>
  </link>
  <link name="moved_with_q3"/>
  <link name="K3_arm">
    <inertial>
      <origin rpy="0 0 0" xyz="0.3015 -4.6229559516e-05 1.263"/>
      <mass value="275.94"/>
      <inertia ixx="236.507399621315" ixy="0.00625973116675" ixz="-0.238132647784304" iyy="236.049919798635" iyz="-0.009420134899049" izz="5.2724707120198"/>
    </inertial>
    <visual>
      <origin xyz="0.39250 0 0"/>
      <geometry>
        <mesh filename="file://../meshes/visual/arm.stl" />
      </geometry>
    </visual>
    <collision>
      <origin xyz="0.39250 0 0"/>
      <geometry>
        <mesh filename="file://../meshes/collision/arm_001.stl" />
      </geometry>
    </collision>
    <collision>
      <origin xyz="0.39250 0 0"/>
      <geometry>
        <mesh filename="file://../meshes/collision/arm_002.stl" />
      </geometry>
    </collision>
    <collision>
      <origin xyz="0.39250 0 0"/>
      <geometry>
        <mesh filename="file://../meshes/collision/arm_003.stl" />
      </geometry>
    </collision>
    <collision>
      <origin xyz="0.39250 0 0"/>
      <geometry>
        <mesh filename="file://../meshes/collision/arm_004.stl" />
      </geometry>
    </collision>
  </link>
  <link name="moved_with_q4"/>
  <link name="K4_outer_telescope">
    <inertial>
      <origin rpy="0 0 0" xyz="0.294715259451448 1.7201675251e-05 -1.6657059950"/>
      <mass value="128.16"/>
      <inertia ixx="1.2813802808e+02" ixy="0.00073591476101" ixz="-3.4553421977e-01" iyy="1.2837811642e+02" iyz="3.9487861087e-03" izz="1.08572871277175"/>
    </inertial>
    <visual>
      <origin xyz="0.2905 0 -0.0712"/>
      <geometry>
        <mesh filename="file://../meshes/visual/outer_telescope.stl" />
      </geometry>
    </visual>
    <collision>
      <origin xyz="0.2905 0 -0.0712"/>
      <geometry>
        <mesh filename="file://../meshes/collision/outer_telescope_001.stl" />
      </geometry>
    </collision>
    <collision>
      <origin xyz="0.2905 0 -0.0712"/>
      <geometry>
        <mesh filename="file://../meshes/collision/outer_telescope_002.stl" />
      </geometry>
    </collision>
    <collision>
      <origin xyz="0.2905 0 -0.0712"/>
      <geometry>
        <mesh filename="file://../meshes/collision/outer_telescope_003.stl" />
      </geometry>
    </collision>
    <collision>
      <origin xyz="0.2905 0 -0.0712"/>
      <geometry>
        <mesh filename="file://../meshes/collision/outer_telescope_004.stl" />
      </geometry>
    </collision>
  </link>
  <link name="moved_with_q5"/>
  <link name="K5_inner_telescope">
    <inertial>
      <origin rpy="0 0 0 " xyz="0.251 1.570 -1.5699152000e-04"/>
      <mass value="95.827"/>
      <inertia ixx="87.879703" ixy="-3.6539487" ixz="-8.7453688000e-05" iyy="1.1104039" iyz="0.01647281" izz="88.419175"/>
    </inertial>
    <visual>
      <origin xyz="0.281 0 0"/>
      <geometry>
        <mesh filename="file://../meshes/visual/inner_telescope.stl" />
      </geometry>
      <material name="black"/>
    </visual>
    <collision>
      <origin xyz="0.281 0 0"/>
      <geometry>
        <mesh filename="file://../meshes/collision/inner_telescope.stl" />
      </geometry>
    </collision>
  </link>
  <link name="moved_with_q6"/>
  <link name="K6_double_joint_link">
    <inertial>
      <origin rpy="0 0 0" xyz="0.1065 0 0"/>
      <mass value="15."/>
      <inertia ixx="0.061516250000000" ixy="0" ixz="0" iyy="0.037407812500000" iyz="0" izz="0.089314062500000"/>
    </inertial>
    <visual>
      <geometry>
        <mesh filename="file://../meshes/visual/double_joint_link.stl"/>
      </geometry>
    </visual>
    <collision>
      <geometry>
        <mesh filename="file://../meshes/collision/double_joint_link.stl" />
      </geometry>
    </collision>
  </link>
  <link name="moved_with_q7"/>
  <joint name="dh_trans8" type="fixed">
    <origin rpy="0 0 0" xyz="0 0 0.578000000000000"/>
    <parent link="moved_with_q8"/>
    <child link="K8_tool_center_point"/>
  </joint>
  <joint name="dh_trans9" type="fixed">
    <origin rpy="1.570796327 0 -1.5707963270" xyz="0 -0.34018 0 "/>
    <parent link="K8_tool_center_point"/>
    <child link="K9"/>
  </joint>
  <joint name="dh_trans10" type="fixed">
    <origin rpy="0 0 0" xyz="0.8566 0 0 "/>
    <parent link="moved_with_q10"/>
    <child link="K10_outer_jaw"/>
  </joint>
  <joint name="dh_trans11" type="fixed">
    <origin rpy="1.570796327 0 1.5707963270" xyz="0 0.3248 0 "/>
    <parent link="K8_tool_center_point"/>
    <child link="K11"/>
  </joint>
  <joint name="dh_trans12" type="fixed">
    <origin rpy="0 0 0" xyz="0.8566 0 0 "/>
    <parent link="moved_with_q12"/>
    <child link="K12_inner_jaw"/>
  </joint>
  <!-- In der zum Zeitpunkt der Erstellung verwendenten Version von
  Gazebo ist der inital_position
  tag leider ohne Funktion, ebeneso
  ist leider das Service der ROS2 API zum Setzen der Joint
  Positions
  nicht implementiert, cf. set_model_configuration in
  https://github.com/ros-simulation/gazebo_ros_pkgs/issues/779 or
  https://answers.gazebosim.org/question/27584/ros2-setting-initial-joint-position-at-spawn/

  Aus
  diesem Grund müssen die initalen Winkel direkt
  im Joint gesetzt werden. Über jedem Gelenk wird
  ein Kommentar eingefügt,
  in dem die Definition des Origins + Limits OHNE DIESE INITIALE POSITION
  steht.-->
  <joint name="theta8_rotator_joint" type="revolute">
    <origin rpy="0 0 0.0" xyz=" 0 0 0"/>
    <limit effort="2200" lower="-3.14" upper="3.14" velocity="10"/>
    <parent link="K7_rotator_upper_part"/>
    <child link="moved_with_q8"/>
    <axis xyz="0 0 1"/>
  </joint>
  <link name="K7_rotator_upper_part">
    <inertial>
      <origin rpy="0 0 0" xyz="0 0 0.1715"/>
      <mass value="55."/>
      <inertia ixx="0.676724583333333" ixy="0" ixz="0" iyy="0.676724583333333" iyz="0" izz="0.275000000000000"/>
    </inertial>
    <visual>
      <origin xyz=" 0 0 0.113385"/>
      <geometry>
        <mesh filename="file://../meshes/visual/rotator_upper_part.stl"/>
      </geometry>
      <material name="black"/>
    </visual>
    <collision>
      <origin xyz=" 0 0 0.113385"/>
      <geometry>
        <mesh filename="file://../meshes/collision/rotator_upper_part.stl" />
      </geometry>
    </collision>
  </link>
  <link name="moved_with_q8"/>
  <link name="K8_tool_center_point">
    <inertial>
      <origin rpy="0 0 0" xyz=" -0.0011602622 -0.0035701998 -0.02914623"/>
      <mass value="67.613348000000000"/>
      <inertia ixx="4.240" ixy="-0.002249" ixz="0.00876" iyy="2.4714" iyz="-0.01253" izz="5.3299"/>
    </inertial>
    <visual>
      <origin xyz=" 0 0 -0.454717 "/>
      <geometry>
        <mesh filename="file://../meshes/visual/pincer_frame.stl" />
      </geometry>
    </visual>
    <collision>
      <origin xyz="0 0 -0.454717 "/>
      <geometry>
        <mesh filename="file://../meshes/collision/pincer_frame.stl" />
      </geometry>
    </collision>
  </link>
  <link name="K9">
    <inertial>
      <mass value="0.001"/>
      <!--must not be zero-->
      <inertia ixx="1e-6" ixy="0" ixz="0" iyy="1e-6" iyz="0" izz="1e-6"/>
      <!--tag must exist-->
    </inertial>
  </link>
  <link name="moved_with_q10"/>
  <link name="K10_outer_jaw">
    <inertial>
      <origin rpy="0 0 0" xyz="-0.61400616 -0.13624746 0.0015810155"/>
      <mass value="63.557"/>
      <inertia ixx="3.3547704" ixy="0.53740795" ixz="0.030265788" iyy="9.1819806" iyz="-0.012190869" izz="7.4407964"/>
    </inertial>
    <visual>
      <origin rpy="0 1.5707963270 0.052742" xyz="-0.5509339 0.47161 0"/>
      <geometry>
        <mesh filename="file://../meshes/visual/outer_jaw.stl" />
      </geometry>
    </visual>
    <collision>
      <origin rpy="0 1.5707963270 0.052742" xyz="-0.5509339 0.47161 0"/>
      <geometry>
        <mesh filename="file://../meshes/collision/outer_jaw_001.stl" />
      </geometry>
    </collision>
    <collision>
      <origin rpy="0 1.5707963270 0.052742" xyz="-0.5509339 0.47161 0"/>
      <geometry>
        <mesh filename="file://../meshes/collision/outer_jaw_002.stl" />
      </geometry>
    </collision>
    <collision>
      <origin rpy="0 1.5707963270 0.052742" xyz="-0.5509339 0.47161 0"/>
      <geometry>
        <mesh filename="file://../meshes/collision/outer_jaw_003.stl" />
      </geometry>
    </collision>
    <collision>
      <origin rpy="0 1.5707963270 0.052742" xyz="-0.5509339 0.47161 0"/>
      <geometry>
        <mesh filename="file://../meshes/collision/outer_jaw_004.stl" />
      </geometry>
    </collision>
    <collision>
      <origin rpy="0 1.5707963270 0.052742" xyz="-0.5509339 0.47161 0"/>
      <geometry>
        <mesh filename="file://../meshes/collision/outer_jaw_005.stl" />
      </geometry>
    </collision>
    <collision>
      <origin rpy="0 1.5707963270 0.052742" xyz="-0.5509339 0.47161 0"/>
      <geometry>
        <mesh filename="file://../meshes/collision/outer_jaw_006.stl" />
      </geometry>
    </collision>
    <collision>
      <origin rpy="0 1.5707963270 0.052742" xyz="-0.5509339 0.47161 0"/>
      <geometry>
        <mesh filename="file://../meshes/collision/outer_jaw_007.stl" />
      </geometry>
    </collision>
    <collision>
      <origin rpy="0 1.5707963270 0.052742" xyz="-0.5509339 0.47161 0"/>
      <geometry>
        <mesh filename="file://../meshes/collision/outer_jaw_008.stl" />
      </geometry>
    </collision>
    <collision>
      <origin rpy="0 1.5707963270 0.052742" xyz="-0.5509339 0.47161 0"/>
      <geometry>
        <mesh filename="file://../meshes/collision/outer_jaw_009.stl" />
      </geometry>
    </collision>
    <collision>
      <origin rpy="0 1.5707963270 0.052742" xyz="-0.5509339 0.47161 0"/>
      <geometry>
        <mesh filename="file://../meshes/collision/outer_jaw_010.stl" />
      </geometry>
    </collision>
    <collision>
      <origin rpy="0 1.5707963270 0.052742" xyz="-0.5509339 0.47161 0"/>
      <geometry>
        <mesh filename="file://../meshes/collision/outer_jaw_011.stl" />
      </geometry>
    </collision>
    <collision>
      <origin rpy="0 1.5707963270 0.052742" xyz="-0.5509339 0.47161 0"/>
      <geometry>
        <mesh filename="file://../meshes/collision/outer_jaw_012.stl" />
      </geometry>
    </collision>
    <collision>
      <origin rpy="0 1.5707963270 0.052742" xyz="-0.5509339 0.47161 0"/>
      <geometry>
        <mesh filename="file://../meshes/collision/outer_jaw_013.stl" />
      </geometry>
    </collision>
    <collision>
      <origin rpy="0 1.5707963270 0.052742" xyz="-0.5509339 0.47161 0"/>
      <geometry>
        <mesh filename="file://../meshes/collision/outer_jaw_014.stl" />
      </geometry>
    </collision>
    <collision>
      <origin rpy="0 1.5707963270 0.052742" xyz="-0.5509339 0.47161 0"/>
      <geometry>
        <mesh filename="file://../meshes/collision/outer_jaw_015.stl" />
      </geometry>
    </collision>
  </link>
  <link name="K11">
    <inertial>
      <mass value="0.001"/>
      <!--must not be zero-->
      <inertia ixx="1e-6" ixy="0" ixz="0" iyy="1e-6" iyz="0" izz="1e-6"/>
      <!--tag must exist-->
    </inertial>
  </link>
  <link name="moved_with_q12"/>
  <link name="K12_inner_jaw">
    <inertial>
      <origin rpy="0 0 0" xyz="-0.615697300000000 -0.130086390000000 -0.001763718300000"/>
      <mass value="61.03"/>
      <inertia ixx="2.64355" ixy="0.426088" ixz="-7.0337020000e-03" iyy="7.6996" iyz="1.0131076000e-02" izz="6.4273"/>
    </inertial>
    <visual>
      <origin rpy="0 -1.5707963270 0.085" xyz="-0.5663 0.4813 0"/>
      <geometry>
        <mesh filename="file://../meshes/visual/inner_jaw.stl" />
      </geometry>
    </visual>
    <collision>
      <origin rpy="0 -1.5707963270 0.085" xyz="-0.5663 0.4813 0"/>
      <geometry>
        <mesh filename="file://../meshes/collision/inner_jaw_001.stl"/>
      </geometry>
    </collision>
    <collision>
      <origin rpy="0 -1.5707963270 0.085" xyz="-0.5663 0.4813 0"/>
      <geometry>
        <mesh filename="file://../meshes/collision/inner_jaw_002.stl"/>
      </geometry>
    </collision>
    <collision>
      <origin rpy="0 -1.5707963270 0.085" xyz="-0.5663 0.4813 0"/>
      <geometry>
        <mesh filename="file://../meshes/collision/inner_jaw_003.stl"/>
      </geometry>
    </collision>
    <collision>
      <origin rpy="0 -1.5707963270 0.085" xyz="-0.5663 0.4813 0"/>
      <geometry>
        <mesh filename="file://../meshes/collision/inner_jaw_004.stl"/>
      </geometry>
    </collision>
    <collision>
      <origin rpy="0 -1.5707963270 0.085" xyz="-0.5663 0.4813 0"/>
      <geometry>
        <mesh filename="file://../meshes/collision/inner_jaw_005.stl"/>
      </geometry>
    </collision>
    <collision>
      <origin rpy="0 -1.5707963270 0.085" xyz="-0.5663 0.4813 0"/>
      <geometry>
        <mesh filename="file://../meshes/collision/inner_jaw_006.stl"/>
      </geometry>
    </collision>
    <collision>
      <origin rpy="0 -1.5707963270 0.085" xyz="-0.5663 0.4813 0"/>
      <geometry>
        <mesh filename="file://../meshes/collision/inner_jaw_007.stl"/>
      </geometry>
    </collision>
    <collision>
      <origin rpy="0 -1.5707963270 0.085" xyz="-0.5663 0.4813 0"/>
      <geometry>
        <mesh filename="file://../meshes/collision/inner_jaw_008.stl"/>
      </geometry>
    </collision>
    <collision>
      <origin rpy="0 -1.5707963270 0.085" xyz="-0.5663 0.4813 0"/>
      <geometry>
        <mesh filename="file://../meshes/collision/inner_jaw_009.stl"/>
      </geometry>
    </collision>
    <collision>
      <origin rpy="0 -1.5707963270 0.085" xyz="-0.5663 0.4813 0"/>
      <geometry>
        <mesh filename="file://../meshes/collision/inner_jaw_010.stl"/>
      </geometry>
    </collision>
    <collision>
      <origin rpy="0 -1.5707963270 0.085" xyz="-0.5663 0.4813 0"/>
      <geometry>
        <mesh filename="file://../meshes/collision/inner_jaw_011.stl"/>
      </geometry>
    </collision>
    <collision>
      <origin rpy="0 -1.5707963270 0.085" xyz="-0.5663 0.4813 0"/>
      <geometry>
        <mesh filename="file://../meshes/collision/inner_jaw_012.stl"/>
      </geometry>
    </collision>
    <collision>
      <origin rpy="0 -1.5707963270 0.085" xyz="-0.5663 0.4813 0"/>
      <geometry>
        <mesh filename="file://../meshes/collision/inner_jaw_013.stl"/>
      </geometry>
    </collision>
    <collision>
      <origin rpy="0 -1.5707963270 0.085" xyz="-0.5663 0.4813 0"/>
      <geometry>
        <mesh filename="file://../meshes/collision/inner_jaw_014.stl"/>
      </geometry>
    </collision>
    <collision>
      <origin rpy="0 -1.5707963270 0.085" xyz="-0.5663 0.4813 0"/>
      <geometry>
        <mesh filename="file://../meshes/collision/inner_jaw_015.stl"/>
      </geometry>
    </collision>
  </link>
  <!--The yaw value of pi/2-0.1129 is the starting position and must be considered to get the
  correct joint position in relation to the coordinate systems defined in the sketches -->
  <joint name="theta10_outer_jaw_joint" type="revolute">
    <origin rpy="0 0 0" xyz="0 0 0"/>
    <limit effort="1000.0" lower="0" upper="3" velocity="0.5"/>
    <parent link="K9"/>
    <child link="moved_with_q10"/>
    <axis xyz="0 0 1"/>
    <dynamics damping="400"/>
  </joint>
  <!--The yaw value of pi/2 is the starting position and must be considered to get the correct joint
  position in relation to the coordinate systems defined in the sketches -->
  <joint name="theta12_inner_jaw_joint" type="revolute">
    <parent link="K11"/>
    <child link="moved_with_q12"/>
    <axis xyz="0 0 1"/>
    <!-- this one not simply an offset, but the four-bar linkage can't be implemented
            directly
      here, as it is done with gazebo -->
    <mimic joint="theta10_outer_jaw_joint" multiplier="1" offset="0.1"/>
    <origin rpy="0 0 0.0" xyz="0 0 0 "/>
    <limit effort="1000.0" lower="-3" upper="3" velocity="0.5"/>
  </joint>
  <joint name="q5_small_telescope" type="prismatic">
    <origin rpy="0 0 0" xyz="0 0 0"/>
    <limit effort="1e5" lower="0" upper="2.236" velocity="10"/>
    <parent link="K4_outer_telescope"/>
    <child link="moved_with_q5"/>
    <axis xyz="0 0 1"/>
    <!-- increased damping, otherwise the EPSCOPE implementation shows oszillatory behavior -->
    <dynamics damping="8000"/>
    <!-- mimic telescope arm -->
    <mimic joint="q4_big_telescope" multiplier="1" offset="0"/>
  </joint>
  <!--Uncomment this line to see the collision bodies defined in matlab-->
  <!-- <xacro:include filename="$(find
  epsilon_crane_description)/urdf/collision_bodies_truck_matlab.urdf.xacro"/> -->
  <!-- Interface Names for Plugin-->
  
  <ros2_control name="GazeboSystem" type="system">
    <hardware>
      <plugin>gazebo_ros2_control_actuators/GazeboSystem</plugin>
    </hardware>
    <joint name="theta1_slewing_joint">
      <command_interface name="velocitycontrolled"/>
      <param name="k1">4.1e08</param>
      <param name="k2">5.2e+05</param>
      <param name="p_gain">1.e-01</param>
      <param name="i_gain">1.e-02</param>
      <param name="d_gain">5.e-04</param>
      <param name="q_max">4.8e-3</param>
      <param name="Kff">1.3e-3</param>
      <param name="offset">0.0</param>
      <state_interface name="effort"/>
      <state_interface name="velocity"/>
      <state_interface name="position"/>
    </joint>
    <joint name="theta2_boom_joint">
      <command_interface name="velocitycontrolled"/>
      <param name="joint_actuator">boom_cylinder_piston_in_barrel_linear_joint</param>
      <param name="k1">3.1e+09</param>
      <param name="k2">4.8e+07</param>
      <param name="p_gain">4.5e-5</param>
      <param name="i_gain">9.0e-2</param>
      <param name="d_gain">9.0e-4</param>
      <param name="q_max">4.8e-3</param>
      <param name="Kff">7e-3</param>
      <param name="offset">0.0</param>
      <param name="effort_0">77609.145973</param>
      <state_interface name="effort"/>
      <state_interface name="velocity"/>
      <state_interface name="position"/>
    </joint>
    <joint name="theta3_arm_joint">
      <!-- parameters as if there would be only one cylinder -->
      <command_interface name="velocitycontrolled"/>
      <param name="joint_actuator">arm_cylinder_piston_in_barrel_linear_joint_right</param>
      <param name="k1">3.2e+09</param>
      <param name="k2">4.1e+07</param>
      <param name="p_gain">3.6e-02,0,-3.6e-02</param>
      <param name="i_gain">3.6e-01,0,-3.6e-01</param>
      <param name="d_gain">1.8e-04,0,-1.8e-04</param>
      <param name="q_max">4.8e-3</param>
      <param name="Kff">4.6e-3,0,-4.6e-3</param>
      <param name="offset">0.0</param>
      <!-- deactivate controller close to singular point, change sign afterwards -->
      <param name="gain_schedule_points">1.76,1.93</param>
      <param name="effort_0">-5036.869328</param>
      <state_interface name="effort"/>
      <state_interface name="velocity"/>
      <state_interface name="position"/>
    </joint>
    <joint name="q4_big_telescope">
      <command_interface name="EPSCOPE"/>
      <param name="extension_boom">q5_small_telescope</param>
      <param name="k1">1.3e+09</param>
      <param name="k2">5.2e+06</param>
      <param name="p_gain">5e-02</param>
      <param name="i_gain">1.e-1</param>
      <param name="d_gain">5.e-4</param>
      <param name="q_max">4.8e-3</param>
      <param name="Kff">3.8e-3</param>
      <param name="offset">0.0</param>
      <param name="effort_0">-5272.627435</param>
      <state_interface name="effort"/>
      <state_interface name="velocity"/>
      <state_interface name="position"/>
    </joint>
    <!-- state interface only -->
    <joint name="theta6_tip_joint">
      <param name="offset">0.0</param>
      <state_interface name="effort"/>
      <state_interface name="velocity"/>
      <state_interface name="position"/>
    </joint>
    <joint name="theta7_tilt_joint">
      <param name="offset">0.0</param>
      <state_interface name="effort"/>
      <state_interface name="velocity"/>
      <state_interface name="position"/>
    </joint>
    <joint name="theta8_rotator_joint">
      <command_interface name="velocitycontrolled"/>
      <param name="k1">4.1e+08</param>
      <param name="k2">5.2e+04</param>
      <param name="p_gain">1.e-6</param>
      <param name="i_gain">0</param>
      <param name="d_gain">0</param>
      <param name="Kff">1.2e-4</param>
      <param name="q_max">4.2e-4</param>
      <param name="offset">0.0</param>
      <state_interface name="effort"/>
      <state_interface name="velocity"/>
      <state_interface name="position"/>
    </joint>
    <joint name="theta10_outer_jaw_joint">
      <command_interface name="velocitycontrolled"/>
      <param name="joint_actuator">pincer_cylinder_piston_in_barrel_linear_joint</param>
      <param name="k1">3.3e+09</param>
      <param name="k2">2.8e+07</param>
      <param name="p_gain">0</param>
      <param name="i_gain">0</param>
      <param name="d_gain">0</param>
      <param name="Kff">1.5e-3</param>
      <param name="q_max">1.5e-3</param>
      <param name="offset">0.0</param>
      <state_interface name="effort"/>
      <state_interface name="velocity"/>
      <state_interface name="position"/>
    </joint>
    <joint name="theta12_inner_jaw_joint">
      <!-- it seems that robot_state_publisher does not use mimic tag 
        if joint_state_publisher publishes tf2 frame, therefore we have to apply the 
        offset here too for correct tf2 for rviz-->
      <param name="offset">0.0</param>
      <state_interface name="velocity"/>
      <state_interface name="position"/>
    </joint>
    <joint name="pushrod_mounting_outer_jaw_joint">
      <state_interface name="position"/>
    </joint>
    <joint name="pincer_cylinder_piston_in_barrel_linear_joint">
      <state_interface name="position"/>
      <state_interface name="effort"/>
    </joint>
    <joint name="pincer_cylinder_mounting_outer_jaw_joint">
      <state_interface name="position"/>
    </joint>
    <!-- In gazebo, this joint is used with EPSCOPE interface by q4_big_telescope -->
    <joint name="q5_small_telescope">
      <param name="offset">0.0</param>
      <state_interface name="effort"/>
      <state_interface name="velocity"/>
      <state_interface name="position"/>
    </joint>
    <joint name="boom_cylinder_mounting_on_slewing_column">
      <param name="offset">-0.00612</param>
      <state_interface name="position"/>
    </joint>
    <joint name="boom_cylinder_piston_in_barrel_linear_joint">
      <!--TODO the coordinate system is shifted by 1.18m-->
      <param name="offset">0.43400700000000003</param>
      <state_interface name="position"/>
      <state_interface name="effort"/>
    </joint>
    <joint name="boom_cylinder_linkage_big_mounting_on_slewing_column">
      <param name="offset">-0.158245</param>
      <state_interface name="position"/>
    </joint>
    <joint name="boom_cylinder_linkage_small_mounting_on_boom">
      <param name="offset">-0.087064</param>
      <state_interface name="position"/>
    </joint>
    <joint name="arm_cylinder_mounting_on_boom_right">
      <param name="offset">-1.83314</param>
      <state_interface name="position"/>
    </joint>
    <joint name="arm_cylinder_piston_in_barrel_linear_joint_right">
      <param name="offset">1.617575</param>
      <state_interface name="position"/>
      <state_interface name="effort"/>
    </joint>
    <joint name="arm_cylinder_mounting_on_boom_left">
      <param name="offset">-1.83314</param>
      <state_interface name="position"/>
    </joint>
    <joint name="arm_cylinder_piston_in_barrel_linear_joint_left">
      <param name="offset">1.617575</param>
      <state_interface name="position"/>
    </joint>
  </ros2_control>
</robot>
