#usda 1.0
(
    customLayerData = {
        dictionary cameraSettings = {
            dictionary Front = {
                double3 position = (5, 0, 0)
                double radius = 5
            }
            dictionary Perspective = {
                double3 position = (2.374811500664988, 2.3748115006649884, 2.3748115633235916)
                double3 target = (-3.978038343177559e-8, -3.978038209950796e-8, 7.956076908399723e-8)
            }
            dictionary Right = {
                double3 position = (0, -5, 0)
                double radius = 5
            }
            dictionary Top = {
                double3 position = (0, 0, 5)
                double radius = 5
            }
            string boundCamera = "/OmniverseKit_Persp"
        }
        dictionary omni_layer = {
            string authoring_layer = "./ur5e.usda"
        }
        dictionary renderSettings = {
            float3 "rtx:debugView:pixelDebug:textColor" = (0, 1e18, 0)
            float3 "rtx:fog:fogColor" = (0.75, 0.75, 0.75)
            float3 "rtx:index:backgroundColor" = (0, 0, 0)
            float3 "rtx:index:regionOfInterestMax" = (0, 0, 0)
            float3 "rtx:index:regionOfInterestMin" = (0, 0, 0)
            float3 "rtx:post:backgroundZeroAlpha:backgroundDefaultColor" = (0, 0, 0)
            float3 "rtx:post:colorcorr:contrast" = (1, 1, 1)
            float3 "rtx:post:colorcorr:gain" = (1, 1, 1)
            float3 "rtx:post:colorcorr:gamma" = (1, 1, 1)
            float3 "rtx:post:colorcorr:offset" = (0, 0, 0)
            float3 "rtx:post:colorcorr:saturation" = (1, 1, 1)
            float3 "rtx:post:colorgrad:blackpoint" = (0, 0, 0)
            float3 "rtx:post:colorgrad:contrast" = (1, 1, 1)
            float3 "rtx:post:colorgrad:gain" = (1, 1, 1)
            float3 "rtx:post:colorgrad:gamma" = (1, 1, 1)
            float3 "rtx:post:colorgrad:lift" = (0, 0, 0)
            float3 "rtx:post:colorgrad:multiply" = (1, 1, 1)
            float3 "rtx:post:colorgrad:offset" = (0, 0, 0)
            float3 "rtx:post:colorgrad:whitepoint" = (1, 1, 1)
            float3 "rtx:post:lensDistortion:lensFocalLengthArray" = (10, 30, 50)
            float3 "rtx:post:lensFlares:anisoFlareFalloffX" = (450, 475, 500)
            float3 "rtx:post:lensFlares:anisoFlareFalloffY" = (10, 10, 10)
            float3 "rtx:post:lensFlares:cutoffPoint" = (2, 2, 2)
            float3 "rtx:post:lensFlares:haloFlareFalloff" = (10, 10, 10)
            float3 "rtx:post:lensFlares:haloFlareRadius" = (75, 75, 75)
            float3 "rtx:post:lensFlares:isotropicFlareFalloff" = (50, 50, 50)
            float3 "rtx:post:lensFlares:spectralBlurWavelengthRange" = (380, 550, 770)
            float3 "rtx:post:tonemap:whitepoint" = (1, 1, 1)
            float3 "rtx:raytracing:indexdirect:svoBrickSize" = (32, 32, 32)
            float3 "rtx:raytracing:inscattering:singleScatteringAlbedo" = (0.9, 0.9, 0.9)
            float3 "rtx:raytracing:inscattering:transmittanceColor" = (0.5, 0.5, 0.5)
            float3 "rtx:sceneDb:ambientLightColor" = (0.1, 0.1, 0.1)
            float2 "rtx:viewTile:resolution" = (0, 0)
        }
    }
    defaultPrim = "ur5e"
    metersPerUnit = 1
    upAxis = "Z"
)

def Mujoco "mujoco" (
    prepend apiSchemas = ["MujocoOptionAPI"]
)
{
    string mujoco:model = "ur5e"
    float mujoco:option:timestep = 0.002

    def MujocoAsset "asset"
    {
        def MujocoMesh "meshes"
        {
            def MujocoMesh "base_0"
            {
                asset mujoco:mesh:file = @ur5e/meshes/stl/base_0.stl@
            }

            def MujocoMesh "base_1"
            {
                asset mujoco:mesh:file = @ur5e/meshes/stl/base_1.stl@
            }

            def MujocoMesh "shoulder_0"
            {
                asset mujoco:mesh:file = @ur5e/meshes/stl/shoulder_0.stl@
            }

            def MujocoMesh "shoulder_1"
            {
                asset mujoco:mesh:file = @ur5e/meshes/stl/shoulder_1.stl@
            }

            def MujocoMesh "shoulder_2"
            {
                asset mujoco:mesh:file = @ur5e/meshes/stl/shoulder_2.stl@
            }

            def MujocoMesh "upperarm_0"
            {
                asset mujoco:mesh:file = @ur5e/meshes/stl/upperarm_0.stl@
            }

            def MujocoMesh "upperarm_1"
            {
                asset mujoco:mesh:file = @ur5e/meshes/stl/upperarm_1.stl@
            }

            def MujocoMesh "upperarm_2"
            {
                asset mujoco:mesh:file = @ur5e/meshes/stl/upperarm_2.stl@
            }

            def MujocoMesh "upperarm_3"
            {
                asset mujoco:mesh:file = @ur5e/meshes/stl/upperarm_3.stl@
            }

            def MujocoMesh "forearm_0"
            {
                asset mujoco:mesh:file = @ur5e/meshes/stl/forearm_0.stl@
            }

            def MujocoMesh "forearm_1"
            {
                asset mujoco:mesh:file = @ur5e/meshes/stl/forearm_1.stl@
            }

            def MujocoMesh "forearm_2"
            {
                asset mujoco:mesh:file = @ur5e/meshes/stl/forearm_2.stl@
            }

            def MujocoMesh "forearm_3"
            {
                asset mujoco:mesh:file = @ur5e/meshes/stl/forearm_3.stl@
            }

            def MujocoMesh "wrist1_0"
            {
                asset mujoco:mesh:file = @ur5e/meshes/stl/wrist1_0.stl@
            }

            def MujocoMesh "wrist1_1"
            {
                asset mujoco:mesh:file = @ur5e/meshes/stl/wrist1_1.stl@
            }

            def MujocoMesh "wrist1_2"
            {
                asset mujoco:mesh:file = @ur5e/meshes/stl/wrist1_2.stl@
            }

            def MujocoMesh "wrist2_0"
            {
                asset mujoco:mesh:file = @ur5e/meshes/stl/wrist2_0.stl@
            }

            def MujocoMesh "wrist2_1"
            {
                asset mujoco:mesh:file = @ur5e/meshes/stl/wrist2_1.stl@
            }

            def MujocoMesh "wrist2_2"
            {
                asset mujoco:mesh:file = @ur5e/meshes/stl/wrist2_2.stl@
            }

            def MujocoMesh "wrist3"
            {
                asset mujoco:mesh:file = @ur5e/meshes/stl/wrist3.stl@
            }
        }

        def MujocoMaterial "materials"
        {
            def MujocoMaterial "black"
            {
                float mujoco:material:emission = 0
                color4f mujoco:material:rgba = (0.033, 0.033, 0.033, 1)
                float mujoco:material:specular = 0.5
            }

            def MujocoMaterial "jointgray"
            {
                float mujoco:material:emission = 0
                color4f mujoco:material:rgba = (0.278, 0.278, 0.278, 1)
                float mujoco:material:specular = 0.5
            }

            def MujocoMaterial "urblue"
            {
                float mujoco:material:emission = 0
                color4f mujoco:material:rgba = (0.49, 0.678, 0.8, 1)
                float mujoco:material:specular = 0.5
            }

            def MujocoMaterial "linkgray"
            {
                float mujoco:material:emission = 0
                color4f mujoco:material:rgba = (0.82, 0.82, 0.82, 1)
                float mujoco:material:specular = 0.5
            }
        }

        def MujocoTexture "textures"
        {
        }
    }

    def MujocoEquality "equality"
    {
    }
}

def Xform "ur5e" (
    delete apiSchemas = ["PhysicsRigidBodyAPI"]
    prepend apiSchemas = ["PhysicsMassAPI"]
)
{
    point3f physics:centerOfMass = (0, 0, 0)
    float3 physics:diagonalInertia = (0, 0, 0)
    float physics:mass = 0
    quatf physics:principalAxes = (1, 0, 0, 0)

    def Xform "base_link" (
        prepend apiSchemas = ["MujocoBodyAPI", "PhysicsMassAPI", "PhysicsRigidBodyAPI", "PhysxRigidBodyAPI"]
    )
    {
        point3f mujoco:body:pos = (0, 0, 0)
        quatf mujoco:body:quat = (0.70710677, 0, 0, 0.70710677)
        point3f physics:centerOfMass = (0, 0, 0)
        float3 physics:diagonalInertia = (0.0044333315, 0.0044333315, 0.0072)
        bool physics:kinematicEnabled = 0
        float physics:mass = 4
        quatf physics:principalAxes = (1, 0, 0, 0)
        bool physics:rigidBodyEnabled = 1
        matrix4d xformOp:transform = ( (2.220446049250313e-16, 0.9999999999999998, 0, 0), (-0.9999999999999998, 2.220446049250313e-16, 0, 0), (0, 0, 1, 0), (0, 0, 0, 1) )
        uniform token[] xformOpOrder = ["xformOp:transform"]

        def Mesh "Geom_0" (
            prepend apiSchemas = ["MujocoGeomAPI", "MaterialBindingAPI", "PhysicsCollisionAPI", "PhysxCollisionAPI", "PhysxConvexHullCollisionAPI", "PhysicsMeshCollisionAPI"]
            prepend references = @./ur5e/meshes/usd/base_0.usda@</base_0>
        )
        {
            rel material:binding = </ur5e/base_link/Geom_0/Materials/black>
            rel mujoco:geom:material = </mujoco/asset/materials/black>
            rel mujoco:geom:mesh = </mujoco/asset/meshes/base_0>
            point3f mujoco:geom:pos = (6.7296133e-7, -3.6582438e-7, 0.09357352)
            quatf mujoco:geom:quat = (0.4247327, 0.56532896, -0.42473835, 0.5653341)
            vector3f mujoco:geom:size = (1, 1, 1)
            uniform token mujoco:geom:type = "mesh"
            uniform token physics:approximation = "convexHull"
            bool physics:collisionEnabled = 1
            color3f[] primvars:displayColor = [(0.5, 0.5, 0.5)]
            float[] primvars:displayOpacity = [1]
            matrix4d xformOp:transform = ( (-0.000010615485162457361, -0.0000019669532778099352, 0.9999999999417242, 0), (-0.960465541694468, -0.27839889206341883, -0.000010743405317925614, 0), (0.27839889206832286, -0.9604655417525397, 0.000001066148458628291, 0), (6.729613291636444e-7, -3.658243672095132e-7, 0.09357351479123255, 1) )
            uniform token[] xformOpOrder = ["xformOp:transform"]

            def Scope "Materials"
            {
                def Material "black" (
                    prepend references = @./ur5e/materials/usd/black.usda@</black>
                )
                {
                }
            }
        }

        def Mesh "Geom_1" (
            prepend apiSchemas = ["MujocoGeomAPI", "MaterialBindingAPI", "PhysicsCollisionAPI", "PhysxCollisionAPI", "PhysxConvexHullCollisionAPI", "PhysicsMeshCollisionAPI"]
            prepend references = @./ur5e/meshes/usd/base_1.usda@</base_1>
        )
        {
            rel material:binding = </ur5e/base_link/Geom_1/Materials/jointgray>
            rel mujoco:geom:material = </mujoco/asset/materials/jointgray>
            rel mujoco:geom:mesh = </mujoco/asset/meshes/base_1>
            point3f mujoco:geom:pos = (1.505097e-7, 5.029438e-7, 0.031134091)
            quatf mujoco:geom:quat = (-0.22746089, 0.66952705, 0.22744595, 0.6695247)
            vector3f mujoco:geom:size = (1, 1, 1)
            uniform token mujoco:geom:type = "mesh"
            uniform token physics:approximation = "convexHull"
            bool physics:collisionEnabled = 1
            color3f[] primvars:displayColor = [(0.5, 0.5, 0.5)]
            float[] primvars:displayOpacity = [1]
            matrix4d xformOp:transform = ( (0.000009939201961461919, -0.000018943927687808948, 0.9999999997711742, 0), (0.6091438304809984, -0.7930597665640762, -0.000021078070432112295, 0), (0.7930597667818973, 0.6091438305511072, 0.000003657195481010511, 0), (1.5050970612118353e-7, 5.029437897684572e-7, 0.03113409208382618, 1) )
            uniform token[] xformOpOrder = ["xformOp:transform"]

            def Scope "Materials"
            {
                def Material "jointgray" (
                    prepend references = @./ur5e/materials/usd/jointgray.usda@</jointgray>
                )
                {
                }
            }
        }

        def PhysicsRevoluteJoint "shoulder_pan_joint" (
            prepend apiSchemas = ["MujocoJointAPI"]
        )
        {
            vector3f mujoco:joint:axis = (0, 0, 1)
            point3f mujoco:joint:pos = (0, 0, 0)
            float2 mujoco:joint:range = (-6.28319, 6.28319)
            uniform token mujoco:joint:type = "hinge"
            uniform token physics:axis = "Z"
            rel physics:body0 = </ur5e/base_link>
            rel physics:body1 = </ur5e/shoulder_link>
            bool physics:collisionEnabled = 0
            point3f physics:localPos0 = (0, 0, 0.163)
            point3f physics:localPos1 = (0, 0, 0)
            quatf physics:localRot0 = (1, 0, 0, 0)
            quatf physics:localRot1 = (1, 0, 0, 0)
            float physics:lowerLimit = -360.00027
            float physics:upperLimit = 360.00027
        }
    }

    def Xform "shoulder_link" (
        prepend apiSchemas = ["MujocoBodyAPI", "PhysicsMassAPI"]
    )
    {
        point3f mujoco:body:pos = (0, 0, 0.163)
        quatf mujoco:body:quat = (1, 0, 0, 0)
        point3f physics:centerOfMass = (0, 0, 0)
        float3 physics:diagonalInertia = (0.0102675, 0.0102675, 0.00666)
        float physics:mass = 3.7
        quatf physics:principalAxes = (1, 0, 0, 0)
        matrix4d xformOp:transform = ( (2.220446049250313e-16, 0.9999999999999998, 0, 0), (-0.9999999999999998, 2.220446049250313e-16, 0, 0), (0, 0, 1, 0), (0, 0, 0.163, 1) )
        uniform token[] xformOpOrder = ["xformOp:transform"]

        def Mesh "Geom_2" (
            prepend apiSchemas = ["MujocoGeomAPI", "MaterialBindingAPI"]
            prepend references = @./ur5e/meshes/usd/shoulder_0.usda@</shoulder_0>
        )
        {
            rel material:binding = </ur5e/shoulder_link/Geom_2/Materials/urblue>
            rel mujoco:geom:material = </mujoco/asset/materials/urblue>
            rel mujoco:geom:mesh = </mujoco/asset/meshes/shoulder_0>
            point3f mujoco:geom:pos = (0.0001579199, -0.008422927, 0.048255444)
            quatf mujoco:geom:quat = (0.4574122, 0.53988844, -0.60698557, 0.36174998)
            vector3f mujoco:geom:size = (1, 1, 1)
            uniform token mujoco:geom:type = "mesh"
            color3f[] primvars:displayColor = [(0.5, 0.5, 0.5)]
            float[] primvars:displayOpacity = [1]
            matrix4d xformOp:transform = ( (0.001410902491394861, -0.3244712672486744, 0.9458945005042605, 0), (-0.9863467060702624, 0.1553148844967851, 0.05474908289732383, 0), (-0.16467599940036287, -0.9330571704798126, -0.31982203150768806, 0), (0.00015791990090556265, -0.008422927184789035, 0.04825544231361248, 1) )
            uniform token[] xformOpOrder = ["xformOp:transform"]

            def Scope "Materials"
            {
                def Material "urblue" (
                    prepend references = @./ur5e/materials/usd/urblue.usda@</urblue>
                )
                {
                }
            }
        }

        def Mesh "Geom_3" (
            prepend apiSchemas = ["MujocoGeomAPI", "MaterialBindingAPI"]
            prepend references = @./ur5e/meshes/usd/shoulder_1.usda@</shoulder_1>
        )
        {
            rel material:binding = </ur5e/shoulder_link/Geom_3/Materials/black>
            rel mujoco:geom:material = </mujoco/asset/materials/black>
            rel mujoco:geom:mesh = </mujoco/asset/meshes/shoulder_1>
            point3f mujoco:geom:pos = (0.0000010221603, 0.068884626, -0.0005032848)
            quatf mujoco:geom:quat = (0.7045508, 0.060027406, 0.06001699, 0.7045586)
            vector3f mujoco:geom:size = (1, 1, 1)
            uniform token mujoco:geom:type = "mesh"
            color3f[] primvars:displayColor = [(0.5, 0.5, 0.5)]
            float[] primvars:displayOpacity = [1]
            matrix4d xformOp:transform = ( (-0.000009831581220698382, 0.9999999998296344, 0.000015622871639975333, 0), (-0.9855893430755719, -0.000012332599274023082, 0.16915568764831004, 0), (0.1691556878121621, -0.000013734667914794274, 0.9855893430289074, 0), (0.0000010221602485018881, 0.06888462434941042, -0.0005032847963257957, 1) )
            uniform token[] xformOpOrder = ["xformOp:transform"]

            def Scope "Materials"
            {
                def Material "black" (
                    prepend references = @./ur5e/materials/usd/black.usda@</black>
                )
                {
                }
            }
        }

        def Mesh "Geom_4" (
            prepend apiSchemas = ["MujocoGeomAPI", "MaterialBindingAPI"]
            prepend references = @./ur5e/meshes/usd/shoulder_2.usda@</shoulder_2>
        )
        {
            rel material:binding = </ur5e/shoulder_link/Geom_4/Materials/jointgray>
            rel mujoco:geom:material = </mujoco/asset/materials/jointgray>
            rel mujoco:geom:mesh = </mujoco/asset/meshes/shoulder_2>
            point3f mujoco:geom:pos = (-0.000049871116, 0.000563615, -0.018757718)
            quatf mujoco:geom:quat = (0.6390854, 0.3009769, 0.6553343, 0.2674318)
            vector3f mujoco:geom:size = (1, 1, 1)
            uniform token mujoco:geom:type = "mesh"
            color3f[] primvars:displayColor = [(0.5, 0.5, 0.5)]
            float[] primvars:displayOpacity = [1]
            matrix4d xformOp:transform = ( (-0.00196552902692404, 0.7363044671257264, -0.6766475215253136, 0), (0.05265747552036992, 0.6757862721745562, 0.7352143256304517, 0), (0.9986106984042737, -0.034185465202602905, -0.04010021198716851, 0), (-0.00004987111589031359, 0.0005636150230643856, -0.01875771788843443, 1) )
            uniform token[] xformOpOrder = ["xformOp:transform"]

            def Scope "Materials"
            {
                def Material "jointgray" (
                    prepend references = @./ur5e/materials/usd/jointgray.usda@</jointgray>
                )
                {
                }
            }
        }

        def Cylinder "Geom_5" (
            prepend apiSchemas = ["PhysicsCollisionAPI", "MujocoGeomAPI"]
        )
        {
            float3[] extent = [(-0.06, -0.06, -0.06), (0.06, 0.06, 0.06)]
            double height = 0.12
            point3f mujoco:geom:pos = (0, 0, -0.04)
            quatf mujoco:geom:quat = (1, 0, 0, 0)
            vector3f mujoco:geom:size = (0.06, 0.06, 0)
            uniform token mujoco:geom:type = "capsule"
            bool physics:collisionEnabled = 1
            color3f[] primvars:displayColor = [(0.5, 0.5, 0.5)]
            float[] primvars:displayOpacity = [1]
            double radius = 0.06
            token visibility = "invisible"
            matrix4d xformOp:transform = ( (1, 0, 0, 0), (0, 1, 0, 0), (0, 0, 1, 0), (0, 0, -0.04, 1) )
            uniform token[] xformOpOrder = ["xformOp:transform"]
        }

        def PhysicsRevoluteJoint "shoulder_lift_joint" (
            prepend apiSchemas = ["MujocoJointAPI"]
        )
        {
            vector3f mujoco:joint:axis = (0, 1, 0)
            point3f mujoco:joint:pos = (0, 0, 0)
            float2 mujoco:joint:range = (-6.28319, 6.28319)
            uniform token mujoco:joint:type = "hinge"
            uniform token physics:axis = "Z"
            rel physics:body0 = </ur5e/shoulder_link>
            rel physics:body1 = </ur5e/upper_arm_link>
            bool physics:collisionEnabled = 0
            point3f physics:localPos0 = (0, 0.138, 0)
            point3f physics:localPos1 = (0, 0, 0)
            quatf physics:localRot0 = (0.5, -0.5, 0.5, 0.5)
            quatf physics:localRot1 = (0.7071068, -0.7071068, 0, 0)
            float physics:lowerLimit = -360.00027
            float physics:upperLimit = 360.00027
        }
    }

    def Xform "upper_arm_link" (
        prepend apiSchemas = ["MujocoBodyAPI", "PhysicsMassAPI"]
    )
    {
        point3f mujoco:body:pos = (0, 0.138, 0)
        quatf mujoco:body:quat = (0.70710677, 0, 0.70710677, 0)
        point3f physics:centerOfMass = (0, 0, 0.2125)
        float3 physics:diagonalInertia = (0.133886, 0.133886, 0.0151074)
        float physics:mass = 8.393
        quatf physics:principalAxes = (1, 0, 0, 0)
        matrix4d xformOp:transform = ( (4.930380657631324e-32, 2.2204460492503126e-16, -0.9999999999999998, 0), (-0.9999999999999998, 2.220446049250313e-16, 0, 0), (2.2204460492503126e-16, 0.9999999999999996, 2.220446049250313e-16, 0), (-0.13799999999999998, 3.064215547965432e-17, 0.163, 1) )
        uniform token[] xformOpOrder = ["xformOp:transform"]

        def Mesh "Geom_6" (
            prepend apiSchemas = ["MujocoGeomAPI", "MaterialBindingAPI"]
            prepend references = @./ur5e/meshes/usd/upperarm_0.usda@</upperarm_0>
        )
        {
            rel material:binding = </ur5e/upper_arm_link/Geom_6/Materials/linkgray>
            rel mujoco:geom:material = </mujoco/asset/materials/linkgray>
            rel mujoco:geom:mesh = </mujoco/asset/meshes/upperarm_0>
            point3f mujoco:geom:pos = (-0.0000035760645, -0.00019999969, 0.21213518)
            quatf mujoco:geom:quat = (0.9842776, -0.00016280472, 0.000028460901, -0.17662817)
            vector3f mujoco:geom:size = (1, 1, 1)
            uniform token mujoco:geom:type = "mesh"
            color3f[] primvars:displayColor = [(0.5, 0.5, 0.5)]
            float[] primvars:displayOpacity = [1]
            matrix4d xformOp:transform = ( (0.9376049803474907, -0.34770231639345806, 0.0000014849425660471327, 0), (0.3477022978591823, 0.9376049289567825, -0.0003305440837917095, 0), (0.0001135386541353872, 0.00031043609712990864, 0.9999999453692003, 0), (-0.0000035760646000637493, -0.00019999968769833566, 0.21213517773732127, 1) )
            uniform token[] xformOpOrder = ["xformOp:transform"]

            def Scope "Materials"
            {
                def Material "linkgray" (
                    prepend references = @./ur5e/materials/usd/linkgray.usda@</linkgray>
                )
                {
                }
            }
        }

        def Mesh "Geom_7" (
            prepend apiSchemas = ["MujocoGeomAPI", "MaterialBindingAPI"]
            prepend references = @./ur5e/meshes/usd/upperarm_1.usda@</upperarm_1>
        )
        {
            rel material:binding = </ur5e/upper_arm_link/Geom_7/Materials/black>
            rel mujoco:geom:material = </mujoco/asset/materials/black>
            rel mujoco:geom:mesh = </mujoco/asset/meshes/upperarm_1>
            point3f mujoco:geom:pos = (-7.533427e-7, -0.024559025, 0.29812747)
            quatf mujoco:geom:quat = (0.99607927, 0.08846509, 0.000018374092, -0.00024359496)
            vector3f mujoco:geom:size = (1, 1, 1)
            uniform token mujoco:geom:type = "mesh"
            color3f[] primvars:displayColor = [(0.5, 0.5, 0.5)]
            float[] primvars:displayOpacity = [1]
            matrix4d xformOp:transform = ( (0.9999998806477723, -0.00048202884594790034, -0.00007970340480369244, 0), (0.0004885307088366186, 0.9843477369171281, 0.1762364722861725, 0), (-0.000006495197206928452, -0.1762364901895178, 0.9843478549189267, 0), (-7.533427155925417e-7, -0.02455902479462408, 0.2981274589864789, 1) )
            uniform token[] xformOpOrder = ["xformOp:transform"]

            def Scope "Materials"
            {
                def Material "black" (
                    prepend references = @./ur5e/materials/usd/black.usda@</black>
                )
                {
                }
            }
        }

        def Mesh "Geom_8" (
            prepend apiSchemas = ["MujocoGeomAPI", "MaterialBindingAPI"]
            prepend references = @./ur5e/meshes/usd/upperarm_2.usda@</upperarm_2>
        )
        {
            rel material:binding = </ur5e/upper_arm_link/Geom_8/Materials/jointgray>
            rel mujoco:geom:material = </mujoco/asset/materials/jointgray>
            rel mujoco:geom:mesh = </mujoco/asset/meshes/upperarm_2>
            point3f mujoco:geom:pos = (0.000012475194, -0.020613765, 0.2135478)
            quatf mujoco:geom:quat = (0.7064585, 0.0033099835, -0.0033342245, 0.7077388)
            vector3f mujoco:geom:size = (1, 1, 1)
            uniform token mujoco:geom:type = "mesh"
            color3f[] primvars:displayColor = [(0.5, 0.5, 0.5)]
            float[] primvars:displayOpacity = [1]
            matrix4d xformOp:transform = ( (-0.0018107579933028806, 0.9999542153335294, 0.00939619030233708, 0), (-0.9999983602442327, -0.0018104358709361001, -0.00004278791250212407, 0), (-0.000025774753498339353, -0.00939625237343441, 0.9999558539140599, 0), (0.000012475193933552453, -0.020613766259404608, 0.21354779136318264, 1) )
            uniform token[] xformOpOrder = ["xformOp:transform"]

            def Scope "Materials"
            {
                def Material "jointgray" (
                    prepend references = @./ur5e/materials/usd/jointgray.usda@</jointgray>
                )
                {
                }
            }
        }

        def Mesh "Geom_9" (
            prepend apiSchemas = ["MujocoGeomAPI", "MaterialBindingAPI"]
            prepend references = @./ur5e/meshes/usd/upperarm_3.usda@</upperarm_3>
        )
        {
            rel material:binding = </ur5e/upper_arm_link/Geom_9/Materials/urblue>
            rel mujoco:geom:material = </mujoco/asset/materials/urblue>
            rel mujoco:geom:mesh = </mujoco/asset/meshes/upperarm_3>
            point3f mujoco:geom:pos = (-0.00001673886, 0.045309722, 0.21224046)
            quatf mujoco:geom:quat = (0.7069376, 0.00011442576, -0.0001222678, 0.70727587)
            vector3f mujoco:geom:size = (1, 1, 1)
            uniform token mujoco:geom:type = "mesh"
            color3f[] primvars:displayColor = [(0.5, 0.5, 0.5)]
            float[] primvars:displayOpacity = [1]
            matrix4d xformOp:transform = ( (-0.00047838120998400235, 0.9999998295527469, 0.00033473257666317784, 0), (-0.999999885515091, -0.0004783774976631072, -0.000011170384572600805, 0), (-0.00001101025413622944, -0.00033473788204343665, 0.9999999439146607, 0), (-0.000016738860146607153, 0.04530972331282584, 0.21224046051237042, 1) )
            uniform token[] xformOpOrder = ["xformOp:transform"]

            def Scope "Materials"
            {
                def Material "urblue" (
                    prepend references = @./ur5e/materials/usd/urblue.usda@</urblue>
                )
                {
                }
            }
        }

        def Cylinder "Geom_10" (
            prepend apiSchemas = ["PhysicsCollisionAPI", "MujocoGeomAPI"]
        )
        {
            float3[] extent = [(-0.06, -0.06, -0.06), (0.06, 0.06, 0.06)]
            double height = 0.12
            point3f mujoco:geom:pos = (0, -0.04, 0)
            quatf mujoco:geom:quat = (0.70710677, 0.70710677, 0, 0)
            vector3f mujoco:geom:size = (0.06, 0.06, 0)
            uniform token mujoco:geom:type = "capsule"
            bool physics:collisionEnabled = 1
            color3f[] primvars:displayColor = [(0.5, 0.5, 0.5)]
            float[] primvars:displayOpacity = [1]
            double radius = 0.06
            token visibility = "invisible"
            matrix4d xformOp:transform = ( (1, 0, 0, 0), (0, 2.220446049250313e-16, 0.9999999999999998, 0), (0, -0.9999999999999998, 2.220446049250313e-16, 0), (0, -0.04, 0, 1) )
            uniform token[] xformOpOrder = ["xformOp:transform"]
        }

        def Cylinder "Geom_11" (
            prepend apiSchemas = ["PhysicsCollisionAPI", "MujocoGeomAPI"]
        )
        {
            float3[] extent = [(-0.05, -0.05, -0.2), (0.05, 0.05, 0.2)]
            double height = 0.4
            point3f mujoco:geom:pos = (0, 0, 0.2)
            quatf mujoco:geom:quat = (1, 0, 0, 0)
            vector3f mujoco:geom:size = (0.05, 0.2, 0)
            uniform token mujoco:geom:type = "capsule"
            bool physics:collisionEnabled = 1
            color3f[] primvars:displayColor = [(0.5, 0.5, 0.5)]
            float[] primvars:displayOpacity = [1]
            double radius = 0.05
            token visibility = "invisible"
            matrix4d xformOp:transform = ( (1, 0, 0, 0), (0, 1, 0, 0), (0, 0, 1, 0), (0, 0, 0.2, 1) )
            uniform token[] xformOpOrder = ["xformOp:transform"]
        }

        def PhysicsRevoluteJoint "elbow_joint" (
            prepend apiSchemas = ["MujocoJointAPI"]
        )
        {
            vector3f mujoco:joint:axis = (0, 1, 0)
            point3f mujoco:joint:pos = (0, 0, 0)
            float2 mujoco:joint:range = (-3.1415, 3.1415)
            uniform token mujoco:joint:type = "hinge"
            uniform token physics:axis = "Z"
            rel physics:body0 = </ur5e/upper_arm_link>
            rel physics:body1 = </ur5e/forearm_link>
            bool physics:collisionEnabled = 0
            point3f physics:localPos0 = (0, -0.131, 0.425)
            point3f physics:localPos1 = (0, 0, 0)
            quatf physics:localRot0 = (0.7071068, -0.7071068, 0, 0)
            quatf physics:localRot1 = (0.7071068, -0.7071068, 0, 0)
            float physics:lowerLimit = -179.99469
            float physics:upperLimit = 179.99469
        }
    }

    def Xform "forearm_link" (
        prepend apiSchemas = ["MujocoBodyAPI", "PhysicsMassAPI"]
    )
    {
        point3f mujoco:body:pos = (0, -0.131, 0.425)
        quatf mujoco:body:quat = (1, 0, 0, 0)
        point3f physics:centerOfMass = (0, 0, 0.196)
        float3 physics:diagonalInertia = (0.0311796, 0.0311796, 0.004095)
        float physics:mass = 2.275
        quatf physics:principalAxes = (1, 0, 0, 0)
        matrix4d xformOp:transform = ( (4.930380657631324e-32, 2.2204460492503126e-16, -0.9999999999999998, 0), (-0.9999999999999998, 2.220446049250313e-16, 0, 0), (2.2204460492503126e-16, 0.9999999999999996, 2.220446049250313e-16, 0), (-0.006999999999999923, 0.4249999999999998, 0.1630000000000001, 1) )
        uniform token[] xformOpOrder = ["xformOp:transform"]

        def Mesh "Geom_12" (
            prepend apiSchemas = ["MujocoGeomAPI", "MaterialBindingAPI"]
            prepend references = @./ur5e/meshes/usd/forearm_0.usda@</forearm_0>
        )
        {
            rel material:binding = </ur5e/forearm_link/Geom_12/Materials/urblue>
            rel mujoco:geom:material = </mujoco/asset/materials/urblue>
            rel mujoco:geom:mesh = </mujoco/asset/meshes/forearm_0>
            point3f mujoco:geom:pos = (0.00002620745, -0.03986928, 0.39588937)
            quatf mujoco:geom:quat = (0.7046946, -0.057185028, 0.16114429, 0.68859845)
            vector3f mujoco:geom:size = (1, 1, 1)
            uniform token mujoco:geom:type = "mesh"
            color3f[] primvars:displayColor = [(0.5, 0.5, 0.5)]
            float[] primvars:displayOpacity = [1]
            matrix4d xformOp:transform = ( (-0.00027065455778685354, 0.9520732211475884, -0.30587008405492827, 0), (-0.9889333841793724, 0.04512405646222961, 0.14133145857851565, 0), (0.14835999596133614, 0.3025233893470915, 0.9415247795444901, 0), (0.000026207450606710292, -0.039869278793902285, 0.3958893860897068, 1) )
            uniform token[] xformOpOrder = ["xformOp:transform"]

            def Scope "Materials"
            {
                def Material "urblue" (
                    prepend references = @./ur5e/materials/usd/urblue.usda@</urblue>
                )
                {
                }
            }
        }

        def Mesh "Geom_13" (
            prepend apiSchemas = ["MujocoGeomAPI", "MaterialBindingAPI"]
            prepend references = @./ur5e/meshes/usd/forearm_1.usda@</forearm_1>
        )
        {
            rel material:binding = </ur5e/forearm_link/Geom_13/Materials/linkgray>
            rel mujoco:geom:material = </mujoco/asset/materials/linkgray>
            rel mujoco:geom:mesh = </mujoco/asset/meshes/forearm_1>
            point3f mujoco:geom:pos = (-0.000023636832, -0.00043409114, 0.20434308)
            quatf mujoco:geom:quat = (0.7858982, 0.00030249593, -0.00011293544, 0.6183558)
            vector3f mujoco:geom:size = (1, 1, 1)
            uniform token mujoco:geom:type = "mesh"
            color3f[] primvars:displayColor = [(0.5, 0.5, 0.5)]
            float[] primvars:displayOpacity = [1]
            matrix4d xformOp:transform = ( (0.23527211658807168, 0.9719293836903089, 0.0005516117718460988, 0), (-0.9719295203403597, 0.23527195908931609, 0.0003357934414239298, 0), (0.00019658873035144654, -0.0006151305985246751, 0.9999997914835872, 0), (-0.000023636833205504254, -0.0004340911527384576, 0.20434307929108567, 1) )
            uniform token[] xformOpOrder = ["xformOp:transform"]

            def Scope "Materials"
            {
                def Material "linkgray" (
                    prepend references = @./ur5e/materials/usd/linkgray.usda@</linkgray>
                )
                {
                }
            }
        }

        def Mesh "Geom_14" (
            prepend apiSchemas = ["MujocoGeomAPI", "MaterialBindingAPI"]
            prepend references = @./ur5e/meshes/usd/forearm_2.usda@</forearm_2>
        )
        {
            rel material:binding = </ur5e/forearm_link/Geom_14/Materials/black>
            rel mujoco:geom:material = </mujoco/asset/materials/black>
            rel mujoco:geom:mesh = </mujoco/asset/meshes/forearm_2>
            point3f mujoco:geom:pos = (-0.000009661517, 0.01697651, 0.25503904)
            quatf mujoco:geom:quat = (0.99732256, -0.073086165, 0.00014625516, 0.002477442)
            vector3f mujoco:geom:size = (1, 1, 1)
            uniform token mujoco:geom:type = "mesh"
            color3f[] primvars:displayColor = [(0.5, 0.5, 0.5)]
            float[] primvars:displayOpacity = [1]
            matrix4d xformOp:transform = ( (0.9999876817808967, 0.004920239096459412, -0.0006538606134088193, 0), (-0.00496299601235621, 0.9893045499997645, -0.14578023192581677, 0), (-0.0000704063167013422, 0.14578168128059596, 0.9893167826565732, 0), (-0.000009661516749736769, 0.01697650909542407, 0.25503902244340926, 1) )
            uniform token[] xformOpOrder = ["xformOp:transform"]

            def Scope "Materials"
            {
                def Material "black" (
                    prepend references = @./ur5e/materials/usd/black.usda@</black>
                )
                {
                }
            }
        }

        def Mesh "Geom_15" (
            prepend apiSchemas = ["MujocoGeomAPI", "MaterialBindingAPI"]
            prepend references = @./ur5e/meshes/usd/forearm_3.usda@</forearm_3>
        )
        {
            rel material:binding = </ur5e/forearm_link/Geom_15/Materials/jointgray>
            rel mujoco:geom:material = </mujoco/asset/materials/jointgray>
            rel mujoco:geom:mesh = </mujoco/asset/meshes/forearm_3>
            point3f mujoco:geom:pos = (0.0000029752032, 0.0119606685, 0.16361682)
            quatf mujoco:geom:quat = (0.7067976, -0.0071781436, 0.0071936604, 0.7073428)
            vector3f mujoco:geom:size = (1, 1, 1)
            uniform token mujoco:geom:type = "mesh"
            color3f[] primvars:displayColor = [(0.5, 0.5, 0.5)]
            float[] primvars:displayOpacity = [1]
            matrix4d xformOp:transform = ( (-0.0007711704551374154, 0.9997931540387415, -0.020323740634968328, 0), (-0.9999997025484995, -0.0007707244367582966, 0.000029778486211646735, 0), (0.000014108323098362824, 0.020323757553929914, 0.9997934510086792, 0), (0.0000029752030802592747, 0.011960668315823576, 0.16361682552290555, 1) )
            uniform token[] xformOpOrder = ["xformOp:transform"]

            def Scope "Materials"
            {
                def Material "jointgray" (
                    prepend references = @./ur5e/materials/usd/jointgray.usda@</jointgray>
                )
                {
                }
            }
        }

        def Cylinder "Geom_16" (
            prepend apiSchemas = ["PhysicsCollisionAPI", "MujocoGeomAPI"]
        )
        {
            float3[] extent = [(-0.055, -0.055, -0.06), (0.055, 0.055, 0.06)]
            double height = 0.12
            point3f mujoco:geom:pos = (0, 0.08, 0)
            quatf mujoco:geom:quat = (0.70710677, 0.70710677, 0, 0)
            vector3f mujoco:geom:size = (0.055, 0.06, 0)
            uniform token mujoco:geom:type = "capsule"
            bool physics:collisionEnabled = 1
            color3f[] primvars:displayColor = [(0.5, 0.5, 0.5)]
            float[] primvars:displayOpacity = [1]
            double radius = 0.055
            token visibility = "invisible"
            matrix4d xformOp:transform = ( (1, 0, 0, 0), (0, 2.220446049250313e-16, 0.9999999999999998, 0), (0, -0.9999999999999998, 2.220446049250313e-16, 0), (0, 0.08, 0, 1) )
            uniform token[] xformOpOrder = ["xformOp:transform"]
        }

        def Cylinder "Geom_17" (
            prepend apiSchemas = ["PhysicsCollisionAPI", "MujocoGeomAPI"]
        )
        {
            float3[] extent = [(-0.038, -0.038, -0.19), (0.038, 0.038, 0.19)]
            double height = 0.38
            point3f mujoco:geom:pos = (0, 0, 0.2)
            quatf mujoco:geom:quat = (1, 0, 0, 0)
            vector3f mujoco:geom:size = (0.038, 0.19, 0)
            uniform token mujoco:geom:type = "capsule"
            bool physics:collisionEnabled = 1
            color3f[] primvars:displayColor = [(0.5, 0.5, 0.5)]
            float[] primvars:displayOpacity = [1]
            double radius = 0.038
            token visibility = "invisible"
            matrix4d xformOp:transform = ( (1, 0, 0, 0), (0, 1, 0, 0), (0, 0, 1, 0), (0, 0, 0.2, 1) )
            uniform token[] xformOpOrder = ["xformOp:transform"]
        }

        def PhysicsRevoluteJoint "wrist_1_joint" (
            prepend apiSchemas = ["MujocoJointAPI"]
        )
        {
            vector3f mujoco:joint:axis = (0, 1, 0)
            point3f mujoco:joint:pos = (0, 0, 0)
            float2 mujoco:joint:range = (-6.28319, 6.28319)
            uniform token mujoco:joint:type = "hinge"
            uniform token physics:axis = "Z"
            rel physics:body0 = </ur5e/forearm_link>
            rel physics:body1 = </ur5e/wrist_1_link>
            bool physics:collisionEnabled = 0
            point3f physics:localPos0 = (2.7755576e-17, 8.6736174e-19, 0.392)
            point3f physics:localPos1 = (0, 0, 0)
            quatf physics:localRot0 = (0.5, -0.5, 0.5, 0.5)
            quatf physics:localRot1 = (0.7071068, -0.7071068, 0, 0)
            float physics:lowerLimit = -360.00027
            float physics:upperLimit = 360.00027
        }
    }

    def Xform "wrist_1_link" (
        prepend apiSchemas = ["MujocoBodyAPI", "PhysicsMassAPI"]
    )
    {
        point3f mujoco:body:pos = (0, 0, 0.392)
        quatf mujoco:body:quat = (0.70710677, 0, 0.70710677, 0)
        point3f physics:centerOfMass = (0, 0.127, 0)
        float3 physics:diagonalInertia = (0.0025599, 0.0025599, 0.0021942)
        float physics:mass = 1.219
        quatf physics:principalAxes = (1, 0, 0, 0)
        matrix4d xformOp:transform = ( (-2.220446049250312e-16, -0.9999999999999993, -4.440892098500625e-16, 0), (-0.9999999999999998, 2.220446049250313e-16, 0, 0), (9.860761315262645e-32, 4.440892098500624e-16, -0.9999999999999996, 0), (-0.006999999999999836, 0.8169999999999997, 0.16300000000000017, 1) )
        uniform token[] xformOpOrder = ["xformOp:transform"]

        def Mesh "Geom_18" (
            prepend apiSchemas = ["MujocoGeomAPI", "MaterialBindingAPI"]
            prepend references = @./ur5e/meshes/usd/wrist1_0.usda@</wrist1_0>
        )
        {
            rel material:binding = </ur5e/wrist_1_link/Geom_18/Materials/black>
            rel mujoco:geom:material = </mujoco/asset/materials/black>
            rel mujoco:geom:mesh = </mujoco/asset/meshes/wrist1_0>
            point3f mujoco:geom:pos = (-0.000023247816, 0.12628514, 0.048975058)
            quatf mujoco:geom:quat = (-0.14090557, 0.6929781, 0.14077793, 0.6928987)
            vector3f mujoco:geom:size = (1, 1, 1)
            uniform token mujoco:geom:type = "mesh"
            color3f[] primvars:displayColor = [(0.5, 0.5, 0.5)]
            float[] primvars:displayOpacity = [1]
            matrix4d xformOp:transform = ( (0.00014597261243920467, -0.00015453494917827548, 0.9999999774054766, 0), (0.39037860343596553, -0.9206543902440818, -0.00019925786849472882, 0), (0.9206544002346317, 0.39037862370173715, -0.00007406318886271634, 0), (-0.00002324781546803138, 0.12628514057599924, 0.04897505965681284, 1) )
            uniform token[] xformOpOrder = ["xformOp:transform"]

            def Scope "Materials"
            {
                def Material "black" (
                    prepend references = @./ur5e/materials/usd/black.usda@</black>
                )
                {
                }
            }
        }

        def Mesh "Geom_19" (
            prepend apiSchemas = ["MujocoGeomAPI", "MaterialBindingAPI"]
            prepend references = @./ur5e/meshes/usd/wrist1_1.usda@</wrist1_1>
        )
        {
            rel material:binding = </ur5e/wrist_1_link/Geom_19/Materials/urblue>
            rel mujoco:geom:material = </mujoco/asset/materials/urblue>
            rel mujoco:geom:mesh = </mujoco/asset/meshes/wrist1_1>
            point3f mujoco:geom:pos = (-0.000036644615, 0.13040179, -0.03970349)
            quatf mujoco:geom:quat = (0.3947796, 0.5868229, -0.5545021, 0.43853766)
            vector3f mujoco:geom:size = (1, 1, 1)
            uniform token mujoco:geom:type = "mesh"
            color3f[] primvars:displayColor = [(0.5, 0.5, 0.5)]
            float[] primvars:displayOpacity = [1]
            matrix4d xformOp:transform = ( (0.00042419962231976527, -0.30453773437056014, 0.9525001776373234, 0), (-0.9970405965959412, -0.07335290598107402, -0.023008692351971727, 0), (0.07687567101688236, -0.9496715850906483, -0.30366760063781495, 0), (-0.000036644614818292445, 0.13040179175860142, -0.039703488660788, 1) )
            uniform token[] xformOpOrder = ["xformOp:transform"]

            def Scope "Materials"
            {
                def Material "urblue" (
                    prepend references = @./ur5e/materials/usd/urblue.usda@</urblue>
                )
                {
                }
            }
        }

        def Mesh "Geom_20" (
            prepend apiSchemas = ["MujocoGeomAPI", "MaterialBindingAPI"]
            prepend references = @./ur5e/meshes/usd/wrist1_2.usda@</wrist1_2>
        )
        {
            rel material:binding = </ur5e/wrist_1_link/Geom_20/Materials/jointgray>
            rel mujoco:geom:material = </mujoco/asset/materials/jointgray>
            rel mujoco:geom:mesh = </mujoco/asset/meshes/wrist1_2>
            point3f mujoco:geom:pos = (-0.0000020991024, 0.11289622, 0.012388334)
            quatf mujoco:geom:quat = (0.34823856, 0.6150896, -0.615513, 0.34862366)
            vector3f mujoco:geom:size = (1, 1, 1)
            uniform token mujoco:geom:type = "mesh"
            color3f[] primvars:displayColor = [(0.5, 0.5, 0.5)]
            float[] primvars:displayOpacity = [1]
            matrix4d xformOp:transform = ( (-0.0007894481374617346, -0.5143828678489163, 0.8575602847818738, 0), (-0.99999967239794, 0.0002527319341811829, -0.0007689802261526824, 0), (0.00017881738459490926, -0.8575606109133627, -0.5143828988547854, 0), (-0.0000020991024420246793, 0.11289621782275673, 0.01238833387042214, 1) )
            uniform token[] xformOpOrder = ["xformOp:transform"]

            def Scope "Materials"
            {
                def Material "jointgray" (
                    prepend references = @./ur5e/materials/usd/jointgray.usda@</jointgray>
                )
                {
                }
            }
        }

        def Cylinder "Geom_21" (
            prepend apiSchemas = ["PhysicsCollisionAPI", "MujocoGeomAPI"]
        )
        {
            float3[] extent = [(-0.04, -0.04, -0.07), (0.04, 0.04, 0.07)]
            double height = 0.14
            point3f mujoco:geom:pos = (0, 0.05, 0)
            quatf mujoco:geom:quat = (0.70710677, 0.70710677, 0, 0)
            vector3f mujoco:geom:size = (0.04, 0.07, 0)
            uniform token mujoco:geom:type = "capsule"
            bool physics:collisionEnabled = 1
            color3f[] primvars:displayColor = [(0.5, 0.5, 0.5)]
            float[] primvars:displayOpacity = [1]
            double radius = 0.04
            token visibility = "invisible"
            matrix4d xformOp:transform = ( (1, 0, 0, 0), (0, 2.220446049250313e-16, 0.9999999999999998, 0), (0, -0.9999999999999998, 2.220446049250313e-16, 0), (0, 0.05, 0, 1) )
            uniform token[] xformOpOrder = ["xformOp:transform"]
        }

        def PhysicsRevoluteJoint "wrist_2_joint" (
            prepend apiSchemas = ["MujocoJointAPI"]
        )
        {
            vector3f mujoco:joint:axis = (0, 0, 1)
            point3f mujoco:joint:pos = (0, 0, 0)
            float2 mujoco:joint:range = (-6.28319, 6.28319)
            uniform token mujoco:joint:type = "hinge"
            uniform token physics:axis = "Z"
            rel physics:body0 = </ur5e/wrist_1_link>
            rel physics:body1 = </ur5e/wrist_2_link>
            bool physics:collisionEnabled = 0
            point3f physics:localPos0 = (0, 0.127, 0)
            point3f physics:localPos1 = (0, 0, 0)
            quatf physics:localRot0 = (1, 0, 0, 0)
            quatf physics:localRot1 = (1, 0, 0, 0)
            float physics:lowerLimit = -360.00027
            float physics:upperLimit = 360.00027
        }
    }

    def Xform "wrist_2_link" (
        prepend apiSchemas = ["MujocoBodyAPI", "PhysicsMassAPI"]
    )
    {
        point3f mujoco:body:pos = (0, 0.127, 0)
        quatf mujoco:body:quat = (1, 0, 0, 0)
        point3f physics:centerOfMass = (0, 0, 0.1)
        float3 physics:diagonalInertia = (0.0025599, 0.0025599, 0.0021942)
        float physics:mass = 1.219
        quatf physics:principalAxes = (1, 0, 0, 0)
        matrix4d xformOp:transform = ( (-2.220446049250312e-16, -0.9999999999999993, -4.440892098500625e-16, 0), (-0.9999999999999998, 2.220446049250313e-16, 0, 0), (9.860761315262645e-32, 4.440892098500624e-16, -0.9999999999999996, 0), (-0.1339999999999998, 0.8169999999999997, 0.16300000000000017, 1) )
        uniform token[] xformOpOrder = ["xformOp:transform"]

        def Mesh "Geom_22" (
            prepend apiSchemas = ["MujocoGeomAPI", "MaterialBindingAPI"]
            prepend references = @./ur5e/meshes/usd/wrist2_0.usda@</wrist2_0>
        )
        {
            rel material:binding = </ur5e/wrist_2_link/Geom_22/Materials/black>
            rel mujoco:geom:material = </mujoco/asset/materials/black>
            rel mujoco:geom:mesh = </mujoco/asset/meshes/wrist2_0>
            point3f mujoco:geom:pos = (-0.0000038001244, 0.048536457, 0.099435806)
            quatf mujoco:geom:quat = (0.7043315, 0.06266733, 0.062667474, 0.70431715)
            vector3f mujoco:geom:size = (1, 1, 1)
            uniform token mujoco:geom:type = "mesh"
            color3f[] primvars:displayColor = [(0.5, 0.5, 0.5)]
            float[] primvars:displayOpacity = [1]
            matrix4d xformOp:transform = ( (0.000020213581733985464, 0.9999999997937065, -0.0000020002688767839505, 0), (-0.9842911859950053, 0.000020249203240840785, 0.1765527138350429, 0), (0.1765527138391248, -0.0000015999156866841613, 0.9842911862012584, 0), (-0.000003800124318643313, 0.048536456164498844, 0.09943580405134815, 1) )
            uniform token[] xformOpOrder = ["xformOp:transform"]

            def Scope "Materials"
            {
                def Material "black" (
                    prepend references = @./ur5e/materials/usd/black.usda@</black>
                )
                {
                }
            }
        }

        def Mesh "Geom_23" (
            prepend apiSchemas = ["MujocoGeomAPI", "MaterialBindingAPI"]
            prepend references = @./ur5e/meshes/usd/wrist2_1.usda@</wrist2_1>
        )
        {
            rel material:binding = </ur5e/wrist_2_link/Geom_23/Materials/urblue>
            rel mujoco:geom:material = </mujoco/asset/materials/urblue>
            rel mujoco:geom:mesh = </mujoco/asset/meshes/wrist2_1>
            point3f mujoco:geom:pos = (0.00003169642, -0.040206056, 0.103591196)
            quatf mujoco:geom:quat = (0.703503, -0.07002305, 0.14760865, 0.69165885)
            vector3f mujoco:geom:size = (1, 1, 1)
            uniform token mujoco:geom:type = "mesh"
            color3f[] primvars:displayColor = [(0.5, 0.5, 0.5)]
            float[] primvars:displayOpacity = [1]
            matrix4d xformOp:transform = ( (-0.0003605688563859122, 0.9524961545978589, -0.30455039889383545, 0), (-0.9938401902351516, 0.033409605746194004, 0.10566680896688571, 0), (0.11082213796647461, 0.30271252653330727, 0.9466169130204476, 0), (0.00003169641991937526, -0.04020605573983935, 0.10359119909236272, 1) )
            uniform token[] xformOpOrder = ["xformOp:transform"]

            def Scope "Materials"
            {
                def Material "urblue" (
                    prepend references = @./ur5e/materials/usd/urblue.usda@</urblue>
                )
                {
                }
            }
        }

        def Mesh "Geom_24" (
            prepend apiSchemas = ["MujocoGeomAPI", "MaterialBindingAPI"]
            prepend references = @./ur5e/meshes/usd/wrist2_2.usda@</wrist2_2>
        )
        {
            rel material:binding = </ur5e/wrist_2_link/Geom_24/Materials/jointgray>
            rel mujoco:geom:material = </mujoco/asset/materials/jointgray>
            rel mujoco:geom:mesh = </mujoco/asset/meshes/wrist2_2>
            point3f mujoco:geom:pos = (9.000236e-7, 0.016056655, 0.0966318)
            quatf mujoco:geom:quat = (0.2761371, 0.6509364, -0.65085834, 0.27642998)
            vector3f mujoco:geom:size = (1, 1, 1)
            uniform token mujoco:geom:type = "mesh"
            color3f[] primvars:displayColor = [(0.5, 0.5, 0.5)]
            float[] primvars:displayOpacity = [1]
            matrix4d xformOp:transform = ( (-0.000060167252158738194, -0.6946696265927309, 0.7193289277301611, 0), (-0.9999999081298984, -0.00026349085821153473, -0.00033810171304821113, 0), (0.00042440558725537203, -0.7193288819879884, -0.6946695469198416, 0), (9.000236468802749e-7, 0.016056655901336325, 0.09663180262077588, 1) )
            uniform token[] xformOpOrder = ["xformOp:transform"]

            def Scope "Materials"
            {
                def Material "jointgray" (
                    prepend references = @./ur5e/materials/usd/jointgray.usda@</jointgray>
                )
                {
                }
            }
        }

        def Cylinder "Geom_25" (
            prepend apiSchemas = ["PhysicsCollisionAPI", "MujocoGeomAPI"]
        )
        {
            float3[] extent = [(-0.04, -0.04, -0.06), (0.04, 0.04, 0.06)]
            double height = 0.12
            point3f mujoco:geom:pos = (0, 0, 0.04)
            quatf mujoco:geom:quat = (1, 0, 0, 0)
            vector3f mujoco:geom:size = (0.04, 0.06, 0)
            uniform token mujoco:geom:type = "capsule"
            bool physics:collisionEnabled = 1
            color3f[] primvars:displayColor = [(0.5, 0.5, 0.5)]
            float[] primvars:displayOpacity = [1]
            double radius = 0.04
            token visibility = "invisible"
            matrix4d xformOp:transform = ( (1, 0, 0, 0), (0, 1, 0, 0), (0, 0, 1, 0), (0, 0, 0.04, 1) )
            uniform token[] xformOpOrder = ["xformOp:transform"]
        }

        def Cylinder "Geom_26" (
            prepend apiSchemas = ["PhysicsCollisionAPI", "MujocoGeomAPI"]
        )
        {
            float3[] extent = [(-0.04, -0.04, -0.04), (0.04, 0.04, 0.04)]
            double height = 0.08
            point3f mujoco:geom:pos = (0, 0.02, 0.1)
            quatf mujoco:geom:quat = (0.70710677, 0.70710677, 0, 0)
            vector3f mujoco:geom:size = (0.04, 0.04, 0)
            uniform token mujoco:geom:type = "capsule"
            bool physics:collisionEnabled = 1
            color3f[] primvars:displayColor = [(0.5, 0.5, 0.5)]
            float[] primvars:displayOpacity = [1]
            double radius = 0.04
            token visibility = "invisible"
            matrix4d xformOp:transform = ( (1, 0, 0, 0), (0, 2.220446049250313e-16, 0.9999999999999998, 0), (0, -0.9999999999999998, 2.220446049250313e-16, 0), (0, 0.02, 0.1, 1) )
            uniform token[] xformOpOrder = ["xformOp:transform"]
        }

        def PhysicsRevoluteJoint "wrist_3_joint" (
            prepend apiSchemas = ["MujocoJointAPI"]
        )
        {
            vector3f mujoco:joint:axis = (0, 1, 0)
            point3f mujoco:joint:pos = (0, 0, 0)
            float2 mujoco:joint:range = (-6.28319, 6.28319)
            uniform token mujoco:joint:type = "hinge"
            uniform token physics:axis = "Z"
            rel physics:body0 = </ur5e/wrist_2_link>
            rel physics:body1 = </ur5e/wrist_3_link>
            bool physics:collisionEnabled = 0
            point3f physics:localPos0 = (1.110223e-16, 0, 0.1)
            point3f physics:localPos1 = (0, 0, 0)
            quatf physics:localRot0 = (0.7071068, -0.7071068, 0, 0)
            quatf physics:localRot1 = (0.7071068, -0.7071068, 0, 0)
            float physics:lowerLimit = -360.00027
            float physics:upperLimit = 360.00027
        }
    }

    def Xform "wrist_3_link" (
        prepend apiSchemas = ["MujocoBodyAPI", "PhysicsMassAPI"]
    )
    {
        point3f mujoco:body:pos = (0, 0, 0.1)
        quatf mujoco:body:quat = (1, 0, 0, 0)
        point3f physics:centerOfMass = (0, 0.0771683, 0)
        float3 physics:diagonalInertia = (0.000132134, 0.0000990863, 0.0000990863)
        float physics:mass = 0.1889
        quatf physics:principalAxes = (0.70710677, 0, 0, 0.70710677)
        matrix4d xformOp:transform = ( (-2.220446049250312e-16, -0.9999999999999993, -4.440892098500625e-16, 0), (-0.9999999999999998, 2.220446049250313e-16, 0, 0), (9.860761315262645e-32, 4.440892098500624e-16, -0.9999999999999996, 0), (-0.1339999999999998, 0.8169999999999997, 0.06300000000000021, 1) )
        uniform token[] xformOpOrder = ["xformOp:transform"]

        def Mesh "Geom_27" (
            prepend apiSchemas = ["MujocoGeomAPI", "MaterialBindingAPI"]
            prepend references = @./ur5e/meshes/usd/wrist3.usda@</wrist3>
        )
        {
            rel material:binding = </ur5e/wrist_3_link/Geom_27/Materials/linkgray>
            rel mujoco:geom:material = </mujoco/asset/materials/linkgray>
            rel mujoco:geom:mesh = </mujoco/asset/meshes/wrist3>
            point3f mujoco:geom:pos = (0.0000137304005, 0.07930911, -0.00053786853)
            quatf mujoco:geom:quat = (0.70295554, 0.07806526, 0.08144403, 0.70222944)
            vector3f mujoco:geom:size = (1, 1, 1)
            uniform token mujoco:geom:type = "mesh"
            color3f[] primvars:displayColor = [(0.5, 0.5, 0.5)]
            float[] primvars:displayOpacity = [1]
            matrix4d xformOp:transform = ( (0.00048137557071770143, 0.9999880566740829, -0.004863618689212881, 0), (-0.9745562582642942, 0.0015592660662582247, 0.22413760989007636, 0), (0.22414251661713214, 0.004631975661503099, 0.9745453694138667, 0), (0.000013730400112049665, 0.07930911085542494, -0.0005378685093544538, 1) )
            uniform token[] xformOpOrder = ["xformOp:transform"]

            def Scope "Materials"
            {
                def Material "linkgray" (
                    prepend references = @./ur5e/materials/usd/linkgray.usda@</linkgray>
                )
                {
                }
            }
        }

        def Cylinder "Geom_28" (
            prepend apiSchemas = ["PhysicsCollisionAPI", "MujocoGeomAPI"]
        )
        {
            float3[] extent = [(-0.04, -0.04, -0.02), (0.04, 0.04, 0.02)]
            double height = 0.04
            point3f mujoco:geom:pos = (0, 0.08, 0)
            quatf mujoco:geom:quat = (0.70710677, 0.70710677, 0, 0)
            vector3f mujoco:geom:size = (0.04, 0.02, 0)
            uniform token mujoco:geom:type = "cylinder"
            bool physics:collisionEnabled = 1
            color3f[] primvars:displayColor = [(0.5, 0.5, 0.5)]
            float[] primvars:displayOpacity = [1]
            double radius = 0.04
            token visibility = "invisible"
            matrix4d xformOp:transform = ( (1, 0, 0, 0), (0, 2.220446049250313e-16, 0.9999999999999998, 0), (0, -0.9999999999999998, 2.220446049250313e-16, 0), (0, 0.08, 0, 1) )
            uniform token[] xformOpOrder = ["xformOp:transform"]
        }
    }
}

