<?xml version="1.0" ?>
<robot name="panda" version="1.0">
  <link name="panda"/>
  <joint name="link0_joint" type="fixed">
    <origin xyz="0.0 0.0 0.0" rpy="0.0 0.0 0.0"/>
    <parent link="panda"/>
    <child link="link0"/>
  </joint>
  <link name="link0">
    <visual name="Geom_0">
      <origin xyz="-0.024341708049178123 0.06898584216833115 0.03700129687786102" rpy="0.8809733390808105 -0.0009012197842821479 1.7310597896575928"/>
      <geometry>
        <mesh filename="file://panda/meshes/obj/link0_0.obj" scale="1.0 1.0 1.0"/>
      </geometry>
    </visual>
    <visual name="Geom_1">
      <origin xyz="-0.02500513754785061 0.07288967818021774 0.03697875142097473" rpy="2.354224443435669 -0.06627609580755234 1.654933214187622"/>
      <geometry>
        <mesh filename="file://panda/meshes/obj/link0_1.obj" scale="1.0 1.0 1.0"/>
      </geometry>
    </visual>
    <visual name="Geom_2">
      <origin xyz="-0.023746833205223083 -0.06535296142101288 0.06299932301044464" rpy="1.570400595664978 -0.005743013229221106 -0.1658989042043686"/>
      <geometry>
        <mesh filename="file://panda/meshes/obj/link0_2.obj" scale="1.0 1.0 1.0"/>
      </geometry>
    </visual>
    <visual name="Geom_3">
      <origin xyz="-0.024884207174181938 -0.07268133759498596 0.06293128430843353" rpy="0.8625312447547913 0.08519240468740463 1.2866321802139282"/>
      <geometry>
        <mesh filename="file://panda/meshes/obj/link0_3.obj" scale="1.0 1.0 1.0"/>
      </geometry>
    </visual>
    <visual name="Geom_4">
      <origin xyz="-0.06482117623090744 -0.06560424715280533 0.048001378774642944" rpy="0.03037586249411106 0.012032273225486279 1.4114311933517456"/>
      <geometry>
        <mesh filename="file://panda/meshes/obj/link0_4.obj" scale="1.0 1.0 1.0"/>
      </geometry>
    </visual>
    <visual name="Geom_5">
      <origin xyz="-0.0596388541162014 0.0578850694000721 0.03690848499536514" rpy="1.7514346837997437 0.0 1.7317832708358765"/>
      <geometry>
        <mesh filename="file://panda/meshes/obj/link0_5.obj" scale="1.0 1.0 1.0"/>
      </geometry>
    </visual>
    <visual name="Geom_6">
      <origin xyz="0.011052804067730904 -0.07200003415346146 0.04606270045042038" rpy="-0.12475356459617615 0.0026193384546786547 1.4119155406951904"/>
      <geometry>
        <mesh filename="file://panda/meshes/obj/link0_7.obj" scale="1.0 1.0 1.0"/>
      </geometry>
    </visual>
    <visual name="Geom_7">
      <origin xyz="-0.029952924698591232 -3.44801701430697e-05 0.05349454656243324" rpy="-0.0013455851003527641 -1.135651707649231 -3.138012647628784"/>
      <geometry>
        <mesh filename="file://panda/meshes/obj/link0_8.obj" scale="1.0 1.0 1.0"/>
      </geometry>
    </visual>
    <visual name="Geom_8">
      <origin xyz="-0.02499927394092083 -0.07303207367658615 0.0328950434923172" rpy="1.8630088567733765 -1.555160403251648 -0.4334036707878113"/>
      <geometry>
        <mesh filename="file://panda/meshes/obj/link0_9.obj" scale="1.0 1.0 1.0"/>
      </geometry>
    </visual>
    <visual name="Geom_9">
      <origin xyz="-0.023787200450897217 -0.06548630446195602 0.03297410532832146" rpy="1.5455597639083862 -0.011791349388659 -0.15464279055595398"/>
      <geometry>
        <mesh filename="file://panda/meshes/obj/link0_10.obj" scale="1.0 1.0 1.0"/>
      </geometry>
    </visual>
    <visual name="Geom_10">
      <origin xyz="0.01104283332824707 0.07199695706367493 0.046087440103292465" rpy="-0.12477058172225952 -0.0025225700810551643 1.7314902544021606"/>
      <geometry>
        <mesh filename="file://panda/meshes/obj/link0_11.obj" scale="1.0 1.0 1.0"/>
      </geometry>
    </visual>
    <collision name="Geom_11">
      <origin xyz="-0.029189765453338623 -0.000879464962054044 0.056603193283081055" rpy="0.0734105035662651 -1.1999953985214233 3.081376791000366"/>
      <geometry>
        <mesh filename="file://panda/meshes/stl/link0_c.stl" scale="1.0 1.0 1.0"/>
      </geometry>
    </collision>
  </link>
  <joint name="joint1" type="revolute">
    <origin xyz="0.0 0.0 0.3330000042915344" rpy="0.0 0.0 0.0"/>
    <axis xyz="0.0 0.0 1.0"/>
    <parent link="link0"/>
    <child link="link1"/>
    <limit effort="1000.0" lower="-2.8973000049591064" upper="2.8973000049591064" velocity="1000.0"/>
  </joint>
  <link name="link1">
    <inertial>
      <origin xyz="0.003874999936670065 0.0020810000132769346 -0.04761999845504761" rpy="-0.009398424997925758 -0.02757652848958969 1.5581063032150269"/>
      <mass value="4.970684051513672"/>
      <inertia ixx="0.7071369886398315" ixy="0.0" ixz="0.0" iyy="0.7034354209899902" iyz="0.0" izz="0.008524556644260883"/>
    </inertial>
    <visual name="Geom_12">
      <origin xyz="2.2415551939047873e-06 -0.032479386776685715 -0.0675758644938469" rpy="0.38337042927742004 0.00014062898117117584 -0.00037883082404732704"/>
      <geometry>
        <mesh filename="file://panda/meshes/obj/link1.obj" scale="1.0 1.0 1.0"/>
      </geometry>
    </visual>
    <collision name="Geom_13">
      <origin xyz="1.1398981769161765e-05 -0.03126552700996399 -0.06937330961227417" rpy="0.35075756907463074 -0.000321827334119007 0.0006491282838396728"/>
      <geometry>
        <mesh filename="file://panda/meshes/stl/link1_c.stl" scale="1.0 1.0 1.0"/>
      </geometry>
    </collision>
  </link>
  <joint name="joint2" type="revolute">
    <origin xyz="0.0 0.0 0.0" rpy="-1.5707963705062866 0.0 0.0"/>
    <axis xyz="0.0 0.0 1.0"/>
    <parent link="link1"/>
    <child link="link2"/>
    <limit effort="1000.0" lower="-1.7627999782562256" upper="1.7627999782562256" velocity="1000.0"/>
  </joint>
  <link name="link2">
    <inertial>
      <origin xyz="-0.003140999935567379 -0.028720000758767128 0.003495000069960952" rpy="-2.351445436477661 -0.9617881774902344 -0.7229855060577393"/>
      <mass value="0.6469259858131409"/>
      <inertia ixx="0.031032642349600792" ixy="0.0" ixz="0.0" iyy="0.028300106525421143" iyz="0.0" izz="0.0027342503890395164"/>
    </inertial>
    <visual name="Geom_14">
      <origin xyz="3.0825528938294156e-06 -0.06860275566577911 0.03220973163843155" rpy="1.9510754346847534 -0.00039106394979171455 -0.00013279869745019823"/>
      <geometry>
        <mesh filename="file://panda/meshes/obj/link2.obj" scale="1.0 1.0 1.0"/>
      </geometry>
    </visual>
    <collision name="Geom_15">
      <origin xyz="-1.3176553693483584e-05 -0.07032155245542526 0.031178239732980728" rpy="1.9167766571044922 3.8633865187875926e-05 -0.00017520097026135772"/>
      <geometry>
        <mesh filename="file://panda/meshes/stl/link2_c.stl" scale="1.0 1.0 1.0"/>
      </geometry>
    </collision>
  </link>
  <joint name="joint3" type="revolute">
    <origin xyz="0.0 -0.3160000145435333 2.465190328815662e-32" rpy="1.5707963705062866 0.0 0.0"/>
    <axis xyz="0.0 0.0 1.0"/>
    <parent link="link2"/>
    <child link="link3"/>
    <limit effort="1000.0" lower="-2.8973000049591064" upper="2.8973000049591064" velocity="1000.0"/>
  </joint>
  <link name="link3">
    <inertial>
      <origin xyz="0.027518000453710556 0.03925200179219246 -0.06650199741125107" rpy="0.37785014510154724 0.3508239984512329 1.700415015220642"/>
      <mass value="3.2286040782928467"/>
      <inertia ixx="0.04150138795375824" ixy="0.0" ixz="0.0" iyy="0.04147925600409508" iyz="0.0" izz="0.0012463544262573123"/>
    </inertial>
    <visual name="Geom_16">
      <origin xyz="0.04164006933569908 0.024441450834274292 -0.037274930626153946" rpy="0.570658266544342 -0.7242336869239807 2.9041154384613037"/>
      <geometry>
        <mesh filename="file://panda/meshes/obj/link3_0.obj" scale="1.0 1.0 1.0"/>
      </geometry>
    </visual>
    <visual name="Geom_17">
      <origin xyz="0.02155347913503647 -0.011223170906305313 -0.011548318900167942" rpy="-3.120213270187378 -1.0597566366195679 -1.490752935409546"/>
      <geometry>
        <mesh filename="file://panda/meshes/obj/link3_1.obj" scale="1.0 1.0 1.0"/>
      </geometry>
    </visual>
    <visual name="Geom_18">
      <origin xyz="0.056876711547374725 -0.011394920758903027 -0.06117446348071098" rpy="0.0014353713486343622 -0.007864445447921753 2.350186586380005"/>
      <geometry>
        <mesh filename="file://panda/meshes/obj/link3_2.obj" scale="1.0 1.0 1.0"/>
      </geometry>
    </visual>
    <visual name="Geom_19">
      <origin xyz="0.07749117165803909 0.07963346689939499 -0.0040228888392448425" rpy="0.9103807210922241 0.0531575009226799 1.636165976524353"/>
      <geometry>
        <mesh filename="file://panda/meshes/obj/link3_3.obj" scale="1.0 1.0 1.0"/>
      </geometry>
    </visual>
    <collision name="Geom_20">
      <origin xyz="0.04434830695390701 0.024928325787186623 -0.038129985332489014" rpy="0.6264281272888184 -0.6489124298095703 2.7888150215148926"/>
      <geometry>
        <mesh filename="file://panda/meshes/stl/link3_c.stl" scale="1.0 1.0 1.0"/>
      </geometry>
    </collision>
  </link>
  <joint name="joint4" type="revolute">
    <origin xyz="0.08250000327825546 -1.232595164407831e-32 1.1102230246251565e-16" rpy="1.5707963705062866 0.0 0.0"/>
    <axis xyz="0.0 0.0 1.0"/>
    <parent link="link3"/>
    <child link="link4"/>
    <limit effort="1000.0" lower="-3.0717999935150146" upper="-0.0697999969124794" velocity="1000.0"/>
  </joint>
  <link name="link4">
    <inertial>
      <origin xyz="-0.05316999927163124 0.10441900044679642 0.02745399996638298" rpy="0.9491373300552368 -0.7651340961456299 0.9696856141090393"/>
      <mass value="3.587894916534424"/>
      <inertia ixx="0.034959640353918076" ixy="0.0" ixz="0.0" iyy="0.02814827673137188" iyz="0.0" izz="0.010620083659887314"/>
    </inertial>
    <visual name="Geom_21">
      <origin xyz="-0.02562248893082142 0.06118521839380264 -0.011393831111490726" rpy="-1.5781503915786743 -0.7912640571594238 -3.1295969486236572"/>
      <geometry>
        <mesh filename="file://panda/meshes/obj/link4_0.obj" scale="1.0 1.0 1.0"/>
      </geometry>
    </visual>
    <visual name="Geom_22">
      <origin xyz="-0.041551943868398666 0.038693804293870926 0.024040184915065765" rpy="1.1469171047210693 0.3272036015987396 0.6576570272445679"/>
      <geometry>
        <mesh filename="file://panda/meshes/obj/link4_1.obj" scale="1.0 1.0 1.0"/>
      </geometry>
    </visual>
    <visual name="Geom_23">
      <origin xyz="-0.005009009037166834 0.004010283388197422 0.07963447272777557" rpy="0.01728704944252968 -1.4866933822631836 2.462376356124878"/>
      <geometry>
        <mesh filename="file://panda/meshes/obj/link4_2.obj" scale="1.0 1.0 1.0"/>
      </geometry>
    </visual>
    <visual name="Geom_24">
      <origin xyz="-0.060935694724321365 0.01154452096670866 -0.011228485032916069" rpy="-0.11249836534261703 -0.5091463923454285 1.6149866580963135"/>
      <geometry>
        <mesh filename="file://panda/meshes/obj/link4_3.obj" scale="1.0 1.0 1.0"/>
      </geometry>
    </visual>
    <collision name="Geom_25">
      <origin xyz="-0.03855029493570328 0.03952560946345329 0.024716241285204887" rpy="1.1575253009796143 0.3623373508453369 0.6286469101905823"/>
      <geometry>
        <mesh filename="file://panda/meshes/stl/link4_c.stl" scale="1.0 1.0 1.0"/>
      </geometry>
    </collision>
  </link>
  <joint name="joint5" type="revolute">
    <origin xyz="-0.08250000327825546 0.3840000033378601 0.0" rpy="-1.5707963705062866 0.0 0.0"/>
    <axis xyz="0.0 0.0 1.0"/>
    <parent link="link4"/>
    <child link="link5"/>
    <limit effort="1000.0" lower="-2.8973000049591064" upper="2.8973000049591064" velocity="1000.0"/>
  </joint>
  <link name="link5">
    <inertial>
      <origin xyz="-0.011952999979257584 0.041064999997615814 -0.038437001407146454" rpy="-0.04481489956378937 0.13901987671852112 -0.2868998348712921"/>
      <mass value="1.2259459495544434"/>
      <inertia ixx="0.0367625392973423" ixy="0.0" ixz="0.0" iyy="0.02885309047996998" iyz="0.0" izz="0.008034370839595795"/>
    </inertial>
    <visual name="Geom_26">
      <origin xyz="-0.00012909492943435907 0.09575388580560684 -0.0327296257019043" rpy="0.002164683537557721 0.04994665086269379 1.5671027898788452"/>
      <geometry>
        <mesh filename="file://panda/meshes/obj/link5_0.obj" scale="1.0 1.0 1.0"/>
      </geometry>
    </visual>
    <visual name="Geom_27">
      <origin xyz="-0.010146972723305225 0.10322721302509308 -0.11142128705978394" rpy="0.12574712932109833 0.17403830587863922 1.6920329332351685"/>
      <geometry>
        <mesh filename="file://panda/meshes/obj/link5_1.obj" scale="1.0 1.0 1.0"/>
      </geometry>
    </visual>
    <visual name="Geom_28">
      <origin xyz="-1.4686699500998657e-07 0.04425269737839699 -0.11129853874444962" rpy="-0.2770003378391266 2.4900251446524635e-05 6.554603896802291e-05"/>
      <geometry>
        <mesh filename="file://panda/meshes/obj/link5_2.obj" scale="1.0 1.0 1.0"/>
      </geometry>
    </visual>
    <collision name="Geom_29">
      <origin xyz="0.0009732588077895343 0.019922221079468727 -0.2091069519519806" rpy="-2.9667460918426514 -0.9061652421951294 -1.8724935054779053"/>
      <geometry>
        <mesh filename="file://panda/meshes/stl/link5_c0.stl" scale="1.0 1.0 1.0"/>
      </geometry>
    </collision>
    <collision name="Geom_30">
      <origin xyz="-0.00023507016885560006 0.08005925267934799 -0.12115345150232315" rpy="0.003785613691434264 0.24683557450771332 1.5664136409759521"/>
      <geometry>
        <mesh filename="file://panda/meshes/stl/link5_c1.stl" scale="1.0 1.0 1.0"/>
      </geometry>
    </collision>
    <collision name="Geom_31">
      <origin xyz="0.0001502534287283197 0.06918296962976456 -0.0045388308353722095" rpy="1.1780917644500732 -0.005182717461138964 0.005207657348364592"/>
      <geometry>
        <mesh filename="file://panda/meshes/stl/link5_c2.stl" scale="1.0 1.0 1.0"/>
      </geometry>
    </collision>
  </link>
  <joint name="joint6" type="revolute">
    <origin xyz="0.0 -3.0814879110195774e-33 0.0" rpy="1.5707963705062866 0.0 0.0"/>
    <axis xyz="0.0 0.0 1.0"/>
    <parent link="link5"/>
    <child link="link6"/>
    <limit effort="1000.0" lower="-0.017500000074505806" upper="3.752500057220459" velocity="1000.0"/>
  </joint>
  <link name="link6">
    <inertial>
      <origin xyz="0.060148999094963074 -0.014116999693214893 -0.010517000220716" rpy="0.5130247473716736 -1.2262420654296875 2.5246615409851074"/>
      <mass value="1.6665550470352173"/>
      <inertia ixx="0.0058427611365914345" ixy="0.0" ixz="0.0" iyy="0.004310373682528734" iyz="0.0" izz="0.001597865018993616"/>
    </inertial>
    <visual name="Geom_32">
      <origin xyz="0.025386864319443703 -0.015517999418079853 -0.005139967426657677" rpy="0.16938182711601257 -1.5174187421798706 2.4590718746185303"/>
      <geometry>
        <mesh filename="file://panda/meshes/obj/link6_0.obj" scale="1.0 1.0 1.0"/>
      </geometry>
    </visual>
    <visual name="Geom_33">
      <origin xyz="9.689128637546673e-05 0.0014892221661284566 0.05296730622649193" rpy="-1.7817827463150024 -1.4691929817199707 -3.1375558376312256"/>
      <geometry>
        <mesh filename="file://panda/meshes/obj/link6_1.obj" scale="1.0 1.0 1.0"/>
      </geometry>
    </visual>
    <visual name="Geom_34">
      <origin xyz="0.10335279256105423 0.06819413602352142 -0.000582073989789933" rpy="1.4199872016906738 -0.009911899454891682 1.3432543277740479"/>
      <geometry>
        <mesh filename="file://panda/meshes/obj/link6_2.obj" scale="1.0 1.0 1.0"/>
      </geometry>
    </visual>
    <visual name="Geom_35">
      <origin xyz="0.0882054790854454 0.07772552967071533 -0.01060483232140541" rpy="0.0 0.0 0.0"/>
      <geometry>
        <mesh filename="file://panda/meshes/obj/link6_3.obj" scale="1.0 1.0 1.0"/>
      </geometry>
    </visual>
    <visual name="Geom_36">
      <origin xyz="0.09866821020841599 0.0758848786354065 -3.818381628661882e-06" rpy="1.5707963705062866 0.0 1.5707963705062866"/>
      <geometry>
        <mesh filename="file://panda/meshes/obj/link6_4.obj" scale="1.0 1.0 1.0"/>
      </geometry>
    </visual>
    <visual name="Geom_37">
      <origin xyz="0.0882030725479126 0.07772792130708694 0.010619455948472023" rpy="0.0 0.0 0.0"/>
      <geometry>
        <mesh filename="file://panda/meshes/obj/link6_5.obj" scale="1.0 1.0 1.0"/>
      </geometry>
    </visual>
    <visual name="Geom_38">
      <origin xyz="0.07775598764419556 0.079569511115551 -2.4452554043818964e-06" rpy="1.5707963705062866 0.0 1.5707963705062866"/>
      <geometry>
        <mesh filename="file://panda/meshes/obj/link6_6.obj" scale="1.0 1.0 1.0"/>
      </geometry>
    </visual>
    <visual name="Geom_39">
      <origin xyz="0.06338933110237122 0.08160700649023056 -1.3937560083832068e-07" rpy="0.0 0.0 0.0"/>
      <geometry>
        <mesh filename="file://panda/meshes/obj/link6_7.obj" scale="1.0 1.0 1.0"/>
      </geometry>
    </visual>
    <visual name="Geom_40">
      <origin xyz="0.11443524807691574 0.07093671709299088 -1.2390758001856739e-06" rpy="0.0 0.0 0.0"/>
      <geometry>
        <mesh filename="file://panda/meshes/obj/link6_8.obj" scale="1.0 1.0 1.0"/>
      </geometry>
    </visual>
    <visual name="Geom_41">
      <origin xyz="-0.0007293919916264713 -0.00010126877896254882 0.052537377923727036" rpy="-0.012449674308300018 -1.4689421653747559 3.1415927410125732"/>
      <geometry>
        <mesh filename="file://panda/meshes/obj/link6_9.obj" scale="1.0 1.0 1.0"/>
      </geometry>
    </visual>
    <visual name="Geom_42">
      <origin xyz="0.09152591973543167 0.07575305551290512 -6.295970524661243e-05" rpy="1.6008551120758057 -0.0005903012934140861 1.3515726327896118"/>
      <geometry>
        <mesh filename="file://panda/meshes/obj/link6_10.obj" scale="1.0 1.0 1.0"/>
      </geometry>
    </visual>
    <visual name="Geom_43">
      <origin xyz="0.08805238455533981 0.07680706679821014 -1.2221260476508178e-05" rpy="0.0 0.0 1.3960084915161133"/>
      <geometry>
        <mesh filename="file://panda/meshes/obj/link6_11.obj" scale="1.0 1.0 1.0"/>
      </geometry>
    </visual>
    <visual name="Geom_44">
      <origin xyz="0.0883026272058487 0.07748927175998688 -0.024865582585334778" rpy="0.0 0.0 0.0"/>
      <geometry>
        <mesh filename="file://panda/meshes/obj/link6_12.obj" scale="1.0 1.0 1.0"/>
      </geometry>
    </visual>
    <visual name="Geom_45">
      <origin xyz="0.08817030489444733 0.07745552808046341 0.025032425299286842" rpy="0.0 0.0 0.0"/>
      <geometry>
        <mesh filename="file://panda/meshes/obj/link6_13.obj" scale="1.0 1.0 1.0"/>
      </geometry>
    </visual>
    <visual name="Geom_46">
      <origin xyz="0.007414994761347771 0.00012494443217292428 0.043721359223127365" rpy="0.028641361743211746 -1.4710581302642822 3.124202251434326"/>
      <geometry>
        <mesh filename="file://panda/meshes/obj/link6_14.obj" scale="1.0 1.0 1.0"/>
      </geometry>
    </visual>
    <visual name="Geom_47">
      <origin xyz="0.08954532444477081 0.07420171052217484 -2.5736657335073687e-05" rpy="1.5450208187103271 5.602602686849423e-05 1.3505364656448364"/>
      <geometry>
        <mesh filename="file://panda/meshes/obj/link6_15.obj" scale="1.0 1.0 1.0"/>
      </geometry>
    </visual>
    <visual name="Geom_48">
      <origin xyz="0.05840050056576729 0.003517891513183713 0.008369866758584976" rpy="2.946964979171753 -1.3099440336227417 0.18028473854064941"/>
      <geometry>
        <mesh filename="file://panda/meshes/obj/link6_16.obj" scale="1.0 1.0 1.0"/>
      </geometry>
    </visual>
    <collision name="Geom_49">
      <origin xyz="0.051002293825149536 0.006932673044502735 0.006168993189930916" rpy="-3.0615999698638916 -1.4277689456939697 0.048520706593990326"/>
      <geometry>
        <mesh filename="file://panda/meshes/stl/link6_c.stl" scale="1.0 1.0 1.0"/>
      </geometry>
    </collision>
  </link>
  <joint name="joint7" type="revolute">
    <origin xyz="0.08799999952316284 0.0 -2.465190328815662e-32" rpy="1.5707963705062866 0.0 0.0"/>
    <axis xyz="0.0 0.0 1.0"/>
    <parent link="link6"/>
    <child link="link7"/>
    <limit effort="1000.0" lower="-2.8973000049591064" upper="2.8973000049591064" velocity="1000.0"/>
  </joint>
  <link name="link7">
    <inertial>
      <origin xyz="0.010517000220716 -0.004251999780535698 0.06159700080752373" rpy="-0.16143882274627686 0.1379346251487732 -0.11924774199724197"/>
      <mass value="0.7355219721794128"/>
      <inertia ixx="0.012734493240714073" ixy="0.0" ixz="0.0" iyy="0.010105476714670658" iyz="0.0" izz="0.00451803021132946"/>
    </inertial>
    <visual name="Geom_50">
      <origin xyz="0.04177794232964516 0.04183594137430191 0.08217258006334305" rpy="-1.58473801612854 -1.3546061515808105 -2.356671094894409"/>
      <geometry>
        <mesh filename="file://panda/meshes/obj/link7_0.obj" scale="1.0 1.0 1.0"/>
      </geometry>
    </visual>
    <visual name="Geom_51">
      <origin xyz="0.06381389498710632 0.017703890800476074 0.08298637717962265" rpy="1.802862286567688 0.002041242551058531 -0.7013431787490845"/>
      <geometry>
        <mesh filename="file://panda/meshes/obj/link7_1.obj" scale="1.0 1.0 1.0"/>
      </geometry>
    </visual>
    <visual name="Geom_52">
      <origin xyz="-0.03175903484225273 -0.031760748475790024 0.08578120917081833" rpy="-1.696004867553711 -1.453742504119873 2.4810845851898193"/>
      <geometry>
        <mesh filename="file://panda/meshes/obj/link7_2.obj" scale="1.0 1.0 1.0"/>
      </geometry>
    </visual>
    <visual name="Geom_53">
      <origin xyz="-0.036950308829545975 -0.036942269653081894 0.08580172061920166" rpy="0.0 0.0 0.7851092219352722"/>
      <geometry>
        <mesh filename="file://panda/meshes/obj/link7_3.obj" scale="1.0 1.0 1.0"/>
      </geometry>
    </visual>
    <visual name="Geom_54">
      <origin xyz="-0.037706732749938965 -0.037708986550569534 0.08578035980463028" rpy="0.0 0.0 0.7851522564888"/>
      <geometry>
        <mesh filename="file://panda/meshes/obj/link7_4.obj" scale="1.0 1.0 1.0"/>
      </geometry>
    </visual>
    <visual name="Geom_55">
      <origin xyz="0.017698489129543304 0.06383849680423737 0.0829557552933693" rpy="1.3374820947647095 0.002436215989291668 2.271496534347534"/>
      <geometry>
        <mesh filename="file://panda/meshes/obj/link7_5.obj" scale="1.0 1.0 1.0"/>
      </geometry>
    </visual>
    <visual name="Geom_56">
      <origin xyz="0.04115965589880943 0.04120412841439247 0.0677582398056984" rpy="-1.5750199556350708 -1.2906385660171509 -2.352616786956787"/>
      <geometry>
        <mesh filename="file://panda/meshes/obj/link7_6.obj" scale="1.0 1.0 1.0"/>
      </geometry>
    </visual>
    <visual name="Geom_57">
      <origin xyz="1.216750774801767e-06 4.293975871405564e-05 0.07774802297353745" rpy="-1.6481696367263794 -1.5676263570785522 -1.4958122968673706"/>
      <geometry>
        <mesh filename="file://panda/meshes/obj/link7_7.obj" scale="1.0 1.0 1.0"/>
      </geometry>
    </visual>
    <collision name="Geom_58">
      <origin xyz="0.010361372493207455 0.01035960391163826 0.07910777628421783" rpy="3.1380321979522705 -1.517140507698059 -2.352038621902466"/>
      <geometry>
        <mesh filename="file://panda/meshes/stl/link7_c.stl" scale="1.0 1.0 1.0"/>
      </geometry>
    </collision>
  </link>
  <joint name="hand_joint" type="fixed">
    <origin xyz="0.0 0.0 0.107" rpy="0.0 0.0 -0.7853981256484985"/>
    <parent link="link7"/>
    <child link="hand"/>
  </joint>
  <link name="hand">
    <inertial>
      <origin xyz="-0.009999999776482582 0.0 0.029999999329447746" rpy="0.0 0.0 0.0"/>
      <mass value="0.7300000190734863"/>
      <inertia ixx="0.0010000000474974513" ixy="0.0" ixz="0.0" iyy="0.0024999999441206455" iyz="0.0" izz="0.0017000000225380063"/>
    </inertial>
    <visual name="Geom_59">
      <origin xyz="-2.568993628937477e-10 1.0579090485407505e-05 0.01880798675119877" rpy="-7.46279947561046e-12 -1.5707814693450928 1.5707963705062866"/>
      <geometry>
        <mesh filename="file://panda/meshes/obj/hand_0.obj" scale="1.0 1.0 1.0"/>
      </geometry>
    </visual>
    <visual name="Geom_60">
      <origin xyz="6.841203230578685e-06 -0.09552084654569626 -0.0064749950543046" rpy="0.3617514371871948 0.0004961385857313871 -0.002415464026853442"/>
      <geometry>
        <mesh filename="file://panda/meshes/obj/hand_1.obj" scale="1.0 1.0 1.0"/>
      </geometry>
    </visual>
    <visual name="Geom_61">
      <origin xyz="6.350477406158461e-07 -0.06609330326318741 -0.020179778337478638" rpy="1.5699316263198853 0.3154538571834564 -0.0003590725245885551"/>
      <geometry>
        <mesh filename="file://panda/meshes/obj/hand_2.obj" scale="1.0 1.0 1.0"/>
      </geometry>
    </visual>
    <visual name="Geom_62">
      <origin xyz="3.5900632155971834e-07 0.003152384888380766 0.029725011438131332" rpy="1.5597975254058838 -2.0673478502430953e-05 -1.3983675444251276e-06"/>
      <geometry>
        <mesh filename="file://panda/meshes/obj/hand_3.obj" scale="1.0 1.0 1.0"/>
      </geometry>
    </visual>
    <visual name="Geom_63">
      <origin xyz="0.0003354762156959623 0.00039802773972041905 0.003179796738550067" rpy="-1.6317697763442993 -1.5702500343322754 -1.4412840604782104"/>
      <geometry>
        <mesh filename="file://panda/meshes/obj/hand_4.obj" scale="1.0 1.0 1.0"/>
      </geometry>
    </visual>
    <collision name="Geom_64">
      <origin xyz="-2.7661790227284655e-06 -0.0006154695292934775 0.023929521441459656" rpy="1.5965445041656494 -0.00045987850171513855 -0.00022900091425981373"/>
      <geometry>
        <mesh filename="file://panda/meshes/stl/hand_c.stl" scale="1.0 1.0 1.0"/>
      </geometry>
    </collision>
  </link>
  <joint name="finger_joint1" type="prismatic">
    <origin xyz="1.3877787807814457e-17 6.938893903907228e-18 0.058400001376867294" rpy="0.0 0.0 0.0"/>
    <axis xyz="0.0 1.0 0.0"/>
    <parent link="hand"/>
    <child link="left_finger"/>
    <limit effort="1000.0" lower="0.0" upper="0.03999999910593033" velocity="1000.0"/>
  </joint>
  <link name="left_finger">
    <inertial>
      <origin xyz="0.0 0.0 0.0" rpy="0.0 0.0 0.0"/>
      <mass value="0.014999999664723873"/>
      <inertia ixx="2.3749998945277184e-06" ixy="0.0" ixz="0.0" iyy="2.3749998945277184e-06" iyz="0.0" izz="7.500000265281415e-07"/>
    </inertial>
    <visual name="Geom_65">
      <origin xyz="4.874055434811453e-07 0.01569541171193123 0.0168744083493948" rpy="0.0002753754670266062 -0.07663142681121826 1.5712788105010986"/>
      <geometry>
        <mesh filename="file://panda/meshes/obj/finger_0.obj" scale="1.0 1.0 1.0"/>
      </geometry>
    </visual>
    <visual name="Geom_66">
      <origin xyz="-1.1254475111854845e-06 0.004738647490739822 0.04476996138691902" rpy="1.3088574409484863 0.002891773823648691 1.5701396465301514"/>
      <geometry>
        <mesh filename="file://panda/meshes/obj/finger_1.obj" scale="1.0 1.0 1.0"/>
      </geometry>
    </visual>
    <collision name="Geom_67">
      <origin xyz="4.874055434811453e-07 0.01569541171193123 0.0168744083493948" rpy="0.0002753754670266062 -0.07663142681121826 1.5712788105010986"/>
      <geometry>
        <mesh filename="file://panda/meshes/stl/finger_0.stl" scale="1.0 1.0 1.0"/>
      </geometry>
    </collision>
    <collision name="Geom_68">
      <origin xyz="0.0 0.005499999970197678 0.04450000077486038" rpy="0.0 0.0 0.0"/>
      <geometry>
        <box size="0.017000000923871994 0.00800000037997961 0.017000000923871994"/>
      </geometry>
    </collision>
    <collision name="Geom_69">
      <origin xyz="0.005499999970197678 0.0020000000949949026 0.05000000074505806" rpy="0.0 0.0 0.0"/>
      <geometry>
        <box size="0.006000000052154064 0.004000000189989805 0.006000000052154064"/>
      </geometry>
    </collision>
    <collision name="Geom_70">
      <origin xyz="-0.005499999970197678 0.0020000000949949026 0.05000000074505806" rpy="0.0 0.0 0.0"/>
      <geometry>
        <box size="0.006000000052154064 0.004000000189989805 0.006000000052154064"/>
      </geometry>
    </collision>
    <collision name="Geom_71">
      <origin xyz="0.005499999970197678 0.0020000000949949026 0.039500001817941666" rpy="0.0 0.0 0.0"/>
      <geometry>
        <box size="0.006000000052154064 0.004000000189989805 0.007000000216066837"/>
      </geometry>
    </collision>
    <collision name="Geom_72">
      <origin xyz="-0.005499999970197678 0.0020000000949949026 0.039500001817941666" rpy="0.0 0.0 0.0"/>
      <geometry>
        <box size="0.006000000052154064 0.004000000189989805 0.007000000216066837"/>
      </geometry>
    </collision>
  </link>
  <joint name="finger_joint2" type="prismatic">
    <origin xyz="1.3877787807814457e-17 6.938893903907228e-18 0.058400001376867294" rpy="0.0 0.0 3.1415927410125732"/>
    <axis xyz="0.0 1.0 0.0"/>
    <parent link="hand"/>
    <child link="right_finger"/>
    <limit effort="1000.0" lower="0.0" upper="0.03999999910593033" velocity="1000.0"/>
  </joint>
  <link name="right_finger">
    <inertial>
      <origin xyz="0.0 0.0 0.0" rpy="0.0 0.0 0.0"/>
      <mass value="0.014999999664723873"/>
      <inertia ixx="2.3749998945277184e-06" ixy="0.0" ixz="0.0" iyy="2.3749998945277184e-06" iyz="0.0" izz="7.500000265281415e-07"/>
    </inertial>
    <visual name="Geom_73">
      <origin xyz="4.874055434811453e-07 0.01569541171193123 0.0168744083493948" rpy="0.0002753754670266062 -0.07663142681121826 1.5712788105010986"/>
      <geometry>
        <mesh filename="file://panda/meshes/obj/finger_0.obj" scale="1.0 1.0 1.0"/>
      </geometry>
    </visual>
    <visual name="Geom_74">
      <origin xyz="-1.1254475111854845e-06 0.004738647490739822 0.04476996138691902" rpy="1.3088574409484863 0.002891773823648691 1.5701396465301514"/>
      <geometry>
        <mesh filename="file://panda/meshes/obj/finger_1.obj" scale="1.0 1.0 1.0"/>
      </geometry>
    </visual>
    <collision name="Geom_75">
      <origin xyz="4.874055434811453e-07 0.01569541171193123 0.0168744083493948" rpy="0.0002753754670266062 -0.07663142681121826 1.5712788105010986"/>
      <geometry>
        <mesh filename="file://panda/meshes/stl/finger_0.stl" scale="1.0 1.0 1.0"/>
      </geometry>
    </collision>
    <collision name="Geom_76">
      <origin xyz="0.0 0.005499999970197678 0.04450000077486038" rpy="0.0 0.0 0.0"/>
      <geometry>
        <box size="0.017000000923871994 0.00800000037997961 0.017000000923871994"/>
      </geometry>
    </collision>
    <collision name="Geom_77">
      <origin xyz="0.005499999970197678 0.0020000000949949026 0.05000000074505806" rpy="0.0 0.0 0.0"/>
      <geometry>
        <box size="0.006000000052154064 0.004000000189989805 0.006000000052154064"/>
      </geometry>
    </collision>
    <collision name="Geom_78">
      <origin xyz="-0.005499999970197678 0.0020000000949949026 0.05000000074505806" rpy="0.0 0.0 0.0"/>
      <geometry>
        <box size="0.006000000052154064 0.004000000189989805 0.006000000052154064"/>
      </geometry>
    </collision>
    <collision name="Geom_79">
      <origin xyz="0.005499999970197678 0.0020000000949949026 0.039500001817941666" rpy="0.0 0.0 0.0"/>
      <geometry>
        <box size="0.006000000052154064 0.004000000189989805 0.007000000216066837"/>
      </geometry>
    </collision>
    <collision name="Geom_80">
      <origin xyz="-0.005499999970197678 0.0020000000949949026 0.039500001817941666" rpy="0.0 0.0 0.0"/>
      <geometry>
        <box size="0.006000000052154064 0.004000000189989805 0.007000000216066837"/>
      </geometry>
    </collision>
  </link>
</robot>