<?xml version="1.0" ?>
<robot name="hsrb" version="1.0">
  <link name="hsrb"/>
  <joint name="base_footprint_joint" type="fixed">
    <origin xyz="0.0 0.0 0.0" rpy="0.0 0.0 0.0"/>
    <parent link="hsrb"/>
    <child link="base_footprint"/>
  </joint>
  <link name="base_footprint">
    <inertial>
      <origin xyz="0.0 0.0 0.0" rpy="0.0 0.0 0.0"/>
      <mass value="0.0"/>
      <inertia ixx="0.0" ixy="0.0" ixz="0.0" iyy="0.0" iyz="0.0" izz="0.0"/>
    </inertial>
  </link>
  <joint name="base_link_joint" type="fixed">
    <origin xyz="0.0 0.0 0.0" rpy="0.0 0.0 0.0"/>
    <parent link="base_footprint"/>
    <child link="base_link"/>
  </joint>
  <link name="base_link">
    <inertial>
      <origin xyz="-0.036911655217409134 0.0005294239963404834 0.2725730836391449" rpy="0.014468075707554817 -1.4206515550613403 3.1283280849456787"/>
      <mass value="51.38246154785156"/>
      <inertia ixx="0.8733259439468384" ixy="0.0" ixz="0.0" iyy="6.004275798797607" iyz="0.0" izz="6.15233039855957"/>
    </inertial>
    <visual name="SM_base_link_visual_0">
      <origin xyz="0.0 0.0 0.0" rpy="0.0 0.0 0.0"/>
      <geometry>
        <mesh filename="file://hsrb/meshes/obj/base_light.obj"/>
      </geometry>
    </visual>
    <visual name="SM_base_link_visual_1">
      <origin xyz="0.0 0.0 0.0" rpy="0.0 0.0 0.0"/>
      <geometry>
        <mesh filename="file://hsrb/meshes/obj/body_light.obj"/>
      </geometry>
    </visual>
    <visual name="SM_base_link_visual_2">
      <origin xyz="0.0 0.0 0.0" rpy="0.0 0.0 0.0"/>
      <geometry>
        <mesh filename="file://hsrb/meshes/obj/torso_base.obj"/>
      </geometry>
    </visual>
    <collision name="SM_base_link_collision_0">
      <origin xyz="0.0 0.0 0.0" rpy="0.0 0.0 0.0"/>
      <geometry>
        <mesh filename="file://hsrb/meshes/stl/base.stl"/>
      </geometry>
    </collision>
  </link>
  <joint name="base_roll_joint" type="continuous">
    <origin xyz="0.0 0.0 0.0" rpy="0.0 0.0 0.0"/>
    <axis xyz="0.0 0.0 1.0"/>
    <parent link="base_link"/>
    <child link="base_roll_link"/>
  </joint>
  <link name="base_roll_link">
    <inertial>
      <origin xyz="0.0 0.0 0.0" rpy="0.0 0.0 0.0"/>
      <mass value="0.0"/>
      <inertia ixx="0.0" ixy="0.0" ixz="0.0" iyy="0.0" iyz="0.0" izz="0.0"/>
    </inertial>
  </link>
  <joint name="base_r_drive_wheel_joint" type="continuous">
    <origin xyz="-0.10999999940395355 -0.13300000131130219 0.03999999910593033" rpy="0.0 0.0 0.0"/>
    <axis xyz="0.0 1.0 0.0"/>
    <parent link="base_roll_link"/>
    <child link="base_r_drive_wheel_link"/>
  </joint>
  <link name="base_r_drive_wheel_link">
    <inertial>
      <origin xyz="0.0 0.0 0.0" rpy="-1.5707963705062866 0.0 3.1415927410125732"/>
      <mass value="0.15079644322395325"/>
      <inertia ixx="7.162831025198102e-05" ixy="0.0" ixz="0.0" iyy="7.162831025198102e-05" iyz="0.0" izz="0.00012063715985277668"/>
    </inertial>
    <visual name="SM_base_r_drive_wheel_link_visual_0">
      <origin xyz="0.0 0.0 0.0" rpy="1.5707963705062866 0.0 0.0"/>
      <geometry>
        <cylinder radius="0.03999999910593033" length="0.029999999329447746"/>
      </geometry>
    </visual>
    <collision name="SM_base_r_drive_wheel_link_collision_0">
      <origin xyz="0.0 0.0 0.0" rpy="1.5707963705062866 0.0 0.0"/>
      <geometry>
        <cylinder radius="0.03999999910593033" length="0.029999999329447746"/>
      </geometry>
    </collision>
  </link>
  <joint name="base_l_drive_wheel_joint" type="continuous">
    <origin xyz="-0.10999999940395355 0.13300000131130219 0.03999999910593033" rpy="0.0 0.0 0.0"/>
    <axis xyz="0.0 1.0 0.0"/>
    <parent link="base_roll_link"/>
    <child link="base_l_drive_wheel_link"/>
  </joint>
  <link name="base_l_drive_wheel_link">
    <inertial>
      <origin xyz="0.0 0.0 0.0" rpy="-1.5707963705062866 0.0 3.1415927410125732"/>
      <mass value="0.15079644322395325"/>
      <inertia ixx="7.162831025198102e-05" ixy="0.0" ixz="0.0" iyy="7.162831025198102e-05" iyz="0.0" izz="0.00012063715985277668"/>
    </inertial>
    <visual name="SM_base_l_drive_wheel_link_visual_0">
      <origin xyz="0.0 0.0 0.0" rpy="1.5707963705062866 0.0 0.0"/>
      <geometry>
        <cylinder radius="0.03999999910593033" length="0.029999999329447746"/>
      </geometry>
    </visual>
    <collision name="SM_base_l_drive_wheel_link_collision_0">
      <origin xyz="0.0 0.0 0.0" rpy="1.5707963705062866 0.0 0.0"/>
      <geometry>
        <cylinder radius="0.03999999910593033" length="0.029999999329447746"/>
      </geometry>
    </collision>
  </link>
  <joint name="base_r_passive_wheel_x_frame_joint" type="continuous">
    <origin xyz="0.14949999749660492 -0.054999999701976776 0.029999999329447746" rpy="0.0 0.0 0.0"/>
    <axis xyz="1.0 0.0 0.0"/>
    <parent link="base_roll_link"/>
    <child link="base_r_passive_wheel_x_frame"/>
  </joint>
  <link name="base_r_passive_wheel_x_frame">
    <inertial>
      <origin xyz="0.0 0.0 0.0" rpy="0.0 0.0 0.0"/>
      <mass value="0.0"/>
      <inertia ixx="0.0" ixy="0.0" ixz="0.0" iyy="0.0" iyz="0.0" izz="0.0"/>
    </inertial>
  </link>
  <joint name="base_r_passive_wheel_y_frame_joint" type="continuous">
    <origin xyz="0 0 0" rpy="0 0 0"/>
    <axis xyz="0.0 1.0 0.0"/>
    <parent link="base_r_passive_wheel_x_frame"/>
    <child link="base_r_passive_wheel_y_frame"/>
  </joint>
  <link name="base_r_passive_wheel_y_frame">
    <inertial>
      <origin xyz="0.0 0.0 0.0" rpy="0.0 0.0 0.0"/>
      <mass value="0.0"/>
      <inertia ixx="0.0" ixy="0.0" ixz="0.0" iyy="0.0" iyz="0.0" izz="0.0"/>
    </inertial>
  </link>
  <joint name="base_r_passive_wheel_z_joint" type="continuous">
    <origin xyz="0 0 0" rpy="0 0 0"/>
    <axis xyz="0.0 0.0 1.0"/>
    <parent link="base_r_passive_wheel_y_frame"/>
    <child link="base_r_passive_wheel_z_link"/>
  </joint>
  <link name="base_r_passive_wheel_z_link">
    <inertial>
      <origin xyz="0.0 0.0 0.0" rpy="0.0 0.0 0.0"/>
      <mass value="0.11309733241796494"/>
      <inertia ixx="4.0715040086070076e-05" ixy="0.0" ixz="0.0" iyy="4.0715040086070076e-05" iyz="0.0" izz="4.0715040086070076e-05"/>
    </inertial>
    <visual name="SM_base_r_passive_wheel_z_link_visual_0">
      <origin xyz="0.0 0.0 0.0" rpy="0.0 0.0 0.0"/>
      <geometry>
        <sphere radius="0.029999999329447746"/>
      </geometry>
    </visual>
    <collision name="SM_base_r_passive_wheel_z_link_collision_0">
      <origin xyz="0.0 0.0 0.0" rpy="0.0 0.0 0.0"/>
      <geometry>
        <sphere radius="0.029999999329447746"/>
      </geometry>
    </collision>
  </link>
  <joint name="base_l_passive_wheel_x_frame_joint" type="continuous">
    <origin xyz="0.14949999749660492 0.054999999701976776 0.029999999329447746" rpy="0.0 0.0 0.0"/>
    <axis xyz="1.0 0.0 0.0"/>
    <parent link="base_roll_link"/>
    <child link="base_l_passive_wheel_x_frame"/>
  </joint>
  <link name="base_l_passive_wheel_x_frame">
    <inertial>
      <origin xyz="0.0 0.0 0.0" rpy="0.0 0.0 0.0"/>
      <mass value="0.0"/>
      <inertia ixx="0.0" ixy="0.0" ixz="0.0" iyy="0.0" iyz="0.0" izz="0.0"/>
    </inertial>
  </link>
  <joint name="base_l_passive_wheel_y_frame_joint" type="continuous">
    <origin xyz="0 0 0" rpy="0 0 0"/>
    <axis xyz="0.0 1.0 0.0"/>
    <parent link="base_l_passive_wheel_x_frame"/>
    <child link="base_l_passive_wheel_y_frame"/>
  </joint>
  <link name="base_l_passive_wheel_y_frame">
    <inertial>
      <origin xyz="0.0 0.0 0.0" rpy="0.0 0.0 0.0"/>
      <mass value="0.0"/>
      <inertia ixx="0.0" ixy="0.0" ixz="0.0" iyy="0.0" iyz="0.0" izz="0.0"/>
    </inertial>
  </link>
  <joint name="base_l_passive_wheel_z_joint" type="continuous">
    <origin xyz="0 0 0" rpy="0 0 0"/>
    <axis xyz="0.0 0.0 1.0"/>
    <parent link="base_l_passive_wheel_y_frame"/>
    <child link="base_l_passive_wheel_z_link"/>
  </joint>
  <link name="base_l_passive_wheel_z_link">
    <inertial>
      <origin xyz="0.0 0.0 0.0" rpy="0.0 0.0 0.0"/>
      <mass value="0.11309733241796494"/>
      <inertia ixx="4.0715040086070076e-05" ixy="0.0" ixz="0.0" iyy="4.0715040086070076e-05" iyz="0.0" izz="4.0715040086070076e-05"/>
    </inertial>
    <visual name="SM_base_l_passive_wheel_z_link_visual_0">
      <origin xyz="0.0 0.0 0.0" rpy="0.0 0.0 0.0"/>
      <geometry>
        <sphere radius="0.029999999329447746"/>
      </geometry>
    </visual>
    <collision name="SM_base_l_passive_wheel_z_link_collision_0">
      <origin xyz="0.0 0.0 0.0" rpy="0.0 0.0 0.0"/>
      <geometry>
        <sphere radius="0.029999999329447746"/>
      </geometry>
    </collision>
  </link>
  <joint name="base_range_sensor_link_joint" type="fixed">
    <origin xyz="0.1675 0.0 0.1844" rpy="0.0 0.0 0.0"/>
    <parent link="base_link"/>
    <child link="base_range_sensor_link"/>
  </joint>
  <link name="base_range_sensor_link">
    <inertial>
      <origin xyz="-4.4308851726571064e-11 -2.1491329549316873e-10 -0.005050084087997675" rpy="-2.4144394397735596 1.5707963705062866 0.0"/>
      <mass value="0.13287509977817535"/>
      <inertia ixx="4.4946875277673826e-05" ixy="0.0" ixz="0.0" iyy="7.912974979262799e-05" iyz="0.0" izz="7.912974979262799e-05"/>
    </inertial>
    <visual name="SM_base_range_sensor_link_visual_0">
      <origin xyz="0.0 0.0 0.0" rpy="0.0 0.0 0.0"/>
      <geometry>
        <mesh filename="file://hsrb/meshes/obj/laser.obj"/>
      </geometry>
    </visual>
    <collision name="SM_base_range_sensor_link_collision_0">
      <origin xyz="0.0 0.0 0.0" rpy="0.0 0.0 0.0"/>
      <geometry>
        <mesh filename="file://hsrb/meshes/stl/laser.stl"/>
      </geometry>
    </collision>
  </link>
  <joint name="base_imu_frame_joint" type="fixed">
    <origin xyz="0.0005 0.1296 0.181" rpy="-3.1415927410125732 0.0 0.0"/>
    <parent link="base_link"/>
    <child link="base_imu_frame"/>
  </joint>
  <link name="base_imu_frame">
    <inertial>
      <origin xyz="0.0 0.0 0.0" rpy="0.0 0.0 0.0"/>
      <mass value="0.0"/>
      <inertia ixx="0.0" ixy="0.0" ixz="0.0" iyy="0.0" iyz="0.0" izz="0.0"/>
    </inertial>
  </link>
  <joint name="torso_lift_joint" type="prismatic">
    <origin xyz="0.0 0.0 0.7519999742507935" rpy="0.0 0.0 0.0"/>
    <axis xyz="0.0 0.0 1.0"/>
    <parent link="base_link"/>
    <child link="torso_lift_link"/>
    <limit effort="100.0" lower="0.0" upper="0.3449999988079071" velocity="0.10000000149011612"/>
    <mimic joint="arm_lift_joint" multiplier="0.5" offset="0.0"/>
  </joint>
  <link name="torso_lift_link">
    <inertial>
      <origin xyz="-0.038848523050546646 -0.0004158369265496731 -0.3223643898963928" rpy="-1.5812219381332397 -1.4720245599746704 0.011897391639649868"/>
      <mass value="11.268409729003906"/>
      <inertia ixx="0.04201531782746315" ixy="0.0" ixz="0.0" iyy="1.4784327745437622" iyz="0.0" izz="1.4862946271896362"/>
    </inertial>
    <visual name="SM_torso_lift_link_visual_0">
      <origin xyz="0.0 0.0 0.0" rpy="0.0 0.0 0.0"/>
      <geometry>
        <mesh filename="file://hsrb/meshes/obj/torso_light.obj"/>
      </geometry>
    </visual>
    <collision name="SM_torso_lift_link_collision_0">
      <origin xyz="0.0 0.0 0.0" rpy="0.0 0.0 0.0"/>
      <geometry>
        <mesh filename="file://hsrb/meshes/stl/torso.stl"/>
      </geometry>
    </collision>
  </link>
  <joint name="head_pan_joint" type="revolute">
    <origin xyz="0.0 0.0 0.0" rpy="0.0 0.0 0.0"/>
    <axis xyz="0.0 0.0 1.0"/>
    <parent link="torso_lift_link"/>
    <child link="head_pan_link"/>
    <limit effort="100.0" lower="-3.8399999141693115" upper="1.75" velocity="1.0"/>
  </joint>
  <link name="head_pan_link">
    <inertial>
      <origin xyz="-0.006927147973328829 -2.5756405648280634e-06 -0.02850755862891674" rpy="0.0008144741877913475 1.1508769989013672 -3.140512466430664"/>
      <mass value="0.31557589769363403"/>
      <inertia ixx="0.0003908935468643904" ixy="0.0" ixz="0.0" iyy="0.0005272923153825104" iyz="0.0" izz="0.0006329496391117573"/>
    </inertial>
    <visual name="SM_head_pan_link_visual_0">
      <origin xyz="0.0 0.0 0.0" rpy="0.0 0.0 0.0"/>
      <geometry>
        <mesh filename="file://hsrb/meshes/obj/head_pan.obj"/>
      </geometry>
    </visual>
    <collision name="SM_head_pan_link_collision_0">
      <origin xyz="0.0 0.0 0.0" rpy="0.0 0.0 0.0"/>
      <geometry>
        <mesh filename="file://hsrb/meshes/stl/head_pan.stl"/>
      </geometry>
    </collision>
  </link>
  <joint name="head_tilt_joint" type="revolute">
    <origin xyz="0.019999999552965164 0.0 0.0" rpy="0.0 0.0 0.0"/>
    <axis xyz="0.0 -1.0 0.0"/>
    <parent link="head_pan_link"/>
    <child link="head_tilt_link"/>
    <limit effort="100.0" lower="-1.5700000524520874" upper="0.5199999809265137" velocity="1.0"/>
  </joint>
  <link name="head_tilt_link">
    <inertial>
      <origin xyz="-0.055457424372434616 3.3125500067399116e-06 0.0913025513291359" rpy="0.010071031749248505 1.006140947341919 0.003685160307213664"/>
      <mass value="4.578278541564941"/>
      <inertia ixx="0.018316378816962242" ixy="0.0" ixz="0.0" iyy="0.08084337413311005" iyz="0.0" izz="0.09207417815923691"/>
    </inertial>
    <visual name="SM_head_tilt_link_visual_0">
      <origin xyz="0.0 0.0 0.0" rpy="0.0 0.0 0.0"/>
      <geometry>
        <mesh filename="file://hsrb/meshes/obj/head_upper.obj"/>
      </geometry>
    </visual>
    <visual name="SM_head_tilt_link_visual_1">
      <origin xyz="0.0 0.0 0.0" rpy="0.0 0.0 0.0"/>
      <geometry>
        <mesh filename="file://hsrb/meshes/obj/head_tilt.obj"/>
      </geometry>
    </visual>
    <visual name="SM_head_tilt_link_visual_2">
      <origin xyz="0.0 0.0 0.0" rpy="0.0 0.0 0.0"/>
      <geometry>
        <mesh filename="file://hsrb/meshes/obj/tablet_base.obj"/>
      </geometry>
    </visual>
    <collision name="SM_head_tilt_link_collision_0">
      <origin xyz="0.0 0.0 0.0" rpy="0.0 0.0 0.0"/>
      <geometry>
        <mesh filename="file://hsrb/meshes/stl/head.stl"/>
      </geometry>
    </collision>
    <collision name="SM_head_tilt_link_collision_1">
      <origin xyz="0.0 0.0 0.0" rpy="0.0 0.0 0.0"/>
      <geometry>
        <mesh filename="file://hsrb/meshes/stl/tablet.stl"/>
      </geometry>
    </collision>
  </link>
  <joint name="head_l_stereo_camera_link_joint" type="fixed">
    <origin xyz="0.02 0.07 0.061" rpy="-1.5707963705062866 0.0 -1.5707963705062866"/>
    <parent link="head_tilt_link"/>
    <child link="head_l_stereo_camera_link"/>
  </joint>
  <link name="head_l_stereo_camera_link">
    <inertial>
      <origin xyz="0.0 0.0 0.0" rpy="0.0 0.0 0.0"/>
      <mass value="0.0"/>
      <inertia ixx="0.0" ixy="0.0" ixz="0.0" iyy="0.0" iyz="0.0" izz="0.0"/>
    </inertial>
    <visual name="SM_head_l_stereo_camera_link_visual_0">
      <origin xyz="0.0 0.0 0.0" rpy="0.0 0.0 0.0"/>
      <geometry>
        <mesh filename="file://hsrb/meshes/obj/head_camera.obj"/>
      </geometry>
    </visual>
  </link>
  <joint name="head_l_stereo_camera_gazebo_frame_joint" type="fixed">
    <origin xyz="0.0 0.0 0.0" rpy="1.5707963705062866 -1.5707963705062866 0.0"/>
    <parent link="head_l_stereo_camera_link"/>
    <child link="head_l_stereo_camera_gazebo_frame"/>
  </joint>
  <link name="head_l_stereo_camera_gazebo_frame">
    <inertial>
      <origin xyz="0.0 0.0 0.0" rpy="0.0 0.0 0.0"/>
      <mass value="0.0"/>
      <inertia ixx="0.0" ixy="0.0" ixz="0.0" iyy="0.0" iyz="0.0" izz="0.0"/>
    </inertial>
  </link>
  <joint name="head_r_stereo_camera_link_joint" type="fixed">
    <origin xyz="0.02 -0.07 0.061" rpy="-1.5707963705062866 0.0 -1.5707963705062866"/>
    <parent link="head_tilt_link"/>
    <child link="head_r_stereo_camera_link"/>
  </joint>
  <link name="head_r_stereo_camera_link">
    <inertial>
      <origin xyz="0.0 0.0 0.0" rpy="0.0 0.0 0.0"/>
      <mass value="0.0"/>
      <inertia ixx="0.0" ixy="0.0" ixz="0.0" iyy="0.0" iyz="0.0" izz="0.0"/>
    </inertial>
    <visual name="SM_head_r_stereo_camera_link_visual_0">
      <origin xyz="0.0 0.0 0.0" rpy="0.0 0.0 0.0"/>
      <geometry>
        <mesh filename="file://hsrb/meshes/obj/head_camera.obj"/>
      </geometry>
    </visual>
  </link>
  <joint name="head_r_stereo_camera_gazebo_frame_joint" type="fixed">
    <origin xyz="0.0 0.0 0.0" rpy="1.5707963705062866 -1.5707963705062866 0.0"/>
    <parent link="head_r_stereo_camera_link"/>
    <child link="head_r_stereo_camera_gazebo_frame"/>
  </joint>
  <link name="head_r_stereo_camera_gazebo_frame">
    <inertial>
      <origin xyz="0.0 0.0 0.0" rpy="0.0 0.0 0.0"/>
      <mass value="0.0"/>
      <inertia ixx="0.0" ixy="0.0" ixz="0.0" iyy="0.0" iyz="0.0" izz="0.0"/>
    </inertial>
  </link>
  <joint name="head_center_camera_frame_joint" type="fixed">
    <origin xyz="0.0195 0.0 0.061" rpy="-1.5707963705062866 0.0 -1.5707963705062866"/>
    <parent link="head_tilt_link"/>
    <child link="head_center_camera_frame"/>
  </joint>
  <link name="head_center_camera_frame">
    <inertial>
      <origin xyz="0.0 0.0 0.0" rpy="0.0 0.0 0.0"/>
      <mass value="0.0"/>
      <inertia ixx="0.0" ixy="0.0" ixz="0.0" iyy="0.0" iyz="0.0" izz="0.0"/>
    </inertial>
  </link>
  <joint name="head_center_camera_gazebo_frame_joint" type="fixed">
    <origin xyz="0.0 0.0 0.0" rpy="1.5707963705062866 -1.5707963705062866 0.0"/>
    <parent link="head_center_camera_frame"/>
    <child link="head_center_camera_gazebo_frame"/>
  </joint>
  <link name="head_center_camera_gazebo_frame">
    <inertial>
      <origin xyz="0.0 0.0 0.0" rpy="0.0 0.0 0.0"/>
      <mass value="0.0"/>
      <inertia ixx="0.0" ixy="0.0" ixz="0.0" iyy="0.0" iyz="0.0" izz="0.0"/>
    </inertial>
  </link>
  <joint name="head_rgbd_sensor_link_joint" type="fixed">
    <origin xyz="-0.079796 0.022 0.215172" rpy="-1.5707963705062866 0.0 -1.5707963705062866"/>
    <parent link="head_tilt_link"/>
    <child link="head_rgbd_sensor_link"/>
  </joint>
  <link name="head_rgbd_sensor_link">
    <inertial>
      <origin xyz="0.022312525659799576 0.003084133379161358 -0.015074222348630428" rpy="-1.3791697025299072 0.1349184811115265 0.02716098353266716"/>
      <mass value="0.1929166316986084"/>
      <inertia ixx="7.308930798899382e-05" ixy="0.0" ixz="0.0" iyy="0.000560473941732198" iyz="0.0" izz="0.000600011320784688"/>
    </inertial>
    <visual name="SM_head_rgbd_sensor_link_visual_0">
      <origin xyz="0.0 0.0 0.0" rpy="0.0 0.0 0.0"/>
      <geometry>
        <mesh filename="file://hsrb/meshes/obj/rgbd_light.obj"/>
      </geometry>
    </visual>
    <collision name="SM_head_rgbd_sensor_link_collision_0">
      <origin xyz="0.0 0.0 0.0" rpy="0.0 0.0 0.0"/>
      <geometry>
        <mesh filename="file://hsrb/meshes/stl/rgbd.stl"/>
      </geometry>
    </collision>
  </link>
  <joint name="head_rgbd_sensor_gazebo_frame_joint" type="fixed">
    <origin xyz="0.0 0.0 0.0" rpy="1.5707963705062866 -1.5707963705062866 0.0"/>
    <parent link="head_rgbd_sensor_link"/>
    <child link="head_rgbd_sensor_gazebo_frame"/>
  </joint>
  <link name="head_rgbd_sensor_gazebo_frame">
    <inertial>
      <origin xyz="0.0 0.0 0.0" rpy="0.0 0.0 0.0"/>
      <mass value="0.0"/>
      <inertia ixx="0.0" ixy="0.0" ixz="0.0" iyy="0.0" iyz="0.0" izz="0.0"/>
    </inertial>
  </link>
  <joint name="arm_lift_joint" type="prismatic">
    <origin xyz="0.0 0.0 0.3400000035762787" rpy="0.0 0.0 0.0"/>
    <axis xyz="0.0 0.0 1.0"/>
    <parent link="base_link"/>
    <child link="arm_lift_link"/>
    <limit effort="100.0" lower="0.0" upper="0.6899999976158142" velocity="0.20000000298023224"/>
  </joint>
  <link name="arm_lift_link">
    <inertial>
      <origin xyz="0.0813228189945221 0.026763053610920906 -0.04826762154698372" rpy="-2.430516242980957 0.4805789887905121 0.4823969304561615"/>
      <mass value="0.1369386464357376"/>
      <inertia ixx="0.0009512149845249951" ixy="0.0" ixz="0.0" iyy="0.0017490539466962218" iyz="0.0" izz="0.0022147856652736664"/>
    </inertial>
    <visual name="SM_arm_lift_link_visual_0">
      <origin xyz="0.0 0.0 0.0" rpy="0.0 0.0 0.0"/>
      <geometry>
        <mesh filename="file://hsrb/meshes/obj/shoulder.obj"/>
      </geometry>
    </visual>
    <collision name="SM_arm_lift_link_collision_0">
      <origin xyz="0.0 0.0 0.0" rpy="0.0 0.0 0.0"/>
      <geometry>
        <mesh filename="file://hsrb/meshes/stl/shoulder.stl"/>
      </geometry>
    </collision>
  </link>
  <joint name="arm_flex_joint" type="revolute">
    <origin xyz="0.14100000262260437 0.07800000160932541 0.0" rpy="0.0 0.0 0.0"/>
    <axis xyz="0.0 -1.0 0.0"/>
    <parent link="arm_lift_link"/>
    <child link="arm_flex_link"/>
    <limit effort="100.0" lower="-2.619999885559082" upper="0.0" velocity="1.2000000476837158"/>
  </joint>
  <link name="arm_flex_link">
    <inertial>
      <origin xyz="-0.0004589901363942772 0.0065834117121994495 0.10606901347637177" rpy="1.6724159717559814 1.5225048065185547 -1.4755094051361084"/>
      <mass value="2.1093451976776123"/>
      <inertia ixx="0.0029768238309770823" ixy="0.0" ixz="0.0" iyy="0.03662457689642906" iyz="0.0" izz="0.037757232785224915"/>
    </inertial>
    <visual name="SM_arm_flex_link_visual_0">
      <origin xyz="0.0 0.0 0.0" rpy="0.0 0.0 0.0"/>
      <geometry>
        <mesh filename="file://hsrb/meshes/obj/arm_flex_light.obj"/>
      </geometry>
    </visual>
    <collision name="SM_arm_flex_link_collision_0">
      <origin xyz="0.0 0.0 0.0" rpy="0.0 0.0 0.0"/>
      <geometry>
        <mesh filename="file://hsrb/meshes/stl/arm_flex.stl"/>
      </geometry>
    </collision>
  </link>
  <joint name="arm_roll_joint" type="revolute">
    <origin xyz="0.004999999888241291 0.0 0.3449999988079071" rpy="0.0 0.0 0.0"/>
    <axis xyz="0.0 0.0 1.0"/>
    <parent link="arm_flex_link"/>
    <child link="arm_roll_link"/>
    <limit effort="100.0" lower="-2.0899999141693115" upper="3.8399999141693115" velocity="2.0"/>
  </joint>
  <link name="arm_roll_link">
    <inertial>
      <origin xyz="-0.004909095820039511 0.003416739171370864 -0.04720309004187584" rpy="2.402834892272949 1.448037028312683 2.3931026458740234"/>
      <mass value="0.9090999960899353"/>
      <inertia ixx="0.001125680049881339" ixy="0.0" ixz="0.0" iyy="0.0036435395013540983" iyz="0.0" izz="0.0040444317273795605"/>
    </inertial>
    <visual name="SM_arm_roll_link_visual_0">
      <origin xyz="0.0 0.0 0.0" rpy="0.0 0.0 0.0"/>
      <geometry>
        <mesh filename="file://hsrb/meshes/obj/arm_roll_light.obj"/>
      </geometry>
    </visual>
    <collision name="SM_arm_roll_link_collision_0">
      <origin xyz="0.0 0.0 0.0" rpy="0.0 0.0 0.0"/>
      <geometry>
        <mesh filename="file://hsrb/meshes/stl/arm_roll.stl"/>
      </geometry>
    </collision>
  </link>
  <joint name="wrist_flex_joint" type="revolute">
    <origin xyz="0.0 0.0 0.0" rpy="0.0 0.0 0.0"/>
    <axis xyz="0.0 -1.0 0.0"/>
    <parent link="arm_roll_link"/>
    <child link="wrist_flex_link"/>
    <limit effort="100.0" lower="-1.9199999570846558" upper="1.2200000286102295" velocity="1.5"/>
  </joint>
  <link name="wrist_flex_link">
    <inertial>
      <origin xyz="0.0 0.0 0.029999999329447746" rpy="-0.0 1.570796251296997 0.0"/>
      <mass value="0.03631681203842163"/>
      <inertia ixx="5.247779427008936e-06" ixy="0.0" ixz="0.0" iyy="4.015126251033507e-05" iyz="0.0" izz="4.015126251033507e-05"/>
    </inertial>
    <visual name="SM_wrist_flex_link_visual_0">
      <origin xyz="0.0 0.0 0.0" rpy="0.0 0.0 0.0"/>
      <geometry>
        <mesh filename="file://hsrb/meshes/obj/wrist_flex.obj"/>
      </geometry>
    </visual>
    <visual name="SM_wrist_flex_link_visual_1">
      <origin xyz="0.0 0.0 0.03999999910593033" rpy="0.0 0.0 0.0"/>
      <geometry>
        <cylinder radius="0.017000000923871994" length="0.019999999552965164"/>
      </geometry>
    </visual>
    <collision name="SM_wrist_flex_link_collision_0">
      <origin xyz="0.0 0.0 0.029999999329447746" rpy="0.0 0.0 0.0"/>
      <geometry>
        <cylinder radius="0.017000000923871994" length="0.03999999910593033"/>
      </geometry>
    </collision>
  </link>
  <joint name="wrist_roll_joint" type="revolute">
    <origin xyz="0.0 0.0 0.0" rpy="0.0 0.0 0.0"/>
    <axis xyz="0.0 0.0 1.0"/>
    <parent link="wrist_flex_link"/>
    <child link="wrist_roll_link"/>
    <limit effort="100.0" lower="-1.9199999570846558" upper="3.6700000762939453" velocity="1.5"/>
  </joint>
  <link name="wrist_roll_link">
    <inertial>
      <origin xyz="-0.010066617280244827 -2.47548523475416e-05 0.0884910598397255" rpy="3.1379220485687256 -1.4284381866455078 -3.1384637355804443"/>
      <mass value="0.06149858608841896"/>
      <inertia ixx="0.00011161583825014532" ixy="0.0" ixz="0.0" iyy="0.0005890678730793297" iyz="0.0" izz="0.000613926793448627"/>
    </inertial>
    <visual name="SM_wrist_roll_link_visual_0">
      <origin xyz="0.0 0.0 0.0" rpy="0.0 0.0 0.0"/>
      <geometry>
        <mesh filename="file://hsrb/meshes/obj/wrist_roll.obj"/>
      </geometry>
    </visual>
    <collision name="SM_wrist_roll_link_collision_0">
      <origin xyz="0.0 0.0 0.0" rpy="0.0 0.0 0.0"/>
      <geometry>
        <mesh filename="file://hsrb/meshes/stl/wrist_roll.stl"/>
      </geometry>
    </collision>
  </link>
  <joint name="wrist_ft_sensor_frame_joint" type="fixed">
    <origin xyz="0.0 0.0 0.0735" rpy="-3.1415927410125732 0.0 0.0"/>
    <parent link="wrist_roll_link"/>
    <child link="wrist_ft_sensor_frame"/>
  </joint>
  <link name="wrist_ft_sensor_frame">
    <inertial>
      <origin xyz="0.0 0.0 0.0" rpy="0.0 0.0 0.0"/>
      <mass value="0.0"/>
      <inertia ixx="0.0" ixy="0.0" ixz="0.0" iyy="0.0" iyz="0.0" izz="0.0"/>
    </inertial>
  </link>
  <joint name="hand_palm_link_joint" type="fixed">
    <origin xyz="0.012 0.0 0.1405" rpy="0.0 0.0 -3.1415927410125732"/>
    <parent link="wrist_roll_link"/>
    <child link="hand_palm_link"/>
  </joint>
  <link name="hand_palm_link">
    <inertial>
      <origin xyz="0.0012877753470093012 0.00030466882162727416 -0.024661114439368248" rpy="2.7498908042907715 -1.50751531124115 -2.7445483207702637"/>
      <mass value="0.08773984014987946"/>
      <inertia ixx="3.0547216738341376e-05" ixy="0.0" ixz="0.0" iyy="7.715255196671933e-05" iyz="0.0" izz="9.0780173195526e-05"/>
    </inertial>
    <visual name="SM_hand_palm_link_visual_0">
      <origin xyz="0.0 0.0 0.0" rpy="0.0 0.0 0.0"/>
      <geometry>
        <mesh filename="file://hsrb/meshes/stl/palm.stl"/>
      </geometry>
    </visual>
    <collision name="SM_hand_palm_link_collision_0">
      <origin xyz="0.0 0.0 0.0" rpy="0.0 0.0 0.0"/>
      <geometry>
        <mesh filename="file://hsrb/meshes/stl/palm.stl"/>
      </geometry>
    </collision>
  </link>
  <joint name="hand_motor_joint" type="revolute">
    <origin xyz="0 0 0" rpy="0 0 0"/>
    <axis xyz="1.0 0.0 0.0"/>
    <parent link="hand_palm_link"/>
    <child link="hand_motor_dummy_link"/>
    <limit effort="100.0" lower="-0.7979999780654907" upper="1.2400000095367432" velocity="1.0"/>
  </joint>
  <link name="hand_motor_dummy_link">
    <inertial>
      <origin xyz="0.0 0.0 0.0" rpy="0.0 0.0 0.0"/>
      <mass value="0.0"/>
      <inertia ixx="0.0" ixy="0.0" ixz="0.0" iyy="0.0" iyz="0.0" izz="0.0"/>
    </inertial>
  </link>
  <joint name="hand_l_proximal_joint" type="revolute">
    <origin xyz="-0.016750000417232513 -0.02449999935925007 -0.017500000074505806" rpy="0.0 0.0 0.0"/>
    <axis xyz="1.0 0.0 0.0"/>
    <parent link="hand_palm_link"/>
    <child link="hand_l_proximal_link"/>
    <limit effort="100.0" lower="-0.7979999780654907" upper="1.2400000095367432" velocity="1.0"/>
    <mimic joint="hand_motor_joint" multiplier="1.0" offset="0.0"/>
  </joint>
  <link name="hand_l_proximal_link">
    <inertial>
      <origin xyz="0.0 0.0 0.0" rpy="0.0 0.0 0.0"/>
      <mass value="0.0"/>
      <inertia ixx="0.0" ixy="0.0" ixz="0.0" iyy="0.0" iyz="0.0" izz="0.0"/>
    </inertial>
  </link>
  <joint name="hand_l_spring_proximal_joint" type="revolute">
    <origin xyz="0 0 0" rpy="0 0 0"/>
    <axis xyz="1.0 0.0 0.0"/>
    <parent link="hand_l_proximal_link"/>
    <child link="hand_l_spring_proximal_link"/>
    <limit effort="100.0" lower="0.0" upper="0.6980000138282776" velocity="1.0"/>
  </joint>
  <link name="hand_l_spring_proximal_link">
    <inertial>
      <origin xyz="0.018756786361336708 -0.0022016807924956083 0.030663585290312767" rpy="-1.532872200012207 -1.1292961835861206 -0.10901301354169846"/>
      <mass value="0.042135074734687805"/>
      <inertia ixx="8.60757427290082e-06" ixy="0.0" ixz="0.0" iyy="7.024005753919482e-05" iyz="0.0" izz="7.688956247875467e-05"/>
    </inertial>
    <visual name="SM_hand_l_spring_proximal_link_visual_0">
      <origin xyz="0.0 0.0 0.0" rpy="0.0 0.0 0.0"/>
      <geometry>
        <mesh filename="file://hsrb/meshes/stl/l_proximal.stl"/>
      </geometry>
    </visual>
    <collision name="SM_hand_l_spring_proximal_link_collision_0">
      <origin xyz="0.0 0.0 0.0" rpy="0.0 0.0 0.0"/>
      <geometry>
        <mesh filename="file://hsrb/meshes/stl/l_proximal.stl"/>
      </geometry>
    </collision>
  </link>
  <joint name="hand_l_mimic_distal_joint" type="revolute">
    <origin xyz="0.0 0.0 0.07000000029802322" rpy="0.0 0.0 0.0"/>
    <axis xyz="1.0 0.0 0.0"/>
    <parent link="hand_l_spring_proximal_link"/>
    <child link="hand_l_mimic_distal_link"/>
    <limit effort="100.0" lower="-0.6980000138282776" upper="-0.0" velocity="1.0"/>
    <mimic joint="hand_l_spring_proximal_joint" multiplier="-1.0" offset="0.0"/>
  </joint>
  <link name="hand_l_mimic_distal_link">
    <inertial>
      <origin xyz="0.0 0.0 0.0" rpy="0.0 0.0 0.0"/>
      <mass value="0.0"/>
      <inertia ixx="0.0" ixy="0.0" ixz="0.0" iyy="0.0" iyz="0.0" izz="0.0"/>
    </inertial>
  </link>
  <joint name="hand_l_distal_joint" type="revolute">
    <origin xyz="0 0 0" rpy="0 0 0"/>
    <axis xyz="1.0 0.0 0.0"/>
    <parent link="hand_l_mimic_distal_link"/>
    <child link="hand_l_distal_link"/>
    <limit effort="100.0" lower="-1.2400000095367432" upper="0.7979999780654907" velocity="1.0"/>
    <mimic joint="hand_motor_joint" multiplier="-1.0" offset="-0.08699999749660492"/>
  </joint>
  <link name="hand_l_distal_link">
    <inertial>
      <origin xyz="0.01525004580616951 0.004431677516549826 0.019333720207214355" rpy="-1.4266875982284546 0.8896632790565491 -2.8373043537139893"/>
      <mass value="0.03458765894174576"/>
      <inertia ixx="6.055272024241276e-06" ixy="0.0" ixz="0.0" iyy="2.712272726057563e-05" iyz="0.0" izz="2.945130836451426e-05"/>
    </inertial>
    <visual name="SM_hand_l_distal_link_visual_0">
      <origin xyz="0.0 0.0 0.0" rpy="0.0 0.0 0.0"/>
      <geometry>
        <mesh filename="file://hsrb/meshes/stl/l_distal.stl"/>
      </geometry>
    </visual>
    <collision name="SM_hand_l_distal_link_collision_0">
      <origin xyz="0.0 0.0 0.0" rpy="0.0 0.0 0.0"/>
      <geometry>
        <mesh filename="file://hsrb/meshes/stl/l_distal.stl"/>
      </geometry>
    </collision>
  </link>
  <joint name="hand_l_finger_tip_frame_joint" type="fixed">
    <origin xyz="0.01675 0.0193 0.0379" rpy="-1.5707963705062866 0.0 0.0"/>
    <parent link="hand_l_distal_link"/>
    <child link="hand_l_finger_tip_frame"/>
  </joint>
  <link name="hand_l_finger_tip_frame">
    <inertial>
      <origin xyz="0.0 0.0 0.0" rpy="0.0 0.0 0.0"/>
      <mass value="0.0"/>
      <inertia ixx="0.0" ixy="0.0" ixz="0.0" iyy="0.0" iyz="0.0" izz="0.0"/>
    </inertial>
  </link>
  <joint name="hand_l_finger_vacuum_frame_joint" type="fixed">
    <origin xyz="0.00475 -0.011539 0.03322" rpy="0.7853981852531433 0.0 0.0"/>
    <parent link="hand_l_distal_link"/>
    <child link="hand_l_finger_vacuum_frame"/>
  </joint>
  <link name="hand_l_finger_vacuum_frame">
    <inertial>
      <origin xyz="0.0 0.0 0.0" rpy="0.0 0.0 0.0"/>
      <mass value="0.0"/>
      <inertia ixx="0.0" ixy="0.0" ixz="0.0" iyy="0.0" iyz="0.0" izz="0.0"/>
    </inertial>
    <visual name="SM_hand_l_finger_vacuum_frame_visual_0">
      <origin xyz="0.0 0.0 -0.009999999776482582" rpy="0.0 0.0 0.0"/>
      <geometry>
        <box size="0.00800000037997961 0.00800000037997961 0.019999999552965164"/>
      </geometry>
    </visual>
  </link>
  <joint name="hand_r_proximal_joint" type="revolute">
    <origin xyz="-0.016750000417232513 0.02449999935925007 -0.017500000074505806" rpy="0.0 0.0 0.0"/>
    <axis xyz="-1.0 0.0 0.0"/>
    <parent link="hand_palm_link"/>
    <child link="hand_r_proximal_link"/>
    <limit effort="100.0" lower="-0.7979999780654907" upper="1.2400000095367432" velocity="1.0"/>
    <mimic joint="hand_motor_joint" multiplier="1.0" offset="0.0"/>
  </joint>
  <link name="hand_r_proximal_link">
    <inertial>
      <origin xyz="0.0 0.0 0.0" rpy="0.0 0.0 0.0"/>
      <mass value="0.0"/>
      <inertia ixx="0.0" ixy="0.0" ixz="0.0" iyy="0.0" iyz="0.0" izz="0.0"/>
    </inertial>
  </link>
  <joint name="hand_r_spring_proximal_joint" type="revolute">
    <origin xyz="0 0 0" rpy="0 0 0"/>
    <axis xyz="-1.0 0.0 0.0"/>
    <parent link="hand_r_proximal_link"/>
    <child link="hand_r_spring_proximal_link"/>
    <limit effort="100.0" lower="0.0" upper="0.6980000138282776" velocity="1.0"/>
  </joint>
  <link name="hand_r_spring_proximal_link">
    <inertial>
      <origin xyz="0.018127676099538803 0.0021659941412508488 0.030857620760798454" rpy="-1.5883344411849976 -1.1393007040023804 0.11346551030874252"/>
      <mass value="0.04147995635867119"/>
      <inertia ixx="7.921276846900582e-06" ixy="0.0" ixz="0.0" iyy="6.877347186673433e-05" iyz="0.0" izz="7.483593799406663e-05"/>
    </inertial>
    <visual name="SM_hand_r_spring_proximal_link_visual_0">
      <origin xyz="0.0 0.0 0.0" rpy="0.0 0.0 0.0"/>
      <geometry>
        <mesh filename="file://hsrb/meshes/stl/r_proximal.stl"/>
      </geometry>
    </visual>
    <collision name="SM_hand_r_spring_proximal_link_collision_0">
      <origin xyz="0.0 0.0 0.0" rpy="0.0 0.0 0.0"/>
      <geometry>
        <mesh filename="file://hsrb/meshes/stl/r_proximal.stl"/>
      </geometry>
    </collision>
  </link>
  <joint name="hand_r_mimic_distal_joint" type="revolute">
    <origin xyz="0.0 0.0 0.07000000029802322" rpy="0.0 0.0 0.0"/>
    <axis xyz="-1.0 0.0 0.0"/>
    <parent link="hand_r_spring_proximal_link"/>
    <child link="hand_r_mimic_distal_link"/>
    <limit effort="100.0" lower="-0.6980000138282776" upper="-0.0" velocity="1.0"/>
    <mimic joint="hand_r_spring_proximal_joint" multiplier="-1.0" offset="0.0"/>
  </joint>
  <link name="hand_r_mimic_distal_link">
    <inertial>
      <origin xyz="0.0 0.0 0.0" rpy="0.0 0.0 0.0"/>
      <mass value="0.0"/>
      <inertia ixx="0.0" ixy="0.0" ixz="0.0" iyy="0.0" iyz="0.0" izz="0.0"/>
    </inertial>
  </link>
  <joint name="hand_r_distal_joint" type="revolute">
    <origin xyz="0 0 0" rpy="0 0 0"/>
    <axis xyz="-1.0 0.0 0.0"/>
    <parent link="hand_r_mimic_distal_link"/>
    <child link="hand_r_distal_link"/>
    <limit effort="100.0" lower="-1.2400000095367432" upper="0.7979999780654907" velocity="1.0"/>
    <mimic joint="hand_motor_joint" multiplier="-1.0" offset="-0.08699999749660492"/>
  </joint>
  <link name="hand_r_distal_link">
    <inertial>
      <origin xyz="0.017135124653577805 -0.007652597967535257 0.01713944971561432" rpy="-2.105471611022949 0.7531828284263611 2.7236809730529785"/>
      <mass value="0.024421628564596176"/>
      <inertia ixx="3.450870281085372e-06" ixy="0.0" ixz="0.0" iyy="1.9094664821750484e-05" iyz="0.0" izz="2.1310002921381965e-05"/>
    </inertial>
    <visual name="SM_hand_r_distal_link_visual_0">
      <origin xyz="0.0 0.0 0.0" rpy="0.0 0.0 0.0"/>
      <geometry>
        <mesh filename="file://hsrb/meshes/stl/r_distal.stl"/>
      </geometry>
    </visual>
    <collision name="SM_hand_r_distal_link_collision_0">
      <origin xyz="0.0 0.0 0.0" rpy="0.0 0.0 0.0"/>
      <geometry>
        <mesh filename="file://hsrb/meshes/stl/r_distal.stl"/>
      </geometry>
    </collision>
  </link>
  <joint name="hand_r_finger_tip_frame_joint" type="fixed">
    <origin xyz="0.01675 -0.0193 0.0379" rpy="1.5707963705062866 0.0 0.0"/>
    <parent link="hand_r_distal_link"/>
    <child link="hand_r_finger_tip_frame"/>
  </joint>
  <link name="hand_r_finger_tip_frame">
    <inertial>
      <origin xyz="0.0 0.0 0.0" rpy="0.0 0.0 0.0"/>
      <mass value="0.0"/>
      <inertia ixx="0.0" ixy="0.0" ixz="0.0" iyy="0.0" iyz="0.0" izz="0.0"/>
    </inertial>
  </link>
  <joint name="hand_camera_frame_joint" type="fixed">
    <origin xyz="0.039 0.0 -0.0045" rpy="0.0 0.0 0.0"/>
    <parent link="hand_palm_link"/>
    <child link="hand_camera_frame"/>
  </joint>
  <link name="hand_camera_frame">
    <inertial>
      <origin xyz="0.0 0.0 0.0" rpy="0.0 0.0 0.0"/>
      <mass value="0.0"/>
      <inertia ixx="0.0" ixy="0.0" ixz="0.0" iyy="0.0" iyz="0.0" izz="0.0"/>
    </inertial>
  </link>
  <joint name="hand_camera_gazebo_frame_joint" type="fixed">
    <origin xyz="0.0 0.0 0.0" rpy="1.5707963705062866 -1.5707963705062866 0.0"/>
    <parent link="hand_camera_frame"/>
    <child link="hand_camera_gazebo_frame"/>
  </joint>
  <link name="hand_camera_gazebo_frame">
    <inertial>
      <origin xyz="0.0 0.0 0.0" rpy="0.0 0.0 0.0"/>
      <mass value="0.0"/>
      <inertia ixx="0.0" ixy="0.0" ixz="0.0" iyy="0.0" iyz="0.0" izz="0.0"/>
    </inertial>
  </link>
  <joint name="hand_gripper_tool_frame_joint" type="fixed">
    <origin xyz="0.0 0.0 0.07" rpy="0.0 0.0 0.0"/>
    <parent link="hand_palm_link"/>
    <child link="hand_gripper_tool_frame"/>
  </joint>
  <link name="hand_gripper_tool_frame">
    <inertial>
      <origin xyz="0.0 0.0 0.0" rpy="0.0 0.0 0.0"/>
      <mass value="0.0"/>
      <inertia ixx="0.0" ixy="0.0" ixz="0.0" iyy="0.0" iyz="0.0" izz="0.0"/>
    </inertial>
  </link>
</robot>