<?xml version="1.0" ?>
<mujoco model="hsrb">
	<compiler meshdir="hsrb/meshes" texturedir="hsrb/textures" angle="radian" autolimits="true" balanceinertia="true" boundmass="0.000001" boundinertia="0.000001"/>
	<default>
		<default class="hsrb_visual">
			<geom contype="0" conaffinity="0"/>
		</default>
		<default class="hsrb_collision">
			<geom rgba="0.7843137254901961 0.7843137254901961 0.7843137254901961 0.0"/>
		</default>
	</default>
	<asset>
		<mesh name="base_light" file="obj/base_light.obj" scale="1.0 1.0 1.0"/>
		<mesh name="body_light" file="obj/body_light.obj" scale="1.0 1.0 1.0"/>
		<mesh name="torso_base" file="obj/torso_base.obj" scale="1.0 1.0 1.0"/>
		<mesh name="base" file="stl/base.stl" scale="1.0 1.0 1.0"/>
		<mesh name="laser" file="stl/laser.stl" scale="1.0 1.0 1.0"/>
		<mesh name="torso_light" file="obj/torso_light.obj" scale="1.0 1.0 1.0"/>
		<mesh name="torso" file="stl/torso.stl" scale="1.0 1.0 1.0"/>
		<mesh name="head_pan" file="stl/head_pan.stl" scale="1.0 1.0 1.0"/>
		<mesh name="head_upper" file="obj/head_upper.obj" scale="1.0 1.0 1.0"/>
		<mesh name="head_tilt" file="obj/head_tilt.obj" scale="1.0 1.0 1.0"/>
		<mesh name="tablet_base" file="obj/tablet_base.obj" scale="1.0 1.0 1.0"/>
		<mesh name="head" file="stl/head.stl" scale="1.0 1.0 1.0"/>
		<mesh name="tablet" file="stl/tablet.stl" scale="1.0 1.0 1.0"/>
		<mesh name="head_camera" file="obj/head_camera.obj" scale="1.0 1.0 1.0"/>
		<mesh name="rgbd_light" file="obj/rgbd_light.obj" scale="1.0 1.0 1.0"/>
		<mesh name="rgbd" file="stl/rgbd.stl" scale="1.0 1.0 1.0"/>
		<mesh name="shoulder" file="stl/shoulder.stl" scale="1.0 1.0 1.0"/>
		<mesh name="arm_flex_light" file="obj/arm_flex_light.obj" scale="1.0 1.0 1.0"/>
		<mesh name="arm_flex" file="stl/arm_flex.stl" scale="1.0 1.0 1.0"/>
		<mesh name="arm_roll_light" file="obj/arm_roll_light.obj" scale="1.0 1.0 1.0"/>
		<mesh name="arm_roll" file="stl/arm_roll.stl" scale="1.0 1.0 1.0"/>
		<mesh name="wrist_flex" file="obj/wrist_flex.obj" scale="1.0 1.0 1.0"/>
		<mesh name="wrist_roll" file="stl/wrist_roll.stl" scale="1.0 1.0 1.0"/>
		<mesh name="palm" file="stl/palm.stl" scale="1.0 1.0 1.0"/>
		<mesh name="l_proximal" file="stl/l_proximal.stl" scale="1.0 1.0 1.0"/>
		<mesh name="l_distal" file="stl/l_distal.stl" scale="1.0 1.0 1.0"/>
		<mesh name="r_proximal" file="stl/r_proximal.stl" scale="1.0 1.0 1.0"/>
		<mesh name="r_distal" file="stl/r_distal.stl" scale="1.0 1.0 1.0"/>
		<material name="M_base_link_visual_0" texture="gray"/>
		<material name="M_base_link_visual_1" texture="gray"/>
		<material name="M_base_link_visual_2" texture="gray"/>
		<material name="M_base_range_sensor_link_visual_0" texture="gray"/>
		<material name="M_torso_lift_link_visual_0" texture="gray"/>
		<material name="M_head_pan_link_visual_0" texture="white"/>
		<material name="M_head_tilt_link_visual_0" texture="gray"/>
		<material name="M_head_tilt_link_visual_1" texture="white"/>
		<material name="M_head_tilt_link_visual_2" texture="microphone"/>
		<material name="M_head_l_stereo_camera_link_visual_0" texture="black"/>
		<material name="M_head_r_stereo_camera_link_visual_0" texture="black"/>
		<material name="M_head_rgbd_sensor_link_visual_0" texture="rgbd"/>
		<material name="M_arm_lift_link_visual_0" texture="gray"/>
		<material name="M_arm_flex_link_visual_0" texture="white"/>
		<material name="M_arm_roll_link_visual_0" texture="white"/>
		<material name="M_wrist_flex_link_visual_0" texture="gray"/>
		<material name="M_wrist_roll_link_visual_0" texture="white"/>
		<texture name="gray" type="2d" file="gray.png"/>
		<texture name="white" type="2d" file="white.png"/>
		<texture name="microphone" type="2d" file="microphone.png"/>
		<texture name="black" type="2d" file="black.png"/>
		<texture name="rgbd" type="2d" file="rgbd.png"/>
	</asset>
	<worldbody>
		<body name="hsrb" pos="0.0 0.0 0.0" quat="1.0 0.0 0.0 0.0">
			<joint name="odom_vel_lin_x_joint" type="slide" axis="1.0 0.0 0.0"/>
			<joint name="odom_vel_lin_y_joint" type="slide" axis="0.0 1.0 0.0"/>
			<joint name="odom_vel_ang_z_joint" type="hinge" axis="0.0 0.0 1.0"/>
			<body name="base_footprint" pos="0.0 0.0 0.0" quat="1.0 0.0 0.0 0.0">
				<inertial mass="0.0" pos="0.0 0.0 0.0" quat="1.0 0.0 0.0 0.0" diaginertia="0.0 0.0 0.0"/>
				<body name="base_link" pos="0.0 0.0 0.0" quat="1.0 0.0 0.0 0.0">
					<inertial mass="51.38246154785156" pos="-0.036911655217409134 0.0005294239963404834 0.2725730836391449" quat="0.00031106165261007845 0.6520857810974121 0.0011596735566854477 0.7581442594528198" diaginertia="0.8733259439468384 6.004275798797607 6.15233039855957"/>
					<geom name="SM_base_link_visual_0" type="mesh" pos="0.0 0.0 0.0" quat="1.0 0.0 0.0 0.0" mesh="base_light" material="M_base_link_visual_0" class="hsrb_visual"/>
					<geom name="SM_base_link_visual_1" type="mesh" pos="0.0 0.0 0.0" quat="1.0 0.0 0.0 0.0" mesh="body_light" material="M_base_link_visual_1" class="hsrb_visual"/>
					<geom name="SM_base_link_visual_2" type="mesh" pos="0.0 0.0 0.0" quat="1.0 0.0 0.0 0.0" mesh="torso_base" material="M_base_link_visual_2" class="hsrb_visual"/>
					<geom name="SM_base_link_collision_0" type="mesh" pos="0.0 0.0 0.0" quat="1.0 0.0 0.0 0.0" mesh="base" class="hsrb_collision"/>
					<body name="base_range_sensor_link" pos="0.16750000417232513 0.0 0.18440000712871552" quat="1.0 0.0 0.0 0.0">
						<inertial mass="0.13287509977817535" pos="-4.4308851726571064e-11 -2.1491329549316873e-10 -0.005050084087997675" quat="0.25146082043647766 -0.6608838438987732 0.25146082043647766 0.6608838438987732" diaginertia="4.4946875277673826e-05 7.912974979262799e-05 7.912974979262799e-05"/>
						<geom name="SM_base_range_sensor_link_visual_0" type="mesh" pos="0.0 0.0 0.0" quat="1.0 0.0 0.0 0.0" mesh="laser" material="M_base_range_sensor_link_visual_0" class="hsrb_visual"/>
						<geom name="SM_base_range_sensor_link_collision_0" type="mesh" pos="0.0 0.0 0.0" quat="1.0 0.0 0.0 0.0" mesh="laser" class="hsrb_collision"/>
					</body>
					<body name="torso_lift_link" pos="0.0 0.0 0.7519999742507935" quat="1.0 0.0 0.0 0.0">
						<inertial mass="11.268409729003906" pos="-0.038848523050546646 -0.0004158369265496731 -0.3223643898963928" quat="0.5241636037826538 -0.5239796042442322 -0.47535187005996704 -0.474065899848938" diaginertia="0.04201531782746315 1.4784327745437622 1.4862946271896362"/>
						<geom name="SM_torso_lift_link_visual_0" type="mesh" pos="0.0 0.0 0.0" quat="1.0 0.0 0.0 0.0" mesh="torso_light" material="M_torso_lift_link_visual_0" class="hsrb_visual"/>
						<geom name="SM_torso_lift_link_collision_0" type="mesh" pos="0.0 0.0 0.0" quat="1.0 0.0 0.0 0.0" mesh="torso" class="hsrb_collision"/>
						<joint damping="10.0" name="torso_lift_joint" type="slide" pos="0.0 0.0 0.0" range="0.0 0.3449999988079071" axis="0.0 0.0 1.0"/>
						<body name="head_pan_link" pos="0.0 0.0 0.0" quat="1.0 0.0 0.0 0.0">
							<inertial mass="0.31557589769363403" pos="-0.006927147973328829 -2.5756405648280634e-06 -0.02850755862891674" quat="-0.00023151653294917196 -0.5442028045654297 4.771801468450576e-05 0.8389536738395691" diaginertia="0.0003908935468643904 0.0005272923153825104 0.0006329496391117573"/>
							<geom name="SM_head_pan_link_visual_0" type="mesh" pos="0.0 0.0 0.0" quat="1.0 0.0 0.0 0.0" mesh="head_pan" material="M_head_pan_link_visual_0" class="hsrb_visual"/>
							<geom name="SM_head_pan_link_collision_0" type="mesh" pos="0.0 0.0 0.0" quat="1.0 0.0 0.0 0.0" mesh="head_pan" class="hsrb_collision"/>
							<joint damping="10.0" name="head_pan_joint" type="hinge" pos="0.0 0.0 0.0" range="-3.8399999141693115 1.75" axis="0.0 0.0 1.0"/>
							<body name="head_tilt_link" pos="0.019999999552965164 0.0 0.0" quat="1.0 0.0 0.0 0.0">
								<inertial mass="4.578278541564941" pos="-0.055457424372434616 3.3125500067399116e-06 0.0913025513291359" quat="0.8760982155799866 0.003523292252793908 0.482119083404541 -0.0008134231902658939" diaginertia="0.018316378816962242 0.08084337413311005 0.09207417815923691"/>
								<geom name="SM_head_tilt_link_visual_0" type="mesh" pos="0.0 0.0 0.0" quat="1.0 0.0 0.0 0.0" mesh="head_upper" material="M_head_tilt_link_visual_0" class="hsrb_visual"/>
								<geom name="SM_head_tilt_link_visual_1" type="mesh" pos="0.0 0.0 0.0" quat="1.0 0.0 0.0 0.0" mesh="head_tilt" material="M_head_tilt_link_visual_1" class="hsrb_visual"/>
								<geom name="SM_head_tilt_link_visual_2" type="mesh" pos="0.0 0.0 0.0" quat="1.0 0.0 0.0 0.0" mesh="tablet_base" material="M_head_tilt_link_visual_2" class="hsrb_visual"/>
								<geom name="SM_head_tilt_link_collision_0" type="mesh" pos="0.0 0.0 0.0" quat="1.0 0.0 0.0 0.0" mesh="head" class="hsrb_collision"/>
								<geom name="SM_head_tilt_link_collision_1" type="mesh" pos="0.0 0.0 0.0" quat="1.0 0.0 0.0 0.0" mesh="tablet" class="hsrb_collision"/>
								<joint damping="10.0" name="head_tilt_joint" type="hinge" pos="0.0 0.0 0.0" range="-1.5700000524520874 0.5200000405311584" axis="0.0 -1.0 0.0"/>
								<body name="head_r_stereo_camera_link" pos="0.019999999552965164 -0.07000000029802322 0.061000000685453415" quat="0.5 -0.5 0.5 -0.5">
									<inertial mass="0.0" pos="0.0 0.0 0.0" quat="1.0 0.0 0.0 0.0" diaginertia="0.0 0.0 0.0"/>
									<geom name="SM_head_r_stereo_camera_link_visual_0" type="mesh" pos="0.0 0.0 0.0" quat="1.0 0.0 0.0 0.0" mesh="head_camera" material="M_head_r_stereo_camera_link_visual_0" class="hsrb_visual"/>
									<body name="head_r_stereo_camera_gazebo_frame" pos="0.0 0.0 0.0" quat="0.5 0.5 -0.5 0.5">
										<inertial mass="0.0" pos="0.0 0.0 0.0" quat="1.0 0.0 0.0 0.0" diaginertia="0.0 0.0 0.0"/>
									</body>
								</body>
								<body name="head_center_camera_frame" pos="0.019500000402331352 0.0 0.061000000685453415" quat="0.5 -0.5 0.5 -0.5">
									<inertial mass="0.0" pos="0.0 0.0 0.0" quat="1.0 0.0 0.0 0.0" diaginertia="0.0 0.0 0.0"/>
									<body name="head_center_camera_gazebo_frame" pos="0.0 0.0 0.0" quat="0.5 0.5 -0.5 0.5">
										<inertial mass="0.0" pos="0.0 0.0 0.0" quat="1.0 0.0 0.0 0.0" diaginertia="0.0 0.0 0.0"/>
									</body>
								</body>
								<body name="head_rgbd_sensor_link" pos="-0.07979600131511688 0.02199999988079071 0.21517199277877808" quat="0.5 -0.5 0.5 -0.5">
									<inertial mass="0.1929166316986084" pos="0.022312525659799576 0.003084133379161358 -0.015074222348630428" quat="0.7691020369529724 -0.6354175806045532 0.04338100925087929 0.05333554744720459" diaginertia="7.308930798899382e-05 0.000560473941732198 0.000600011320784688"/>
									<geom name="SM_head_rgbd_sensor_link_visual_0" type="mesh" pos="0.0 0.0 0.0" quat="1.0 0.0 0.0 0.0" mesh="rgbd_light" material="M_head_rgbd_sensor_link_visual_0" class="hsrb_visual"/>
									<geom name="SM_head_rgbd_sensor_link_collision_0" type="mesh" pos="0.0 0.0 0.0" quat="1.0 0.0 0.0 0.0" mesh="rgbd" class="hsrb_collision"/>
									<body name="head_rgbd_sensor_gazebo_frame" pos="0.0 0.0 0.0" quat="0.5 0.5 -0.5 0.5">
										<inertial mass="0.0" pos="0.0 0.0 0.0" quat="1.0 0.0 0.0 0.0" diaginertia="0.0 0.0 0.0"/>
									</body>
								</body>
								<body name="head_l_stereo_camera_link" pos="0.019999999552965164 0.07000000029802322 0.061000000685453415" quat="0.5 -0.5 0.5 -0.5">
									<inertial mass="0.0" pos="0.0 0.0 0.0" quat="1.0 0.0 0.0 0.0" diaginertia="0.0 0.0 0.0"/>
									<geom name="SM_head_l_stereo_camera_link_visual_0" type="mesh" pos="0.0 0.0 0.0" quat="1.0 0.0 0.0 0.0" mesh="head_camera" material="M_head_l_stereo_camera_link_visual_0" class="hsrb_visual"/>
									<body name="head_l_stereo_camera_gazebo_frame" pos="0.0 0.0 0.0" quat="0.5 0.5 -0.5 0.5">
										<inertial mass="0.0" pos="0.0 0.0 0.0" quat="1.0 0.0 0.0 0.0" diaginertia="0.0 0.0 0.0"/>
									</body>
								</body>
							</body>
						</body>
					</body>
					<body name="arm_lift_link" pos="0.0 0.0 0.3400000035762787" quat="1.0 0.0 0.0 0.0">
						<inertial mass="0.1369386464357376" pos="0.0813228189945221 0.026763053610920906 -0.04826762154698372" quat="-0.2750156819820404 0.9039556980133057 0.13705113530158997 -0.2974012494087219" diaginertia="0.0009512149845249951 0.0017490539466962218 0.0022147856652736664"/>
						<geom name="SM_arm_lift_link_visual_0" type="mesh" pos="0.0 0.0 0.0" quat="1.0 0.0 0.0 0.0" mesh="shoulder" material="M_arm_lift_link_visual_0" class="hsrb_visual"/>
						<geom name="SM_arm_lift_link_collision_0" type="mesh" pos="0.0 0.0 0.0" quat="1.0 0.0 0.0 0.0" mesh="shoulder" class="hsrb_collision"/>
						<joint damping="10.0" name="arm_lift_joint" type="slide" pos="0.0 0.0 0.0" range="0.0 0.6899999976158142" axis="0.0 0.0 1.0"/>
						<body name="arm_flex_link" pos="0.14100000262260437 0.07800000160932541 0.0" quat="1.0 0.0 0.0 0.0">
							<inertial mass="2.1093451976776123" pos="-0.0004589901363942772 0.0065834117121994495 0.10606901347637177" quat="0.01475102361291647 0.7085751891136169 -0.019227612763643265 -0.705219030380249" diaginertia="0.0029768238309770823 0.03662457689642906 0.037757232785224915"/>
							<geom name="SM_arm_flex_link_visual_0" type="mesh" pos="0.0 0.0 0.0" quat="1.0 0.0 0.0 0.0" mesh="arm_flex_light" material="M_arm_flex_link_visual_0" class="hsrb_visual"/>
							<geom name="SM_arm_flex_link_collision_0" type="mesh" pos="0.0 0.0 0.0" quat="1.0 0.0 0.0 0.0" mesh="arm_flex" class="hsrb_collision"/>
							<joint damping="10.0" name="arm_flex_joint" type="hinge" pos="0.0 0.0 0.0" range="-2.620000123977661 0.0" axis="0.0 -1.0 0.0"/>
							<body name="arm_roll_link" pos="0.004999999888241291 0.0 0.3449999988079071" quat="1.0 0.0 0.0 0.0">
								<inertial mass="0.9090999960899353" pos="-0.004909095820039511 0.003416739171370864 -0.04720309004187584" quat="0.673842191696167 0.032797303050756454 0.7376915216445923 0.025928547605872154" diaginertia="0.001125680049881339 0.0036435395013540983 0.0040444317273795605"/>
								<geom name="SM_arm_roll_link_visual_0" type="mesh" pos="0.0 0.0 0.0" quat="1.0 0.0 0.0 0.0" mesh="arm_roll_light" material="M_arm_roll_link_visual_0" class="hsrb_visual"/>
								<geom name="SM_arm_roll_link_collision_0" type="mesh" pos="0.0 0.0 0.0" quat="1.0 0.0 0.0 0.0" mesh="arm_roll" class="hsrb_collision"/>
								<joint damping="10.0" name="arm_roll_joint" type="hinge" pos="-4.336808689942018e-18 0.0 -5.551115123125783e-17" range="-2.0899999141693115 3.8399999141693115" axis="0.0 0.0 1.0"/>
								<body name="wrist_flex_link" pos="0.0 0.0 0.0" quat="1.0 0.0 0.0 0.0">
									<inertial mass="0.03631681203842163" pos="0.0 0.0 0.029999999329447746" quat="0.7071067690849304 0.0 0.7071067690849304 0.0" diaginertia="5.247779427008936e-06 4.015126251033507e-05 4.015126251033507e-05"/>
									<geom name="SM_wrist_flex_link_visual_0" type="mesh" pos="0.0 0.0 0.0" quat="1.0 0.0 0.0 0.0" mesh="wrist_flex" material="M_wrist_flex_link_visual_0" class="hsrb_visual"/>
									<geom name="SM_wrist_flex_link_visual_1" type="cylinder" pos="0.0 0.0 0.03999999910593033" quat="1.0 0.0 0.0 0.0" size="0.017000000923871994 0.009999999776482582 0.0" rgba="0.78431374 0.78431374 0.78431374 1.0" class="hsrb_visual"/>
									<geom name="SM_wrist_flex_link_collision_0" type="cylinder" pos="0.0 0.0 0.029999999329447746" quat="1.0 0.0 0.0 0.0" size="0.017000000923871994 0.019999999552965164 0.0" class="hsrb_collision"/>
									<joint damping="10.0" name="wrist_flex_joint" type="hinge" pos="0.0 0.0 0.0" range="-1.9199999570846558 1.21999990940094" axis="0.0 -1.0 0.0"/>
									<body name="wrist_roll_link" pos="0.0 0.0 0.0" quat="1.0 0.0 0.0 0.0">
										<inertial mass="0.06149858608841896" pos="-0.010066617280244827 -2.47548523475416e-05 0.0884910598397255" quat="-0.6550278663635254 2.011494871112518e-05 0.7556046843528748 0.0003620499628596008" diaginertia="0.00011161583825014532 0.0005890678730793297 0.000613926793448627"/>
										<geom name="SM_wrist_roll_link_visual_0" type="mesh" pos="0.0 0.0 0.0" quat="1.0 0.0 0.0 0.0" mesh="wrist_roll" material="M_wrist_roll_link_visual_0" class="hsrb_visual"/>
										<geom name="SM_wrist_roll_link_collision_0" type="mesh" pos="0.0 0.0 0.0" quat="1.0 0.0 0.0 0.0" mesh="wrist_roll" class="hsrb_collision"/>
										<joint damping="10.0" name="wrist_roll_joint" type="hinge" pos="0.0 0.0 0.0" range="-1.9199999570846558 3.6700000762939453" axis="0.0 0.0 1.0"/>
										<body name="hand_palm_link" pos="0.012000000104308128 0.0 0.1404999941587448" quat="-1.0341155557737347e-13 0.0 0.0 1.0">
											<inertial mass="0.08773984014987946" pos="0.0012877753470093012 0.00030466882162727416 -0.024661114439368248" quat="-0.6860979795455933 -0.010482939891517162 0.7274026870727539 0.006707098800688982" diaginertia="3.0547216738341376e-05 7.715255196671933e-05 9.0780173195526e-05"/>
											<geom name="SM_hand_palm_link_visual_0" type="mesh" pos="0.0 0.0 0.0" quat="1.0 0.0 0.0 0.0" mesh="palm" rgba="0.78431374 0.78431374 0.78431374 1.0" class="hsrb_visual"/>
											<geom name="SM_hand_palm_link_collision_0" type="mesh" pos="0.0 0.0 0.0" quat="1.0 0.0 0.0 0.0" mesh="palm" class="hsrb_collision"/>
											<body name="hand_l_proximal_link" pos="-0.016750000417232513 -0.02449999935925007 -0.017500000074505806" quat="1.0 0.0 0.0 0.0">
												<inertial mass="0.001" pos="0.0 0.0 0.0" quat="1.0 0.0 0.0 0.0" diaginertia="0.001 0.001 0.001"/>
												<joint damping="10.0" name="hand_l_proximal_joint" type="hinge" pos="-1.3877787807814457e-17 -6.938893903907228e-18 -4.163336342344337e-17" range="-0.7979999780654907 1.2400000095367432" axis="1.0 0.0 0.0"/>
												<body name="hand_l_spring_proximal_link" pos="0.0 0.0 0.0" quat="1.0 0.0 0.0 0.0">
													<inertial mass="0.042135074734687805" pos="0.018756786361336708 -0.0022016807924956083 0.030663585290312767" quat="-0.5874428749084473 0.6060451865196228 0.3529996871948242 0.403746634721756" diaginertia="8.60757427290082e-06 7.024005753919482e-05 7.688956247875467e-05"/>
													<geom name="SM_hand_l_spring_proximal_link_visual_0" type="mesh" pos="0.0 0.0 0.0" quat="1.0 0.0 0.0 0.0" mesh="l_proximal" rgba="0.78431374 0.78431374 0.78431374 1.0" class="hsrb_visual"/>
													<geom name="SM_hand_l_spring_proximal_link_collision_0" type="mesh" pos="0.0 0.0 0.0" quat="1.0 0.0 0.0 0.0" mesh="l_proximal" class="hsrb_collision"/>
													<joint damping="10.0" name="hand_l_spring_proximal_joint" type="hinge" pos="0.0 0.0 0.0" range="0.0 0.6980000138282776" axis="1.0 0.0 0.0"/>
													<body name="hand_l_mimic_distal_link" pos="0.0 0.0 0.07000000029802322" quat="1.0 0.0 0.0 0.0">
														<inertial mass="0.001" pos="0.0 0.0 0.0" quat="1.0 0.0 0.0 0.0" diaginertia="0.001 0.001 0.001"/>
														<joint damping="10.0" name="hand_l_mimic_distal_joint" type="hinge" pos="0.0 0.0 5.551115123125783e-17" range="-0.6980000138282776 -0.0" axis="1.0 0.0 0.0"/>
														<body name="hand_l_distal_link" pos="0.0 0.0 0.0" quat="1.0 0.0 0.0 0.0">
															<inertial mass="0.03458765894174576" pos="0.01525004580616951 0.004431677516549826 0.019333720207214355" quat="0.3817766010761261 0.23210614919662476 0.6331768035888672 -0.6320288777351379" diaginertia="6.055272024241276e-06 2.712272726057563e-05 2.945130836451426e-05"/>
															<geom name="SM_hand_l_distal_link_visual_0" type="mesh" pos="0.0 0.0 0.0" quat="1.0 0.0 0.0 0.0" mesh="l_distal" rgba="0.78431374 0.78431374 0.78431374 1.0" class="hsrb_visual"/>
															<geom name="SM_hand_l_distal_link_collision_0" type="mesh" pos="0.0 0.0 0.0" quat="1.0 0.0 0.0 0.0" mesh="l_distal" class="hsrb_collision"/>
															<joint damping="10.0" name="hand_l_distal_joint" type="hinge" pos="0.0 0.0 0.0" range="-1.2400000095367432 0.7979999780654907" axis="1.0 0.0 0.0"/>
															<body name="hand_l_finger_vacuum_frame" pos="0.004749999847263098 -0.01153900008648634 0.03322000056505203" quat="0.9238795042037964 0.3826834261417389 0.0 0.0">
																<inertial mass="0.001" pos="0.0 0.0 0.0" quat="1.0 0.0 0.0 0.0" diaginertia="0.001 0.001 0.001"/>
																<geom name="SM_hand_l_finger_vacuum_frame_visual_0" type="box" pos="0.0 0.0 -0.009999999776482582" quat="1.0 0.0 0.0 0.0" size="0.004000000189989805 0.004000000189989805 0.009999999776482582" rgba="0.78431374 0.78431374 0.78431374 1.0" class="hsrb_visual"/>
															</body>
															<body name="hand_l_finger_tip_frame" pos="0.016750000417232513 0.019300000742077827 0.03790000081062317" quat="-0.7071067690849304 0.7071067690849304 0.0 0.0">
																<inertial mass="0.0" pos="0.0 0.0 0.0" quat="1.0 0.0 0.0 0.0" diaginertia="0.0 0.0 0.0"/>
															</body>
														</body>
													</body>
												</body>
											</body>
											<body name="hand_r_proximal_link" pos="-0.016750000417232513 0.02449999935925007 -0.017500000074505806" quat="1.0 0.0 0.0 0.0">
												<inertial mass="0.001" pos="0.0 0.0 0.0" quat="1.0 0.0 0.0 0.0" diaginertia="0.001 0.001 0.001"/>
												<joint damping="10.0" name="hand_r_proximal_joint" type="hinge" pos="-1.3877787807814457e-17 2.8702472503576013e-30 -4.163336342344337e-17" range="-0.7979999780654907 1.2400000095367432" axis="-1.0 0.0 0.0"/>
												<body name="hand_r_spring_proximal_link" pos="0.0 0.0 0.0" quat="1.0 0.0 0.0 0.0">
													<inertial mass="0.04147995635867119" pos="0.018127676099538803 0.0021659941412508488 0.030857620760798454" quat="0.6110666990280151 -0.5782454013824463 -0.411460280418396 -0.3506140410900116" diaginertia="7.921276846900582e-06 6.877347186673433e-05 7.483593799406663e-05"/>
													<geom name="SM_hand_r_spring_proximal_link_visual_0" type="mesh" pos="0.0 0.0 0.0" quat="1.0 0.0 0.0 0.0" mesh="r_proximal" rgba="0.78431374 0.78431374 0.78431374 1.0" class="hsrb_visual"/>
													<geom name="SM_hand_r_spring_proximal_link_collision_0" type="mesh" pos="0.0 0.0 0.0" quat="1.0 0.0 0.0 0.0" mesh="r_proximal" class="hsrb_collision"/>
													<joint damping="10.0" name="hand_r_spring_proximal_joint" type="hinge" pos="0.0 0.0 0.0" range="0.0 0.6980000138282776" axis="-1.0 0.0 0.0"/>
													<body name="hand_r_mimic_distal_link" pos="0.0 0.0 0.07000000029802322" quat="1.0 0.0 0.0 0.0">
														<inertial mass="0.001" pos="0.0 0.0 0.0" quat="1.0 0.0 0.0 0.0" diaginertia="0.001 0.001 0.001"/>
														<joint damping="10.0" name="hand_r_mimic_distal_joint" type="hinge" pos="0.0 0.0 5.551115123125783e-17" range="-0.6980000138282776 -0.0" axis="-1.0 0.0 0.0"/>
														<body name="hand_r_distal_link" pos="0.0 0.0 0.0" quat="1.0 0.0 0.0 0.0">
															<inertial mass="0.024421628564596176" pos="0.017135124653577805 -0.007652597967535257 0.01713944971561432" quat="0.21702277660369873 0.3457382321357727 0.7525501251220703 -0.5167538523674011" diaginertia="3.450870281085372e-06 1.9094664821750484e-05 2.1310002921381965e-05"/>
															<geom name="SM_hand_r_distal_link_visual_0" type="mesh" pos="0.0 0.0 0.0" quat="1.0 0.0 0.0 0.0" mesh="r_distal" rgba="0.78431374 0.78431374 0.78431374 1.0" class="hsrb_visual"/>
															<geom name="SM_hand_r_distal_link_collision_0" type="mesh" pos="0.0 0.0 0.0" quat="1.0 0.0 0.0 0.0" mesh="r_distal" class="hsrb_collision"/>
															<joint damping="10.0" name="hand_r_distal_joint" type="hinge" pos="0.0 0.0 0.0" range="-1.2400000095367432 0.7979999780654907" axis="-1.0 0.0 0.0"/>
															<body name="hand_r_finger_tip_frame" pos="0.016750000417232513 -0.019300000742077827 0.03790000081062317" quat="0.7071067690849304 0.7071067690849304 0.0 0.0">
																<inertial mass="0.001" pos="0.0 0.0 0.0" quat="1.0 0.0 0.0 0.0" diaginertia="0.001 0.001 0.001"/>
															</body>
														</body>
													</body>
												</body>
											</body>
											<body name="hand_camera_frame" pos="0.039000000804662704 -1.3877787807814457e-17 -0.0044999998062849045" quat="1.0 0.0 0.0 0.0">
												<inertial mass="0.0" pos="0.0 0.0 0.0" quat="1.0 0.0 0.0 0.0" diaginertia="0.0 0.0 0.0"/>
												<body name="hand_camera_gazebo_frame" pos="0.0 0.0 0.0" quat="0.5 0.5 -0.5 0.5">
													<inertial mass="0.0" pos="0.0 0.0 0.0" quat="1.0 0.0 0.0 0.0" diaginertia="0.0 0.0 0.0"/>
												</body>
											</body>
											<body name="hand_gripper_tool_frame" pos="0.0 0.0 0.07000000029802322" quat="1.0 0.0 0.0 0.0">
												<inertial mass="0.0" pos="0.0 0.0 0.0" quat="1.0 0.0 0.0 0.0" diaginertia="0.0 0.0 0.0"/>
											</body>
											<body name="hand_motor_dummy_link" pos="0.0 0.0 0.0" quat="1.0 0.0 0.0 0.0">
												<inertial mass="0.001" pos="0.0 0.0 0.0" quat="1.0 0.0 0.0 0.0" diaginertia="0.001 0.001 0.001"/>
												<joint damping="10.0" name="hand_motor_joint" type="hinge" pos="0.0 0.0 0.0" range="-0.7979999780654907 1.2400000095367432" axis="1.0 0.0 0.0"/>
											</body>
										</body>
										<body name="wrist_ft_sensor_frame" pos="0.0 0.0 0.07349999994039536" quat="-1.0341155557737347e-13 1.0 0.0 0.0">
											<inertial mass="0.0" pos="0.0 0.0 0.0" quat="1.0 0.0 0.0 0.0" diaginertia="0.0 0.0 0.0"/>
										</body>
									</body>
								</body>
							</body>
						</body>
					</body>
					<body name="base_roll_link" pos="0.0 0.0 0.0" quat="1.0 0.0 0.0 0.0">
						<inertial mass="0.0" pos="0.0 0.0 0.0" quat="1.0 0.0 0.0 0.0" diaginertia="0.0 0.0 0.0"/>
						<joint damping="10.0" name="base_roll_joint" type="hinge" pos="0.0 0.0 0.0" axis="0.0 0.0 1.0"/>
						<body name="base_l_drive_wheel_link" pos="-0.10999999940395355 0.13300000131130219 0.03999999910593033" quat="1.0 0.0 0.0 0.0">
							<inertial mass="0.15079644322395325" pos="0.0 0.0 0.0" quat="0.0 0.0 0.7071067690849304 -0.7071067690849304" diaginertia="7.162831025198102e-05 7.162831025198102e-05 0.00012063715985277668"/>
							<geom name="SM_base_l_drive_wheel_link_visual_0" type="cylinder" pos="0.0 0.0 0.0" quat="0.7071067690849304 0.7071067690849304 0.0 0.0" size="0.03999999910593033 0.014999999664723873 0.0" rgba="0.78431374 0.78431374 0.78431374 1.0" class="hsrb_visual"/>
							<geom name="SM_base_l_drive_wheel_link_collision_0" type="cylinder" pos="0.0 0.0 0.0" quat="0.7071067690849304 0.7071067690849304 0.0 0.0" size="0.03999999910593033 0.014999999664723873 0.0" class="hsrb_collision"/>
							<joint damping="10.0" name="base_l_drive_wheel_joint" type="hinge" pos="0.0 0.0 0.0" axis="0.0 1.0 0.0"/>
						</body>
						<body name="base_l_passive_wheel_x_frame" pos="0.14949999749660492 0.054999999701976776 0.029999999329447746" quat="1.0 0.0 0.0 0.0">
							<inertial mass="0.0" pos="0.0 0.0 0.0" quat="1.0 0.0 0.0 0.0" diaginertia="0.0 0.0 0.0"/>
							<joint damping="10.0" name="base_l_passive_wheel_x_frame_joint" type="hinge" pos="0.0 0.0 0.0" axis="1.0 0.0 0.0"/>
							<body name="base_l_passive_wheel_y_frame" pos="0.0 0.0 0.0" quat="1.0 0.0 0.0 0.0">
								<inertial mass="0.0" pos="0.0 0.0 0.0" quat="1.0 0.0 0.0 0.0" diaginertia="0.0 0.0 0.0"/>
								<joint damping="10.0" name="base_l_passive_wheel_y_frame_joint" type="hinge" pos="0.0 0.0 0.0" axis="0.0 1.0 0.0"/>
								<body name="base_l_passive_wheel_z_link" pos="0.0 0.0 0.0" quat="1.0 0.0 0.0 0.0">
									<inertial mass="0.11309733241796494" pos="0.0 0.0 0.0" quat="1.0 0.0 0.0 0.0" diaginertia="4.0715040086070076e-05 4.0715040086070076e-05 4.0715040086070076e-05"/>
									<geom name="SM_base_l_passive_wheel_z_link_visual_0" type="sphere" pos="0.0 0.0 0.0" quat="1.0 0.0 0.0 0.0" size="0.029999999329447746 0.0 0.0" rgba="0.78431374 0.78431374 0.78431374 1.0" class="hsrb_visual"/>
									<geom name="SM_base_l_passive_wheel_z_link_collision_0" type="sphere" pos="0.0 0.0 0.0" quat="1.0 0.0 0.0 0.0" size="0.029999999329447746 0.0 0.0" class="hsrb_collision"/>
									<joint damping="10.0" name="base_l_passive_wheel_z_joint" type="hinge" pos="0.0 0.0 0.0" axis="0.0 0.0 1.0"/>
								</body>
							</body>
						</body>
						<body name="base_r_drive_wheel_link" pos="-0.10999999940395355 -0.13300000131130219 0.03999999910593033" quat="1.0 0.0 0.0 0.0">
							<inertial mass="0.15079644322395325" pos="0.0 0.0 0.0" quat="0.0 0.0 0.7071067690849304 -0.7071067690849304" diaginertia="7.162831025198102e-05 7.162831025198102e-05 0.00012063715985277668"/>
							<geom name="SM_base_r_drive_wheel_link_visual_0" type="cylinder" pos="0.0 0.0 0.0" quat="0.7071067690849304 0.7071067690849304 0.0 0.0" size="0.03999999910593033 0.014999999664723873 0.0" rgba="0.78431374 0.78431374 0.78431374 1.0" class="hsrb_visual"/>
							<geom name="SM_base_r_drive_wheel_link_collision_0" type="cylinder" pos="0.0 0.0 0.0" quat="0.7071067690849304 0.7071067690849304 0.0 0.0" size="0.03999999910593033 0.014999999664723873 0.0" class="hsrb_collision"/>
							<joint damping="10.0" name="base_r_drive_wheel_joint" type="hinge" pos="0.0 0.0 0.0" axis="0.0 1.0 0.0"/>
						</body>
						<body name="base_r_passive_wheel_x_frame" pos="0.14949999749660492 -0.054999999701976776 0.029999999329447746" quat="1.0 0.0 0.0 0.0">
							<inertial mass="0.0" pos="0.0 0.0 0.0" quat="1.0 0.0 0.0 0.0" diaginertia="0.0 0.0 0.0"/>
							<joint damping="10.0" name="base_r_passive_wheel_x_frame_joint" type="hinge" pos="0.0 0.0 0.0" axis="1.0 0.0 0.0"/>
							<body name="base_r_passive_wheel_y_frame" pos="0.0 0.0 0.0" quat="1.0 0.0 0.0 0.0">
								<inertial mass="0.0" pos="0.0 0.0 0.0" quat="1.0 0.0 0.0 0.0" diaginertia="0.0 0.0 0.0"/>
								<joint damping="10.0" name="base_r_passive_wheel_y_frame_joint" type="hinge" pos="0.0 0.0 0.0" axis="0.0 1.0 0.0"/>
								<body name="base_r_passive_wheel_z_link" pos="0.0 0.0 0.0" quat="1.0 0.0 0.0 0.0">
									<inertial mass="0.11309733241796494" pos="0.0 0.0 0.0" quat="1.0 0.0 0.0 0.0" diaginertia="4.0715040086070076e-05 4.0715040086070076e-05 4.0715040086070076e-05"/>
									<geom name="SM_base_r_passive_wheel_z_link_visual_0" type="sphere" pos="0.0 0.0 0.0" quat="1.0 0.0 0.0 0.0" size="0.029999999329447746 0.0 0.0" rgba="0.78431374 0.78431374 0.78431374 1.0" class="hsrb_visual"/>
									<geom name="SM_base_r_passive_wheel_z_link_collision_0" type="sphere" pos="0.0 0.0 0.0" quat="1.0 0.0 0.0 0.0" size="0.029999999329447746 0.0 0.0" class="hsrb_collision"/>
									<joint damping="10.0" name="base_r_passive_wheel_z_joint" type="hinge" pos="0.0 0.0 0.0" axis="0.0 0.0 1.0"/>
								</body>
							</body>
						</body>
					</body>
					<body name="base_imu_frame" pos="0.0005000000237487257 0.12960000336170197 0.1809999942779541" quat="-1.0341155557737347e-13 1.0 0.0 0.0">
						<inertial mass="0.0" pos="0.0 0.0 0.0" quat="1.0 0.0 0.0 0.0" diaginertia="0.0 0.0 0.0"/>
					</body>
				</body>
			</body>
		</body>
	</worldbody>
	<equality>
		<joint name="torso_lift_joint_arm_lift_joint" joint1="torso_lift_joint" joint2="arm_lift_joint" polycoef="0.0 0.5 0.0 0.0 0.0"/>
		<joint name="hand_l_proximal_joint_hand_motor_joint" joint1="hand_l_proximal_joint" joint2="hand_motor_joint" polycoef="0.0 1.0 0.0 0.0 0.0"/>
		<joint name="hand_r_proximal_joint_hand_motor_joint" joint1="hand_r_proximal_joint" joint2="hand_motor_joint" polycoef="0.0 1.0 0.0 0.0 0.0"/>
		<joint name="hand_r_mimic_distal_joint_hand_r_spring_proximal_joint" joint1="hand_r_mimic_distal_joint" joint2="hand_r_spring_proximal_joint" polycoef="0.0 -1.0 0.0 0.0 0.0"/>
		<joint name="hand_l_mimic_distal_joint_hand_l_spring_proximal_joint" joint1="hand_l_mimic_distal_joint" joint2="hand_l_spring_proximal_joint" polycoef="0.0 -1.0 0.0 0.0 0.0"/>
		<joint name="hand_r_distal_joint_hand_motor_joint" joint1="hand_r_distal_joint" joint2="hand_motor_joint" polycoef="-0.08699999749660492 -1.0 0.0 0.0 0.0"/>
		<joint name="hand_l_distal_joint_hand_motor_joint" joint1="hand_l_distal_joint" joint2="hand_motor_joint" polycoef="-0.08699999749660492 -1.0 0.0 0.0 0.0"/>
	</equality>

	<actuator>
		<position name="arm_lift_actuator" joint="arm_lift_joint" kp="2000" kv="500" forcerange="-1500 1500" ctrlrange="0.0 0.6899999976158142" />
		<position name="arm_flex_actuator" joint="arm_flex_joint" kp="500" kv="100" forcerange="-1500 1500" ctrlrange="-2.620000123977661 0.0" />
		<position name="arm_roll_actuator" joint="arm_roll_joint" kp="500" kv="5" forcerange="-1000 1000" ctrlrange="-2.0899999141693115 3.8399999141693115" />
		<position name="wrist_flex_actuator" joint="wrist_flex_joint" kp="200" kv="2" forcerange="-500 500" ctrlrange="-1.9199999570846558 1.21999990940094" />
		<position name="wrist_roll_actuator" joint="wrist_roll_joint" kp="200" kv="2" forcerange="-100 100" ctrlrange="-1.9199999570846558 3.6700000762939453" />
		
		<motor name="hand_motor_actuator" joint="hand_motor_joint" forcerange="-1000 1000" ctrlrange="-100 100"/>

		<position name="head_pan_actuator" joint="head_pan_joint" kp="500" kv="10" forcerange="-500 500" ctrlrange="-3.8399999141693115 1.75"/>
		<position name="head_tilt_actuator" joint="head_tilt_joint" kp="500" kv="10" forcerange="-500 500" ctrlrange="-1.5700000524520874 0.5200000405311584"/>
	</actuator>

	<contact>
		<exclude name="base_link_arm_lift_link" body1="base_link" body2="arm_lift_link"/>
        <exclude name="base_link_arm_flex_link" body1="base_link" body2="arm_flex_link"/>
        <exclude name="base_link_torso_lift_link" body1="base_link" body2="torso_lift_link"/>
        <exclude name="base_l_drive_wheel_link_base_link" body1="base_l_drive_wheel_link" body2="base_link"/>
        <exclude name="base_l_passive_wheel_z_link_base_link" body1="base_l_passive_wheel_z_link" body2="base_link"/>
        <exclude name="base_r_drive_wheel_link_base_link" body1="base_r_drive_wheel_link" body2="base_link"/>
        <exclude name="base_r_passive_wheel_z_link_base_link" body1="base_r_passive_wheel_z_link" body2="base_link"/>
        <exclude name="wrist_roll_link_hand_r_spring_proximal_link" body1="wrist_roll_link" body2="hand_r_spring_proximal_link"/>
        <exclude name="wrist_roll_link_hand_l_spring_proximal_link" body1="wrist_roll_link" body2="hand_l_spring_proximal_link"/>
        <exclude name="hand_palm_link_hand_r_spring_proximal_link" body1="hand_palm_link" body2="hand_r_spring_proximal_link"/>
        <exclude name="hand_palm_link_hand_l_spring_proximal_link" body1="hand_palm_link" body2="hand_l_spring_proximal_link"/>
        <exclude name="hand_l_spring_proximal_link_hand_l_distal_link" body1="hand_l_spring_proximal_link" body2="hand_l_distal_link"/>
        <exclude name="hand_r_spring_proximal_link_hand_r_distal_link" body1="hand_r_spring_proximal_link" body2="hand_r_distal_link"/>
    </contact>
</mujoco>
