<?xml version="1.0" ?>
<mujoco model="justin">
	<compiler meshdir="rollin-justin/meshes" texturedir="rollin-justin/textures" angle="radian" autolimits="true" balanceinertia="true" boundmass="0.000001" boundinertia="0.000001"/>
	<default>
		<default class="rollin-justin_visual">
			<geom contype="0" conaffinity="0"/>
		</default>
		<default class="rollin-justin_collision">
			<geom rgba="0.9 0.9 0.9 1.0"/>
		</default>
	</default>
	<asset>
		<mesh name="mp_mobile_plattform_rj_BASE_collision_0_0010000000474974513_0_0010000000474974513_0_0010000000474974513" file="stl/mp_mobile_plattform_rj_BASE_collision.stl" scale="0.0010000000474974513 0.0010000000474974513 0.0010000000474974513"/>
		<mesh name="mp_mobile_plattform_rj_ROT1_collision_0_0010000000474974513_0_0010000000474974513_0_0010000000474974513" file="stl/mp_mobile_plattform_rj_ROT1_collision.stl" scale="0.0010000000474974513 0.0010000000474974513 0.0010000000474974513"/>
		<mesh name="mp_mobile_plattform_rj_ROT2_collision_0_0010000000474974513_0_0010000000474974513_0_0010000000474974513" file="stl/mp_mobile_plattform_rj_ROT2_collision.stl" scale="0.0010000000474974513 0.0010000000474974513 0.0010000000474974513"/>
		<mesh name="mp_mobile_plattform_rj_ROT3_collision_0_0010000000474974513_0_0010000000474974513_0_0010000000474974513" file="stl/mp_mobile_plattform_rj_ROT3_collision.stl" scale="0.0010000000474974513 0.0010000000474974513 0.0010000000474974513"/>
		<mesh name="mp_mobile_plattform_rj_ROT4_collision_0_0010000000474974513_0_0010000000474974513_0_0010000000474974513" file="stl/mp_mobile_plattform_rj_ROT4_collision.stl" scale="0.0010000000474974513 0.0010000000474974513 0.0010000000474974513"/>
		<mesh name="trs_plat_dummy_Trs_Base_A0_collision_0_0010000000474974513_0_0010000000474974513_0_0010000000474974513" file="stl/trs_plat_dummy_Trs_Base_A0_collision.stl" scale="0.0010000000474974513 0.0010000000474974513 0.0010000000474974513"/>
		<mesh name="trs_plat_dummy_A1_collision_0_0010000000474974513_0_0010000000474974513_0_0010000000474974513" file="stl/trs_plat_dummy_A1_collision.stl" scale="0.0010000000474974513 0.0010000000474974513 0.0010000000474974513"/>
		<mesh name="trs_plat_dummy_A2_collision_0_0010000000474974513_0_0010000000474974513_0_0010000000474974513" file="stl/trs_plat_dummy_A2_collision.stl" scale="0.0010000000474974513 0.0010000000474974513 0.0010000000474974513"/>
		<mesh name="trs_plat_dummy_A3_collision_0_0010000000474974513_0_0010000000474974513_0_0010000000474974513" file="stl/trs_plat_dummy_A3_collision.stl" scale="0.0010000000474974513 0.0010000000474974513 0.0010000000474974513"/>
		<mesh name="trs_plat_dummy_A4_collision_0_0010000000474974513_0_0010000000474974513_0_0010000000474974513" file="stl/trs_plat_dummy_A4_collision.stl" scale="0.0010000000474974513 0.0010000000474974513 0.0010000000474974513"/>
		<mesh name="lr33_J1_Base_frame_collision_0_0010000000474974513_0_0010000000474974513_0_0010000000474974513" file="stl/lr33_J1_Base_frame_collision.stl" scale="0.0010000000474974513 0.0010000000474974513 0.0010000000474974513"/>
		<mesh name="justin_rj_kopf_HALS_EINBAU_collision_0_0010000000474974513_0_0010000000474974513_0_0010000000474974513" file="stl/justin_rj_kopf_HALS_EINBAU_collision.stl" scale="0.0010000000474974513 0.0010000000474974513 0.0010000000474974513"/>
		<mesh name="lr33_J2_HUELLE_A1_collision_0_0010000000474974513_0_0010000000474974513_0_0010000000474974513" file="stl/lr33_J2_HUELLE_A1_collision.stl" scale="0.0010000000474974513 0.0010000000474974513 0.0010000000474974513"/>
		<mesh name="lr33_J3_HUELLE_A2_collision_0_0010000000474974513_0_0010000000474974513_0_0010000000474974513" file="stl/lr33_J3_HUELLE_A2_collision.stl" scale="0.0010000000474974513 0.0010000000474974513 0.0010000000474974513"/>
		<mesh name="lr33_J4_HUELLE_A3_collision_0_0010000000474974513_0_0010000000474974513_0_0010000000474974513" file="stl/lr33_J4_HUELLE_A3_collision.stl" scale="0.0010000000474974513 0.0010000000474974513 0.0010000000474974513"/>
		<mesh name="lr33_J5_HUELLE_A4_collision_0_0010000000474974513_0_0010000000474974513_0_0010000000474974513" file="stl/lr33_J5_HUELLE_A4_collision.stl" scale="0.0010000000474974513 0.0010000000474974513 0.0010000000474974513"/>
		<mesh name="lr33_J6_HUELLE_A5_collision_0_0010000000474974513_0_0010000000474974513_0_0010000000474974513" file="stl/lr33_J6_HUELLE_A5_collision.stl" scale="0.0010000000474974513 0.0010000000474974513 0.0010000000474974513"/>
		<mesh name="lr33_J7_HUELLE_A6_collision_0_0010000000474974513_0_0010000000474974513_0_0010000000474974513" file="stl/lr33_J7_HUELLE_A6_collision.stl" scale="0.0010000000474974513 0.0010000000474974513 0.0010000000474974513"/>
		<mesh name="lr33_J8_HUELLE_A7_collision_0_0010000000474974513_0_0010000000474974513_0_0010000000474974513" file="stl/lr33_J8_HUELLE_A7_collision.stl" scale="0.0010000000474974513 0.0010000000474974513 0.0010000000474974513"/>
		<mesh name="hii_links_export_Base_SWA_collision_0_0010000000474974513_0_0010000000474974513_0_0010000000474974513" file="stl/hii_links_export_Base_SWA_collision.stl" scale="0.0010000000474974513 0.0010000000474974513 0.0010000000474974513"/>
		<mesh name="hii_links_export_D_MP_AB1_collision_0_0010000000474974513_0_0010000000474974513_0_0010000000474974513" file="stl/hii_links_export_D_MP_AB1_collision.stl" scale="0.0010000000474974513 0.0010000000474974513 0.0010000000474974513"/>
		<mesh name="hii_links_export_D_MP_AB2_collision_0_0010000000474974513_0_0010000000474974513_0_0010000000474974513" file="stl/hii_links_export_D_MP_AB2_collision.stl" scale="0.0010000000474974513 0.0010000000474974513 0.0010000000474974513"/>
		<mesh name="hii_links_export_D_PIP_collision_0_0010000000474974513_0_0010000000474974513_0_0010000000474974513" file="stl/hii_links_export_D_PIP_collision.stl" scale="0.0010000000474974513 0.0010000000474974513 0.0010000000474974513"/>
		<mesh name="hii_links_export_D_DIP_collision_0_0010000000474974513_0_0010000000474974513_0_0010000000474974513" file="stl/hii_links_export_D_DIP_collision.stl" scale="0.0010000000474974513 0.0010000000474974513 0.0010000000474974513"/>
		<mesh name="hii_links_export_ZF_MP_AB1_collision_0_0010000000474974513_0_0010000000474974513_0_0010000000474974513" file="stl/hii_links_export_ZF_MP_AB1_collision.stl" scale="0.0010000000474974513 0.0010000000474974513 0.0010000000474974513"/>
		<mesh name="hii_links_export_ZF_MP_AB2_collision_0_0010000000474974513_0_0010000000474974513_0_0010000000474974513" file="stl/hii_links_export_ZF_MP_AB2_collision.stl" scale="0.0010000000474974513 0.0010000000474974513 0.0010000000474974513"/>
		<mesh name="hii_links_export_ZF_PIP_collision_0_0010000000474974513_0_0010000000474974513_0_0010000000474974513" file="stl/hii_links_export_ZF_PIP_collision.stl" scale="0.0010000000474974513 0.0010000000474974513 0.0010000000474974513"/>
		<mesh name="hii_links_export_ZF_DIP_collision_0_0010000000474974513_0_0010000000474974513_0_0010000000474974513" file="stl/hii_links_export_ZF_DIP_collision.stl" scale="0.0010000000474974513 0.0010000000474974513 0.0010000000474974513"/>
		<mesh name="hii_links_export_MF_MP_AB1_collision_0_0010000000474974513_0_0010000000474974513_0_0010000000474974513" file="stl/hii_links_export_MF_MP_AB1_collision.stl" scale="0.0010000000474974513 0.0010000000474974513 0.0010000000474974513"/>
		<mesh name="hii_links_export_MF_MP_AB2_collision_0_0010000000474974513_0_0010000000474974513_0_0010000000474974513" file="stl/hii_links_export_MF_MP_AB2_collision.stl" scale="0.0010000000474974513 0.0010000000474974513 0.0010000000474974513"/>
		<mesh name="hii_links_export_MF_PIP_collision_0_0010000000474974513_0_0010000000474974513_0_0010000000474974513" file="stl/hii_links_export_MF_PIP_collision.stl" scale="0.0010000000474974513 0.0010000000474974513 0.0010000000474974513"/>
		<mesh name="hii_links_export_MF_DIP_collision_0_0010000000474974513_0_0010000000474974513_0_0010000000474974513" file="stl/hii_links_export_MF_DIP_collision.stl" scale="0.0010000000474974513 0.0010000000474974513 0.0010000000474974513"/>
		<mesh name="hii_links_export_RF_MP_AB1_collision_0_0010000000474974513_0_0010000000474974513_0_0010000000474974513" file="stl/hii_links_export_RF_MP_AB1_collision.stl" scale="0.0010000000474974513 0.0010000000474974513 0.0010000000474974513"/>
		<mesh name="hii_links_export_RF_MP_AB2_collision_0_0010000000474974513_0_0010000000474974513_0_0010000000474974513" file="stl/hii_links_export_RF_MP_AB2_collision.stl" scale="0.0010000000474974513 0.0010000000474974513 0.0010000000474974513"/>
		<mesh name="hii_links_export_RF_PIP_collision_0_0010000000474974513_0_0010000000474974513_0_0010000000474974513" file="stl/hii_links_export_RF_PIP_collision.stl" scale="0.0010000000474974513 0.0010000000474974513 0.0010000000474974513"/>
		<mesh name="hii_links_export_RF_DIP_collision_0_0010000000474974513_0_0010000000474974513_0_0010000000474974513" file="stl/hii_links_export_RF_DIP_collision.stl" scale="0.0010000000474974513 0.0010000000474974513 0.0010000000474974513"/>
		<mesh name="hand2_export_Base_SWA_collision_0_0010000000474974513_0_0010000000474974513_0_0010000000474974513" file="stl/hand2_export_Base_SWA_collision.stl" scale="0.0010000000474974513 0.0010000000474974513 0.0010000000474974513"/>
		<mesh name="hand2_export_D_MP_AB1_collision_0_0010000000474974513_0_0010000000474974513_0_0010000000474974513" file="stl/hand2_export_D_MP_AB1_collision.stl" scale="0.0010000000474974513 0.0010000000474974513 0.0010000000474974513"/>
		<mesh name="hand2_export_D_MP_AB2_collision_0_0010000000474974513_0_0010000000474974513_0_0010000000474974513" file="stl/hand2_export_D_MP_AB2_collision.stl" scale="0.0010000000474974513 0.0010000000474974513 0.0010000000474974513"/>
		<mesh name="hand2_export_D_PIP_collision_0_0010000000474974513_0_0010000000474974513_0_0010000000474974513" file="stl/hand2_export_D_PIP_collision.stl" scale="0.0010000000474974513 0.0010000000474974513 0.0010000000474974513"/>
		<mesh name="hand2_export_D_DIP_collision_0_0010000000474974513_0_0010000000474974513_0_0010000000474974513" file="stl/hand2_export_D_DIP_collision.stl" scale="0.0010000000474974513 0.0010000000474974513 0.0010000000474974513"/>
		<mesh name="hand2_export_ZF_MP_AB1_collision_0_0010000000474974513_0_0010000000474974513_0_0010000000474974513" file="stl/hand2_export_ZF_MP_AB1_collision.stl" scale="0.0010000000474974513 0.0010000000474974513 0.0010000000474974513"/>
		<mesh name="hand2_export_ZF_MP_AB2_collision_0_0010000000474974513_0_0010000000474974513_0_0010000000474974513" file="stl/hand2_export_ZF_MP_AB2_collision.stl" scale="0.0010000000474974513 0.0010000000474974513 0.0010000000474974513"/>
		<mesh name="hand2_export_ZF_PIP_collision_0_0010000000474974513_0_0010000000474974513_0_0010000000474974513" file="stl/hand2_export_ZF_PIP_collision.stl" scale="0.0010000000474974513 0.0010000000474974513 0.0010000000474974513"/>
		<mesh name="hand2_export_ZF_DIP_collision_0_0010000000474974513_0_0010000000474974513_0_0010000000474974513" file="stl/hand2_export_ZF_DIP_collision.stl" scale="0.0010000000474974513 0.0010000000474974513 0.0010000000474974513"/>
		<mesh name="hand2_export_MF_MP_AB1_collision_0_0010000000474974513_0_0010000000474974513_0_0010000000474974513" file="stl/hand2_export_MF_MP_AB1_collision.stl" scale="0.0010000000474974513 0.0010000000474974513 0.0010000000474974513"/>
		<mesh name="hand2_export_MF_MP_AB2_collision_0_0010000000474974513_0_0010000000474974513_0_0010000000474974513" file="stl/hand2_export_MF_MP_AB2_collision.stl" scale="0.0010000000474974513 0.0010000000474974513 0.0010000000474974513"/>
		<mesh name="hand2_export_MF_PIP_collision_0_0010000000474974513_0_0010000000474974513_0_0010000000474974513" file="stl/hand2_export_MF_PIP_collision.stl" scale="0.0010000000474974513 0.0010000000474974513 0.0010000000474974513"/>
		<mesh name="hand2_export_MF_DIP_collision_0_0010000000474974513_0_0010000000474974513_0_0010000000474974513" file="stl/hand2_export_MF_DIP_collision.stl" scale="0.0010000000474974513 0.0010000000474974513 0.0010000000474974513"/>
		<mesh name="hand2_export_RF_MP_AB1_collision_0_0010000000474974513_0_0010000000474974513_0_0010000000474974513" file="stl/hand2_export_RF_MP_AB1_collision.stl" scale="0.0010000000474974513 0.0010000000474974513 0.0010000000474974513"/>
		<mesh name="hand2_export_RF_MP_AB2_collision_0_0010000000474974513_0_0010000000474974513_0_0010000000474974513" file="stl/hand2_export_RF_MP_AB2_collision.stl" scale="0.0010000000474974513 0.0010000000474974513 0.0010000000474974513"/>
		<mesh name="hand2_export_RF_PIP_collision_0_0010000000474974513_0_0010000000474974513_0_0010000000474974513" file="stl/hand2_export_RF_PIP_collision.stl" scale="0.0010000000474974513 0.0010000000474974513 0.0010000000474974513"/>
		<mesh name="hand2_export_RF_DIP_collision_0_0010000000474974513_0_0010000000474974513_0_0010000000474974513" file="stl/hand2_export_RF_DIP_collision.stl" scale="0.0010000000474974513 0.0010000000474974513 0.0010000000474974513"/>
		<mesh name="justin_rj_kopf_HALS_ROT_collision_0_0010000000474974513_0_0010000000474974513_0_0010000000474974513" file="stl/justin_rj_kopf_HALS_ROT_collision.stl" scale="0.0010000000474974513 0.0010000000474974513 0.0010000000474974513"/>
		<mesh name="justin_rj_kopf_HALS_KNICK_collision_0_0010000000474974513_0_0010000000474974513_0_0010000000474974513" file="stl/justin_rj_kopf_HALS_KNICK_collision.stl" scale="0.0010000000474974513 0.0010000000474974513 0.0010000000474974513"/>
	</asset>
	<worldbody>
		<body name="justin" pos="0.0 0.0 0.0" quat="1.0 0.0 0.0 0.0">
			<body name="base_link" pos="0.0 0.0 0.0" quat="1.0 0.0 0.0 0.0">
				<body name="platform_link" pos="0.0 0.0 0.0" quat="1.0 0.0 0.0 0.0">
					<inertial mass="7066.02783203125" pos="0.7600398659706116 -4.508365236688405e-05 0.3522954285144806" quat="0.04318780079483986 -0.705715000629425 0.7058592438697815 -0.04317247122526169" diaginertia="2088.999267578125 3975.7216796875 5402.5419921875"/>
					<geom name="platform_link_geom_collision_0_mp_mobile_plattform_rj_BASE_collision" type="mesh" pos="0.0 0.0 0.0" quat="1.0 0.0 0.0 0.0" mesh="mp_mobile_plattform_rj_BASE_collision_0_0010000000474974513_0_0010000000474974513_0_0010000000474974513" class="rollin-justin_collision"/>
					<body name="wheel_lf_link" pos="0.34198999404907227 0.25784000754356384 0.02889999933540821" quat="0.270600825548172 -0.270600825548172 -0.6532803177833557 0.6532803177833557">
						<inertial mass="5.6581597328186035" pos="-0.014599199406802654 -0.011620926670730114 -3.107102384092286e-05" quat="0.5004712343215942 0.5054946541786194 -0.49133065342903137 -0.5025911927223206" diaginertia="0.019188283011317253 0.02395530231297016 0.036094557493925095"/>
						<geom name="wheel_lf_link_geom_collision_0_mp_mobile_plattform_rj_ROT2_collision" type="mesh" pos="0.0 0.0 0.0" quat="1.0 0.0 0.0 0.0" mesh="mp_mobile_plattform_rj_ROT2_collision_0_0010000000474974513_0_0010000000474974513_0_0010000000474974513" class="rollin-justin_collision"/>
					</body>
					<body name="wheel_lb_link" pos="-0.34198999404907227 -0.25784000754356384 0.02889999933540821" quat="-0.6532803177833557 0.6532803177833557 -0.270600825548172 0.270600825548172">
						<inertial mass="5.6581597328186035" pos="-0.014599199406802654 -0.011620926670730114 -3.107102384092286e-05" quat="0.5004712343215942 0.5054946541786194 -0.49133065342903137 -0.5025911927223206" diaginertia="0.019188283011317253 0.02395530231297016 0.036094557493925095"/>
						<geom name="wheel_lb_link_geom_collision_0_mp_mobile_plattform_rj_ROT4_collision" type="mesh" pos="0.0 0.0 0.0" quat="1.0 0.0 0.0 0.0" mesh="mp_mobile_plattform_rj_ROT4_collision_0_0010000000474974513_0_0010000000474974513_0_0010000000474974513" class="rollin-justin_collision"/>
					</body>
					<body name="wheel_rf_link" pos="0.3427000045776367 -0.25714001059532166 0.02889999933540821" quat="0.653282642364502 -0.653282642364502 -0.2705952823162079 0.2705952823162079">
						<inertial mass="5.6581597328186035" pos="-0.014599462039768696 -0.011620926670730114 -3.107102384092286e-05" quat="0.5004712343215942 0.5054946541786194 -0.49133065342903137 -0.5025911927223206" diaginertia="0.019188283011317253 0.02395530231297016 0.036094557493925095"/>
						<geom name="wheel_rf_link_geom_collision_0_mp_mobile_plattform_rj_ROT1_collision" type="mesh" pos="0.0 0.0 0.0" quat="1.0 0.0 0.0 0.0" mesh="mp_mobile_plattform_rj_ROT1_collision_0_0010000000474974513_0_0010000000474974513_0_0010000000474974513" class="rollin-justin_collision"/>
					</body>
					<body name="torso_base_link" pos="0.0 0.0 0.5935999751091003" quat="0.7071067690849304 0.0 0.0 0.7071067690849304">
						<inertial mass="1.9703621864318848" pos="0.00012105821224395186 -0.0005396138876676559 -0.03439111262559891" quat="-0.06244904547929764 0.7582458853721619 0.6484001278877258 0.02721455879509449" diaginertia="0.004207400605082512 0.004225637298077345 0.004618835169821978"/>
						<geom name="torso_base_link_geom_collision_0_trs_plat_dummy_Trs_Base_A0_collision" type="mesh" pos="0.0 0.0 0.0" quat="1.0 0.0 0.0 0.0" mesh="trs_plat_dummy_Trs_Base_A0_collision_0_0010000000474974513_0_0010000000474974513_0_0010000000474974513" class="rollin-justin_collision"/>
						<body name="torso1_link" pos="0.0 0.0 0.0" quat="0.7071067690849304 -7.850390690659011e-17 -7.85053362746886e-17 -0.7071067690849304">
							<inertial mass="4.561734676361084" pos="0.003514489158987999 0.008436225354671478 0.07320666313171387" quat="0.3836207687854767 0.6057295203208923 -0.4177759289741516 -0.5580233931541443" diaginertia="0.020089130848646164 0.024789990857243538 0.029776673763990402"/>
							<geom name="torso1_link_geom_collision_0_trs_plat_dummy_A1_collision" type="mesh" pos="0.0 0.0 0.0" quat="1.0 0.0 0.0 0.0" mesh="trs_plat_dummy_A1_collision_0_0010000000474974513_0_0010000000474974513_0_0010000000474974513" class="rollin-justin_collision"/>
							<joint name="torso1" type="hinge" pos="0.0 0.0 0.0" range="-1.7453300952911377 3.3161301612854004" axis="0.0 0.0 1.0"/>
							<body name="torso2_link" pos="2.502442706504828e-17 2.2790941285239353e-22 0.11270000040531158" quat="0.5 -0.5 -0.5 -0.5">
								<inertial mass="5.400197505950928" pos="0.20680852234363556 -0.01380209345370531 0.00449080765247345" quat="-0.6823769807815552 0.7302553057670593 0.0082869753241539 -0.03194094076752663" diaginertia="0.03372090682387352 0.07742772251367569 0.09883572161197662"/>
								<geom name="torso2_link_geom_collision_0_trs_plat_dummy_A2_collision" type="mesh" pos="0.0 0.0 0.0" quat="1.0 0.0 0.0 0.0" mesh="trs_plat_dummy_A2_collision_0_0010000000474974513_0_0010000000474974513_0_0010000000474974513" class="rollin-justin_collision"/>
								<joint name="torso2" type="hinge" pos="-1.5407439555097887e-32 -5.61291613287647e-38 -2.7755575615628914e-17" range="-1.2217299938201904 0.5235999822616577" axis="0.0 0.0 1.0"/>
								<body name="torso3_link" pos="0.30000001192092896 -2.4554090183517157e-16 -9.184547819103952e-18" quat="1.0 1.1102230246251565e-16 8.859277744181285e-33 2.701939016441264e-16">
									<inertial mass="3.249762535095215" pos="0.14568641781806946 -0.021572645753622055 0.003904165467247367" quat="0.7311420440673828 0.6798600554466248 0.036644842475652695 -0.043344587087631226" diaginertia="0.02376645803451538 0.04419974237680435 0.059361010789871216"/>
									<geom name="torso3_link_geom_collision_0_trs_plat_dummy_A3_collision" type="mesh" pos="0.0 0.0 0.0" quat="1.0 0.0 0.0 0.0" mesh="trs_plat_dummy_A3_collision_0_0010000000474974513_0_0010000000474974513_0_0010000000474974513" class="rollin-justin_collision"/>
									<joint name="torso3" type="hinge" pos="8.271806125530277e-25 5.551115123125783e-17 -9.392203575540786e-25" range="0.17453299462795258 2.338740110397339" axis="0.0 0.0 1.0"/>
									<body name="torso4_link" pos="0.30000001192092896 -4.076572375276915e-16 -4.592273909551976e-18" quat="1.0 3.697785493223493e-32 -4.622231866529366e-33 -6.528573674202708e-16">
										<inertial mass="2.8514466285705566" pos="0.02660156600177288 0.05478963628411293 -0.005599359981715679" quat="0.6599236726760864 -0.3304471969604492 -0.6370190978050232 -0.2225131094455719" diaginertia="0.020694581791758537 0.026655033230781555 0.031100261956453323"/>
										<geom name="torso4_link_geom_collision_0_trs_plat_dummy_A4_collision" type="mesh" pos="0.0 0.0 0.0" quat="1.0 0.0 0.0 0.0" mesh="trs_plat_dummy_A4_collision_0_0010000000474974513_0_0010000000474974513_0_0010000000474974513" class="rollin-justin_collision"/>
										<joint name="torso4" type="hinge" pos="-8.271806125530277e-25 -5.551115123125783e-17 -3.32286317636865e-24" range="-1.5700000524520874 0.10000000149011612" axis="0.0 0.0 1.0"/>
										<body name="right_base_link" pos="0.03500000014901161 0.08799999952316284 0.012662800028920174" quat="5.914589533937914e-17 0.9659258127212524 -1.5848102248413717e-17 0.2588191330432892">
											<inertial mass="1.6371830701828003" pos="-0.0005617791321128607 -0.00012307609722483903 0.08790497481822968" quat="0.9917028546333313 0.05624055117368698 -0.09607525169849396 -0.06428057700395584" diaginertia="0.001993055222555995 0.0020098104141652584 0.0021475462708622217"/>
											<geom name="right_base_link_geom_collision_0_lr33_J1_Base_frame_collision" type="mesh" pos="0.0 0.0 0.0" quat="1.0 0.0 0.0 0.0" mesh="lr33_J1_Base_frame_collision_0_0010000000474974513_0_0010000000474974513_0_0010000000474974513" class="rollin-justin_collision"/>
											<body name="right_arm1_link" pos="-2.220446049250313e-16 1.3877787807814457e-17 0.3100000023841858" quat="6.123234262925839e-17 2.7755575615628914e-17 4.591774807899561e-41 1.0">
												<inertial mass="2.6516671180725098" pos="-0.00035640178248286247 0.020114121958613396 -0.04674214497208595" quat="-0.036522213369607925 0.7049224972724915 0.13465753197669983 0.6954262852668762" diaginertia="0.004406968131661415 0.018196815624833107 0.018303321674466133"/>
												<geom name="right_arm1_link_geom_collision_0_lr33_J2_HUELLE_A1_collision" type="mesh" pos="0.0 0.0 0.0" quat="1.0 0.0 0.0 0.0" mesh="lr33_J2_HUELLE_A1_collision_0_0010000000474974513_0_0010000000474974513_0_0010000000474974513" class="rollin-justin_collision"/>
												<joint name="right_arm1" type="hinge" pos="-1.511610762505288e-16 -2.220446049250313e-16 -7.124823591529958e-17" range="-2.96705961227417 2.96705961227417" axis="0.0 0.0 1.0"/>
												<body name="right_arm2_link" pos="2.220446049250313e-16 -1.3877787807814457e-17 0.0" quat="0.7071067690849304 0.7071067690849304 -1.962615539765984e-17 1.962615539765984e-17">
													<inertial mass="2.243405818939209" pos="-0.0005093194195069373 0.1101473793387413 0.017628269270062447" quat="-0.6917832493782043 0.14308129251003265 0.01373263355344534 0.7076546549797058" diaginertia="0.0036283512599766254 0.020731721073389053 0.020837366580963135"/>
													<geom name="right_arm2_link_geom_collision_0_lr33_J3_HUELLE_A2_collision" type="mesh" pos="0.0 0.0 0.0" quat="1.0 0.0 0.0 0.0" mesh="lr33_J3_HUELLE_A2_collision_0_0010000000474974513_0_0010000000474974513_0_0010000000474974513" class="rollin-justin_collision"/>
													<joint name="right_arm2" type="hinge" pos="-6.938893490316922e-18 -2.220446049250313e-16 -1.2018517401366765e-17" range="-2.094395160675049 2.094395160675049" axis="0.0 0.0 1.0"/>
													<body name="right_arm3_link" pos="0.0 0.4000000059604645 4.163336342344337e-17" quat="-0.5 0.5 0.5 0.5">
														<inertial mass="2.244774103164673" pos="-0.00021507605561055243 0.017854882404208183 -0.0544300377368927" quat="-0.06707902997732162 -0.7046396136283875 0.02658449485898018 0.7058871388435364" diaginertia="0.003937996923923492 0.016633031889796257 0.016893062740564346"/>
														<geom name="right_arm3_link_geom_collision_0_lr33_J4_HUELLE_A3_collision" type="mesh" pos="0.0 0.0 0.0" quat="1.0 0.0 0.0 0.0" mesh="lr33_J4_HUELLE_A3_collision_0_0010000000474974513_0_0010000000474974513_0_0010000000474974513" class="rollin-justin_collision"/>
														<joint name="right_arm3" type="hinge" pos="1.2586638280957986e-16 1.8372602553132884e-16 -2.5541210838515554e-25" range="-2.96705961227417 2.96705961227417" axis="0.0 0.0 1.0"/>
														<body name="right_arm4_link" pos="0.0 0.0 0.0" quat="0.7071067690849304 0.7071067690849304 -5.84905010392065e-25 -0.0">
															<inertial mass="2.2601213455200195" pos="-0.0005056654918007553 0.11100444197654724 0.017488593235611916" quat="-0.6906089186668396 0.14856114983558655 0.008349796757102013 0.7077564001083374" diaginertia="0.0036368200089782476 0.020869005471467972 0.02096852846443653"/>
															<geom name="right_arm4_link_geom_collision_0_lr33_J5_HUELLE_A4_collision" type="mesh" pos="0.0 0.0 0.0" quat="1.0 0.0 0.0 0.0" mesh="lr33_J5_HUELLE_A4_collision_0_0010000000474974513_0_0010000000474974513_0_0010000000474974513" class="rollin-justin_collision"/>
															<joint name="right_arm4" type="hinge" pos="0.0 0.0 -0.0" range="-2.094395160675049 2.094395160675049" axis="0.0 0.0 1.0"/>
															<body name="right_arm5_link" pos="1.3877787807814457e-17 0.38999998569488525 2.220446049250313e-16" quat="-4.329780301713277e-17 -4.329780301713277e-17 0.7071067690849304 0.7071067690849304">
																<inertial mass="0.9629648923873901" pos="2.8970931452931836e-05 0.019128579646348953 -0.11188261955976486" quat="0.5841289758682251 0.3985241949558258 -0.3972199559211731 0.5849684476852417" diaginertia="0.0015503353206440806 0.006506775505840778 0.00668455520644784"/>
																<geom name="right_arm5_link_geom_collision_0_lr33_J6_HUELLE_A5_collision" type="mesh" pos="0.0 0.0 0.0" quat="1.0 0.0 0.0 0.0" mesh="lr33_J6_HUELLE_A5_collision_0_0010000000474974513_0_0010000000474974513_0_0010000000474974513" class="rollin-justin_collision"/>
																<joint name="right_arm5" type="hinge" pos="1.3877785326272619e-17 -1.8328984326816227e-16 -9.542264887416591e-17" range="-2.96705961227417 2.96705961227417" axis="0.0 0.0 1.0"/>
																<body name="right_arm6_link" pos="0.0 0.0 2.220446049250313e-16" quat="0.5 0.5 -0.5 0.5">
																	<inertial mass="1.7235873937606812" pos="7.239815022330731e-05 -0.007147205527871847 -0.005423184018582106" quat="-0.6586084961891174 0.07558540254831314 0.7455106377601624 0.06881553679704666" diaginertia="0.0031067354138940573 0.003225507913157344 0.003377326764166355"/>
																	<geom name="right_arm6_link_geom_collision_0_lr33_J7_HUELLE_A6_collision" type="mesh" pos="0.0 0.0 0.0" quat="1.0 0.0 0.0 0.0" mesh="lr33_J7_HUELLE_A6_collision_0_0010000000474974513_0_0010000000474974513_0_0010000000474974513" class="rollin-justin_collision"/>
																	<joint name="right_arm6" type="hinge" pos="3.3087222529968844e-24 -1.9229625195208864e-16 -1.1102234216718506e-16" range="-0.785398006439209 1.3962599039077759" axis="0.0 0.0 1.0"/>
																	<body name="right_arm7_link" pos="2.220446049250313e-16 1.3877787807814457e-17 0.0" quat="0.7071067690849304 0.7071067690849304 1.3746048541917424e-17 -3.93297125667781e-18">
																		<inertial mass="2.104095935821533" pos="0.0076743136160075665 -0.00439220666885376 0.013334192335605621" quat="0.7447554469108582 0.6639961004257202 -0.028430724516510963 0.06033402308821678" diaginertia="0.004227632191032171 0.0046717883087694645 0.0051336102187633514"/>
																		<geom name="right_arm7_link_geom_collision_0_lr33_J8_HUELLE_A7_collision" type="mesh" pos="0.0 0.0 0.0" quat="1.0 0.0 0.0 0.0" mesh="lr33_J8_HUELLE_A7_collision_0_0010000000474974513_0_0010000000474974513_0_0010000000474974513" class="rollin-justin_collision"/>
																		<joint name="right_arm7" type="hinge" pos="1.2018514092644315e-17 2.220446049250313e-16 6.938898866990904e-18" range="-0.785398006439209 2.3561899662017822" axis="0.0 0.0 1.0"/>
																		<body name="rightarm7" pos="2.220446049250313e-16 0.0 0.0" quat="0.7071067690849304 -0.0 -5.84905010392065e-25 -0.7071067690849304">
																			<body name="right_arm" pos="0.0 0.11309999972581863 -1.3877787807814457e-17" quat="5.887846453861829e-17 -3.925231079531968e-17 -0.7071067690849304 0.7071067690849304"/>
																			<body name="right_arm_palm_link" pos="0.0 -2.220446049250313e-16 0.0" quat="0.7071067690849304 -5.84905010392065e-25 -0.0 0.7071067690849304">
																				<body name="right_hand_base_link" pos="0.10109999775886536 -2.220446049250313e-16 -2.7755575615628914e-17" quat="0.5 0.5 0.5 0.5">
																					<inertial mass="1.3667323589324951" pos="-0.015598330646753311 0.0009486987255513668 0.07018250972032547" quat="-0.38064780831336975 -0.2778644561767578 0.8186787962913513 0.3281213343143463" diaginertia="0.002146710641682148 0.003319483483210206 0.004234615247696638"/>
																					<geom name="right_hand_base_link_geom_collision_0_hand2_export_Base_SWA_collision" type="mesh" pos="0.0 0.0 0.0" quat="1.0 0.0 0.0 0.0" mesh="hand2_export_Base_SWA_collision_0_0010000000474974513_0_0010000000474974513_0_0010000000474974513" class="rollin-justin_collision"/>
																					<body name="right_2index_add" pos="-0.04822095111012459 0.02358194999396801 0.1388426423072815" quat="0.990906834602356 0.05092969164252281 -0.10476531833410263 0.06733562797307968">
																						<inertial mass="0.01832089014351368" pos="1.3835101526638027e-06 -0.00594230554997921 0.0002689856628421694" quat="0.49364426732063293 0.5061689615249634 0.49341049790382385 0.5066107511520386" diaginertia="8.063312293415947e-07 1.9452459127933253e-06 1.9491430975904223e-06"/>
																						<geom name="right_2index_add_geom_collision_0_hand2_export_ZF_MP_AB1_collision" type="mesh" pos="0.0 0.0 0.0" quat="1.0 0.0 0.0 0.0" mesh="hand2_export_ZF_MP_AB1_collision_0_0010000000474974513_0_0010000000474974513_0_0010000000474974513" class="rollin-justin_collision"/>
																						<joint name="right_2index1" type="hinge" pos="1.2191988425475466e-16 -7.632783294297951e-17 -6.638433450414897e-17" range="-0.5235987901687622 0.5235987901687622" axis="1.0 0.0 0.0"/>
																						<body name="right_2index_prox" pos="1.1102230246251565e-16 -5.551115123125783e-17 4.440892098500626e-16" quat="1.0 1.3877787807814457e-17 2.7755575615628914e-17 1.0408340855860843e-17">
																							<inertial mass="0.1042167991399765" pos="-0.0007062018266879022 0.001489807851612568 0.045419350266456604" quat="0.04115879535675049 -0.7005778551101685 -0.005969339516013861 0.7123629450798035" diaginertia="1.2149941539973952e-05 7.304679456865415e-05 7.585596904391423e-05"/>
																							<geom name="right_2index_prox_geom_collision_0_hand2_export_ZF_MP_AB2_collision" type="mesh" pos="0.0 0.0 0.0" quat="1.0 0.0 0.0 0.0" mesh="hand2_export_ZF_MP_AB2_collision_0_0010000000474974513_0_0010000000474974513_0_0010000000474974513" class="rollin-justin_collision"/>
																							<joint name="right_2index2" type="hinge" pos="2.7420094981979047e-16 -1.8431906770841505e-16 -3.216566324342027e-16" range="-0.5235987901687622 1.5707963705062866" axis="0.0 1.0 0.0"/>
																							<body name="right_2index_middle" pos="-2.654909621924162e-06 -6.4521373133175075e-06 0.07549382746219635" quat="1.0 3.469446951953614e-18 2.7755575615628914e-17 3.469446951953614e-18">
																								<inertial mass="0.020456522703170776" pos="-0.0021607212256640196 0.0009400434792041779 0.018235867843031883" quat="-0.7038758993148804 -0.007882834412157536 0.7093521356582642 0.036278292536735535" diaginertia="3.305681730125798e-06 4.883020665147342e-06 5.772400072601158e-06"/>
																								<geom name="right_2index_middle_geom_collision_0_hand2_export_ZF_PIP_collision" type="mesh" pos="0.0 0.0 0.0" quat="1.0 0.0 0.0 0.0" mesh="hand2_export_ZF_PIP_collision_0_0010000000474974513_0_0010000000474974513_0_0010000000474974513" class="rollin-justin_collision"/>
																								<joint name="right_2index3" type="hinge" pos="1.1689316722927401e-16 -7.169135987816668e-17 -1.8844201381406516e-16" range="-0.5235987901687622 1.5707963705062866" axis="0.0 1.0 0.0"/>
																								<body name="right_2index_distal" pos="-1.1598298215176328e-06 2.644729875100893e-06 0.04000259190797806" quat="1.0 3.469446951953614e-18 2.7755575615628914e-17 3.469446951953614e-18">
																									<inertial mass="0.022882064804434776" pos="0.001276868162676692 -0.0006573523860424757 0.020717136561870575" quat="-0.10149012506008148 -0.6412995457649231 -0.0016901132185012102 0.7605470418930054" diaginertia="1.5308153251680778e-06 3.831848971458385e-06 4.2437532101757824e-06"/>
																									<geom name="right_2index_distal_geom_collision_0_hand2_export_ZF_DIP_collision" type="mesh" pos="0.0 0.0 0.0" quat="1.0 0.0 0.0 0.0" mesh="hand2_export_ZF_DIP_collision_0_0010000000474974513_0_0010000000474974513_0_0010000000474974513" class="rollin-justin_collision"/>
																									<joint name="right_2index4" type="hinge" pos="-4.4175764578362675e-16 -7.534414314108655e-17 3.807272013982803e-16" range="-0.5235987901687622 1.5707963705062866" axis="0.0 1.0 0.0"/>
																								</body>
																							</body>
																						</body>
																					</body>
																					<body name="right_3middle_add" pos="-0.04691247642040253 -0.01625622995197773 0.13329803943634033" quat="0.990906834602356 0.05092969164252281 -0.10476531833410263 0.06733562797307968">
																						<inertial mass="0.01832089014351368" pos="1.3835101526638027e-06 -0.00594230554997921 0.0002689856628421694" quat="0.49364426732063293 0.5061689615249634 0.49341049790382385 0.5066107511520386" diaginertia="8.063312293415947e-07 1.9452459127933253e-06 1.9491430975904223e-06"/>
																						<geom name="right_3middle_add_geom_collision_0_hand2_export_MF_MP_AB1_collision" type="mesh" pos="0.0 0.0 0.0" quat="1.0 0.0 0.0 0.0" mesh="hand2_export_MF_MP_AB1_collision_0_0010000000474974513_0_0010000000474974513_0_0010000000474974513" class="rollin-justin_collision"/>
																						<joint name="right_3middle1" type="hinge" pos="7.731526160124121e-17 2.7755575615628914e-16 -3.261949026166932e-17" range="-0.5235987901687622 0.5235987901687622" axis="1.0 0.0 0.0"/>
																						<body name="right_3middle_prox" pos="0.0 5.551115123125783e-17 0.0" quat="1.0 6.938893903907228e-18 2.407412430484045e-35 1.734723475976807e-17">
																							<inertial mass="0.1042167991399765" pos="-0.0007062018266879022 0.001489807851612568 0.045419350266456604" quat="0.04115879535675049 -0.7005778551101685 -0.005969339516013861 0.7123629450798035" diaginertia="1.2149941539973952e-05 7.304679456865415e-05 7.585596904391423e-05"/>
																							<geom name="right_3middle_prox_geom_collision_0_hand2_export_MF_MP_AB2_collision" type="mesh" pos="0.0 0.0 0.0" quat="1.0 0.0 0.0 0.0" mesh="hand2_export_MF_MP_AB2_collision_0_0010000000474974513_0_0010000000474974513_0_0010000000474974513" class="rollin-justin_collision"/>
																							<joint name="right_3middle2" type="hinge" pos="3.720573691968793e-17 1.7391606795776947e-19 4.1196976019484895e-17" range="-0.5235987901687622 1.5707963705062866" axis="0.0 1.0 0.0"/>
																							<body name="right_3middle_middle" pos="-4.313829322200036e-06 3.3959411211981205e-06 0.07549331337213516" quat="1.0 -3.469446951953614e-18 0.0 3.469446951953614e-18">
																								<inertial mass="0.020456522703170776" pos="-0.0021607212256640196 0.0009400434792041779 0.018235867843031883" quat="-0.7038758993148804 -0.007882834412157536 0.7093521356582642 0.036278292536735535" diaginertia="3.305681730125798e-06 4.883020665147342e-06 5.772400072601158e-06"/>
																								<geom name="right_3middle_middle_geom_collision_0_hand2_export_MF_PIP_collision" type="mesh" pos="0.0 0.0 0.0" quat="1.0 0.0 0.0 0.0" mesh="hand2_export_MF_PIP_collision_0_0010000000474974513_0_0010000000474974513_0_0010000000474974513" class="rollin-justin_collision"/>
																								<joint name="right_3middle3" type="hinge" pos="-2.288317740522616e-16 1.2444369005863153e-17 1.6352570587252246e-16" range="-0.5235987901687622 1.5707963705062866" axis="0.0 1.0 0.0"/>
																								<body name="right_3middle_distal" pos="-1.1598298215176328e-06 2.644729875100893e-06 0.04000259190797806" quat="1.0 -6.938893903907228e-18 -0.0 3.469446951953614e-18">
																									<inertial mass="0.022882064804434776" pos="0.001276868162676692 -0.0006573523860424757 0.020717136561870575" quat="-0.10149012506008148 -0.6412995457649231 -0.0016901132185012102 0.7605470418930054" diaginertia="1.5308153251680778e-06 3.831848971458385e-06 4.2437532101757824e-06"/>
																									<geom name="right_3middle_distal_geom_collision_0_hand2_export_MF_DIP_collision" type="mesh" pos="0.0 0.0 0.0" quat="1.0 0.0 0.0 0.0" mesh="hand2_export_MF_DIP_collision_0_0010000000474974513_0_0010000000474974513_0_0010000000474974513" class="rollin-justin_collision"/>
																									<joint name="right_3middle4" type="hinge" pos="-1.1964403907438036e-16 -1.420183084969843e-16 2.9664635677507397e-17" range="-0.5235987901687622 1.5707963705062866" axis="0.0 1.0 0.0"/>
																								</body>
																							</body>
																						</body>
																					</body>
																					<body name="right_4ring_add" pos="-0.037444453686475754 -0.06233131140470505 0.12780100107192993" quat="0.989348292350769 0.02939184568822384 -0.0807262659072876 0.11751319468021393">
																						<inertial mass="0.01832089014351368" pos="1.3835101526638027e-06 -0.00594230554997921 0.0002689856628421694" quat="0.49364426732063293 0.5061689615249634 0.49341049790382385 0.5066107511520386" diaginertia="8.063312293415947e-07 1.9452459127933253e-06 1.9491430975904223e-06"/>
																						<geom name="right_4ring_add_geom_collision_0_hand2_export_RF_MP_AB1_collision" type="mesh" pos="0.0 0.0 0.0" quat="1.0 0.0 0.0 0.0" mesh="hand2_export_RF_MP_AB1_collision_0_0010000000474974513_0_0010000000474974513_0_0010000000474974513" class="rollin-justin_collision"/>
																						<joint name="right_4ring1" type="hinge" pos="2.403702950877761e-16 -2.7755572306906463e-17 -1.3877793101770377e-16" range="-0.5235987901687622 0.5235987901687622" axis="1.0 0.0 0.0"/>
																						<body name="right_4ring_prox" pos="1.1102230246251565e-16 0.0 0.0" quat="1.0 0.0 1.0408340855860843e-17 1.0408340855860843e-17">
																							<inertial mass="0.1042167991399765" pos="-0.0007062018266879022 0.001489807851612568 0.045419350266456604" quat="0.04115879535675049 -0.7005778551101685 -0.005969339516013861 0.7123629450798035" diaginertia="1.2149941539973952e-05 7.304679456865415e-05 7.585596904391423e-05"/>
																							<geom name="right_4ring_prox_geom_collision_0_hand2_export_RF_MP_AB2_collision" type="mesh" pos="0.0 0.0 0.0" quat="1.0 0.0 0.0 0.0" mesh="hand2_export_RF_MP_AB2_collision_0_0010000000474974513_0_0010000000474974513_0_0010000000474974513" class="rollin-justin_collision"/>
																							<joint name="right_4ring2" type="hinge" pos="-2.52883903246813e-17 -1.0776419023090199e-16 8.563187940927594e-18" range="-0.5235987901687622 1.5707963705062866" axis="0.0 1.0 0.0"/>
																							<body name="right_4ring_middle" pos="4.239479949319502e-06 -4.270954832463758e-06 0.07550221681594849" quat="1.0 0.0 1.0408340855860843e-17 1.0408340855860843e-17">
																								<inertial mass="0.020456522703170776" pos="-0.0021607212256640196 0.0009400434792041779 0.018235867843031883" quat="-0.7038758993148804 -0.007882834412157536 0.7093521356582642 0.036278292536735535" diaginertia="3.305681730125798e-06 4.883020665147342e-06 5.772400072601158e-06"/>
																								<geom name="right_4ring_middle_geom_collision_0_hand2_export_RF_PIP_collision" type="mesh" pos="0.0 0.0 0.0" quat="1.0 0.0 0.0 0.0" mesh="hand2_export_RF_PIP_collision_0_0010000000474974513_0_0010000000474974513_0_0010000000474974513" class="rollin-justin_collision"/>
																								<joint name="right_4ring3" type="hinge" pos="4.966209756289126e-16 1.2544397806669598e-16 -3.1720571252439776e-16" range="-0.5235987901687622 1.5707963705062866" axis="0.0 1.0 0.0"/>
																								<body name="right_4ring_distal" pos="-9.464939694225905e-07 3.012420165759977e-06 0.03999772667884827" quat="1.0 0.0 1.0408340855860843e-17 1.0408340855860843e-17">
																									<inertial mass="0.022882064804434776" pos="0.001276868162676692 -0.0006573523860424757 0.020717136561870575" quat="-0.10149012506008148 -0.6412995457649231 -0.0016901132185012102 0.7605470418930054" diaginertia="1.5308153251680778e-06 3.831848971458385e-06 4.2437532101757824e-06"/>
																									<geom name="right_4ring_distal_geom_collision_0_hand2_export_RF_DIP_collision" type="mesh" pos="0.0 0.0 0.0" quat="1.0 0.0 0.0 0.0" mesh="hand2_export_RF_DIP_collision_0_0010000000474974513_0_0010000000474974513_0_0010000000474974513" class="rollin-justin_collision"/>
																									<joint name="right_4ring4" type="hinge" pos="2.722674647687845e-16 -2.610606365414589e-16 -2.2429644201530687e-16" range="-0.5235987901687622 1.5707963705062866" axis="0.0 1.0 0.0"/>
																								</body>
																							</body>
																						</body>
																					</body>
																					<body name="right_1thumb_add" pos="0.050334978848695755 0.046195030212402344 0.1009046882390976" quat="-0.11157138645648956 0.28528428077697754 -0.018463127315044403 0.9517477750778198">
																						<inertial mass="0.01832089014351368" pos="1.3835101526638027e-06 -0.00594230554997921 0.0002689856628421694" quat="0.49364426732063293 0.5061689615249634 0.49341049790382385 0.5066107511520386" diaginertia="8.063312293415947e-07 1.9452459127933253e-06 1.9491430975904223e-06"/>
																						<geom name="right_1thumb_add_geom_collision_0_hand2_export_D_MP_AB1_collision" type="mesh" pos="0.0 0.0 0.0" quat="1.0 0.0 0.0 0.0" mesh="hand2_export_D_MP_AB1_collision_0_0010000000474974513_0_0010000000474974513_0_0010000000474974513" class="rollin-justin_collision"/>
																						<joint name="right_1thumb1" type="hinge" pos="7.55805447427093e-17 -1.0408340855860843e-16 -3.562412126637224e-17" range="-0.5235987901687622 0.5235987901687622" axis="1.0 0.0 0.0"/>
																						<body name="right_1thumb_prox" pos="2.220446049250313e-16 0.0 2.220446049250313e-16" quat="1.0 2.168404344971009e-18 1.734723475976807e-18 6.938893903907228e-18">
																							<inertial mass="0.01832089014351368" pos="1.3835101526638027e-06 -0.00594230554997921 0.0002689856628421694" quat="0.49364426732063293 0.5061689615249634 0.49341049790382385 0.5066107511520386" diaginertia="8.063312293415947e-07 1.9452459127933253e-06 1.9491430975904223e-06"/>
																							<geom name="right_1thumb_prox_geom_collision_0_hand2_export_D_MP_AB2_collision" type="mesh" pos="0.0 0.0 0.0" quat="1.0 0.0 0.0 0.0" mesh="hand2_export_D_MP_AB2_collision_0_0010000000474974513_0_0010000000474974513_0_0010000000474974513" class="rollin-justin_collision"/>
																							<joint name="right_1thumb2" type="hinge" pos="-1.6654379014270794e-16 2.661478105435498e-16 6.009697933588648e-18" range="-0.5235987901687622 1.5707963705062866" axis="0.0 1.0 0.0"/>
																							<body name="right_1thumb_middle" pos="-2.7737087293644436e-06 8.763641972109326e-07 0.07549897581338882" quat="1.0 9.107298248878237e-18 1.734723475976807e-18 6.938893903907228e-18">
																								<inertial mass="0.020456522703170776" pos="-0.0021607212256640196 0.0009400434792041779 0.018235867843031883" quat="-0.7038758993148804 -0.007882834412157536 0.7093521356582642 0.036278292536735535" diaginertia="3.305681730125798e-06 4.883020665147342e-06 5.772400072601158e-06"/>
																								<geom name="right_1thumb_middle_geom_collision_0_hand2_export_D_PIP_collision" type="mesh" pos="0.0 0.0 0.0" quat="1.0 0.0 0.0 0.0" mesh="hand2_export_D_PIP_collision_0_0010000000474974513_0_0010000000474974513_0_0010000000474974513" class="rollin-justin_collision"/>
																								<joint name="right_1thumb3" type="hinge" pos="-1.9887475980671877e-16 -6.003975994419374e-17 6.759969360738027e-18" range="-0.5235987901687622 1.5707963705062866" axis="0.0 1.0 0.0"/>
																								<body name="right_1thumb_distal" pos="2.6136007136301487e-08 1.941551772688399e-06 0.03999917954206467" quat="1.0 1.3877787807814457e-17 1.734723475976807e-18 6.938893903907228e-18">
																									<inertial mass="0.022882064804434776" pos="0.001276868162676692 -0.0006573523860424757 0.020717136561870575" quat="-0.10149012506008148 -0.6412995457649231 -0.0016901132185012102 0.7605470418930054" diaginertia="1.5308153251680778e-06 3.831848971458385e-06 4.2437532101757824e-06"/>
																									<geom name="right_1thumb_distal_geom_collision_0_hand2_export_D_DIP_collision" type="mesh" pos="0.0 0.0 0.0" quat="1.0 0.0 0.0 0.0" mesh="hand2_export_D_DIP_collision_0_0010000000474974513_0_0010000000474974513_0_0010000000474974513" class="rollin-justin_collision"/>
																									<joint name="right_1thumb4" type="hinge" pos="2.525044920434472e-16 -5.5243925571288896e-17 2.3796667697254197e-17" range="-0.5235987901687622 1.5707963705062866" axis="0.0 1.0 0.0"/>
																								</body>
																							</body>
																						</body>
																					</body>
																				</body>
																			</body>
																		</body>
																	</body>
																</body>
															</body>
														</body>
													</body>
												</body>
											</body>
										</body>
										<body name="head_base_link" pos="0.135685995221138 0.08799970149993896 -1.232595164407831e-32" quat="0.5 -0.5 0.5 0.5">
											<inertial mass="0.14162780344486237" pos="6.646781912422739e-06 -0.005732597317546606 -7.834989082766697e-05" quat="0.5233476161956787 -0.523155689239502 -0.47547250986099243 -0.47575345635414124" diaginertia="5.9025915106758475e-05 5.926195808569901e-05 0.00010223277058685198"/>
											<geom name="head_base_link_geom_collision_0_justin_rj_kopf_HALS_EINBAU_collision" type="mesh" pos="0.0 0.0 0.0" quat="1.0 0.0 0.0 0.0" mesh="justin_rj_kopf_HALS_EINBAU_collision_0_0010000000474974513_0_0010000000474974513_0_0010000000474974513" class="rollin-justin_collision"/>
											<body name="head1_link" pos="1.8368364410546407e-18 -0.029997816309332848 4.8436013457830995e-06" quat="1.0 0.0 -3.54876954373769e-32 0.0">
												<inertial mass="0.6662372946739197" pos="-0.0008219002047553658 -0.02463667094707489 0.00013467359531205148" quat="-0.6832971572875977 0.0032222727313637733 -0.007899422198534012 0.7300904989242554" diaginertia="0.0005995018291287124 0.0010528807761147618 0.001160198007710278"/>
												<geom name="head1_link_geom_collision_0_justin_rj_kopf_HALS_ROT_collision" type="mesh" pos="0.0 0.0 0.0" quat="1.0 0.0 0.0 0.0" mesh="justin_rj_kopf_HALS_ROT_collision_0_0010000000474974513_0_0010000000474974513_0_0010000000474974513" class="rollin-justin_collision"/>
												<joint name="head1" type="hinge" pos="8.673617379884035e-17 -1.6209669511605546e-17 -2.4154289829143205e-25" range="-0.785398006439209 0.785398006439209" axis="0.0 -1.0 0.0"/>
												<body name="head2_link" pos="4.246289074739421e-18 -0.06934716552495956 -7.17752209311584e-06" quat="0.7071067690849304 -2.229749878995289e-17 0.7071067690849304 2.229749878995289e-17">
													<inertial mass="2.7802786827087402" pos="-0.03770316392183304 -0.1356721967458725 0.00041176530066877604" quat="-0.5709280967712402 -0.007026903331279755 0.009677840396761894 0.8209129571914673" diaginertia="0.011197322979569435 0.020993672311306 0.02413904294371605"/>
													<geom name="head2_link_geom_collision_0_justin_rj_kopf_HALS_KNICK_collision" type="mesh" pos="0.0 0.0 0.0" quat="1.0 0.0 0.0 0.0" mesh="justin_rj_kopf_HALS_KNICK_collision_0_0010000000474974513_0_0010000000474974513_0_0010000000474974513" class="rollin-justin_collision"/>
													<joint name="head2_joint" type="hinge" pos="-9.71445146547012e-17 -1.887189406482581e-18 -2.812125808253623e-26" range="-0.43633201718330383 0.785398006439209" axis="0.0 0.0 -1.0"/>
													<body name="head_realsense" pos="-0.128260999917984 -0.23263899981975555 -0.017500000074505806" quat="0.7010575532913208 -0.09229481965303421 -0.7010575532913208 -0.09229481965303421"/>
													<body name="head2" pos="0.0 0.0 2.0679515313825692e-25" quat="-4.084453421281075e-17 9.236319233846298e-17 -0.7071067690849304 0.7071067690849304"/>
												</body>
											</body>
										</body>
										<body name="left_base_link" pos="0.03500000014901161 0.08799999952316284 -0.012662800028920174" quat="0.9659258127212524 -2.6466832770764665e-18 0.2588191330432892 -9.877552291675366e-18">
											<inertial mass="1.6371830701828003" pos="-0.0005617791321128607 -0.00012307609722483903 0.08790497481822968" quat="0.9917028546333313 0.05624055117368698 -0.09607525169849396 -0.06428057700395584" diaginertia="0.001993055222555995 0.0020098104141652584 0.0021475462708622217"/>
											<geom name="left_base_link_geom_collision_0_lr33_J1_Base_frame_collision" type="mesh" pos="0.0 0.0 0.0" quat="1.0 0.0 0.0 0.0" mesh="lr33_J1_Base_frame_collision_0_0010000000474974513_0_0010000000474974513_0_0010000000474974513" class="rollin-justin_collision"/>
											<body name="left_arm1_link" pos="-2.220446049250313e-16 -2.7755575615628914e-17 0.3100000023841858" quat="1.0 -6.162975822039155e-33 -1.3877787807814457e-17 -4.1359030627651384e-25">
												<inertial mass="2.6517059803009033" pos="-0.000355884141754359 0.02011404000222683 -0.04674375429749489" quat="-0.03651833534240723 0.7049189209938049 0.1346525251865387 0.695431113243103" diaginertia="0.004407019820064306 0.01819733716547489 0.01830379106104374"/>
												<geom name="left_arm1_link_geom_collision_0_lr33_J2_HUELLE_A1_collision" type="mesh" pos="0.0 0.0 0.0" quat="1.0 0.0 0.0 0.0" mesh="lr33_J2_HUELLE_A1_collision_0_0010000000474974513_0_0010000000474974513_0_0010000000474974513" class="rollin-justin_collision"/>
												<joint name="left_arm1" type="hinge" pos="3.4196271871485254e-17 2.220446049250313e-16 5.1792617035807345e-17" range="-2.96705961227417 2.96705961227417" axis="0.0 0.0 -1.0"/>
												<body name="left_arm2_link" pos="-2.220446049250313e-16 -1.3877787807814457e-17 -1.1102230246251565e-16" quat="0.7071067690849304 0.7071067690849304 -2.4532688043220205e-18 6.869154637335128e-17">
													<inertial mass="2.2434444427490234" pos="-0.0005090597551316023 0.11014486849308014 0.017628708854317665" quat="-0.6917832493782043 0.14309000968933105 0.013722304254770279 0.7076530456542969" diaginertia="0.003628362901508808 0.020732561126351357 0.020838217809796333"/>
													<geom name="left_arm2_link_geom_collision_0_lr33_J3_HUELLE_A2_collision" type="mesh" pos="0.0 0.0 0.0" quat="1.0 0.0 0.0 0.0" mesh="lr33_J3_HUELLE_A2_collision_0_0010000000474974513_0_0010000000474974513_0_0010000000474974513" class="rollin-justin_collision"/>
													<joint name="left_arm2" type="hinge" pos="8.92092320721371e-17 2.220446049250313e-16 6.752968848495929e-17" range="-2.094395160675049 2.094395160675049" axis="0.0 0.0 -1.0"/>
													<body name="left_arm3_link" pos="0.0 0.4000000059604645 2.7755575615628914e-17" quat="0.5 -0.5 0.5 0.5">
														<inertial mass="2.2448127269744873" pos="-0.0002144670143024996 0.017854824662208557 -0.05443180352449417" quat="-0.06706275045871735 -0.7046449780464172 0.026598772034049034 0.7058828473091125" diaginertia="0.003938048612326384 0.01663348451256752 0.016893470659852028"/>
														<geom name="left_arm3_link_geom_collision_0_lr33_J4_HUELLE_A3_collision" type="mesh" pos="0.0 0.0 0.0" quat="1.0 0.0 0.0 0.0" mesh="lr33_J4_HUELLE_A3_collision_0_0010000000474974513_0_0010000000474974513_0_0010000000474974513" class="rollin-justin_collision"/>
														<joint name="left_arm3" type="hinge" pos="-1.1384857347481744e-16 1.9066452238854204e-16 -4.8629281198542696e-26" range="-2.96705961227417 2.96705961227417" axis="0.0 0.0 -1.0"/>
														<body name="left_arm4_link" pos="-1.3877787807814457e-17 -2.220446049250313e-16 -2.220446049250313e-16" quat="0.7071067690849304 0.7071067690849304 -5.84905010392065e-25 0.0">
															<inertial mass="2.260159969329834" pos="-0.0005054078064858913 0.11100193858146667 0.017489030957221985" quat="-0.6906087398529053 0.14857058227062225 0.008338751271367073 0.7077547311782837" diaginertia="0.0036368316505104303 0.02086985670030117 0.020969387143850327"/>
															<geom name="left_arm4_link_geom_collision_0_lr33_J5_HUELLE_A4_collision" type="mesh" pos="0.0 0.0 0.0" quat="1.0 0.0 0.0 0.0" mesh="lr33_J5_HUELLE_A4_collision_0_0010000000474974513_0_0010000000474974513_0_0010000000474974513" class="rollin-justin_collision"/>
															<joint name="left_arm4" type="hinge" pos="1.3877784499092007e-17 -8.127390316745869e-17 3.033185808843839e-16" range="-2.094395160675049 2.094395160675049" axis="0.0 0.0 -1.0"/>
															<body name="left_arm5_link" pos="1.3877787807814457e-17 0.38999998569488525 -2.220446049250313e-16" quat="-9.236319233846298e-17 -4.084453421281075e-17 0.7071067690849304 0.7071067690849304">
																<inertial mass="0.9630035758018494" pos="2.955424861283973e-05 0.019126400351524353 -0.11188402771949768" quat="0.5841537714004517 0.39848408102989197 -0.3972514271736145 0.5849496722221375" diaginertia="0.001550398301333189 0.0065069375559687614 0.006684670224785805"/>
																<geom name="left_arm5_link_geom_collision_0_lr33_J6_HUELLE_A5_collision" type="mesh" pos="0.0 0.0 0.0" quat="1.0 0.0 0.0 0.0" mesh="lr33_J6_HUELLE_A5_collision_0_0010000000474974513_0_0010000000474974513_0_0010000000474974513" class="rollin-justin_collision"/>
																<joint name="left_arm5" type="hinge" pos="-1.3877791116536907e-17 2.0717046814322938e-16 1.3678507425105122e-16" range="-2.96705961227417 2.96705961227417" axis="0.0 0.0 -1.0"/>
																<body name="left_arm6_link" pos="1.3877787807814457e-17 2.220446049250313e-16 -2.220446049250313e-16" quat="0.5 0.5 0.5 -0.5">
																	<inertial mass="1.7235873937606812" pos="7.239815022330731e-05 -0.007147205527871847 -0.005423184018582106" quat="-0.6586084961891174 0.07558540254831314 0.7455106377601624 0.06881553679704666" diaginertia="0.0031067354138940573 0.003225507913157344 0.003377326764166355"/>
																	<geom name="left_arm6_link_geom_collision_0_lr33_J7_HUELLE_A6_collision" type="mesh" pos="0.0 0.0 0.0" quat="1.0 0.0 0.0 0.0" mesh="lr33_J7_HUELLE_A6_collision_0_0010000000474974513_0_0010000000474974513_0_0010000000474974513" class="rollin-justin_collision"/>
																	<joint name="left_arm6" type="hinge" pos="1.3877791116536907e-17 3.033185808843839e-16 -8.127390316745869e-17" range="-0.785398006439209 1.3962599039077759" axis="0.0 0.0 -1.0"/>
																	<body name="left_arm7_link" pos="0.0 1.3877787807814457e-17 -2.220446049250313e-16" quat="-1.2993184978882488e-16 9.404684899214322e-17 -0.7071067690849304 0.7071067690849304">
																		<inertial mass="0.3805086016654968" pos="0.04210865870118141 0.0002613264077808708 0.041361767798662186" quat="0.9526688456535339 0.14238415658473969 0.2653566598892212 -0.04164895415306091" diaginertia="0.0002721994824241847 0.0010987790301442146 0.00110084586776793"/>
																		<geom name="left_arm7_link_geom_collision_0_lr33_J8_HUELLE_A7_collision" type="mesh" pos="0.0 0.0 0.0" quat="1.0 0.0 0.0 0.0" mesh="lr33_J8_HUELLE_A7_collision_0_0010000000474974513_0_0010000000474974513_0_0010000000474974513" class="rollin-justin_collision"/>
																		<joint name="left_arm7" type="hinge" pos="-9.900382476581829e-17 3.3087222529968844e-24 -1.9923514585599587e-16" range="-0.785398006439209 2.3561899662017822" axis="0.0 0.0 -1.0"/>
																		<body name="leftarm7" pos="0.0 2.220446049250313e-16 0.0" quat="2.3671647619472932e-17 0.7071067690849304 0.7071067690849304 6.292396006915384e-17">
																			<body name="left_arm" pos="0.0 0.11309999972581863 1.3877787807814457e-17" quat="3.925231079531968e-17 -3.925231079531968e-17 -0.7071067690849304 0.7071067690849304"/>
																			<body name="left_arm_palm_link" pos="0.0 0.0 1.3877787807814457e-17" quat="4.329780301713277e-17 0.7071067690849304 0.7071067690849304 4.329780301713277e-17">
																				<body name="left_hand_base_link" pos="0.10260000079870224 0.0 -1.3877787807814457e-17" quat="0.5 -0.5 0.5 -0.5">
																					<inertial mass="1.3667323589324951" pos="-0.00878995656967163 -0.010129254311323166 0.05989619717001915" quat="0.32401925325393677 0.8394043445587158 -0.14734089374542236 -0.410734087228775" diaginertia="0.0011974949156865478 0.0016897829482331872 0.002164067467674613"/>
																					<geom name="left_hand_base_link_geom_collision_0_hii_links_export_Base_SWA_collision" type="mesh" pos="0.0 0.0 0.0" quat="1.0 0.0 0.0 0.0" mesh="hii_links_export_Base_SWA_collision_0_0010000000474974513_0_0010000000474974513_0_0010000000474974513" class="rollin-justin_collision"/>
																					<body name="left_2index_add" pos="-0.04822095111012459 -0.02358194999396801 0.1388426423072815" quat="0.990906834602356 -0.05092969164252281 -0.10476531833410263 -0.06733562797307968">
																						<inertial mass="0.01832089014351368" pos="1.3835101526638027e-06 -0.00594230554997921 0.0002689856628421694" quat="0.49364426732063293 0.5061689615249634 0.49341049790382385 0.5066107511520386" diaginertia="8.063312293415947e-07 1.9452459127933253e-06 1.9491430975904223e-06"/>
																						<geom name="left_2index_add_geom_collision_0_hii_links_export_ZF_MP_AB1_collision" type="mesh" pos="0.0 0.0 0.0" quat="1.0 0.0 0.0 0.0" mesh="hii_links_export_ZF_MP_AB1_collision_0_0010000000474974513_0_0010000000474974513_0_0010000000474974513" class="rollin-justin_collision"/>
																						<joint name="left_2index1" type="hinge" pos="-4.113516577539248e-17 -2.7755575615628914e-17 3.977409963444058e-17" range="-0.5235987901687622 0.5235987901687622" axis="1.0 0.0 0.0"/>
																						<body name="left_2index_prox" pos="-1.1102230246251565e-16 0.0 0.0" quat="1.0 3.851859888774472e-34 2.7755575615628914e-17 3.469446951953614e-18">
																							<inertial mass="0.1042167991399765" pos="-0.0007062018266879022 0.001489807851612568 0.045419350266456604" quat="0.04115879535675049 -0.7005778551101685 -0.005969339516013861 0.7123629450798035" diaginertia="1.2149941539973952e-05 7.304679456865415e-05 7.585596904391423e-05"/>
																							<geom name="left_2index_prox_geom_collision_0_hii_links_export_ZF_MP_AB2_collision" type="mesh" pos="0.0 0.0 0.0" quat="1.0 0.0 0.0 0.0" mesh="hii_links_export_ZF_MP_AB2_collision_0_0010000000474974513_0_0010000000474974513_0_0010000000474974513" class="rollin-justin_collision"/>
																							<joint name="left_2index2" type="hinge" pos="1.3630799948712248e-17 -1.0943958831334649e-16 -1.2772230313454671e-17" range="-0.5235987901687622 1.5707963705062866" axis="0.0 1.0 0.0"/>
																							<body name="left_2index_middle" pos="-2.743769300650456e-06 2.1042985736130504e-06 0.07499294728040695" quat="1.0 3.851859888774472e-34 2.7755575615628914e-17 3.469446951953614e-18">
																								<inertial mass="0.020456522703170776" pos="-0.0021607212256640196 0.0009400434792041779 0.018735868856310844" quat="-0.7038758993148804 -0.007882834412157536 0.7093521356582642 0.036278292536735535" diaginertia="3.305681730125798e-06 4.883020665147342e-06 5.772400072601158e-06"/>
																								<geom name="left_2index_middle_geom_collision_0_hii_links_export_ZF_PIP_collision" type="mesh" pos="0.0 0.0 0.0" quat="1.0 0.0 0.0 0.0" mesh="hii_links_export_ZF_PIP_collision_0_0010000000474974513_0_0010000000474974513_0_0010000000474974513" class="rollin-justin_collision"/>
																								<joint name="left_2index3" type="hinge" pos="1.7364882161828522e-16 -2.871394045588795e-17 -1.0907537738091694e-16" range="-0.5235987901687622 1.5707963705062866" axis="0.0 1.0 0.0"/>
																								<body name="left_2index_distal" pos="4.990901629753353e-07 7.203348559414735e-06 0.040003105998039246" quat="1.0 3.851859888774472e-34 2.7755575615628914e-17 3.469446951953614e-18">
																									<inertial mass="0.022882064804434776" pos="0.001276868162676692 -0.0006573523860424757 0.021217137575149536" quat="-0.10149012506008148 -0.6412995457649231 -0.0016901132185012102 0.7605470418930054" diaginertia="1.5308153251680778e-06 3.831848971458385e-06 4.2437532101757824e-06"/>
																									<geom name="left_2index_distal_geom_collision_0_hii_links_export_ZF_DIP_collision" type="mesh" pos="0.0 0.0 0.0" quat="1.0 0.0 0.0 0.0" mesh="hii_links_export_ZF_DIP_collision_0_0010000000474974513_0_0010000000474974513_0_0010000000474974513" class="rollin-justin_collision"/>
																									<joint name="left_2index4" type="hinge" pos="-1.6062765543538578e-17 1.730104499436311e-16 3.6780893648358245e-17" range="-0.5235987901687622 1.5707963705062866" axis="0.0 1.0 0.0"/>
																								</body>
																							</body>
																						</body>
																					</body>
																					<body name="left_3middle_add" pos="-0.04691247642040253 0.01625622995197773 0.13329803943634033" quat="0.990906834602356 -0.05092969164252281 -0.10476531833410263 -0.06733562797307968">
																						<inertial mass="0.01832089014351368" pos="1.3835101526638027e-06 -0.00594230554997921 0.0002689856628421694" quat="0.49364426732063293 0.5061689615249634 0.49341049790382385 0.5066107511520386" diaginertia="8.063312293415947e-07 1.9452459127933253e-06 1.9491430975904223e-06"/>
																						<geom name="left_3middle_add_geom_collision_0_hii_links_export_MF_MP_AB1_collision" type="mesh" pos="0.0 0.0 0.0" quat="1.0 0.0 0.0 0.0" mesh="hii_links_export_MF_MP_AB1_collision_0_0010000000474974513_0_0010000000474974513_0_0010000000474974513" class="rollin-justin_collision"/>
																						<joint name="left_3middle1" type="hinge" pos="1.2365460773073147e-16 1.457167719820518e-16 -6.337970349944605e-17" range="-0.5235987901687622 0.5235987901687622" axis="1.0 0.0 0.0"/>
																						<body name="left_3middle_prox" pos="2.220446049250313e-16 0.0 4.440892098500626e-16" quat="1.0 3.851859888774472e-34 2.7755575615628914e-17 3.469446951953614e-18">
																							<inertial mass="0.1042167991399765" pos="-0.0007062018266879022 0.001489807851612568 0.045419350266456604" quat="0.04115879535675049 -0.7005778551101685 -0.005969339516013861 0.7123629450798035" diaginertia="1.2149941539973952e-05 7.304679456865415e-05 7.585596904391423e-05"/>
																							<geom name="left_3middle_prox_geom_collision_0_hii_links_export_MF_MP_AB2_collision" type="mesh" pos="0.0 0.0 0.0" quat="1.0 0.0 0.0 0.0" mesh="hii_links_export_MF_MP_AB2_collision_0_0010000000474974513_0_0010000000474974513_0_0010000000474974513" class="rollin-justin_collision"/>
																							<joint name="left_3middle2" type="hinge" pos="2.977758884451274e-16 2.935847429523335e-16 -2.676874252740825e-16" range="-0.5235987901687622 1.5707963705062866" axis="0.0 1.0 0.0"/>
																							<body name="left_3middle_middle" pos="-2.743769300650456e-06 2.1042985736130504e-06 0.07499294728040695" quat="1.0 3.851859888774472e-34 2.7755575615628914e-17 3.469446951953614e-18">
																								<inertial mass="0.020456522703170776" pos="-0.0021607212256640196 0.0009400434792041779 0.018735868856310844" quat="-0.7038758993148804 -0.007882834412157536 0.7093521356582642 0.036278292536735535" diaginertia="3.305681730125798e-06 4.883020665147342e-06 5.772400072601158e-06"/>
																								<geom name="left_3middle_middle_geom_collision_0_hii_links_export_MF_PIP_collision" type="mesh" pos="0.0 0.0 0.0" quat="1.0 0.0 0.0 0.0" mesh="hii_links_export_MF_PIP_collision_0_0010000000474974513_0_0010000000474974513_0_0010000000474974513" class="rollin-justin_collision"/>
																								<joint name="left_3middle3" type="hinge" pos="1.110245920984512e-16 2.8808850497627795e-16 -1.187990443001554e-16" range="-0.5235987901687622 1.5707963705062866" axis="0.0 1.0 0.0"/>
																								<body name="left_3middle_distal" pos="-1.1598295941439574e-06 -2.6447296477272175e-06 0.04000259190797806" quat="1.0 3.851859888774472e-34 2.7755575615628914e-17 3.469446951953614e-18">
																									<inertial mass="0.022882064804434776" pos="0.001276868162676692 -0.0006573523860424757 0.021217137575149536" quat="-0.10149012506008148 -0.6412995457649231 -0.0016901132185012102 0.7605470418930054" diaginertia="1.5308153251680778e-06 3.831848971458385e-06 4.2437532101757824e-06"/>
																									<geom name="left_3middle_distal_geom_collision_0_hii_links_export_MF_DIP_collision" type="mesh" pos="0.0 0.0 0.0" quat="1.0 0.0 0.0 0.0" mesh="hii_links_export_MF_DIP_collision_0_0010000000474974513_0_0010000000474974513_0_0010000000474974513" class="rollin-justin_collision"/>
																									<joint name="left_3middle4" type="hinge" pos="2.91112068490841e-16 -1.1814841711754568e-16 -1.5928687507177613e-16" range="-0.5235987901687622 1.5707963705062866" axis="0.0 1.0 0.0"/>
																								</body>
																							</body>
																						</body>
																					</body>
																					<body name="left_4ring_add" pos="-0.037444453686475754 0.06233131140470505 0.12780100107192993" quat="0.989348292350769 -0.029391737654805183 -0.08072628080844879 -0.11751299351453781">
																						<inertial mass="0.01832089014351368" pos="1.3835101526638027e-06 -0.00594230554997921 0.0002689856628421694" quat="0.49364426732063293 0.5061689615249634 0.49341049790382385 0.5066107511520386" diaginertia="8.063312293415947e-07 1.9452459127933253e-06 1.9491430975904223e-06"/>
																						<geom name="left_4ring_add_geom_collision_0_hii_links_export_RF_MP_AB1_collision" type="mesh" pos="0.0 0.0 0.0" quat="1.0 0.0 0.0 0.0" mesh="hii_links_export_RF_MP_AB1_collision_0_0010000000474974513_0_0010000000474974513_0_0010000000474974513" class="rollin-justin_collision"/>
																						<joint name="left_4ring1" type="hinge" pos="-1.9229623871719884e-16 2.0816681711721685e-16 1.1102234216718506e-16" range="-0.5235987901687622 0.5235987901687622" axis="1.0 0.0 0.0"/>
																						<body name="left_4ring_prox" pos="-1.1102230246251565e-16 0.0 0.0" quat="1.0 -1.3877787807814457e-17 -1.3877787807814457e-17 6.938893903907228e-18">
																							<inertial mass="0.1042167991399765" pos="-0.0007062018266879022 0.001489807851612568 0.045419350266456604" quat="0.04115879535675049 -0.7005778551101685 -0.005969339516013861 0.7123629450798035" diaginertia="1.2149941539973952e-05 7.304679456865415e-05 7.585596904391423e-05"/>
																							<geom name="left_4ring_prox_geom_collision_0_hii_links_export_RF_MP_AB2_collision" type="mesh" pos="0.0 0.0 0.0" quat="1.0 0.0 0.0 0.0" mesh="hii_links_export_RF_MP_AB2_collision_0_0010000000474974513_0_0010000000474974513_0_0010000000474974513" class="rollin-justin_collision"/>
																							<joint name="left_4ring2" type="hinge" pos="2.5288347311289448e-17 -1.0776420346579179e-16 -8.56316064396738e-18" range="-0.5235987901687622 1.5707963705062866" axis="0.0 1.0 0.0"/>
																							<body name="left_4ring_middle" pos="-2.127009565811022e-06 -6.785803066122753e-07 0.07499859482049942" quat="1.0 -1.3877787807814457e-17 -1.3877787807814457e-17 6.938893903907228e-18">
																								<inertial mass="0.020456522703170776" pos="-0.0021607212256640196 0.0009400434792041779 0.018735868856310844" quat="-0.7038758993148804 -0.007882834412157536 0.7093521356582642 0.036278292536735535" diaginertia="3.305681730125798e-06 4.883020665147342e-06 5.772400072601158e-06"/>
																								<geom name="left_4ring_middle_geom_collision_0_hii_links_export_RF_PIP_collision" type="mesh" pos="0.0 0.0 0.0" quat="1.0 0.0 0.0 0.0" mesh="hii_links_export_RF_PIP_collision_0_0010000000474974513_0_0010000000474974513_0_0010000000474974513" class="rollin-justin_collision"/>
																								<joint name="left_4ring3" type="hinge" pos="-5.53361785434651e-18 -1.0536581147766776e-17 -1.041308969975751e-17" range="-0.5235987901687622 1.5707963705062866" axis="0.0 1.0 0.0"/>
																								<body name="left_4ring_distal" pos="7.282319984369678e-06 6.307909188763006e-06 0.04000448063015938" quat="1.0 -1.3877787807814457e-17 -1.3877787807814457e-17 6.938893903907228e-18">
																									<inertial mass="0.022882064804434776" pos="0.001276868162676692 -0.0006573523860424757 0.021217137575149536" quat="-0.10149012506008148 -0.6412995457649231 -0.0016901132185012102 0.7605470418930054" diaginertia="1.5308153251680778e-06 3.831848971458385e-06 4.2437532101757824e-06"/>
																									<geom name="left_4ring_distal_geom_collision_0_hii_links_export_RF_DIP_collision" type="mesh" pos="0.0 0.0 0.0" quat="1.0 0.0 0.0 0.0" mesh="hii_links_export_RF_DIP_collision_0_0010000000474974513_0_0010000000474974513_0_0010000000474974513" class="rollin-justin_collision"/>
																									<joint name="left_4ring4" type="hinge" pos="1.5835422562240014e-16 -1.3116405773395327e-16 -4.658293096755242e-17" range="-0.5235987901687622 1.5707963705062866" axis="0.0 1.0 0.0"/>
																								</body>
																							</body>
																						</body>
																					</body>
																					<body name="left_1thumb_add" pos="0.050334978848695755 -0.046195030212402344 0.1009046882390976" quat="0.11157157272100449 0.2852843105792999 0.01846318691968918 0.951747715473175">
																						<inertial mass="0.01832089014351368" pos="1.3835101526638027e-06 -0.005948239471763372 -4.237922257743776e-05" quat="0.48022517561912537 0.5189175605773926 0.47997987270355225 0.5193530917167664" diaginertia="8.063312293415947e-07 1.9452459127933253e-06 1.9491430975904223e-06"/>
																						<geom name="left_1thumb_add_geom_collision_0_hii_links_export_D_MP_AB1_collision" type="mesh" pos="0.0 0.0 0.0" quat="1.0 0.0 0.0 0.0" mesh="hii_links_export_D_MP_AB1_collision_0_0010000000474974513_0_0010000000474974513_0_0010000000474974513" class="rollin-justin_collision"/>
																						<joint name="left_1thumb1" type="hinge" pos="-2.919138116451968e-16 -8.326672022944184e-17 1.6052425785881665e-16" range="-0.5235987901687622 0.5235987901687622" axis="1.0 0.0 0.0"/>
																						<body name="left_1thumb_prox" pos="0.0 0.0 0.0" quat="1.0 1.0842021724855044e-17 -7.703719777548943e-34 0.0">
																							<inertial mass="0.1042167991399765" pos="-0.0007062018266879022 -0.0008892991463653743 0.04543507844209671" quat="0.05948368087410927 -0.699260413646698 -0.024614781141281128 0.7119625806808472" diaginertia="1.2149941539973952e-05 7.304679456865415e-05 7.585596904391423e-05"/>
																							<geom name="left_1thumb_prox_geom_collision_0_hii_links_export_D_MP_AB2_collision" type="mesh" pos="0.0 0.0 0.0" quat="1.0 0.0 0.0 0.0" mesh="hii_links_export_D_MP_AB2_collision_0_0010000000474974513_0_0010000000474974513_0_0010000000474974513" class="rollin-justin_collision"/>
																							<joint name="left_1thumb2" type="hinge" pos="0.0 0.0 0.0" range="-0.5235987901687622 1.5707963705062866" axis="0.0 1.0 0.0"/>
																							<body name="left_1thumb_middle" pos="-2.769701495708432e-06 -8.75379441822588e-07 0.07549897581338882" quat="1.0 3.0357660829594124e-18 1.734723475976807e-18 0.0">
																								<inertial mass="0.020456522703170776" pos="-0.0021607212256640196 -0.003967001102864742 0.01815660484135151" quat="-0.703428328037262 -0.02630545198917389 0.7081593871116638 0.05483453348278999" diaginertia="3.305681730125798e-06 4.883020665147342e-06 5.772400072601158e-06"/>
																								<geom name="left_1thumb_middle_geom_collision_0_hii_links_export_D_PIP_collision" type="mesh" pos="0.0 0.0 0.0" quat="1.0 0.0 0.0 0.0" mesh="hii_links_export_D_PIP_collision_0_0010000000474974513_0_0010000000474974513_0_0010000000474974513" class="rollin-justin_collision"/>
																								<joint name="left_1thumb3" type="hinge" pos="-1.0137910367326636e-16 -3.820938361191159e-16 -7.003094369097674e-17" range="-0.5235987901687622 1.5707963705062866" axis="0.0 1.0 0.0"/>
																								<body name="left_1thumb_distal" pos="2.8259695028509668e-08 -1.941029495355906e-06 0.03999917954206467" quat="1.0 1.0408340855860843e-17 1.734723475976807e-18 0.0">
																									<inertial mass="0.022882064804434776" pos="0.001276868162676692 -0.00778550561517477 0.020496053621172905" quat="0.6437364816665649 -0.08466807752847672 0.7602421641349792 0.0215983297675848" diaginertia="1.5308153251680778e-06 3.831848971458385e-06 4.2437532101757824e-06"/>
																									<geom name="left_1thumb_distal_geom_collision_0_hii_links_export_D_DIP_collision" type="mesh" pos="0.0 0.0 0.0" quat="1.0 0.0 0.0 0.0" mesh="hii_links_export_D_DIP_collision_0_0010000000474974513_0_0010000000474974513_0_0010000000474974513" class="rollin-justin_collision"/>
																									<joint name="left_1thumb4" type="hinge" pos="-1.0976400193214489e-16 1.1254050314135058e-16 3.063870702323759e-17" range="-0.5235987901687622 1.5707963705062866" axis="0.0 1.0 0.0"/>
																								</body>
																							</body>
																						</body>
																					</body>
																				</body>
																			</body>
																		</body>
																	</body>
																</body>
															</body>
														</body>
													</body>
												</body>
											</body>
										</body>
									</body>
								</body>
							</body>
						</body>
					</body>
					<body name="wheel_rb_link" pos="-0.3427000045776367 0.25714001059532166 0.02889999933540821" quat="-0.2705952823162079 0.2705952823162079 -0.653282642364502 0.653282642364502">
						<inertial mass="5.6581597328186035" pos="-0.014599462039768696 -0.011620926670730114 -3.107102384092286e-05" quat="0.5004712343215942 0.5054946541786194 -0.49133065342903137 -0.5025911927223206" diaginertia="0.019188283011317253 0.02395530231297016 0.036094557493925095"/>
						<geom name="wheel_rb_link_geom_collision_0_mp_mobile_plattform_rj_ROT3_collision" type="mesh" pos="0.0 0.0 0.0" quat="1.0 0.0 0.0 0.0" mesh="mp_mobile_plattform_rj_ROT3_collision_0_0010000000474974513_0_0010000000474974513_0_0010000000474974513" class="rollin-justin_collision"/>
					</body>
				</body>
			</body>
		</body>
	</worldbody>
	<equality/>
</mujoco>
